Workbook

Sheet takvim
A1: f | C1: TARİH | D1: Randevu Alan | E1: ID | F1: RESTORAN | G1: SAAT | H1: İLÇE / MAHALLE | I1: YETKİLİ KİŞİ / TELEFON | J1: ADRES | K1: Notlar | L1: Fotoğraf Adeti | M1: Toplam ürün | N1: Şubeli | O1: İptal
C2: 44285
B3: Çukurova | N3: FALSE | O3: FALSE
A4: =E4 -> 5ff302a74f55ab6f4e9ea62f | C4: Nazmi Okbaz | D4: Özlem arslan | E4: 5ff302a74f55ab6f4e9ea62f | F4: BIG-S Burger, Çukurova (Güzelyalı Mah.) | G4: 0.45833333 | H4: Çukurova Mahfesığmaz | I4: Süleyman 5426752656 | J4: güzelyalı mah turgut özal blv. aksa gaz karşısı sturbacks yanı kenanaoğlu apt altı çukurova adana | K4: Kendi ajanslarına çektirmişler | M4: =VLOOKUP(E4,'hedef liste'!A:I,8,false) -> 46 | N4: FALSE | O4: FALSE
A5: =E5 -> 604538b0075e9b5c86b52986 | C5: Nazmi Okbaz | D5: Özlem arslan | E5: 604538b0075e9b5c86b52986 | F5: Hataylım Döner & Tantuni (Yüzüncü Yıl Mah.) | G5: 0.52083333 | H5: Çukurova Yüzüncüyıl | I5: mehmet bey 5442582307 | J5: hacı bektaş veli bulv. no 77 | M5: =VLOOKUP(E5,'hedef liste'!A:I,8,false) -> 9 | N5: FALSE | O5: FALSE
A6: =E6 -> 600605867441fc14ff7f7c0a | C6: Nazmi Okbaz | D6: Özlem arslan | E6: 600605867441fc14ff7f7c0a | F6: Fırat Cafe Pandora,Yurt Mah. - Turgut Özal Blv.) | G6: 15:00 | H6: Çukurova Yurt | I6: ferhat bey 3222398595 | J6: yurt mah turgut özal bulvarı no:178 / a çukurova adana | M6: =VLOOKUP(E6,'hedef liste'!A:I,8,false) -> 7 | N6: FALSE | O6: FALSE
A7: =E7 -> 603a1b3f717836115614220d | C7: Nazmi Okbaz | D7: Özlem arslan | E7: 603a1b3f717836115614220d | F7: Antakya Express Döner (Belediyeevleri Mah.) | G7: 17:00 | H7: Çukurova Belediye Evleri | I7: Adem bey 5316968522 | J7: belediye evleri mh hilmi küklü blv yasemen apt no 65 - 2 A çukurova adana | M7: =VLOOKUP(E7,'hedef liste'!A:I,8,false) -> 19 | N7: FALSE | O7: FALSE
A8: =E8 -> 60155dca998c13f968875764 | C8: Nazmi Okbaz | D8: Beyza gülşah | E8: 60155dca998c13f968875764 | F8: Fa’ Mira Pasta & Cafe, Çukurova (Belediyeevleri Mah.) | G8: 18.30 | H8: Çukurova Belediye Evleri | I8: Hakanbey/5530893212 | J8: belediye evleri mah turgut özal bulv no 279 a çukurova adana | N8: FALSE | O8: FALSE
A9: =E9 | C9: 44286
A10: =E10 | B10: Çukurova | N10: FALSE | O10: FALSE
A11: =E11 | M11: =VLOOKUP(E11,'hedef liste'!A:I,8,false) -> #N/A | N11: FALSE | O11: FALSE
A12: =E12 -> 5feb8f7237c1dbf256558540 | C12: Nazmi Okbaz | D12: Özlem arslan | E12: 5feb8f7237c1dbf256558540 | F12: The Zula, Çukurova (Mahfesığmaz Mah. Turgut Özal Blv.) | G12: 0.54166667 | H12: çukurova Güzelyalı | I12: aykut bey 3222334477 | J12: mahfesıgmaz mah turgut ozal bulvarı no:35/f çukuova adana | M12: =VLOOKUP(E12,'hedef liste'!A:I,8,false) -> #N/A | N12: FALSE | O12: FALSE
A13: =E13 -> 5ff39882ee0f72652ca8f3a6 | C13: Nazmi Okbaz | D13: Beyza gülşah | E13: 5ff39882ee0f72652ca8f3a6 | F13: Antakyam Döner, Çukurova (Mahfesığmaz Mah.) | G13: 15:00 | H13: çukurova Güzelyalı | J13: mahfesığmaz mah turgut özal bulv abbas bilir apt b blok no:59/a çukurova adana | M13: =VLOOKUP(E13,'hedef liste'!A:I,8,false) -> 26 | N13: FALSE | O13: FALSE
A14: =E14 -> 5ffafe0efd88ae2c276c1a8b | C14: Nazmi Okbaz | D14: Özlem arslan | E14: 5ffafe0efd88ae2c276c1a8b | F14: Ortaköy Çorbacısı, Çukurova (Güzelyalı Mah. - Turgut Özal Blv.) | G14: 14:00 | H14: çukurova Güzelyalı | I14: culyan bey 05368201805 | J14: mahfesığmaz mah turgut özal bulv parlak gümüş apt no:111/a çukurova adana | K14: İPTAL SESBİ İÇİN SONRA ARA | M14: =VLOOKUP(E14,'hedef liste'!A:I,8,false) -> #N/A | N14: FALSE | O14: FALSE
A15: =E15 -> 600478050d6f591a059c2f51 | C15: Nazmi Okbaz | D15: Özlem arslan | E15: 600478050d6f591a059c2f51 | F15: Ciğerci Ulaş,(Güzelyalı Mah. - Turgut Özal Blv.) | G15: 0.6875 | H15: çukurova Güzelyalı | I15: hüseyin bey 3222328486 | J15: güzelyalı mah turgut özal bulv akçeli 1 apt no:74/a çukurova adana | M15: =VLOOKUP(E15,'hedef liste'!A:I,8,false) -> 16 | N15: FALSE | O15: FALSE
A16: =E16 | C16: 44287
A17: =E17 | B17: Çukurova | N17: FALSE | O17: FALSE
A18: =E18 | C18: Nazmi Okbaz | G18: 0.47916667 | M18: =VLOOKUP(E18,'hedef liste'!A:I,8,false) -> #N/A | N18: FALSE | O18: FALSE
A19: =E19 -> 60093cc8e13dbd0db25c79f9 | C19: Nazmi Okbaz | D19: Özlem arslan | E19: 60093cc8e13dbd0db25c79f9 | F19: Aşık Döner, Çukurova (Belediyeevleri Mah.) | G19: 0.54166667 | H19: Çukurova Belediye Evleri | I19: yalçın bey/3227770303 | J19: belediye evleri mah 84081 sk no 35/a-1 cukurova adana | M19: =VLOOKUP(E19,'hedef liste'!A:I,8,false) -> 4 | N19: FALSE | O19: FALSE
A20: =E20 -> 5fe9001ba415e906823c1038 | C20: Nazmi Okbaz | D20: Beyza gülşah | E20: 5fe9001ba415e906823c1038 | F20: Tuil Cafe & Patiserrie (Yüzüncü Yıl Mah.) | G20: 15:00 | H20: Çukurova/yüzüncüyıl | I20: Oğuzhan bey/3222660044/5079342078 | J20: yüzüncü yıl mah fazlı meto bulv baysallar apt 01360 çukurova adana | M20: =VLOOKUP(E20,'hedef liste'!A:I,8,false) -> 39 | N20: FALSE | O20: FALSE
A21: =E21 -> 5fe5d2ed87a63b1f653166d1 | C21: Nazmi Okbaz | D21: Beyza gülşah | E21: 5fe5d2ed87a63b1f653166d1 | F21: By Tombiş Cafe, Çukurova (Huzurevleri Mah.) | G21: 17:00 | H21: Çukurova/huzurevler | I21: 5393857711 | J21: huzurevleri mah 77215 sok no6/d çukurova adana | N21: FALSE | O21: FALSE
A22: =E22 | N22: FALSE | O22: FALSE
A23: =E23 | C23: 44288
A24: =E24 -> ALINMAYACAK | B24: Çukurova | E24: ALINMAYACAK | N24: FALSE | O24: FALSE
A25: =E25 | C25: Nazmi Okbaz | M25: =VLOOKUP(E25,'hedef liste'!A:I,8,false) -> #N/A | N25: FALSE | O25: FALSE
A26: =E26 | C26: Nazmi Okbaz | M26: =VLOOKUP(E26,'hedef liste'!A:I,8,false) -> #N/A | N26: FALSE | O26: FALSE
A27: =E27 | C27: Nazmi Okbaz | M27: =VLOOKUP(E27,'hedef liste'!A:I,8,false) -> #N/A | N27: FALSE | O27: FALSE
A28: =E28 | C28: Nazmi Okbaz | M28: =VLOOKUP(E28,'hedef liste'!A:I,8,false) -> #N/A | N28: FALSE | O28: FALSE
A29: =E29 | N29: FALSE | O29: FALSE
A30: =E30 | C30: 44291
A31: =E31 | B31: Çukurova | N31: FALSE | O31: FALSE
A32: =E32 | C32: Berat Altunkaya | D32: Ezgi Turan | G32: 0.45833333 | M32: =VLOOKUP(E32,'hedef liste'!A:I,8,false) -> #N/A | N32: FALSE | O32: FALSE
A33: =E33 -> 604c7b12f1352d7b0d49cd68 | C33: Berat Altunkaya | D33: Ezgi Turan | E33: 604c7b12f1352d7b0d49cd68 | F33: @'li Burger, Çukurova (Güzelyalı Mah. - Turgut Özal Blv.) | G33: 0.54166667 | H33: Çukurova Güzelyalı | I33: ozan ulus /5467875437 | J33: GÜZELYALI MAH. TURGUT ÖZAL BLV. NO: 52 /2B ÇUKUROVA/ ADANA | M33: =VLOOKUP(E33,'hedef liste'!A:I,8,false) -> #N/A | N33: FALSE | O33: FALSE
A34: =E34 -> 600456bc3368d68b8aeb1782 | C34: Berat Altunkaya | D34: Ezgi Turan | E34: 600456bc3368d68b8aeb1782 | F34: Best Burger,(Güzelyalı Mah. - Turgut Özal Blv.) | G34: 15:00 | H34: Çukurova /Güzelyalı | I34: rahmetullah özdemir/3222349404 | J34: güzelyalı mah 81106 sok sefa parlak apt no:1/a çukurova adana | M34: =VLOOKUP(E34,'hedef liste'!A:I,8,false) -> 21 | N34: FALSE | O34: FALSE
A35: =E35 -> 60146096f179e4d84c264942 | C35: Berat Altunkaya | D35: Ezgi Turan | E35: 60146096f179e4d84c264942 | F35: Tutku Tantuni, Çukurova (Güzelyalı Mah.) | G35: 17:00 | H35: Çukurova Güzelyalı | I35: Şerife Er/3222342020 | J35: Güzelyalı mah.Turgut Özal Bulvarı.Dermancan Tıp Merkezi Arkası,Talıcı Zeki karşısı çukurova adana | M35: =VLOOKUP(E35,'hedef liste'!A:I,8,false) -> 4 | N35: FALSE | O35: FALSE
A36: =E36 | N36: FALSE | O36: FALSE
A37: =E37 | C37: 44292
A38: =E38 | B38: Çukurova | N38: FALSE | O38: FALSE
A39: =E39 -> 6033a76217a3766376370395 | C39: Berat Altunkaya | D39: Özlem arslan | E39: 6033a76217a3766376370395 | F39: Lale Börekçilik (Yüzüncü Yıl Mah.) | G39: 0.41666667 | H39: Çukurova/yüzüncüyıl | I39: Nusret bey 3222568885/ 5467958513 | J39: yüzüncü yıl mh 85023 sk sudesu apt no 1 iç kapı no 21 çukurova adana | M39: =VLOOKUP(E39,'hedef liste'!A:I,8,false) -> 9 | N39: FALSE | O39: FALSE
A40: =E40 -> 601490c1e3c69cb0618311b6 | C40: Berat Altunkaya | D40: Özlem arslan | E40: 601490c1e3c69cb0618311b6 | F40: Börek House, Çukurova (Yüzüncü Yıl Mah.) | G40: 0.47916667 | H40: Çukurova/yüzüncüyıl | I40: Muzaffer bey 3222563356 | J40: Yüzüncüyıl, Hacı Bektaş Veli Blv No:17, 01170 Çukurova/Adana | M40: =VLOOKUP(E40,'hedef liste'!A:I,8,false) -> 2 | N40: FALSE | O40: FALSE
...

Sheet hedef liste
A1: Restaurant ID | B1: Restoran Adı | C1: Satışa Açık Mı? | D1: Mutfak | E1: TOPLAM SİPARİŞ | F1: SON 2 HAFTA | G1: RESİMLİ ÜRÜN | H1: RESİMSİZ ÜRÜN | I1: TOPLAM ÜRÜN | J1: Ratio | K1: Yetkili | L1: Telefon | M1: İLÇE | N1: MAHALLE | O1: ADRES | P1: Geleneksel Zincir | Q1: FOTOĞRAF SEGMENT | R1: Aradık Mı? | S1: Kendi Fotosu Var | T1: Randevu Durumu | U1: Randevu Alan | V1: Fotoğrafçı | W1: Not | X1: Randevu Alma Tarihi | Y1: Randevu Tarihi | Z1: Anket Durum | AA1: 1. Arama | AB1: 1. Arama Tarihi | AC1: 2. Arama | AD1: 2. Arama Tarihi | AE1: 3. Arama | AF1: 3. Arama Tarihi | AG1: 4. Arama | AH1: 4. Arama Tarihi | AI1: 5. Arama | AJ1: 5. Arama Tarihi | AK1: 1. Arayan | AL1: 2. Arayan | AM1: 3. Arayan | AN1: 4. Arayan | AO1: 5. Arayan | AP1: SY | AQ1: SY - Durum
A2: 6149d88f74c1c5c5db026e6a | B2: 01 Ada Dönercim , Çukurova (Yüzüncü Yıl mah.) | C2: =VLOOKUP(A2,import!A:J,3,0) -> DOĞRU | D2: Döner | E2: =VLOOKUP(A2,import!A:J,5,0) -> 557 | F2: =VLOOKUP(A2,import!A:J,6,0) -> 3 | G2: =VLOOKUP(A2,import!A:J,7,0) -> 8 | H2: =VLOOKUP(A2,import!A:J,8,0) -> 0 | I2: =VLOOKUP(A2,import!A:J,9,0) -> 8 | J2: =VLOOKUP(A2,import!A:J,10,0) -> 1 | K2: barbaros hayreddin gürsoy | L2: 5079724473 | M2: Çukurova | N2: Yüzüncüyıl | O2: yüzüncü yıl mah 85062 sk d blok no 60/2 iç kapı no 4 çukurova adana | P2: =VLOOKUP(A2,import!A:P,16,0) -> Geleneksel | R2: TRUE | S2: FALSE | T2: Randevu Alındı | U2: Ezgi Turan | V2: Berat Altunkaya | W2: musaıt degıl 5ten sonra arancak | X2: 44470 | Y2: 44473 | AA2: Ulaşılamadı | AB2: 44466 | AC2: Ulaşılamadı | AD2: 44467 | AE2: Tekrar Aranacak | AF2: 44469 | AG2: Görüşüldü | AH2: 44470 | AK2: Ferhat Köksal | AL2: Ayşegül Kır | AM2: Tuğba Buyur | AN2: Ezgi Turan | AP2: Sinem Koçak
A3: 60043086a35105b0f4f7cb6d | B3: 01 Bay Şef Döner (Sucuzade Mah.) | C3: =VLOOKUP(A3,import!A:J,3,0) -> DOĞRU | D3: Döner | E3: =VLOOKUP(A3,import!A:J,5,0) -> 4618 | F3: =VLOOKUP(A3,import!A:J,6,0) -> 21 | G3: =VLOOKUP(A3,import!A:J,7,0) -> 30 | H3: =VLOOKUP(A3,import!A:J,8,0) -> 3 | I3: =VLOOKUP(A3,import!A:J,9,0) -> 33 | J3: =VLOOKUP(A3,import!A:J,10,0) -> 0.91 | K3: mustafa altunkaynak | L3: 5526590101 | M3: Seyhan | N3: Sucuzade | O3: sucuzade mah obalar cad no:95/b seyhan adana | P3: =VLOOKUP(A3,import!A:P,16,0) -> Geleneksel | R3: TRUE | S3: FALSE | T3: Randevu Alındı | U3: Ezgi Turan | V3: Berat Altunkaya | X3: 44386 | Y3: 44390 | AA3: Görüşüldü | AB3: 44349 | AC3: Görüşüldü | AD3: 44377 | AE3: Görüşüldü | AF3: 44386 | AL3: Ezgi Turan | AM3: Ezgi Turan | AP3: Fulya Kortak
A4: 617ff3821ff4003da8c6218c | B4: 01 Cheff Döner Cafe, Seyhan (Kurtuluş Mah.) | C4: =VLOOKUP(A4,import!A:J,3,0) -> DOĞRU | D4: Döner | E4: =VLOOKUP(A4,import!A:J,5,0) -> 118 | F4: =VLOOKUP(A4,import!A:J,6,0) | G4: =VLOOKUP(A4,import!A:J,7,0) -> 16 | H4: =VLOOKUP(A4,import!A:J,8,0) -> 13 | I4: =VLOOKUP(A4,import!A:J,9,0) -> 29 | J4: =VLOOKUP(A4,import!A:J,10,0) -> 0.55 | K4: hanefi alp | L4: 3225033803 | M4: Seyhan | N4: Kurtuluş | O4: kurtuluş mah atatürk cd gülbahçesi sitesi seyhan adana | P4: =VLOOKUP(A4,import!A:P,16,0) -> Geleneksel | R4: TRUE | S4: FALSE | T4: Randevu Alındı | U4: Ferhat Köksal | V4: Berat Altunkaya | W4: ULAŞILMADI | X4: 44515 | Y4: 44517 | AA4: Görüşüldü | AB4: 44515 | AC4: Ulaşılamadı | AD4: 44574 | AK4: Ferhat Köksal | AL4: Selcan Topçu | AP4: Fulya Kortak
A5: 6076f807d4c52441976104b8 | B5: 01 Sarıçam Tantuni (Esentepe Mah.) | C5: =VLOOKUP(A5,import!A:J,3,0) -> DOĞRU | D5: Sokak Lezzetleri | E5: =VLOOKUP(A5,import!A:J,5,0) -> 2130 | F5: =VLOOKUP(A5,import!A:J,6,0) -> 41 | G5: =VLOOKUP(A5,import!A:J,7,0) -> 10 | H5: =VLOOKUP(A5,import!A:J,8,0) -> 2 | I5: =VLOOKUP(A5,import!A:J,9,0) -> 12 | J5: =VLOOKUP(A5,import!A:J,10,0) -> 0.83 | K5: pınar uysun | L5: 3223418087 | M5: Sarıçam | N5: Şahintepe | O5: esentepe mah kozan caddesi 161 d sarıçam adana | P5: =VLOOKUP(A5,import!A:P,16,0) -> Geleneksel | R5: TRUE | S5: FALSE | T5: Randevu Alındı | U5: Ferhat Köksal | V5: Berat Altunkaya | W5: yetkililere ezgi hanımın numarasını iletecekler- ulasılamadı - randevu oluşturuldu /teyit için arandı yetkili yok no iletildi | X5: 44459 | Y5: 44460 | AA5: Ulaşılamadı | AB5: 44379 | AC5: Yetkili Yok | AD5: 44379 | AE5: Dönüş Yapacak | AF5: 44407 | AG5: Görüşüldü | AH5: 44428 | AI5: Yetkili Yok | AJ5: 44475 | AK5: Ezgi Turan | AL5: Tutku Erdoğan | AM5: Ezgi Turan | AN5: Mertcan karaman | AO5: Ayşegül Kır | AP5: Fulya Kortak
A6: 624ac7875406c23fc4b9667e | B6: 01 Servis Künefe, Ceyhan (Namık Kemal Mah.) | C6: =VLOOKUP(A6,import!A:J,3,0) -> DOĞRU | D6: Pasta & Tatlı | E6: =VLOOKUP(A6,import!A:J,5,0) -> 21 | F6: =VLOOKUP(A6,import!A:J,6,0) -> 21 | G6: =VLOOKUP(A6,import!A:J,7,0) -> 0 | H6: =VLOOKUP(A6,import!A:J,8,0) -> 23 | I6: =VLOOKUP(A6,import!A:J,9,0) -> 23 | J6: =VLOOKUP(A6,import!A:J,10,0) -> 0 | K6: EMRAH ÖZER | L6: 5354791758 | M6: Ceyhan | N6: Namık Kemal | O6: namık kemal mah. orhan ekinci bul. no 66 iç kapı no z3 ceyhan adana | P6: =VLOOKUP(A6,import!A:P,16,0) -> Geleneksel | R6: FALSE | S6: FALSE
A7: 6204dfe3bc188a960e30cf59 | B7: 01 Urfa Sofrası, Yüreğir (Dadaloğlu Mah.) | C7: =VLOOKUP(A7,import!A:J,3,0) -> DOĞRU | D7: Döner | E7: =VLOOKUP(A7,import!A:J,5,0) -> 411 | F7: =VLOOKUP(A7,import!A:J,6,0) -> 67 | G7: =VLOOKUP(A7,import!A:J,7,0) -> 0 | H7: =VLOOKUP(A7,import!A:J,8,0) -> 20 | I7: =VLOOKUP(A7,import!A:J,9,0) -> 20 | J7: =VLOOKUP(A7,import!A:J,10,0) -> 0 | K7: ABDURRAHMAN TOPRAK | L7: 3223281415 | M7: Yüreğir | N7: Dadaloğlu | O7: DADALOĞLU MAH ŞEHİT JAN. ER MUSTAFA GÖKSAL CAD NO 14 YÜREĞİR ADANA | P7: =VLOOKUP(A7,import!A:P,16,0) -> Geleneksel | R7: TRUE | S7: FALSE | T7: İleride Randevu Alınacak | W7: 5416304677 | AA7: Görüşüldü | AB7: 44622 | AK7: Ferhat Köksal
A8: 62409c93f48420a955ad2cea | B8: 112 Kaburgacı Kenan, Yüreğir (Kazım Karabekir Mah.) | C8: =VLOOKUP(A8,import!A:J,3,0) -> DOĞRU | D8: Kebap | E8: =VLOOKUP(A8,import!A:J,5,0) | F8: =VLOOKUP(A8,import!A:J,6,0) | G8: =VLOOKUP(A8,import!A:J,7,0) -> 0 | H8: =VLOOKUP(A8,import!A:J,8,0) -> 8 | I8: =VLOOKUP(A8,import!A:J,9,0) -> 8 | J8: =VLOOKUP(A8,import!A:J,10,0) -> 0 | K8: Onur Öncü Uyandı | L8: 5372339571 | M8: Yüreğir | N8: Kazım Karabekir | O8: kazım karabekir mah. 4192 sok. no 4 iç kapı no 201 | P8: =VLOOKUP(A8,import!A:P,16,0) -> Geleneksel | R8: FALSE | S8: FALSE
A9: 60cf803e7761e5799d054248 | B9: 27 Tat Cafe , Çukurova (Yurt Mah.) | C9: =VLOOKUP(A9,import!A:J,3,0) -> DOĞRU | D9: Döner | E9: =VLOOKUP(A9,import!A:J,5,0) -> 103 | F9: =VLOOKUP(A9,import!A:J,6,0) -> 3 | G9: =VLOOKUP(A9,import!A:J,7,0) -> 10 | H9: =VLOOKUP(A9,import!A:J,8,0) -> 2 | I9: =VLOOKUP(A9,import!A:J,9,0) -> 12 | J9: =VLOOKUP(A9,import!A:J,10,0) -> 0.83 | K9: zeynep topaloğlu | L9: 3222320040 | M9: Çukurova | N9: Yurt | O9: yurt mah 71445 sok no 5 d çukurova adana | P9: =VLOOKUP(A9,import!A:P,16,0) -> Geleneksel | R9: TRUE | S9: FALSE | T9: Randevu Alındı | U9: Nazlıcan Dinçer | V9: Berat Altunkaya | W9: 5452370127 | X9: 44382 | Y9: 44383 | AA9: Tekrar Aranacak | AB9: 44382 | AC9: Görüşüldü | AD9: 44382 | AK9: Ayşegül Dulkadir | AL9: Nazlıcan Dinçer | AP9: Sinem Koçak
A10: 603e3464303c95afe93092dc | B10: 5 Kardeşler Kebap Ve Izgara Çeşitleri (Gültepe Mah.) | C10: =VLOOKUP(A10,import!A:J,3,0) -> DOĞRU | D10: Kebap | E10: =VLOOKUP(A10,import!A:J,5,0) -> 1664 | F10: =VLOOKUP(A10,import!A:J,6,0) -> 62 | G10: =VLOOKUP(A10,import!A:J,7,0) -> 10 | H10: =VLOOKUP(A10,import!A:J,8,0) -> 1 | I10: =VLOOKUP(A10,import!A:J,9,0) -> 11 | J10: =VLOOKUP(A10,import!A:J,10,0) -> 0.91 | K10: leyla kocaman | L10: 5454013058 | M10: Sarıçam | N10: Gültepe | O10: gültepe mah. çatalan cd. no 31 sarıçam adana | P10: =VLOOKUP(A10,import!A:P,16,0) -> Geleneksel | R10: TRUE | S10: FALSE | T10: Randevu Alındı | U10: Mertcan karaman | V10: Berat Altunkaya | W10: yarın 4 de aranacak | X10: 44428 | Y10: 44434 | AA10: Ulaşılamadı | AB10: 44407 | AC10: Tekrar Aranacak | AD10: 44424 | AE10: Görüşüldü | AF10: 44428 | AL10: Deneme | AM10: Mertcan karaman | AP10: Fulya Kortak
A11: 6070c6c9dc91044886734ac4 | B11: 5 Ocak Kebap (Kurtuluş Mah.) | C11: =VLOOKUP(A11,import!A:J,3,0) -> DOĞRU | D11: Kebap | E11: =VLOOKUP(A11,import!A:J,5,0) -> 137 | F11: =VLOOKUP(A11,import!A:J,6,0) | G11: =VLOOKUP(A11,import!A:J,7,0) -> 0 | H11: =VLOOKUP(A11,import!A:J,8,0) -> 35 | I11: =VLOOKUP(A11,import!A:J,9,0) -> 35 | J11: =VLOOKUP(A11,import!A:J,10,0) -> 0 | K11: erisn şendoğan | L11: 3224582868 | M11: Seyhan | N11: Kurtuluş | O11: kurtuluş mah şinasi efendi cd suphi ramazanoğlu apt b girişi no 22 d seyhan adana | P11: =VLOOKUP(A11,import!A:P,16,0) -> Geleneksel | R11: TRUE | S11: TRUE | W11: 5324412251 ersin bey mail verildi bayramdan sonra gönderimini sağlayacaklar-bır saate aranacak- yüzüme kapattı | AA11: Görüşüldü | AB11: 44386 | AC11: Görüşüldü | AD11: 44414 | AE11: Yetkili Yok | AF11: 44418 | AG11: Ulaşılamadı | AH11: 44432 | AI11: Görüşüldü | AJ11: 44459 | AK11: Ezgi Turan | AL11: Sezer Arslan | AM11: Mertcan karaman | AO11: Ferhat Köksal | AP11: Fulya Kortak
A12: 602ba8e05eff103e230ddcf1 | B12: 7/C Ocakbaşı (Mahfesığmaz Mah.) | C12: =VLOOKUP(A12,import!A:J,3,0) -> YANLIŞ | D12: Kebap | E12: =VLOOKUP(A12,import!A:J,5,0) -> 459 | F12: =VLOOKUP(A12,import!A:J,6,0) | G12: =VLOOKUP(A12,import!A:J,7,0) -> 0 | H12: =VLOOKUP(A12,import!A:J,8,0) -> 49 | I12: =VLOOKUP(A12,import!A:J,9,0) -> 49 | J12: =VLOOKUP(A12,import!A:J,10,0) -> 0 | K12: soner sarp | L12: 5339298859 | M12: Çukurova | N12: Mahfesığmaz | O12: MAHFESIĞMAZ MAH. 79019 sk no 23/A ÇUKUROVA/ ADANA | P12: =VLOOKUP(A12,import!A:P,16,0) -> Geleneksel | R12: TRUE | S12: FALSE | T12: Başka Şubeden Çekilecek | W12: 5ffe23ee4a4dfa3a5caba607 7/C Ocakbaşı Gazipaşa,(Cemalpaşa Mah.) ızgara ürünleri buradan yüklenecek | AA12: Görüşüldü | AB12: 44349 | AK12: Nazlıcan Dinçer | AP12: Sinem Koçak
A13: 5ffe23ee4a4dfa3a5caba607 | B13: 7/C Ocakbaşı Gazipaşa,(Cemalpaşa Mah.) | C13: =VLOOKUP(A13,import!A:J,3,0) -> DOĞRU | D13: Kebap | E13: =VLOOKUP(A13,import!A:J,5,0) -> 4029 | F13: =VLOOKUP(A13,import!A:J,6,0) -> 35 | G13: =VLOOKUP(A13,import!A:J,7,0) -> 0 | H13: =VLOOKUP(A13,import!A:J,8,0) -> 75 | I13: =VLOOKUP(A13,import!A:J,9,0) -> 75 | J13: =VLOOKUP(A13,import!A:J,10,0) -> 0 | K13: soner sarp | L13: 3224546565 | M13: Seyhan | N13: Cemalpaşa | O13: cemalpaşa mah toros cad yeşil apt no:19/a seyhan adana | P13: =VLOOKUP(A13,import!A:P,16,0) -> Geleneksel | R13: TRUE | S13: FALSE | T13: İleride Randevu Alınacak | U13: Serap Apaydın | V13: Berat Altunkaya | X13: 44550 | Y13: 44560 | AA13: Görüşüldü | AB13: 44379 | AC13: Ulaşılamadı | AD13: 44385 | AE13: Görüşüldü | AF13: 44386 | AG13: Görüşüldü | AH13: 44415 | AI13: Görüşüldü | AJ13: 44555 | AK13: Reşit Usta Light Kebap, Seyhan (Yenibaraj Mah. - Barajyolu) | AL13: Ezgi Turan | AM13: Ezgi Turan | AN13: Duygu Telli | AO13: Serap Apaydın | AP13: Sinem Koçak
A14: 61b264592be549f3bda5fe7f | B14: 7/C Ocakbaşı, Çukurova (Mahfesığmaz Mah.) | C14: =VLOOKUP(A14,import!A:J,3,0) -> DOĞRU | D14: Kebap | E14: =VLOOKUP(A14,import!A:J,5,0) -> 9 | F14: =VLOOKUP(A14,import!A:J,6,0) | G14: =VLOOKUP(A14,import!A:J,7,0) -> 0 | H14: =VLOOKUP(A14,import!A:J,8,0) -> 35 | I14: =VLOOKUP(A14,import!A:J,9,0) -> 35 | J14: =VLOOKUP(A14,import!A:J,10,0) -> 0 | K14: SONER SARP | L14: 5339298859 | M14: Çukurova | N14: Mahfesığmaz | O14: Mahfesığmaz mh, 79019. Sk 23/A, 01150 Çukurova/Adana | P14: =VLOOKUP(A14,import!A:P,16,0) -> Geleneksel | R14: TRUE | S14: FALSE | T14: Başka Şubeden Çekilecek | W14: 5ffe23ee4a4dfa3a5caba607 7/C Ocakbaşı Gazipaşa,(Cemalpaşa Mah.) izgara ürünleri buradan yüklenecek
A15: 60153c905fe8231f17cfb78f | B15: Abdullah Usta Kebap, Seyhan (Pınar Mah.) | C15: =VLOOKUP(A15,import!A:J,3,0) -> DOĞRU | D15: Kebap | E15: =VLOOKUP(A15,import!A:J,5,0) -> 520 | F15: =VLOOKUP(A15,import!A:J,6,0) -> 7 | G15: =VLOOKUP(A15,import!A:J,7,0) -> 0 | H15: =VLOOKUP(A15,import!A:J,8,0) -> 9 | I15: =VLOOKUP(A15,import!A:J,9,0) -> 9 | J15: =VLOOKUP(A15,import!A:J,10,0) -> 0 | K15: ismail kılınç | L15: 5370509967 | M15: Seyhan | N15: Pınar | O15: pınar mah semt 74052sk seyhan adana | P15: =VLOOKUP(A15,import!A:P,16,0) -> Geleneksel | R15: TRUE | S15: TRUE | W15: fotograflarımı bugun çekecegim sizlere gönderirim dedi mail verildi.(bügün atcaz dedİ)/ açmadı- ulasılamadı | AA15: Yetkili Yok | AB15: 44389 | AC15: Ulaşılamadı | AD15: 44390 | AE15: Görüşüldü | AF15: 44414 | AG15: Görüşüldü | AH15: 44418 | AI15: Ulaşılamadı | AJ15: 44502 | AM15: Nazlıcan Dinçer | AN15: Mertcan karaman | AO15: Ferhat Köksal | AP15: Fulya Kortak
A16: 602721f33a2e4e6b65d17d17 | B16: Acıktım Büfe, Seyhan (Kayalıbağ Mah.) | C16: =VLOOKUP(A16,import!A:J,3,0) -> DOĞRU | D16: Tost & Sandviç | E16: =VLOOKUP(A16,import!A:J,5,0) -> 953 | F16: =VLOOKUP(A16,import!A:J,6,0) -> 11 | G16: =VLOOKUP(A16,import!A:J,7,0) -> 10 | H16: =VLOOKUP(A16,import!A:J,8,0) -> 6 | I16: =VLOOKUP(A16,import!A:J,9,0) -> 16 | J16: =VLOOKUP(A16,import!A:J,10,0) -> 0.63 | K16: memduh birdir | L16: 5539373685 | M16: Seyhan | N16: Kayalıbağ | O16: KAYALIBAĞ MAH. 26001 SK. NO: 1 E SEYHAN/ ADANA | P16: =VLOOKUP(A16,import!A:P,16,0) -> Geleneksel | R16: TRUE | S16: FALSE | T16: Randevu Alındı | U16: Derya Tatlı | V16: Berat Altunkaya | X16: 44378 | Y16: 44383 | AA16: Ulaşılamadı | AB16: 44349 | AC16: Ulaşılamadı | AD16: 44372 | AE16: Görüşüldü | AF16: 44378 | AG16: Ulaşılamadı | AH16: 44434 | AK16: Nazlıcan Dinçer | AL16: Ayşegül Dulkadir | AM16: Derya Tatlı | AN16: Deneme | AP16: Fulya Kortak
A17: 6061ee4b4c11b057fb3b6f6c | B17: Adana Ateşi Mangalcı (Sümer Mah. - Barajyolu) | C17: =VLOOKUP(A17,import!A:J,3,0) -> DOĞRU | D17: Kebap | E17: =VLOOKUP(A17,import!A:J,5,0) -> 1081 | F17: =VLOOKUP(A17,import!A:J,6,0) -> 38 | G17: =VLOOKUP(A17,import!A:J,7,0) -> 10 | H17: =VLOOKUP(A17,import!A:J,8,0) -> 13 | I17: =VLOOKUP(A17,import!A:J,9,0) -> 23 | J17: =VLOOKUP(A17,import!A:J,10,0) -> 0.43 | K17: kemal sabancı | L17: 5324989006 | M17: Seyhan | N17: Sümer | O17: sümer mh 69077 sk gökhan apartmanı 3 E seyhan adana | P17: =VLOOKUP(A17,import!A:P,16,0) -> Geleneksel | R17: TRUE | S17: FALSE | T17: Randevu Alındı | U17: ezgi turan | V17: BERAT | W17: HAFTAYA | X17: 44469 | Y17: 44474 | AA17: Görüşüldü | AB17: 44379 | AC17: Ulaşılamadı | AD17: 44432 | AE17: Görüşüldü | AF17: 44406 | AG17: Ulaşılamadı | AH17: 44407 | AI17: Görüşüldü | AJ17: 44469 | AK17: Ezgi Turan | AM17: Ezgi Turan | AN17: Ezgi Turan | AO17: Ezgi Turan | AP17: Fulya Kortak
A18: 5fff32b068b4946f548f8458 | B18: Adana Başkent Döner, Seyhan (Döşeme Mah.) | C18: =VLOOKUP(A18,import!A:J,3,0) -> DOĞRU | D18: Döner | E18: =VLOOKUP(A18,import!A:J,5,0) -> 2713 | F18: =VLOOKUP(A18,import!A:J,6,0) -> 131 | G18: =VLOOKUP(A18,import!A:J,7,0) -> 5 | H18: =VLOOKUP(A18,import!A:J,8,0) -> 1 | I18: =VLOOKUP(A18,import!A:J,9,0) -> 6 | J18: =VLOOKUP(A18,import!A:J,10,0) -> 0.83 | K18: mustafa orhan | L18: 3224362727 | M18: Seyhan | N18: Döşeme | O18: döşeme mah cumhuriyet cad çolpan apt no:71/d1 seyhan adana | P18: =VLOOKUP(A18,import!A:P,16,0) -> Geleneksel | R18: TRUE | S18: TRUE | AP18: Fulya Kortak
A19: 604d30a2cc98d70511a66c8a | B19: Adana Börekçilik (Selahattin Eyyubi Mah.) | C19: =VLOOKUP(A19,import!A:J,3,0) -> DOĞRU | D19: Börek | E19: =VLOOKUP(A19,import!A:J,5,0) -> 2276 | F19: =VLOOKUP(A19,import!A:J,6,0) -> 68 | G19: =VLOOKUP(A19,import!A:J,7,0) -> 3 | H19: =VLOOKUP(A19,import!A:J,8,0) -> 5 | I19: =VLOOKUP(A19,import!A:J,9,0) -> 8 | J19: =VLOOKUP(A19,import!A:J,10,0) -> 0.38 | K19: ersin kardaş | L19: 3223283535 | M19: Yüreğir | N19: Serinevler | O19: serinevler mh Mustafa Kemal Paşa Blv. No:108, 01240 Yüreğir/Adana | P19: =VLOOKUP(A19,import!A:P,16,0) -> Geleneksel | R19: TRUE | S19: FALSE | T19: Randevu Alındı | U19: Sezer Arslan | V19: Berat Altunkaya | W19: dç için arandı yalnızca su boregı urunlerı eksık | X19: 44432 | Y19: 44435 | AA19: Yetkili Yok | AB19: 44403 | AC19: Yetkili Yok | AD19: 44432 | AE19: Görüşüldü | AF19: 44432 | AG19: Görüşüldü | AH19: 44496 | AK19: Derya Tatlı | AM19: Sezer Arslan | AN19: Tuğba Buyur | AP19: Fulya Kortak
A20: 60492e300392aa19f82322d8 | B20: Adana Döner Cafe (2000 Evler Mah.) | C20: =VLOOKUP(A20,import!A:J,3,0) -> DOĞRU | D20: Döner | E20: =VLOOKUP(A20,import!A:J,5,0) -> 856 | F20: =VLOOKUP(A20,import!A:J,6,0) -> 30 | G20: =VLOOKUP(A20,import!A:J,7,0) -> 2 | H20: =VLOOKUP(A20,import!A:J,8,0) -> 12 | I20: =VLOOKUP(A20,import!A:J,9,0) -> 14 | J20: =VLOOKUP(A20,import!A:J,10,0) -> 0.14 | K20: veysel zengin | L20: 5368944006 | M20: Seyhan | N20: 2000 Evler | O20: 2000 evler mah 76067 sk göksu apt er-as inşaat no 1a seyhan adana | P20: =VLOOKUP(A20,import!A:P,16,0) -> Geleneksel | R20: TRUE | S20: FALSE | T20: Randevu Alındı | U20: Ezgi Turan | V20: Berat Altunkaya | W20: çekim yapıldı . | X20: 44460 | Y20: 44462 | AA20: Ulaşılamadı | AB20: 44434 | AC20: Ulaşılamadı | AD20: 44450 | AK20: Deneme | AL20: Zeliha Özer | AP20: Fulya Kortak
A21: 615de1ae16054412f42dae92 | B21: Adana Dürümcüsü , Çukurova (Toros Mah.) | C21: =VLOOKUP(A21,import!A:J,3,0) -> DOĞRU | D21: Kebap | E21: =VLOOKUP(A21,import!A:J,5,0) -> 3613 | F21: =VLOOKUP(A21,import!A:J,6,0) -> 169 | G21: =VLOOKUP(A21,import!A:J,7,0) -> 12 | H21: =VLOOKUP(A21,import!A:J,8,0) -> 27 | I21: =VLOOKUP(A21,import!A:J,9,0) -> 39 | J21: =VLOOKUP(A21,import!A:J,10,0) -> 0.31 | K21: Muhammet Belindir | L21: 5064670177 | M21: Çukurova | N21: Toros | O21: TOROS MAH. ALİ SEPİCİ BLV. NO: 7 B ÇUKUROVA/ ADANA | P21: =VLOOKUP(A21,import!A:P,16,0) -> Geleneksel | R21: TRUE | S21: FALSE | T21: Randevu Alındı | U21: Ferhat Köksal | V21: Berat Altunkaya | X21: 44483 | Y21: 44484 | AA21: Görüşüldü | AB21: 44483 | AK21: Ferhat Köksal | AP21: Sinem Koçak
A22: 60774818a562d4e7c2efd287 | B22: Adana Erbey Döner (Tellidere Mah.) | C22: =VLOOKUP(A22,import!A:J,3,0) -> DOĞRU | D22: Döner | E22: =VLOOKUP(A22,import!A:J,5,0) -> 1125 | F22: =VLOOKUP(A22,import!A:J,6,0) -> 63 | G22: =VLOOKUP(A22,import!A:J,7,0) -> 0 | H22: =VLOOKUP(A22,import!A:J,8,0) -> 20 | I22: =VLOOKUP(A22,import!A:J,9,0) -> 20 | J22: =VLOOKUP(A22,import!A:J,10,0) -> 0 | K22: serkan büyükocak | L22: 3222620430 | M22: Seyhan | N22: Tellidere | O22: pınar mah mücahitler cd 305/b seyhan adana | P22: =VLOOKUP(A22,import!A:P,16,0) -> Geleneksel | R22: TRUE | S22: FALSE | T22: Çekim İstemiyor | U22: Zeliha Özer | V22: Berat Altunkaya | W22: yetkili müsait degil. yarım saat sonra arayın dediler./mail verildi (musait oldugumda göndercem dedi)-yetkili iki saate gelir dedi- yanlış numara | X22: 44450 | Y22: 44452 | AA22: Yetkili Yok | AB22: 44377 | AC22: Görüşüldü | AD22: 44378 | AE22: Görüşüldü | AF22: 44386 | AG22: Yetkili Yok | AH22: 44414 | AI22: Ulaşılamadı | AJ22: 44490 | AK22: Gül Değirmenci | AL22: Derya Tatlı | AM22: Ezgi Turan | AN22: Sezer Arslan | AO22: Ferhat Köksal | AP22: Fulya Kortak
A23: 61b32fd96311be259b7c4149 | B23: Adana Gurmesi Tantuni Dünyası, Sarıçam (Yeşiltepe Mah.) | C23: =VLOOKUP(A23,import!A:J,3,0) -> DOĞRU | D23: Sokak Lezzetleri | E23: =VLOOKUP(A23,import!A:J,5,0) -> 198 | F23: =VLOOKUP(A23,import!A:J,6,0) -> 9 | G23: =VLOOKUP(A23,import!A:J,7,0) -> 0 | H23: =VLOOKUP(A23,import!A:J,8,0) -> 15 | I23: =VLOOKUP(A23,import!A:J,9,0) -> 15 | J23: =VLOOKUP(A23,import!A:J,10,0) -> 0 | K23: Taner Aksoy | L23: 5433741115 | M23: Sarıçam | N23: Yeşiltepe | O23: YEŞİLTEPE MAH. ÇATALAN CAD. NO: 2 B SARIÇAM/ ADANA | P23: =VLOOKUP(A23,import!A:P,16,0) -> Geleneksel | R23: FALSE | S23: FALSE
A24: 6255318a77674f597b22477b | B24: Adana Lezzet Durağı, Çukurova (Mahfesığmaz Mah.) | C24: =VLOOKUP(A24,import!A:J,3,0) -> DOĞRU | D24: Tost & Sandviç | E24: =VLOOKUP(A24,import!A:J,5,0) -> 12 | F24: =VLOOKUP(A24,import!A:J,6,0) -> 12 | G24: =VLOOKUP(A24,import!A:J,7,0) -> 0 | H24: =VLOOKUP(A24,import!A:J,8,0) -> 14 | I24: =VLOOKUP(A24,import!A:J,9,0) -> 14 | J24: =VLOOKUP(A24,import!A:J,10,0) -> 0 | K24: Riber Ergün | L24: 5444024221 | M24: Çukurova | N24: Mahfesığmaz | O24: mahfesığmaz mah. damar arıkoğlu bul. no 22 a çukurova adana | P24: =VLOOKUP(A24,import!A:P,16,0) -> Geleneksel | R24: FALSE | S24: FALSE
A25: 61138ceadf23a498ae6d3d8b | B25: Adana Lezzet Sokağı, Seyhan (Yeşilyurt Mah.) | C25: =VLOOKUP(A25,import!A:J,3,0) -> DOĞRU | D25: Kebap | E25: =VLOOKUP(A25,import!A:J,5,0) -> 199 | F25: =VLOOKUP(A25,import!A:J,6,0) -> 8 | G25: =VLOOKUP(A25,import!A:J,7,0) -> 14 | H25: =VLOOKUP(A25,import!A:J,8,0) -> 6 | I25: =VLOOKUP(A25,import!A:J,9,0) -> 20 | J25: =VLOOKUP(A25,import!A:J,10,0) -> 0.7 | K25: Ali Miraç Aşık | L25: 3222257171 | M25: Seyhan | N25: Yeşilyurt | O25: yeşilyurt mah ibo osman cd no 3/A seyhan adana | P25: =VLOOKUP(A25,import!A:P,16,0) -> Geleneksel | R25: TRUE | S25: FALSE | T25: Randevu Alındı | U25: Deneme | V25: Berat Altunkaya | W25: donus yapılacak | X25: 44432 | Y25: 44435 | AA25: Tekrar Aranacak | AB25: 44424 | AC25: Görüşüldü | AD25: 44432 | AK25: Deneme | AL25: Deneme | AP25: Fulya Kortak
A26: 605cd2d0e81f5bc7fe859127 | B26: Adana Mercan Şaşlık Kebap (Toros Mah.) | C26: =VLOOKUP(A26,import!A:J,3,0) -> DOĞRU | D26: Kebap | E26: =VLOOKUP(A26,import!A:J,5,0) -> 1088 | F26: =VLOOKUP(A26,import!A:J,6,0) -> 69 | G26: =VLOOKUP(A26,import!A:J,7,0) -> 18 | H26: =VLOOKUP(A26,import!A:J,8,0) -> 26 | I26: =VLOOKUP(A26,import!A:J,9,0) -> 44 | J26: =VLOOKUP(A26,import!A:J,10,0) -> 0.41 | K26: murat bey | L26: 3222270000 | M26: Çukurova | N26: Toros | O26: Toros mah Özkan Apt. D:No. 8/B, A Blok, 78195. Sk., 01170 Çukurova | P26: =VLOOKUP(A26,import!A:P,16,0) -> Geleneksel | R26: TRUE | S26: FALSE | T26: Randevu Alındı | U26: Gül Değirmenci | V26: Berat Altunkaya | W26: 2 kere randevu alınmış gidilmemiş./yetkili yoktu(istemiyor | X26: 44355 | Y26: 44357 | AA26: Görüşüldü | AB26: 44355 | AC26: Tekrar Aranacak | AD26: 44415 | AE26: Görüşüldü | AF26: 44425 | AL26: Duygu Telli | AM26: Mertcan karaman | AP26: Sinem Koçak
A27: 60ad6669ab98d3666726872a | B27: Adana Nohut Dürüm, Seyhan (Cemalpaşa Mah.) | C27: =VLOOKUP(A27,import!A:J,3,0) -> YANLIŞ | D27: Sokak Lezzetleri | E27: =VLOOKUP(A27,import!A:J,5,0) -> 88 | F27: =VLOOKUP(A27,import!A:J,6,0) | G27: =VLOOKUP(A27,import!A:J,7,0) -> 0 | H27: =VLOOKUP(A27,import!A:J,8,0) -> 10 | I27: =VLOOKUP(A27,import!A:J,9,0) -> 10 | J27: =VLOOKUP(A27,import!A:J,10,0) -> 0 | K27: canan boğa | L27: 5322814079 | M27: Seyhan | N27: Cemalpaşa | O27: cemalpaşa mah 63005 sok gonca apt no 19 b seyhan adana | P27: =VLOOKUP(A27,import!A:P,16,0) -> Geleneksel | R27: TRUE | S27: FALSE | T27: Randevu İptal | U27: Ferhat Köksal | V27: Berat Altunkaya | W27: açıp yüzüme kapattı | X27: 44498 | Y27: 44501 | AA27: Görüşüldü | AB27: 44349 | AC27: Ulaşılamadı | AD27: 44414 | AE27: Ulaşılamadı | AF27: 44418 | AG27: Ulaşılamadı | AH27: 44432 | AI27: Görüşüldü | AJ27: 44498 | AK27: Ecem Ünal | AL27: Sezer Arslan | AM27: Mertcan karaman | AN27: Deneme | AO27: Ferhat Köksal | AP27: Sinem Koçak
A28: 6229d63c31a6056df37ed1a7 | B28: Adana Sofrası, Ceyhan (Namık Kemal Mah.) | C28: =VLOOKUP(A28,import!A:J,3,0) -> DOĞRU | D28: Kebap | E28: =VLOOKUP(A28,import!A:J,5,0) -> 220 | F28: =VLOOKUP(A28,import!A:J,6,0) -> 49 | G28: =VLOOKUP(A28,import!A:J,7,0) -> 0 | H28: =VLOOKUP(A28,import!A:J,8,0) -> 32 | I28: =VLOOKUP(A28,import!A:J,9,0) -> 32 | J28: =VLOOKUP(A28,import!A:J,10,0) -> 0 | K28: Gökhan Lak | L28: 541820921 | M28: Ceyhan | N28: Namık Kemal | O28: NAMIK KEMAL MAHALLESİ AHMET URAL SOKAK NO:54/ZA | P28: =VLOOKUP(A28,import!A:P,16,0) -> Geleneksel | R28: FALSE | S28: FALSE
A29: 6034fc52a26855195d29cf96 | B29: Adana Taşköprü Közde Döner (Türkocağı Mah.) | C29: =VLOOKUP(A29,import!A:J,3,0) -> DOĞRU | D29: Döner | E29: =VLOOKUP(A29,import!A:J,5,0) -> 3846 | F29: =VLOOKUP(A29,import!A:J,6,0) -> 188 | G29: =VLOOKUP(A29,import!A:J,7,0) -> 19 | H29: =VLOOKUP(A29,import!A:J,8,0) -> 0 | I29: =VLOOKUP(A29,import!A:J,9,0) -> 19 | J29: =VLOOKUP(A29,import!A:J,10,0) -> 1 | K29: osman bey | L29: 5382822213 | M29: Seyhan | N29: Türkocağı | O29: türkocağı mh debboy cd no 22 a seyhan adana | P29: =VLOOKUP(A29,import!A:P,16,0) -> Geleneksel | R29: TRUE | S29: FALSE | T29: Randevu Alındı | U29: Deneme | V29: Berat Altunkaya | X29: 44414 | Y29: 44420 | AA29: Görüşüldü | AB29: 44379 | AC29: Ulaşılamadı | AD29: 44406 | AE29: Ulaşılamadı | AF29: 44407 | AG29: Görüşüldü | AH29: 44414 | AK29: Ezgi Turan | AL29: Ezgi Turan | AM29: Deneme | AP29: Fulya Kortak
A30: 5fde3e1ec0e54f3447874015 | B30: Adana Tatlıcı Gönül Kardeşler, Çukurova (Yurt Mah.) | C30: =VLOOKUP(A30,import!A:J,3,0) -> DOĞRU | D30: Pasta & Tatlı | E30: =VLOOKUP(A30,import!A:J,5,0) -> 2344 | F30: =VLOOKUP(A30,import!A:J,6,0) -> 84 | G30: =VLOOKUP(A30,import!A:J,7,0) -> 17 | H30: =VLOOKUP(A30,import!A:J,8,0) -> 3 | I30: =VLOOKUP(A30,import!A:J,9,0) -> 20 | J30: =VLOOKUP(A30,import!A:J,10,0) -> 0.85 | K30: Nilüfer Erçelik | L30: 5457477171 | M30: Çukurova | N30: Güzelyalı | O30: yurt mah anadolu Lisesi cd. Cem Atasever apt. altı Ablok No:17/C Çukurova Adana | P30: =VLOOKUP(A30,import!A:P,16,0) -> Geleneksel | R30: TRUE | S30: FALSE | T30: Randevu Alındı | U30: Duygu Telli | V30: Berat Altunkaya | W30: 5379682594 bütün ürünlerin çekimleri gerçekleştirilmiş | X30: 44412 | Y30: 44413 | AA30: Görüşüldü | AB30: 44412 | AK30: Duygu Telli | AP30: Sinem Koçak
A31: 621340f818fb79fc0432e4ea | B31: Adanas Çiğ Köfte & Meze, Ceyhan (Burhaniye Mah.) | C31: =VLOOKUP(A31,import!A:J,3,0) -> DOĞRU | D31: Çiğ Köfte | E31: =VLOOKUP(A31,import!A:J,5,0) -> 52 | F31: =VLOOKUP(A31,import!A:J,6,0) -> 5 | G31: =VLOOKUP(A31,import!A:J,7,0) -> 0 | H31: =VLOOKUP(A31,import!A:J,8,0) -> 14 | I31: =VLOOKUP(A31,import!A:J,9,0) -> 14 | J31: =VLOOKUP(A31,import!A:J,10,0) -> 0 | K31: NİGAR UZUN | L31: 5013588370 | M31: Ceyhan | N31: Burhaniye | O31: burhaniye mah kızılay cad no 72 ceyhan adana | P31: =VLOOKUP(A31,import!A:P,16,0) -> Geleneksel | R31: FALSE | S31: FALSE
A32: 600c3c27104d8bc181f29e17 | B32: Adıyamanlı Çiğ Köfteci Ali Baba, Seyhan (Reşatbey Mah.) | C32: =VLOOKUP(A32,import!A:J,3,0) -> DOĞRU | D32: Çiğ Köfte | E32: =VLOOKUP(A32,import!A:J,5,0) -> 2223 | F32: =VLOOKUP(A32,import!A:J,6,0) -> 15 | G32: =VLOOKUP(A32,import!A:J,7,0) -> 9 | H32: =VLOOKUP(A32,import!A:J,8,0) -> 2 | I32: =VLOOKUP(A32,import!A:J,9,0) -> 11 | J32: =VLOOKUP(A32,import!A:J,10,0) -> 0.82 | K32: Serkan Kılıçarslan | L32: 5495121940 | M32: Seyhan | N32: Reşatbey | O32: Reşatbey Mahallesi 62005 sokak no:18/A KVK karşısı Seyhan/ADANA | P32: =VLOOKUP(A32,import!A:P,16,0) -> Geleneksel | R32: TRUE | S32: TRUE | U32: Deneme | V32: Berat Altunkaya | W32: salı çarşamba randevu verilebilir | X32: 44434 | Y32: 44439 | Z32: Fotoğraflarım Var | AA32: Ulaşılamadı | AB32: 44379 | AC32: Görüşüldü | AD32: 44384 | AE32: Dönüş Yapacak | AF32: 44414 | AG32: Ulaşılamadı | AH32: 44418 | AI32: Görüşüldü | AJ32: 44434 | AK32: Tutku Erdoğan | AL32: Tutku Erdoğan | AM32: Sezer Arslan | AN32: Mertcan karaman | AO32: Deneme | AP32: Fulya Kortak
A33: 60af971c521633e1bffc15bb | B33: Adıyamanlı Çiğ Köfteci Erdoğan Usta (Gürselpaşa Mah.) | C33: =VLOOKUP(A33,import!A:J,3,0) -> YANLIŞ | D33: Çiğ Köfte | E33: =VLOOKUP(A33,import!A:J,5,0) -> 16 | F33: =VLOOKUP(A33,import!A:J,6,0) | G33: =VLOOKUP(A33,import!A:J,7,0) -> 6 | H33: =VLOOKUP(A33,import!A:J,8,0) -> 2 | I33: =VLOOKUP(A33,import!A:J,9,0) -> 8 | J33: =VLOOKUP(A33,import!A:J,10,0) -> 0.75 | K33: erdoğan özer | L33: 5425942705 | M33: Seyhan | N33: Pınar | O33: pınar mah mavi bulvar üzeri al sitesi b blok no 79/2 seyhan adana | P33: =VLOOKUP(A33,import!A:P,16,0) -> Geleneksel | R33: TRUE | S33: FALSE | T33: Randevu Alındı | U33: Zeliha Özer | V33: Berat Altunkaya | W33: açmadı | X33: 44476 | Y33: 44480 | AA33: Görüşüldü | AB33: 44377 | AC33: Ulaşılamadı | AD33: 44393 | AE33: Ulaşılamadı | AF33: 44414 | AG33: Ulaşılamadı | AH33: 44435 | AI33: Görüşüldü | AJ33: 44476 | AK33: Gül Değirmenci | AL33: Derya Tatlı | AM33: Deneme | AN33: Deneme | AO33: Zeliha Özer | AP33: Fulya Kortak
A34: 6038ebc8a69617f99256f27c | B34: Adıyörem Çiğ Köfte (Karacaoğlan Mah.) | C34: =VLOOKUP(A34,import!A:J,3,0) -> DOĞRU | D34: Çiğ Köfte | E34: =VLOOKUP(A34,import!A:J,5,0) -> 1637 | F34: =VLOOKUP(A34,import!A:J,6,0) -> 59 | G34: =VLOOKUP(A34,import!A:J,7,0) -> 8 | H34: =VLOOKUP(A34,import!A:J,8,0) -> 1 | I34: =VLOOKUP(A34,import!A:J,9,0) -> 9 | J34: =VLOOKUP(A34,import!A:J,10,0) -> 0.89 | K34: adem kocatürk | L34: 5377484554 | M34: Kozan | N34: Karacaoğlan | O34: karacaoğlan mah turgut özal blv sultan hatun apt no 115 c kozan adana | P34: =VLOOKUP(A34,import!A:P,16,0) -> Geleneksel | R34: FALSE | S34: FALSE | T34: Franchise | AP34: Fulya Kortak
A35: 614d972035a05d0b209f023a | B35: Adıyörem Çiğ Köfte, Seyhan (İkibinevler Mah.) | C35: =VLOOKUP(A35,import!A:J,3,0) -> DOĞRU | D35: Çiğ Köfte | E35: =VLOOKUP(A35,import!A:J,5,0) -> 241 | F35: =VLOOKUP(A35,import!A:J,6,0) -> 9 | G35: =VLOOKUP(A35,import!A:J,7,0) -> 6 | H35: =VLOOKUP(A35,import!A:J,8,0) -> 5 | I35: =VLOOKUP(A35,import!A:J,9,0) -> 11 | J35: =VLOOKUP(A35,import!A:J,10,0) -> 0.55 | K35: mehmet kaya | L35: 5421550201 | M35: Seyhan | N35: 2000 Evler | O35: 2000 evler mah 76067 sk no 1 a seyhan adana | P35: =VLOOKUP(A35,import!A:P,16,0) -> Geleneksel | R35: TRUE | S35: FALSE | T35: Franchise | AP35: Fulya Kortak
A36: 606258b0b48e8457df440076 | B36: Afilli Balık (Mahfesığmaz Mah.) | C36: =VLOOKUP(A36,import!A:J,3,0) -> DOĞRU | D36: Balık & Deniz Ürünleri | E36: =VLOOKUP(A36,import!A:J,5,0) -> 379 | F36: =VLOOKUP(A36,import!A:J,6,0) -> 30 | G36: =VLOOKUP(A36,import!A:J,7,0) -> 21 | H36: =VLOOKUP(A36,import!A:J,8,0) -> 13 | I36: =VLOOKUP(A36,import!A:J,9,0) -> 34 | J36: =VLOOKUP(A36,import!A:J,10,0) -> 0.62 | K36: doğukan idigük | L36: 5449234554 | M36: Çukurova | N36: Mahfesığmaz | O36: mahfesıgmaz mah 79079 sok no: 1/2a çukurova adana | P36: =VLOOKUP(A36,import!A:P,16,0) -> Geleneksel | R36: TRUE | S36: FALSE | T36: Randevu Alındı | U36: Ezgi Turan | V36: Berat Altunkaya | W36: 2 saat sonra aranacak/haftaya cuma günü için aranacak-randevu olusturuldu | X36: 44459 | Y36: 44460 | AA36: Tekrar Aranacak | AB36: 44362 | AC36: Tekrar Aranacak | AD36: 44371 | AE36: Tekrar Aranacak | AF36: 44349 | AG36: Görüşüldü | AH36: 44382 | AI36: Görüşüldü | AJ36: 44447 | AK36: Selcan Topçu | AL36: Tutku Erdoğan | AM36: Ezgi Turan | AN36: Ezgi Turan | AO36: Ferhat Köksal | AP36: Sinem Koçak
A37: 60376534f4f38611c483385e | B37: Afiyet Kebap (Huzurevleri Mah.) | C37: =VLOOKUP(A37,import!A:J,3,0) -> DOĞRU | D37: Kebap | E37: =VLOOKUP(A37,import!A:J,5,0) -> 2174 | F37: =VLOOKUP(A37,import!A:J,6,0) -> 66 | G37: =VLOOKUP(A37,import!A:J,7,0) -> 0 | H37: =VLOOKUP(A37,import!A:J,8,0) -> 29 | I37: =VLOOKUP(A37,import!A:J,9,0) -> 29 | J37: =VLOOKUP(A37,import!A:J,10,0) -> 0 | K37: erdoğan aksoyan | L37: 3228020818 | M37: Çukurova | N37: Huzurevleri | O37: HUZUREVLERİ MAH. 77088 SK. GİRİCİLER APT. NO: 2 İÇ KAPI NO: 02 ÇUKUROVA/ ADANA | P37: =VLOOKUP(A37,import!A:P,16,0) -> Geleneksel | R37: TRUE | S37: TRUE | U37: Ferhat Köksal | V37: Berat Altunkaya | W37: mail olarak gönderilmiş.(göndermiş 15 gün olmuş / yarın ara /yt yok 1 saat sonra/Profesyonel çekimleri varmış mail verildi | X37: 44480 | Y37: 44481 | AA37: Görüşüldü | AB37: 44414 | AC37: Görüşüldü | AD37: 44418 | AE37: Görüşüldü | AF37: 44440 | AG37: Görüşüldü | AH37: 44480 | AI37: Görüşüldü | AJ37: 44635 | AK37: Sezer Arslan | AL37: Mertcan karaman | AM37: Ferhat Köksal | AN37: Ferhat Köksal | AO37: Ayşegül Kır | AP37: Sinem Koçak
A38: 62598b5ab1244c6188cf9899 | B38: Agah Restaurant, Seyhan (Kurtuluş Mah.) | C38: =VLOOKUP(A38,import!A:J,3,0) -> DOĞRU | D38: Kebap | E38: =VLOOKUP(A38,import!A:J,5,0) | F38: =VLOOKUP(A38,import!A:J,6,0) | G38: =VLOOKUP(A38,import!A:J,7,0) -> 0 | H38: =VLOOKUP(A38,import!A:J,8,0) -> 24 | I38: =VLOOKUP(A38,import!A:J,9,0) -> 24 | J38: =VLOOKUP(A38,import!A:J,10,0) -> 0 | K38: KADİR SİCİMOĞLU | L38: 3225039888 | M38: Seyhan | N38: Kurtuluş | O38: Kurtuluş mahallesi Ramazanoğlu caddesi 64003 sokak No:27/A Seyhan/ADANA | P38: =VLOOKUP(A38,import!A:P,16,0) -> Geleneksel | R38: FALSE | S38: FALSE
A39: 6063065cb71fbc0cc919823f | B39: Ağabey Döner (Yeşilyurt Mah. - İbo Osman Cad.) | C39: =VLOOKUP(A39,import!A:J,3,0) -> DOĞRU | D39: Döner | E39: =VLOOKUP(A39,import!A:J,5,0) -> 2420 | F39: =VLOOKUP(A39,import!A:J,6,0) -> 131 | G39: =VLOOKUP(A39,import!A:J,7,0) -> 6 | H39: =VLOOKUP(A39,import!A:J,8,0) -> 4 | I39: =VLOOKUP(A39,import!A:J,9,0) -> 10 | J39: =VLOOKUP(A39,import!A:J,10,0) -> 0.6 | K39: osman bayer | L39: 3222268444 | M39: Seyhan | N39: Yeşilyurt | O39: yeşilyurt mh iboosman cd küpeli apt no 137/E seyhan adana | P39: =VLOOKUP(A39,import!A:P,16,0) -> Geleneksel | R39: TRUE | S39: FALSE | T39: Randevu Alındı | U39: Derya Tatlı | V39: Berat Altunkaya | W39: 5444760172 | X39: 44384 | Y39: 44386 | AA39: Görüşüldü | AB39: 44384 | AK39: Derya Tatlı | AP39: Fulya Kortak
A40: 61a762f9e3548a519246b129 | B40: Ağabey Döner, Seyhan (Sümer Mah.) | C40: =VLOOKUP(A40,import!A:J,3,0) -> DOĞRU | D40: Döner | E40: =VLOOKUP(A40,import!A:J,5,0) -> 629 | F40: =VLOOKUP(A40,import!A:J,6,0) -> 8 | G40: =VLOOKUP(A40,import!A:J,7,0) -> 0 | H40: =VLOOKUP(A40,import!A:J,8,0) -> 6 | I40: =VLOOKUP(A40,import!A:J,9,0) -> 6 | J40: =VLOOKUP(A40,import!A:J,10,0) -> 0 | K40: ERCAN DOĞAN | L40: 3222261998 | M40: Seyhan | N40: Sümer | O40: sümer mah ibo osman cd seyhan adana | P40: =VLOOKUP(A40,import!A:P,16,0) -> Geleneksel | R40: TRUE | S40: FALSE | W40: yetkili 1 saate gelir dedi tekrar aranack | AP40: Fulya Kortak
...

Sheet import
A1: x | B1: Restoran Adı | C1: IsActive | D1: Mutfak | E1: TOPLAM SİPARİŞ | F1: SON 2 HAFTA | G1: RESİMLİ ÜRÜN | H1: RESİMSİZ ÜRÜN | I1: TOPLAM ÜRÜN | J1: Ratio | K1: Yetkili | L1: Telefon | M1: İLÇE | N1: MAHALLE | O1: ADRES | P1: Geleneksel Zincir | Q1: Eklendi mi
A2: 5fe4aac44669ba5a62461443 | B2: KFC, Seyhan (Yeni Mah.) | C2: DOĞRU | D2: Tavuk | E2: 12446 | F2: 318 | G2: 80 | H2: 1 | I2: 81 | J2: 0.99 | K2: Tamer Yılmaz | L2: 1111111111 | M2: Seyhan | N2: Yeni | O2: M1 Merkez AVM, Yeni Mahalle, No 15/70-A | P2: Key | Q2: =COUNTIF('hedef liste'!A:A,A2) -> 0
A3: 5fde53622ef1233c6d201c4b | B3: Kanatçı Ünal, Çukurova (Güzelyalı Mah. - Turgut Özal Blv.) | C3: DOĞRU | D3: Kebap | E3: 1162 | F3: 41 | G3: 3 | H3: 29 | I3: 32 | J3: 0.09 | K3: Ünal ildeniz | L3: 3222350515 | M3: Çukurova | N3: Güzelyalı | O3: Güzelyalı mah T. Özal bLV. İNCİEVLER SİT Bblok no :86/D Çukurova adana | P3: Geleneksel | Q3: =COUNTIF('hedef liste'!A:A,A3) -> 1
A4: 5fe0c327d108fca7a22c00ee | B4: Cihangir Kebap, Çukurova (Güzelyalı Mah.) | C4: DOĞRU | D4: Kebap | E4: 7339 | F4: 72 | G4: 0 | H4: 28 | I4: 28 | J4: 0 | K4: GÖKHAN KORKMAZ | L4: 5013306070 | M4: Çukurova | N4: Beyazevler | O4: güzelyalı mah devlet bahçeli bulv no41 a çukurova adana | P4: Geleneksel | Q4: =COUNTIF('hedef liste'!A:A,A4) -> 1
A5: 5feb3bc13458671b6a461b86 | B5: McDonald's, Çukurova (Güzelyalı Mah. Turgut Özal Blv.) | C5: DOĞRU | D5: Burger | E5: 15024 | F5: 375 | G5: 99 | H5: 0 | I5: 99 | J5: 1 | K5: Ömer Tarık Güney | L5: 2123363575 | M5: Çukurova | N5: Mahfesığmaz | O5: Turgut Özal Bulvarı, Güzelyalı Mah. Sefa Parlak Gümüş Apt Altı No:7-8 Çukurova / Adana | P5: Key | Q5: =COUNTIF('hedef liste'!A:A,A5) -> 0
A6: 5feba37b12a8508e73bbe362 | B6: McDonald's, Seyhan (Cemalpaşa Mah. Galleria) | C6: DOĞRU | D6: Burger | E6: 15459 | F6: 472 | G6: 95 | H6: 1 | I6: 96 | J6: 0.99 | K6: Ömer Tarık Güney | L6: 2123363575 | M6: Seyhan | N6: Cemalpaşa | O6: Fuzuli Cad. Galeria İş Mrk. Yanı No:16 Seyhan-Adana 01120 | P6: Key | Q6: =COUNTIF('hedef liste'!A:A,A6) -> 0
A7: 5feba9182ccf257497219882 | B7: McDonald's, Seyhan (Pınar Mah.) | C7: DOĞRU | D7: Burger | E7: 21177 | F7: 478 | G7: 99 | H7: 2 | I7: 101 | J7: 0.98 | K7: Ömer Tarık Güney | L7: 2123363575 | M7: Seyhan | N7: Pınar | O7: Pınar mah. Ali Bozdoğanoğlu Bulvarı No: 54/A Seyhan/Adana | P7: Key | Q7: =COUNTIF('hedef liste'!A:A,A7) -> 0
A8: 5fe5d2ed87a63b1f653166d1 | B8: Adana Tombiş Döner, Çukurova (Huzurevleri Mah.) | C8: DOĞRU | D8: Döner | E8: 7748 | F8: 228 | G8: 0 | H8: 45 | I8: 45 | J8: 0 | K8: abdullah uğar | L8: 3222420003 | M8: Çukurova | N8: Huzurevleri | O8: huzurevleri mah 77215 sok no6/d çukurova adana | P8: Geleneksel | Q8: =COUNTIF('hedef liste'!A:A,A8) -> 1
A9: 5fec67588365ab46508eb3d5 | B9: SoBig Burger,(Güzelyalı Mah. - Uğur Mumcu Blv.) | C9: DOĞRU | D9: Burger | E9: 3712 | F9: 214 | G9: 0 | H9: 35 | I9: 35 | J9: 0 | K9: serkan atabay | L9: 8507500999 | M9: Çukurova | N9: Güzelyalı | O9: Uğur Mumcu Blv. 11 B,Güzelyalı,01170, 01150 Çukurova adana | P9: Geleneksel | Q9: =COUNTIF('hedef liste'!A:A,A9) -> 1
A10: 5fece285e5886a237d949e21 | B10: Hamburgerci Mükerrem, Seyhan (Kurtuluş Mah.) | C10: DOĞRU | D10: Burger | E10: 574 | F10: 36 | G10: 6 | H10: 2 | I10: 8 | J10: 0.75 | K10: mustafa çiftçi | L10: 3224598008 | M10: Seyhan | N10: Kurtuluş | O10: kurtuluş mah şinasi efendi dk. no:25/b seyhan adana | P10: Geleneksel | Q10: =COUNTIF('hedef liste'!A:A,A10) -> 1
A11: 5ff752f0292a61f3e5b13ff8 | B11: Rengin Pastanesi, Çukurova (Güzelyalı Mah.) | C11: DOĞRU | D11: Pasta & Tatlı | E11: 8566 | F11: 282 | G11: 82 | H11: 27 | I11: 109 | J11: 0.75 | K11: özcan sergun gümüşay | L11: 5422356939 | M11: Çukurova | N11: Güzelyalı | O11: güzelyalı mah uğur mumcu bulvarı adana kule apt altı no:2/a çukurova adana | P11: Geleneksel | Q11: =COUNTIF('hedef liste'!A:A,A11) -> 1
A12: 5ffaf75b292a615149b1de90 | B12: Ahmet Yıldızoğlu Künefe, Seyhan (Pınar Mah.) | C12: DOĞRU | D12: Pasta & Tatlı | E12: 2445 | F12: 84 | G12: 27 | H12: 18 | I12: 45 | J12: 0.6 | K12: ibrahim üstün | L12: 3222255139 | M12: Seyhan | N12: Pınar | O12: pınar mha ali bozdoğanoğlu bulv. demirkol plaza 2 no:8/b seyhan adana | P12: Geleneksel | Q12: =COUNTIF('hedef liste'!A:A,A12) -> 1
A13: 5fe8f24e71e89c163c95f429 | B13: Pizza Taxi, Yüreğir (Kiremithane Mah.) | C13: DOĞRU | D13: Pizza | E13: 7033 | F13: 254 | G13: 10 | H13: 90 | I13: 100 | J13: 0.1 | K13: mehmet gencay onay | L13: 3228820882 | M13: Yüreğir | N13: Kiremithane | O13: kiremithane mah kazım barışık apt dadaloğlu bulv a blok no 44 yüreğir adana | P13: Geleneksel | Q13: =COUNTIF('hedef liste'!A:A,A13) -> 1
... A37: 5ffe02a3292a61819db25f49 | B37: Köse, Çukurova (Huzurevleri Mah.) | C37: DOĞRU | D37: Pasta & Tatlı | E37: 3647 | F37: 172 | G37: 7 | H37: 21 | I37: 28 | J37: 0.25 | K37: özkan tanrıverdi | L37: 5359770301 | M37: Çukurova | N37: Yurt | O37: huzurevleri mah kurttepe cd no:21 d:17 çukurova adana | P37: Geleneksel | Q37: =COUNTIF('hedef liste'!A:A,A37) -> 1
A38: 60019a0e97e0d62e97cbaed4 | B38: Komagene Etsiz Çiğ Köfte, Yüreğir (Kazım Karabekir Mah.) | C38: YANLIŞ | D38: Çiğ Köfte | E38: 193 | G38: 60 | H38: 4 | I38: 64 | J38: 0.94 | K38: Esra Gonca Parlar | L38: 5443500301 | M38: Yüreğir | N38: Kazım Karabekir | O38: KAZIM KARABEKİR MH. 4199 SK. NO:1 | P38: Key | Q38: =COUNTIF('hedef liste'!A:A,A38) -> 0
A39: 6001a23676b10d52aaca55f9 | B39: Komagene Etsiz Çiğ Köfte, Seyhan (Yeşiloba Mah.) | C39: DOĞRU | D39: Çiğ Köfte | E39: 1492 | F39: 30 | G39: 102 | H39: 4 | I39: 106 | J39: 0.96 | K39: Esra Gonca Parlar | L39: 5050156992 | M39: Seyhan | N39: Yeşiloba | O39: YEŞİLOBA MH. 46200 SK. NO:17 | P39: Key | Q39: =COUNTIF('hedef liste'!A:A,A39) -> 0
A40: 6001a4a10e7109c6729aab27 | B40: Komagene Etsiz Çiğ Köfte, Seyhan (Yeşilevler Mah.) | C40: DOĞRU | D40: Çiğ Köfte | E40: 1178 | F40: 39 | G40: 50 | H40: 3 | I40: 53 | J40: 0.94 | K40: Esra Gonca Parlar | L40: 5342265290 | M40: Seyhan | N40: Bahçelievler | O40: BAHÇELİEVLER MH. MEHMET AKİF ERSOY CD. NO:96/B | P40: Key | Q40: =COUNTIF('hedef liste'!A:A,A40) -> 0
A41: 6001b021675cf55af66d347f | B41: Komagene Etsiz Çiğ Köfte, Çukurova (Yüzüncü Yıl Mah.) | C41: DOĞRU | D41: Çiğ Köfte | E41: 1105 | F41: 45 | G41: 76 | H41: 2 | I41: 78 | J41: 0.97 | K41: Esra Gonca Parlar | L41: 5418214826 | M41: Çukurova | N41: Yüzüncüyıl | O41: YÜZÜNCÜ YIL MH. 85054 SK. NO:24/C | P41: Key | Q41: =COUNTIF('hedef liste'!A:A,A41) -> 0
A42: 5ffe23ee4a4dfa3a5caba607 | B42: 7/C Ocakbaşı Gazipaşa , Seyhan (Cemalpaşa Mah.) | C42: DOĞRU | D42: Kebap | E42: 4029 | F42: 35 | G42: 0 | H42: 75 | I42: 75 | J42: 0 | K42: soner sarp | L42: 3224546565 | M42: Seyhan | N42: Cemalpaşa | O42: cemalpaşa mah toros cad yeşil apt no:19/a seyhan adana | P42: Geleneksel | Q42: =COUNTIF('hedef liste'!A:A,A42) -> 1
A43: 6001aa02d0f3bab2a710138b | B43: Komagene Etsiz Çiğ Köfte, Çukurova (Mahfesığmaz Mah.) | C43: DOĞRU | D43: Çiğ Köfte | E43: 1075 | F43: 105 | G43: 39 | H43: 3 | I43: 42 | J43: 0.93 | K43: Esra Gonca Parlar | L43: 5449660405 | M43: Çukurova | N43: Mahfesığmaz | O43: MAHFESIĞMAZ MH. ŞEHİTLER BUL. GÜNEY GELİŞİM SİT. ALTI B BLOK APT NO:78/B | P43: Key | Q43: =COUNTIF('hedef liste'!A:A,A43) -> 0
A44: 6001b4447349b8cf2ec2140e | B44: Komagene Etsiz Çiğ Köfte, Yüreğir (Selahattin Eyyubi Mah.) | C44: DOĞRU | D44: Çiğ Köfte | E44: 3465 | F44: 74 | G44: 51 | H44: 3 | I44: 54 | J44: 0.94 | K44: Esra Gonca Parlar | L44: 5052112286 | M44: Yüreğir | N44: Dadaloğlu | O44: SELAHATTİN EYYUBİ MH.MUSTAFA KEMAL PAŞA BLV NO:123/B | P44: Key | Q44: =COUNTIF('hedef liste'!A:A,A44) -> 0
A45: 6001b7c75c726d3674f9a0ff | B45: Komagene Etsiz Çiğ Köfte, Seyhan (İbo Osman Cad.) | C45: DOĞRU | D45: Çiğ Köfte | E45: 10054 | F45: 351 | G45: 99 | H45: 11 | I45: 110 | J45: 0.9 | K45: Esra Gonca Parlar | L45: 3223290655 | M45: Seyhan | N45: Yeşilyurt | O45: SÜMER MH. İBO OSMAN CD. NO:210D | P45: Key | Q45: =COUNTIF('hedef liste'!A:A,A45) -> 0
A46: 6001d8ea57c431f7200349d1 | B46: Komagene Etsiz Çiğ Köfte, Çukurova (Barış Manço Blv.) | C46: DOĞRU | D46: Çiğ Köfte | E46: 3463 | F46: 76 | G46: 70 | H46: 6 | I46: 76 | J46: 0.92 | K46: Esra Gonca Parlar | L46: 5366098062 | M46: Çukurova | N46: Toros | O46: TOROS MH.78190 SK=9. MERCAN KEBAP KARŞISI BARIŞ MANÇO BLV. NO/28 D/1 | P46: Key | Q46: =COUNTIF('hedef liste'!A:A,A46) -> 0
A47: 6001dccea35105c54ef78134 | B47: Komagene Etsiz Çiğ Köfte, Çukurova (Belediye Evleri Mah.) | C47: DOĞRU | D47: Çiğ Köfte | E47: 3590 | F47: 154 | G47: 66 | H47: 6 | I47: 72 | J47: 0.92 | K47: Esra Gonca Parlar | L47: 5528384922 | M47: Çukurova | N47: Belediye Evleri | O47: BELEDİYE EVLERİ MAH.TURGUT ÖZAL BLV.NO:223 B | P47: Key | Q47: =COUNTIF('hedef liste'!A:A,A47) -> 0
A48: 6003132149bc3dbfaac9dbc8 | B48: Alaçatı Muhallebicisi , Çukurova (Mahfesığmaz Mah.) | C48: YANLIŞ | D48: Kahvaltı | E48: 84 | G48: 47 | H48: 18 | I48: 65 | J48: 0.72 | K48: önder çebiç | L48: 5447420101 | M48: Çukurova | N48: Mahfesığmaz | O48: mahfesığmaz mah turgut özal bulv no 79 b çukurova adana | P48: Geleneksel | Q48: =COUNTIF('hedef liste'!A:A,A48) -> 1
A49: 6004478c49bc3d4820c9f558 | B49: Kayabey Gaziantep Sofrası, Çukurova (Mahfesığmaz Mah.) | C49: DOĞRU | D49: Ev Yemekleri | E49: 3554 | F49: 114 | G49: 16 | H49: 12 | I49: 28 | J49: 0.57 | K49: isa kaya | L49: 3222350090 | M49: Çukurova | N49: Güzelyalı | O49: mahfesığmaz mah turgut özal blv no:113/a çukurova adana | P49: Geleneksel | Q49: =COUNTIF('hedef liste'!A:A,A49) -> 1
A50: 600478050d6f591a059c2f51 | B50: Ciğerci Ulaş,(Güzelyalı Mah. - Turgut Özal Blv.) | C50: DOĞRU | D50: Kebap | E50: 5492 | F50: 181 | G50: 35 | H50: 16 | I50: 51 | J50: 0.69 | K50: hüseyin kıstak | L50: 3222328486 | M50: Çukurova | N50: Güzelyalı | O50: güzelyalı mah turgut özal bulv akçeli 1 apt no:74/a çukurova adana | P50: Geleneksel | Q50: =COUNTIF('hedef liste'!A:A,A50) -> 1
A51: 6009aec80a0197ecc6f349e5 | B51: Tuffy's Road House, Seyhan (Reşatbey Mah.) | C51: DOĞRU | D51: Dünya Mutfağı | E51: 459 | F51: 35 | G51: 0 | H51: 88 | I51: 88 | J51: 0 | K51: AZİZ ERTEM | L51: 3224546354 | M51: Seyhan | N51: Reşatbey | O51: reşatbey mah.türkkuşu cad.bilgen apt altı no :32/B büyükşehir belediyesi cam bina yanı seyhan /ADANA | P51: Geleneksel | Q51: =COUNTIF('hedef liste'!A:A,A51) -> 1
A52: 600605867441fc14ff7f7c0a | B52: Fırat Cafe Pandora , Çukurova (Yurt Mah. - Turgut Özal Blv.) | C52: DOĞRU | D52: Döner | E52: 18194 | F52: 570 | G52: 27 | H52: 7 | I52: 34 | J52: 0.79 | K52: ferhat nizam | L52: 3222398595 | M52: Çukurova | N52: Yurt | O52: yurt mah turgut özal bulvarı no:178 / a çukurova adana | P52: Geleneksel | Q52: =COUNTIF('hedef liste'!A:A,A52) -> 1
A53: 5fe5c56d345867129a457093 | B53: Ayvalık Tostçusu, Seyhan (Sümer Mah. - Barajyolu) | C53: DOĞRU | D53: Tost & Sandviç | E53: 3459 | F53: 153 | G53: 0 | H53: 32 | I53: 32 | J53: 0 | K53: gökhan birdir | L53: 3222264654 | M53: Seyhan | N53: Yenibaraj | O53: yenibaraj mah 68046 sk dilek apt a blok no:3/f seyhan adana | P53: Geleneksel | Q53: =COUNTIF('hedef liste'!A:A,A53) -> 1
A54: 5fe5dd21f0267c6313124b8d | B54: Cajun Corner, Seyhan (Pınar Mah.) | C54: DOĞRU | D54: Tavuk | E54: 20663 | F54: 795 | G54: 26 | H54: 41 | I54: 67 | J54: 0.39 | K54: tunç karslı | L54: 5528720303 | M54: Seyhan | N54: Pınar | O54: pınar mah 74097 sok a blok no 3/c seyhan adana | P54: Geleneksel | Q54: =COUNTIF('hedef liste'!A:A,A54) -> 1
A55: 5fde8d7d856302162f54fbec | B55: Road Burger, Seyhan (Cemalpaşa Mah.) | C55: YANLIŞ | D55: Burger | E55: 3692 | G55: 13 | H55: 23 | I55: 36 | J55: 0.36 | K55: Mehmet Sayılık | L55: 5424757623 | M55: Seyhan | N55: Cemalpaşa | O55: cemalpaşa mah 63012 sok özdemir sit no 5/b seyhan adana | P55: Geleneksel | Q55: =COUNTIF('hedef liste'!A:A,A55) -> 1
A56: 5fde89ec0654ee84b2e89aa1 | B56: American Chicken Box, Seyhan (Cemalpaşa Mah.) | C56: YANLIŞ | D56: Tavuk | E56: 471 | G56: 2 | H56: 8 | I56: 10 | J56: 0.2 | K56: Mehmet Sayılık | L56: 5413808788 | M56: Seyhan | N56: Cemalpaşa | O56: cemalpaşa mah 63012 sok özdemir sit no 5/b seyhan adana | P56: Geleneksel | Q56: =COUNTIF('hedef liste'!A:A,A56) -> 1
A57: 5fe624e487a63b2b5b316d45 | B57: Kadayıfçı Olcay (Hanedan Mah.) | C57: DOĞRU | D57: Pasta & Tatlı | E57: 1291 | F57: 38 | G57: 8 | H57: 9 | I57: 17 | J57: 0.47 | K57: olcay tekin | L57: 3223653900 | M57: Seyhan | N57: Hanedan | O57: hanedan mah 35009 sok no:1 seyhan adana | P57: Geleneksel | Q57: =COUNTIF('hedef liste'!A:A,A57) -> 1
A58: 5fe0e758d3f42b1416aedfe0 | B58: Pizza Homemade Seyhan (Gürselpaşa Mah.) | C58: DOĞRU | D58: Pizza | E58: 2132 | F58: 29 | G58: 47 | H58: 45 | I58: 92 | J58: 0.51 | K58: Mehmet Ziya Akçay | L58: 3229994929 | M58: Seyhan | N58: Gürselpaşa | O58: gürselpaşa mah aliya izzet begoviç blv no 102/c seyhan adana | P58: Geleneksel | Q58: =COUNTIF('hedef liste'!A:A,A58) -> 1
A59: 5fe68863eeb85d4e34ccd650 | B59: Pakfırın, Seyhan (Kurtuluş Mah. - Ziyapaşa Blv.) | C59: DOĞRU | D59: Pasta & Tatlı | E59: 5156 | F59: 376 | G59: 42 | H59: 28 | I59: 70 | J59: 0.6 | K59: hatice akyıldız | L59: 5377605905 | M59: Seyhan | N59: Kurtuluş | O59: kurtulus mah ziyapaşa blv havuz apt a blok no :46/b seyhan adana | P59: Geleneksel | Q59: =COUNTIF('hedef liste'!A:A,A59) -> 1
A60: 5fe8f60d12a85080b9bb58d3 | B60: Ala Mezze, (Güzelyalı Mah. - Süleyman Demirel Blv.) | C60: DOĞRU | D60: Deniz Ürünleri | E60: 982 | F60: 35 | G60: 46 | H60: 15 | I60: 61 | J60: 0.75 | K60: savaş savaş | L60: 3224540407 | M60: Çukurova | N60: Güzelyalı | O60: güzelyalı mah süleyman demirel bulv no:19/e başer sitesi b blok çukurova adana | P60: Geleneksel | Q60: =COUNTIF('hedef liste'!A:A,A60) -> 1
A61: 5fe9001ba415e906823c1038 | B61: Tuil Cafe & Patiserrie (Yüzüncü Yıl Mah.) | C61: DOĞRU | D61: Pasta & Tatlı | E61: 2656 | F61: 27 | G61: 53 | H61: 39 | I61: 92 | J61: 0.58 | K61: oğuzhan çalımlı | L61: 3222660044 | M61: Çukurova | N61: Yüzüncüyıl | O61: yüzüncü yıl mah fazlı meto bulv baysallar apt 01360 çukurova adana | P61: Geleneksel | Q61: =COUNTIF('hedef liste'!A:A,A61) -> 1
A62: 5fe8e78af0267c8b9e1285a4 | B62: Helvacı Hello, Çukurova (Mahfesığmaz Mah.) | C62: DOĞRU | D62: Pasta & Tatlı | E62: 3619 | F62: 115 | G62: 16 | H62: 18 | I62: 34 | J62: 0.47 | K62: alican halme | L62: 5414060124 | M62: Çukurova | N62: Mahfesığmaz | O62: Mahfesığmaz Mah. Turgut Özal Blv. Abbas Bilir A Blok No:61 C Çukurova/Adana | P62: Geleneksel | Q62: =COUNTIF('hedef liste'!A:A,A62) -> 1
A63: 5fe8eeeba415e97d1f3c1006 | B63: Pizza Taxi, Çukurova (Yüzüncü Yıl Mah.) | C63: DOĞRU | D63: Pizza | E63: 8199 | F63: 270 | G63: 10 | H63: 92 | I63: 102 | J63: 0.1 | K63: gencay mehmet onay | L63: 3222564848 | M63: Çukurova | N63: Yüzüncüyıl | O63: yüzüncü yıl mah hacı bektaş veli blv. no:18-3a zemin 25 | P63: Geleneksel | Q63: =COUNTIF('hedef liste'!A:A,A63) -> 1
...

Sheet Durum Parametreler
C2: Başka Şubeden Çekilecek | H2: Mertcan
C3: BlackList | F3: Nazmi Okbaz | H3: Enes
A4: 44197 | C4: Çekim İstemiyor | F4: Berat Altunkaya | H4: Ezgi Turan
A5: 44198 | C5: Devir | F5: Nurattin Yücesoy | H5: Hatem Soyaslan
A6: 44199 | C6: Dönüş Yapacak | F6: Abdulhenan Doğan | H6: Zeliha Özer
A7: 44200 | C7: Franchise | F7: Yakup Koçoğlu | H7: Emre Dalgıç
A8: 44201 | C8: İleride Randevu Alınacak | H8: Gül Değirmenci
A9: 44202 | C9: Lokasyon Uzak | H9: Yurdagül Kulaksız
A10: 44203 | C10: Haziran'da Aranacak | F10: Hemen Randevu İstiyorum | H10: Ayfer Altın
A11: 44204 | C11: Menü Güncellemesi Yapılacak | F11: Fotoğraflarım Var | H11: Ayşegül Kır
A12: 44205 | C12: Personel Eksik | F12: İleride Randevu İstiyorum | H12: Damla Kılcı
A13: 44206 | C13: Randevu Alındı | H13: Özlem arslan
A14: 44207 | C14: Randevu İptal | H14: Beyza gülşah
A15: 44208 | C15: Restoran Silindi | H15: Özlem gümüş
A16: 44209 | C16: Sistemden Çıkmak İstiyor | F16: Ayşegül Kır | H16: Tuğba Buyur
A17: 44210 | C17: Tadilat Var | F17: Betül Demir | H17: Kadriye Polat
A18: 44211 | C18: Ulaşılamadı | F18: Hatem Soyaslan | H18: Şükriye Demir
A19: 44212 | C19: Yılbaşından Sonra Aranacak | F19: Selcan Topçu | H19: Ece Bayındır
A20: 44213 | F20: Sude Alkan | H20: Senanur Çınar
A21: 44214 | C21: Dönüş Yapacak | F21: Yurdagül Kulaksız | H21: Şura Özcan
A22: 44215 | C22: Görüşüldü | F22: Zeliha Özer | H22: Funda Ünlü
A23: 44216 | C23: Tekrar Aranacak | F23: Ferhat Köksal | H23: Sıla Göksunaz Esen
A24: 44217 | C24: Ulaşılamadı | F24: Enes Günal | H24: Emel Yılmaz
A25: 44218 | C25: Yetkili Yok | F25: Serap Apaydın | H25: Ecem Ersöz
A26: 44219 | H26: Livanur Elibol
A27: 44220 | H27: Eda Cıbır
A28: 44221 | C28: Randevu Alınabilir | H28: Meryem Yalabık
A29: 44222 | C29: Çekim İstemiyor | H29: Serenay Yalabık
A30: 44223 | C30: Fotoğrafları Yok - Randevu Alınabilir
A31: 44224 | C31: Fotoğrafları Gönderecek
A32: 44225
A33: 44226
A34: 44227
A35: 44228
A36: 44229
A37: 44230
A38: 44231
A39: 44232
A40: 44233
A41: 44234
...

Sheet özet
G4: Tarih | H4: Başarılı Randevu | I4: İptal Randevu | J4: Top. Rest | K4: =COUNTIFS(import!$C:$C,"true",import!$P:$P,"Geleneksel") -> 0 | O4: İptal Randevu | P4: Fotoğraflandırılan Top. Ürün | Q4: Fotoğraflandırılan Ort. Ürün
B5: Başka Şubeden Çekilecek | C5: =COUNTIFS('hedef liste'!T:T,B5,'hedef liste'!C:C,"doğru",'hedef liste'!P:P,"Geleneksel",'hedef liste'!J:J,"=0%") -> 7 | D5: toplam rest | E5: =COUNTIFS(import!C:C,"doğru",import!P:P,"Geleneksel") -> 964 | J5: Fotoğraflı | K5: =COUNTIFS(import!$C:$C,"true",import!$P:$P,"Geleneksel",import!$J:$J,">0%") -> 0 | M5: =$K$5/$K$4 -> #DIV/0!
B6: BlackList | C6: =COUNTIFS('hedef liste'!T:T,B6,'hedef liste'!C:C,"doğru",'hedef liste'!P:P,"Geleneksel",'hedef liste'!J:J,"=0%") -> 1 | D6: fotoğraflı | E6: =COUNTIFS(import!C:C,"doğru",import!P:P,"Geleneksel",import!J:J,">0%") -> 512
B7: Çekim İstemiyor | C7: =COUNTIFS('hedef liste'!T:T,B7,'hedef liste'!C:C,"doğru",'hedef liste'!P:P,"Geleneksel",'hedef liste'!J:J,"=0%") -> 54 | D7: % | E7: =E6/E5 -> 0.53112033 | J7: Ürün Adet | K7: 0-25 | M7: 25+ | S7: İptal Oranı
B8: Devir | C8: =COUNTIFS('hedef liste'!T:T,B8,'hedef liste'!C:C,"doğru",'hedef liste'!P:P,"Geleneksel",'hedef liste'!J:J,"=0%") -> 2 | J8: Fotoğraflı | K8: =COUNTIFS(import!$C:$C,"true",import!$J:$J,">0%",import!$P:$P,"Geleneksel",import!$I:$I,"<=25") -> 0 | L8: =K8/K5 -> #DIV/0! | M8: =COUNTIFS(import!C:C,"true",import!J:J,">0%",import!P:P,"Geleneksel",import!I:I,">25") -> 0 | N8: =M8/K5 -> #DIV/0! | S8: =O13/N13 -> #DIV/0!
B9: Dönüş Yapacak | C9: =COUNTIFS('hedef liste'!T:T,B9,'hedef liste'!C:C,"doğru",'hedef liste'!P:P,"Geleneksel",'hedef liste'!J:J,"=0%") -> 19 | J9: 0-20% | K9: =COUNTIFS(import!C:C,"true",import!J:J,">0%",import!J:J,"<=20%",import!P:P,"Geleneksel",import!I:I,"<=25") -> 0 | L9: =K9/K8 -> #DIV/0! | M9: =COUNTIFS(import!C:C,"true",import!J:J,">0%",import!J:J,"<=20%",import!P:P,"Geleneksel",import!I:I,">25") -> 0 | N9: =M9/M8 -> #DIV/0!
