Workbook

Sheet Hedef Liste
A1: Restaurant ID | B1: Restoran Adı | C1: Satışa Açık Mı? | D1: Mutfak | E1: TOPLAM SİPARİŞ | F1: SON 2 HAFTA | G1: RESİMLİ ÜRÜN | H1: RESİMSİZ ÜRÜN | I1: TOPLAM ÜRÜN | J1: Ratio | K1: Yetkili | L1: Telefon | M1: İLÇE | N1: MAHALLE | O1: ADRES | P1: Geleneksel Zincir | Q1: FOTOĞRAF SEGMENT | R1: Aradık Mı? | S1: Kendi Fotosu Var | T1: Randevu Durumu | U1: Randevu Alan | V1: Fotoğrafçı | W1: Not | X1: Randevu Alma Tarihi | Y1: Randevu Tarihi | Z1: Anket Durum | AA1: 1. Arama | AB1: 1. Arama Tarihi | AC1: 2. Arama | AD1: 2. Arama Tarihi | AE1: 3. Arama | AF1: 3. Arama Tarihi | AG1: 4. Arama | AH1: 4. Arama Tarihi | AI1: 5. Arama | AJ1: 5. Arama Tarihi | AK1: 1. Arayan | AL1: 2. Arayan | AM1: 3. Arayan | AN1: 4. Arayan | AO1: 5. Arayan | AP1: SY | AQ1: SY - Durum
A2: 605e04551a40c448083875ad | B2: 07 Gizem Döner, Muratpaşa (Kızılsaray Mah.) | C2: =VLOOKUP(A2,import!A:C,3,0) -> DOĞRU | D2: Döner | E2: =VLOOKUP(A2,import!A:J,5,0) -> 1316 | F2: =VLOOKUP(A2,import!A:J,6,0) -> 111 | G2: =VLOOKUP(A2,import!A:J,7,0) -> 16 | H2: =VLOOKUP(A2,import!A:J,8,0) -> 2 | I2: =VLOOKUP(A2,import!A:J,9,0) -> 18 | J2: =VLOOKUP(A2,import!A:J,10,0) -> 0.89 | K2: UĞUR SÜRMELİOĞLU | L2: 5317162173 | M2: Muratpaşa | N2: Kışla | O2: Kızılsaray Mah. Milli Egemenlik Cad. No:1 Muratpaşa/ANTALYA | P2: =VLOOKUP(A2,import!A:P,16,0) -> Geleneksel | R2: TRUE | S2: FALSE | T2: Randevu Alındı | U2: Hatem Soyaslan | V2: Önder Örtel | W2: TEYİT İÇİN ARANDI ÇEKİM GERÇEKLEŞMİŞ | X2: 44344 | Y2: 44348 | AP2: Aşur Can Acar
A3: 623c21c9b7d66ecf1749936e | B3: 07 Manavgat Döner, Manavgat (A. Pazarcı Mah.) | C3: =VLOOKUP(A3,import!A:C,3,0) -> DOĞRU | D3: Döner | E3: =VLOOKUP(A3,import!A:J,5,0) -> 17 | F3: =VLOOKUP(A3,import!A:J,6,0) -> 11 | G3: =VLOOKUP(A3,import!A:J,7,0) -> 0 | H3: =VLOOKUP(A3,import!A:J,8,0) -> 13 | I3: =VLOOKUP(A3,import!A:J,9,0) -> 13 | J3: =VLOOKUP(A3,import!A:J,10,0) -> 0 | K3: Murat Şenol | L3: 5013583038 | M3: Manavgat | N3: A. Pazarcı | O3: A. Pazarcı Mah. 1003 Sk. No:6/Z10 Manavgat/Antalya | P3: =VLOOKUP(A3,import!A:P,16,0) -> Geleneksel | R3: FALSE | S3: FALSE
A4: 61aa1ee50e81ea78c09b2df1 | B4: 07 Midye, Kepez (Yeşiltepe Mah.) | C4: =VLOOKUP(A4,import!A:C,3,0) -> DOĞRU | D4: Sokak Lezzetleri | E4: =VLOOKUP(A4,import!A:J,5,0) -> 12 | F4: =VLOOKUP(A4,import!A:J,6,0) -> 6 | G4: =VLOOKUP(A4,import!A:J,7,0) -> 10 | H4: =VLOOKUP(A4,import!A:J,8,0) -> 11 | I4: =VLOOKUP(A4,import!A:J,9,0) -> 21 | J4: =VLOOKUP(A4,import!A:J,10,0) -> 0.48 | K4: GÜLHAN BAHADIR | L4: 5510848751 | M4: Kepez | N4: Yeşiltepe | O4: Yeşiltepe Mah. Ziya Gökalp Cad. No:4 Kepez/ANTALYA | P4: =VLOOKUP(A4,import!A:P,16,0) -> Geleneksel | R4: TRUE | S4: FALSE | T4: Randevu Alındı | U4: Kübra Toprak | V4: Ahmet Balcı | W4: ömer beyden randevu alındı. | X4: 44539 | Y4: 44539 | AA4: Görüşüldü | AB4: 44539 | AK4: Kübra Toprak | AP4: Aşur Can Acar
A5: 6220ac01fa2e0f4112053b24 | B5: 07 Mola Kafe, Muratpaşa (Yüksekalan Mah.) | C5: =VLOOKUP(A5,import!A:C,3,0) -> DOĞRU | D5: Tost & Sandviç | E5: =VLOOKUP(A5,import!A:J,5,0) -> 37 | F5: =VLOOKUP(A5,import!A:J,6,0) -> 24 | G5: =VLOOKUP(A5,import!A:J,7,0) -> 10 | H5: =VLOOKUP(A5,import!A:J,8,0) -> 5 | I5: =VLOOKUP(A5,import!A:J,9,0) -> 15 | J5: =VLOOKUP(A5,import!A:J,10,0) -> 0.67 | K5: MEHMET KAZAR | L5: 5076681213 | M5: Muratpaşa | N5: Yüksekalan | O5: Yüksekalan Mah. Fahrettin Altay Cad. No:26/F Muratpasa/Antalya | P5: =VLOOKUP(A5,import!A:P,16,0) -> Geleneksel | R5: TRUE | S5: FALSE | T5: Randevu Alındı | U5: Hatem Soyaslan | V5: Ahmet Balcı | X5: 44627 | Y5: 44628 | AA5: Görüşüldü | AB5: 44627 | AK5: Hatem Soyaslan
A6: 60cf56e24876bb5c61b9c1d3 | B6: 1. Nesil Sokak Lezzetleri, Muratpaşa (Sinan Mah.) | C6: =VLOOKUP(A6,import!A:C,3,0) -> YANLIŞ | D6: Sokak Lezzetleri | E6: =VLOOKUP(A6,import!A:J,5,0) -> 3 | F6: =VLOOKUP(A6,import!A:J,6,0) | G6: =VLOOKUP(A6,import!A:J,7,0) -> 0 | H6: =VLOOKUP(A6,import!A:J,8,0) -> 10 | I6: =VLOOKUP(A6,import!A:J,9,0) -> 10 | J6: =VLOOKUP(A6,import!A:J,10,0) -> 0 | K6: MEHMET VOLKAN ALICI | L6: 5303281402 | M6: Muratpaşa | N6: Sinan | O6: Sinan Mah. Cebesoy Cd. No:18/B Muratpaşa/Antalya | P6: =VLOOKUP(A6,import!A:P,16,0) -> Geleneksel | R6: TRUE | S6: FALSE | T6: Çekim İstemiyor | W6: taciz boyutuna geçti yeter aramayı istemiyorum hergün hergün arıyorsunuz dediler/açmadı.kesinlikle istemiyorum bidaha ararsanız getiri kapattıracam dedi. | AA6: Görüşüldü | AB6: 44377 | AC6: Tekrar Aranacak | AD6: 44379 | AE6: Görüşüldü | AF6: 44404 | AG6: Görüşüldü | AH6: 44413 | AI6: Görüşüldü | AJ6: 44417 | AK6: Nurhayat Kabataş | AL6: Nurhayat Kabataş | AM6: Hatem Soyaslan | AN6: Mavi aslan | AO6: Deneme | AP6: Korcan Işık
A7: 6050635acd69790dd4c21dbf | B7: 10'LAR Makarna, Muratpaşa (Çağlayan Mah.) | C7: =VLOOKUP(A7,import!A:C,3,0) -> DOĞRU | D7: Dünya Mutfağı | E7: =VLOOKUP(A7,import!A:J,5,0) -> 125 | F7: =VLOOKUP(A7,import!A:J,6,0) -> 2 | G7: =VLOOKUP(A7,import!A:J,7,0) -> 0 | H7: =VLOOKUP(A7,import!A:J,8,0) -> 8 | I7: =VLOOKUP(A7,import!A:J,9,0) -> 8 | J7: =VLOOKUP(A7,import!A:J,10,0) -> 0 | K7: HASİBE DUMAN | L7: 5527471010 | M7: Muratpaşa | N7: Çağlayan | O7: Çağlayan Mah. 2007 Sk. No:9/2 Muratpaşa/Antalya | P7: =VLOOKUP(A7,import!A:P,16,0) -> Geleneksel | R7: TRUE | S7: FALSE | T7: Çekim İstemiyor | W7: DİĞER ŞUBEDEKİ ÜRÜNLER MAKARNA DEĞİL ARKADAŞLAR, UYMUYOR FOTOĞRAFLAR O YÜZDEN YÜKLEYEMİYORUZ // 5322980224 istemiyor/haftaya salı randevu için aranacak/diğer şubesine çekim yapılmış eksik fotoğrafları var/şuan müsait zamnları yokmuş daha sonra dönüş yapılcak/yarım saat sonra aranacak. istiyor fakat çok yoğunlarmış daha sonra arayacak./ çok yoğunlarmış şuan düşünmüyorlarmış.//yarım saat sonra dönüş yapayım dedi/Ben size dönüş sağlarım dedi hatem hanımın numarası verildi.//istemiyorum çok yoğun tşk dedi / vakti uokmuş istemedi / hiç müsait değilim deyip suratıma kapattı | AA7: Görüşüldü | AB7: 44356 | AC7: Tekrar Aranacak | AD7: 44370 | AE7: Tekrar Aranacak | AF7: 44384 | AG7: Görüşüldü | AH7: 44391 | AI7: Görüşüldü | AJ7: 44700 | AK7: Nazmiye Yuka | AL7: Derya Tatlı | AM7: Derya Tatlı | AN7: Hatem Soyaslan | AO7: Betül Demir | AP7: Korcan Işık
A8: 5fd4b735eceda3aae41e35cc | B8: 10LAR Food'n Beverage, Muratpaşa (Çağlayan Mah.) | C8: =VLOOKUP(A8,import!A:C,3,0) -> DOĞRU | D8: Kahvaltı | E8: =VLOOKUP(A8,import!A:J,5,0) -> 1827 | F8: =VLOOKUP(A8,import!A:J,6,0) -> 64 | G8: =VLOOKUP(A8,import!A:J,7,0) -> 33 | H8: =VLOOKUP(A8,import!A:J,8,0) -> 14 | I8: =VLOOKUP(A8,import!A:J,9,0) -> 47 | J8: =VLOOKUP(A8,import!A:J,10,0) -> 0.7 | K8: HASİBE DUMAN | L8: 5527471010 | M8: Muratpaşa | N8: Çağlayan | O8: Çağlayan Mah. 2007 Sk. No:9/2 Muratpaşa/Antalya | P8: =VLOOKUP(A8,import!A:P,16,0) -> Geleneksel | Q8: 35+ | R8: TRUE | S8: FALSE | T8: Randevu Alındı | U8: Serap Apaydın | V8: Önder Örtel | W8: devam alındı | X8: 44546 | Y8: 44552 | AA8: Tekrar Aranacak | AB8: 44385 | AC8: Ulaşılamadı | AD8: 44413 | AE8: Görüşüldü | AF8: 44421 | AG8: Görüşüldü | AH8: 44546 | AK8: Simge Tüçay | AL8: Mavi aslan | AM8: Mavi aslan | AN8: Serap Apaydın | AP8: Korcan Işık
A9: 6155e3833a59d98e3530dc6c | B9: 112 Pizza, Kepez (Kültür Mah.) | C9: =VLOOKUP(A9,import!A:C,3,0) -> DOĞRU | D9: Pizza | E9: =VLOOKUP(A9,import!A:J,5,0) -> 846 | F9: =VLOOKUP(A9,import!A:J,6,0) -> 110 | G9: =VLOOKUP(A9,import!A:J,7,0) -> 16 | H9: =VLOOKUP(A9,import!A:J,8,0) -> 58 | I9: =VLOOKUP(A9,import!A:J,9,0) -> 74 | J9: =VLOOKUP(A9,import!A:J,10,0) -> 0.22 | K9: FATİME ÖZER | L9: 2422269595 | M9: Kepez | N9: Kültür | O9: Kültür, Ulusoy Cd. 25/A, 07090 Bahtılı Köyü Köyü/Kepez/Antalya | P9: =VLOOKUP(A9,import!A:P,16,0) -> Geleneksel | R9: TRUE | S9: FALSE | T9: Randevu Alındı | W9: hatalı no / geçen haftya çekim oldu diyor | AA9: Ulaşılamadı | AB9: 44487 | AC9: Görüşüldü | AD9: 44491 | AK9: Sude Alkan | AL9: Betül Demir | AP9: Kutluhan Peker
A10: 6155e3123592bcc6f753a29a | B10: 112 Pizza, Muratpaşa (Mehmetçik Mah.) | C10: =VLOOKUP(A10,import!A:C,3,0) -> DOĞRU | D10: Pizza | E10: =VLOOKUP(A10,import!A:J,5,0) -> 207 | F10: =VLOOKUP(A10,import!A:J,6,0) -> 7 | G10: =VLOOKUP(A10,import!A:J,7,0) -> 15 | H10: =VLOOKUP(A10,import!A:J,8,0) -> 60 | I10: =VLOOKUP(A10,import!A:J,9,0) -> 75 | J10: =VLOOKUP(A10,import!A:J,10,0) -> 0.2 | K10: FATİME ÖZER | L10: 2422269595 | M10: Muratpaşa | N10: Mehmetçik | O10: Mehmetçik Mah. Termesos Bulv. No:23 Muratpaşa/ANTALYA | P10: =VLOOKUP(A10,import!A:P,16,0) -> Geleneksel | R10: TRUE | S10: FALSE | T10: Başka Şubeden Çekilecek | W10: pizza momo manias panelınde cekım yapmısız | AA10: Görüşüldü | AB10: 44483 | AK10: Tuğba Buyur | AP10: Aşur Can Acar
A11: 5fa43ee1b82e0eafcfc65e03 | B11: 1453 Çorbacı Edo (Kültür Mah.) | C11: =VLOOKUP(A11,import!A:C,3,0) -> YANLIŞ | D11: Köfte | E11: =VLOOKUP(A11,import!A:J,5,0) -> 911 | F11: =VLOOKUP(A11,import!A:J,6,0) | G11: =VLOOKUP(A11,import!A:J,7,0) -> 16 | H11: =VLOOKUP(A11,import!A:J,8,0) -> 14 | I11: =VLOOKUP(A11,import!A:J,9,0) -> 30 | J11: =VLOOKUP(A11,import!A:J,10,0) -> 0.53 | K11: Şeyma Demir | L11: 5384844336 | M11: Kepez | N11: Kültür | O11: Kültür Mah. 3821 Sk. Birlik Apt. No:36/32 | P11: =VLOOKUP(A11,import!A:P,16,0) -> Geleneksel | Q11: 26-35 | R11: TRUE | S11: FALSE | T11: Randevu Alındı | U11: Derya Tatlı | V11: Önder Örtel | W11: yetkili yok | X11: 44363 | Y11: 44365 | AA11: Görüşüldü | AB11: 44363 | AC11: Görüşüldü | AD11: 44516 | AK11: Derya Tatlı | AL11: Zeliha Özer | AP11: Kutluhan Peker
A12: 5fa4408eb3982c27aba0317f | B12: 1453 Köfteci Edo (Kültür Mah.) | C12: =VLOOKUP(A12,import!A:C,3,0) -> YANLIŞ | D12: Köfte | E12: =VLOOKUP(A12,import!A:J,5,0) -> 487 | F12: =VLOOKUP(A12,import!A:J,6,0) | G12: =VLOOKUP(A12,import!A:J,7,0) -> 8 | H12: =VLOOKUP(A12,import!A:J,8,0) -> 6 | I12: =VLOOKUP(A12,import!A:J,9,0) -> 14 | J12: =VLOOKUP(A12,import!A:J,10,0) -> 0.57 | K12: Şeyma Demir | L12: 5384844336 | M12: Kepez | N12: Kültür | O12: Kültür mah. 3844 sk. No:4/2 | P12: =VLOOKUP(A12,import!A:P,16,0) -> Geleneksel | Q12: 16-25 | R12: TRUE | S12: FALSE | T12: Randevu Alındı | U12: Derya Tatlı | V12: Önder Örtel | W12: yetkili yok | X12: 44363 | Y12: 44365 | AA12: Görüşüldü | AB12: 44516 | AK12: Zeliha Özer | AP12: Kutluhan Peker
A13: 6220b734e9fa38820650c4ff | B13: 1453 Köfteci Edo, Konyaaltı (Kuşkavağı Mah.) | C13: =VLOOKUP(A13,import!A:C,3,0) -> DOĞRU | D13: Köfte | E13: =VLOOKUP(A13,import!A:J,5,0) -> 5 | F13: =VLOOKUP(A13,import!A:J,6,0) -> 2 | G13: =VLOOKUP(A13,import!A:J,7,0) -> 0 | H13: =VLOOKUP(A13,import!A:J,8,0) -> 19 | I13: =VLOOKUP(A13,import!A:J,9,0) -> 19 | J13: =VLOOKUP(A13,import!A:J,10,0) -> 0 | K13: Şeyma Demir | L13: 5384844336 | M13: Konyaaltı | N13: Kuşkavağı | O13: Kuşkavağı Mah. 563 Sk. No 13 | P13: =VLOOKUP(A13,import!A:P,16,0) -> Geleneksel | R13: FALSE | S13: FALSE
A14: 5fb5377921cc6b7202d19053 | B14: 3070 Fit Mutfak (Şirinyalı Mah.) | C14: =VLOOKUP(A14,import!A:C,3,0) -> DOĞRU | D14: Ev Yemekleri | E14: =VLOOKUP(A14,import!A:J,5,0) -> 438 | F14: =VLOOKUP(A14,import!A:J,6,0) -> 23 | G14: =VLOOKUP(A14,import!A:J,7,0) -> 15 | H14: =VLOOKUP(A14,import!A:J,8,0) -> 26 | I14: =VLOOKUP(A14,import!A:J,9,0) -> 41 | J14: =VLOOKUP(A14,import!A:J,10,0) -> 0.37 | K14: AYTAÇ YÜRELİ | L14: 2429993767 | M14: Muratpaşa | N14: Şirinyalı | O14: Şirinyalı Mah. 1507 Sk. No:55/1 PK:07160 Lara Muratpaşa/Antalya | P14: =VLOOKUP(A14,import!A:P,16,0) -> Geleneksel | Q14: 35+ | R14: TRUE | S14: TRUE | W14: 05324757471:emre bey//antalya yetkilisiyle bu konuyla alakalı görüştük dha sonra onu planlıycaz dedi/MEŞGUL//açmadı //ö.s arayın lütfen dedi.//05324033028aytaç bey fotoğraflarının olduğunu söyledi mail adresi verildi fotoğrafları gönderim sağlayacak. | AA14: Ulaşılamadı | AB14: 44370 | AC14: Tekrar Aranacak | AD14: 44392 | AE14: Görüşüldü | AF14: 44412 | AK14: Hatice Özer | AL14: Gül Değirmenci | AM14: Deneme | AP14: Korcan Işık
A15: 5fbff3a10868bb759a19b68f | B15: 32 Kardelen Pide & Kebap (Ahatlı Mah.) | C15: =VLOOKUP(A15,import!A:C,3,0) -> DOĞRU | D15: Pide | E15: =VLOOKUP(A15,import!A:J,5,0) -> 3061 | F15: =VLOOKUP(A15,import!A:J,6,0) -> 249 | G15: =VLOOKUP(A15,import!A:J,7,0) -> 0 | H15: =VLOOKUP(A15,import!A:J,8,0) -> 37 | I15: =VLOOKUP(A15,import!A:J,9,0) -> 37 | J15: =VLOOKUP(A15,import!A:J,10,0) -> 0 | K15: Mehmet Bilgiç | L15: 2425020191 | M15: Kepez | N15: Kültür | O15: Ahatlı Mah. Ulusoy Cad. No:48 B | P15: =VLOOKUP(A15,import!A:P,16,0) -> Geleneksel | Q15: 26-35 | R15: TRUE | S15: TRUE | T15: Çekim İstemiyor | W15: kendisi çekip atacak telefon çekimi yapacakmış ürün çıkaramam maliyeti çok dedi 05356386674 - / açılış saati 11:00 / ürünleri çıktıkça gönderecek / öğle ara / ben şuan çekim istemiyorum dedi | AA15: Görüşüldü | AB15: 44442 | AC15: Görüşüldü | AD15: 44391 | AE15: Tekrar Aranacak | AF15: 44405 | AG15: Görüşüldü | AH15: 44503 | AI15: Görüşüldü | AJ15: 44545 | AK15: Ferhat Köksal | AL15: Hatem Soyaslan | AM15: Tutku Erdoğan | AN15: Betül Demir | AO15: Betül Demir | AP15: Kutluhan Peker
A16: 60eb620248bb3778d7b6c370 | B16: 3Tek Meze, Konyaaltı (Öğretmenevleri Mah.) | C16: =VLOOKUP(A16,import!A:C,3,0) -> YANLIŞ | D16: Dünya Mutfağı | E16: =VLOOKUP(A16,import!A:J,5,0) -> 230 | F16: =VLOOKUP(A16,import!A:J,6,0) | G16: =VLOOKUP(A16,import!A:J,7,0) -> 24 | H16: =VLOOKUP(A16,import!A:J,8,0) -> 6 | I16: =VLOOKUP(A16,import!A:J,9,0) -> 30 | J16: =VLOOKUP(A16,import!A:J,10,0) -> 0.8 | K16: Ayçin Say | L16: 2422303300 | M16: Konyaaltı | N16: Akkuyu | O16: Öğretmenevleri, Ata aprt, Anadolu Cd D:No:98 | P16: =VLOOKUP(A16,import!A:P,16,0) -> Geleneksel | R16: TRUE | S16: TRUE | T16: Randevu Alındı | U16: Adem Sezer | W16: yarın aranıp cuma gününe randevu alınacak//devam çekimi için alıcaz | X16: 44435 | Y16: 44438 | AA16: Görüşüldü | AB16: 44414 | AC16: Görüşüldü | AD16: 44429 | AE16: Görüşüldü | AF16: 44435 | AK16: Mavi aslan | AL16: Mertcan karaman | AM16: Adem Sezer | AP16: Kutluhan Peker
A17: 61de231b91e3f03a9b35c9bb | B17: 42 Konyalı Kardeşler Lezzet Diyarı, Kepez (Yeşilyurt Mah.) | C17: =VLOOKUP(A17,import!A:C,3,0) -> DOĞRU | D17: Pide | E17: =VLOOKUP(A17,import!A:J,5,0) -> 740 | F17: =VLOOKUP(A17,import!A:J,6,0) -> 102 | G17: =VLOOKUP(A17,import!A:J,7,0) -> 0 | H17: =VLOOKUP(A17,import!A:J,8,0) -> 37 | I17: =VLOOKUP(A17,import!A:J,9,0) -> 37 | J17: =VLOOKUP(A17,import!A:J,10,0) -> 0 | K17: AHMET CENGİZ | L17: 2422276757 | M17: Kepez | N17: Yeşilyurt | O17: Yeşilyurt Mah. 4340 Sk. No:3 | P17: =VLOOKUP(A17,import!A:P,16,0) -> Geleneksel | R17: TRUE | S17: TRUE | W17: fotağraflrı varmış mail atacak | AA17: Görüşüldü | AB17: 44587 | AK17: Betül Demir
A18: 60800082df4d78e747ed4bc3 | B18: 42 Konyalılar Etli Ekmek Dünyası, Manavgat (Aşağı Pazarcı Mah.) | C18: =VLOOKUP(A18,import!A:C,3,0) -> DOĞRU | D18: Pide | E18: =VLOOKUP(A18,import!A:J,5,0) -> 496 | F18: =VLOOKUP(A18,import!A:J,6,0) -> 27 | G18: =VLOOKUP(A18,import!A:J,7,0) -> 0 | H18: =VLOOKUP(A18,import!A:J,8,0) -> 43 | I18: =VLOOKUP(A18,import!A:J,9,0) -> 43 | J18: =VLOOKUP(A18,import!A:J,10,0) -> 0 | K18: HASAN KAŞ | L18: 5528020742 | M18: Manavgat | N18: A. Pazarcı | O18: A. Pazarcı Mah. Zübeyde Hanım Cad. No:12/B Manavgat/Antalya | P18: =VLOOKUP(A18,import!A:P,16,0) -> Geleneksel | R18: TRUE | S18: FALSE | T18: Çekim İstemiyor | W18: şuanlık hiç gerek yok der / yetkili yok 1 saat sonra aranacak | AA18: Görüşüldü | AB18: 44484 | AC18: Yetkili Yok | AD18: 44497 | AE18: Görüşüldü | AF18: 44503 | AK18: Hatem Soyaslan | AL18: Betül Demir | AM18: Betül Demir | AP18: Korcan Işık
A19: 5f9dd61e4f83057cc7f7bc32 | B19: 55 Samsun Pide (Liman Mah.) | C19: =VLOOKUP(A19,import!A:C,3,0) -> DOĞRU | D19: Pide | E19: =VLOOKUP(A19,import!A:J,5,0) -> 389 | F19: =VLOOKUP(A19,import!A:J,6,0) -> 8 | G19: =VLOOKUP(A19,import!A:J,7,0) -> 0 | H19: =VLOOKUP(A19,import!A:J,8,0) -> 21 | I19: =VLOOKUP(A19,import!A:J,9,0) -> 21 | J19: =VLOOKUP(A19,import!A:J,10,0) -> 0 | K19: Şehri Yıldırım | L19: 2422594217 | M19: Konyaaltı | N19: Liman | O19: Liman mah. Atatürk Bulv. Çınar Apt. No: 204 /B | P19: =VLOOKUP(A19,import!A:P,16,0) -> Geleneksel | Q19: 16-25 | R19: TRUE | S19: TRUE | W19: mail atacak.fotoğraflar için arandı müsait değillermiş. / haftaya fotoğraf işi ile ilgileneceğim dedi | AA19: Tekrar Aranacak | AB19: 44405 | AC19: Görüşüldü | AD19: 44582 | AK19: Betül Demir | AP19: Kutluhan Peker
A20: 5f50ebae3b7b0542315c9763 | B20: 55 Samsun Pide & Pizza, Güzeloba | C20: =VLOOKUP(A20,import!A:C,3,0) -> DOĞRU | D20: Pide | E20: =VLOOKUP(A20,import!A:J,5,0) -> 1735 | F20: =VLOOKUP(A20,import!A:J,6,0) -> 70 | G20: =VLOOKUP(A20,import!A:J,7,0) -> 12 | H20: =VLOOKUP(A20,import!A:J,8,0) -> 57 | I20: =VLOOKUP(A20,import!A:J,9,0) -> 69 | J20: =VLOOKUP(A20,import!A:J,10,0) -> 0.17 | K20: MEHMET KARAKUŞ | L20: 2423497353 | M20: Muratpaşa | N20: Güzeloba | O20: Güzeloba, Havaalanı Cd. No:38/D, 07230 Muratpaşa/Antalya | P20: =VLOOKUP(A20,import!A:P,16,0) -> Geleneksel | Q20: 35+ | R20: TRUE | S20: TRUE | W20: fotoğraf göndercek teyit için arandı fotografı varmış ama 10 tanesiin sadece onları yükleyecek sonrasında bi arayacagaız hala digerlerini yüklememişse yeni bi randevu oluşturcaz//Unutmuş fotografları tekrar mail verildi atacak.yarım saat sonra tekrar aranacak.fotoğraflar için arandı mail adresi verildi ben fotoğrafları bugün gönderirim dedi.-bır ıkı saate aranacak/yetkili yok dedirtti dönüş yapacakmış./ MAİL VERİLDİ / yetkili | AA20: Ulaşılamadı | AB20: 44385 | AC20: Tekrar Aranacak | AD20: 44386 | AE20: Tekrar Aranacak | AF20: 44389 | AG20: Görüşüldü | AH20: 44403 | AI20: Görüşüldü | AJ20: 44499 | AK20: Simge Tüçay | AL20: Eylem Ünal | AM20: Nurhayat Kabataş | AN20: Hatem Soyaslan | AO20: Betül Demir | AP20: Korcan Işık
A21: 6077fbc8574496e4d14b8889 | B21: 61 Hamsi Tava, Muratpaşa (12.Cadde) | C21: =VLOOKUP(A21,import!A:C,3,0) -> YANLIŞ | D21: Balık & Deniz Ürünleri | E21: =VLOOKUP(A21,import!A:J,5,0) -> 53 | F21: =VLOOKUP(A21,import!A:J,6,0) | G21: =VLOOKUP(A21,import!A:J,7,0) -> 0 | H21: =VLOOKUP(A21,import!A:J,8,0) -> 38 | I21: =VLOOKUP(A21,import!A:J,9,0) -> 38 | J21: =VLOOKUP(A21,import!A:J,10,0) -> 0 | K21: ALİ KARTAL | L21: 2422376161 | M21: Muratpaşa | N21: Meydankavağı | O21: Meydankavağı Mah. İsmail Cem Cad. No:56 Muratpaşa/ANTALYA | P21: =VLOOKUP(A21,import!A:P,16,0) -> Geleneksel | R21: TRUE | S21: TRUE | W21: 2 saat sonra tekrar arancak/açmadı//açmadı/no verildi fotoğraf kontrolü yapıp dönecekler/yarın müsait olurlarsa randevu için arayacaklar yoksa ertesi gün aranacak//mail verildi fotoğrafları.atacakyukarıdakiyle aynı ama frklıürünleri varmış orayı arayın dedi.fotoğraflar için arandı müsait değillermiş daha sonra tekrar aranacak.-12 gibi aranacak/ | AA21: Görüşüldü | AB21: 44356 | AC21: Görüşüldü | AD21: 44362 | AE21: Görüşüldü | AF21: 44389 | AG21: Tekrar Aranacak | AH21: 44405 | AI21: Yetkili Yok | AJ21: 44442 | AK21: Nazmiye Yuka | AL21: Simge Tüçay | AM21: Nurhayat Kabataş | AN21: Hatem Soyaslan | AO21: Ferhat Köksal | AP21: Korcan Işık
A22: 5fbe2833a9c8365e72adad31 | B22: 63 Ervan Urfa Sofrası (Pınarbaşı Mah.) | C22: =VLOOKUP(A22,import!A:C,3,0) -> DOĞRU | D22: Kebap | E22: =VLOOKUP(A22,import!A:J,5,0) -> 505 | F22: =VLOOKUP(A22,import!A:J,6,0) -> 3 | G22: =VLOOKUP(A22,import!A:J,7,0) -> 0 | H22: =VLOOKUP(A22,import!A:J,8,0) -> 33 | I22: =VLOOKUP(A22,import!A:J,9,0) -> 33 | J22: =VLOOKUP(A22,import!A:J,10,0) -> 0 | K22: Recep Çevik | L22: 2422286307 | M22: Konyaaltı | N22: Pınarbaşı | O22: Pınarbaşı Mah. Pınarbaşı Cad. No:10 | P22: =VLOOKUP(A22,import!A:P,16,0) -> Geleneksel | Q22: 26-35 | R22: TRUE | S22: TRUE | T22: Çekim İstemiyor | U22: Enes | V22: Kaan Soytürk | W22: tekrar randevu istemiyor/şuan sıkıntı olurmuş ürünleride çöpe atamam dedi / YETKİLİ / ürünler kışın pek olmuyor iki klaem çıkıyoer anca dedi kendisi yemeksepetinden alıp gönderecek | X22: 44271 | Y22: 44274 | AA22: Görüşüldü | AB22: 44363 | AC22: Ulaşılamadı | AD22: 44439 | AE22: Görüşüldü | AF22: 44508 | AG22: Görüşüldü | AH22: 44573 | AI22: Görüşüldü | AJ22: 44573 | AK22: Derya Tatlı | AL22: Ferhat Köksal | AM22: Betül Demir | AN22: Serap Apaydın | AP22: Kutluhan Peker
A23: 5f5f4128f2f31e3210c66429 | B23: 7 Köfte & Et, Muratpaşa (Şirinyalı Mah.) | C23: =VLOOKUP(A23,import!A:C,3,0) -> DOĞRU | D23: Kebap | E23: =VLOOKUP(A23,import!A:J,5,0) -> 5084 | F23: =VLOOKUP(A23,import!A:J,6,0) -> 259 | G23: =VLOOKUP(A23,import!A:J,7,0) -> 0 | H23: =VLOOKUP(A23,import!A:J,8,0) -> 98 | I23: =VLOOKUP(A23,import!A:J,9,0) -> 98 | J23: =VLOOKUP(A23,import!A:J,10,0) -> 0 | K23: ALİ ÖZTÜRK | L23: 2423160581 | M23: Muratpaşa | N23: Şirinyalı | O23: Şirinyalı, Kurt Apt, İsmet Gökşen Cd. 63/A, 07160 Muratpaşa/Antalya | P23: =VLOOKUP(A23,import!A:P,16,0) -> Geleneksel | Q23: 35+ | R23: TRUE | S23: TRUE | W23: 2 hafta sonra tekrar aranacak//mail atacak// RESİMLER HENÜZ ELİME ULAŞMADI RANDEVU DA ÇOK YOĞUNUM DİYE İSTEMİYOR BEN SİZE DÖNÜŞ SAĞLAYACAĞIM DEDİ.eylül 15 ten sonra arancak-2 saat sonra gelir dedi- vakit ayıramam dedi çekim istemiyor / fotoğraflar için yetkili gelince dönüş sağlayacak | AA23: Dönüş Yapacak | AB23: 44370 | AC23: Tekrar Aranacak | AD23: 44389 | AE23: Yetkili Yok | AF23: 44442 | AG23: Görüşüldü | AH23: 44469 | AI23: Dönüş Yapacak | AJ23: 44567 | AK23: Hatice Özer | AL23: Nurhayat Kabataş | AM23: Ferhat Köksal | AN23: Ferhat Köksal | AO23: Betül Demir | AP23: Korcan Işık
A24: 5f55e7921fcf335b6c81b7bb | B24: A + New Concept Pide (Çağlayan Mah.) | C24: =VLOOKUP(A24,import!A:C,3,0) -> DOĞRU | D24: Pide | E24: =VLOOKUP(A24,import!A:J,5,0) -> 633 | F24: =VLOOKUP(A24,import!A:J,6,0) -> 22 | G24: =VLOOKUP(A24,import!A:J,7,0) -> 0 | H24: =VLOOKUP(A24,import!A:J,8,0) -> 39 | I24: =VLOOKUP(A24,import!A:J,9,0) -> 39 | J24: =VLOOKUP(A24,import!A:J,10,0) -> 0 | K24: ABDULLAH KORAL DEMİRAL | L24: 2423230002 | M24: Muratpaşa | N24: Çağlayan | O24: Çağlayan Mah, Nazlı Apt, Bülent Ecevit Blv. D:No:123, 07230 Muratpaşa/Antalya | P24: =VLOOKUP(A24,import!A:P,16,0) -> Geleneksel | Q24: 35+ | R24: TRUE | S24: TRUE | W24: müsait değil daha sonra tekrar aranacak.//açmadı//yetk yok ama biz öyle bir şey düşünmüyoruz dedi / MAİLE ATACAK | AA24: Görüşüldü | AB24: 44391 | AC24: Görüşüldü | AD24: 44393 | AE24: Tekrar Aranacak | AF24: 44405 | AG24: Yetkili Yok | AH24: 44411 | AI24: Görüşüldü | AJ24: 44499 | AK24: Gül Değirmenci | AL24: Mavi Arslan | AM24: Hatem Soyaslan | AN24: Edanur Türkkan | AO24: Betül Demir | AP24: Korcan Işık
A25: 5f4f4d1e0f8c874fbdfd8514 | B25: A + New Concept Pide, Muratpaşa (Güzeloba Mah.) | C25: =VLOOKUP(A25,import!A:C,3,0) -> DOĞRU | D25: Pide | E25: =VLOOKUP(A25,import!A:J,5,0) -> 332 | F25: =VLOOKUP(A25,import!A:J,6,0) -> 8 | G25: =VLOOKUP(A25,import!A:J,7,0) -> 0 | H25: =VLOOKUP(A25,import!A:J,8,0) -> 30 | I25: =VLOOKUP(A25,import!A:J,9,0) -> 30 | J25: =VLOOKUP(A25,import!A:J,10,0) -> 0 | K25: ABDULLAH KORAL DEMİRAL | L25: 2423230002 | M25: Muratpaşa | N25: Güzeloba | O25: Güzeloba Mah. 2114 Sok. No:6/A Muratpaşa/Antalya | P25: =VLOOKUP(A25,import!A:P,16,0) -> Geleneksel | Q25: 35+ | R25: TRUE | S25: TRUE | W25: açıyor ama ses gelmiyor//AÇMADI / yetkili yok daha sonra arancak.numara meşgul. / MAİLE ATACAK | AA25: Ulaşılamadı | AB25: 44370 | AC25: Yetkili Yok | AD25: 44391 | AE25: Tekrar Aranacak | AF25: 44392 | AG25: Tekrar Aranacak | AH25: 44403 | AI25: Ulaşılamadı | AJ25: 44405 | AK25: Hatice Özer | AL25: Hatem Soyaslan | AM25: Nurhayat Kabataş | AN25: Hatem Soyaslan | AO25: Hatem Soyaslan | AP25: Korcan Işık
A26: 615c15ebdd546e2c61e709ff | B26: A la Dantel Köfteli Lezzetler (Fener Mah.) | C26: =VLOOKUP(A26,import!A:C,3,0) -> DOĞRU | D26: Köfte | E26: =VLOOKUP(A26,import!A:J,5,0) -> 66 | F26: =VLOOKUP(A26,import!A:J,6,0) -> 4 | G26: =VLOOKUP(A26,import!A:J,7,0) -> 23 | H26: =VLOOKUP(A26,import!A:J,8,0) -> 6 | I26: =VLOOKUP(A26,import!A:J,9,0) -> 29 | J26: =VLOOKUP(A26,import!A:J,10,0) -> 0.79 | K26: DİDEM TANRIKULU | L26: 2429990170 | M26: Muratpaşa | N26: Fener | O26: FENER MAH. BÜLENT ECEVİT BLV ALTAY APT. NO: 13/A | P26: =VLOOKUP(A26,import!A:P,16,0) -> Geleneksel | R26: TRUE | S26: TRUE | W26: MAİL VERILDİ - çalmıyor telefon | AA26: Görüşüldü | AB26: 44487 | AC26: Ulaşılamadı | AD26: 44495 | AK26: Selcan Topçu | AL26: Ferhat Köksal | AP26: Korcan Işık
A27: 60fe55409d8c89474ec87e9f | B27: A La Vita Burger, Muratpaşa (Fener Mah.) | C27: =VLOOKUP(A27,import!A:C,3,0) -> DOĞRU | D27: Burger | E27: =VLOOKUP(A27,import!A:J,5,0) -> 173 | F27: =VLOOKUP(A27,import!A:J,6,0) -> 7 | G27: =VLOOKUP(A27,import!A:J,7,0) -> 0 | H27: =VLOOKUP(A27,import!A:J,8,0) -> 12 | I27: =VLOOKUP(A27,import!A:J,9,0) -> 12 | J27: =VLOOKUP(A27,import!A:J,10,0) -> 0 | K27: GÜLAY EREN TOYRAN | L27: 5453245550 | M27: Muratpaşa | N27: Çağlayan | O27: Fener Mah. Fener Cad. Lal Sitesi A Blok 45 A/A Muratpaşa/Antalya | P27: =VLOOKUP(A27,import!A:P,16,0) -> Geleneksel | R27: TRUE | S27: FALSE | T27: BlackList | W27: suratıma kapatıyor// terbiyesiz | AA27: Görüşüldü | AB27: 44417 | AK27: Hatem Soyaslan | AP27: Korcan Işık
A28: 5fa2ffcb3c0fb55fae0659b9 | B28: A La Vita Pizza, Fener | C28: =VLOOKUP(A28,import!A:C,3,0) -> DOĞRU | D28: Pizza | E28: =VLOOKUP(A28,import!A:J,5,0) -> 336 | F28: =VLOOKUP(A28,import!A:J,6,0) -> 24 | G28: =VLOOKUP(A28,import!A:J,7,0) -> 0 | H28: =VLOOKUP(A28,import!A:J,8,0) -> 37 | I28: =VLOOKUP(A28,import!A:J,9,0) -> 37 | J28: =VLOOKUP(A28,import!A:J,10,0) -> 0 | K28: GÜLAY EREN TOYRAN | L28: 5453245550 | M28: Muratpaşa | N28: Çağlayan | O28: Fener Mah. Fener Cad. Lal Sitesi A Blok 45 A/A Muratpaşa/Antalya | P28: =VLOOKUP(A28,import!A:P,16,0) -> Geleneksel | Q28: 35+ | R28: TRUE | S28: FALSE | T28: BlackList | W28: terbiyesizce tersliyo/tersliyor hemen | AA28: Ulaşılamadı | AB28: 44356 | AC28: Görüşüldü | AD28: 44383 | AE28: Görüşüldü | AF28: 44414 | AK28: Nazmiye Yuka | AL28: Nurhayat Kabataş | AM28: Tuğba Buyur | AP28: Korcan Işık
A29: 619505c41370ebac2143190f | B29: A Little Cook & Coffee (Fener Mah.) | C29: =VLOOKUP(A29,import!A:C,3,0) -> DOĞRU | D29: Dünya Mutfağı | E29: =VLOOKUP(A29,import!A:J,5,0) -> 23 | F29: =VLOOKUP(A29,import!A:J,6,0) | G29: =VLOOKUP(A29,import!A:J,7,0) -> 0 | H29: =VLOOKUP(A29,import!A:J,8,0) -> 18 | I29: =VLOOKUP(A29,import!A:J,9,0) -> 18 | J29: =VLOOKUP(A29,import!A:J,10,0) -> 0 | K29: SEDA URAL | L29: 5332478286 | M29: Muratpaşa | N29: Fener | O29: Fener mahallesi.Bülent ecevit bulvarı.No:1937 sokak.No:47/B Muratpaşa/Antalya | P29: =VLOOKUP(A29,import!A:P,16,0) -> Geleneksel | R29: TRUE | S29: FALSE | T29: Tadilat Var | W29: cevapsız/tadılat var kapalı suan | AA29: Ulaşılamadı | AB29: 44533 | AC29: Ulaşılamadı | AD29: 44537 | AE29: Ulaşılamadı | AF29: 44544 | AG29: Görüşüldü | AH29: 44618 | AK29: Ayşegül Kır | AL29: Sude Alkan | AM29: Ayşegül Kır | AN29: Selcan Topçu | AP29: Korcan Işık
A30: 603385f4fbe5053573aa8079 | B30: Abaküs Cafe & Food, Kepez (Kültür Mah.) | C30: =VLOOKUP(A30,import!A:C,3,0) -> DOĞRU | D30: Tost & Sandviç | E30: =VLOOKUP(A30,import!A:J,5,0) -> 4541 | F30: =VLOOKUP(A30,import!A:J,6,0) -> 52 | G30: =VLOOKUP(A30,import!A:J,7,0) -> 11 | H30: =VLOOKUP(A30,import!A:J,8,0) -> 76 | I30: =VLOOKUP(A30,import!A:J,9,0) -> 87 | J30: =VLOOKUP(A30,import!A:J,10,0) -> 0.13 | K30: GİZEM AVŞAR | L30: 5348129499 | M30: Kepez | N30: Kültür | O30: Kültür Mah. 3816 Sk. No:20/A Kepez/Antalya | P30: =VLOOKUP(A30,import!A:P,16,0) -> Geleneksel | Q30: 26-35 | R30: TRUE | S30: FALSE | T30: Randevu Alındı | U30: Derya Tatlı | V30: Önder Örtel | W30: devam çekimi için müsait değillermiş | X30: 44371 | Y30: 44376 | AA30: Ulaşılamadı | AB30: 44361 | AC30: Görüşüldü | AD30: 44371 | AE30: Tekrar Aranacak | AF30: 44405 | AG30: Ulaşılamadı | AH30: 44439 | AI30: Görüşüldü | AJ30: 44484 | AK30: Nazmiye Yuka | AL30: Derya Tatlı | AM30: Tutku Erdoğan | AN30: Ferhat Köksal | AO30: Ayşegül Kır | AP30: Kutluhan Peker
A31: 602bbbb87b6e5c92a2783860 | B31: Abalı Tavuk & Kebap & Kokoreç, Kepez (Avni Tolunay Mah.) | C31: =VLOOKUP(A31,import!A:C,3,0) -> DOĞRU | D31: Döner | E31: =VLOOKUP(A31,import!A:J,5,0) -> 210 | F31: =VLOOKUP(A31,import!A:J,6,0) -> 8 | G31: =VLOOKUP(A31,import!A:J,7,0) -> 0 | H31: =VLOOKUP(A31,import!A:J,8,0) -> 59 | I31: =VLOOKUP(A31,import!A:J,9,0) -> 59 | J31: =VLOOKUP(A31,import!A:J,10,0) -> 0 | K31: Özgür Kahraman | L31: 2422270902 | M31: Kepez | N31: Avni Tolunay | O31: Avni Tolunay, Mahallesi, Hürriyet Cd. No:402 | P31: =VLOOKUP(A31,import!A:P,16,0) -> Geleneksel | Q31: 35+ | R31: TRUE | S31: FALSE | T31: Randevu Alındı | U31: Emre Dalgıç | V31: Engin Akyurt | W31: TEYİT İÇİN ARANDI ÇEKİM hakkında bilgi alamdım öfkeliydi-fotografların hepsi çekildi | X31: 44291 | Y31: 44293 | AA31: Görüşüldü | AB31: 44227 | AC31: Ulaşılamadı | AD31: 44574 | AK31: Ferhat Köksal | AL31: Betül Demir | AP31: Aşur Can Acar
A32: 6149c34e8cfa1e4c2d0364fd | B32: Abim Restaurant, Muratpaşa (Dutlubahçe Mah.) | C32: =VLOOKUP(A32,import!A:C,3,0) -> DOĞRU | D32: Kebap | E32: =VLOOKUP(A32,import!A:J,5,0) -> 509 | F32: =VLOOKUP(A32,import!A:J,6,0) -> 55 | G32: =VLOOKUP(A32,import!A:J,7,0) -> 13 | H32: =VLOOKUP(A32,import!A:J,8,0) -> 15 | I32: =VLOOKUP(A32,import!A:J,9,0) -> 28 | J32: =VLOOKUP(A32,import!A:J,10,0) -> 0.46 | K32: İBRAHİM HALİL ÇETİN | L32: 2423465353 | M32: Muratpaşa | N32: Dutlubahçe | O32: Dutlubahçe Mah. 761 sk. No:7 Muratpaşa/ANTALYA | P32: =VLOOKUP(A32,import!A:P,16,0) -> Geleneksel | R32: TRUE | S32: FALSE | T32: Randevu Alındı | U32: Betül Demir | V32: Ahmet Balcı | W32: kendileri dönüş yapacaklar daHA ÖNCE RANDEVU OLUSTURULMUS ÇEKİM GERÇEKLEŞMEMİS FOTOGRAFCININ NUMARASI DA VARMIS | X32: 44491 | Y32: 44552 | AA32: Görüşüldü | AB32: 44469 | AC32: Görüşüldü | AD32: 44491 | AE32: Görüşüldü | AF32: 44511 | AG32: Dönüş Yapacak | AH32: 44512 | AK32: Ferhat Köksal | AL32: Betül Demir | AM32: Kübra Toprak | AN32: Kübra Toprak | AP32: Aşur Can Acar
A33: 605888cd3abb06da3733c8e9 | B33: Abla Gözleme & Tost, Muratpaşa (Varlık Mah.) | C33: =VLOOKUP(A33,import!A:C,3,0) -> DOĞRU | D33: Tost & Sandviç | E33: =VLOOKUP(A33,import!A:J,5,0) -> 1236 | F33: =VLOOKUP(A33,import!A:J,6,0) -> 87 | G33: =VLOOKUP(A33,import!A:J,7,0) -> 13 | H33: =VLOOKUP(A33,import!A:J,8,0) -> 27 | I33: =VLOOKUP(A33,import!A:J,9,0) -> 40 | J33: =VLOOKUP(A33,import!A:J,10,0) -> 0.33 | K33: KÜBRA ARAZ | L33: 5374311280 | M33: Muratpaşa | N33: Varlık | O33: Varlık Mah. 100. Yıl Blv. No:91 Muratpaşa/Antalya | P33: =VLOOKUP(A33,import!A:P,16,0) -> Geleneksel | R33: TRUE | S33: FALSE | T33: Randevu Alındı | U33: Şura Özcan | V33: Ahmet Can Mülayim | W33: adres değişikliği not alındı//tüm ürünler çekilmiş | X33: 44291 | Y33: 44293 | AP33: Korcan Işık
A34: 5f5f3ad04686128c2ac969ef | B34: Abooby Food & Drink, Muratpaşa (Sinan Mah.) | C34: =VLOOKUP(A34,import!A:C,3,0) -> DOĞRU | D34: Burger | E34: =VLOOKUP(A34,import!A:J,5,0) -> 2871 | F34: =VLOOKUP(A34,import!A:J,6,0) -> 100 | G34: =VLOOKUP(A34,import!A:J,7,0) -> 1 | H34: =VLOOKUP(A34,import!A:J,8,0) -> 29 | I34: =VLOOKUP(A34,import!A:J,9,0) -> 30 | J34: =VLOOKUP(A34,import!A:J,10,0) -> 0.03 | K34: BAHADIR ÜNAL | L34: 5528113272 | M34: Muratpaşa | N34: Haşimişcan | O34: Sinan Mah. 1255 Sk. Avcıoğlu İşhanı No:3/D Muratpaşa/Antalya | P34: =VLOOKUP(A34,import!A:P,16,0) -> Geleneksel | Q34: 16-25 | R34: TRUE | S34: FALSE | T34: İleride Randevu Alınacak | W34: fotoğrafların paylaşılmayacağı için istemedi kendim çekip yollarım dedi//telefon kapalı//hala kapalı/ antalyada hava durumu yağışlı olduğu için randevu alınamadı yağış olmadığı gün tekrar alınacak | AA34: Ulaşılamadı | AB34: 44356 | AC34: Ulaşılamadı | AD34: 44377 | AE34: Ulaşılamadı | AF34: 44386 | AG34: Ulaşılamadı | AH34: 44389 | AI34: Tekrar Aranacak | AJ34: 44571 | AK34: Nazmiye Yuka | AL34: Nazmiye Yuka | AM34: Eylem Ünal | AN34: Nurhayat Kabataş | AO34: Hatem Soyaslan | AP34: Korcan Işık
A35: 5fc8b6f396d4c483f6cb3ea9 | B35: Abra Kebap & Fast Food (Ahatlı Mah.) | C35: =VLOOKUP(A35,import!A:C,3,0) -> DOĞRU | D35: Kebap | E35: =VLOOKUP(A35,import!A:J,5,0) -> 276 | F35: =VLOOKUP(A35,import!A:J,6,0) -> 3 | G35: =VLOOKUP(A35,import!A:J,7,0) -> 0 | H35: =VLOOKUP(A35,import!A:J,8,0) -> 16 | I35: =VLOOKUP(A35,import!A:J,9,0) -> 16 | J35: =VLOOKUP(A35,import!A:J,10,0) -> 0 | K35: Murat Öziç | L35: 5395546272 | M35: Kepez | N35: Ahatlı | O35: Ahatlı Mah. Ulıusoy Cad. Ptt No:36/C Kepez/Antalya | P35: =VLOOKUP(A35,import!A:P,16,0) -> Geleneksel | Q35: 26-35 | R35: TRUE | S35: FALSE | T35: Başka Şubeden Çekilecek | U35: Serap Apaydın | V35: Ahmet Balcı | W35: Yetkili yarım saate gelir/yetkili şuan yok//10dk sonra aranacak//ulaşılmıyor//yetkili yok pakete gitti 10 dkya gelir dediler// numara servis dışı/no geçiciolark kapalı //açmadı / açılış saati 17:00 | X35: 44533 | Y35: 44536 | AA35: Ulaşılamadı | AB35: 44348 | AC35: Ulaşılamadı | AD35: 44362 | AE35: Ulaşılamadı | AF35: 44405 | AG35: Ulaşılamadı | AH35: 44411 | AI35: Görüşüldü | AJ35: 44533 | AK35: Derya Tatlı | AL35: Nazmiye Yuka | AM35: Tutku Erdoğan | AN35: Ravza Eğilmez | AO35: Serap Apaydın | AP35: Kutluhan Peker
A36: 5fd71eaa2d7fe332e563af53 | B36: Abu Sivas Pide & Köfte, Muratpaşa (Güzeloba Mah.) | C36: =VLOOKUP(A36,import!A:C,3,0) -> DOĞRU | D36: Pide | E36: =VLOOKUP(A36,import!A:J,5,0) -> 68 | F36: =VLOOKUP(A36,import!A:J,6,0) | G36: =VLOOKUP(A36,import!A:J,7,0) -> 0 | H36: =VLOOKUP(A36,import!A:J,8,0) -> 29 | I36: =VLOOKUP(A36,import!A:J,9,0) -> 29 | J36: =VLOOKUP(A36,import!A:J,10,0) -> 0 | K36: FEYRUZ KAYA | L36: 2423490758 | M36: Muratpaşa | N36: Güzeloba | O36: Güzeloba Mah. 2253 Sk. No:11/A Muratpaşa/Antalya | P36: =VLOOKUP(A36,import!A:P,16,0) -> Geleneksel | Q36: 26-35 | R36: TRUE | S36: FALSE | T36: Sistemden Çıkmak İstiyor | W36: feyruz beyin ortağıyla konuştum serkan bey o öğleden sonra gelecek o zaman ara/getirle problemleri varmış eğer hallorusa düşünecek/getir yemeği aktif kullanmıyolarmış2 saat sonra gelirmiş feyruz bey // feyruz beyin olmadığı söylendi.feyruz bey cok gelmezmiş. ö.s aransın ortagı ile görüşülsün sorunlar ögrenilsin genel merkeze iletilsin. / GETİRİ KULLANMIYORMUŞ | AA36: Görüşüldü | AB36: 44356 | AC36: Tekrar Aranacak | AD36: 44389 | AE36: Ulaşılamadı | AF36: 44391 | AG36: Görüşüldü | AH36: 44392 | AI36: Görüşüldü | AJ36: 44491 | AK36: Nazmiye Yuka | AL36: Nurhayat Kabataş | AM36: Hatem Soyaslan | AN36: Nurhayat Kabataş | AO36: Betül Demir | AP36: Korcan Işık
A37: 5fbb907a34703f31dac198c4 | B37: Acı Tantuni (Sinan Mah.) | C37: =VLOOKUP(A37,import!A:C,3,0) -> DOĞRU | D37: Sokak Lezzetleri | E37: =VLOOKUP(A37,import!A:J,5,0) -> 1511 | F37: =VLOOKUP(A37,import!A:J,6,0) -> 39 | G37: =VLOOKUP(A37,import!A:J,7,0) -> 7 | H37: =VLOOKUP(A37,import!A:J,8,0) -> 3 | I37: =VLOOKUP(A37,import!A:J,9,0) -> 10 | J37: =VLOOKUP(A37,import!A:J,10,0) -> 0.7 | K37: MURAT ACI | L37: 2422447464 | M37: Muratpaşa | N37: Sinan | O37: Sinan Mah. 1251 Sk. Atatürk Cad. No:4 Muratpaşa/Antalya | P37: =VLOOKUP(A37,import!A:P,16,0) -> Geleneksel | Q37: 0-15 | R37: TRUE | S37: FALSE | T37: Randevu Alındı | U37: Hatem Soyaslan | V37: Ahmet Can Mülayim | W37: teyit için arandı çekim gerçekleşti | X37: 44343 | Y37: 44347 | AP37: Korcan Işık
A38: 603bb54f7c87b48dacaffb51 | B38: Acıktım Izgara, Kaş (Kalkan Mah.) | C38: =VLOOKUP(A38,import!A:C,3,0) -> DOĞRU | D38: Kahvaltı | E38: =VLOOKUP(A38,import!A:J,5,0) -> 284 | F38: =VLOOKUP(A38,import!A:J,6,0) -> 7 | G38: =VLOOKUP(A38,import!A:J,7,0) -> 0 | H38: =VLOOKUP(A38,import!A:J,8,0) -> 85 | I38: =VLOOKUP(A38,import!A:J,9,0) -> 85 | J38: =VLOOKUP(A38,import!A:J,10,0) -> 0 | K38: MEHMET KÜÇÜKKAYA | L38: 2428442796 | M38: Kaş | N38: Kalkan | O38: Akasya sokak no:5 Kalkan mah/Kaş/Antalya | P38: =VLOOKUP(A38,import!A:P,16,0) -> Geleneksel | Q38: 35+ | R38: FALSE | S38: FALSE | AP38: Kutluhan Peker
A39: 5f5f4252356069484db33453 | B39: Acıktım Sivas Pide & Köfte, Muratpaşa (Şirinyalı Mah.) | C39: =VLOOKUP(A39,import!A:C,3,0) -> DOĞRU | D39: Pide | E39: =VLOOKUP(A39,import!A:J,5,0) -> 530 | F39: =VLOOKUP(A39,import!A:J,6,0) -> 15 | G39: =VLOOKUP(A39,import!A:J,7,0) -> 29 | H39: =VLOOKUP(A39,import!A:J,8,0) -> 9 | I39: =VLOOKUP(A39,import!A:J,9,0) -> 38 | J39: =VLOOKUP(A39,import!A:J,10,0) -> 0.76 | K39: ERDAL BULUT | L39: 2423170758 | M39: Muratpaşa | N39: Şirinyalı | O39: Şirinyalı mah. 1523 sk. Durhan apt. 10/A ANTALYA, 07180 Muratpaşa/Antalya | P39: =VLOOKUP(A39,import!A:P,16,0) -> Geleneksel | Q39: 35+ | R39: TRUE | S39: FALSE | T39: Randevu Alındı | U39: Hatem Soyaslan | V39: Ahmet Balcı | W39: 5523100758 | X39: 44496 | Y39: 44497 | AA39: Görüşüldü | AB39: 44349 | AC39: Yetkili Yok | AD39: 44356 | AE39: Görüşüldü | AF39: 44383 | AG39: Görüşüldü | AH39: 44496 | AI39: Görüşüldü | AJ39: 44424 | AK39: Derya Tatlı | AL39: Nazmiye Yuka | AM39: Nurhayat Kabataş | AN39: Hatem Soyaslan | AO39: Ravza Eğilmez | AP39: Korcan Işık
A40: 604bbd2d34b8b44b700952e0 | B40: Acıktım, Kepez (Altınova Sinan Mah.) | C40: =VLOOKUP(A40,import!A:C,3,0) -> YANLIŞ | D40: Tost & Sandviç | E40: =VLOOKUP(A40,import!A:J,5,0) -> 18 | F40: =VLOOKUP(A40,import!A:J,6,0) | G40: =VLOOKUP(A40,import!A:J,7,0) -> 0 | H40: =VLOOKUP(A40,import!A:J,8,0) -> 40 | I40: =VLOOKUP(A40,import!A:J,9,0) -> 40 | J40: =VLOOKUP(A40,import!A:J,10,0) -> 0 | K40: İBRAHİM ÜSTÜNCÜ | L40: 5396177421 | M40: Kepez | N40: Altınova Orta | O40: Altınova Sinan Mah. Yunus Emre sk. No:34 Kepez/ANTALYA | P40: =VLOOKUP(A40,import!A:P,16,0) -> Geleneksel | R40: TRUE | S40: FALSE | T40: İleride Randevu Alınacak | W40: 2 haftaya arama sağlansın menü güncellemesi yapacak ekle-çıkart yapmam gerek der/henüz sonlanmamış | AA40: Tekrar Aranacak | AB40: 44638 | AC40: Görüşüldü | AD40: 44648 | AK40: Hatem Soyaslan | AL40: Zeliha Özer
...

Sheet Takvim
A1: =E1 -> ID | B1: Hedef İlçeler | C1: TARİH | D1: Randevu Alan | E1: ID | F1: RESTORAN | G1: SAAT | H1: İLÇE / MAHALLE | I1: YETKİLİ KİŞİ / TELEFON | J1: ADRES | K1: Notlar | L1: Fotoğraf Adeti | M1: Toplam Ürün | N1: Şubeli | O1: İptal
A2: =E2 | C2: 44270
A3: =E3 | B3: Kepez Konyaaltı Muratpaşa
A4: =E4 -> 601aa203f0cf7b1acfa2a62d | C4: Ahmet Can Mülayim | D4: Beyza gülşah | E4: 601aa203f0cf7b1acfa2a62d | F4: Hakan Usta Çorba & Döner, Muratpaşa (Güllük Mah.) | G4: 12.00 | H4: Muratpaşa/Kızılsaray | I4: Yener bey/5526969609 | J4: Kızılsaray Mah. Anafartalar Cad. Tuna Apt. No:68/B Muratpaşa/Antalya | L4: 24 | M4: =VLOOKUP(E4,'Hedef Liste'!A:J,9,0) -> #N/A
A5: =E5 -> 5fe5918c1a12f955ddf7caa7 | C5: Ahmet Can Mülayim | D5: Beyza gülşah | E5: 5fe5918c1a12f955ddf7caa7 | F5: Başak Pide & Lahmacun, Muratpaşa (Etiler Mah.) | G5: 0.58333333 | H5: Muratpaşa/Muratpaşa | I5: İlkay bey/2422449154 | J5: Muratpaşa Mah. 564 Sk. No:38/C Muratpaşa/Antalya | M5: =VLOOKUP(E5,'Hedef Liste'!A:J,9,0) -> 31
A6: =E6 -> 5ff2da3ee97c0d6355d27827 | C6: Ahmet Can Mülayim | D6: Beyza gülşah | E6: 5ff2da3ee97c0d6355d27827 | F6: Antalya Ht Pide & Kebap & Lahmacun, Muratpaşa (Kızılsaray Mah.) | G6: 16.00 | H6: Muratpaşa/Kızılsaray | I6: Haşim bey/2422480007 | J6: kızılsaray mahallesi 76 sokak demir apt. no27/B muratpaşa Antalya | L6: 8 | M6: =VLOOKUP(E6,'Hedef Liste'!A:J,9,0) -> #N/A
A7: =E7 -> 601915862a3726165912b983 | C7: Ahmet Can Mülayim | D7: Beyza gülşah | E7: 601915862a3726165912b983 | F7: Gelatte, Muratpaşa (Kapalıyol Mah.) | G7: 17.30 | H7: Muratpaşa/Kızılsaray | I7: Hacer hanım/2422282333 | J7: Kızılsaray Mah. Şarampol Cd. No:1 Muratpaşa/Antalya | K7: Adres:bazı yerlerde şu şekilde görünüyor: Kazım Özalp Cad. Elmalı Mah. No:1 | L7: 26 | M7: =VLOOKUP(E7,'Hedef Liste'!A:J,9,0) -> 50
A8: =E8
A9: =E9 | B9: ÇARŞAMBAYA ERTELENECEK
A10: =E10
A11: =E11
A12: =E12
A13: =E13
A14: =E14
A15: =E15 -> 5fa124f4e5cea0023bb0d57b | B15: Konyaaltı Muratpaşa | C15: Kaan Soytürk | D15: Özlem gümüş | E15: 5fa124f4e5cea0023bb0d57b | F15: Dürümcü Bedir Usta , Konyaaltı (Liman Mah.) | G15: 0.4375 | H15: Konyaaltı/Liman | I15: Mehmet / 5075130984 | J15: Liman Mah. 32. Sk.3B | M15: =VLOOKUP(E15,'Hedef Liste'!A:J,9,0) -> 14
A16: =E16 -> 5f8445a9ec14c4f567032b72 | C16: Kaan Soytürk | D16: Özlem gümüş | E16: 5f8445a9ec14c4f567032b72 | F16: Urfa Sultan Sofrası, Konyaaltı (Liman Mah.) | G16: 14.00 | H16: Konyaaltı/ Liman | I16: Ali/ 2422593304 | J16: Liman, Liman Mah. Boğaçay Cad, Erhan Apt 63/B, 07130 Konyaaltı/Antalya | M16: =VLOOKUP(E16,'Hedef Liste'!A:J,9,0) -> 65
A17: =E17 -> 6023457ef981397be13b5287 | C17: Kaan Soytürk | D17: Özlem gümüş | E17: 6023457ef981397be13b5287 | F17: Han Döner, Konyaaltı (Liman Mah.) | G17: 16.00 | H17: Konyaaltı/Liman | I17: Cantürk/ 2422593459 | J17: Liman mahallesi Akdeniz Bulvarı 278 C | M17: =VLOOKUP(E17,'Hedef Liste'!A:J,9,0) -> 34
A18: =E18 -> 5f50ef2902f0631f92f2b317 | C18: Kaan Soytürk | D18: Özlem gümüş | E18: 5f50ef2902f0631f92f2b317 | F18: Urfa Sultan Sofrası (Hurma Mah.) | G18: 0.72916667 | H18: Konyaaltı/ Hurma | I18: Mehmet Bey/ 0532 428 0763 | J18: Hurma, Boğaçay Cd. 86/A, 07130 Konyaaltı/Antalya | M18: =VLOOKUP(E18,'Hedef Liste'!A:J,9,0) -> 63
A19: =E19
A20: =E20
A21: =E21 | C21: 44271
A22: =E22 -> 5fe5918c1a12f955ddf7caa7 | B22: Kepez Konyaaltı Muratpaşa | C22: Ahmet Can Mülayim | D22: Beyza gülşah | E22: 5fe5918c1a12f955ddf7caa7 | F22: Başak Pide & Lahmacun, Muratpaşa (Etiler Mah.) | G22: 0.58333333 | H22: Muratpaşa/Muratpaşa | I22: İlkay bey/2422449154 | J22: Muratpaşa Mah. 564 Sk. No:38/C Muratpaşa/Antalya | M22: =VLOOKUP(E22,'Hedef Liste'!A:J,9,0) -> 31
A23: =E23 -> 5fa50b7051c1c4a31fdfce68 | C23: Ahmet Can Mülayim | D23: Beyza gülşah | E23: 5fa50b7051c1c4a31fdfce68 | F23: Bi Lezzet , Konyaaltı (Altınkum mah.) | G23: 12.00 | H23: Konyaaltı/Altınkum | I23: Aysel hanım/2422291234 | J23: Altınkum Mah. 448 Sk. No: 1/B | L23: 32 | M23: =VLOOKUP(E23,'Hedef Liste'!A:J,9,0) -> 10
A24: =E24 -> 5fc78cf8492cf9585db7f161 | C24: Ahmet Can Mülayim | D24: Beyza gülşah | E24: 5fc78cf8492cf9585db7f161 | F24: Harika Simit (Altınkum Mah.) | G24: 14.00 | H24: Konyaaltı/Altınkum | I24: Arif bey/5433461666 | J24: Altınkum Mah. Kuşçu Apt 450. Sk. No:3 07070 Konyaaltı/Antalya | K24: Adres gitmeden aranıp sorulacak | L24: 16 | M24: =VLOOKUP(E24,'Hedef Liste'!A:J,9,0) -> #N/A
A25: =E25 -> 5fc4aa314073e31cb6b797bb | C25: Ahmet Can Mülayim | D25: Beyza gülşah | E25: 5fc4aa314073e31cb6b797bb | F25: Charlotte Pastane & Fırın (Altınkum Mah.) | G25: 16.00 | H25: Konyaaltı/Altınkum | I25: Mehmet Mert bey/ 02423123456/2422302526 | J25: Altınkum Mah. Atatürk Bulv. İbrahim Ak Apt. No:134/A Konyaaltı/Antalya | L25: 50 | M25: =VLOOKUP(E25,'Hedef Liste'!A:J,9,0) -> #N/A
A26: =E26 -> 5ff7dbf9292a6106c2b160e2 | C26: Ahmet Can Mülayim | D26: Beyza gülşah | E26: 5ff7dbf9292a6106c2b160e2 | F26: Gözleme Mantı & Çorba 06 , Konyaaltı (Altınkum Mah.) | G26: 17.30 | H26: Konyaaltı/Altınkum | I26: Cahide Uğurlu/2422302244 | J26: Altınkum, özlem apartmanı, 431. Sk. 10/A | L26: 28
A27: =E27
A28: =E28 -> 5fd4c1f414bd8861dcaabc66 | B28: ERTELENECEK | D28: Özlem arslan | E28: 5fd4c1f414bd8861dcaabc66 | F28: Avşar Tantuni (Arapsuyu Mah.) | G28: 0.4375 | H28: Konyaaltı Arapsuyu | I28: Osman Avşar/2422302133 | J28: Arapsuyu Mah. Atatürk Blv. 5M Migros AVM | L28: numara düşmüyor direk kapanıyor
A29: =E29
A30: =E30
A31: =E31
A32: =E32
A33: =E33
A34: =E34 -> 5f9dd416e5cea08c88b0b572 | B34: Konyaaltı Muratpaşa | C34: Kaan Soytürk | D34: Özlem gümüş | E34: 5f9dd416e5cea08c88b0b572 | F34: Baraqah Cafe & Bistro , Konyaaltı (Hurma Mah.) | G34: 0.4375 | H34: Konyaaltı/ Hurma | I34: İlyas / 2425040404 | J34: Hurma Mah. 37. Cad. (Hurma Cad.) No: 37 | K34: Ustası yokmuş | M34: =VLOOKUP(E34,'Hedef Liste'!A:J,9,0) -> #N/A | N34: hedefg listede bulınamadı
A35: =E35 -> 5ff588f8fd7f0a6a810c62bf | C35: Kaan Soytürk | D35: Özlem gümüş | E35: 5ff588f8fd7f0a6a810c62bf | F35: Torku Ziyafet Döner, Konyaaltı (Liman Mah.) | G35: 0.5 | H35: Konyaaltı/ Liman | I35: Buğrahan / 05546299234 | J35: Liman Mahallesi Atatürk Bulvarı No:224/1 Konyaaltı-Antalya | K35: 15 ürün çıkartamam şuan ben sizi arıycam dedi | M35: =VLOOKUP(E35,'Hedef Liste'!A:J,9,0) -> 47
A36: =E36 -> 5f909d089d51bfe47d29ddf7 | C36: Kaan Soytürk | D36: Özlem gümüş | E36: 5f909d089d51bfe47d29ddf7 | F36: Yamaçoba Restoran | G36: 0.58333333 | H36: Konyaaltı/ Liman | I36: Dilek/ 2422595040 | J36: Liman Mah. Atatürk Bulv. Heniye Hnm. Apt. No: 283 / B | K36: Ustası İstanbul'a gitmiş | M36: =VLOOKUP(E36,'Hedef Liste'!A:J,9,0) -> #N/A | N36: hedef listede bulunamadı
A37: =E37 -> 604338c695464a8594840860 | C37: Kaan Soytürk | D37: Özlem gümüş | E37: 604338c695464a8594840860 | F37: Ayvalık Tost, Konyaaltı (Liman Mah.) | G37: 16:00 | H37: Konyaaltı/ Liman | I37: Halil/ 2422596663 | J37: Liman Mah. Atatürk Bulv. No:206/A Konyaaltı/ANTALYA | M37: =VLOOKUP(E37,'Hedef Liste'!A:J,9,0) -> 84
A38: =E38
A39: =E39
A40: =E40 | B40: Alanya
...

Sheet import
A1: Restaurant ID | B1: Restoran Adı | C1: IsActive | D1: Mutfak | E1: TOPLAM SİPARİŞ | F1: SON 2 HAFTA | G1: RESİMLİ ÜRÜN | H1: RESİMSİZ ÜRÜN | I1: TOPLAM ÜRÜN | J1: Ratio | K1: Yetkili | L1: Telefon | M1: İLÇE | N1: MAHALLE | O1: ADRES | P1: Geleneksel Zincir | Q1: Eklendi mi
A2: 5f50ef2902f0631f92f2b317 | B2: Urfa Sultan Sofrası, Konyaaltı (Hurma Mah.) | C2: DOĞRU | D2: Kebap | E2: 1882 | F2: 106 | G2: 29 | H2: 34 | I2: 63 | J2: 0.46 | K2: Mehmet Sait Tuzlu | L2: 2422593737 | M2: Konyaaltı | N2: Hurma | O2: Hurma, Boğaçay Cd. 86/A, 07130 Konyaaltı/Antalya | P2: Geleneksel | Q2: =COUNTIF('Hedef Liste'!$A:$A,A2) -> 1
A3: 5f51a845db3207980f921da7 | B3: Buffalo Burger (Güzeloba Mah.) | C3: DOĞRU | D3: Burger | E3: 2826 | F3: 174 | G3: 24 | H3: 37 | I3: 61 | J3: 0.39 | K3: TARIK ÇAĞIMNI | L3: 2423490053 | M3: Muratpaşa | N3: Güzeloba | O3: Güzeloba, Rauf Denktaş Cd No:20, 07230 Muratpaşa/Antalya | P3: Geleneksel | Q3: =COUNTIF('Hedef Liste'!$A:$A,A3) -> 1
A4: 5f4f4d1e0f8c874fbdfd8514 | B4: A + New Concept Pide, Muratpaşa (Güzeloba Mah.) | C4: DOĞRU | D4: Pide | E4: 332 | F4: 8 | G4: 0 | H4: 30 | I4: 30 | J4: 0 | K4: ABDULLAH KORAL DEMİRAL | L4: 2423230002 | M4: Muratpaşa | N4: Güzeloba | O4: Güzeloba Mah. 2114 Sok. No:6/A Muratpaşa/Antalya | P4: Geleneksel | Q4: =COUNTIF('Hedef Liste'!$A:$A,A4) -> 1
A5: 5f523281a1df3029230c5746 | B5: Kayseri Yöre Sofrası Börek & Mantı (Güzeloba Mah.) | C5: DOĞRU | D5: Börek | E5: 942 | F5: 67 | G5: 0 | H5: 41 | I5: 41 | J5: 0 | K5: HAYRULLAH KARACA | L5: 2423495638 | M5: Muratpaşa | N5: Güzeloba | O5: Güzeloba, Havaalanı Cd. No:39, 07230 Muratpaşa/Antalya | P5: Geleneksel | Q5: =COUNTIF('Hedef Liste'!$A:$A,A5) -> 1
A6: 5f55e7921fcf335b6c81b7bb | B6: A + New Concept Pide (Çağlayan Mah.) | C6: DOĞRU | D6: Pide | E6: 633 | F6: 22 | G6: 0 | H6: 39 | I6: 39 | J6: 0 | K6: ABDULLAH KORAL DEMİRAL | L6: 2423230002 | M6: Muratpaşa | N6: Çağlayan | O6: Çağlayan Mah, Nazlı Apt, Bülent Ecevit Blv. D:No:123, 07230 Muratpaşa/Antalya | P6: Geleneksel | Q6: =COUNTIF('Hedef Liste'!$A:$A,A6) -> 1
A7: 5f565c3b4769a6b4cb4e3a87 | B7: Ali Baba Lahmacun & Pide, Kepez (Kültür Mah.) | C7: DOĞRU | D7: Pide | E7: 22394 | F7: 1182 | G7: 24 | H7: 50 | I7: 74 | J7: 0.32 | K7: Yener Beytüzün | L7: 2425031637 | M7: Kepez | N7: Kültür | O7: Kültür mah. 75. Yıl caddesi Mecid Beytüzün aprt. No 22, 07090 Kepez/Antalya | P7: Geleneksel | Q7: =COUNTIF('Hedef Liste'!$A:$A,A7) -> 1
A8: 5f59e8063d4a6419d4ac9ee9 | B8: Dürümcü Cafer Usta, Muratpaşa (Etiler Mah.) | C8: DOĞRU | D8: Kebap | E8: 1294 | F8: 80 | G8: 0 | H8: 23 | I8: 23 | J8: 0 | K8: MUSTAFA YILDIRIM | L8: 5074445664 | M8: Muratpaşa | N8: Muratpaşa | O8: Etiler Mahallesi Şair Dede Caddesi &, 592. Sk. No:12, 07000 Muratpaşa/Antalya | P8: Geleneksel | Q8: =COUNTIF('Hedef Liste'!$A:$A,A8) -> 1
A9: 5f5f379bc5a78437df6f559e | B9: Usta Lahmacun & Kebap, Muratpaşa (Perge Caddesi) | C9: DOĞRU | D9: Lahmacun | E9: 1803 | F9: 113 | G9: 0 | H9: 46 | I9: 46 | J9: 0 | K9: İSMAİL KILIÇ | L9: 2423117007 | M9: Muratpaşa | N9: Meydankavağı | O9: Tarım Mah, Perge Blv. No:63/3, 07100 Muratpaşa/Antalya | P9: Geleneksel | Q9: =COUNTIF('Hedef Liste'!$A:$A,A9) -> 1
A10: 5f609515c0a00b2653212f59 | B10: Up To You Tost & Sandviç, Kepez (Ahatlı Mah.) | C10: DOĞRU | D10: Tost & Sandviç | E10: 8686 | F10: 248 | G10: 0 | H10: 30 | I10: 30 | J10: 0 | K10: Büşra Oktay | L10: 5060559516 | M10: Kepez | N10: Ahatlı | O10: Ahatlı, Ulusoy Cd. No:96, 07090 Kepez/Antalya | P10: Geleneksel | Q10: =COUNTIF('Hedef Liste'!$A:$A,A10) -> 1
A11: 5f60a5178d5d517bed03bc6e | B11: Duru Pizza & Lahmacun, Kepez (Kültür Mah.) | C11: DOĞRU | D11: Pizza | E11: 8415 | F11: 709 | G11: 0 | H11: 53 | I11: 53 | J11: 0 | K11: Recep Kavak | L11: 2422274466 | M11: Kepez | N11: Kültür | O11: Kültür, 3840. Sk. No:5, 07090 Bahtılı Köyü Köyü/Kepez/Antalya | P11: Geleneksel | Q11: =COUNTIF('Hedef Liste'!$A:$A,A11) -> 1
A12: 5f5257464769a628d74e14b8 | B12: Chicken Box, Kepez (Ahatlı Mah.) | C12: DOĞRU | D12: Tavuk | E12: 5820 | F12: 142 | G12: 0 | H12: 13 | I12: 13 | J12: 0 | K12: MEHMET AKGÜN | L12: 5510346339 | M12: Kepez | N12: Ahatlı | O12: Ahatlı, 3140. Sk., 07090 Kepez/Antalya | P12: Geleneksel | Q12: =COUNTIF('Hedef Liste'!$A:$A,A12) -> 1
A13: 5f55efebde36fc4648bf74b9 | B13: Pide Dünyası 07 (Güvenlik Mah.) | C13: DOĞRU | D13: Pide | E13: 1425 | F13: 68 | G13: 17 | H13: 15 | I13: 32 | J13: 0.53 | K13: NURDAN BAŞARAN | L13: 2423464371 | M13: Muratpaşa | N13: Memurevleri | O13: Güvenlik Mahallesi Derya Caddesi Gencer Apt, D:8/A, 07050 Muratpaşa/Antalya | P13: Geleneksel | Q13: =COUNTIF('Hedef Liste'!$A:$A,A13) -> 1
... A23: 5f7f24a3449e3137c1f07479 | B23: Karadeniz Pide & Kebap, Konyaaltı (Liman Mah.) | C23: DOĞRU | D23: Kebap | E23: 4323 | F23: 176 | G23: 53 | H23: 42 | I23: 95 | J23: 0.56 | K23: Halil Nane | L23: 2422590753 | M23: Konyaaltı | N23: Liman | O23: Liman, Boğaçayı Cd. Metin Apt., 07000 Konyaaltı/Antalya | P23: Geleneksel | Q23: =COUNTIF('Hedef Liste'!$A:$A,A23) -> 1
A24: 5f68c298eed8843043a9efc1 | B24: Kepçe Kayseri Mantısı & Ev Yemekleri, Kepez (Kültür Mah.) | C24: DOĞRU | D24: Mantı | E24: 1428 | G24: 0 | H24: 15 | I24: 15 | J24: 0 | K24: NEHİR TAYFUR | L24: 5523560738 | M24: Kepez | N24: Kültür | O24: Kültür, Ulusoy Cd. No: 41/A, 07090 Kepez/Antalya | P24: Geleneksel | Q24: =COUNTIF('Hedef Liste'!$A:$A,A24) -> 1
A25: 5f85a0f4a32e9971993964be | B25: Burger State, Muratpaşa (Mehmetçik Mah. - Termessos Bulvarı) | C25: DOĞRU | D25: Burger | E25: 2741 | F25: 89 | G25: 30 | H25: 40 | I25: 70 | J25: 0.43 | K25: CENGİZ KIRATLI | L25: 2423212424 | M25: Muratpaşa | N25: Mehmetçik | O25: Mehmetçik Mah., Muratpaşa, Antalya, Türkiye, | P25: Geleneksel | Q25: =COUNTIF('Hedef Liste'!$A:$A,A25) -> 1
A26: 5f8361f7e3bea65025bba8d3 | B26: Lara Sultan Çorbacısı (Fener Mah.) | C26: DOĞRU | D26: Kebap | E26: 845 | G26: 20 | H26: 53 | I26: 73 | J26: 0.27 | K26: ŞEYHMUS AKTAN | L26: 2423231121 | M26: Muratpaşa | N26: Fener | O26: Fener, Tekelioğlu Cd. No:65, 07100 Muratpaşa/Antalya | P26: Geleneksel | Q26: =COUNTIF('Hedef Liste'!$A:$A,A26) -> 1
A27: 5f837c1f962a9610dcccb359 | B27: Akçalar Restaurant, Kepez (Yeni Mah.) | C27: DOĞRU | D27: Pide | E27: 7548 | F27: 320 | G27: 15 | H27: 13 | I27: 28 | J27: 0.54 | K27: AHMET TIBIK | L27: 2423259900 | M27: Kepez | N27: Yeni | O27: Yeni, Aliya Izzet Begoviç Cd, 07060 Kepez/Antalya | P27: Geleneksel | Q27: =COUNTIF('Hedef Liste'!$A:$A,A27) -> 1
A28: 5f837cfe83cb6ed75b3c59a0 | B28: Ayyıldız Döner, Kepez (Yenidoğan Mah.) | C28: DOĞRU | D28: Döner | E28: 1315 | F28: 47 | G28: 0 | H28: 15 | I28: 15 | J28: 0 | K28: ADEM YILDIZ | L28: 2422270727 | M28: Kepez | N28: Kültür | O28: Yeni Doğan, 3066. Sk. No:2 D:6, 07090 Kepez/Antalya | P28: Geleneksel | Q28: =COUNTIF('Hedef Liste'!$A:$A,A28) -> 1
A29: 5f843cb28599559a441565da | B29: Doğa Sofrası, Konyaaltı (Arapsuyu Mah.) | C29: DOĞRU | D29: Kebap | E29: 2652 | F29: 82 | G29: 12 | H29: 45 | I29: 57 | J29: 0.21 | K29: Gökdeniz Küçükaslan | L29: 2422291897 | M29: Konyaaltı | N29: Arapsuyu | O29: Arapsuyu, Belediye Cd. 23/A, 07070 Konyaaltı/Antalya | P29: Geleneksel | Q29: =COUNTIF('Hedef Liste'!$A:$A,A29) -> 1
A30: 5f8445a9ec14c4f567032b72 | B30: Urfa Sultan Sofrası, Konyaaltı (Liman Mah.) | C30: DOĞRU | D30: Kebap | E30: 1732 | F30: 62 | G30: 16 | H30: 49 | I30: 65 | J30: 0.25 | K30: Ali Yıldız | L30: 2422593304 | M30: Konyaaltı | N30: Liman | O30: Liman, Liman Mah. Boğaçay Cad, Erhan Apt 63/B, 07130 Konyaaltı/Antalya | P30: Geleneksel | Q30: =COUNTIF('Hedef Liste'!$A:$A,A30) -> 1
A31: 5f91c87c20c35273b586d454 | B31: McDonald's, Alanya (Güllerpınarı Mah.) | C31: DOĞRU | D31: Burger | E31: 6575 | F31: 147 | G31: 362 | H31: 3 | I31: 365 | J31: 0.99 | K31: Filiz Coşkun | L31: 2123363575 | M31: Alanya | N31: Şekerhane | O31: Güller pınarı mahellesi Keykubat Cad. No: 5 07400 Alanya / Antalya | P31: Key | Q31: =COUNTIF('Hedef Liste'!$A:$A,A31) -> 0
A32: 5f68be11bfa7ff6806d7afad | B32: Gaziantepliler Kebapçısı, Kepez (Kültür Mah.) | C32: DOĞRU | D32: Kebap | E32: 5100 | F32: 181 | G32: 0 | H32: 38 | I32: 38 | J32: 0 | K32: CUMA ÇOBAN | L32: 2422220027 | M32: Kepez | N32: Kültür | O32: Kültür, Hürriyet Cd. No:38, 07090 Kepez/Antalya | P32: Geleneksel | Q32: =COUNTIF('Hedef Liste'!$A:$A,A32) -> 1
A33: 5f82f95cec14c4919b031948 | B33: Aydoğanlar 32 Pide & Kebap, Kepez (Kanal Mah.) | C33: DOĞRU | D33: Kebap | E33: 5081 | F33: 180 | G33: 14 | H33: 9 | I33: 23 | J33: 0.61 | K33: Şahin Aydoğan | L33: 2423328945 | M33: Kepez | N33: Kanal | O33: Yasemin Cad., No:26 Kanal Mah., Kepez, Antalya, Türkiye | P33: Geleneksel | Q33: =COUNTIF('Hedef Liste'!$A:$A,A33) -> 1
A34: 5f836022711c853e1df82779 | B34: Havva Tantuni (Soğuksu Mah.) | C34: DOĞRU | D34: Sokak Lezzetleri | E34: 2700 | F34: 108 | G34: 19 | H34: 86 | I34: 105 | J34: 0.18 | K34: ALİ CAN | L34: 2423447475 | M34: Muratpaşa | N34: Güvenlik | O34: Soğuksu Mah. Palmiye Cad. Hasan Acar Apt. No:20/C Çallı Muratpaşa, Antalya | P34: Geleneksel | Q34: =COUNTIF('Hedef Liste'!$A:$A,A34) -> 1
A35: 5f840a26c1a12254390958f4 | B35: Ayaz'ım Mutfak, Kepez (Yeşilyurt Mah.) | C35: DOĞRU | D35: Döner | E35: 2134 | F35: 155 | G35: 15 | H35: 38 | I35: 53 | J35: 0.28 | K35: Hande Çabuk | L35: 5422461677 | M35: Kepez | N35: Yeşilyurt | O35: Yeşilyurt, 4376. Sk. No:11, 07220 Bahtılı Köyü Köyü/Kepez/Antalya | P35: Geleneksel | Q35: =COUNTIF('Hedef Liste'!$A:$A,A35) -> 1
A36: 5f84344da32e99e33339441d | B36: Meltem Balıkçısı & Meze Evi, Konyaaltı (Altınkum Mah.) | C36: DOĞRU | D36: Deniz Ürünleri | E36: 487 | F36: 2 | G36: 0 | H36: 53 | I36: 53 | J36: 0 | K36: Çağla Deniz Dönmez | L36: 2422298181 | M36: Konyaaltı | N36: Gürsu | O36: Altınkum, 126/1, Gazi Mustafa Kemal Blv., 07070 Konyaaltı/Antalya | P36: Geleneksel | Q36: =COUNTIF('Hedef Liste'!$A:$A,A36) -> 1
A37: 5f844958a09b8c9df7a1b345 | B37: Dr. Pizza, Konyaaltı (Toros Mah.) | C37: DOĞRU | D37: Pizza | E37: 3831 | F37: 145 | G37: 17 | H37: 74 | I37: 91 | J37: 0.19 | K37: SÜLEYMAN ARIKAN | L37: 2422298180 | M37: Konyaaltı | N37: Pınarbaşı | O37: Toros, 15. Cd. No:37, 07070, 07070 Konyaaltı/Antalya | P37: Geleneksel | Q37: =COUNTIF('Hedef Liste'!$A:$A,A37) -> 1
A38: 5f88460d5071cad15090decb | B38: Ghot Pizzeria (Yeşilbahçe Mah.) | C38: DOĞRU | D38: Pizza | E38: 1590 | F38: 90 | G38: 48 | H38: 27 | I38: 75 | J38: 0.64 | K38: İSA BAHÇECİ | L38: 2423110785 | M38: Muratpaşa | N38: Yeşilbahçe | O38: Yeşilbahçe, Metin Kasapoğlu Cd. No:38, 07160 Muratpaşa/Antalya | P38: Geleneksel | Q38: =COUNTIF('Hedef Liste'!$A:$A,A38) -> 1
... A43: 5f55eb6a3d4a64b3dfac5eca | B43: Kor Ateş Pide & Kebap & Lahmacun (Doğugarajı Mevkii) | C43: DOĞRU | D43: Lahmacun | E43: 5055 | F43: 328 | G43: 26 | H43: 33 | I43: 59 | J43: 0.44 | K43: Rıdvan Tunç | L43: 2423221881 | M43: Muratpaşa | N43: Yüksekalan | O43: Yüksekalan, kepekçi apartmanı, 488. Sk. no: 13/d, 07100 Muratpaşa/Antalya | P43: Geleneksel | Q43: =COUNTIF('Hedef Liste'!$A:$A,A43) -> 1
A44: 5f5652d2bfaa9ab5c031db80 | B44: Gülveren Pilavcısı, Kepez (Gülveren Mah.) | C44: YANLIŞ | D44: Sokak Lezzetleri | E44: 15 | G44: 0 | H44: 25 | I44: 25 | J44: 0 | K44: Yılmaz Turan | L44: 5300445410 | M44: Kepez | N44: Gülveren | O44: Gülveren, saray apartmanı, 3713. Sk. no 3 D:b, 07070 Kepez/Antalya | P44: Geleneksel | Q44: =COUNTIF('Hedef Liste'!$A:$A,A44) -> 1
A45: 5f59e3a20cca8c11047b12ac | B45: Fratelli Di Pizza, Muratpaşa (Meydankavağı Mah.) | C45: DOĞRU | D45: Pizza | E45: 3071 | F45: 102 | G45: 78 | H45: 24 | I45: 102 | J45: 0.76 | K45: ÖNDER ÖZTÜRK | L45: 2423127878 | M45: Muratpaşa | N45: Meydankavağı | O45: Lara Karataş Apartmanı, Meydankavağı Mahallesi İsmail Cem Caddesi, 1596. Sk., 07000 Muratpaşa | P45: Geleneksel | Q45: =COUNTIF('Hedef Liste'!$A:$A,A45) -> 1
A46: 5f5f4252356069484db33453 | B46: Acıktım Sivas Pide & Köfte, Muratpaşa (Şirinyalı Mah.) | C46: DOĞRU | D46: Pide | E46: 530 | F46: 15 | G46: 29 | H46: 9 | I46: 38 | J46: 0.76 | K46: ERDAL BULUT | L46: 2423170758 | M46: Muratpaşa | N46: Şirinyalı | O46: Şirinyalı mah. 1523 sk. Durhan apt. 10/A ANTALYA, 07180 Muratpaşa/Antalya | P46: Geleneksel | Q46: =COUNTIF('Hedef Liste'!$A:$A,A46) -> 1
A47: 5f68c64d60fd3fcfac89580f | B47: Korikos Tantuni, Kepez (Kültür Mah.) | C47: DOĞRU | D47: Sokak Lezzetleri | E47: 11044 | F47: 336 | G47: 5 | H47: 11 | I47: 16 | J47: 0.31 | K47: Volkan Kazancı | L47: 5495191004 | M47: Kepez | N47: Kültür | O47: Kültür, 3876. Sk. No: 64/B, 07100 Kepez/Antalya | P47: Geleneksel | Q47: =COUNTIF('Hedef Liste'!$A:$A,A47) -> 1
A48: 5f7f29a3962a963fa3cc6286 | B48: Iva Sushi & Bistro, Konyaaltı (Liman Mah.) | C48: DOĞRU | D48: Uzak Doğu | E48: 737 | F48: 28 | G48: 0 | H48: 161 | I48: 161 | J48: 0 | K48: MURAT KAYA | L48: 2422595960 | M48: Konyaaltı | N48: Liman | O48: Liman Mah. Boğaçay Cd. No:65/A, 07130 Konyaaltı/Antalya | P48: Geleneksel | Q48: =COUNTIF('Hedef Liste'!$A:$A,A48) -> 1
A49: 5f807d0100b31a6d4e16fa48 | B49: Ascuola Pizza, Muratpaşa (Meltem Mah.) | C49: DOĞRU | D49: Pizza | E49: 2945 | F49: 168 | G49: 34 | H49: 11 | I49: 45 | J49: 0.76 | K49: TİMUÇİN ÖNAL | L49: 2422370022 | M49: Muratpaşa | N49: Meltem | O49: Meltem, Sakıp Sabancı Blv. No:14, 07030 Muratpaşa/Antalya | P49: Geleneksel | Q49: =COUNTIF('Hedef Liste'!$A:$A,A49) -> 1
A50: 5f84e0b8ef2d604cbb0050d5 | B50: Hacı Saad Kebap (Şirinyalı Mah.) | C50: DOĞRU | D50: Lahmacun | E50: 2283 | F50: 136 | G50: 1 | H50: 56 | I50: 57 | J50: 0.02 | K50: ERDOĞAN KONUK | L50: 2423240707 | M50: Muratpaşa | N50: Fener | O50: Şirinyalı Mahallesi Tekelioğlu Cd. Bașer Apt. 6/2, 07170 Muratpaşa/Antalya | P50: Geleneksel | Q50: =COUNTIF('Hedef Liste'!$A:$A,A50) -> 1
A51: 5f843125ace10e640ca5d170 | B51: Lahmacun Diyarı (Altınkum Mah.) | C51: YANLIŞ | D51: Lahmacun | E51: 50 | G51: 0 | H51: 30 | I51: 30 | J51: 0 | K51: Nuran Doğan | L51: 2422280666 | M51: Konyaaltı | N51: Altınkum | O51: Altınkum Mah. Anadolu Cad. Sinan Apt. No:41 A | P51: Geleneksel | Q51: =COUNTIF('Hedef Liste'!$A:$A,A51) -> 1
A52: 5f8441450e96ef55f47d6bcb | B52: Şanlıurfa Dergah Sofrası, Konyaaltı (Hurma Mah.) | C52: DOĞRU | D52: Kebap | E52: 5538 | F52: 549 | G52: 0 | H52: 61 | I52: 61 | J52: 0 | K52: Mehmet KILIÇ | L52: 2422909050 | M52: Konyaaltı | N52: Hurma | O52: Hurma mah. 195 sk. No:3 / B | P52: Geleneksel | Q52: =COUNTIF('Hedef Liste'!$A:$A,A52) -> 1
A53: 5f845216b238a1cacf89a205 | B53: Ülkü Fırın, Konyaaltı (Uncalı Mah.) | C53: DOĞRU | D53: Tost & Sandviç | E53: 3305 | F53: 165 | G53: 76 | H53: 87 | I53: 163 | J53: 0.47 | K53: HAKAN KAYA | L53: 2423127474 | M53: Konyaaltı | N53: Uncalı | O53: Uncalı mah. Toroslar cad. İncedağ G 72 E, 07100 Konyaaltı/Antalya | P53: Geleneksel | Q53: =COUNTIF('Hedef Liste'!$A:$A,A53) -> 1
...

Sheet Durum Parametreler
C2: Başka Şubeden Çekilecek | H2: Mertcan
C3: BlackList | H3: Enes
A4: 44197 | C4: Çekim İstemiyor | H4: Ezgi Turan
A5: 44198 | C5: Devir | H5: Hatem Soyaslan
A6: 44199 | C6: Dönüş Yapacak | H6: Zeliha Özer
A7: 44200 | C7: Franchise | H7: Emre Dalgıç
A8: 44201 | C8: İleride Randevu Alınacak | F8: Önder Örtel | H8: Gül Değirmenci
A9: 44202 | C9: Lokasyon Uzak | F9: Fatih Özpelit | H9: Yurdagül Kulaksız
A10: 44203 | C10: Haziran'da Aranacak | H10: Ayfer Altın
A11: 44204 | C11: Menü Güncellemesi Yapılacak | H11: Ayşegül Kır
A12: 44205 | C12: Personel Eksik | H12: Damla Kılcı
A13: 44206 | C13: Randevu Alındı | F13: Ayşegül Kır | H13: Özlem arslan
A14: 44207 | C14: Randevu İptal | F14: Betül Demir | H14: Beyza gülşah
A15: 44208 | C15: Restoran Silindi | F15: Hatem Soyaslan | H15: Özlem gümüş
A16: 44209 | C16: Sistemden Çıkmak İstiyor | F16: Selcan Topçu | H16: Tuğba Buyur
A17: 44210 | C17: Tadilat Var | F17: Sude Alkan | H17: Kadriye Polat
A18: 44211 | C18: Ulaşılamadı | F18: Yurdagül Kulaksız | H18: Şükriye Demir
A19: 44212 | C19: Yılbaşından Sonra Aranacak | F19: Zeliha Özer | H19: Ece Bayındır
A20: 44213 | F20: Ferhat Köksal | H20: Senanur Çınar
A21: 44214 | F21: Enes Günal | H21: Şura Özcan
A22: 44215 | C22: Dönüş Yapacak | F22: Serap Apaydın | H22: Funda Ünlü
A23: 44216 | C23: Görüşüldü | H23: Sıla Göksunaz Esen
