Workbook

Sheet TAKVİM
C1: TARİH | D1: Randevu Alan | E1: ID | F1: RESTORAN | G1: SAAT | H1: İLÇE / MAHALLE | I1: YETKİLİ KİŞİ / TELEFON | J1: ADRES | K1: Notlar | L1: Fotoğraf Adeti | M1: Toplam ürün | N1: Şubeli | O1: İptal
C2: 44250
B3: Nilüfer | C3: Okan Yazıcı | E3: 5f9830a779e0ec412130a6e1 | F3: The Dream Cafe, Nilüfer (Görükle Mah.) | G3: 10.30 | H3: Nilüfer/Dumlupınar | I3: Muhammet Bey / 5370591840 | J3: DUMLUPINAR MAH/SEMT KALKAN SK. NO: 6 B NİLÜFER/ BURSA | K3: iptal sebebi : ürünlerini yetiştirememis. yeni rand alındı | M3: =VLOOKUP(E3,'Hedef Liste'!A:I,8,false) -> 7 | N3: FALSE | O3: TRUE
A4: =E4 -> 5f8a0cdc5e5acb1aa3c96c71 | C4: Okan Yazıcı | E4: 5f8a0cdc5e5acb1aa3c96c71 | F4: Dr. Çıtır Nilüfer (Görükle Mah.) | G4: 12.30 | H4: Nilüfer/Dumlupınar | I4: Abdullah Erdağ/ 5325113724 | J4: Dumlupınar Mah. Atatürk BLV. A Blok No:9 C Nilüfer / Bursa | L4: 13 | M4: =VLOOKUP(E4,'Hedef Liste'!A:I,8,false) -> #N/A | N4: FALSE | O4: FALSE
A5: =E5 -> 5feb936512b71547b1a47059 | C5: Okan Yazıcı | E5: 5feb936512b71547b1a47059 | F5: Bari Pizza, Nilüfer (Görükle Mah.) | G5: 16:00 | H5: Nilüfer/Dumlupınar | I5: Erbay Bey / 5355024060 | J5: Dumlupınar Mah. Yonca Sk B No 3 B / C | L5: 20 | M5: =VLOOKUP(E5,'Hedef Liste'!A:I,8,false) -> #N/A | N5: FALSE | O5: FALSE
A6: =E6 -> 5f33d5aa9876961be68f5c32 | C6: Okan Yazıcı | E6: 5f33d5aa9876961be68f5c32 | F6: Bi Dünya Tavuk, Görükle | G6: 16:15 | H6: Nilüfer/Dumlupınar | I6: Erbay Bey / 5355024060 | J6: Dumlupınar Mah. Yonca Sk B No 3 B / C | M6: =VLOOKUP(E6,'Hedef Liste'!A:I,8,false) -> 20 | N6: FALSE | O6: FALSE
A7: =E7 -> 5f33d6ac13c9ae370a245201 | C7: Okan Yazıcı | E7: 5f33d6ac13c9ae370a245201 | F7: Ekmekarası Cheese & Steak, Görükle | G7: 16:30 | H7: Nilüfer/Dumlupınar | I7: Erbay Bey / 5355024060 | J7: Dumlupınar Mah. Yonca Sk B No 3 B / C | M7: =VLOOKUP(E7,'Hedef Liste'!A:I,8,false) -> 18 | N7: FALSE | O7: FALSE
A8: =E8 | N8: FALSE | O8: FALSE
A9: =E9 | C9: 44251
A10: =E10 | N10: FALSE | O10: FALSE
A11: =E11 -> 5fc9f2ecf7f5fedadbf474c7 | B11: Nilüfer | C11: Okan Yazıcı | E11: 5fc9f2ecf7f5fedadbf474c7 | F11: Nezih Sofrası, İhsaniye | G11: 0.45833333 | H11: Nilüfer/İhsaniye | I11: Mehmet Bey / 5076903821 | J11: İhsaniye Mah. Cami Sok. No:40 A Nilüfer / Bursa | L11: 36 | M11: =VLOOKUP(E11,'Hedef Liste'!A:I,8,false) -> 17 | N11: FALSE | O11: FALSE
A12: =E12 -> 5f356216bee28716b7544376 | C12: Okan Yazıcı | E12: 5f356216bee28716b7544376 | F12: Çınar Pideli Köfte, Görükle | G12: 0.52083333 | H12: Nilüfer/Dumlupınar | I12: Cem Bey / 2244837473 | J12: Dumlupınar, Atatürk Cd. No:96, 16285 Nilüfer/Bursa | L12: 7 | M12: =VLOOKUP(E12,'Hedef Liste'!A:I,8,false) -> 14 | N12: FALSE | O12: FALSE
A13: =E13 -> 5f29acb8f52a7882a29ce8f8 | C13: Okan Yazıcı | E13: 5f29acb8f52a7882a29ce8f8 | F13: Maydonoz Döner (Yediselviler Mah.) | G13: 14.00 | H13: Yıldırım/ Mehmet Akif Ersoy | I13: Mustafa Yeşilyurt /5379605800 | J13: Yediselviler Mahallesi Teyyareci Mehmet Ali Cad. No: 122/B Bursa/Yıldırım | L13: 22 | M13: =VLOOKUP(E13,'Hedef Liste'!A:I,8,false) -> #N/A | N13: FALSE | O13: FALSE
A14: =E14 -> 5f986b9cf5e5b1409859f617 | C14: Okan Yazıcı | E14: 5f986b9cf5e5b1409859f617 | F14: Şiptar Waffle & Kumpirr | G14: 0.66666667 | H14: Nilüfer/Dumlupınar | I14: Furkan Bey / 5414293800 | J14: Dumlupınar mah, Yurt Sk. No:1 B, 16285 Nilüfer Bursa | L14: 5 | M14: =VLOOKUP(E14,'Hedef Liste'!A:I,8,false) -> 8 | N14: FALSE | O14: FALSE
A15: =E15 -> 5f93f0c47ddac110b496a88a | C15: Okan Yazıcı | E15: 5f93f0c47ddac110b496a88a | F15: Hobi Paket Büfe (Görükle) | G15: 0.72916667 | H15: Nilüfer/Dumlupınar | I15: Sezer Dindar/ 2244835300 | J15: Dumlupınar Mah. Atatürk Cad. İnak Apt No:98 Nilüfer Bursa | L15: 21 | M15: =VLOOKUP(E15,'Hedef Liste'!A:I,8,false) -> #N/A | N15: FALSE | O15: FALSE
A16: =E16 | C16: 44252
A17: =E17 | N17: FALSE | O17: FALSE
A18: =E18 | N18: FALSE | O18: FALSE
A19: =E19 -> 5f33cb9613c9ae3a45245042 | B19: Nilüfer | C19: Okan Yazıcı | E19: 5f33cb9613c9ae3a45245042 | F19: Tatlı Kafa (Görükle Mah.) | G19: 12.30 | H19: Nilüfer/Görükle | I19: TAYFUR UGUR/05535059382 | J19: Görükle, Görükle, Güneş Sitesi B Blok, Üçoluk Cd., 16285 Nilüfer/Bursa | L19: 28 | M19: =VLOOKUP(E19,'Hedef Liste'!A:I,8,false) -> 15 | N19: FALSE | O19: FALSE
A20: =E20 -> 60141cc0f8fb0b4cbff9fd57 | C20: Okan Yazıcı | E20: 60141cc0f8fb0b4cbff9fd57 | F20: Got The Munchies, Nilüfer (Görükle Mah.) | G20: 13.30 | H20: Nilüfer/Görükle | I20: TAYFUR UGUR/05535059382 | J20: Görükle, Görükle, Güneş Sitesi B Blok, Üçoluk Cd., 16285 Nilüfer/Bursa | L20: 7 | M20: =VLOOKUP(E20,'Hedef Liste'!A:I,8,false) -> 1 | N20: FALSE | O20: FALSE
A21: =E21 -> 5f35164cf7ff4273512a75e9 | C21: Okan Yazıcı | E21: 5f35164cf7ff4273512a75e9 | F21: Aybalam Fast Food & Salad, Nilüfer (Görükle Mah.) | G21: 15:30 | H21: Nilüfer/Dumlupınar | I21: Orkhan Bey / 5387882843 | J21: Dumlupınar, Gülveren Cd. No 3a D:f, 16285 Nilüfer/Bursa | L21: 34 | M21: =VLOOKUP(E21,'Hedef Liste'!A:I,8,false) -> #N/A | N21: FALSE | O21: FALSE
A22: =E22 -> 5f9c3c6346f1ccdda9012da3 | C22: Okan Yazıcı | E22: 5f9c3c6346f1ccdda9012da3 | F22: Abad Izgara Tavuk, Nilüfer (Görükle Mah.) | G22: 16:30 | H22: Nilüfer/Dumlupınar | I22: Orkhan Bey / 5387882843 | J22: Dumlupınar, Gülveren Cd. No 3a D:f, 16285 Nilüfer/Bursa | L22: 11 | M22: =VLOOKUP(E22,'Hedef Liste'!A:I,8,false) -> #N/A | N22: FALSE | O22: FALSE
A23: =E23 | C23: 44253
A24: =E24 | N24: FALSE | O24: FALSE
A25: =E25 -> 5f89ec2cf3a2617e0116e56c | B25: Nilüfer | C25: Okan Yazıcı | E25: 5f89ec2cf3a2617e0116e56c | F25: Tacos House Nilüfer (Görükle Mah.) | G25: 0.4375 | H25: Nilüfer / Dumlupınar | I25: Ali Osman Bey / 5367083340 | J25: Dumlupınar Mah. Selanik Cad. C Blok No:2 C/B Nilüfer / BURSA | L25: 4 | M25: =VLOOKUP(E25,'Hedef Liste'!A:I,8,false) -> 16 | N25: FALSE | O25: FALSE
A26: =E26 -> 5fe70f4912b7157194a3e7b7 | C26: Okan Yazıcı | E26: 5fe70f4912b7157194a3e7b7 | F26: Ataköy Çorbacısı ( Görükle Mah. ) | G26: 0.5 | H26: Nilüfer / Dumlupınar | I26: Adil Bey / 5300524029 | J26: DUMLUPINAR MAH. MEHTAP(500) SK. NO: 1 B İÇ KAPI NO: 1 NİLÜFER/ BURSA | L26: 40 | M26: =VLOOKUP(E26,'Hedef Liste'!A:I,8,false) -> #N/A | N26: FALSE | O26: FALSE
A27: =E27 -> 5fdc9d0151fcae23bf932d49 | C27: Okan Yazıcı | E27: 5fdc9d0151fcae23bf932d49 | F27: Bursam Yöresel Tatlılar, Nilüfer (Görükle Mah.) | G27: 14:00 | H27: Nilüfer/Dumlupınar | I27: Ömer Bey / 5334656393 | J27: Dumlupınar, İskele Sk. No:11, 16100 Nilüfer/Bursa | L27: 4 | M27: =VLOOKUP(E27,'Hedef Liste'!A:I,8,false) -> 1 | N27: FALSE | O27: FALSE
A28: =E28 -> 5f2a60ebd93dda939adfd661 | C28: Okan Yazıcı | E28: 5f2a60ebd93dda939adfd661 | F28: Tarihi Sürmene Pilavcısı (Görükle Mah.) | G28: 0.58333333 | H28: Nilüfer/Dumlupınar | I28: Ömer Bey / 5334656393 | J28: Dumlupınar, İskele Sk. No:11, 16100 Nilüfer/Bursa | L28: 54 | M28: =VLOOKUP(E28,'Hedef Liste'!A:I,8,false) -> 11 | N28: FALSE | O28: FALSE
A29: =E29 -> 5f99a7246d4572ecf0865f21 | C29: Okan Yazıcı | E29: 5f99a7246d4572ecf0865f21 | F29: Lokma & Sweet, Nilüfer (Görükle Mah.) | G29: 16:00 | H29: Nilüfer/Görükle | I29: Onur Bey / 5436649775 | J29: Görükle Mah. Atatürk Bulvarı Yeşilova Sit. No: 4 / A Nilüfer / Bursa | L29: 26 | M29: =VLOOKUP(E29,'Hedef Liste'!A:I,8,false) -> 16 | N29: FALSE | O29: FALSE
A30: =E30 | C30: 44256
A31: =E31 | N31: FALSE | O31: FALSE
A32: =E32 -> 5f8afff5850babf36035123f | B32: Nilüfer | C32: Okan Yazıcı | D32: Mertcan | E32: 5f8afff5850babf36035123f | F32: Maydanoz Döner (Görükle Mah.) | G32: 0.5 | H32: Nilüfer / Görükle | I32: Neziyha Baykal / 2249990587 | J32: Dumlupınar Mah. Gelibolu Cad. No:44 D Blok Nilüfer Bursa/Görükle | L32: 5 | M32: =VLOOKUP(E32,'Hedef Liste'!A:I,8,false) -> 9 | N32: FALSE | O32: FALSE
C33: Okan Yazıcı | D33: Mertcan | E33: 5f96f8d4cb8e8dc51fd7fa06 | F33: Şehzade Ev Yemekleri (Görükle Mah.) | G33: 0.58333333 | H33: Nilüfer / Dumlupınar | I33: Fatih Bey / 2244835765 | J33: Dumlupınar Mah. Atatürk (500) Cad. A Blok No:96 A İç Kapı No:4 Nilüfer / Bursa | K33: İptal sebebi : restorantı o anda yogunmuş . Tekrar Rand. oluşturulmuş. | M33: =VLOOKUP(E33,'Hedef Liste'!A:I,8,false) -> 8 | N33: FALSE | O33: TRUE
A34: =E34 | C34: Okan Yazıcı | M34: =VLOOKUP(E304,'Hedef Liste'!A:I,8,false) -> 45 | N34: FALSE | O34: FALSE
A35: =E35 -> 5fb8e56a4da10631737ad4e5 | C35: Okan Yazıcı | E35: 5fb8e56a4da10631737ad4e5 | F35: Konya Mutfağı ( 23 Nisan Mah.) | G35: 16:30 | H35: Nilüfer / 23 Nisan | I35: Levent Bey / 2244434542 | J35: 23 Nisan Mah. 75. yıl Bulvarı no 3 a | L35: 18 | M35: =VLOOKUP(E35,'Hedef Liste'!A:I,8,false) -> 43 | N35: FALSE | O35: FALSE
A36: =E36 -> 5fa455fed0f0f7001443f111 | C36: Okan Yazıcı | D36: Enes | E36: 5fa455fed0f0f7001443f111 | F36: Aztec Coffee | G36: 14:00 | H36: Nilüfer / Dumlupınar | I36: Mehmet Bey / 5422837240 | J36: Dumlupınar, Adapark sitesi, Doluca Sk. 2b, 16240 Nilüfer/Bursa | L36: 39 | M36: =VLOOKUP(E36,'Hedef Liste'!A:I,8,false) -> 119 | N36: FALSE | O36: FALSE
A37: =E37 | C37: 44257
A38: =E38 | N38: FALSE | O38: FALSE
A39: =E39 | B39: Nilüfer | M39: =VLOOKUP(E47,'Hedef Liste'!A:I,8,false) -> 4 | N39: FALSE | O39: FALSE
A40: =E40 -> 5fe337a4879562b335ccd438 | C40: Okan Yazıcı | E40: 5fe337a4879562b335ccd438 | F40: İkizler Hasan Ustam, Nilüfer (Konak Mah.) | G40: 0.5625 | H40: Nilüfer/konak | I40: EMEL AÇAR/2244528080/Yavuz bey 5363136131 | J40: Konak Mah. yıldırım cad. No 19/ a NİLÜFER/ BURSA | L40: 37 | M40: =VLOOKUP(E40,'Hedef Liste'!A:I,8,false) -> 3 | N40: FALSE | O40: FALSE
...

Sheet Hedef Liste
A1: Restaurant ID | B1: Restoran Adı | C1: Satışa Açık Mı? | D1: Mutfak | E1: TOPLAM SİPARİŞ | F1: SON 2 HAFTA | G1: RESİMLİ ÜRÜN | H1: RESİMSİZ ÜRÜN | I1: TOPLAM ÜRÜN | J1: Ratio | K1: Yetkili | L1: Telefon | M1: İLÇE | N1: MAHALLE | O1: ADRES | P1: Geleneksel Zincir | Q1: Telefon 2 | R1: Aradık Mı? | S1: Kendi Fotosu Var | T1: Randevu Durumu | U1: Randevu Alan | V1: Fotoğrafçı | W1: Not | X1: Randevu Alma Tarihi | Y1: Randevu Tarihi | Z1: Anket Durum | AA1: 1. Arama | AB1: 1. Arama Tarihi | AC1: 2. Arama | AD1: 2. Arama Tarihi | AE1: 3. Arama | AF1: 3. Arama Tarihi | AG1: 4. Arama | AH1: 4. Arama Tarihi | AI1: 5. Arama | AJ1: 5. Arama Tarihi | AK1: 1. Arayan | AL1: 2. Arayan | AM1: 3. Arayan | AN1: 4. Arayan | AO1: 5. Arayan | AP1: SY | AQ1: SY - Durum
A2: 6065701b2b0371904cddc921 | B2: 01 Güney Tantuni Nilüfer (23 Nisan Mah.) | C2: =VLOOKUP(A2,import!A:C,3,false) -> DOĞRU | D2: Sokak Lezzetleri | E2: =VLOOKUP(A2,import!A:J,5,0) -> 3421 | F2: =VLOOKUP(A2,import!A:J,6,0) -> 177 | G2: =VLOOKUP(A2,import!A:J,7,0) -> 9 | H2: =VLOOKUP(A2,import!A:J,8,0) -> 8 | I2: =VLOOKUP(A2,import!A:J,9,0) -> 17 | J2: =VLOOKUP(A2,import!A:J,10,0) -> 0.53 | K2: ŞÜKRÜ GEZDİM | L2: 5392092343 | M2: Nilüfer | N2: 44309 | O2: 23 NİSAN MAH. 253. SK. A BLOK NO: 10 A NİLÜFER/ BURSA | P2: =VLOOKUP(A2,import!A:P,16,0) -> Geleneksel | R2: TRUE | S2: FALSE | T2: Randevu Alındı | U2: Ezgi Turan | V2: Alper Gökdemir | X2: 44302 | Y2: 44302 | AP2: Furkan Çağdaş Kuloğlu
A3: 616d96b36556b4255ed7731c | B3: 1 Ankara Dönercisi, Nilüfer ( Görükle Mah.) | C3: =VLOOKUP(A3,import!A:C,3,false) -> DOĞRU | D3: Döner | E3: =VLOOKUP(A3,import!A:J,5,0) -> 502 | F3: =VLOOKUP(A3,import!A:J,6,0) -> 72 | G3: =VLOOKUP(A3,import!A:J,7,0) -> 0 | H3: =VLOOKUP(A3,import!A:J,8,0) -> 20 | I3: =VLOOKUP(A3,import!A:J,9,0) -> 20 | J3: =VLOOKUP(A3,import!A:J,10,0) -> 0 | K3: Tolga Halat | L3: 5416370229 | M3: Nilüfer | N3: Görükle | O3: Görükle Mah. Kardelen Cad. No:17 A Nilüfer / Bursa | P3: Geleneksel | R3: TRUE | S3: FALSE | T3: Çekim İstemiyor | W3: şuan düşünmüyorum dedi / şuan istemiyorum daha öncede dedim dedi | AA3: Görüşüldü | AB3: 44494 | AC3: Tekrar Aranacak | AD3: 44496 | AE3: Görüşüldü | AF3: 44501 | AG3: Görüşüldü | AH3: 44519 | AK3: Ferhat Köksal | AL3: Tuğba Buyur | AM3: Ezgi Turan | AN3: Betül Demir | AP3: Hakan Özler
A4: 60cd9b99a761103d1155a701 | B4: 1 Lezzet Yaprak Döner, Osmangazi (Fatih Mah.) | C4: =VLOOKUP(A4,import!A:C,3,false) -> DOĞRU | D4: Döner | E4: =VLOOKUP(A4,import!A:J,5,0) -> 270 | F4: =VLOOKUP(A4,import!A:J,6,0) -> 1 | G4: =VLOOKUP(A4,import!A:J,7,0) -> 3 | H4: =VLOOKUP(A4,import!A:J,8,0) -> 1 | I4: =VLOOKUP(A4,import!A:J,9,0) -> 4 | J4: =VLOOKUP(A4,import!A:J,10,0) -> 0.75 | K4: LALELİ YEMEK TARIM ÜRÜNLERİ HAYVANCILIK GID.SAN.TİC VE LTD.ŞTİ | L4: 5418561676 | M4: Osmangazi | N4: Fatih | O4: Fatih Mah/Semt 1.Meram Sk. No: 2 Osmangazi/ Bursa | P4: =VLOOKUP(A4,import!A:P,16,0) -> Geleneksel | R4: TRUE | S4: FALSE | T4: Randevu Alındı | U4: Ayşegül Dulkadir | V4: Alper Gökdemir | X4: 44375 | Y4: 44377 | AA4: Görüşüldü | AB4: 44375 | AK4: Ayşegül Dulkadir | AP4: Zuhal Kocabıçak
A5: 614d98e9d439820bc8499796 | B5: 1 Tat Fast Food, Mudanya (Güzeyalı Mah.) | C5: =VLOOKUP(A5,import!A:C,3,false) -> DOĞRU | D5: Tost & Sandviç | E5: =VLOOKUP(A5,import!A:J,5,0) -> 231 | F5: =VLOOKUP(A5,import!A:J,6,0) -> 19 | G5: =VLOOKUP(A5,import!A:J,7,0) -> 0 | H5: =VLOOKUP(A5,import!A:J,8,0) -> 28 | I5: =VLOOKUP(A5,import!A:J,9,0) -> 28 | J5: =VLOOKUP(A5,import!A:J,10,0) -> 0 | K5: İBRAHİM HALİL ZENCİRLİ | L5: 5558924525 | M5: Mudanya | N5: Güzelyalı Yalı | O5: güzelyalı Yalı mah. atatürk cad. no 121 | P5: =VLOOKUP(A5,import!A:P,16,0) -> Geleneksel | R5: TRUE | S5: TRUE | W5: mail verildi | AA5: Ulaşılamadı | AB5: 44504 | AC5: Görüşüldü | AD5: 44504 | AK5: Sude Alkan | AL5: Sude Alkan | AP5: Furkan Çağdaş Kuloğlu
A6: 609a93310c17448a0f23bf61 | B6: 10 Bull's Burger, Nilüfer (Görükle Mah.) | C6: =VLOOKUP(A6,import!A:C,3,false) -> DOĞRU | D6: Burger | E6: =VLOOKUP(A6,import!A:J,5,0) -> 9347 | F6: =VLOOKUP(A6,import!A:J,6,0) -> 415 | G6: =VLOOKUP(A6,import!A:J,7,0) -> 24 | H6: =VLOOKUP(A6,import!A:J,8,0) -> 7 | I6: =VLOOKUP(A6,import!A:J,9,0) -> 31 | J6: =VLOOKUP(A6,import!A:J,10,0) -> 0.77 | K6: EBRU DOĞRU | L6: 5424080565 | M6: Nilüfer | N6: Dumlupınar | O6: Dumlupınar Mah. Tarabya Cad. No 5 | P6: =VLOOKUP(A6,import!A:P,16,0) -> Geleneksel | R6: TRUE | S6: FALSE | T6: Randevu Alındı | U6: Duygu Telli | V6: Alper Gökdemir | W6: dç perşembe randevu alınacak | X6: 44428 | Y6: 44433 | AC6: Görüşüldü | AD6: 44428 | AE6: Tekrar Aranacak | AF6: 44434 | AG6: Ulaşılamadı | AH6: 44435 | AI6: Görüşüldü | AJ6: 44436 | AL6: Duygu Telli | AM6: Deneme | AN6: Deneme | AP6: Furkan Çağdaş Kuloğlu
A7: 60cda7265d9a80560a976b7f | B7: 10 Fil Döner, Nilüfer (Cumhuriyet Mah.) | C7: =VLOOKUP(A7,import!A:C,3,false) -> YANLIŞ | D7: Döner | E7: =VLOOKUP(A7,import!A:J,5,0) -> 3004 | F7: =VLOOKUP(A7,import!A:J,6,0) | G7: =VLOOKUP(A7,import!A:J,7,0) -> 25 | H7: =VLOOKUP(A7,import!A:J,8,0) -> 14 | I7: =VLOOKUP(A7,import!A:J,9,0) -> 39 | J7: =VLOOKUP(A7,import!A:J,10,0) -> 0.64 | K7: ALİ İHSAN ATAR | L7: 2244500065 | M7: Nilüfer | N7: Cumhuriyet | O7: Cumhuriyet Mah., Selin Sitesi, No:D Blok, Nilüfer, Bursa, Türkiye, | P7: =VLOOKUP(A7,import!A:P,16,0) -> Geleneksel | R7: TRUE | S7: TRUE | U7: Mertcan karaman | V7: hamdican | W7: yüzüme kapattı | X7: 44411 | Y7: 44414 | AA7: Görüşüldü | AB7: 44410 | AC7: Görüşüldü | AD7: 44411 | AE7: Görüşüldü | AG7: Görüşüldü | AH7: 44419 | AI7: Tekrar Aranacak | AJ7: 44434 | AK7: Derya Tatlı | AL7: Mertcan karaman | AN7: Deneme | AP7: Furkan Çağdaş Kuloğlu
A8: 60b63875c17ff7c8b64732b5 | B8: 10 Fil Döner, Nilüfer (Görükle Mah.) | C8: =VLOOKUP(A8,import!A:C,3,false) -> DOĞRU | D8: Döner | E8: =VLOOKUP(A8,import!A:J,5,0) -> 9375 | F8: =VLOOKUP(A8,import!A:J,6,0) -> 388 | G8: =VLOOKUP(A8,import!A:J,7,0) -> 21 | H8: =VLOOKUP(A8,import!A:J,8,0) -> 5 | I8: =VLOOKUP(A8,import!A:J,9,0) -> 26 | J8: =VLOOKUP(A8,import!A:J,10,0) -> 0.81 | K8: FARUK TAHTALI | L8: 2244800018 | M8: Nilüfer | N8: Dumlupınar | O8: Dumlupınar mahallesi Selanik cadde no35/D | P8: =VLOOKUP(A8,import!A:P,16,0) -> Geleneksel | R8: TRUE | S8: FALSE | T8: Franchise | W8: ulaşılamadı-05534382288 | AA8: Ulaşılamadı | AB8: 44355 | AK8: Ezgi Turan | AP8: Furkan Çağdaş Kuloğlu
A9: 6123e6661ccf6f7101a3d036 | B9: 10 Fil Dönerrrrr, Nilüfer (29 Ekim Mah.) | C9: =VLOOKUP(A9,import!A:C,3,false) -> DOĞRU | D9: Döner | E9: =VLOOKUP(A9,import!A:J,5,0) -> 2893 | F9: =VLOOKUP(A9,import!A:J,6,0) -> 193 | G9: =VLOOKUP(A9,import!A:J,7,0) -> 23 | H9: =VLOOKUP(A9,import!A:J,8,0) -> 7 | I9: =VLOOKUP(A9,import!A:J,9,0) -> 30 | J9: =VLOOKUP(A9,import!A:J,10,0) -> 0.77 | K9: ENİSE ÖNEMLİ | L9: 5529226455 | M9: Nilüfer | N9: 44498 | O9: 29 ekim mahallesi cavit orhan tütengil caddesi A blok no:16A/B Nilüfer Bursa | P9: =VLOOKUP(A9,import!A:P,16,0) -> Geleneksel | R9: TRUE | S9: FALSE | T9: Randevu Alındı | U9: Ezgi Turan | V9: Alper Gökdemir | X9: 44441 | Y9: 44441 | AA9: Görüşüldü | AB9: 44441 | AK9: Ezgi Turan | AP9: Furkan Çağdaş Kuloğlu
A10: 5fb69e473a023211f821b345 | B10: 1991 Tarihi Ortaköy Kumpircisi & Waffle & Mantı ( Balat Mah ) | C10: =VLOOKUP(A10,import!A:C,3,false) -> DOĞRU | D10: Sokak Lezzetleri | E10: =VLOOKUP(A10,import!A:J,5,0) -> 937 | F10: =VLOOKUP(A10,import!A:J,6,0) -> 16 | G10: =VLOOKUP(A10,import!A:J,7,0) -> 4 | H10: =VLOOKUP(A10,import!A:J,8,0) -> 31 | I10: =VLOOKUP(A10,import!A:J,9,0) -> 35 | J10: =VLOOKUP(A10,import!A:J,10,0) -> 0.11 | K10: Seniye Katılmış | L10: 5414877429 | M10: Nilüfer | N10: Ahmet Yesevi | O10: ahmet yesevi mah. Bey sokak no 4 / B / C | P10: =VLOOKUP(A10,import!A:P,16,0) -> Geleneksel | Q10: 35+ | R10: TRUE | S10: FALSE | T10: Franchise | W10: ahmet bey ile görüşüldü. eksikleri ben mail atarım dediler. mail verildi. | AA10: Görüşüldü | AB10: 44440 | AK10: Gül Değirmenci | AP10: Furkan Çağdaş Kuloğlu
A11: 5f340d9c4c2c7718b137c273 | B11: 1991 Tarihi Ortaköy Kumpircisi, Gemlik (Hamidiye Mah.) | C11: =VLOOKUP(A11,import!A:C,3,false) -> DOĞRU | D11: Sokak Lezzetleri | E11: =VLOOKUP(A11,import!A:J,5,0) -> 1406 | F11: =VLOOKUP(A11,import!A:J,6,0) -> 22 | G11: =VLOOKUP(A11,import!A:J,7,0) -> 9 | H11: =VLOOKUP(A11,import!A:J,8,0) -> 32 | I11: =VLOOKUP(A11,import!A:J,9,0) -> 41 | J11: =VLOOKUP(A11,import!A:J,10,0) -> 0.22 | K11: Seda Akaç | L11: 5541913228 | M11: Gemlik | N11: Hamidiye | O11: Hamidiye, Yalı Ap, Kumsal Sk. No:15/A, 16600 Gemlik/Bursa | P11: =VLOOKUP(A11,import!A:P,16,0) -> Geleneksel | Q11: 35+ | R11: TRUE | S11: FALSE | T11: Franchise | AP11: Furkan Çağdaş Kuloğlu
A12: 5fafcc7a12b47973bd4cb881 | B12: 1991 Tarihi Ortaköy Kumpiricisi ( 23 Nisan ) | C12: =VLOOKUP(A12,import!A:C,3,false) -> DOĞRU | D12: Sokak Lezzetleri | E12: =VLOOKUP(A12,import!A:J,5,0) -> 1830 | F12: =VLOOKUP(A12,import!A:J,6,0) -> 53 | G12: =VLOOKUP(A12,import!A:J,7,0) -> 6 | H12: =VLOOKUP(A12,import!A:J,8,0) -> 43 | I12: =VLOOKUP(A12,import!A:J,9,0) -> 49 | J12: =VLOOKUP(A12,import!A:J,10,0) -> 0.12 | K12: Gülşah Berkan | L12: 2244411710 | M12: Nilüfer | N12: 44309 | O12: 23 Nisan Mah. 254. sokak a blok no 2 a/a | P12: =VLOOKUP(A12,import!A:P,16,0) -> Geleneksel | Q12: 35+ | R12: TRUE | S12: FALSE | T12: Franchise | AK12: Nazlıcan Dinçer | AP12: Furkan Çağdaş Kuloğlu
A13: 5fa2cbcccd7959cc76d320ec | B13: 1991 Tarihi Ortaköy Kumpiricisi ( Altınşehir ) | C13: =VLOOKUP(A13,import!A:C,3,false) -> DOĞRU | D13: Pasta & Tatlı | E13: =VLOOKUP(A13,import!A:J,5,0) -> 774 | F13: =VLOOKUP(A13,import!A:J,6,0) -> 17 | G13: =VLOOKUP(A13,import!A:J,7,0) -> 29 | H13: =VLOOKUP(A13,import!A:J,8,0) -> 16 | I13: =VLOOKUP(A13,import!A:J,9,0) -> 45 | J13: =VLOOKUP(A13,import!A:J,10,0) -> 0.64 | K13: Burcu Budak | L13: 2245022828 | M13: Nilüfer | N13: Özlüce | O13: Altınşehir Mah. Abdipekçi Caddesi b/48 Firuze tarihi ortaköy kumpircisi | P13: =VLOOKUP(A13,import!A:P,16,0) -> Geleneksel | Q13: 35+ | R13: TRUE | S13: FALSE | T13: Randevu Alındı | U13: Ezgi Turan | V13: Alper Gökdemir | W13: devam çekimi talep etmiyor | X13: 44295 | Y13: 44299 | AA13: Tekrar Aranacak | AB13: 44418 | AC13: Görüşüldü | AD13: 44384 | AE13: Görüşüldü | AF13: 44439 | AK13: Zeliha Özer | AL13: Tutku Erdoğan | AM13: Ferhat Köksal | AO13: Sude Alkan | AP13: Zuhal Kocabıçak
A14: 6202601046efdf498165a5e9 | B14: 20 m2 Sosisli, Osmangazi (Demirtaş Cumhuriyet Mah.) | C14: =VLOOKUP(A14,import!A:C,3,false) -> DOĞRU | D14: Sokak Lezzetleri | E14: =VLOOKUP(A14,import!A:J,5,0) | F14: =VLOOKUP(A14,import!A:J,6,0) | G14: =VLOOKUP(A14,import!A:J,7,0) -> 0 | H14: =VLOOKUP(A14,import!A:J,8,0) -> 21 | I14: =VLOOKUP(A14,import!A:J,9,0) -> 21 | J14: =VLOOKUP(A14,import!A:J,10,0) -> 0 | K14: Emre Parmaksız | L14: 5316748752 | M14: Osmangazi | N14: Demirtaş Cumhuriyet | O14: Demirtaş Cumhuriyet Mah. 3. Cad. L Blok No:20 2/1 Osmangazi / Bursa | P14: =VLOOKUP(A14,import!A:P,16,0) -> Geleneksel | R14: TRUE | S14: TRUE | T14: Çekim İstemiyor | U14: Ferhat Köksal | V14: Alper Gökdemir | W14: işletme müdürü ferdi beyden randevu alındı | X14: 44618 | Y14: 44619 | AA14: Görüşüldü | AB14: 44618 | AK14: Ferhat Köksal
A15: 60cdf42dc1b0a308ad9e5e94 | B15: 20 m2 Sosisli, Osmangazi (Kayıhan Mah.) | C15: =VLOOKUP(A15,import!A:C,3,false) -> DOĞRU | D15: Sokak Lezzetleri | E15: =VLOOKUP(A15,import!A:J,5,0) -> 118 | F15: =VLOOKUP(A15,import!A:J,6,0) -> 6 | G15: =VLOOKUP(A15,import!A:J,7,0) -> 0 | H15: =VLOOKUP(A15,import!A:J,8,0) -> 14 | I15: =VLOOKUP(A15,import!A:J,9,0) -> 14 | J15: =VLOOKUP(A15,import!A:J,10,0) -> 0 | K15: EMRE PARMAKSIZ | L15: 2242256224 | M15: Osmangazi | N15: Kayıhan | O15: Kayihan mahallesi ünlü cadde no 15A Osmangazi/BURSA | P15: =VLOOKUP(A15,import!A:P,16,0) -> Geleneksel | R15: TRUE | S15: FALSE | T15: Ulaşılamadı | W15: açmıyor / AÇMADI - ulaşılamadı - ulaşılamadı | AA15: Ulaşılamadı | AB15: 44378 | AC15: Ulaşılamadı | AD15: 44389 | AE15: Ulaşılamadı | AF15: 44411 | AG15: Ulaşılamadı | AH15: 44492 | AI15: Ulaşılamadı | AJ15: 44517 | AK15: Ayşegül Dulkadir | AL15: Derya Tatlı | AM15: Özlem Güner | AN15: Hatem Soyaslan | AO15: Ferhat Köksal | AP15: Furkan Çağdaş Kuloğlu
A16: 6255ba54f6892a49e26e0ea4 | B16: 3 Kardeşler Group Tantuni Yaprak Döner, Osmangazi (Ulu Mah.) | C16: =VLOOKUP(A16,import!A:C,3,false) -> DOĞRU | D16: Döner | E16: =VLOOKUP(A16,import!A:J,5,0) -> 69 | F16: =VLOOKUP(A16,import!A:J,6,0) -> 57 | G16: =VLOOKUP(A16,import!A:J,7,0) -> 0 | H16: =VLOOKUP(A16,import!A:J,8,0) -> 20 | I16: =VLOOKUP(A16,import!A:J,9,0) -> 20 | J16: =VLOOKUP(A16,import!A:J,10,0) -> 0 | K16: ÜÇ KARDEŞLER GROUP GIDA SANAYİ VE TİCARET LİMİTED ŞİRKETİ | L16: 2242521195 | M16: Osmangazi | N16: Ulu | O16: Ulu Mah. Kıbrıs Şehitleri Cad. No: 109 Osmangazi | P16: =VLOOKUP(A16,import!A:P,16,0) -> Geleneksel | R16: FALSE | S16: FALSE
A17: 5f351858b0d244ce3f801c0c | B17: 33 Suat Usta Mersin Tantuni, Nilüfer (Görükle Mah.) | C17: =VLOOKUP(A17,import!A:C,3,false) -> DOĞRU | D17: Sokak Lezzetleri | E17: =VLOOKUP(A17,import!A:J,5,0) -> 25824 | F17: =VLOOKUP(A17,import!A:J,6,0) -> 661 | G17: =VLOOKUP(A17,import!A:J,7,0) -> 6 | H17: =VLOOKUP(A17,import!A:J,8,0) -> 22 | I17: =VLOOKUP(A17,import!A:J,9,0) -> 28 | J17: =VLOOKUP(A17,import!A:J,10,0) -> 0.21 | K17: Fatih Sali | L17: 5399392129 | M17: Nilüfer | N17: Görükle | O17: Görükle, Bariş Sk, 16110 Nilüfer/Bursa | P17: =VLOOKUP(A17,import!A:P,16,0) -> Geleneksel | Q17: 16-25 | R17: TRUE | S17: FALSE | T17: Randevu Alındı | U17: Ezgi Turan | V17: Okan Yazıcı | W17: 5349314239 devam çekimi istemiyorlar/1 ay sonra aransın menüye yeniler eklenecek/1 ay sonra aransın | X17: 44303 | Y17: 44305 | AA17: Tekrar Aranacak | AB17: 44378 | AC17: Görüşüldü | AD17: 44390 | AE17: Tekrar Aranacak | AF17: 44412 | AG17: Görüşüldü | AH17: 44417 | AI17: Ulaşılamadı | AJ17: 44522 | AK17: Ezgi Turan | AL17: Mavi Arslan | AM17: Duygu Telli | AN17: Duygu Telli | AO17: Tuğba Buyur | AP17: Hakan Özler
A18: 61adf65d041d10e59e79ae8f | B18: 4 Bros Burger, Nilüfer (Balat Mah.) | C18: =VLOOKUP(A18,import!A:C,3,false) -> DOĞRU | D18: Burger | E18: =VLOOKUP(A18,import!A:J,5,0) -> 264 | F18: =VLOOKUP(A18,import!A:J,6,0) -> 16 | G18: =VLOOKUP(A18,import!A:J,7,0) -> 0 | H18: =VLOOKUP(A18,import!A:J,8,0) -> 36 | I18: =VLOOKUP(A18,import!A:J,9,0) -> 36 | J18: =VLOOKUP(A18,import!A:J,10,0) -> 0 | K18: 4 Bros Gıda Sanayi Ve Ticaret Limited Şirketi | L18: 2245041404 | M18: Nilüfer | N18: Balat | O18: Balat Mah. Bozkır Sk. Dikencik Meteor Evleri No:15-16 Nilüfer | P18: =VLOOKUP(A18,import!A:P,16,0) -> Geleneksel | R18: TRUE | S18: FALSE | T18: Başka Şubeden Çekilecek | W18: 29 ekim mah. işletmesindeki fotoğrafları kullanmak istiyor | AA18: Görüşüldü | AB18: 44543 | AK18: Ferhat Köksal | AP18: Zuhal Kocabıçak
A19: 6051f8f8118797393b4072a8 | B19: 7 Başak Börek, Osmangazi ( Dikkaldırım Mah.) | C19: =VLOOKUP(A19,import!A:C,3,false) -> DOĞRU | D19: Börek | E19: =VLOOKUP(A19,import!A:J,5,0) -> 975 | F19: =VLOOKUP(A19,import!A:J,6,0) -> 26 | G19: =VLOOKUP(A19,import!A:J,7,0) -> 3 | H19: =VLOOKUP(A19,import!A:J,8,0) -> 6 | I19: =VLOOKUP(A19,import!A:J,9,0) -> 9 | J19: =VLOOKUP(A19,import!A:J,10,0) -> 0.33 | K19: Şükrü Köse | L19: 5326381573 | M19: Osmangazi | N19: Dikkaldırım | O19: Dikkaldırım Mah. Dikkaldırım Cad. No:58 A Osamangazi / Bursa | P19: =VLOOKUP(A19,import!A:P,16,0) -> Geleneksel | R19: TRUE | S19: FALSE | T19: Randevu Alındı | U19: Emel Yılmaz | V19: t.y. | X19: 44292 | Y19: 44293 | AK19: Derya Tatlı | AO19: Mertcan karaman | AP19: Hakan Özler
A20: 60bf711716598a9ceecd2fb6 | B20: 7 İklim Döner, Yıldırım (Esenevler Mah.) | C20: =VLOOKUP(A20,import!A:C,3,false) -> DOĞRU | D20: Döner | E20: =VLOOKUP(A20,import!A:J,5,0) -> 463 | F20: =VLOOKUP(A20,import!A:J,6,0) -> 25 | G20: =VLOOKUP(A20,import!A:J,7,0) -> 0 | H20: =VLOOKUP(A20,import!A:J,8,0) -> 21 | I20: =VLOOKUP(A20,import!A:J,9,0) -> 21 | J20: =VLOOKUP(A20,import!A:J,10,0) -> 0 | K20: BİRSEL EKİZ | L20: 5372132516 | M20: Yıldırım | N20: Esenevler | O20: Esenevler Mh. Erikli Cd. 27 | P20: =VLOOKUP(A20,import!A:P,16,0) -> Geleneksel | R20: TRUE | S20: FALSE | T20: Çekim İstemiyor | W20: saat uygun olmadı/ 1 ay sonra aranacak- şuanda mesgul | Z20: Hemen Randevu İstiyorum | AA20: Tekrar Aranacak | AB20: 44392 | AC20: Ulaşılamadı | AD20: 44393 | AE20: Görüşüldü | AF20: 44410 | AG20: Yetkili Yok | AH20: 44411 | AI20: Görüşüldü | AJ20: 44494 | AL20: Tutku Erdoğan | AM20: Ezgi Turan | AN20: Deneme | AO20: Ezgi Turan | AP20: Furkan Çağdaş Kuloğlu
A21: 626883ff9c98ac5891443855 | B21: Aba Tost House, Nilüfer (Görükle Mah.) | C21: =VLOOKUP(A21,import!A:C,3,false) -> DOĞRU | D21: Tost & Sandviç | E21: =VLOOKUP(A21,import!A:J,5,0) -> 4 | F21: =VLOOKUP(A21,import!A:J,6,0) -> 4 | G21: =VLOOKUP(A21,import!A:J,7,0) -> 2 | H21: =VLOOKUP(A21,import!A:J,8,0) -> 77 | I21: =VLOOKUP(A21,import!A:J,9,0) -> 79 | J21: =VLOOKUP(A21,import!A:J,10,0) -> 0.03 | K21: Volkan Bredereke | L21: 5364574409 | M21: Nilüfer | N21: Görükle | O21: Görükle Mah., Taşkent Sok., No:14, Nilüfer, Bursa, Türkiye, | P21: =VLOOKUP(A21,import!A:P,16,0) -> Geleneksel | R21: FALSE | S21: FALSE
A22: 5f364665a886cd8bd548f5d7 | B22: Ababe Uygar Cafe, Nilüfer (Görükle Mah.) | C22: =VLOOKUP(A22,import!A:C,3,false) -> DOĞRU | D22: Tost & Sandviç | E22: =VLOOKUP(A22,import!A:J,5,0) -> 2067 | F22: =VLOOKUP(A22,import!A:J,6,0) -> 90 | G22: =VLOOKUP(A22,import!A:J,7,0) -> 5 | H22: =VLOOKUP(A22,import!A:J,8,0) -> 42 | I22: =VLOOKUP(A22,import!A:J,9,0) -> 47 | J22: =VLOOKUP(A22,import!A:J,10,0) -> 0.11 | K22: Erkut Kocabaş | L22: 5076451405 | M22: Nilüfer | N22: Dumlupınar | O22: Dumlupınar, Pamukkale Cd. No:27 D:B, 16285 Nilüfer/Bursa | P22: =VLOOKUP(A22,import!A:P,16,0) -> Geleneksel | Q22: 35+ | R22: TRUE | T22: Randevu Alındı | U22: Özlem Güner | V22: Hamdi Can | W22: 5327063031- dç istemez | X22: 44411 | Y22: 44413 | AA22: Tekrar Aranacak | AB22: 44355 | AC22: Görüşüldü | AD22: 44362 | AE22: Tekrar Aranacak | AF22: 44363 | AG22: Görüşüldü | AH22: 44364 | AI22: Dönüş Yapacak | AJ22: 44518 | AK22: Deneme | AL22: Gül Değirmenci | AM22: Ezgi Turan | AN22: Deneme | AO22: Tuğba Buyur | AP22: Furkan Çağdaş Kuloğlu
A23: 61154c77be8d2d3ec8606237 | B23: Abacus Tavuk (Görükle Mah.) | C23: =VLOOKUP(A23,import!A:C,3,false) -> DOĞRU | D23: Tavuk | E23: =VLOOKUP(A23,import!A:J,5,0) -> 1763 | F23: =VLOOKUP(A23,import!A:J,6,0) -> 158 | G23: =VLOOKUP(A23,import!A:J,7,0) -> 10 | H23: =VLOOKUP(A23,import!A:J,8,0) -> 68 | I23: =VLOOKUP(A23,import!A:J,9,0) -> 78 | J23: =VLOOKUP(A23,import!A:J,10,0) -> 0.13 | K23: Furkan Tosunoğlu | L23: 5522397317 | M23: Nilüfer | N23: Görükle | O23: Görükle Mah., Taşkent Sok., No:14, Nilüfer, Bursa, Türkiye, | P23: =VLOOKUP(A23,import!A:P,16,0) -> Geleneksel | R23: TRUE | S23: FALSE | T23: Randevu Alındı | U23: Sezer Arslan | V23: hamdi | W23: açmadı /cekım ıstemıyorlar gerıye kalan uurunlerı ıcın | X23: 44431 | Y23: 44434 | AA23: Ulaşılamadı | AB23: 44431 | AC23: Görüşüldü | AD23: 44431 | AE23: Ulaşılamadı | AF23: 44488 | AG23: Görüşüldü | AH23: 44489 | AK23: Dicle Harmancı | AL23: Sezer Arslan | AM23: Zeliha Özer | AN23: Selcan Topçu | AP23: Hakan Özler
A24: 613c514313a2a902b80b1a30 | B24: Abad Izgara Tavuk (Görükle Mah.) | C24: =VLOOKUP(A24,import!A:C,3,false) -> DOĞRU | D24: Tavuk | E24: =VLOOKUP(A24,import!A:J,5,0) | F24: =VLOOKUP(A24,import!A:J,6,0) | G24: =VLOOKUP(A24,import!A:J,7,0) -> 0 | H24: =VLOOKUP(A24,import!A:J,8,0) -> 19 | I24: =VLOOKUP(A24,import!A:J,9,0) -> 19 | J24: =VLOOKUP(A24,import!A:J,10,0) -> 0 | K24: NAZLI DENİZ EZGİ | L24: 2249992819 | M24: Nilüfer | N24: Dumlupınar | O24: DUMLUPINAR MAH. GÜLVEREN CAD. A BLOK NO: 3 A/F NİLÜFER/ BURSA | P24: =VLOOKUP(A24,import!A:P,16,0) -> Geleneksel | R24: TRUE | S24: FALSE | T24: Çekim İstemiyor | U24: Ezgi Turan | V24: HAMDİ | W24: ulaşılamadı | X24: 44463 | Y24: 44466 | AA24: Ulaşılamadı | AB24: 44482 | AK24: Ferhat Köksal | AP24: Hakan Özler
A25: 6262ab55987dd34202a14d5e | B25: Abant Tost & Gözleme, Nilüfer (Görükle Mah.) | C25: =VLOOKUP(A25,import!A:C,3,false) -> DOĞRU | D25: Tost & Sandviç | E25: =VLOOKUP(A25,import!A:J,5,0) -> 5 | F25: =VLOOKUP(A25,import!A:J,6,0) -> 5 | G25: =VLOOKUP(A25,import!A:J,7,0) -> 0 | H25: =VLOOKUP(A25,import!A:J,8,0) -> 11 | I25: =VLOOKUP(A25,import!A:J,9,0) -> 11 | J25: =VLOOKUP(A25,import!A:J,10,0) -> 0 | K25: AYŞE GÜL KUYUMCU | L25: 5411176537 | M25: Nilüfer | N25: Görükle | O25: Görükle Mah. Koza Cad. C Blok No: 6 C/A Nilüfer / Bursa | P25: =VLOOKUP(A25,import!A:P,16,0) -> Geleneksel | R25: FALSE | S25: FALSE
A26: 60e84d4b3e4ad3a3ba05edb3 | B26: Abarttık Çiğ Köfteci & Fast Food, Nilüfer (Dumlupınar Mah.) | C26: =VLOOKUP(A26,import!A:C,3,false) -> YANLIŞ | D26: Tost & Sandviç | E26: =VLOOKUP(A26,import!A:J,5,0) -> 146 | F26: =VLOOKUP(A26,import!A:J,6,0) | G26: =VLOOKUP(A26,import!A:J,7,0) -> 12 | H26: =VLOOKUP(A26,import!A:J,8,0) -> 8 | I26: =VLOOKUP(A26,import!A:J,9,0) -> 20 | J26: =VLOOKUP(A26,import!A:J,10,0) -> 0.6 | K26: MUSA FURKAN BAYIL | L26: 5370111496 | M26: Nilüfer | N26: Dumlupınar | O26: Dumlupınar mahallesi Bahariye caddesi sefaniye gündüz sitesi apt. No2/a nilüfer | P26: =VLOOKUP(A26,import!A:P,16,0) -> Geleneksel | R26: TRUE | S26: FALSE | T26: Randevu Alındı | V26: hamdi | X26: 44405 | Y26: 44407 | AA26: Görüşüldü | AB26: 44405 | AP26: Furkan Çağdaş Kuloğlu
A27: 5f9b1536c933834abf817896 | B27: Abc Pizza & Fast Food | C27: =VLOOKUP(A27,import!A:C,3,false) -> DOĞRU | D27: Pizza | E27: =VLOOKUP(A27,import!A:J,5,0) -> 5307 | F27: =VLOOKUP(A27,import!A:J,6,0) -> 112 | G27: =VLOOKUP(A27,import!A:J,7,0) -> 29 | H27: =VLOOKUP(A27,import!A:J,8,0) -> 20 | I27: =VLOOKUP(A27,import!A:J,9,0) -> 49 | J27: =VLOOKUP(A27,import!A:J,10,0) -> 0.59 | K27: YASEMİN CEYHAN | L27: 2249994135 | M27: Nilüfer | N27: Görükle | O27: GÖRÜKLE MAH. KOZA(490) CAD. ÖZİNAL-4 APT. NO: 46 A NİLÜFER/ BURSA | P27: =VLOOKUP(A27,import!A:P,16,0) -> Geleneksel | Q27: 35+ | R27: TRUE | S27: FALSE | T27: Randevu Alındı | U27: Nazlıcan Dinçer | V27: Alper Gökdemir | W27: açmadı | X27: 44287 | Y27: 44291 | AA27: Ulaşılamadı | AB27: 44496 | AC27: Ulaşılamadı | AD27: 44412 | AE27: Ulaşılamadı | AF27: 44434 | AK27: Nurhayat Kabataş | AL27: Duygu Telli | AM27: Deneme | AP27: Hakan Özler
A28: 5f29adfb83063085497055cc | B28: Abi Açız (Görükle Mah.) | C28: =VLOOKUP(A28,import!A:C,3,false) -> DOĞRU | D28: Börek | E28: =VLOOKUP(A28,import!A:J,5,0) -> 7221 | F28: =VLOOKUP(A28,import!A:J,6,0) -> 324 | G28: =VLOOKUP(A28,import!A:J,7,0) -> 31 | H28: =VLOOKUP(A28,import!A:J,8,0) -> 78 | I28: =VLOOKUP(A28,import!A:J,9,0) -> 109 | J28: =VLOOKUP(A28,import!A:J,10,0) -> 0.28 | K28: Muhammet Erat | L28: 5433144844 | M28: Nilüfer | N28: Görükle | O28: Görükle, Koza Cd., 16285 Nilüfer/Bursa | P28: =VLOOKUP(A28,import!A:P,16,0) -> Geleneksel | Q28: 35+ | R28: TRUE | S28: FALSE | T28: Randevu Alındı | U28: Ezgi Turan | V28: hamdican | W28: KESİNLİKLE AMA KESİNLİKLE ARAMAYIN!!!!!!!!/fotoğrafları göndermişler/hıc musaıt degılım kapatmak zorundayım dedı | X28: 44469 | Y28: 44470 | AA28: Görüşüldü | AB28: 44362 | AC28: Ulaşılamadı | AD28: 44389 | AE28: Görüşüldü | AF28: 44393 | AG28: Görüşüldü | AH28: 44469 | AI28: Görüşüldü | AJ28: 44522 | AK28: Tutku Erdoğan | AL28: Dicle Harmancı | AM28: Tutku Erdoğan | AN28: Ezgi Turan | AO28: Tuğba Buyur | AP28: Hakan Özler
A29: 61c4e26546db4eefa91489b3 | B29: Abişoğlu Patisserie & Cafe, Nilüfer (Görükle Mah.) | C29: =VLOOKUP(A29,import!A:C,3,false) -> DOĞRU | D29: Pasta & Tatlı | E29: =VLOOKUP(A29,import!A:J,5,0) -> 1568 | F29: =VLOOKUP(A29,import!A:J,6,0) -> 218 | G29: =VLOOKUP(A29,import!A:J,7,0) -> 56 | H29: =VLOOKUP(A29,import!A:J,8,0) -> 25 | I29: =VLOOKUP(A29,import!A:J,9,0) -> 81 | J29: =VLOOKUP(A29,import!A:J,10,0) -> 0.69 | K29: Ali Taş | L29: 2244834096 | M29: Nilüfer | N29: Dumlupınar | O29: Görükle Mah. Atatürk Cad. Yeşiloba Sit. E Blok No:86 E/A İç Kapı No:1 Nilüfer Bursa | P29: =VLOOKUP(A29,import!A:P,16,0) -> Geleneksel | R29: TRUE | S29: FALSE | T29: Randevu Alındı | U29: Kübra Toprak | V29: Alper Gökdemir | W29: yetkili yok barış bey ilgileniyormuş 4 den sonra geliyormuş. barış bey :05439406149 / BARIŞ BEYDEN RANDEVU ALINDI. | X29: 44565 | Y29: 44567 | AA29: Yetkili Yok | AB29: 44565 | AC29: Görüşüldü | AD29: 44565 | AK29: Kübra Toprak | AL29: Kübra Toprak
A30: 5f351fd2bee2878e2a543d9b | B30: Abla Eli Tost & Kumru, Nilüfer (Görükle Mah.) | C30: =VLOOKUP(A30,import!A:C,3,false) -> YANLIŞ | D30: Tost & Sandviç | E30: =VLOOKUP(A30,import!A:J,5,0) -> 7081 | F30: =VLOOKUP(A30,import!A:J,6,0) | G30: =VLOOKUP(A30,import!A:J,7,0) -> 2 | H30: =VLOOKUP(A30,import!A:J,8,0) -> 7 | I30: =VLOOKUP(A30,import!A:J,9,0) -> 9 | J30: =VLOOKUP(A30,import!A:J,10,0) -> 0.22 | K30: Elşan Sungur | L30: 5053752166 | M30: Nilüfer | N30: Görükle | O30: Görükle, As acar sitesi, Bahriye Üçok Cd. 37 /A, 16285 Nilüfer/Bursa | P30: =VLOOKUP(A30,import!A:P,16,0) -> Geleneksel | Q30: 35+ | R30: TRUE | S30: FALSE | T30: Randevu Alındı | U30: Ezgi Turan | V30: hamdi | W30: devam çekimi alındı 5532714925/Önder bey/ tüm ürünler çekilmiş | X30: 44442 | Y30: 44445 | AA30: Görüşüldü | AB30: 44362 | AC30: Görüşüldü | AD30: 44370 | AE30: Ulaşılamadı | AF30: 44412 | AG30: Görüşüldü | AH30: 44424 | AK30: Gül Değirmenci | AL30: Tutku Erdoğan | AM30: Duygu Telli | AN30: Sezer Arslan | AP30: Hakan Özler
A31: 60ec64a231e8d1ca239ba21d | B31: Ablanın Pilavı, Nilüfer (Görükle Mah.) | C31: =VLOOKUP(A31,import!A:C,3,false) -> DOĞRU | D31: Sokak Lezzetleri | E31: =VLOOKUP(A31,import!A:J,5,0) -> 283 | F31: =VLOOKUP(A31,import!A:J,6,0) -> 25 | G31: =VLOOKUP(A31,import!A:J,7,0) -> 0 | H31: =VLOOKUP(A31,import!A:J,8,0) -> 14 | I31: =VLOOKUP(A31,import!A:J,9,0) -> 14 | J31: =VLOOKUP(A31,import!A:J,10,0) -> 0 | K31: Kadir Yelim | L31: 5453630016 | M31: Nilüfer | N31: Görükle | O31: Görükle Mah. Atatürk Cad. Yerleşim B Blok Karanfil No:87 İç Kapı No:41 B/L Nilüfer / Bursa | P31: =VLOOKUP(A31,import!A:P,16,0) -> Geleneksel | R31: TRUE | S31: FALSE | T31: Çekim İstemiyor | V31: Alper Gökdemir | W31: Açmıyorrr-istemiyorum dedi yüzüme kapattı/ kesinlikle aranmasın ben hiç bir işletmem için fotoğraf çekimi istemiyorum bi faydasını görmedim daha önce çekim yaptırdım çünkü dedi. | AA31: Ulaşılamadı | AB31: 44411 | AC31: Ulaşılamadı | AD31: 44433 | AE31: Ulaşılamadı | AF31: 44435 | AG31: Ulaşılamadı | AH31: 44436 | AI31: Görüşüldü | AJ31: 44517 | AK31: Ezgi Turan | AL31: Deneme | AM31: Deneme | AN31: Ferhat Köksal | AO31: Kübra Toprak | AP31: Hakan Özler
A32: 60a0fbd35d8f6a605b763595 | B32: Ablanın Yeri Chicken & Fast Food, Nilüfer (Görükle Mah.) | C32: =VLOOKUP(A32,import!A:C,3,false) -> DOĞRU | D32: Tavuk | E32: =VLOOKUP(A32,import!A:J,5,0) -> 679 | F32: =VLOOKUP(A32,import!A:J,6,0) | G32: =VLOOKUP(A32,import!A:J,7,0) -> 0 | H32: =VLOOKUP(A32,import!A:J,8,0) -> 8 | I32: =VLOOKUP(A32,import!A:J,9,0) -> 8 | J32: =VLOOKUP(A32,import!A:J,10,0) -> 0 | K32: Melike Sarı | L32: 5425511619 | M32: Nilüfer | N32: Dumlupınar | O32: Dumlupınar Mah. Gürpınar Cad. Hiltoon-9 B Blok No:16 B / B Nilüfer / Bursa | P32: =VLOOKUP(A32,import!A:P,16,0) -> Geleneksel | R32: TRUE | S32: FALSE | T32: Başka Şubeden Çekilecek | W32: Bu aralar çok yoğunuz elemanımızda yok tek başımıza olduğumuz için ilerleyen haftalarfa görüşme sağlayalım istediler.-Telefoun kapalı öğleden snra tekrar aransın.ÇEKİM OLMUŞ | AA32: Ulaşılamadı | AB32: 44351 | AC32: Ulaşılamadı | AD32: 44355 | AE32: Ulaşılamadı | AF32: 44361 | AG32: Ulaşılamadı | AH32: 44362 | AI32: Ulaşılamadı | AJ32: 44436 | AK32: Özlem Güner | AL32: Nazlıcan Dinçer | AM32: Nazlıcan Dinçer | AN32: Deneme | AP32: Furkan Çağdaş Kuloğlu
A33: 61d6f94ced4531cad1fffb44 | B33: Ablay Döner, Orhangazi (Arapzade Mah.) | C33: =VLOOKUP(A33,import!A:C,3,false) -> DOĞRU | D33: Döner | E33: =VLOOKUP(A33,import!A:J,5,0) -> 559 | F33: =VLOOKUP(A33,import!A:J,6,0) -> 10 | G33: =VLOOKUP(A33,import!A:J,7,0) -> 0 | H33: =VLOOKUP(A33,import!A:J,8,0) -> 11 | I33: =VLOOKUP(A33,import!A:J,9,0) -> 11 | J33: =VLOOKUP(A33,import!A:J,10,0) -> 0 | K33: NURAY ABLAY | L33: 5414697066 | M33: Orhangazi | N33: Arapzade | O33: Arapzade MAh. Yalova Cad. No: 57 Orhangazi | P33: =VLOOKUP(A33,import!A:P,16,0) -> Geleneksel | R33: TRUE | S33: FALSE | T33: Randevu İptal | U33: Ferhat Köksal | V33: Mustafa OCAK | X33: 44693 | Y33: 44694 | AA33: Görüşüldü | AB33: 44693 | AK33: Ferhat Köksal
A34: 5f9945892c0f986692e0161e | B34: Able Chef Brekfast & Sandviç, Nilüfer (Görükle Mah.) | C34: =VLOOKUP(A34,import!A:C,3,false) -> DOĞRU | D34: Tost & Sandviç | E34: =VLOOKUP(A34,import!A:J,5,0) -> 15789 | F34: =VLOOKUP(A34,import!A:J,6,0) -> 370 | G34: =VLOOKUP(A34,import!A:J,7,0) -> 25 | H34: =VLOOKUP(A34,import!A:J,8,0) -> 22 | I34: =VLOOKUP(A34,import!A:J,9,0) -> 47 | J34: =VLOOKUP(A34,import!A:J,10,0) -> 0.53 | K34: Fatih Karakaya | L34: 5334232078 | M34: Nilüfer | N34: Görükle | O34: GÖRÜKLE MAH. TAŞKENT(490) SK. AKŞEMSETTİN KONUTLARI A BLOK NO: 4 A/A İÇ KAPI NO: 1 NİLÜFER/ BURSA | P34: =VLOOKUP(A34,import!A:P,16,0) -> Geleneksel | R34: TRUE | S34: FALSE | T34: Randevu Alındı | U34: Emel Yılmaz | V34: Alper Gökdemir | W34: devam çekimi istemiyor/teyit için arandı meşgule attı | X34: 44293 | Y34: 44294 | AA34: Görüşüldü | AB34: 44368 | AC34: Dönüş Yapacak | AD34: 44411 | AE34: Ulaşılamadı | AF34: 44412 | AG34: Görüşüldü | AH34: 44417 | AK34: Ezgi Turan | AM34: Duygu Telli | AN34: Deneme | AP34: Hakan Özler
A35: 616d9161a233ccd70b1d9b10 | B35: Abone Cafe & Fast Food, Nilüfer (Görükle Mah.) | C35: =VLOOKUP(A35,import!A:C,3,false) -> DOĞRU | D35: Tost & Sandviç | E35: =VLOOKUP(A35,import!A:J,5,0) -> 1855 | F35: =VLOOKUP(A35,import!A:J,6,0) -> 345 | G35: =VLOOKUP(A35,import!A:J,7,0) -> 27 | H35: =VLOOKUP(A35,import!A:J,8,0) -> 4 | I35: =VLOOKUP(A35,import!A:J,9,0) -> 31 | J35: =VLOOKUP(A35,import!A:J,10,0) -> 0.87 | K35: Farrukh Mammadov | L35: 2249992695 | M35: Nilüfer | N35: Görükle | O35: Görükle Mah. Harmanlık Cad. No:30 A Nilüfer / Bursa | P35: Geleneksel | R35: TRUE | S35: FALSE | T35: Randevu Alındı | U35: Tuğba Buyur | V35: Hamdi Can Hikmet | W35: 5537144341 / ferruh bey | X35: 44522 | Y35: 44524 | AA35: Ulaşılamadı | AB35: 44494 | AC35: Ulaşılamadı | AD35: 44496 | AE35: Ulaşılamadı | AF35: 44518 | AG35: Görüşüldü | AH35: 44522 | AK35: Ferhat Köksal | AL35: Tuğba Buyur | AM35: Tuğba Buyur | AN35: Tuğba Buyur | AP35: Hakan Özler
A36: 5f33cc41c1fe82072db006f7 | B36: Abooo Öz Doruk Döner (Görükle Mah.) | C36: =VLOOKUP(A36,import!A:C,3,false) -> DOĞRU | D36: Döner | E36: =VLOOKUP(A36,import!A:J,5,0) -> 726 | F36: =VLOOKUP(A36,import!A:J,6,0) -> 31 | G36: =VLOOKUP(A36,import!A:J,7,0) -> 0 | H36: =VLOOKUP(A36,import!A:J,8,0) -> 28 | I36: =VLOOKUP(A36,import!A:J,9,0) -> 28 | J36: =VLOOKUP(A36,import!A:J,10,0) -> 0 | K36: Şabettin Çallar | L36: 2244833034 | M36: Nilüfer | N36: Görükle | O36: Görükle Sakarya Mah. Atatürk Cad. Gonca Sok. 3 Oruç Dokuz Apt. Nilüfer, Bursa | P36: =VLOOKUP(A36,import!A:P,16,0) -> Geleneksel | Q36: 0-15 | R36: TRUE | S36: FALSE | T36: Çekim İstemiyor | W36: SÜREKLİ TERS KONUSUYOR. | AA36: Görüşüldü | AB36: 44365 | AC36: Dönüş Yapacak | AD36: 44436 | AE36: Görüşüldü | AF36: 44439 | AK36: Ezgi Turan | AL36: Deneme | AM36: Ezgi Turan | AO36: Duygu Telli | AP36: Hakan Özler
A37: 602119c9450e7fb53adf11e1 | B37: Abuzer Usta Pide & Kebap & Lahmacun, Yıldırım (Teferrüç Mah.) | C37: =VLOOKUP(A37,import!A:C,3,false) -> DOĞRU | D37: Pide | E37: =VLOOKUP(A37,import!A:J,5,0) -> 2228 | F37: =VLOOKUP(A37,import!A:J,6,0) -> 86 | G37: =VLOOKUP(A37,import!A:J,7,0) -> 18 | H37: =VLOOKUP(A37,import!A:J,8,0) -> 5 | I37: =VLOOKUP(A37,import!A:J,9,0) -> 23 | J37: =VLOOKUP(A37,import!A:J,10,0) -> 0.78 | K37: Emine Taşçı | L37: 2243262701 | M37: Yıldırım | N37: Teferrüç | O37: Teferrüç Mah Devrengeç Cad. No 8 | P37: =VLOOKUP(A37,import!A:P,16,0) -> Geleneksel | Q37: 0-15 | R37: TRUE | S37: FALSE | T37: Randevu Alındı | U37: Ferhat Köksal | V37: Alper Gökdemir | W37: YTKİLİ YOK ben iletirim sizlere geri donus saglarım dedi- randevu olusturuldu | AA37: Yetkili Yok | AB37: 44389 | AC37: Ulaşılamadı | AD37: 44393 | AE37: Görüşüldü | AF37: 44455 | AK37: Nurhayat Kabataş | AL37: Tutku Erdoğan | AM37: Ferhat Köksal | AO37: Duygu Telli | AP37: Furkan Çağdaş Kuloğlu
A38: 6116a1bf3891a331e6487ecd | B38: Academy Döner, Osmangazi (Emek Adnan Menderes Mah.) | C38: =VLOOKUP(A38,import!A:C,3,false) -> DOĞRU | D38: Döner | E38: =VLOOKUP(A38,import!A:J,5,0) -> 7155 | F38: =VLOOKUP(A38,import!A:J,6,0) -> 545 | G38: =VLOOKUP(A38,import!A:J,7,0) -> 16 | H38: =VLOOKUP(A38,import!A:J,8,0) -> 103 | I38: =VLOOKUP(A38,import!A:J,9,0) -> 119 | J38: =VLOOKUP(A38,import!A:J,10,0) -> 0.13 | K38: MUSTAFA YEŞİLYURT | L38: 5523630300 | M38: Osmangazi | N38: Emek Adnan Menderes | O38: EMEK ADNAN MENDERES MAH. TURGUT ÖZAL CAD. NO: 62 A OSMANGAZİ/ BURSA | P38: =VLOOKUP(A38,import!A:P,16,0) -> Geleneksel | R38: TRUE | S38: FALSE | T38: Randevu Alındı | W38: çekimim gerçekleşti benim der kontrol ettim randevu yok takvimde yeniden de çekim istemiyor yapıldı zaten onları yükleyin der | AA38: Görüşüldü | AB38: 44515 | AK38: Hatem Soyaslan | AP38: Beray Güllü
A39: 6210ce1c4f6e67b56fe00076 | B39: Acars Fast Food, Osmangazi (Bahar Mah.) | C39: =VLOOKUP(A39,import!A:C,3,false) -> DOĞRU | D39: Tost & Sandviç | E39: =VLOOKUP(A39,import!A:J,5,0) -> 9 | F39: =VLOOKUP(A39,import!A:J,6,0) | G39: =VLOOKUP(A39,import!A:J,7,0) -> 0 | H39: =VLOOKUP(A39,import!A:J,8,0) -> 21 | I39: =VLOOKUP(A39,import!A:J,9,0) -> 21 | J39: =VLOOKUP(A39,import!A:J,10,0) -> 0 | K39: Yunus Acar | L39: 5510042989 | M39: Osmangazi | N39: Bahar | O39: Bahar Mah. 2. Kanarya Sok. No:16 Osmangazi / Bursa | P39: =VLOOKUP(A39,import!A:P,16,0) -> Geleneksel | R39: FALSE | S39: FALSE
A40: 62276b0fecbcbba16453a93e | B40: Acı Dayı Cantık, Osmangazi (Kayhan Mah.) | C40: =VLOOKUP(A40,import!A:C,3,false) -> DOĞRU | D40: Pide | E40: =VLOOKUP(A40,import!A:J,5,0) -> 54 | F40: =VLOOKUP(A40,import!A:J,6,0) -> 26 | G40: =VLOOKUP(A40,import!A:J,7,0) -> 0 | H40: =VLOOKUP(A40,import!A:J,8,0) -> 14 | I40: =VLOOKUP(A40,import!A:J,9,0) -> 14 | J40: =VLOOKUP(A40,import!A:J,10,0) -> 0 | K40: YUSUF PİDECİ | L40: 2242215489 | M40: Osmangazi | N40: Kayıhan | O40: Kayıhan Mah. Boğaz Sok. No:11 Osmangazi/Bursa | P40: =VLOOKUP(A40,import!A:P,16,0) -> Geleneksel | R40: FALSE | S40: FALSE
...

Sheet Geleneksel Zincir
A1: Restaurant ID | B1: G/Key
A2: 5e42bcad21681f73277de18d | B2: Geleneksel
A3: 5f29442d27ec987405facadc | B3: Geleneksel
A4: 5f75f18e137b77b369284b20 | B4: Geleneksel
A5: 5fff61e335e580873f459b0d | B5: Geleneksel
A6: 5f29ae6e7ff0a337ab2ef12c | B6: Geleneksel
A7: 5f9bf9345a3727fc4bef1d96 | B7: Key Account
A8: 5fac9888f1d8540ff7e94ea4 | B8: Geleneksel
A9: 5fad8f102048d250a2a0a990 | B9: Geleneksel
A10: 5de68bec178a640b7145ef9e | B10: Geleneksel
A11: 5f990ca8016ad282e607df5a | B11: Geleneksel
A12: 5c56a2bc9f3d2620d4e42f94 | B12: Geleneksel
... A27060: 6089529b0c8d630422d48008 | B27060: Geleneksel
A27061: 6089526c3a5c1faf3acd6609 | B27061: #N/A
A27062: 6089515bed7a3e745073f5ac | B27062: Geleneksel
A27063: 60894e914589d3085c99cacf | B27063: Key Account
A27064: 60894ab44589d3087799c995 | B27064: Key Account
A27065: 608947ac2590ce2e57238ee5 | B27065: Key Account
A27066: 608946992590cef651238edb | B27066: Geleneksel
A27067: 6089468286ba16ef858de303 | B27067: Geleneksel
A27068: 608943ff588eb021484b8452 | B27068: Geleneksel
A27069: 6089432cf372e1d61025277e | B27069: Key Account
A27070: 60893f7f77461c7e52f08b4e | B27070: Key Account
A27071: 60893f2a588eb0bcb84b83fe | B27071: Geleneksel
A27072: 60893ebf94bee037a9836af4 | B27072: Geleneksel
A27073: 60893bc12d44eb4c328a417f | B27073: Geleneksel
... A43330: 5c5459989f3d26761ae3b456 | B43330: SİLİNDİ

Sheet import
A1: Restaurant ID | B1: Restoran Adı | C1: IsActive | D1: Mutfak | E1: TOPLAM SİPARİŞ | F1: SON 2 HAFTA | G1: RESİMLİ ÜRÜN | H1: RESİMSİZ ÜRÜN | I1: TOPLAM ÜRÜN | J1: Ratio | K1: Yetkili | L1: Telefon | M1: İLÇE | N1: MAHALLE | O1: ADRES | P1: Geleneksel Zincir | Q1: Eklendi mi
A2: 5f29abbc3fdebeba45b35296 | B2: Mis Döner (Dikkaldırım) | C2: DOĞRU | D2: Döner | E2: 17836 | F2: 365 | G2: 35 | H2: 35 | I2: 70 | J2: 0.5 | K2: Mustafa Aksoy | L2: 2242380282 | M2: Osmangazi | N2: Dikkaldırım | O2: Dikkaldırım, Herkül Sk. 1/A, 16090 Osmangazi/Bursa | P2: Geleneksel | Q2: =COUNTIF('Hedef Liste'!$A:$A,A2) -> 1
A3: 5f33c84bc159868b8b919721 | B3: Gel Tat Pide Sarayı, İnegöl (Kemal Paşa Mah.) | C3: DOĞRU | D3: Pide | E3: 1102 | F3: 19 | G3: 14 | H3: 8 | I3: 22 | J3: 0.64 | K3: Mehmet Bingöl | L3: 2247770656 | M3: İnegöl | N3: Uludağ Üniversitesi İnegöl Yerleşkesi | O3: Kemalpaşa, Mahmut Esat Bey Cd. No:261, 16400 İnegöl/Bursa | P3: Geleneksel | Q3: =COUNTIF('Hedef Liste'!$A:$A,A3) -> 1
A4: 5f33d277b61d53824a6d788c | B4: Yasa Cafe & Restaurant (Üçevler Mah.) | C4: DOĞRU | D4: Sokak Lezzetleri | E4: 1292 | F4: 15 | G4: 87 | H4: 22 | I4: 109 | J4: 0.8 | K4: Mehmet Ferhan Dal | L4: 2242320333 | M4: Nilüfer | N4: Üçevler | O4: Üçevler, Nilüfer Cd. No:29, 16120 Nilüfer/Bursa | P4: Geleneksel | Q4: =COUNTIF('Hedef Liste'!$A:$A,A4) -> 1
A5: 5f33e70730bf636aaf2c96e4 | B5: Big Mamma's (Ahmet Yesevi Mah.) | C5: DOĞRU | D5: Dünya Mutfağı | E5: 911 | F5: 37 | G5: 0 | H5: 99 | I5: 99 | J5: 0 | K5: Raif Yılmaz | L5: 2242448414 | M5: Nilüfer | N5: Ahmet Yesevi | O5: Ahmetyesevi Mah., Hürriyet Cad. Flora Rezidans Evleri No:21, 16140 Nilüfer/Bursa | P5: Geleneksel | Q5: =COUNTIF('Hedef Liste'!$A:$A,A5) -> 1
A6: 5f33f13c6b1e0f5516f3a80a | B6: Konya Tandır & Etli Ekmek, Osmangazi (Panayır Mah.) | C6: DOĞRU | D6: Sokak Lezzetleri | E6: 2535 | F6: 72 | G6: 20 | H6: 17 | I6: 37 | J6: 0.54 | K6: ARİF USLU | L6: 5510119000 | M6: Osmangazi | N6: Panayır | O6: Panayır, 3. Pınar Cd. no:194/A, 16600 Osmangazi/Bursa | P6: Geleneksel | Q6: =COUNTIF('Hedef Liste'!$A:$A,A6) -> 1
A7: 5f33f2cb759ccb1f3a4fbfbf | B7: Türk Sofrası Beyran & Kebap, Osmangazi (Soğanlı Mah.) | C7: DOĞRU | D7: Kebap | E7: 13104 | F7: 304 | G7: 45 | H7: 24 | I7: 69 | J7: 0.65 | K7: Hamit Türk | L7: 2242340027 | M7: Osmangazi | N7: Altınova | O7: Soğanlı, Soğanlı Blv. No:30, 16190 Osmangazi/Bursa | P7: Geleneksel | Q7: =COUNTIF('Hedef Liste'!$A:$A,A7) -> 1
A8: 5f34136af16ee24bc29e89f6 | B8: İllede Tantuni, Gemlik (Hamidiye Mah.) | C8: DOĞRU | D8: Sokak Lezzetleri | E8: 2024 | F8: 73 | G8: 19 | H8: 34 | I8: 53 | J8: 0.36 | K8: Gülfer Turan | L8: 2245122155 | M8: Gemlik | N8: Balıkpazarı | O8: Balıkpazarı, Sefa Sk. No:1, 16600 Gemlik/Bursa | P8: Geleneksel | Q8: =COUNTIF('Hedef Liste'!$A:$A,A8) -> 1
A9: 5f3525910274b85bbc5c9499 | B9: Demir Amca, Nilüfer (Görükle Mah.) | C9: DOĞRU | D9: Döner | E9: 4525 | G9: 0 | H9: 32 | I9: 32 | J9: 0 | K9: Tamer Esigül | L9: 2244836600 | M9: Nilüfer | N9: Dumlupınar | O9: Dumlupınar, Gelibolu Cd. Birlik Apt D:no:8/B, 16285 Nilüfer/Bursa | P9: Geleneksel | Q9: =COUNTIF('Hedef Liste'!$A:$A,A9) -> 1
A10: 5f356353c1827876608d31e3 | B10: Kaşık Kaşık Ev Yemekleri & Pide (Görükle Mah.) | C10: DOĞRU | D10: Ev Yemekleri | E10: 5989 | F10: 290 | G10: 28 | H10: 45 | I10: 73 | J10: 0.38 | K10: Emre Alkış | L10: 2244836662 | M10: Nilüfer | N10: Görükle | O10: Görükle, Atatürk Cd. No:101, 16220 Nilüfer/Bursa | P10: Geleneksel | Q10: =COUNTIF('Hedef Liste'!$A:$A,A10) -> 1
A11: 5f2bea2c6207d21afba4051b | B11: Gıt Gıt Piliç (Çekirge Mah.) | C11: YANLIŞ | D11: Tavuk | E11: 1168 | G11: 15 | H11: 2 | I11: 17 | J11: 0.88 | K11: Ayhan Bal | L11: 2242330022 | M11: Osmangazi | N11: Çekirge | O11: Çekirge, Çekirge Cd. No:195/A, 16000 Osmangazi/Bursa | P11: Geleneksel | Q11: =COUNTIF('Hedef Liste'!$A:$A,A11) -> 1
A12: 5f363e910274b875b25c9e6a | B12: Beyzade Kebap (Konak Mah.) | C12: DOĞRU | D12: Pide | E12: 4218 | F12: 132 | G12: 25 | H12: 27 | I12: 52 | J12: 0.48 | K12: Cemal Çelik | L12: 2244518381 | M12: Nilüfer | N12: Konak | O12: Konak Mahallesi, Beşevler Cad, Alıcı Sitesi 75/A, 16110 Nilüfer | P12: Geleneksel | Q12: =COUNTIF('Hedef Liste'!$A:$A,A12) -> 1
A13: 5f363f4f64610e6375605aaa | B13: Güler Pide & Kebap (Çamlıca Mah.) | C13: DOĞRU | D13: Kebap | E13: 3166 | F13: 57 | G13: 20 | H13: 15 | I13: 35 | J13: 0.57 | K13: Feyzinur Dinç | L13: 2244511103 | M13: Nilüfer | N13: Çamlıca | O13: Çamlıca, Kavakdere Cd. No:152, 16110 Nilüfer/Bursa | P13: Geleneksel | Q13: =COUNTIF('Hedef Liste'!$A:$A,A13) -> 1
A14: 5f364322da66dcf75ed6fa17 | B14: Maviş Döner (Ertuğrul Mah.) | C14: DOĞRU | D14: Döner | E14: 1049 | F14: 27 | G14: 8 | H14: 25 | I14: 33 | J14: 0.24 | K14: Dilek Konak | L14: 5315104612 | M14: Nilüfer | N14: Ertuğrul | O14: Ertuğrul, Elmas Sk. No:37 D:1A, 16120 Nilüfer/Bursa | P14: Geleneksel | Q14: =COUNTIF('Hedef Liste'!$A:$A,A14) -> 1
A15: 5f36459686f7db3bf9f8f783 | B15: Kelebek Izgara (Fethiye Mah.) | C15: DOĞRU | D15: Tavuk | E15: 842 | F15: 9 | G15: 17 | H15: 10 | I15: 27 | J15: 0.63 | K15: Serhan Kelebekler | L15: 2242420272 | M15: Nilüfer | N15: Fethiye | O15: Fethiye, Top Sahası Cd. 6/B, 16140 Nilüfer/Bursa | P15: Geleneksel | Q15: =COUNTIF('Hedef Liste'!$A:$A,A15) -> 1
A16: 5f364665a886cd8bd548f5d7 | B16: Ababe Uygar Cafe, Nilüfer (Görükle Mah.) | C16: DOĞRU | D16: Tost & Sandviç | E16: 2067 | F16: 90 | G16: 5 | H16: 42 | I16: 47 | J16: 0.11 | K16: Erkut Kocabaş | L16: 5076451405 | M16: Nilüfer | N16: Dumlupınar | O16: Dumlupınar, Pamukkale Cd. No:27 D:B, 16285 Nilüfer/Bursa | P16: Geleneksel | Q16: =COUNTIF('Hedef Liste'!$A:$A,A16) -> 1
A17: 5f3647a7d64681800afebdf8 | B17: Doyum Ev Yemekleri & Kahvaltı, Nilüfer (Görükle Mah.) | C17: DOĞRU | D17: Ev Yemekleri | E17: 1463 | F17: 45 | G17: 8 | H17: 21 | I17: 29 | J17: 0.28 | K17: Yüksel Bütün | L17: 5322081634 | M17: Nilüfer | N17: Dumlupınar | O17: Dumlupınar, Cevizlik Cd., 16285 Nilüfer/Bursa | P17: Geleneksel | Q17: =COUNTIF('Hedef Liste'!$A:$A,A17) -> 1
A18: 5f3655dcf41354fdb64f34ec | B18: Öz Urfa Altıngül Kebap & Pide (Ulu Mah.) | C18: DOĞRU | D18: Kebap | E18: 5577 | F18: 136 | G18: 46 | H18: 20 | I18: 66 | J18: 0.7 | K18: Hasan Güzel | L18: 2242510202 | M18: Osmangazi | N18: Ulu | O18: Ulu, Kıbrıs Şehitleri Cd. No:79 D:44, 16220 Osmangazi/Bursa | P18: Geleneksel | Q18: =COUNTIF('Hedef Liste'!$A:$A,A18) -> 1
A19: 5f36705e7bcccf3ebed975cd | B19: Ağa Dürüm (Esenevler Mah.) | C19: DOĞRU | D19: Kebap | E19: 1760 | F19: 44 | G19: 0 | H19: 16 | I19: 16 | J19: 0 | K19: Ağa Kaçar | L19: 2243421240 | M19: Yıldırım | N19: Esenevler | O19: Esenevler, Erikli Cd. No:67, 16300 Yıldırım/Bursa | P19: Geleneksel | Q19: =COUNTIF('Hedef Liste'!$A:$A,A19) -> 1
A20: 5f367a690274b83dd15ca324 | B20: Pesto Makarna, Nilüfer (Görükle Mah.) | C20: DOĞRU | D20: Mantı | E20: 1314 | F20: 31 | G20: 23 | H20: 12 | I20: 35 | J20: 0.66 | K20: Egemen Kalelioğlu | L20: 5327021093 | M20: Nilüfer | N20: Dumlupınar | O20: Dumlupınar, Doluca Sk. No:2, 16285 Nilüfer/Bursa | P20: Geleneksel | Q20: =COUNTIF('Hedef Liste'!$A:$A,A20) -> 1
A21: 5f331a0a456a2699c5cf7696 | B21: İncirli Tostçusu, (İhsaniye Mah.) | C21: DOĞRU | D21: Tost & Sandviç | E21: 905 | F21: 80 | G21: 0 | H21: 46 | I21: 46 | J21: 0 | K21: Yaşar Gedikli | L21: 5536660016 | M21: Nilüfer | N21: İhsaniye | O21: İhsaniye Mah. Tuna Cad. Uğurkent Apt. A Blok No:125/1C Nilüfer Bursa | P21: Geleneksel | Q21: =COUNTIF('Hedef Liste'!$A:$A,A21) -> 1
A22: 5f35454d02e0080ccb8fd4e8 | B22: Arsamiea Çiğ Köfte, Nilüfer (Görükle Mah.) | C22: DOĞRU | D22: Sokak Lezzetleri | E22: 3154 | F22: 55 | G22: 10 | H22: 12 | I22: 22 | J22: 0.45 | K22: ASADULLAH RAHMANI | L22: 5078230818 | M22: Nilüfer | N22: Dumlupınar | O22: Dumlupınar mah. Gülveren cad. A blok No:3 A/A Nilüfer/BURSA | P22: Geleneksel | Q22: =COUNTIF('Hedef Liste'!$A:$A,A22) -> 1
A23: 5f33b3071f35d301c156d256 | B23: Lezzet Dürümcüsü (FSM Bulvarı) | C23: DOĞRU | D23: Kebap | E23: 4129 | F23: 225 | G23: 0 | H23: 66 | I23: 66 | J23: 0 | K23: Bedri Özdemir | L23: 2242450089 | M23: Osmangazi | N23: Bağlarbaşı | O23: Esentepe, Fsm Bulvarı, Esentepe Kavşağı 227/D, 16130 Nilüfer/Bursa | P23: Geleneksel | Q23: =COUNTIF('Hedef Liste'!$A:$A,A23) -> 1
... A33: 5f34104bc58bef77bb118692 | B33: Ala İskender, Gemlik (Hamidiye Mah.) | C33: DOĞRU | D33: Döner | E33: 2960 | F33: 77 | G33: 33 | H33: 6 | I33: 39 | J33: 0.85 | K33: Mehmet Ferit Çelik | L33: 5067772758 | M33: Gemlik | N33: Hamidiye | O33: Hamidiye, İstiklal Cd. No:12, 16600 Gemlik/Bursa | P33: Geleneksel | Q33: =COUNTIF('Hedef Liste'!$A:$A,A33) -> 1
A34: 5f34111f987696e1048f6a49 | B34: Kardelen Etli Ekmek, Gemlik (Hamidiye Mah.) | C34: YANLIŞ | D34: Pide | E34: 339 | G34: 7 | H34: 4 | I34: 11 | J34: 0.64 | K34: Mülazım Rama | L34: 2245121100 | M34: Gemlik | N34: Dr.ziya Kaya | O34: Hamidiye, Orhangazi Cd. No:75, 16600 Gemlik/Bursa | P34: Geleneksel | Q34: =COUNTIF('Hedef Liste'!$A:$A,A34) -> 1
A35: 5f34f5bd5e18f6d8f23e52c2 | B35: Aktif Kumru, Nilüfer (Beşevler Mah.) | C35: DOĞRU | D35: Sokak Lezzetleri | E35: 3489 | F35: 101 | G35: 4 | H35: 1 | I35: 5 | J35: 0.8 | K35: Fadime Aras Turgut | L35: 2244510042 | M35: Nilüfer | N35: Beşevler | O35: Yıldırım Caddesi Beşevler Mahallesi 161A, Nilufer/Bursa | P35: Geleneksel | Q35: =COUNTIF('Hedef Liste'!$A:$A,A35) -> 1
A36: 5f363dce5e18f66f053e6206 | B36: Pide Store (Konak Mah.) | C36: DOĞRU | D36: Pide | E36: 3624 | F36: 122 | G36: 0 | H36: 46 | I36: 46 | J36: 0 | K36: Gülçin Cengizhan | L36: 2244514060 | M36: Nilüfer | N36: Konak | O36: Konak, Konak Cd. No:7, 16110 Nilüfer/Bursa | P36: Geleneksel | Q36: =COUNTIF('Hedef Liste'!$A:$A,A36) -> 1
A37: 5f3646b764610ea11d605c2b | B37: Tostçu İlker (Selamet Mah.) | C37: DOĞRU | D37: Tost & Sandviç | E37: 3045 | F37: 116 | G37: 27 | H37: 5 | I37: 32 | J37: 0.84 | K37: Serpil Şen | L37: 2242562359 | M37: Osmangazi | N37: Selamet | O37: Selamet, Zekibey Sk. No:24, 16240 Osmangazi/Bursa | P37: Geleneksel | Q37: =COUNTIF('Hedef Liste'!$A:$A,A37) -> 1
A38: 5f364a11c18278ab7b8d3c65 | B38: Raşit Usta Etli Ekmek & Pide (19 Mayıs Mah.) | C38: DOĞRU | D38: Pide | E38: 2000 | F38: 58 | G38: 33 | H38: 24 | I38: 57 | J38: 0.58 | K38: Mehmet Bozbaş | L38: 5378812335 | M38: Nilüfer | N38: 44700 | O38: Özlüce, Side Cd. No:2, 16120 Nilüfer/Bursa | P38: Geleneksel | Q38: =COUNTIF('Hedef Liste'!$A:$A,A38) -> 1
A39: 5f366db34589dfec564a9a7a | B39: Dönerci Murat Paket Büfe (Beşevler Mah.) | C39: DOĞRU | D39: Döner | E39: 10523 | F39: 448 | G39: 34 | H39: 37 | I39: 71 | J39: 0.48 | K39: Songül Han | L39: 2244511632 | M39: Nilüfer | N39: Beşevler | O39: Beşevler, Bilginler Cd. No:10, 16110 Nilüfer/Bursa | P39: Geleneksel | Q39: =COUNTIF('Hedef Liste'!$A:$A,A39) -> 1
A40: 5f3681be82cfcf554f526711 | B40: İsos Döner, Osmangazi (Dikkaldırım Mah.) | C40: DOĞRU | D40: Döner | E40: 14931 | F40: 554 | G40: 12 | H40: 7 | I40: 19 | J40: 0.63 | K40: Hacer Tutkun | L40: 2242331033 | M40: Osmangazi | N40: Dikkaldırım | O40: Hüdavendigar, Dikkaldırım Cd. 71/A, 16090 Osmangazi/Bursa | P40: Geleneksel | Q40: =COUNTIF('Hedef Liste'!$A:$A,A40) -> 1
A41: 5f333cefabcd6ae24be1561e | B41: Atmaca'a Aperarif (Aktarhüssam Mah.) | C41: DOĞRU | D41: Kahvaltı | E41: 1573 | F41: 31 | G41: 20 | H41: 19 | I41: 39 | J41: 0.51 | K41: Orhan Atmaca | L41: 2242251256 | M41: Osmangazi | N41: Aktarhüssam | O41: Şehreküstü Mahallesi Şehreküstü Caddesi 15-1 16050 Osmangazi/Bursa Türkiye | P41: Geleneksel | Q41: =COUNTIF('Hedef Liste'!$A:$A,A41) -> 1
A42: 5f330e97d60227fcc5d3256a | B42: Kelebek Pastanesi, Nilüfer (Görükle Mah.) | C42: DOĞRU | D42: Kahvaltı | E42: 4102 | F42: 346 | G42: 15 | H42: 2 | I42: 17 | J42: 0.88 | K42: Nigar Sabir | L42: 5366077750 | M42: Nilüfer | N42: Görükle | O42: Görükle, Bahriye Üçok Cd., 16285 Nilüfer/Bursa | P42: Geleneksel | Q42: =COUNTIF('Hedef Liste'!$A:$A,A42) -> 1
A43: 5f3310a8d602277241d3257e | B43: Strong Burger, Nilüfer (Görükle Mah.) | C43: DOĞRU | D43: Burger | E43: 9367 | F43: 284 | G43: 17 | H43: 22 | I43: 39 | J43: 0.44 | K43: MUHAMMED FURKAN KELEŞ | L43: 2244800088 | M43: Nilüfer | N43: Dumlupınar | O43: Dumlupınar mahallesi selanik caddesi no:6 görükle, 1, 16285 Bursa | P43: Geleneksel | Q43: =COUNTIF('Hedef Liste'!$A:$A,A43) -> 1
A44: 5f33b8876b1e0f42e1f39bf7 | B44: Can Pide (Gürsu) | C44: DOĞRU | D44: Pide | E44: 5801 | F44: 92 | G44: 0 | H44: 20 | I44: 20 | J44: 0 | K44: Ali Yılmaz | L44: 2243711340 | M44: Gürsu | N44: Zafer | O44: Zafer Mah. Atatürk Cad. 22/A Gürsu, Bursa | P44: Geleneksel | Q44: =COUNTIF('Hedef Liste'!$A:$A,A44) -> 1
A45: 5f33d6cf089c64743b779dfe | B45: Yetad Pide (Ahmetvefikpaşa Mah.) | C45: DOĞRU | D45: Pide | E45: 2244 | G45: 0 | H45: 24 | I45: 24 | J45: 0 | K45: Yakup Han | L45: 2243728100 | M45: Kestel | N45: Ahmetvefikpaşa | O45: Ahmet Vefik Paşa, Bursa Cd. No:45 D:B, 16450 Kestel/Bursa | P45: Geleneksel | Q45: =COUNTIF('Hedef Liste'!$A:$A,A45) -> 1
A46: 5f33d943e99eb6a9711c0f22 | B46: Kayhan Pideli Köfte & Cantık (Beşevler Mah.) | C46: DOĞRU | D46: Pide | E46: 3787 | F46: 59 | G46: 8 | H46: 26 | I46: 34 | J46: 0.24 | K46: İsmail Topaloğlu | L46: 2244518471 | M46: Nilüfer | N46: Beşevler | O46: Konak, Yıldırım Cd., 16110 Nilüfer/Bursa | P46: Geleneksel | Q46: =COUNTIF('Hedef Liste'!$A:$A,A46) -> 1
A47: 5f340cdead55164706586156 | B47: Dürümce 01 Ciğer & Kebap, Gemlik (Hamidiye Mah.) | C47: YANLIŞ | D47: Kebap | E47: 761 | G47: 0 | H47: 24 | I47: 24 | J47: 0 | K47: Saadet Malbora | L47: 2245136363 | M47: Gemlik | N47: Hamidiye | O47: Hamidiye, Kumsal Sk. no 11a, 16600 Gemlik/Bursa | P47: Geleneksel | Q47: =COUNTIF('Hedef Liste'!$A:$A,A47) -> 1
A48: 5f34565fbdf9f831e7223706 | B48: Şanlı 63 Kebap & Pide & Lahmacun, Nilüfer (Beşevler Mah.) | C48: DOĞRU | D48: Kebap | E48: 1741 | F48: 79 | G48: 15 | H48: 17 | I48: 32 | J48: 0.47 | K48: Mehmet Çiftçi | L48: 2244530563 | M48: Nilüfer | N48: Beşevler | O48: Beşevler Cd. No 152, 16140 Nilüfer/Bursa | P48: Geleneksel | Q48: =COUNTIF('Hedef Liste'!$A:$A,A48) -> 1
A49: 5f33d6fa03a8183101924b13 | B49: Beef Burger (İhsaniye Mah.) | C49: DOĞRU | D49: Burger | E49: 3563 | F49: 28 | G49: 0 | H49: 94 | I49: 94 | J49: 0 | K49: Özge Dündar | L49: 5331668655 | M49: Nilüfer | N49: İhsaniye | O49: İhsaniye Mah., Barbaros Cad., No:16, Nilüfer, Bursa, | P49: Geleneksel | Q49: =COUNTIF('Hedef Liste'!$A:$A,A49) -> 1
...

Sheet Durum Parametreler
J1: Arama Durum
C2: Başka Şubeden Çekilecek | F2: Okan Yazıcı | H2: Mertcan | J2: Ulaşılamadı
C3: BlackList | F3: Salih Kolcu | H3: Enes | J3: Yetkiliyle Görüşüldü
A4: 44197 | C4: Çekim İstemiyor | F4: Ahmet Durmaz | H4: Ezgi Turan | J4: Yetkili yok
A5: 44198 | C5: Devir | F5: Alper Gökdemir | H5: Hatem Soyaslan | J5: Numara yanlış
A6: 44199 | C6: Dönüş Yapacak | H6: Zeliha Özer | J6: Yoğun - Tekrar Ara
A7: 44200 | C7: Franchise | H7: Emre Dalgıç
A8: 44201 | C8: İleride Randevu Alınacak | F8: Ayşegül Kır | H8: Gül Değirmenci
A9: 44202 | C9: Lokasyon Uzak | F9: Betül Demir | H9: Yurdagül Kulaksız
A10: 44203 | C10: Haziran'da Aranacak | F10: Hatem Soyaslan | H10: Ayfer Altın
A11: 44204 | C11: Menü Güncellemesi Yapılacak | F11: Selcan Topçu | H11: Ayşegül Kır
A12: 44205 | C12: Personel Eksik | F12: Sude Alkan | H12: Damla Kılcı
A13: 44206 | C13: Randevu Alındı | F13: Yurdagül Kulaksız | H13: Özlem arslan
