Workbook

Sheet Takvim
C1: TARİH | D1: Randevu Alan | E1: ID | F1: RESTORAN | G1: SAAT | H1: İLÇE / MAHALLE | I1: YETKİLİ KİŞİ / TELEFON | J1: ADRES | K1: Notlar | L1: Fotoğraf Adeti | M1: Toplam ürün | N1: Şubeli | O1: İptal
C2: 44235
A3: =E3 -> 5f723b068cdcec6cea6fb0f8 | C3: Altuğ | E3: 5f723b068cdcec6cea6fb0f8 | F3: Çiğ Köfteci Sait, Tepebaşı (Yenibağlar Mah.) | G3: 11:00 | H3: Tepebaşı / Yenibağlar | I3: İbrahim / 5308302580 | J3: Yenibağlar mah.Sapanca sok. no16/b | L3: 4 | M3: =VLOOKUP(E3,'Hedef Liste'!A:I,8,false) -> 5 | N3: FALSE | O3: FALSE
A4: =E4 -> 5f33c6e6572e4c8d5bc3e1df | C4: Altuğ | E4: 5f33c6e6572e4c8d5bc3e1df | F4: Always Tantuni Coffee Food, Tepebaşı (Yenibağlar Mah.) | G4: 0.54166667 | H4: Tepebaşı / Yenibağlar | I4: Nurşen / 5334575856 | J4: Yenibağlar, No:63, Şimşek Sk. No:63, 26170 Tepebaşı | L4: 13 | M4: =VLOOKUP(E4,'Hedef Liste'!A:I,8,false) -> #N/A | N4: FALSE | O4: FALSE
A5: =E5 -> 5fd3e01912cbf37cc3e51a9a | C5: Altuğ | E5: 5fd3e01912cbf37cc3e51a9a | F5: Munchies Cookies, Tepebaşı (Işıklar Mah.) | G5: 0.6875 | H5: Tepebaşı / Yenibağlar | I5: Ahmet / 5362058266 | J5: YENİBAĞLAR MAH. GÜN SK. NO: 20 B TEPEBAŞI/ ESKİŞEHİR | L5: 11 | M5: =VLOOKUP(E5,'Hedef Liste'!A:I,8,false) -> #N/A | N5: FALSE | O5: FALSE
A6: =E6 -> 600632a626a65ac94432c35f | C6: Altuğ | E6: 600632a626a65ac94432c35f | F6: Queen Waffle, Tepebaşı (Yenibağlar mah.) | G6: 18:00 | H6: Tepebaşı / Yenibağlar | I6: Ahmet / 5362058266 | J6: YENİBAĞLAR MAH. GÜN SK. NO: 20 B TEPEBAŞI/ ESKİŞEHİR | L6: 6 | M6: =VLOOKUP(E6,'Hedef Liste'!A:I,8,false) -> #N/A | N6: FALSE | O6: FALSE
A7: =E7 | C7: Altuğ | N7: FALSE | O7: FALSE
A8: =E8 | C8: Altuğ | N8: FALSE | O8: FALSE
A9: =E9 -> 5f75a57096c8ed304936c0a2 | C9: Emir | E9: 5f75a57096c8ed304936c0a2 | F9: Black & Red Fried Chicken, Tepebaşı (Eskibağlar Mah.) | G9: 10:00 | H9: Tepebaşı / Eskibağlar | I9: Ayça / 5454202646 | J9: Eskibağlar Mah . Balkan Cad. No:71/A Tepebaşı/Eskişehir | L9: 18 | M9: =VLOOKUP(E9,'Hedef Liste'!A:I,8,false) -> #N/A | N9: FALSE | O9: FALSE
A10: =E10 -> 5ffb7551e348f63a5fa2656b | C10: Emir | E10: 5ffb7551e348f63a5fa2656b | F10: Miss Pilav & Yemek, Tepebaşı (Yenibağlar Mah.) | G10: 11:00 | H10: Tepebaşı / Yenibağlar | I10: Hümmet / 5534194645 | J10: Yenibağlar Mah. Üniversite Cad. No:150/B Tepebaşı/ Eskişehir | L10: 25 | M10: =VLOOKUP(E10,'Hedef Liste'!A:I,8,false) -> #N/A | N10: FALSE | O10: FALSE
A11: =E11 -> 5f33be106b1e0fee8df39e5f | C11: Emir | E11: 5f33be106b1e0fee8df39e5f | F11: Bucks Burger, Tepebaşı (Eskibağlar Mah.) | G11: 0.66666667 | H11: Tepebaşı / Eskibağlar | I11: Kaan / 5308445526 | J11: Eskibağlar, Oğuz Sk. No 6 A, 26170 Tepebaşı/Eskişehir | L11: 18 | M11: =VLOOKUP(E11,'Hedef Liste'!A:I,8,false) -> #N/A | N11: TRUE | O11: FALSE
A12: =E12 | C12: Emir
A13: =E13 | C13: Emir | N13: FALSE | O13: FALSE
A14: =E14 | C14: Emir | N14: FALSE | O14: FALSE
A15: =E15 | C15: Melika
A16: =E16 -> 5f6e9c2e32054a515c428e57 | C16: Melika | E16: 5f6e9c2e32054a515c428e57 | F16: Arasta Döner, Tepebaşı (Yenibağlar Mah.) | G16: 0.45833333 | H16: Tepebaşı / Yenibağlar | I16: İbrahim / 2222050315 | J16: Yenibağlar, Sapanca Sk., 26170 Tepebaşı/Eskişehir | L16: 10 | M16: =VLOOKUP(E16,'Hedef Liste'!A:I,8,false) -> 8 | N16: FALSE | O16: FALSE
A17: =E17 -> 5fcb1b98a28082395ebedef2 | C17: Melika | E17: 5fcb1b98a28082395ebedef2 | F17: Kütük Cafe, Tepebaşı (Eskibağlar Mah.) | G17: 0.54166667 | H17: Tepebaşı / Güllük | I17: Safiye / 5073695868 | J17: Eskibağlar mah. Talat Paşa sok. No:49 A D:9 Tepebaşı / Eskişehir | L17: 10 | M17: =VLOOKUP(E17,'Hedef Liste'!A:I,8,false) -> 1 | N17: FALSE | O17: FALSE
A18: =E18 -> 5f7b1a02ec14c4d9cd0273f8 | C18: Melika | E18: 5f7b1a02ec14c4d9cd0273f8 | F18: Adanalı Dürümcü Soner Usta, Cumhuriye | G18: 0.625 | H18: Tepebaşı / Yenibağlar | I18: Soner / 2222212601 | J18: Cumhuriye mah. Zübeyde Hanım Cad. No: 4/A Tepebaşı/Eskişehir | L18: 12 | M18: =VLOOKUP(E18,'Hedef Liste'!A:I,8,false) -> 21 | N18: FALSE | O18: FALSE
A19: =E19 | C19: Melika | N19: FALSE | O19: FALSE
A20: =E20 | C20: Sonya & Sofya | N20: FALSE | O20: FALSE
A21: =E21 | C21: Sonya & Sofya | N21: FALSE | O21: FALSE
A22: =E22 | C22: Sonya & Sofya | N22: FALSE | O22: FALSE
A23: =E23 | C23: Sonya & Sofya | N23: FALSE | O23: FALSE
A24: =E24 | C24: Sonya & Sofya | N24: FALSE | O24: FALSE
A25: =E25 | C25: Sonya & Sofya | N25: FALSE | O25: FALSE
A26: =E26 | C26: 44236
A27: =E27 -> 5ff45aae87a63b19b533eb59 | C27: Altuğ | E27: 5ff45aae87a63b19b533eb59 | F27: Turuncu Tantuni, Tepebaşı (Eskibağlar Mah.) | G27: 11:00 | H27: Tepebaşı / Eskibağlar | I27: İsmet / 2223230565 | J27: Eskibağlar, Yılmaz Büyükerşen Blv No:58 D:B, 26170 Tepebaşı/Eskişehir | L27: 6 | M27: =VLOOKUP(E27,'Hedef Liste'!A:I,8,false) -> 3 | N27: FALSE | O27: FALSE
A28: =E28 | C28: Altuğ | N28: FALSE | O28: FALSE
A29: =E29 -> 5ff7c4d93c3b6e5099616461 | C29: Altuğ | E29: 5ff7c4d93c3b6e5099616461 | F29: % Yüz Tantuni, Tepebaşı (Hacı Seyit Mah.) | G29: 0.58333333 | H29: Odunpazar / Kurtuluş | I29: Cemil / 2222320100 | J29: KURTULUŞ MAH/SEMT ZİYA PAŞA CAD. NO: 77 B ODUNPAZARI/ ESKİŞEHİR | L29: 2 | M29: =VLOOKUP(E29,'Hedef Liste'!A:I,8,false) -> 5 | N29: FALSE | O29: FALSE
A30: =E30 -> 5f315566b9e5e1dd64db6114 | C30: Altuğ | E30: 5f315566b9e5e1dd64db6114 | F30: Ali Baba Tantuni (Vişnelik Mah.) | G30: 0.625 | H30: Odunpazarı/Vişnelik | I30: Metin / 2222255303 | J30: Vişnelik, Öğretmenler Blv No:8, 26020 Odunpazarı/Eskişehir | K30: Bir daha çekim randevusu alınmayacak | N30: FALSE | O30: TRUE
A31: =E31 | C31: Altuğ | N31: FALSE | O31: FALSE
A32: =E32 | C32: Altuğ | N32: FALSE | O32: FALSE
A33: =E33 -> 5f3322c003a8187cc9924036 | C33: Emir | E33: 5f3322c003a8187cc9924036 | F33: Eskişehir Çibörek Evi, Odunpazarı (Akarbaşı Mah.) | G33: 10:00 | H33: Odunpazarı / Akarbaşı | I33: AYHAN/ / 2222331616 | J33: Arifiye Mahallesi Mustafa Kemal Atatürk Caddesi No: 38 B Odunpazarı / Eskişehir | L33: 14 | M33: =VLOOKUP(E33,'Hedef Liste'!A:I,8,false) -> 3 | N33: FALSE | O33: FALSE
A34: =E34 | C34: Emir | N34: FALSE | O34: FALSE
A35: =E35 -> 5f33c747c1598600399196f3 | C35: Emir | E35: 5f33c747c1598600399196f3 | F35: Bi Dana Döner, Tepebaşı (Yenibağlar Mah.) | G35: 0.54166667 | H35: Tepebaşı / Eskibağlar | I35: ÖMER / 2223250036 | J35: Prof. Dr. Yılmaz Büyükerşen Blv., No:48, Tepebaşı, Eskişehir, Türkiye | L35: 11 | M35: =VLOOKUP(E35,'Hedef Liste'!A:I,8,false) -> #N/A | N35: FALSE | O35: FALSE
A36: =E36 -> 5f3335c503a8180e1d92403b | C36: Emir | E36: 5f3335c503a8180e1d92403b | F36: Köfteci Ali, Hoşnudiye | G36: 0.60416667 | H36: Tepebaşı / Hoşnudiye | I36: İbrahim / 530 229 14 14 | J36: Hoşnudiye Mah., İstasyon Cad., No:45A, Tepebaşı, Eskişehir | L36: 5 | M36: =VLOOKUP(E36,'Hedef Liste'!A:I,8,false) -> 1 | N36: FALSE | O36: FALSE
A37: =E37 -> 5f67f7192702e9083fb20a37 | C37: Emir | E37: 5f67f7192702e9083fb20a37 | F37: Adıyaman Çiğ Köfte Murat Usta, Tepebaşı (Cumhuriye Mah.) | G37: 0.64583333 | H37: Tepebaşı / Ömerağa | I37: Mehmet / 5337761568 | J37: Cumhuriye mah. Zübeyde Hanım Cad. No: 26/A Tepebaşı/Eskişehir | L37: 7 | M37: =VLOOKUP(E37,'Hedef Liste'!A:I,8,false) -> 12 | N37: FALSE | O37: FALSE
A38: =E38 -> 5fa5f00566a584ab34fdd59a | C38: Emir | E38: 5fa5f00566a584ab34fdd59a | F38: Adıyaman Çiğ Köftecisi, Odunpazarı (Ihlamurkent Mah.) | G38: 16:00 | H38: Odunpazar/Ihlamurkent | I38: Serhat / 5412208287 | J38: Ihlamurkent Mah. Nevruz cad. No:42/EB Odunpazarı/Eskişehir | L38: 4 | M38: =VLOOKUP(E38,'Hedef Liste'!A:I,8,false) -> 13 | N38: FALSE | O38: FALSE
A39: =E39 | C39: Melika | N39: FALSE | O39: FALSE
A40: =E40 -> 5f35ada4d64681eb3bfeb406 | C40: Melika | E40: 5f35ada4d64681eb3bfeb406 | F40: Adıyaman Çiğköftecisi İlyas Aybak, Odunpazarı (Emek Mah.) | G40: 12:30 | H40: Odunpazar/EMEK | I40: Hakan 5438920626 | J40: Emek, Ertaş Blv. No:111, 26080 Odunpazarı/Eskişehir | L40: 8 | M40: =VLOOKUP(E40,'Hedef Liste'!A:I,8,false) -> 10 | N40: FALSE | O40: FALSE
...

Sheet Hedef Liste
A1: Restaurant ID | B1: Restoran Adı | C1: Satışa Açık Mı? | D1: Mutfak | E1: TOPLAM SİPARİŞ | F1: SON 2 HAFTA | G1: RESİMLİ ÜRÜN | H1: RESİMSİZ ÜRÜN | I1: TOPLAM ÜRÜN | J1: Ratio | K1: Yetkili | L1: Telefon | M1: İLÇE | N1: MAHALLE | O1: ADRES | P1: Geleneksel Zincir | Q1: FOTOĞRAF SEGMENT | R1: Aradık Mı? | S1: Kendi Fotosu Var | T1: Randevu Durum | U1: Randevu Alan | V1: Fotoğrafçı | W1: Not | X1: Randevu Alma Tarihi | Y1: Randevu Tarihi | Z1: Anket Durum | AA1: 1. Arama | AB1: 1. Arama Tarihi | AC1: 2. Arama | AD1: 2. Arama Tarihi | AE1: 3. Arama | AF1: 3. Arama Tarihi | AG1: 4. Arama | AH1: 4. Arama Tarihi | AI1: 5. Arama | AJ1: 5. Arama Tarihi | AK1: 1. Arayan | AL1: 2. Arayan | AM1: 3. Arayan | AN1: 4. Arayan | AO1: 5. Arayan | AP1: SY | AQ1: SY - Durum
A2: 5ff7c4d93c3b6e5099616461 | B2: % Yüz Tantuni, Tepebaşı (Hacı Seyit Mah.) | C2: =VLOOKUP(A2,Import!A:C,3,false) -> DOĞRU | D2: Sokak Lezzetleri | E2: =VLOOKUP(A2,Import!A:J,5,0) -> 1515 | F2: =VLOOKUP(A2,Import!A:J,6,0) -> 18 | G2: =VLOOKUP(A2,Import!A:J,7,0) -> 2 | H2: =VLOOKUP(A2,Import!A:J,8,0) -> 5 | I2: =VLOOKUP(A2,Import!A:J,9,0) -> 7 | J2: =VLOOKUP(A2,Import!A:J,10,0) -> 0.29 | K2: =VLOOKUP(A2,Import!A:P,11,0) -> CEMİL AYAZ | L2: 2222320100 | M2: Odunpazarı | N2: Kurtuluş | O2: KURTULUŞ MAH/SEMT ZİYA PAŞA CAD. NO: 77 B ODUNPAZARI/ ESKİŞEHİR | P2: =VLOOKUP(A2,Import!A:P,16,0) -> Geleneksel | Q2: 0-15 | R2: TRUE | S2: FALSE | T2: Randevu Alındı | V2: Altuğ | W2: TEYİT İÇİN ARANDI ÇEKİM GERÇEKLEŞTİMİ BİLMİYORUM DEDİLER GERİ DÖNÜŞ YAPACAKLAR ÇEKİM YAPILMAMIŞSA | X2: 44232 | Y2: 44236 | AP2: Gökhan Çakır
A3: 61dca4539cda244596c47c8a | B3: 10line Fast Food & Kokoreç, Tepebaşı (Hoşnudiye Mah.) | C3: =VLOOKUP(A3,Import!A:C,3,false) -> YANLIŞ | D3: Tost & Sandviç | E3: =VLOOKUP(A3,Import!A:J,5,0) | F3: =VLOOKUP(A3,Import!A:J,6,0) | G3: =VLOOKUP(A3,Import!A:J,7,0) -> 0 | H3: =VLOOKUP(A3,Import!A:J,8,0) -> 16 | I3: =VLOOKUP(A3,Import!A:J,9,0) -> 16 | J3: =VLOOKUP(A3,Import!A:J,10,0) -> 0 | K3: Alperen Orhan | L3: 5523763838 | M3: Tepebaşı | N3: Hoşnudiye | O3: HOŞNUDİYE MAH. BAYRAK SK. NO: 8 C- İÇ KAPI NO: - TEPEBAŞI/ ESKİŞEHİR | P3: =VLOOKUP(A3,Import!A:P,16,0) -> Geleneksel | R3: TRUE | S3: FALSE | T3: Randevu İptal | U3: Betül Demir | V3: Muammer Çakır | X3: 44641 | Y3: 44643 | AA3: Görüşüldü | AB3: 44578 | AC3: Görüşüldü | AD3: 44641 | AK3: Hatem Soyaslan | AL3: Betül Demir
A4: 622c7bc1704f8c7d9226c83e | B4: 1965 Efsane Tantuni, Tepebaşı (Erenköy Mah.) | C4: =VLOOKUP(A4,Import!A:C,3,false) -> DOĞRU | D4: Döner | E4: =VLOOKUP(A4,Import!A:J,5,0) | F4: =VLOOKUP(A4,Import!A:J,6,0) | G4: =VLOOKUP(A4,Import!A:J,7,0) -> 0 | H4: =VLOOKUP(A4,Import!A:J,8,0) -> 11 | I4: =VLOOKUP(A4,Import!A:J,9,0) -> 11 | J4: =VLOOKUP(A4,Import!A:J,10,0) -> 0 | K4: METİN YAMAN | L4: 5441602676 | M4: Odunpazarı | N4: Yenidoğan | O4: Erenköy Mahallesi, Sevinç Caddesi 12/A Odunpazarı/Eskişehir | P4: =VLOOKUP(A4,Import!A:P,16,0) -> Geleneksel | R4: FALSE | S4: FALSE
A5: 5fa474ba857e1a1eb42ad590 | B5: 1991 Tarihi Ortaköy Kumpircisi (Hoşnudiye Mah. - Cassaba Modern) | C5: =VLOOKUP(A5,Import!A:C,3,false) -> DOĞRU | D5: Sokak Lezzetleri | E5: =VLOOKUP(A5,Import!A:J,5,0) -> 1646 | F5: =VLOOKUP(A5,Import!A:J,6,0) | G5: =VLOOKUP(A5,Import!A:J,7,0) -> 6 | H5: =VLOOKUP(A5,Import!A:J,8,0) -> 15 | I5: =VLOOKUP(A5,Import!A:J,9,0) -> 21 | J5: =VLOOKUP(A5,Import!A:J,10,0) -> 0.29 | K5: =VLOOKUP(A5,Import!A:P,11,0) -> NİHAL PEKÇOLAKLAR | L5: 8508404512 | M5: Tepebaşı | N5: Hoşnudiye | O5: Hoşnudiye mah.770.sok.no:4 c103 Cassaba, Modern AVM, 26030 Tepebaşı | P5: =VLOOKUP(A5,Import!A:P,16,0) -> Geleneksel | Q5: 0-15 | R5: TRUE | S5: FALSE | W5: dç istemez/ tam/ fotoğraflar için arandı gerek yok diğerleri ile zaten benzer gibi diğerlerinden alıp koyabilirsiniz dedi. | AA5: Görüşüldü | AB5: 44517 | AC5: Görüşüldü | AD5: 44525 | AK5: Tuğba Buyur | AL5: Kübra Toprak | AP5: Gökhan Çakır
A6: 5f74d7639fe43ab7463ac6a6 | B6: 1991 Tarihi Ortaköy Kumpircisi Premium (Eskibağlar) | C6: =VLOOKUP(A6,Import!A:C,3,false) -> DOĞRU | D6: Sokak Lezzetleri | E6: =VLOOKUP(A6,Import!A:J,5,0) -> 5391 | F6: =VLOOKUP(A6,Import!A:J,6,0) -> 157 | G6: =VLOOKUP(A6,Import!A:J,7,0) -> 6 | H6: =VLOOKUP(A6,Import!A:J,8,0) -> 1 | I6: =VLOOKUP(A6,Import!A:J,9,0) -> 7 | J6: =VLOOKUP(A6,Import!A:J,10,0) -> 0.86 | K6: =VLOOKUP(A6,Import!A:P,11,0) -> EBRU SÖNMEZ | L6: 5442626140 | M6: Tepebaşı | N6: Eskibağlar | O6: Eskibağlar mah. Kumlubel sk. No:8 Tepebaşı/Eskişehir | P6: =VLOOKUP(A6,Import!A:P,16,0) -> Geleneksel | Q6: 0-15 | R6: TRUE | S6: TRUE | AP6: Gökhan Çakır
A7: 600968ecf69aa48850474729 | B7: 3 Monkey Burger, Tepebaşı (Batıkent Mah) | C7: =VLOOKUP(A7,Import!A:C,3,false) -> DOĞRU | D7: Burger | E7: =VLOOKUP(A7,Import!A:J,5,0) -> 6197 | F7: =VLOOKUP(A7,Import!A:J,6,0) -> 121 | G7: =VLOOKUP(A7,Import!A:J,7,0) -> 35 | H7: =VLOOKUP(A7,Import!A:J,8,0) -> 37 | I7: =VLOOKUP(A7,Import!A:J,9,0) -> 72 | J7: =VLOOKUP(A7,Import!A:J,10,0) -> 0.49 | K7: =VLOOKUP(A7,Import!A:P,11,0) -> Gökhan Demircan | L7: 5380933426 | M7: Tepebaşı | N7: Batıkent | O7: Batıkent Mah. Dizili Sok. No:11 Tepebaşı/ Eskişehir | P7: =VLOOKUP(A7,Import!A:P,16,0) -> Geleneksel | Q7: 16-25 | R7: TRUE | S7: FALSE | T7: Randevu Alındı | U7: Yurdagül Kulaksız | V7: Muammer Çakır | W7: gökhan bey/ 5534959158 | X7: 44566 | Y7: 44568 | AA7: Görüşüldü | AB7: 44525 | AC7: Dönüş Yapacak | AD7: 44565 | AE7: Görüşüldü | AF7: 44566 | AK7: Kübra Toprak | AL7: Betül Demir | AM7: Yurdagül Kulaksız | AP7: Gökhan Çakır
A8: 5f3671600274b83d2c5ca2f9 | B8: Aba Fast Food & Kahvaltı, Odunpazarı (Kırmızıtoprak Mah.) | C8: =VLOOKUP(A8,Import!A:C,3,false) -> DOĞRU | D8: Tost & Sandviç | E8: =VLOOKUP(A8,Import!A:J,5,0) -> 1560 | F8: =VLOOKUP(A8,Import!A:J,6,0) -> 20 | G8: =VLOOKUP(A8,Import!A:J,7,0) -> 0 | H8: =VLOOKUP(A8,Import!A:J,8,0) -> 55 | I8: =VLOOKUP(A8,Import!A:J,9,0) -> 55 | J8: =VLOOKUP(A8,Import!A:J,10,0) -> 0 | K8: =VLOOKUP(A8,Import!A:P,11,0) -> HOSSEIN DELAVANDANI | L8: 5377449269 | M8: Tepebaşı | N8: Hoşnudiye | O8: Kırmızıtoprak Mahallesi, Mustafa Kemal Atatürk Caddesi no: 95 / A | P8: =VLOOKUP(A8,Import!A:P,16,0) -> Geleneksel | Q8: 16-25 | R8: TRUE | S8: FALSE | T8: Dönüş Yapacak | W8: 3 hafta sonra randevu için arayacak // kendisidönecek / yeni dükana taşınmış bir hafta 10 güne oluşturmak istedi / henüz kendisini düzene sokamamış çok fazla türkçe konuşamıyor kendisi bana dönüş yapacak sık sık aranmak istemez | AA8: Görüşüldü | AB8: 44515 | AC8: Ulaşılamadı | AD8: 44525 | AE8: Dönüş Yapacak | AF8: 44547 | AK8: Betül Demir | AL8: Hatem Soyaslan | AM8: Hatem Soyaslan | AP8: Gökhan Çakır
A9: 5f328f81572e4cb196c3ce23 | B9: Abartı Izgara (Cumhuriye Mah.) | C9: =VLOOKUP(A9,Import!A:C,3,false) -> DOĞRU | D9: Kebap | E9: =VLOOKUP(A9,Import!A:J,5,0) -> 2481 | F9: =VLOOKUP(A9,Import!A:J,6,0) -> 495 | G9: =VLOOKUP(A9,Import!A:J,7,0) -> 0 | H9: =VLOOKUP(A9,Import!A:J,8,0) -> 47 | I9: =VLOOKUP(A9,Import!A:J,9,0) -> 47 | J9: =VLOOKUP(A9,Import!A:J,10,0) -> 0 | K9: =VLOOKUP(A9,Import!A:P,11,0) -> Mehmet Önal | L9: 2222342312 | M9: Tepebaşı | N9: Hoşnudiye | O9: Cumhuriyet Mah., Tepebaşı, Eskişehir, Türkiye, | P9: =VLOOKUP(A9,Import!A:P,16,0) -> Geleneksel | Q9: 16-25 | R9: TRUE | S9: TRUE | W9: fotoğraflar için arandı yetkili yok. | AA9: Yetkili Yok | AB9: 44525 | AK9: Kübra Toprak | AP9: Gökhan Çakır
A10: 5f35b5c7da66dcbc5ad6f478 | B10: ABC Kumru, Odunpazarı (İstiklal Mah.) | C10: =VLOOKUP(A10,Import!A:C,3,false) -> DOĞRU | D10: Sokak Lezzetleri | E10: =VLOOKUP(A10,Import!A:J,5,0) -> 1297 | F10: =VLOOKUP(A10,Import!A:J,6,0) -> 30 | G10: =VLOOKUP(A10,Import!A:J,7,0) -> 8 | H10: =VLOOKUP(A10,Import!A:J,8,0) -> 1 | I10: =VLOOKUP(A10,Import!A:J,9,0) -> 9 | J10: =VLOOKUP(A10,Import!A:J,10,0) -> 0.89 | K10: =VLOOKUP(A10,Import!A:P,11,0) -> AHMET SERTKAL | L10: 5359112020 | M10: Odunpazarı | N10: İstiklal | O10: İstiklal, Mustafa Kemal Atatürk Cd No:68, 26000 Odunpazarı/Eskişehir | P10: =VLOOKUP(A10,Import!A:P,16,0) -> Geleneksel | Q10: 16-25 | R10: TRUE | S10: FALSE | V10: Altuğ | X10: 44232 | Y10: 44246 | AP10: Gökhan Çakır
A11: 61c0d747b396924295573f37 | B11: Abdullah Amcabey Baklavaları, Odunpazarı (Emek Mah.) | C11: =VLOOKUP(A11,Import!A:C,3,false) -> DOĞRU | D11: Pasta & Tatlı | E11: =VLOOKUP(A11,Import!A:J,5,0) -> 47 | F11: =VLOOKUP(A11,Import!A:J,6,0) | G11: =VLOOKUP(A11,Import!A:J,7,0) -> 11 | H11: =VLOOKUP(A11,Import!A:J,8,0) -> 5 | I11: =VLOOKUP(A11,Import!A:J,9,0) -> 16 | J11: =VLOOKUP(A11,Import!A:J,10,0) -> 0.69 | K11: Funda Özkan | L11: 5458789294 | M11: Odunpazarı | N11: Emek | O11: Emek Mah. Dilek Caddesi No:17/A Odunpazarı Eskişehir | P11: =VLOOKUP(A11,Import!A:P,16,0) -> Geleneksel | R11: TRUE | S11: FALSE | T11: Randevu Alındı | U11: Hatem Soyaslan | V11: Muammer Çakır | X11: 44572 | Y11: 44581 | AA11: Görüşüldü | AB11: 44572 | AK11: Hatem Soyaslan
A12: 61dcac0ef55c685ed4f65ba6 | B12: Abdullah Amcabey Baklavaları, Odunpazarı (Osmangazi Mah.) | C12: =VLOOKUP(A12,Import!A:C,3,false) -> DOĞRU | D12: Pasta & Tatlı | E12: =VLOOKUP(A12,Import!A:J,5,0) -> 195 | F12: =VLOOKUP(A12,Import!A:J,6,0) -> 62 | G12: =VLOOKUP(A12,Import!A:J,7,0) -> 28 | H12: =VLOOKUP(A12,Import!A:J,8,0) -> 9 | I12: =VLOOKUP(A12,Import!A:J,9,0) -> 37 | J12: =VLOOKUP(A12,Import!A:J,10,0) -> 0.76 | K12: Ahmet Harun Akbulut | L12: 5461962025 | M12: Odunpazarı | N12: Osmangazi | O12: Osmangazi Mah. Basın Şehitleri Cad. No:275 C Odunpazarı Eskişehir | P12: =VLOOKUP(A12,Import!A:P,16,0) -> Geleneksel | R12: TRUE | S12: FALSE | T12: Randevu Alındı | U12: Betül Demir | V12: Muammer Çakır | X12: 44621 | Y12: 44622 | AA12: Görüşüldü | AB12: 44578 | AC12: Görüşüldü | AD12: 44621 | AK12: Betül Demir | AL12: Betül Demir
A13: 5f681b00021726a862107d15 | B13: Abi Tost & Kahvaltı & Köfte (Kırmızıtoprak Mah.) | C13: =VLOOKUP(A13,Import!A:C,3,false) -> DOĞRU | D13: Kahvaltı | E13: =VLOOKUP(A13,Import!A:J,5,0) -> 1508 | F13: =VLOOKUP(A13,Import!A:J,6,0) -> 57 | G13: =VLOOKUP(A13,Import!A:J,7,0) -> 15 | H13: =VLOOKUP(A13,Import!A:J,8,0) -> 60 | I13: =VLOOKUP(A13,Import!A:J,9,0) -> 75 | J13: =VLOOKUP(A13,Import!A:J,10,0) -> 0.2 | K13: =VLOOKUP(A13,Import!A:P,11,0) -> İZZET KAYALI | L13: 5355003005 | M13: Odunpazarı | N13: Kırmızıtoprak | O13: Kırmızıtoprak mah. Mustafa Kemal Atatürk Cad. No: 95 / c Odunpazarı / Eskişehir | P13: =VLOOKUP(A13,Import!A:P,16,0) -> Geleneksel | Q13: 16-25 | R13: TRUE | S13: FALSE | T13: Randevu Alındı | V13: Altuğ | W13: TEYİT İÇİN ARANDI ÇEKİM GERÇEKLEŞMİŞ | X13: 44250 | Y13: 44258 | AP13: Gökhan Çakır
A14: 6023ddaf2789557d9b92211a | B14: Ablanın Yeri, Tepebaşı (Cumhuriye Mah.) | C14: =VLOOKUP(A14,Import!A:C,3,false) -> DOĞRU | D14: Tost & Sandviç | E14: =VLOOKUP(A14,Import!A:J,5,0) -> 2738 | F14: =VLOOKUP(A14,Import!A:J,6,0) -> 71 | G14: =VLOOKUP(A14,Import!A:J,7,0) -> 0 | H14: =VLOOKUP(A14,Import!A:J,8,0) -> 83 | I14: =VLOOKUP(A14,Import!A:J,9,0) -> 83 | J14: =VLOOKUP(A14,Import!A:J,10,0) -> 0 | K14: =VLOOKUP(A14,Import!A:P,11,0) -> Ahmet Temel | L14: 5541918811 | M14: Tepebaşı | N14: Cumhuriye | O14: Cumhuriye Mah. Tersel Sk. No: 6 D Tepebaşı/Eskişehir | P14: =VLOOKUP(A14,Import!A:P,16,0) -> Geleneksel | Q14: 35+ | R14: TRUE | S14: FALSE | T14: Çekim İstemiyor | W14: ürünleri hepsini çıkaramam çekim istemiyorum demektedir.//açmadılar/ikna edilmek üzere arandı açmıyor/ ne dediysem yok ben istemiyorum dedi istemiyor kesinlikle aranmasın. | AA14: Ulaşılamadı | AB14: 44525 | AC14: Görüşüldü | AD14: 44530 | AK14: Hatem Soyaslan | AL14: Kübra Toprak | AP14: Gökhan Çakır
A15: 5f329ce0fb6dd9c3badd3098 | B15: Abone Mersin Tantuni, Arifiye | C15: =VLOOKUP(A15,Import!A:C,3,false) -> DOĞRU | D15: Sokak Lezzetleri | E15: =VLOOKUP(A15,Import!A:J,5,0) -> 5294 | F15: =VLOOKUP(A15,Import!A:J,6,0) -> 148 | G15: =VLOOKUP(A15,Import!A:J,7,0) -> 25 | H15: =VLOOKUP(A15,Import!A:J,8,0) -> 28 | I15: =VLOOKUP(A15,Import!A:J,9,0) -> 53 | J15: =VLOOKUP(A15,Import!A:J,10,0) -> 0.47 | K15: =VLOOKUP(A15,Import!A:P,11,0) -> İlyas Uzun | L15: 2222213326 | M15: Odunpazarı | N15: Arifiye | O15: Arifiye, Tayfun Sk. No:3-D, 26000 Odunpazarı/Eskişehir | P15: =VLOOKUP(A15,Import!A:P,16,0) -> Geleneksel | Q15: 16-25 | R15: TRUE | S15: FALSE | T15: Randevu Alındı | U15: Betül Demir | V15: Muammer Çakır | W15: Önceki çekim randevusunu gidilmemiş yeni tarih verildi./çekim gerçekleşmiş iki ay oldu dediler / yetkili yoktu ileteceek | X15: 44502 | Y15: 44504 | AA15: Görüşüldü | AB15: 44376 | AC15: Dönüş Yapacak | AD15: 44496 | AE15: Ulaşılamadı | AF15: 44498 | AG15: Görüşüldü | AH15: 44502 | AK15: Nazmiye Yuka | AL15: Betül Demir | AM15: Ezgi Turan | AN15: Betül Demir | AP15: Gökhan Çakır
A16: 5f3152cfd0c302043a3fce6d | B16: Abone Meşhur Tostçu (Yenibağlar Mah.) | C16: =VLOOKUP(A16,Import!A:C,3,false) -> DOĞRU | D16: Tost & Sandviç | E16: =VLOOKUP(A16,Import!A:J,5,0) -> 5915 | F16: =VLOOKUP(A16,Import!A:J,6,0) -> 187 | G16: =VLOOKUP(A16,Import!A:J,7,0) -> 0 | H16: =VLOOKUP(A16,Import!A:J,8,0) -> 193 | I16: =VLOOKUP(A16,Import!A:J,9,0) -> 193 | J16: =VLOOKUP(A16,Import!A:J,10,0) -> 0 | K16: =VLOOKUP(A16,Import!A:P,11,0) -> ALİ KARGA | L16: 2223227770 | M16: Tepebaşı | N16: Yenibağlar | O16: Yenibağlar, No:, Martı Sk. No:17, 26170 Tepebaşı/Eskişehir | P16: =VLOOKUP(A16,Import!A:P,16,0) -> Geleneksel | Q16: 16-25 | R16: TRUE | S16: FALSE | T16: Devir | W16: DEVİR EDEBİLİR // yetkili yokmuş | AP16: Gökhan Çakır
A17: 5f3517363322a8a481d8bc6b | B17: Abur Cubur Pizza, Eskibağlar | C17: =VLOOKUP(A17,Import!A:C,3,false) -> DOĞRU | D17: Pizza | E17: =VLOOKUP(A17,Import!A:J,5,0) -> 3065 | F17: =VLOOKUP(A17,Import!A:J,6,0) -> 201 | G17: =VLOOKUP(A17,Import!A:J,7,0) -> 65 | H17: =VLOOKUP(A17,Import!A:J,8,0) -> 36 | I17: =VLOOKUP(A17,Import!A:J,9,0) -> 101 | J17: =VLOOKUP(A17,Import!A:J,10,0) -> 0.64 | K17: =VLOOKUP(A17,Import!A:P,11,0) -> AHMET İSMAİL YAŞAR | L17: 5444632015 | M17: Tepebaşı | N17: Eskibağlar | O17: Eskibağlar, Oğuz Sk. No:6/B, 26020 Eskişehir Merkez/Eskişehir | P17: =VLOOKUP(A17,Import!A:P,16,0) -> Geleneksel | Q17: 16-25 | R17: TRUE | S17: FALSE | T17: Randevu Alındı | U17: Emre Dalgıç | V17: Emir | W17: Bahçelievler mah. Fulya sokak no:22/A Bahçelievler / Eskişehir/TEYİT İÇİN ARANDI ÇEKİM GERÇEKLEŞMİŞ | X17: 44267 | Y17: 44271 | AP17: Gökhan Çakır
A18: 5f3150d00c243ba11365248c | B18: Acayip Izgara Köfte & Sucuk (Yenibağlar Mah.) | C18: =VLOOKUP(A18,Import!A:C,3,false) -> DOĞRU | D18: Kebap | E18: =VLOOKUP(A18,Import!A:J,5,0) -> 1078 | F18: =VLOOKUP(A18,Import!A:J,6,0) -> 13 | G18: =VLOOKUP(A18,Import!A:J,7,0) -> 0 | H18: =VLOOKUP(A18,Import!A:J,8,0) -> 25 | I18: =VLOOKUP(A18,Import!A:J,9,0) -> 25 | J18: =VLOOKUP(A18,Import!A:J,10,0) -> 0 | K18: =VLOOKUP(A18,Import!A:P,11,0) -> ALİ KARGA | L18: 5416921792 | M18: Tepebaşı | N18: Yenibağlar | O18: Yenibağlar Mah., Martı Sok., No:17/B, Tepebaşı, Eskişehir, Türkiye, | P18: =VLOOKUP(A18,Import!A:P,16,0) -> Geleneksel | Q18: 16-25 | R18: TRUE | S18: FALSE | T18: Çekim İstemiyor | W18: MEŞGULE ATIYOR | AP18: Gökhan Çakır
A19: 60c0e3ed40dfe0e01ed9492b | B19: Acıktım Mersin Tantuni,Odunpazarı (Büyükdere Mah.) | C19: =VLOOKUP(A19,Import!A:C,3,false) -> DOĞRU | D19: Döner | E19: =VLOOKUP(A19,Import!A:J,5,0) -> 2740 | F19: =VLOOKUP(A19,Import!A:J,6,0) -> 91 | G19: =VLOOKUP(A19,Import!A:J,7,0) -> 5 | H19: =VLOOKUP(A19,Import!A:J,8,0) -> 28 | I19: =VLOOKUP(A19,Import!A:J,9,0) -> 33 | J19: =VLOOKUP(A19,Import!A:J,10,0) -> 0.15 | K19: =VLOOKUP(A19,Import!A:P,11,0) -> HAMİT KARAÇOL | L19: 5453569103 | M19: Odunpazarı | N19: Büyükdere | O19: Büyükdere Mah. Millet Cad. No: 66 A Odunpazarı / Eskişehir | P19: =VLOOKUP(A19,Import!A:P,16,0) -> Geleneksel | R19: TRUE | S19: FALSE | T19: Başka Şubeden Çekilecek | W19: damak tantuni ile aynı ürünler varmış ordan alıp koyabilirsiniz der / damak tantunidekilerin koyulmasını istedi hala koyulmamış (Damak Tantuni, Odunpazarı (Büyükdere Mah.) | AA19: Görüşüldü | AB19: 44376 | AC19: Görüşüldü | AD19: 44496 | AK19: Hatem Soyaslan | AL19: Betül Demir | AP19: Gökhan Çakır
A20: 5ff0ecb4f351dc2884680cb5 | B20: Ada Çibörek, Tepebaşı ( Hoşnudiye Mah.) | C20: =VLOOKUP(A20,Import!A:C,3,false) -> DOĞRU | D20: Mantı | E20: =VLOOKUP(A20,Import!A:J,5,0) -> 219 | F20: =VLOOKUP(A20,Import!A:J,6,0) | G20: =VLOOKUP(A20,Import!A:J,7,0) -> 34 | H20: =VLOOKUP(A20,Import!A:J,8,0) -> 40 | I20: =VLOOKUP(A20,Import!A:J,9,0) -> 74 | J20: =VLOOKUP(A20,Import!A:J,10,0) -> 0.46 | K20: =VLOOKUP(A20,Import!A:P,11,0) -> ESRA ÇETİNKAYA ENGİN | L20: 2222309249 | M20: Tepebaşı | N20: Hoşnudiye | O20: Hoşnudiye Mh. Sahilyolu Sk. Adalar No:20 | P20: =VLOOKUP(A20,Import!A:P,16,0) -> Geleneksel | Q20: 16-25 | R20: TRUE | S20: FALSE | T20: Randevu Alındı | U20: Emre Dalgıç | V20: Melika | W20: Eksik ürünlerin fotoğrafların çekimi yapılacak %65 oranında eksik.//TEYİT İÇİN ARANDI ÇEKİM GERÇEKLEŞMİŞ/yt yok | X20: 44267 | Y20: 44270 | AA20: Yetkili Yok | AB20: 44517 | AK20: Tuğba Buyur | AP20: Gökhan Çakır
A21: 620ea837141520d8f125d24b | B21: Adalar Mersin Tantuni, Odunpazarı (İstiklal Mah.) | C21: =VLOOKUP(A21,Import!A:C,3,false) -> DOĞRU | D21: Sokak Lezzetleri | E21: =VLOOKUP(A21,Import!A:J,5,0) -> 2 | F21: =VLOOKUP(A21,Import!A:J,6,0) | G21: =VLOOKUP(A21,Import!A:J,7,0) -> 0 | H21: =VLOOKUP(A21,Import!A:J,8,0) -> 4 | I21: =VLOOKUP(A21,Import!A:J,9,0) -> 4 | J21: =VLOOKUP(A21,Import!A:J,10,0) -> 0 | K21: Tahsin Demirok | L21: 5437640523 | M21: Odunpazarı | N21: İstiklal | O21: İstiklal Mah. Şirin Sok. No:45 A Odunpazarı Eskişehir | P21: =VLOOKUP(A21,Import!A:P,16,0) -> Geleneksel | R21: TRUE | S21: FALSE | W21: gönülsüz gibi 1 ay sonra bi bakalım dedi | AA21: Görüşüldü | AB21: 44628 | AK21: Sude Alkan
A22: 5fda79793edee4493d088e97 | B22: Adalar Pide & Kebap, Odunpazarı (İstiklal Mah.) | C22: =VLOOKUP(A22,Import!A:C,3,false) -> DOĞRU | D22: Lahmacun | E22: =VLOOKUP(A22,Import!A:J,5,0) -> 8262 | F22: =VLOOKUP(A22,Import!A:J,6,0) -> 422 | G22: =VLOOKUP(A22,Import!A:J,7,0) -> 11 | H22: =VLOOKUP(A22,Import!A:J,8,0) -> 38 | I22: =VLOOKUP(A22,Import!A:J,9,0) -> 49 | J22: =VLOOKUP(A22,Import!A:J,10,0) -> 0.22 | K22: =VLOOKUP(A22,Import!A:P,11,0) -> Mehmet Yıldız | L22: 2223852679 | M22: Odunpazarı | N22: İstiklal | O22: İstiklal Mah. Akınlar Sok. No:29 A Odunpazarı/ Eskişehir | P22: =VLOOKUP(A22,Import!A:P,16,0) -> Geleneksel | Q22: 16-25 | R22: TRUE | S22: FALSE | U22: Güneş | V22: Emir | W22: ulaşılamadı | X22: 44261 | Y22: 44264 | AA22: Ulaşılamadı | AB22: 44483 | AC22: Ulaşılamadı | AD22: 44504 | AE22: Ulaşılamadı | AF22: 44547 | AK22: Zeliha Özer | AL22: Zeliha Özer | AM22: Tuğba Buyur | AP22: Gökhan Çakır
A23: 620b97881c3900be88e127a0 | B23: Adalar Tantuni, Odunpazarı (İstiklal Mah.) | C23: =VLOOKUP(A23,Import!A:C,3,false) -> DOĞRU | D23: Sokak Lezzetleri | E23: =VLOOKUP(A23,Import!A:J,5,0) -> 955 | F23: =VLOOKUP(A23,Import!A:J,6,0) -> 241 | G23: =VLOOKUP(A23,Import!A:J,7,0) -> 0 | H23: =VLOOKUP(A23,Import!A:J,8,0) -> 19 | I23: =VLOOKUP(A23,Import!A:J,9,0) -> 19 | J23: =VLOOKUP(A23,Import!A:J,10,0) -> 0 | K23: TAHİR TAŞ | L23: 5461232521 | M23: Odunpazarı | N23: İstiklal | O23: İstiklal Mah. Başarılı Sok. No:17 E Odunpazarı Eskişehir | P23: =VLOOKUP(A23,Import!A:P,16,0) -> Geleneksel | R23: TRUE | S23: FALSE | T23: Çekim İstemiyor | W23: aradığınız kişiye ulaşılmıyor/ terbiysiz surartıma kapatarak tekrar aradığımda da buyrun buyrun diye konuştu gelin dedi gelmeyin dedi randeuvu oluşturulmadı | AA23: Ulaşılamadı | AB23: 44620 | AC23: Görüşüldü | AD23: 44628 | AK23: Hatem Soyaslan | AL23: Hatem Soyaslan
A24: 61c0f12f6d2da40466111cf9 | B24: Adalı Kumru & Fast Food, Tepebaşı (Şirintepe Mah.) | C24: =VLOOKUP(A24,Import!A:C,3,false) -> DOĞRU | D24: Tost & Sandviç | E24: =VLOOKUP(A24,Import!A:J,5,0) -> 613 | F24: =VLOOKUP(A24,Import!A:J,6,0) -> 85 | G24: =VLOOKUP(A24,Import!A:J,7,0) -> 29 | H24: =VLOOKUP(A24,Import!A:J,8,0) -> 37 | I24: =VLOOKUP(A24,Import!A:J,9,0) -> 66 | J24: =VLOOKUP(A24,Import!A:J,10,0) -> 0.44 | K24: ALİ ERDÖNMEZ | L24: 5449143300 | M24: Tepebaşı | N24: Şirintepe | O24: Şirintepe Mah. Yaylapınar Cad. NO: 96/ A TEPEBAŞI/ ESKİŞEHİR | P24: =VLOOKUP(A24,Import!A:P,16,0) -> Geleneksel | R24: TRUE | S24: FALSE | T24: Randevu Alındı | U24: Hatem Soyaslan | V24: Muammer Çakır | X24: 44554 | Y24: 44557 | AA24: Görüşüldü | AB24: 44554 | AK24: Hatem Soyaslan
A25: 5f3378fd30bf6361f32c87ca | B25: Adana Böreği Yunus Usta, Tepebaşı (Hoşnudiye Mah.) | C25: =VLOOKUP(A25,Import!A:C,3,false) -> DOĞRU | D25: Börek | E25: =VLOOKUP(A25,Import!A:J,5,0) -> 2378 | F25: =VLOOKUP(A25,Import!A:J,6,0) -> 45 | G25: =VLOOKUP(A25,Import!A:J,7,0) -> 19 | H25: =VLOOKUP(A25,Import!A:J,8,0) -> 15 | I25: =VLOOKUP(A25,Import!A:J,9,0) -> 34 | J25: =VLOOKUP(A25,Import!A:J,10,0) -> 0.56 | K25: =VLOOKUP(A25,Import!A:P,11,0) -> MERVE TINMAZ | L25: 5524240424 | M25: Tepebaşı | N25: Hoşnudiye | O25: Hoşnudiye, İstasyon Cd. No:41, 26130 Tepebaşı/Eskişehir | P25: =VLOOKUP(A25,Import!A:P,16,0) -> Geleneksel | Q25: 0-15 | R25: TRUE | S25: FALSE | T25: Randevu Alındı | U25: Kübra Toprak | V25: Muammer Çakır | W25: numara kullanılmıyor/ 0532 786 00 08 gülseren hanımdan randevu alındı. | X25: 44530 | Y25: 44531 | AA25: Ulaşılamadı | AB25: 44517 | AC25: Görüşüldü | AD25: 44530 | AK25: Tuğba Buyur | AL25: Kübra Toprak | AP25: Gökhan Çakır
A26: 5f3517c5f86cbfd09410dec6 | B26: Adanalı Bekir Usta, Tepebaşı (Hoşnudiye Mah.) | C26: =VLOOKUP(A26,Import!A:C,3,false) -> DOĞRU | D26: Kebap | E26: =VLOOKUP(A26,Import!A:J,5,0) -> 689 | F26: =VLOOKUP(A26,Import!A:J,6,0) -> 2 | G26: =VLOOKUP(A26,Import!A:J,7,0) -> 6 | H26: =VLOOKUP(A26,Import!A:J,8,0) -> 5 | I26: =VLOOKUP(A26,Import!A:J,9,0) -> 11 | J26: =VLOOKUP(A26,Import!A:J,10,0) -> 0.55 | K26: =VLOOKUP(A26,Import!A:P,11,0) -> Keziban Coşman | L26: 2222215047 | M26: Tepebaşı | N26: Hoşnudiye | O26: Hoşnudiye, 36, Vural Sk., 26130 Tepebaşı/Eskişehir | P26: =VLOOKUP(A26,Import!A:P,16,0) -> Geleneksel | Q26: 0-15 | R26: TRUE | S26: FALSE | T26: Randevu Alındı | V26: Melika | W26: çekilmiş | X26: 44231 | Y26: 44237 | AP26: Gökhan Çakır
A27: 61e187b8401ceca56cd942f7 | B27: Adanalı Dürümcü İbrahim Usta, Tepebaşı (Cumhuriye Mah.) | C27: =VLOOKUP(A27,Import!A:C,3,false) -> DOĞRU | D27: Döner | E27: =VLOOKUP(A27,Import!A:J,5,0) -> 790 | F27: =VLOOKUP(A27,Import!A:J,6,0) -> 70 | G27: =VLOOKUP(A27,Import!A:J,7,0) -> 0 | H27: =VLOOKUP(A27,Import!A:J,8,0) -> 19 | I27: =VLOOKUP(A27,Import!A:J,9,0) -> 19 | J27: =VLOOKUP(A27,Import!A:J,10,0) -> 0 | K27: Tekin Coşman | L27: 5324867178 | M27: Tepebaşı | N27: Cumhuriyet | O27: Cumhuriye Mah. Cengiz Topel Cad. No:80 B Tepebaşı Eskişehir | P27: =VLOOKUP(A27,Import!A:P,16,0) -> Geleneksel | R27: TRUE | S27: FALSE | T27: Ulaşılamadı | W27: açmadı | AA27: Ulaşılamadı | AB27: 44596 | AK27: Hatem Soyaslan
A28: 5f7b1a02ec14c4d9cd0273f8 | B28: Adanalı Dürümcü Soner Usta, Cumhuriye | C28: =VLOOKUP(A28,Import!A:C,3,false) -> DOĞRU | D28: Kebap | E28: =VLOOKUP(A28,Import!A:J,5,0) -> 4919 | F28: =VLOOKUP(A28,Import!A:J,6,0) -> 31 | G28: =VLOOKUP(A28,Import!A:J,7,0) -> 12 | H28: =VLOOKUP(A28,Import!A:J,8,0) -> 21 | I28: =VLOOKUP(A28,Import!A:J,9,0) -> 33 | J28: =VLOOKUP(A28,Import!A:J,10,0) -> 0.36 | K28: =VLOOKUP(A28,Import!A:P,11,0) -> SONER COŞMAN | L28: 2222212601 | M28: Tepebaşı | N28: Eskibağlar | O28: Cumhuriye mah. Zübeyde Hanım Cad. No: 4/A Tepebaşı/Eskişehir | P28: =VLOOKUP(A28,Import!A:P,16,0) -> Geleneksel | Q28: 26-35 | R28: TRUE | S28: FALSE | T28: Randevu Alındı | V28: Melika | W28: TEYİT İÇİN ARANDI ÇEKİM GERÇEKLEŞMİŞ | X28: 44231 | Y28: 44235 | AP28: Gökhan Çakır
A29: 61bb78881bcbb528923d4bf0 | B29: Adanalı Sezer Usta Pide & Lahmacun, Tepebaşı (Hoşnudiye Mah.) | C29: =VLOOKUP(A29,Import!A:C,3,false) -> DOĞRU | D29: Pide | E29: =VLOOKUP(A29,Import!A:J,5,0) -> 197 | F29: =VLOOKUP(A29,Import!A:J,6,0) -> 24 | G29: =VLOOKUP(A29,Import!A:J,7,0) -> 0 | H29: =VLOOKUP(A29,Import!A:J,8,0) -> 21 | I29: =VLOOKUP(A29,Import!A:J,9,0) -> 21 | J29: =VLOOKUP(A29,Import!A:J,10,0) -> 0 | K29: SEZER DEMİR | L29: 5525007171 | M29: Tepebaşı | N29: Hoşnudiye | O29: Hoşnudiye, Ay Lounge Altı, Şahin Cd. No:76/C, 26130 Tepebaşı/Eskişehir | P29: =VLOOKUP(A29,Import!A:P,16,0) -> Geleneksel | R29: TRUE | S29: FALSE | T29: Ulaşılamadı | W29: yt yok / yetkili yok | AA29: Yetkili Yok | AB29: 44565 | AC29: Yetkili Yok | AD29: 44571 | AK29: Selcan Topçu | AL29: Hatem Soyaslan
A30: 60e04c27eed350a83e7d1054 | B30: Adanus Ocakbaşı, Tepebaşı (Cumhuriye Mah.) | C30: =VLOOKUP(A30,Import!A:C,3,false) -> YANLIŞ | D30: Kebap | E30: =VLOOKUP(A30,Import!A:J,5,0) -> 121 | F30: =VLOOKUP(A30,Import!A:J,6,0) | G30: =VLOOKUP(A30,Import!A:J,7,0) -> 0 | H30: =VLOOKUP(A30,Import!A:J,8,0) -> 14 | I30: =VLOOKUP(A30,Import!A:J,9,0) -> 14 | J30: =VLOOKUP(A30,Import!A:J,10,0) -> 0 | K30: =VLOOKUP(A30,Import!A:P,11,0) -> Özlem Ürün | L30: 5358778441 | M30: Tepebaşı | N30: Cumhuriye | O30: Cumhuriye Mah. Yaprak Sk. No:6A Tepebaşı/Eskişehir | P30: =VLOOKUP(A30,Import!A:P,16,0) -> Geleneksel | R30: TRUE | S30: FALSE | T30: İleride Randevu Alınacak | W30: karantinadaymış/açmadı | AA30: Tekrar Aranacak | AB30: 44496 | AC30: Ulaşılamadı | AD30: 44524 | AK30: Hatem Soyaslan | AL30: Hatem Soyaslan | AP30: Gökhan Çakır
A31: 5f67f7192702e9083fb20a37 | B31: Adıyaman Çiğ Köfte Murat Usta, Tepebaşı (Cumhuriye Mah.) | C31: =VLOOKUP(A31,Import!A:C,3,false) -> DOĞRU | D31: Çiğ Köfte | E31: =VLOOKUP(A31,Import!A:J,5,0) -> 692 | F31: =VLOOKUP(A31,Import!A:J,6,0) -> 17 | G31: =VLOOKUP(A31,Import!A:J,7,0) -> 11 | H31: =VLOOKUP(A31,Import!A:J,8,0) -> 12 | I31: =VLOOKUP(A31,Import!A:J,9,0) -> 23 | J31: =VLOOKUP(A31,Import!A:J,10,0) -> 0.48 | K31: =VLOOKUP(A31,Import!A:P,11,0) -> Mehmet Tüfenk | L31: 5337761568 | M31: Tepebaşı | N31: Ömerağa | O31: Cumhuriye mah. Zübeyde Hanım Cad. No: 26/A Tepebaşı/Eskişehir | P31: =VLOOKUP(A31,Import!A:P,16,0) -> Geleneksel | Q31: 16-25 | R31: TRUE | S31: FALSE | T31: Randevu Alındı | V31: Emir | W31: TEYİT İÇİN ARANDI ÇEKİM GERÇEKLEŞMİŞ | X31: 44232 | Y31: 44236 | AP31: Gökhan Çakır
A32: 61b9feffa431e1ec64f46669 | B32: Adıyaman Çiğ Köftecisi Ali Usta, Odunpazarı (71 Evler Mah.) | C32: =VLOOKUP(A32,Import!A:C,3,false) -> DOĞRU | D32: Çiğ Köfte | E32: =VLOOKUP(A32,Import!A:J,5,0) -> 39 | F32: =VLOOKUP(A32,Import!A:J,6,0) -> 6 | G32: =VLOOKUP(A32,Import!A:J,7,0) -> 5 | H32: =VLOOKUP(A32,Import!A:J,8,0) -> 0 | I32: =VLOOKUP(A32,Import!A:J,9,0) -> 5 | J32: =VLOOKUP(A32,Import!A:J,10,0) -> 1 | K32: ALİ TURAN | L32: 5456606594 | M32: Odunpazarı | N32: 71 Evler 1. Bölge | O32: 71 Evler Mahallesi Kafkas Caddesi 69/D Odunpazarı Eskişehir | P32: =VLOOKUP(A32,Import!A:P,16,0) -> Geleneksel | R32: TRUE | S32: FALSE | T32: Randevu Alındı | U32: Zeliha Özer | X32: 44578 | Y32: 44580 | AA32: Görüşüldü | AB32: 44578 | AK32: Zeliha Özer
A33: 621a5d2926ef38ff0c67fe63 | B33: Adıyaman Çiğ Köftecisi İlyas Aybak, Odunpazarı (71 Evler Mah.) | C33: =VLOOKUP(A33,Import!A:C,3,false) -> DOĞRU | D33: Çiğ Köfte | E33: =VLOOKUP(A33,Import!A:J,5,0) -> 13 | F33: =VLOOKUP(A33,Import!A:J,6,0) -> 1 | G33: =VLOOKUP(A33,Import!A:J,7,0) -> 0 | H33: =VLOOKUP(A33,Import!A:J,8,0) -> 22 | I33: =VLOOKUP(A33,Import!A:J,9,0) -> 22 | J33: =VLOOKUP(A33,Import!A:J,10,0) -> 0 | K33: İlyas Silindir | L33: 5432761694 | M33: Odunpazarı | N33: Emek | O33: 71 Evler Mahallesi Tarih Bulvarı No:43/B Odunpazarı Eskişehir | P33: =VLOOKUP(A33,Import!A:P,16,0) -> Geleneksel | R33: TRUE | S33: FALSE | W33: 1 saat sonra | AA33: Tekrar Aranacak | AB33: 44628 | AK33: Sude Alkan
A34: 5fa5f00566a584ab34fdd59a | B34: Adıyaman Çiğ Köftecisi, Odunpazarı (Ihlamurkent Mah.) | C34: =VLOOKUP(A34,Import!A:C,3,false) -> DOĞRU | D34: Çiğ Köfte | E34: =VLOOKUP(A34,Import!A:J,5,0) -> 862 | F34: =VLOOKUP(A34,Import!A:J,6,0) -> 21 | G34: =VLOOKUP(A34,Import!A:J,7,0) -> 3 | H34: =VLOOKUP(A34,Import!A:J,8,0) -> 13 | I34: =VLOOKUP(A34,Import!A:J,9,0) -> 16 | J34: =VLOOKUP(A34,Import!A:J,10,0) -> 0.19 | K34: =VLOOKUP(A34,Import!A:P,11,0) -> SERHAT ANILIR | L34: 5412208287 | M34: Odunpazarı | N34: Ihlamurkent | O34: Ihlamurkent Mah. Nevruz cad. No:42/EB Odunpazarı/Eskişehir | P34: =VLOOKUP(A34,Import!A:P,16,0) -> Geleneksel | Q34: 0-15 | R34: TRUE | S34: FALSE | T34: Randevu Alındı | V34: Emir | W34: TEYİT İÇİN ARANDI ÇEKİM GERÇEKLEŞMİŞ | X34: 44232 | Y34: 44236 | AP34: Gökhan Çakır
A35: 5f35ada4d64681eb3bfeb406 | B35: Adıyaman Çiğköftecisi İlyas Aybak, Odunpazarı (Emek Mah.) | C35: =VLOOKUP(A35,Import!A:C,3,false) -> DOĞRU | D35: Çiğ Köfte | E35: =VLOOKUP(A35,Import!A:J,5,0) -> 2628 | F35: =VLOOKUP(A35,Import!A:J,6,0) -> 50 | G35: =VLOOKUP(A35,Import!A:J,7,0) -> 17 | H35: =VLOOKUP(A35,Import!A:J,8,0) -> 10 | I35: =VLOOKUP(A35,Import!A:J,9,0) -> 27 | J35: =VLOOKUP(A35,Import!A:J,10,0) -> 0.63 | K35: =VLOOKUP(A35,Import!A:P,11,0) -> HAKAN ADALIOĞLU | L35: 5438920626 | M35: Odunpazarı | N35: Emek | O35: Emek, Ertaş Blv. No:111, 26080 Odunpazarı/Eskişehir | P35: =VLOOKUP(A35,Import!A:P,16,0) -> Geleneksel | Q35: 16-25 | R35: TRUE | S35: FALSE | T35: Randevu Alındı | V35: Melika | W35: TEYİT İÇİN ARANDI ÇEKİM GERÇEKLEŞMİŞ | X35: 44232 | Y35: 44236 | AP35: Gökhan Çakır
A36: 60bd1a2cdfedba45a30f33ff | B36: Adıyamanlı Abuzeroğulları, Tepebaşı ( Batıkent Mah.) | C36: =VLOOKUP(A36,Import!A:C,3,false) -> DOĞRU | D36: Kebap | E36: =VLOOKUP(A36,Import!A:J,5,0) -> 542 | F36: =VLOOKUP(A36,Import!A:J,6,0) -> 27 | G36: =VLOOKUP(A36,Import!A:J,7,0) -> 0 | H36: =VLOOKUP(A36,Import!A:J,8,0) -> 16 | I36: =VLOOKUP(A36,Import!A:J,9,0) -> 16 | J36: =VLOOKUP(A36,Import!A:J,10,0) -> 0 | K36: =VLOOKUP(A36,Import!A:P,11,0) -> Muhammed Enes İleli | L36: 5379480226 | M36: Tepebaşı | N36: Batıkent | O36: Batıkent Mah. Liman Cad. No:32 A Tepebaşı/ Eskişehir | P36: =VLOOKUP(A36,Import!A:P,16,0) -> Geleneksel | R36: TRUE | S36: FALSE | T36: Randevu İptal | U36: Selcan Topçu | V36: muammer | W36: 5554896073 | X36: 44565 | Y36: 44566 | AA36: Ulaşılamadı | AB36: 44518 | AC36: Ulaşılamadı | AD36: 44518 | AE36: Görüşüldü | AF36: 44565 | AK36: Kübra Toprak | AL36: Kübra Toprak | AM36: Selcan Topçu | AP36: Gökhan Çakır
A37: 61fc026c3f06a77aa56699d5 | B37: Adıyamanlı Baraka Çiğ Köftecisi, Odunpazarı (Büyükdere Mah.) | C37: =VLOOKUP(A37,Import!A:C,3,false) -> DOĞRU | D37: Çiğ Köfte | E37: =VLOOKUP(A37,Import!A:J,5,0) -> 333 | F37: =VLOOKUP(A37,Import!A:J,6,0) -> 137 | G37: =VLOOKUP(A37,Import!A:J,7,0) -> 0 | H37: =VLOOKUP(A37,Import!A:J,8,0) -> 23 | I37: =VLOOKUP(A37,Import!A:J,9,0) -> 23 | J37: =VLOOKUP(A37,Import!A:J,10,0) -> 0 | K37: Uğurcan Aydoğdu | L37: 5346520726 | M37: Odunpazarı | N37: Büyükdere | O37: BÜYÜKDERE MAH. KAPLANLI CAD. NO: 77 A ODUNPAZARI/ ESKİŞEHİR | P37: =VLOOKUP(A37,Import!A:P,16,0) -> Geleneksel | R37: TRUE | S37: FALSE | T37: Restoran Silindi | AA37: Dönüş Yapacak | AB37: 44599 | AC37: Görüşüldü | AD37: 44628 | AK37: Hatem Soyaslan | AL37: Betül Demir
A38: 61b9fc5f10687ded227e2054 | B38: Adıyamanlı Çiğ Köfte & Tatlı, Odunpazarı (Büyükdere Mah.) | C38: =VLOOKUP(A38,Import!A:C,3,false) -> DOĞRU | D38: Çiğ Köfte | E38: =VLOOKUP(A38,Import!A:J,5,0) -> 137 | F38: =VLOOKUP(A38,Import!A:J,6,0) -> 22 | G38: =VLOOKUP(A38,Import!A:J,7,0) -> 3 | H38: =VLOOKUP(A38,Import!A:J,8,0) -> 0 | I38: =VLOOKUP(A38,Import!A:J,9,0) -> 3 | J38: =VLOOKUP(A38,Import!A:J,10,0) -> 1 | K38: ALİ TURAN | L38: 5456606594 | M38: Odunpazarı | N38: Büyükdere | O38: Büyükdere, Fakülte Sok. 5/C, Odunpazarı/Eskişehir | P38: =VLOOKUP(A38,Import!A:P,16,0) -> Geleneksel | R38: TRUE | S38: FALSE | T38: Randevu Alındı | U38: Selcan Topçu | V38: muammer | W38: dalgıc sokak | X38: 44561 | Y38: 44565 | AA38: Görüşüldü | AB38: 44561 | AK38: Selcan Topçu
A39: 601397ff998c1343f7870497 | B39: Adıyamanlı Çiğ Köfteci Abuzeroğulları, Tepebaşı (Şirintepe Mah.) | C39: =VLOOKUP(A39,Import!A:C,3,false) -> DOĞRU | D39: Çiğ Köfte | E39: =VLOOKUP(A39,Import!A:J,5,0) -> 976 | F39: =VLOOKUP(A39,Import!A:J,6,0) -> 4 | G39: =VLOOKUP(A39,Import!A:J,7,0) -> 6 | H39: =VLOOKUP(A39,Import!A:J,8,0) -> 10 | I39: =VLOOKUP(A39,Import!A:J,9,0) -> 16 | J39: =VLOOKUP(A39,Import!A:J,10,0) -> 0.38 | K39: =VLOOKUP(A39,Import!A:P,11,0) -> Murat kaya | L39: 5330373024 | M39: Tepebaşı | N39: Şirintepe | O39: Yaylapınar caddesi no 7 c Tepebaşı Eskişehir | P39: =VLOOKUP(A39,Import!A:P,16,0) -> Geleneksel | Q39: 0-15 | R39: TRUE | S39: FALSE | T39: Başka Şubeden Çekilecek | W39: başka aramada | AP39: Gökhan Çakır
A40: 60e04fc52a992115ac79a314 | B40: Adıyamanlı Çiğ Köfteci Abuzeroğulları, Tepebaşı (Yeşiltepe Mah.) | C40: =VLOOKUP(A40,Import!A:C,3,false) -> DOĞRU | D40: Çiğ Köfte | E40: =VLOOKUP(A40,Import!A:J,5,0) -> 1711 | F40: =VLOOKUP(A40,Import!A:J,6,0) -> 69 | G40: =VLOOKUP(A40,Import!A:J,7,0) -> 0 | H40: =VLOOKUP(A40,Import!A:J,8,0) -> 15 | I40: =VLOOKUP(A40,Import!A:J,9,0) -> 15 | J40: =VLOOKUP(A40,Import!A:J,10,0) -> 0 | K40: =VLOOKUP(A40,Import!A:P,11,0) -> Ömer Küçük | L40: 5447844222 | M40: Tepebaşı | N40: Yeşiltepe | O40: Yeşiltepe Mah. Bilgeç Cad. No:36C Tepebaşı/Eskişehir | P40: =VLOOKUP(A40,Import!A:P,16,0) -> Geleneksel | R40: TRUE | S40: FALSE | T40: Randevu İptal | U40: Betül Demir | V40: Muammer Çakır | X40: 44522 | Y40: 44524 | AA40: Görüşüldü | AB40: 44522 | AK40: Betül Demir | AP40: Gökhan Çakır
...

Sheet özet
B2: Başka Şubeden Çekilecek | C2: =COUNTIFS('Hedef Liste'!T:T,B2,'Hedef Liste'!C:C,"doğru",'Hedef Liste'!P:P,"Geleneksel",'Hedef Liste'!J:J,"=0%") -> 5 | D2: Toplam Rest | E2: =COUNTIFS(Import!C:C,"doğru",Import!P:P,"Geleneksel") -> 725
B3: BlackList | C3: =COUNTIFS('Hedef Liste'!T:T,B3,'Hedef Liste'!C:C,"doğru",'Hedef Liste'!P:P,"Geleneksel",'Hedef Liste'!J:J,"=0%") -> 8 | D3: Fotoğraflı | E3: =COUNTIFS(Import!C:C,"doğru",Import!P:P,"Geleneksel",Import!J:J,">0%") -> 407
B4: Çekim İstemiyor | C4: =COUNTIFS('Hedef Liste'!T:T,B4,'Hedef Liste'!C:C,"doğru",'Hedef Liste'!P:P,"Geleneksel",'Hedef Liste'!J:J,"=0%") -> 76 | D4: % | E4: =E3/E2 -> 0.56137931 | J4: Top. Rest | K4: =COUNTIFS(Import!$C:$C,"true",Import!$P:$P,"Geleneksel") -> 0 | S4: İptal Oranı
B5: Devir | C5: =COUNTIFS('Hedef Liste'!T:T,B5,'Hedef Liste'!C:C,"doğru",'Hedef Liste'!P:P,"Geleneksel",'Hedef Liste'!J:J,"=0%") -> 2 | J5: Fotoğraflı | K5: =COUNTIFS(Import!$C:$C,"true",Import!$P:$P,"Geleneksel",Import!$J:$J,">0%") -> 0 | M5: =$K$5/$K$4 -> #DIV/0! | S5: =O24/N24 -> #DIV/0!
B6: Dönüş Yapacak | C6: =COUNTIFS('Hedef Liste'!T:T,B6,'Hedef Liste'!C:C,"doğru",'Hedef Liste'!P:P,"Geleneksel",'Hedef Liste'!J:J,"=0%") -> 11
B7: Franchise | C7: =COUNTIFS('Hedef Liste'!T:T,B7,'Hedef Liste'!C:C,"doğru",'Hedef Liste'!P:P,"Geleneksel",'Hedef Liste'!J:J,"=0%") -> 2 | J7: Ürün Adet | K7: 0-25 | M7: 25+
B8: İleride Randevu Alınacak | C8: =COUNTIFS('Hedef Liste'!T:T,B8,'Hedef Liste'!C:C,"doğru",'Hedef Liste'!P:P,"Geleneksel",'Hedef Liste'!J:J,"=0%") -> 33 | J8: Fotoğraflı | K8: =COUNTIFS(Import!$C:$C,"true",Import!$J:$J,">0%",Import!$P:$P,"Geleneksel",Import!$I:$I,"<=25") -> 0 | L8: =K8/K5 -> #DIV/0! | M8: =COUNTIFS(Import!C:C,"true",Import!J:J,">0%",Import!P:P,"Geleneksel",Import!I:I,">25") -> 0 | N8: =M8/K5 -> #DIV/0!
B9: Lokasyon Uzak | C9: =COUNTIFS('Hedef Liste'!T:T,B9,'Hedef Liste'!C:C,"doğru",'Hedef Liste'!P:P,"Geleneksel",'Hedef Liste'!J:J,"=0%") -> 0 | J9: 0-20% | K9: =COUNTIFS(Import!C:C,"true",Import!J:J,">0%",Import!J:J,"<=20%",Import!P:P,"Geleneksel",Import!I:I,"<=25") -> 0 | L9: =K9/K8 -> #DIV/0! | M9: =COUNTIFS(Import!C:C,"true",Import!J:J,">0%",Import!J:J,"<=20%",Import!P:P,"Geleneksel",Import!I:I,">25") -> 0 | N9: =M9/M8 -> #DIV/0!
B10: Haziran'da Aranacak | C10: =COUNTIFS('Hedef Liste'!T:T,B10,'Hedef Liste'!C:C,"doğru",'Hedef Liste'!P:P,"Geleneksel",'Hedef Liste'!J:J,"=0%") -> 0 | J10: 21-50% | K10: =COUNTIFS(Import!C:C,"true",Import!J:J,">20%",Import!J:J,"<=50%",Import!P:P,"Geleneksel",Import!I:I,"<=25") -> 0 | L10: =K10/K8 -> #DIV/0! | M10: =COUNTIFS(Import!C:C,"true",Import!J:J,">20%",Import!J:J,"<=50%",Import!P:P,"Geleneksel",Import!I:I,">25") -> 0 | N10: =M10/M8 -> #DIV/0!
B11: Menü Güncellemesi Yapılacak | C11: =COUNTIFS('Hedef Liste'!T:T,B11,'Hedef Liste'!C:C,"doğru",'Hedef Liste'!P:P,"Geleneksel",'Hedef Liste'!J:J,"=0%") -> 1 | J11: 51-80% | K11: =COUNTIFS(Import!C:C,"true",Import!J:J,">50%",Import!J:J,"<=80%",Import!P:P,"Geleneksel",Import!I:I,"<=25") -> 0 | L11: =K11/K8 -> #DIV/0! | M11: =COUNTIFS(Import!C:C,"true",Import!J:J,">50%",Import!J:J,"<=80%",Import!P:P,"Geleneksel",Import!I:I,">25") -> 0 | N11: =M11/M8 -> #DIV/0!
B12: Personel Eksik | C12: =COUNTIFS('Hedef Liste'!T:T,B12,'Hedef Liste'!C:C,"doğru",'Hedef Liste'!P:P,"Geleneksel",'Hedef Liste'!J:J,"=0%") -> 2 | J12: >80% | K12: =COUNTIFS(Import!C:C,"true",Import!J:J,">80%",Import!P:P,"Geleneksel",Import!I:I,"<=25") -> 0 | L12: =K12/K8 -> #DIV/0! | M12: =COUNTIFS(Import!C:C,"true",Import!J:J,">80%",Import!P:P,"Geleneksel",Import!I:I,">25") -> 0 | N12: =M12/M8 -> #DIV/0!
B13: Randevu Alındı | C13: =COUNTIFS('Hedef Liste'!T:T,B13,'Hedef Liste'!C:C,"doğru",'Hedef Liste'!P:P,"Geleneksel",'Hedef Liste'!J:J,"=0%") -> 13
B14: Randevu İptal | C14: =COUNTIFS('Hedef Liste'!T:T,B14,'Hedef Liste'!C:C,"doğru",'Hedef Liste'!P:P,"Geleneksel",'Hedef Liste'!J:J,"=0%") -> 14
B15: Restoran Silindi | C15: =COUNTIFS('Hedef Liste'!T:T,B15,'Hedef Liste'!C:C,"doğru",'Hedef Liste'!P:P,"Geleneksel",'Hedef Liste'!J:J,"=0%") -> 1
B16: Sistemden Çıkmak İstiyor | C16: =COUNTIFS('Hedef Liste'!T:T,B16,'Hedef Liste'!C:C,"doğru",'Hedef Liste'!P:P,"Geleneksel",'Hedef Liste'!J:J,"=0%") -> 4
B17: Tadilat Var | C17: =COUNTIFS('Hedef Liste'!T:T,B17,'Hedef Liste'!C:C,"doğru",'Hedef Liste'!P:P,"Geleneksel",'Hedef Liste'!J:J,"=0%") -> 3
B18: Ulaşılamadı | C18: =COUNTIFS('Hedef Liste'!T:T,B18,'Hedef Liste'!C:C,"doğru",'Hedef Liste'!P:P,"Geleneksel",'Hedef Liste'!J:J,"=0%") -> 22
B19: Ramazandan Sonra Randevu Istiyor | C19: =COUNTIFS('Hedef Liste'!T:T,B19,'Hedef Liste'!C:C,"doğru",'Hedef Liste'!P:P,"Geleneksel",'Hedef Liste'!J:J,"=0%") -> 1
B20: Fotoğrafı Var | C20: =COUNTIFS('Hedef Liste'!S:S,"True",'Hedef Liste'!C:C,"doğru",'Hedef Liste'!P:P,"Geleneksel",'Hedef Liste'!J:J,"=0%",'Hedef Liste'!T:T,"") -> 47
B21: TOPLAM | C21: =SUM(C2:C20) -> 245 | D21: =COUNTIFS('Hedef Liste'!C:C,"true",'Hedef Liste'!P:P,"Geleneksel") -> 0
B23: Randevu Başarı %
B24: =C13/COUNTIFS('Hedef Liste'!R:R,"true",'Hedef Liste'!C:C,"true") -> #DIV/0!

Sheet Import
A1: Restaurant ID | B1: Restoran Adı | C1: Satışa Açık Mı? | D1: Mutfak | E1: TOPLAM SİPARİŞ | F1: SON 2 HAFTA | G1: RESİMLİ ÜRÜN | H1: RESİMSİZ ÜRÜN | I1: TOPLAM ÜRÜN | J1: Ratio | K1: Yetkili | L1: Telefon | M1: İLÇE | N1: MAHALLE | O1: ADRES | P1: Geleneksel Zincir | Q1: Eklendi mi
A2: 5f2c34fd5b6dd080ba3cd27f | B2: Rooster, Tepebaşı (Şirintepe Mah.) | C2: DOĞRU | D2: Döner | E2: 27514 | F2: 1411 | G2: 29 | H2: 1 | I2: 30 | J2: 0.97 | K2: TOLGA KUMRU | L2: 2223353516 | M2: Tepebaşı | N2: Şirintepe | O2: Şirintepe, İsmet İnönü-2 Blv No:58, 26200, 26190 Tepebaşı/Eskişehir | P2: Geleneksel | Q2: =COUNTIF('Hedef Liste'!$A:$A,A2) -> 1
A3: 5f2c35f4276682de259234a3 | B3: Obur Fast Food (Büyükdere Mah.) | C3: DOĞRU | D3: Tost & Sandviç | E3: 17017 | F3: 294 | G3: 47 | H3: 22 | I3: 69 | J3: 0.68 | K3: AHMET ÜSTÜN | L3: 2222390101 | M3: Odunpazarı | N3: Büyükdere | O3: Büyükdere Mah. Mehmet Osman Cad. Sarıkonak Sok, D:NO:6A, 26040 Odunpazarı | P3: Geleneksel | Q3: =COUNTIF('Hedef Liste'!$A:$A,A3) -> 1
A4: 5f2c1572d783356b484989ce | B4: Koza Kebap, Tepebaşı (Hoşnudiye Mah.) | C4: DOĞRU | D4: Kebap | E4: 14468 | F4: 300 | G4: 12 | H4: 60 | I4: 72 | J4: 0.17 | K4: SEZER DEMİR | L4: 5525007171 | M4: Tepebaşı | N4: Hoşnudiye | O4: Hoşnudiye, Ay Lounge Altı, Şahin Cd. No:76/C, 26130 Tepebaşı/Eskişehir | P4: Geleneksel | Q4: =COUNTIF('Hedef Liste'!$A:$A,A4) -> 1
A5: 5f2c1cd6b76a830b5f50b5dd | B5: Çarşı Fırın & Çibörek, Odunpazarı (Arifiye Mah.) | C5: DOĞRU | D5: Börek | E5: 3373 | F5: 165 | G5: 0 | H5: 90 | I5: 90 | J5: 0 | K5: BEKLAN GENCER | L5: 5419782817 | M5: Odunpazarı | N5: İstiklal | O5: Arifiye, Korkmaz Sk. No:7, 26010 Odunpazarı/Eskişehir | P5: Geleneksel | Q5: =COUNTIF('Hedef Liste'!$A:$A,A5) -> 1
A6: 5f2c33a38e6cb27e3714c9c8 | B6: Wopsow Burger, Tepebaşı (Güllük Mah.) | C6: DOĞRU | D6: Burger | E6: 13282 | F6: 189 | G6: 18 | H6: 3 | I6: 21 | J6: 0.86 | K6: TURHAN GÜVENÇ SAYAN | L6: 5457762677 | M6: Tepebaşı | N6: Eskibağlar | O6: Güllük, Bacı Sk. No:10, 26190 Tepebaşı/Eskişehir | P6: Geleneksel | Q6: =COUNTIF('Hedef Liste'!$A:$A,A6) -> 1
A7: 5f2c37946dc562e66bda26c4 | B7: Gaziantepli Ünvermiş Baklavacı (Vişnelik Mah.) | C7: DOĞRU | D7: Pasta & Tatlı | E7: 9675 | F7: 289 | G7: 14 | H7: 19 | I7: 33 | J7: 0.42 | K7: AHMET TOPRAK | L7: 2222262424 | M7: Odunpazarı | N7: Akarbaşı | O7: VİŞNELİK MAHALLESİ ATATÜRK BULVARI NO:106/C ODUNPAZARI ESKİŞEHİR | P7: Geleneksel | Q7: =COUNTIF('Hedef Liste'!$A:$A,A7) -> 1
A8: 5f3282e2b6572ccaf7730568 | B8: Cennet Simit, Odunpazarı (İstiklal Mah.) | C8: DOĞRU | D8: Börek | E8: 4499 | F8: 248 | G8: 0 | H8: 66 | I8: 66 | J8: 0 | K8: Eren Göker | L8: 5356928409 | M8: Odunpazarı | N8: İstiklal | O8: İstiklal Mah., Başarılı Sok., No:10, Odunpazarı, Eskişehir, Türkiye, | P8: Geleneksel | Q8: =COUNTIF('Hedef Liste'!$A:$A,A8) -> 1
A9: 5f328b0b6198064323f8df49 | B9: Hega Pizza & Burger, Tepebaşı (Cumhuriye Mah.) | C9: DOĞRU | D9: Burger | E9: 24275 | F9: 451 | G9: 40 | H9: 10 | I9: 50 | J9: 0.8 | K9: KADRİYE ÇELİKOĞLU | L9: 2222214943 | M9: Tepebaşı | N9: Hoşnudiye | O9: CUMHURİYE MAHALLESİ İŞ BULMA SOKAK NO:33/B. 26130 TEPEBAŞI/Eskişehir | P9: Geleneksel | Q9: =COUNTIF('Hedef Liste'!$A:$A,A9) -> 1
A10: 5f328bf1777d7352944147d4 | B10: Es Alsancak Kumrucusu (Cumhuriye Mah.) | C10: DOĞRU | D10: Sokak Lezzetleri | E10: 2332 | F10: 44 | G10: 26 | H10: 37 | I10: 63 | J10: 0.41 | K10: Murat Erken | L10: 5367656805 | M10: Tepebaşı | N10: Cumhuriye | O10: Cumhuriyet Mah. Tersel Sok. No:6/C D:2 Tepebaşı/ Eskişehir | P10: Geleneksel | Q10: =COUNTIF('Hedef Liste'!$A:$A,A10) -> 1
A11: 5f3291b8e99eb6bacf1bf529 | B11: Gaziantep Cennet Pide & Lahmacun (Vişnelik Mah.) | C11: DOĞRU | D11: Pide | E11: 10026 | F11: 236 | G11: 0 | H11: 45 | I11: 45 | J11: 0 | K11: MEHMET YALPI | L11: 2222268451 | M11: Odunpazarı | N11: Vişnelik | O11: Akarbaşı, Yörüksoy Sk. No:1 D:c, 26020 Odunpazarı/Eskişehir | P11: Geleneksel | Q11: =COUNTIF('Hedef Liste'!$A:$A,A11) -> 1
A12: 5f3297199396285da8b681bf | B12: Gaziantepli Duygu Pide & Kebap (Kurtuluş Mah.) | C12: DOĞRU | D12: Pide | E12: 1696 | F12: 47 | G12: 10 | H12: 7 | I12: 17 | J12: 0.59 | K12: YAKUP TUNÇKAYA | L12: 2222344831 | M12: Odunpazarı | N12: Kurtuluş | O12: Alanönü Mah., Maide Bolel Huzur Evi Cd. No:7 B, Odunpazarı/Eskişehir | P12: Geleneksel | Q12: =COUNTIF('Hedef Liste'!$A:$A,A12) -> 1
A13: 5f33774d355b6a22fd38dbae | B13: Es Kumru Sandviç & Döner, Tepebaşı (Hoşnudiye Mah.) | C13: DOĞRU | D13: Tost & Sandviç | E13: 2196 | F13: 29 | G13: 19 | H13: 58 | I13: 77 | J13: 0.25 | K13: HÜLYA DEMİR | L13: 5423554445 | M13: Tepebaşı | N13: Hoşnudiye | O13: Hoşnudiye Mah., Bayrak Sok., No:10A, Tepebaşı, Eskişehir, Türkiye, | P13: Geleneksel | Q13: =COUNTIF('Hedef Liste'!$A:$A,A13) -> 1
... A31: 5f315a4cf7b4aa7cb0cc56b9 | B31: Kar-pi Karadeniz Pidesi (Uluönder Mah.) | C31: DOĞRU | D31: Pide | E31: 942 | F31: 31 | G31: 5 | H31: 54 | I31: 59 | J31: 0.08 | K31: KORAY İSMAİL AKYÜZ | L31: 5616117277 | M31: Tepebaşı | N31: Uluönder | O31: Uluönder, Salih Bozok Cd. No:7, 26190 Tepebaşı/Eskişehir | P31: Geleneksel | Q31: =COUNTIF('Hedef Liste'!$A:$A,A31) -> 1
A32: 5f315e877004a385a9ce063e | B32: Şahin Pide & Kebap (Tunalı Mah.) | C32: YANLIŞ | D32: Pide | E32: 151 | G32: 0 | H32: 31 | I32: 31 | J32: 0 | K32: BİLAL OKAN | L32: 123456789 | M32: Tepebaşı | N32: Tunalı | O32: Tunalı, Sakarya-2 Cd. no:64/A, 26220 Tepebaşı/Eskişehir | P32: Geleneksel | Q32: =COUNTIF('Hedef Liste'!$A:$A,A32) -> 1
A33: 5f3291a698ff3841ac33a587 | B33: Thyme Tantuni (Yenibağlar Mah.) | C33: DOĞRU | D33: Sokak Lezzetleri | E33: 8699 | F33: 94 | G33: 8 | H33: 28 | I33: 36 | J33: 0.22 | K33: ÖZLEM ŞİDE | L33: 2223220045 | M33: Tepebaşı | N33: Yenibağlar | O33: yenibağlar mh. balkan cad. no : 90 /b | P33: Geleneksel | Q33: =COUNTIF('Hedef Liste'!$A:$A,A33) -> 1
A34: 5f3378fd30bf6361f32c87ca | B34: Adana Böreği Yunus Usta, Tepebaşı (Hoşnudiye Mah.) | C34: DOĞRU | D34: Börek | E34: 2378 | F34: 45 | G34: 19 | H34: 15 | I34: 34 | J34: 0.56 | K34: MERVE TINMAZ | L34: 5524240424 | M34: Tepebaşı | N34: Hoşnudiye | O34: Hoşnudiye, İstasyon Cd. No:41, 26130 Tepebaşı/Eskişehir | P34: Geleneksel | Q34: =COUNTIF('Hedef Liste'!$A:$A,A34) -> 1
A35: 5f338c53abcd6abfb3e15752 | B35: Nostalji Gözleme Evi (Büyükdere Mah.) | C35: DOĞRU | D35: Kahvaltı | E35: 6261 | F35: 340 | G35: 20 | H35: 15 | I35: 35 | J35: 0.57 | K35: Soner AKAGÜNDÜZ | L35: 2222398483 | M35: Odunpazarı | N35: Büyükdere | O35: Büyükdere, Millet Cd. No:12 D:F, 26040 Eskişehir Merkez/Eskişehir | P35: Geleneksel | Q35: =COUNTIF('Hedef Liste'!$A:$A,A35) -> 1
A36: 5f33c87cfb453fd4e85c4aa9 | B36: Ciğerci Sedat (Kurtuluş Mah.) | C36: DOĞRU | D36: Kebap | E36: 4859 | F36: 46 | G36: 9 | H36: 14 | I36: 23 | J36: 0.39 | K36: SEDAT YAKAN | L36: 2222209998 | M36: Odunpazarı | N36: Kurtuluş | O36: Deliklitaş, Yunus Emre Cd. No:93 D:B Odunpazarı/Eskişehir | P36: Geleneksel | Q36: =COUNTIF('Hedef Liste'!$A:$A,A36) -> 1
A37: 5f344c5d03a8183877925533 | B37: İçem Kokoreç, Odunpazarı (Sütlüce Mah.) | C37: DOĞRU | D37: Köfte | E37: 1768 | F37: 59 | G37: 0 | H37: 46 | I37: 46 | J37: 0 | K37: ALİ KOCADAĞ | L37: 2222330708 | M37: Tepebaşı | N37: Anadolu Üniversitesi | O37: Sütlüce, İstiklal Cd. 38/A, 26010 Odunpazarı/Eskişehir | P37: Geleneksel | Q37: =COUNTIF('Hedef Liste'!$A:$A,A37) -> 1
A38: 5f3552e602e0084bf18fd59b | B38: Three Monkeys Burger House (Vişnelik Mah.) | C38: DOĞRU | D38: Burger | E38: 8734 | F38: 264 | G38: 16 | H38: 38 | I38: 54 | J38: 0.3 | K38: Baturhan Şentürk | L38: 5537390250 | M38: Odunpazarı | N38: Vişnelik | O38: Vişnelik, Atatürk Blv. No:112, 26020 Odunpazarı/Eskişehir | P38: Geleneksel | Q38: =COUNTIF('Hedef Liste'!$A:$A,A38) -> 1
A39: 5f35ada4d64681eb3bfeb406 | B39: Adıyaman Çiğköftecisi İlyas Aybak, Odunpazarı (Emek Mah.) | C39: DOĞRU | D39: Çiğ Köfte | E39: 2628 | F39: 50 | G39: 17 | H39: 10 | I39: 27 | J39: 0.63 | K39: HAKAN ADALIOĞLU | L39: 5438920626 | M39: Odunpazarı | N39: Emek | O39: Emek, Ertaş Blv. No:111, 26080 Odunpazarı/Eskişehir | P39: Geleneksel | Q39: =COUNTIF('Hedef Liste'!$A:$A,A39) -> 1
A40: 5f3335c503a8180e1d92403b | B40: Köfteci Ali (Hoşnudiye Mah.) | C40: DOĞRU | D40: Köfte | E40: 1655 | F40: 63 | G40: 5 | H40: 1 | I40: 6 | J40: 0.83 | K40: AYŞE KELEBEK | L40: 2222335101 | M40: Tepebaşı | N40: Hoşnudiye | O40: Hoşnudiye Mah., İstasyon Cad., No:45A, Tepebaşı, Eskişehir | P40: Geleneksel | Q40: =COUNTIF('Hedef Liste'!$A:$A,A40) -> 1
A41: 5f33ea8803a8183586924e8d | B41: For You Fast Food & Toast (Büyükdere Mah.) | C41: DOĞRU | D41: Tost & Sandviç | E41: 12149 | F41: 412 | G41: 22 | H41: 66 | I41: 88 | J41: 0.25 | K41: ŞERİFE BURCU ÖZEGE | L41: 5526323288 | M41: Odunpazarı | N41: Büyükdere | O41: BÜYÜKDERE MAH. NİSAN SK. NO: 29 D ODUNPAZARI/ ESKİŞEHİR | P41: Geleneksel | Q41: =COUNTIF('Hedef Liste'!$A:$A,A41) -> 1
A42: 5f33e1dfbc33c9640badde7f | B42: Samet Döner (Kurtuluş Mah.) | C42: DOĞRU | D42: Döner | E42: 1159 | F42: 39 | G42: 13 | H42: 8 | I42: 21 | J42: 0.62 | K42: Ebru Atak | L42: 2222203501 | M42: Odunpazarı | N42: Kurtuluş | O42: Ziya Paşa Caddesi, 18 Kurtuluş, Odunpazarı, Eskişehir | P42: Geleneksel | Q42: =COUNTIF('Hedef Liste'!$A:$A,A42) -> 1
A43: 5f314fb814446dab23298b90 | B43: Sultan Ateşi Pide & Kebap & Tantuni (Yenibağlar Mah.) | C43: DOĞRU | D43: Pide | E43: 5870 | F43: 187 | G43: 6 | H43: 29 | I43: 35 | J43: 0.17 | K43: ALİ ÇUBUK | L43: 2223211140 | M43: Tepebaşı | N43: Yenibağlar | O43: Yenibağlar, Seylap Cd. No:5, 26170 Tepebaşı/Eskişehir | P43: Geleneksel | Q43: =COUNTIF('Hedef Liste'!$A:$A,A43) -> 1
A44: 5f3152cfd0c302043a3fce6d | B44: Abone Meşhur Tostçu (Yenibağlar Mah.) | C44: DOĞRU | D44: Tost & Sandviç | E44: 5915 | F44: 187 | G44: 0 | H44: 193 | I44: 193 | J44: 0 | K44: ALİ KARGA | L44: 2223227770 | M44: Tepebaşı | N44: Yenibağlar | O44: Yenibağlar, No:, Martı Sk. No:17, 26170 Tepebaşı/Eskişehir | P44: Geleneksel | Q44: =COUNTIF('Hedef Liste'!$A:$A,A44) -> 1
... A52: 5f33bd366b1e0fe8d5f39deb | B52: Kansas Burger, Tepebaşı (Eskibağlar Mah.) | C52: DOĞRU | D52: Burger | E52: 35629 | F52: 1091 | G52: 11 | H52: 30 | I52: 41 | J52: 0.27 | K52: SERKAN ALTAY | L52: 5314508303 | M52: Tepebaşı | N52: Eskibağlar | O52: Eskibağlar, Sakman Sk., 26170 Tepebaşı/Eskişehir | P52: Geleneksel | Q52: =COUNTIF('Hedef Liste'!$A:$A,A52) -> 1
A53: 5f33c28b30bf6356322c8f3a | B53: Gar Pide & Kebap, Tepebaşı (Hoşnudiye Mah.) | C53: YANLIŞ | D53: Kebap | E53: 1005 | G53: 8 | H53: 36 | I53: 44 | J53: 0.18 | K53: Cafer Er | L53: 2222205282 | M53: Tepebaşı | N53: Hoşnudiye | O53: Hoşnudiye, Mustafa Kemal Atatürk Cd 170/A, 26170 Tepebaşı/Eskişehir | P53: Geleneksel | Q53: =COUNTIF('Hedef Liste'!$A:$A,A53) -> 1
A54: 5f353146da66dc55f2d6ea1e | B54: Çiftlik Kokoreç, Odunpazarı (Vişnelik Mah.) | C54: DOĞRU | D54: Sokak Lezzetleri | E54: 2100 | F54: 38 | G54: 0 | H54: 15 | I54: 15 | J54: 0 | K54: SEVİL İNLER | L54: 2222200440 | M54: Odunpazarı | N54: Vişnelik | O54: Vişnelik Mh, Atatürk Blv. No: 112/B, 26020 Odunpazarı/Eskişehir | P54: Geleneksel | Q54: =COUNTIF('Hedef Liste'!$A:$A,A54) -> 1
A55: 5f35521864610e0ca0604d20 | B55: Adıyamanlı Çiğ Köfteci, Odunpazarı (Vişnelik Mah.) | C55: DOĞRU | D55: Sokak Lezzetleri | E55: 2905 | F55: 32 | G55: 8 | H55: 18 | I55: 26 | J55: 0.31 | K55: YAŞAR KİRAZ | L55: 5397248350 | M55: Odunpazarı | N55: Vişnelik | O55: Vişnelik, Öğretmenler Blv no:13/E, 26020 Odunpazarı/Eskişehir | P55: Geleneksel | Q55: =COUNTIF('Hedef Liste'!$A:$A,A55) -> 1
A56: 5f36335364610e46fe605a7e | B56: McDonald's, Yenibağlar | C56: DOĞRU | D56: Burger | E56: 16327 | F56: 502 | G56: 98 | H56: 0 | I56: 98 | J56: 1 | K56: Ömer Tarık Güney | L56: 2123363575 | M56: Tepebaşı | N56: Yenibağlar | O56: Yenibağlar Mh. Üniversite CD. No:112 / A Eskişehir | P56: Key | Q56: =COUNTIF('Hedef Liste'!$A:$A,A56) -> 0
A57: 5f3671600274b83d2c5ca2f9 | B57: Aba Fast Food & Kahvaltı, Odunpazarı (Kırmızıtoprak Mah.) | C57: DOĞRU | D57: Tost & Sandviç | E57: 1560 | F57: 20 | G57: 0 | H57: 55 | I57: 55 | J57: 0 | K57: HOSSEIN DELAVANDANI | L57: 5377449269 | M57: Tepebaşı | N57: Hoşnudiye | O57: Kırmızıtoprak Mahallesi, Mustafa Kemal Atatürk Caddesi no: 95 / A | P57: Geleneksel | Q57: =COUNTIF('Hedef Liste'!$A:$A,A57) -> 1
A58: 5f333c361f35d342b156ce66 | B58: İçel Mersin Tantuni (Kurtuluş Mah.) | C58: DOĞRU | D58: Sokak Lezzetleri | E58: 1609 | F58: 25 | G58: 3 | H58: 8 | I58: 11 | J58: 0.27 | K58: SEDAT YAKAN | L58: 2222213915 | M58: Odunpazarı | N58: Kurtuluş | O58: Deliklitaş Mah. Yunusemre Cad. No:93/A Odunpazarı, Eskişehir | P58: Geleneksel | Q58: =COUNTIF('Hedef Liste'!$A:$A,A58) -> 1
A59: 5f63762d3c9a2c6ad4e7843e | B59: Fratello Pizzeria, Tepebaşı (Güllük Mah.) | C59: DOĞRU | D59: Pizza | E59: 18291 | F59: 269 | G59: 16 | H59: 18 | I59: 34 | J59: 0.47 | K59: AHMET MUSAB TÜRKYILMAZ | L59: 2222203030 | M59: Tepebaşı | N59: Güllük | O59: Güllük, Bacı Sk. No:48/A, 26000 Tepebaşı/Eskişehir | P59: Geleneksel | Q59: =COUNTIF('Hedef Liste'!$A:$A,A59) -> 1
A60: 5f6804d8fbf4612ffd1b6e89 | B60: Margarita Pizza, Tepebaşı (Cumhuriye Mah.) | C60: DOĞRU | D60: Pizza | E60: 18215 | F60: 589 | G60: 20 | H60: 47 | I60: 67 | J60: 0.3 | K60: SERCAN GÜNAY | L60: 5538902626 | M60: Tepebaşı | N60: Cumhuriye | O60: Hoşnudiye Mah., Otopark Sok., No:43, Tepebaşı, Eskişehir, Türkiye, | P60: Geleneksel | Q60: =COUNTIF('Hedef Liste'!$A:$A,A60) -> 1
A61: 5f67fcb56dbb880e3913665a | B61: Galata's Pizza (Yenibağlar Mah.) | C61: DOĞRU | D61: Pizza | E61: 5911 | F61: 149 | G61: 0 | H61: 80 | I61: 80 | J61: 0 | K61: ENGİN MEHMET AKIN | L61: 2223212788 | M61: Tepebaşı | N61: Yenibağlar | O61: Yenibağlar Mah. Akıcı sok. no : 45 /A Tepebaşı/Eskişehir | P61: Geleneksel | Q61: =COUNTIF('Hedef Liste'!$A:$A,A61) -> 1
A62: 5f67f995554732a9edd7b5d9 | B62: İnci Midye (Cumhuriye Mah.) | C62: DOĞRU | D62: Sokak Lezzetleri | E62: 514 | F62: 6 | G62: 12 | H62: 13 | I62: 25 | J62: 0.48 | K62: mehmet tüfenk | L62: 5337761568 | M62: Tepebaşı | N62: Ömerağa | O62: Cumhuriye mah. Zübeyde Hanım Cad. No: 26/A Tepebaşı/Eskişehir | P62: Geleneksel | Q62: =COUNTIF('Hedef Liste'!$A:$A,A62) -> 1
A63: 5f35b29dbe5a0b6c41bb2b98 | B63: Ailem Ev Yemekleri, Odunpazarı (İstiklal Mah.) | C63: DOĞRU | D63: Ev Yemekleri | E63: 6614 | F63: 518 | G63: 0 | H63: 40 | I63: 40 | J63: 0 | K63: Yıldız Çelik | L63: 5333752639 | M63: Odunpazarı | N63: İstiklal | O63: İstiklal, Başarılı Sk. NO:4A/1, 26010 Odunpazarı/Eskişehir | P63: Geleneksel | Q63: =COUNTIF('Hedef Liste'!$A:$A,A63) -> 1
