Workbook

Sheet Temmuz Özet
D8: Company Name
D9: Employee Schedule Jan 2017
D13: Shift Details
D15: Shift | E15: Duration | O15: Period | Y15: Hourly Wage | AI15: Employees per Shift
D16: A | E16: 8 hours | O16: 08:00 - 16:00 | Y16: 50 | AI16: 3
D17: B | E17: 8 hours | O17: 16:00 - 00:00 | Y17: 50 | AI17: 3
D18: C | E18: 8 hours | O18: 00:00 - 07:00 | Y18: 85 | AI18: 3
D21: Employee Wage Overview
D23: Employee's Name | E23: Shift | AI23: Monthly Wage
E24: A | O24: B | Y24: C
D25: Name | E25: W1 | G25: W2 | I25: W3 | K25: W4 | M25: W5 | O25: W1 | Q25: W2 | S25: W3 | U25: W4 | W25: W5 | Y25: W1 | AA25: W2 | AC25: W3 | AE25: W4 | AG25: W5
D26: Wendy Writer | E26: ='26.07'!L15+'26.07'!L27+'26.07'!L39+'26.07'!L50+'26.07'!L62+#REF!+#REF! -> #REF! | G26: ='Week 2 Shifts'!AC20+'Week 2 Shifts'!AC32+'Week 2 Shifts'!AC44+'Week 2 Shifts'!AC56+'Week 2 Shifts'!AC68+'Week 2 Shifts'!AC80+'Week 2 Shifts'!AC92 -> #REF! | I26: ='Week 3 Shifts'!AC20+'Week 3 Shifts'!AC32+'Week 3 Shifts'!AC56+'Week 3 Shifts'!AC68+'Week 3 Shifts'!AC80+'Week 3 Shifts'!AC92 -> #REF! | K26: ='Week 4 Shifts'!AC20+'Week 4 Shifts'!AC32+'Week 4 Shifts'!AC44+'Week 4 Shifts'!AC56+'Week 4 Shifts'!AC68+'Week 4 Shifts'!AC80+'Week 4 Shifts'!AC92 -> #REF! | M26: ='Week 5 Shifts'!AC20+'Week 5 Shifts'!AC32+'Week 5 Shifts'!AC44+'Week 5 Shifts'!AC56+'Week 5 Shifts'!AC68+'Week 5 Shifts'!AC80+'Week 5 Shifts'!AC92 -> #REF! | O26: =#REF!+#REF!+#REF!+#REF!+#REF!+#REF!+#REF! -> #REF! | Q26: ='Week 2 Shifts'!AE20+'Week 2 Shifts'!AE32+'Week 2 Shifts'!AE44+'Week 2 Shifts'!AE56+'Week 2 Shifts'!AE68+'Week 2 Shifts'!AE80+'Week 2 Shifts'!AE92 -> #REF! | S26: ='Week 3 Shifts'!AE20+'Week 3 Shifts'!AE32+'Week 3 Shifts'!AE44+'Week 3 Shifts'!AE56+'Week 3 Shifts'!AE68+'Week 3 Shifts'!AE80+'Week 3 Shifts'!AE92 -> #REF! | U26: ='Week 4 Shifts'!AE20+'Week 4 Shifts'!AE32+'Week 4 Shifts'!AE44+'Week 4 Shifts'!AE56+'Week 4 Shifts'!AE68+'Week 4 Shifts'!AE80+'Week 4 Shifts'!AE92 -> #REF! | W26: ='Week 5 Shifts'!AE20+'Week 5 Shifts'!AE32+'Week 5 Shifts'!AE44+'Week 5 Shifts'!AE56+'Week 5 Shifts'!AE68+'Week 5 Shifts'!AE80+'Week 5 Shifts'!AE92 -> #REF! | Y26: =#REF!+#REF!+#REF!+#REF!+#REF!+#REF!+#REF! -> #REF! | AA26: ='Week 2 Shifts'!AG20+'Week 2 Shifts'!AG32+'Week 2 Shifts'!AG44+'Week 2 Shifts'!AG56+'Week 2 Shifts'!AG68+'Week 2 Shifts'!AG80+'Week 2 Shifts'!AG92 -> #REF! | AC26: ='Week 3 Shifts'!AG20+'Week 3 Shifts'!AG32+'Week 3 Shifts'!AG44+'Week 3 Shifts'!AG56+'Week 3 Shifts'!AG68+'Week 3 Shifts'!AG80+'Week 3 Shifts'!AG92 -> #REF! | AE26: ='Week 4 Shifts'!AG20+'Week 4 Shifts'!AG32+'Week 4 Shifts'!AG44+'Week 4 Shifts'!AG56+'Week 4 Shifts'!AG68+'Week 4 Shifts'!AG80+'Week 4 Shifts'!AG92 -> #REF! | AG26: ='Week 5 Shifts'!AG20+'Week 5 Shifts'!AG32+'Week 5 Shifts'!AG44+'Week 5 Shifts'!AG56+'Week 5 Shifts'!AG68+'Week 5 Shifts'!AG80+'Week 5 Shifts'!AG92 -> #REF! | AI26: =SUM(E26:N26)*Y16+SUM(O26:X26)*Y17+SUM(Y26:AH26)*Y18 -> #REF!
D27: Ronny Reader | E27: ='26.07'!L16+'26.07'!L28+'26.07'!L40+'26.07'!L51+'26.07'!L63+#REF!+#REF! -> #REF! | G27: ='Week 2 Shifts'!AC21+'Week 2 Shifts'!AC33+'Week 2 Shifts'!AC45+'Week 2 Shifts'!AC57+'Week 2 Shifts'!AC69+'Week 2 Shifts'!AC81+'Week 2 Shifts'!AC93 -> #REF! | I27: ='Week 3 Shifts'!AC21+'Week 3 Shifts'!AC33+'Week 3 Shifts'!AC57+'Week 3 Shifts'!AC69+'Week 3 Shifts'!AC81+'Week 3 Shifts'!AC93 -> #REF! | K27: ='Week 4 Shifts'!AC21+'Week 4 Shifts'!AC33+'Week 4 Shifts'!AC45+'Week 4 Shifts'!AC57+'Week 4 Shifts'!AC69+'Week 4 Shifts'!AC81+'Week 4 Shifts'!AC93 -> #REF! | M27: ='Week 5 Shifts'!AC21+'Week 5 Shifts'!AC33+'Week 5 Shifts'!AC45+'Week 5 Shifts'!AC57+'Week 5 Shifts'!AC69+'Week 5 Shifts'!AC81+'Week 5 Shifts'!AC93 -> #REF! | O27: =#REF!+#REF!+#REF!+#REF!+#REF!+#REF!+#REF! -> #REF! | Q27: ='Week 2 Shifts'!AE21+'Week 2 Shifts'!AE33+'Week 2 Shifts'!AE45+'Week 2 Shifts'!AE57+'Week 2 Shifts'!AE69+'Week 2 Shifts'!AE81+'Week 2 Shifts'!AE93 -> #REF! | S27: ='Week 3 Shifts'!AE21+'Week 3 Shifts'!AE33+'Week 3 Shifts'!AE45+'Week 3 Shifts'!AE57+'Week 3 Shifts'!AE69+'Week 3 Shifts'!AE81+'Week 3 Shifts'!AE93 -> #REF! | U27: ='Week 4 Shifts'!AE21+'Week 4 Shifts'!AE33+'Week 4 Shifts'!AE45+'Week 4 Shifts'!AE57+'Week 4 Shifts'!AE69+'Week 4 Shifts'!AE81+'Week 4 Shifts'!AE93 -> #REF! | W27: ='Week 5 Shifts'!AE21+'Week 5 Shifts'!AE33+'Week 5 Shifts'!AE45+'Week 5 Shifts'!AE57+'Week 5 Shifts'!AE69+'Week 5 Shifts'!AE81+'Week 5 Shifts'!AE93 -> #REF! | Y27: =#REF!+#REF!+#REF!+#REF!+#REF!+#REF!+#REF! -> #REF! | AA27: ='Week 2 Shifts'!AG21+'Week 2 Shifts'!AG33+'Week 2 Shifts'!AG45+'Week 2 Shifts'!AG57+'Week 2 Shifts'!AG69+'Week 2 Shifts'!AG81+'Week 2 Shifts'!AG93 -> #REF! | AC27: ='Week 3 Shifts'!AG21+'Week 3 Shifts'!AG33+'Week 3 Shifts'!AG45+'Week 3 Shifts'!AG57+'Week 3 Shifts'!AG69+'Week 3 Shifts'!AG81+'Week 3 Shifts'!AG93 -> #REF! | AE27: ='Week 4 Shifts'!AG21+'Week 4 Shifts'!AG33+'Week 4 Shifts'!AG45+'Week 4 Shifts'!AG57+'Week 4 Shifts'!AG69+'Week 4 Shifts'!AG81+'Week 4 Shifts'!AG93 -> #REF! | AG27: ='Week 5 Shifts'!AG21+'Week 5 Shifts'!AG33+'Week 5 Shifts'!AG45+'Week 5 Shifts'!AG57+'Week 5 Shifts'!AG69+'Week 5 Shifts'!AG81+'Week 5 Shifts'!AG93 -> #REF! | AI27: =SUM(E27:N27)*Y16+SUM(O27:X27)*Y17+SUM(Y27:AH27)*Y18 -> #REF!
D28: Abby Author | E28: ='26.07'!L17+'26.07'!L29+'26.07'!L41+'26.07'!L52+'26.07'!L64+#REF!+#REF! -> #REF! | G28: ='Week 2 Shifts'!AC22+'Week 2 Shifts'!AC34+'Week 2 Shifts'!AC46+'Week 2 Shifts'!AC58+'Week 2 Shifts'!AC70+'Week 2 Shifts'!AC82+'Week 2 Shifts'!AC94 -> #REF! | I28: ='Week 3 Shifts'!AC22+'Week 3 Shifts'!AC34+'Week 3 Shifts'!AC58+'Week 3 Shifts'!AC70+'Week 3 Shifts'!AC82+'Week 3 Shifts'!AC94 -> #REF! | K28: ='Week 4 Shifts'!AC22+'Week 4 Shifts'!AC34+'Week 4 Shifts'!AC46+'Week 4 Shifts'!AC58+'Week 4 Shifts'!AC70+'Week 4 Shifts'!AC82+'Week 4 Shifts'!AC94 -> #REF! | M28: ='Week 5 Shifts'!AC22+'Week 5 Shifts'!AC34+'Week 5 Shifts'!AC46+'Week 5 Shifts'!AC58+'Week 5 Shifts'!AC70+'Week 5 Shifts'!AC82+'Week 5 Shifts'!AC94 -> #REF! | O28: =#REF!+#REF!+#REF!+#REF!+#REF!+#REF!+#REF! -> #REF! | Q28: ='Week 2 Shifts'!AE22+'Week 2 Shifts'!AE34+'Week 2 Shifts'!AE46+'Week 2 Shifts'!AE58+'Week 2 Shifts'!AE70+'Week 2 Shifts'!AE82+'Week 2 Shifts'!AE94 -> #REF! | S28: ='Week 3 Shifts'!AE22+'Week 3 Shifts'!AE34+'Week 3 Shifts'!AE46+'Week 3 Shifts'!AE58+'Week 3 Shifts'!AE70+'Week 3 Shifts'!AE82+'Week 3 Shifts'!AE94 -> #REF! | U28: ='Week 4 Shifts'!AE22+'Week 4 Shifts'!AE34+'Week 4 Shifts'!AE46+'Week 4 Shifts'!AE58+'Week 4 Shifts'!AE70+'Week 4 Shifts'!AE82+'Week 4 Shifts'!AE94 -> #REF! | W28: ='Week 5 Shifts'!AE22+'Week 5 Shifts'!AE34+'Week 5 Shifts'!AE46+'Week 5 Shifts'!AE58+'Week 5 Shifts'!AE70+'Week 5 Shifts'!AE82+'Week 5 Shifts'!AE94 -> #REF! | Y28: =#REF!+#REF!+#REF!+#REF!+#REF!+#REF!+#REF! -> #REF! | AA28: ='Week 2 Shifts'!AG22+'Week 2 Shifts'!AG34+'Week 2 Shifts'!AG46+'Week 2 Shifts'!AG58+'Week 2 Shifts'!AG70+'Week 2 Shifts'!AG82+'Week 2 Shifts'!AG94 -> #REF! | AC28: ='Week 3 Shifts'!AG22+'Week 3 Shifts'!AG34+'Week 3 Shifts'!AG46+'Week 3 Shifts'!AG58+'Week 3 Shifts'!AG70+'Week 3 Shifts'!AG82+'Week 3 Shifts'!AG94 -> #REF! | AE28: ='Week 4 Shifts'!AG22+'Week 4 Shifts'!AG34+'Week 4 Shifts'!AG46+'Week 4 Shifts'!AG58+'Week 4 Shifts'!AG70+'Week 4 Shifts'!AG82+'Week 4 Shifts'!AG94 -> #REF! | AG28: ='Week 5 Shifts'!AG22+'Week 5 Shifts'!AG34+'Week 5 Shifts'!AG46+'Week 5 Shifts'!AG58+'Week 5 Shifts'!AG70+'Week 5 Shifts'!AG82+'Week 5 Shifts'!AG94 -> #REF! | AI28: =SUM(E28:N28)*Y16+SUM(O28:X28)*Y17+SUM(Y28:AH28)*Y18 -> #REF!
D29: Casey Creator | E29: ='26.07'!L18+'26.07'!L30+'26.07'!L42+'26.07'!L53+'26.07'!L66+#REF!+#REF! -> #REF! | G29: ='Week 2 Shifts'!AC23+'Week 2 Shifts'!AC35+'Week 2 Shifts'!AC47+'Week 2 Shifts'!AC59+'Week 2 Shifts'!AC71+'Week 2 Shifts'!AC83+'Week 2 Shifts'!AC95 -> #REF! | I29: ='Week 3 Shifts'!AC23+'Week 3 Shifts'!AC35+'Week 3 Shifts'!AC59+'Week 3 Shifts'!AC71+'Week 3 Shifts'!AC83+'Week 3 Shifts'!AC95 -> #REF! | K29: ='Week 4 Shifts'!AC23+'Week 4 Shifts'!AC35+'Week 4 Shifts'!AC47+'Week 4 Shifts'!AC59+'Week 4 Shifts'!AC71+'Week 4 Shifts'!AC83+'Week 4 Shifts'!AC95 -> #REF! | M29: ='Week 5 Shifts'!AC23+'Week 5 Shifts'!AC35+'Week 5 Shifts'!AC47+'Week 5 Shifts'!AC59+'Week 5 Shifts'!AC71+'Week 5 Shifts'!AC83+'Week 5 Shifts'!AC95 -> #REF! | O29: =#REF!+#REF!+#REF!+#REF!+#REF!+#REF!+#REF! -> #REF! | Q29: ='Week 2 Shifts'!AE23+'Week 2 Shifts'!AE35+'Week 2 Shifts'!AE47+'Week 2 Shifts'!AE59+'Week 2 Shifts'!AE71+'Week 2 Shifts'!AE83+'Week 2 Shifts'!AE95 -> #REF! | S29: ='Week 3 Shifts'!AE23+'Week 3 Shifts'!AE35+'Week 3 Shifts'!AE47+'Week 3 Shifts'!AE59+'Week 3 Shifts'!AE71+'Week 3 Shifts'!AE83+'Week 3 Shifts'!AE95 -> #REF! | U29: ='Week 4 Shifts'!AE23+'Week 4 Shifts'!AE35+'Week 4 Shifts'!AE47+'Week 4 Shifts'!AE59+'Week 4 Shifts'!AE71+'Week 4 Shifts'!AE83+'Week 4 Shifts'!AE95 -> #REF! | W29: ='Week 5 Shifts'!AE23+'Week 5 Shifts'!AE35+'Week 5 Shifts'!AE47+'Week 5 Shifts'!AE59+'Week 5 Shifts'!AE71+'Week 5 Shifts'!AE83+'Week 5 Shifts'!AE95 -> #REF! | Y29: =#REF!+#REF!+#REF!+#REF!+#REF!+#REF!+#REF! -> #REF! | AA29: ='Week 2 Shifts'!AG23+'Week 2 Shifts'!AG35+'Week 2 Shifts'!AG47+'Week 2 Shifts'!AG59+'Week 2 Shifts'!AG71+'Week 2 Shifts'!AG83+'Week 2 Shifts'!AG95 -> #REF! | AC29: ='Week 3 Shifts'!AG23+'Week 3 Shifts'!AG35+'Week 3 Shifts'!AG47+'Week 3 Shifts'!AG59+'Week 3 Shifts'!AG71+'Week 3 Shifts'!AG83+'Week 3 Shifts'!AG95 -> #REF! | AE29: ='Week 4 Shifts'!AG23+'Week 4 Shifts'!AG35+'Week 4 Shifts'!AG47+'Week 4 Shifts'!AG59+'Week 4 Shifts'!AG71+'Week 4 Shifts'!AG83+'Week 4 Shifts'!AG95 -> #REF! | AG29: ='Week 5 Shifts'!AG23+'Week 5 Shifts'!AG35+'Week 5 Shifts'!AG47+'Week 5 Shifts'!AG59+'Week 5 Shifts'!AG71+'Week 5 Shifts'!AG83+'Week 5 Shifts'!AG95 -> #REF! | AI29: =SUM(E29:N29)*Y16+SUM(O29:X29)*Y17+SUM(Y29:AH29)*Y18 -> #REF!
D30: Perry Presenter | E30: ='26.07'!L19+'26.07'!L31+'26.07'!L43+'26.07'!L54+'26.07'!L67+#REF!+#REF! -> #REF! | G30: ='Week 2 Shifts'!AC24+'Week 2 Shifts'!AC36+'Week 2 Shifts'!AC48+'Week 2 Shifts'!AC60+'Week 2 Shifts'!AC72+'Week 2 Shifts'!AC84+'Week 2 Shifts'!AC96 -> #REF! | I30: ='Week 3 Shifts'!AC24+'Week 3 Shifts'!AC36+'Week 3 Shifts'!AC60+'Week 3 Shifts'!AC72+'Week 3 Shifts'!AC84+'Week 3 Shifts'!AC96 -> #REF! | K30: ='Week 4 Shifts'!AC24+'Week 4 Shifts'!AC36+'Week 4 Shifts'!AC48+'Week 4 Shifts'!AC60+'Week 4 Shifts'!AC72+'Week 4 Shifts'!AC84+'Week 4 Shifts'!AC96 -> #REF! | M30: ='Week 5 Shifts'!AC24+'Week 5 Shifts'!AC36+'Week 5 Shifts'!AC48+'Week 5 Shifts'!AC60+'Week 5 Shifts'!AC72+'Week 5 Shifts'!AC84+'Week 5 Shifts'!AC96 -> #REF! | O30: =#REF!+#REF!+#REF!+#REF!+#REF!+#REF!+#REF! -> #REF! | Q30: ='Week 2 Shifts'!AE24+'Week 2 Shifts'!AE36+'Week 2 Shifts'!AE48+'Week 2 Shifts'!AE60+'Week 2 Shifts'!AE72+'Week 2 Shifts'!AE84+'Week 2 Shifts'!AE96 -> #REF! | S30: ='Week 3 Shifts'!AE24+'Week 3 Shifts'!AE36+'Week 3 Shifts'!AE48+'Week 3 Shifts'!AE60+'Week 3 Shifts'!AE72+'Week 3 Shifts'!AE84+'Week 3 Shifts'!AE96 -> #REF! | U30: ='Week 4 Shifts'!AE24+'Week 4 Shifts'!AE36+'Week 4 Shifts'!AE48+'Week 4 Shifts'!AE60+'Week 4 Shifts'!AE72+'Week 4 Shifts'!AE84+'Week 4 Shifts'!AE96 -> #REF! | W30: ='Week 5 Shifts'!AE24+'Week 5 Shifts'!AE36+'Week 5 Shifts'!AE48+'Week 5 Shifts'!AE60+'Week 5 Shifts'!AE72+'Week 5 Shifts'!AE84+'Week 5 Shifts'!AE96 -> #REF! | Y30: =#REF!+#REF!+#REF!+#REF!+#REF!+#REF!+#REF! -> #REF! | AA30: ='Week 2 Shifts'!AG24+'Week 2 Shifts'!AG36+'Week 2 Shifts'!AG48+'Week 2 Shifts'!AG60+'Week 2 Shifts'!AG72+'Week 2 Shifts'!AG84+'Week 2 Shifts'!AG96 -> #REF! | AC30: ='Week 3 Shifts'!AG24+'Week 3 Shifts'!AG36+'Week 3 Shifts'!AG48+'Week 3 Shifts'!AG60+'Week 3 Shifts'!AG72+'Week 3 Shifts'!AG84+'Week 3 Shifts'!AG96 -> #REF! | AE30: ='Week 4 Shifts'!AG24+'Week 4 Shifts'!AG36+'Week 4 Shifts'!AG48+'Week 4 Shifts'!AG60+'Week 4 Shifts'!AG72+'Week 4 Shifts'!AG84+'Week 4 Shifts'!AG96 -> #REF! | AG30: ='Week 5 Shifts'!AG24+'Week 5 Shifts'!AG36+'Week 5 Shifts'!AG48+'Week 5 Shifts'!AG60+'Week 5 Shifts'!AG72+'Week 5 Shifts'!AG84+'Week 5 Shifts'!AG96 -> #REF! | AI30: =SUM(E30:L30)*Y16+SUM(O30:V30)*Y17+SUM(Y30:AF30)*Y18 -> #REF!
D31: Vinny Viewer | E31: ='26.07'!L20+'26.07'!L32+'26.07'!L44+'26.07'!L55+'26.07'!L68+#REF!+#REF! -> #REF! | G31: ='Week 2 Shifts'!AC25+'Week 2 Shifts'!AC37+'Week 2 Shifts'!AC49+'Week 2 Shifts'!AC61+'Week 2 Shifts'!AC73+'Week 2 Shifts'!AC85+'Week 2 Shifts'!AC97 -> #REF! | I31: ='Week 3 Shifts'!AC25+'Week 3 Shifts'!AC37+'Week 3 Shifts'!AC61+'Week 3 Shifts'!AC73+'Week 3 Shifts'!AC85+'Week 3 Shifts'!AC97 -> #REF! | K31: ='Week 4 Shifts'!AC25+'Week 4 Shifts'!AC37+'Week 4 Shifts'!AC49+'Week 4 Shifts'!AC61+'Week 4 Shifts'!AC73+'Week 4 Shifts'!AC85+'Week 4 Shifts'!AC97 -> #REF! | M31: ='Week 5 Shifts'!AC25+'Week 5 Shifts'!AC37+'Week 5 Shifts'!AC49+'Week 5 Shifts'!AC61+'Week 5 Shifts'!AC73+'Week 5 Shifts'!AC85+'Week 5 Shifts'!AC97 -> #REF! | O31: =#REF!+#REF!+#REF!+#REF!+#REF!+#REF!+#REF! -> #REF! | Q31: ='Week 2 Shifts'!AE25+'Week 2 Shifts'!AE37+'Week 2 Shifts'!AE49+'Week 2 Shifts'!AE61+'Week 2 Shifts'!AE73+'Week 2 Shifts'!AE85+'Week 2 Shifts'!AE97 -> #REF! | S31: ='Week 3 Shifts'!AE25+'Week 3 Shifts'!AE37+'Week 3 Shifts'!AE49+'Week 3 Shifts'!AE61+'Week 3 Shifts'!AE73+'Week 3 Shifts'!AE85+'Week 3 Shifts'!AE97 -> #REF! | U31: ='Week 4 Shifts'!AE25+'Week 4 Shifts'!AE37+'Week 4 Shifts'!AE49+'Week 4 Shifts'!AE61+'Week 4 Shifts'!AE73+'Week 4 Shifts'!AE85+'Week 4 Shifts'!AE97 -> #REF! | W31: ='Week 5 Shifts'!AE25+'Week 5 Shifts'!AE37+'Week 5 Shifts'!AE49+'Week 5 Shifts'!AE61+'Week 5 Shifts'!AE73+'Week 5 Shifts'!AE85+'Week 5 Shifts'!AE97 -> #REF! | Y31: =#REF!+#REF!+#REF!+#REF!+#REF!+#REF!+#REF! -> #REF! | AA31: ='Week 2 Shifts'!AG25+'Week 2 Shifts'!AG37+'Week 2 Shifts'!AG49+'Week 2 Shifts'!AG61+'Week 2 Shifts'!AG73+'Week 2 Shifts'!AG85+'Week 2 Shifts'!AG97 -> #REF! | AC31: ='Week 3 Shifts'!AG25+'Week 3 Shifts'!AG37+'Week 3 Shifts'!AG49+'Week 3 Shifts'!AG61+'Week 3 Shifts'!AG73+'Week 3 Shifts'!AG85+'Week 3 Shifts'!AG97 -> #REF! | AE31: ='Week 4 Shifts'!AG25+'Week 4 Shifts'!AG37+'Week 4 Shifts'!AG49+'Week 4 Shifts'!AG61+'Week 4 Shifts'!AG73+'Week 4 Shifts'!AG85+'Week 4 Shifts'!AG97 -> #REF! | AG31: ='Week 5 Shifts'!AG25+'Week 5 Shifts'!AG37+'Week 5 Shifts'!AG49+'Week 5 Shifts'!AG61+'Week 5 Shifts'!AG73+'Week 5 Shifts'!AG85+'Week 5 Shifts'!AG97 -> #REF! | AI31: =SUM(E31:N31)*Y16+SUM(O31:X31)*Y17+SUM(Y31:AH31)*Y18 -> #REF!
D32: Molly Maker | E32: ='26.07'!L21+'26.07'!L33+'26.07'!L45+'26.07'!L56+'26.07'!L69+#REF!+#REF! -> #REF! | G32: ='Week 2 Shifts'!AC26+'Week 2 Shifts'!AC38+'Week 2 Shifts'!AC50+'Week 2 Shifts'!AC62+'Week 2 Shifts'!AC74+'Week 2 Shifts'!AC86+'Week 2 Shifts'!AC98 -> #REF! | I32: ='Week 3 Shifts'!AC26+'Week 3 Shifts'!AC38+'Week 3 Shifts'!AC62+'Week 3 Shifts'!AC74+'Week 3 Shifts'!AC86+'Week 3 Shifts'!AC98 -> #REF! | K32: ='Week 4 Shifts'!AC26+'Week 4 Shifts'!AC38+'Week 4 Shifts'!AC50+'Week 4 Shifts'!AC62+'Week 4 Shifts'!AC74+'Week 4 Shifts'!AC86+'Week 4 Shifts'!AC98 -> #REF! | M32: ='Week 5 Shifts'!AC26+'Week 5 Shifts'!AC38+'Week 5 Shifts'!AC50+'Week 5 Shifts'!AC62+'Week 5 Shifts'!AC74+'Week 5 Shifts'!AC86+'Week 5 Shifts'!AC98 -> #REF! | O32: =#REF!+#REF!+#REF!+#REF!+#REF!+#REF!+#REF! -> #REF! | Q32: ='Week 2 Shifts'!AE26+'Week 2 Shifts'!AE38+'Week 2 Shifts'!AE50+'Week 2 Shifts'!AE62+'Week 2 Shifts'!AE74+'Week 2 Shifts'!AE86+'Week 2 Shifts'!AE98 -> #REF! | S32: ='Week 3 Shifts'!AE26+'Week 3 Shifts'!AE38+'Week 3 Shifts'!AE50+'Week 3 Shifts'!AE62+'Week 3 Shifts'!AE74+'Week 3 Shifts'!AE86+'Week 3 Shifts'!AE98 -> #REF! | U32: ='Week 4 Shifts'!AE26+'Week 4 Shifts'!AE38+'Week 4 Shifts'!AE50+'Week 4 Shifts'!AE62+'Week 4 Shifts'!AE74+'Week 4 Shifts'!AE86+'Week 4 Shifts'!AE98 -> #REF! | W32: ='Week 5 Shifts'!AE26+'Week 5 Shifts'!AE38+'Week 5 Shifts'!AE50+'Week 5 Shifts'!AE62+'Week 5 Shifts'!AE74+'Week 5 Shifts'!AE86+'Week 5 Shifts'!AE98 -> #REF! | Y32: =#REF!+#REF!+#REF!+#REF!+#REF!+#REF!+#REF! -> #REF! | AA32: ='Week 2 Shifts'!AG26+'Week 2 Shifts'!AG38+'Week 2 Shifts'!AG50+'Week 2 Shifts'!AG62+'Week 2 Shifts'!AG74+'Week 2 Shifts'!AG86+'Week 2 Shifts'!AG98 -> #REF! | AC32: ='Week 3 Shifts'!AG26+'Week 3 Shifts'!AG38+'Week 3 Shifts'!AG50+'Week 3 Shifts'!AG62+'Week 3 Shifts'!AG74+'Week 3 Shifts'!AG86+'Week 3 Shifts'!AG98 -> #REF! | AE32: ='Week 4 Shifts'!AG26+'Week 4 Shifts'!AG38+'Week 4 Shifts'!AG50+'Week 4 Shifts'!AG62+'Week 4 Shifts'!AG74+'Week 4 Shifts'!AG86+'Week 4 Shifts'!AG98 -> #REF! | AG32: ='Week 5 Shifts'!AG26+'Week 5 Shifts'!AG38+'Week 5 Shifts'!AG50+'Week 5 Shifts'!AG62+'Week 5 Shifts'!AG74+'Week 5 Shifts'!AG86+'Week 5 Shifts'!AG98 -> #REF! | AI32: =SUM(E32:N32)*Y16+SUM(O32:X32)*Y17+SUM(Y32:AH32)*Y18 -> #REF!
D33: Berry Books | E33: ='26.07'!L22+'26.07'!L34+'26.07'!L46+'26.07'!L57+'26.07'!L70+#REF!+#REF! -> #REF! | G33: ='Week 2 Shifts'!AC27+'Week 2 Shifts'!AC39+'Week 2 Shifts'!AC51+'Week 2 Shifts'!AC63+'Week 2 Shifts'!AC75+'Week 2 Shifts'!AC87+'Week 2 Shifts'!AC99 -> #REF! | I33: ='Week 3 Shifts'!AC27+'Week 3 Shifts'!AC39+'Week 3 Shifts'!AC63+'Week 3 Shifts'!AC75+'Week 3 Shifts'!AC87+'Week 3 Shifts'!AC99 -> #REF! | K33: ='Week 4 Shifts'!AC27+'Week 4 Shifts'!AC39+'Week 4 Shifts'!AC51+'Week 4 Shifts'!AC63+'Week 4 Shifts'!AC75+'Week 4 Shifts'!AC87+'Week 4 Shifts'!AC99 -> #REF! | M33: ='Week 5 Shifts'!AC27+'Week 5 Shifts'!AC39+'Week 5 Shifts'!AC51+'Week 5 Shifts'!AC63+'Week 5 Shifts'!AC75+'Week 5 Shifts'!AC87+'Week 5 Shifts'!AC99 -> #REF! | O33: =#REF!+#REF!+#REF!+#REF!+#REF!+#REF!+#REF! -> #REF! | Q33: ='Week 2 Shifts'!AE27+'Week 2 Shifts'!AE39+'Week 2 Shifts'!AE51+'Week 2 Shifts'!AE63+'Week 2 Shifts'!AE75+'Week 2 Shifts'!AE87+'Week 2 Shifts'!AE99 -> #REF! | S33: ='Week 3 Shifts'!AE27+'Week 3 Shifts'!AE39+'Week 3 Shifts'!AE51+'Week 3 Shifts'!AE63+'Week 3 Shifts'!AE75+'Week 3 Shifts'!AE87+'Week 3 Shifts'!AE99 -> #REF! | U33: ='Week 4 Shifts'!AE27+'Week 4 Shifts'!AE39+'Week 4 Shifts'!AE51+'Week 4 Shifts'!AE63+'Week 4 Shifts'!AE75+'Week 4 Shifts'!AE87+'Week 4 Shifts'!AE99 -> #REF! | W33: ='Week 5 Shifts'!AE27+'Week 5 Shifts'!AE39+'Week 5 Shifts'!AE51+'Week 5 Shifts'!AE63+'Week 5 Shifts'!AE75+'Week 5 Shifts'!AE87+'Week 5 Shifts'!AE99 -> #REF! | Y33: =#REF!+#REF!+#REF!+#REF!+#REF!+#REF!+#REF! -> #REF! | AA33: ='Week 2 Shifts'!AG27+'Week 2 Shifts'!AG39+'Week 2 Shifts'!AG51+'Week 2 Shifts'!AG63+'Week 2 Shifts'!AG75+'Week 2 Shifts'!AG87+'Week 2 Shifts'!AG99 -> #REF! | AC33: ='Week 3 Shifts'!AG27+'Week 3 Shifts'!AG39+'Week 3 Shifts'!AG51+'Week 3 Shifts'!AG63+'Week 3 Shifts'!AG75+'Week 3 Shifts'!AG87+'Week 3 Shifts'!AG99 -> #REF! | AE33: ='Week 4 Shifts'!AG27+'Week 4 Shifts'!AG39+'Week 4 Shifts'!AG51+'Week 4 Shifts'!AG63+'Week 4 Shifts'!AG75+'Week 4 Shifts'!AG87+'Week 4 Shifts'!AG99 -> #REF! | AG33: ='Week 5 Shifts'!AG27+'Week 5 Shifts'!AG39+'Week 5 Shifts'!AG51+'Week 5 Shifts'!AG63+'Week 5 Shifts'!AG75+'Week 5 Shifts'!AG87+'Week 5 Shifts'!AG99 -> #REF! | AI33: =SUM(E33:N33)*Y16+SUM(O33:X33)*Y17+SUM(Y33:AH33)*Y18 -> #REF!
D34: Total Hours / per week | E34: =SUM(E26:F33) -> #REF! | G34: =SUM(G26:H33) -> #REF! | I34: =SUM(I26:J33) -> #REF! | K34: =SUM(K26:L33) -> #REF! | M34: =SUM(M26:N33) -> #REF! | O34: =SUM(O26:P33) -> #REF! | Q34: =SUM(Q26:R33) -> #REF! | S34: =SUM(S26:T33) -> #REF! | U34: =SUM(U26:V33) -> #REF! | W34: =SUM(W26:X33) -> #REF! | Y34: =SUM(Y26:Z33) -> #REF! | AA34: =SUM(AA26:AB33) -> #REF! | AC34: =SUM(AC26:AD33) -> #REF! | AE34: =SUM(AE26:AF33) -> #REF! | AG34: =SUM(AG26:AH33) -> #REF!

Sheet 26.07
D6: 26 - 30 Temmuz
D7: Temmuz 4. Hafta
D9: Dikkat ➜
F10: Fotoğrafçılar sekmesindeki üçgen tuşa basarak kendi isminizi aratıp, daha hızlı bir şekilde işlem yapabilirsiniz.
D14: Fotoğrafçılar | E14: Şehir | F14: Ekip | G14: 44403 | H14: 44404 | I14: 44405 | J14: 44406 | K14: 44407 | L14: Top. Gün | M14: Top. Hedef Randevu
D15: Furkan Berat Altunkaya | E15: =VLOOKUP(D15,Data!H:I,2,0) -> Adana | G15: TRUE | H15: TRUE | I15: TRUE | J15: TRUE | K15: TRUE | L15: =COUNTIF(G15:K15,"TRUE") -> 5 | M15: =L15*4 -> 20
D16: Furkan Berat Altunkaya 2 | E16: =VLOOKUP(D16,Data!H:I,2,0) -> Adana | G16: TRUE | H16: TRUE | I16: TRUE | J16: TRUE | K16: TRUE | L16: =COUNTIF(G16:K16,"TRUE") -> 5 | M16: =L16*4 -> 20
D17: Bedirhan Ankara | E17: =VLOOKUP(D17,Data!H:I,2,0) -> Ankara | G17: FALSE | H17: TRUE | I17: FALSE | J17: TRUE | K17: FALSE | L17: =COUNTIF(G17:K17,"TRUE") -> 2 | M17: =L17*4 -> 8
D18: Furkan Ankara | E18: =VLOOKUP(D18,Data!H:I,2,0) -> Ankara | G18: TRUE | H18: TRUE | I18: FALSE | J18: FALSE | K18: FALSE | L18: =COUNTIF(G18:K18,"TRUE") -> 2 | M18: =L18*4 -> 8
D19: Gizem Fukul | E19: =VLOOKUP(D19,Data!H:I,2,0) -> Ankara | G19: TRUE | H19: TRUE | I19: TRUE | J19: TRUE | K19: TRUE | L19: =COUNTIF(G19:K19,"TRUE") -> 5 | M19: =L19*4 -> 20
D20: Onur Ay | E20: =VLOOKUP(D20,Data!H:I,2,0) -> Ankara | G20: TRUE | H20: TRUE | I20: TRUE | J20: TRUE | K20: TRUE | L20: =COUNTIF(G20:K20,"TRUE") -> 5 | M20: =L20*4 -> 20
D21: Ahmet Kasap | E21: =VLOOKUP(D21,Data!H:I,2,0) -> Ankara | G21: TRUE | H21: TRUE | I21: TRUE | J21: TRUE | K21: TRUE | L21: =COUNTIF(G21:K21,"TRUE") -> 5 | M21: =L21*4 -> 20
D22: Ahmet Emeklioğlu | E22: =VLOOKUP(D22,Data!H:I,2,0) -> Antalya | G22: TRUE | H22: TRUE | I22: FALSE | J22: TRUE | K22: FALSE | L22: =COUNTIF(G22:K22,"TRUE") -> 3 | M22: =L22*4 -> 12
D23: Önder Örtel | E23: =VLOOKUP(D23,Data!H:I,2,0) -> Antalya | G23: TRUE | H23: TRUE | I23: TRUE | J23: TRUE | K23: TRUE | L23: =COUNTIF(G23:K23,"TRUE") -> 5 | M23: =L23*4 -> 20
D24: Özlem Çuhadar | E24: =VLOOKUP(D24,Data!H:I,2,0) -> Aydın | G24: FALSE | H24: FALSE | I24: FALSE | J24: FALSE | K24: FALSE | L24: =COUNTIF(G24:K24,"TRUE") -> 0 | M24: =L24*4 -> 0
D25: Hamdi Can Hikmet | E25: =VLOOKUP(D25,Data!H:I,2,0) -> Bursa | G25: TRUE | H25: TRUE | I25: TRUE | J25: TRUE | K25: TRUE | L25: =COUNTIF(G25:K25,"TRUE") -> 5 | M25: =L25*4 -> 20
D26: Tamay Alper Gökdemir | E26: =VLOOKUP(D26,Data!H:I,2,0) -> Bursa | G26: TRUE | H26: TRUE | I26: FALSE | J26: FALSE | K26: FALSE | L26: =COUNTIF(G26:K26,"TRUE") -> 2 | M26: =L26*4 -> 8
... D30: Sedat Kocagöz | E30: =VLOOKUP(D30,Data!H:I,2,0) -> Isparta | G30: TRUE | H30: TRUE | I30: FALSE | J30: FALSE | K30: FALSE | L30: =COUNTIF(G30:K30,"TRUE") -> 2 | M30: =L30*4 -> 8
D31: Alev Sağdıç | E31: =VLOOKUP(D31,Data!H:I,2,0) -> İstanbul | F31: Freelance | G31: TRUE | H31: TRUE | I31: FALSE | J31: TRUE | K31: TRUE | L31: =COUNTIF(G31:K31,"TRUE") -> 4 | M31: =L31*4 -> 16
D32: Ali Aksu | E32: =VLOOKUP(D32,Data!H:I,2,0) -> İstanbul | F32: Nazım Öztel | G32: FALSE | H32: FALSE | I32: FALSE | J32: FALSE | K32: FALSE | L32: =COUNTIF(G32:K32,"TRUE") -> 0 | M32: =L32*4 -> 0
D33: Aras Gürol | E33: =VLOOKUP(D33,Data!H:I,2,0) -> İstanbul | F33: Nazım Öztel | G33: FALSE | H33: TRUE | I33: FALSE | J33: TRUE | K33: FALSE | L33: =COUNTIF(G33:K33,"TRUE") -> 2 | M33: =L33*4 -> 8
D34: Barkın Örken | E34: =VLOOKUP(D34,Data!H:I,2,0) -> İstanbul | F34: Filamingo | G34: TRUE | H34: TRUE | I34: TRUE | J34: TRUE | K34: FALSE | L34: =COUNTIF(G34:K34,"TRUE") -> 4 | M34: =L34*4 -> 16
D35: Başar Gerçek | E35: =VLOOKUP(D35,Data!H:I,2,0) -> İstanbul | F35: Filamingo | G35: TRUE | H35: TRUE | I35: TRUE | J35: TRUE | K35: TRUE | L35: =COUNTIF(G35:K35,"TRUE") -> 5 | M35: =L35*4 -> 20
D36: Berkan Aydeniz | E36: =VLOOKUP(D36,Data!H:I,2,0) -> İstanbul | F36: Freelance | G36: TRUE | H36: TRUE | I36: FALSE | J36: TRUE | K36: FALSE | L36: =COUNTIF(G36:K36,"TRUE") -> 3 | M36: =L36*4 -> 12
D37: Buğra Sertdemir | E37: =VLOOKUP(D37,Data!H:I,2,0) -> İstanbul | F37: Filamingo | G37: FALSE | H37: FALSE | I37: FALSE | J37: FALSE | K37: FALSE | L37: =COUNTIF(G37:K37,"TRUE") -> 0 | M37: =L37*4 -> 0
D38: Bülent Şahin | E38: =VLOOKUP(D38,Data!H:I,2,0) -> İstanbul | F38: Freelance | G38: FALSE | H38: FALSE | I38: FALSE | J38: FALSE | K38: FALSE | L38: =COUNTIF(G38:K38,"TRUE") -> 0 | M38: =L38*4 -> 0
D39: Cemil Yılmaz | E39: =VLOOKUP(D39,Data!H:I,2,0) -> İstanbul | F39: Nazım Öztel | G39: FALSE | H39: FALSE | I39: FALSE | J39: FALSE | K39: FALSE | L39: =COUNTIF(G39:K39,"TRUE") -> 0 | M39: =L39*4 -> 0
D40: Ceren Kalafat | E40: =VLOOKUP(D40,Data!H:I,2,0) -> İstanbul | F40: Freelance | G40: FALSE | H40: FALSE | I40: FALSE | J40: TRUE | K40: FALSE | L40: =COUNTIF(G40:K40,"TRUE") -> 1 | M40: =L40*4 -> 4
D41: Deniz Tepe | E41: =VLOOKUP(D41,Data!H:I,2,0) -> İstanbul | F41: Filamingo | G41: TRUE | H41: TRUE | I41: TRUE | J41: TRUE | K41: TRUE | L41: =COUNTIF(G41:K41,"TRUE") -> 5 | M41: =L41*4 -> 20
D42: Doğa Sertdemir | E42: =VLOOKUP(D42,Data!H:I,2,0) -> İstanbul | F42: Filamingo | G42: TRUE | H42: TRUE | I42: TRUE | J42: TRUE | K42: TRUE | L42: =COUNTIF(G42:K42,"TRUE") -> 5 | M42: =L42*4 -> 20
... D71: Recep Çakır | E71: =VLOOKUP(D71,Data!H:I,2,0) -> Samsun | F71: Nazım Öztel | G71: TRUE | H71: TRUE | I71: TRUE | J71: FALSE | K71: FALSE | L71: =COUNTIF(G71:K71,"TRUE") -> 3 | M71: =L71*4 -> 12
D72: Zeynep Yazıcı | E72: Sakarya | F72: Filamingo | G72: FALSE | H72: FALSE | I72: FALSE | J72: TRUE | K72: FALSE | L72: =COUNTIF(G72:K72,"TRUE") -> 1 | M72: =L72*4 -> 4
D73: Mustafa Kemal İbiş | E73: =VLOOKUP(D73,Data!H:I,2,0) -> Tekirdağ | F73: Freelance | G73: TRUE | H73: TRUE | I73: TRUE | J73: TRUE | K73: FALSE | L73: =COUNTIF(G73:K73,"TRUE") -> 4 | M73: =L73*4 -> 16
D74: Ahmet Koç | E74: =VLOOKUP(D74,Data!H:I,2,0) -> Trabzon | F74: Nazım Öztel | G74: FALSE | H74: FALSE | I74: FALSE | J74: FALSE | K74: FALSE | L74: =COUNTIF(G74:K74,"TRUE") -> 0 | M74: =L74*4 -> 0
G75: =4*(COUNTIF(G14:G74,"true"))+9 -> 153 | H75: =4*(COUNTIF(H14:H74,"true"))+9 -> 177 | I75: =4*(COUNTIF(I14:I74,"true"))+9 -> 133 | J75: =4*(COUNTIF(J14:J74,"true"))+9 -> 165 | K75: =4*(COUNTIF(K14:K74,"true"))+9 -> 121 | M75: =SUM(M15:M74) -> 704

Sheet 02.08
D6: 2 - 6 Ağustos
D7: Ağustos 1. Hafta
D9: Dikkat ➜
F10: Fotoğrafçılar sekmesindeki üçgen tuşa basarak kendi isminizi aratıp, daha hızlı bir şekilde işlem yapabilirsiniz.
D14: Fotoğrafçılar | E14: Şehir | F14: Ekip | G14: 44410 | H14: 44411 | I14: 44412 | J14: 44413 | K14: 44414 | L14: Top. Gün | M14: Top. Hedef Randevu
D15: Furkan Berat Altunkaya | E15: =VLOOKUP(D15,Data!H:I,2,0) -> Adana | G15: TRUE | H15: TRUE | I15: TRUE | J15: TRUE | K15: FALSE | L15: =COUNTIF(G15:K15,"TRUE") -> 4 | M15: =L15*4 -> 16
D16: Furkan Berat Altunkaya 2 | E16: =VLOOKUP(D16,Data!H:I,2,0) -> Adana | G16: TRUE | H16: TRUE | I16: FALSE | J16: FALSE | K16: FALSE | L16: =COUNTIF(G16:K16,"TRUE") -> 2 | M16: =L16*4 -> 8
D17: Bedirhan Ankara | E17: =VLOOKUP(D17,Data!H:I,2,0) -> Ankara | F17: Medya Özgür Deniz | G17: FALSE | H17: TRUE | I17: FALSE | J17: TRUE | K17: FALSE | L17: =COUNTIF(G17:K17,"TRUE") -> 2 | M17: =L17*4 -> 8
D18: Furkan Ankara | E18: =VLOOKUP(D18,Data!H:I,2,0) -> Ankara | F18: Medya Özgür Deniz | G18: FALSE | H18: TRUE | I18: TRUE | J18: FALSE | K18: FALSE | L18: =COUNTIF(G18:K18,"TRUE") -> 2 | M18: =L18*4 -> 8
D19: Gizem Fukul | E19: =VLOOKUP(D19,Data!H:I,2,0) -> Ankara | F19: Medya Özgür Deniz | G19: TRUE | H19: TRUE | I19: TRUE | J19: TRUE | K19: TRUE | L19: =COUNTIF(G19:K19,"TRUE") -> 5 | M19: =L19*4 -> 20
D20: Ahmet Kasap | E20: =VLOOKUP(D20,Data!H:I,2,0) -> Ankara | F20: Medya Özgür Deniz | G20: TRUE | H20: TRUE | I20: TRUE | J20: TRUE | K20: TRUE | L20: =COUNTIF(G20:K20,"TRUE") -> 5 | M20: =L20*4 -> 20
D21: Onur Ay | E21: =VLOOKUP(D21,Data!H:I,2,0) -> Ankara | F21: Medya Özgür Deniz | G21: TRUE | H21: TRUE | I21: TRUE | J21: TRUE | K21: TRUE | L21: =COUNTIF(G21:K21,"TRUE") -> 5 | M21: =L21*4 -> 20
D22: Ahmet Emeklioğlu | E22: =VLOOKUP(D22,Data!H:I,2,0) -> Antalya | G22: FALSE | H22: FALSE | I22: FALSE | J22: FALSE | K22: FALSE | L22: =COUNTIF(G22:K22,"TRUE") -> 0 | M22: =L22*4 -> 0
D23: Önder Örtel | E23: =VLOOKUP(D23,Data!H:I,2,0) -> Antalya | G23: TRUE | H23: FALSE | I23: FALSE | J23: FALSE | K23: FALSE | L23: =COUNTIF(G23:K23,"TRUE") -> 1 | M23: =L23*4 -> 4
D24: Ergin Avcı | E24: Antalya | G24: FALSE | H24: FALSE | I24: FALSE | J24: TRUE | K24: TRUE | L24: =COUNTIF(G24:K24,"TRUE") -> 2 | M24: =L24*4 -> 8
D25: Özlem Çuhadar | E25: =VLOOKUP(D25,Data!H:I,2,0) -> Aydın | G25: FALSE | H25: TRUE | I25: TRUE | J25: FALSE | K25: FALSE | L25: =COUNTIF(G25:K25,"TRUE") -> 2 | M25: =L25*4 -> 8
D26: Hamdi Can Hikmet | E26: =VLOOKUP(D26,Data!H:I,2,0) -> Bursa | G26: TRUE | H26: TRUE | I26: TRUE | J26: TRUE | K26: TRUE | L26: =COUNTIF(G26:K26,"TRUE") -> 5 | M26: =L26*4 -> 20
D27: Tamay Alper Gökdemir | E27: =VLOOKUP(D27,Data!H:I,2,0) -> Bursa | G27: TRUE | H27: TRUE | I27: TRUE | J27: TRUE | K27: TRUE | L27: =COUNTIF(G27:K27,"TRUE") -> 5 | M27: =L27*4 -> 20
D28: Serhat Tarancı | E28: =VLOOKUP(D28,Data!H:I,2,0) -> Diyarbakır | G28: TRUE | H28: TRUE | I28: TRUE | J28: TRUE | K28: FALSE | L28: =COUNTIF(G28:K28,"TRUE") -> 4 | M28: =L28*4 -> 16
D29: Eda Sıla Doğan | E29: =VLOOKUP(D29,Data!H:I,2,0) -> Erzurum | G29: TRUE | H29: TRUE | I29: TRUE | J29: TRUE | K29: FALSE | L29: =COUNTIF(G29:K29,"TRUE") -> 4 | M29: =L29*4 -> 16
D30: Burak Güralp | E30: =VLOOKUP(D30,Data!H:I,2,0) -> Gaziantep | G30: TRUE | H30: TRUE | I30: TRUE | J30: TRUE | K30: TRUE | L30: =COUNTIF(G30:K30,"TRUE") -> 5 | M30: =L30*4 -> 20
D31: Sedat Kocagöz | E31: =VLOOKUP(D31,Data!H:I,2,0) -> Isparta | G31: FALSE | H31: FALSE | I31: FALSE | J31: FALSE | K31: FALSE | L31: =COUNTIF(G31:K31,"TRUE") -> 0 | M31: =L31*4 -> 0
D32: Barkın Örken | E32: =VLOOKUP(D32,Data!H:I,2,0) -> İstanbul | F32: Filamingo | G32: TRUE | H32: TRUE | I32: TRUE | J32: TRUE | K32: FALSE | L32: =COUNTIF(G32:K32,"TRUE") -> 4 | M32: =L32*4 -> 16
D33: Başar Gerçek | E33: =VLOOKUP(D33,Data!H:I,2,0) -> İstanbul | F33: Filamingo | G33: TRUE | H33: TRUE | I33: TRUE | J33: TRUE | K33: FALSE | L33: =COUNTIF(G33:K33,"TRUE") -> 4 | M33: =L33*4 -> 16
D34: Buğra Sertdemir | E34: =VLOOKUP(D34,Data!H:I,2,0) -> İstanbul | F34: Filamingo | G34: FALSE | H34: FALSE | I34: FALSE | J34: FALSE | K34: FALSE | L34: =COUNTIF(G34:K34,"TRUE") -> 0 | M34: =L34*4 -> 0
D35: Deniz Tepe | E35: =VLOOKUP(D35,Data!H:I,2,0) -> İstanbul | F35: Filamingo | G35: TRUE | H35: TRUE | I35: TRUE | J35: TRUE | K35: TRUE | L35: =COUNTIF(G35:K35,"TRUE") -> 5 | M35: =L35*4 -> 20
D36: Doğa Sertdemir | E36: =VLOOKUP(D36,Data!H:I,2,0) -> İstanbul | F36: Filamingo | G36: TRUE | H36: FALSE | I36: TRUE | J36: TRUE | K36: TRUE | L36: =COUNTIF(G36:K36,"TRUE") -> 4 | M36: =L36*4 -> 16
D37: Ebrar Kılıç | E37: =VLOOKUP(D37,Data!H:I,2,0) -> İstanbul | F37: Filamingo | G37: FALSE | H37: FALSE | I37: FALSE | J37: FALSE | K37: FALSE | L37: =COUNTIF(G37:K37,"TRUE") -> 0 | M37: =L37*4 -> 0
D38: Edanur Aktürk | E38: =VLOOKUP(D38,Data!H:I,2,0) -> İstanbul | F38: Filamingo | G38: TRUE | H38: TRUE | I38: TRUE | J38: TRUE | K38: TRUE | L38: =COUNTIF(G38:K38,"TRUE") -> 5 | M38: =L38*4 -> 20
D39: Oğuzhan Kadıoğlu | E39: =VLOOKUP(D39,Data!H:I,2,0) -> İstanbul | F39: Filamingo | G39: TRUE | H39: TRUE | I39: TRUE | J39: FALSE | K39: FALSE | L39: =COUNTIF(G39:K39,"TRUE") -> 3 | M39: =L39*4 -> 12
D40: Osman Gültekin | E40: =VLOOKUP(D40,Data!H:I,2,0) -> İstanbul | F40: Filamingo | G40: FALSE | H40: FALSE | I40: FALSE | J40: FALSE | K40: FALSE | L40: =COUNTIF(G40:K40,"TRUE") -> 0 | M40: =L40*4 -> 0
D41: Şafak Cömert | E41: =VLOOKUP(D41,Data!H:I,2,0) -> İstanbul | F41: Filamingo | G41: FALSE | H41: TRUE | I41: TRUE | J41: TRUE | K41: TRUE | L41: =COUNTIF(G41:K41,"TRUE") -> 4 | M41: =L41*4 -> 16
D42: Alev Sağdıç | E42: =VLOOKUP(D42,Data!H:I,2,0) -> İstanbul | F42: Freelance | G42: TRUE | H42: TRUE | I42: TRUE | J42: TRUE | K42: TRUE | L42: =COUNTIF(G42:K42,"TRUE") -> 5 | M42: =L42*4 -> 20
D43: Berkan Aydeniz | E43: =VLOOKUP(D43,Data!H:I,2,0) -> İstanbul | F43: Freelance | G43: TRUE | H43: FALSE | I43: TRUE | J43: TRUE | K43: TRUE | L43: =COUNTIF(G43:K43,"TRUE") -> 4 | M43: =L43*4 -> 16
... D61: Sezer Demirbaş | E61: =VLOOKUP(D61,Data!H:I,2,0) -> İstanbul | F61: Nazım Öztel | G61: TRUE | H61: TRUE | I61: TRUE | J61: TRUE | K61: TRUE | L61: =COUNTIF(G61:K61,"TRUE") -> 5 | M61: =L61*4 -> 20
D62: Berhan Aybars | E62: =VLOOKUP(D62,Data!H:I,2,0) -> İzmir | G62: FALSE | H62: FALSE | I62: FALSE | J62: FALSE | K62: FALSE | L62: =COUNTIF(G62:K62,"TRUE") -> 0 | M62: =L62*4 -> 0
D63: Gündüz Akşamoldu | E63: =VLOOKUP(D63,Data!H:I,2,0) -> İzmir | G63: TRUE | H63: TRUE | I63: TRUE | J63: TRUE | K63: TRUE | L63: =COUNTIF(G63:K63,"TRUE") -> 5 | M63: =L63*4 -> 20
D64: Murat Megus | E64: =VLOOKUP(D64,Data!H:I,2,0) -> İzmir | G64: TRUE | H64: TRUE | I64: TRUE | J64: FALSE | K64: FALSE | L64: =COUNTIF(G64:K64,"TRUE") -> 3 | M64: =L64*4 -> 12
D65: Sabri Görkem Etçi | E65: =VLOOKUP(D65,Data!H:I,2,0) -> İzmir | G65: TRUE | H65: TRUE | I65: FALSE | J65: FALSE | K65: FALSE | L65: =COUNTIF(G65:K65,"TRUE") -> 2 | M65: =L65*4 -> 8
D66: Levent Akdeniz | E66: =VLOOKUP(D66,Data!H:I,2,0) -> Kocaeli | G66: TRUE | H66: TRUE | I66: TRUE | J66: FALSE | K66: FALSE | L66: =COUNTIF(G66:K66,"TRUE") -> 3 | M66: =L66*4 -> 12
...

Sheet 09.08
D6: 9-13 Ağustos
D7: Ağustos 2. Hafta
D9: Dikkat ➜
F10: Fotoğrafçılar sekmesindeki üçgen tuşa basarak kendi isminizi aratıp, daha hızlı bir şekilde işlem yapabilirsiniz.
D14: Fotoğrafçılar | E14: Şehir | F14: Ekip | G14: 44417 | H14: 44418 | I14: 44419 | J14: 44420 | K14: 44421 | L14: Top. Gün | M14: Top. Hedef Randevu
D15: Furkan Berat Altunkaya | E15: =VLOOKUP(D15,Data!H:I,2,0) -> Adana | F15: Freelance | G15: TRUE | H15: TRUE | I15: TRUE | J15: TRUE | K15: TRUE | L15: =COUNTIF(G15:K15,"TRUE") -> 5 | M15: =L15*4 -> 20
D16: Furkan Berat Altunkaya 2 | E16: =VLOOKUP(D16,Data!H:I,2,0) -> Adana | F16: Freelance | G16: TRUE | H16: TRUE | I16: TRUE | J16: TRUE | K16: TRUE | L16: =COUNTIF(G16:K16,"TRUE") -> 5 | M16: =L16*4 -> 20
D17: Bedirhan Ankara | E17: =VLOOKUP(D17,Data!H:I,2,0) -> Ankara | F17: Medya Özgür Deniz | G17: FALSE | H17: TRUE | I17: FALSE | J17: TRUE | K17: FALSE | L17: =COUNTIF(G17:K17,"TRUE") -> 2 | M17: =L17*4 -> 8
D18: Furkan Ankara | E18: =VLOOKUP(D18,Data!H:I,2,0) -> Ankara | F18: Medya Özgür Deniz | G18: FALSE | H18: FALSE | I18: FALSE | J18: FALSE | K18: FALSE | L18: =COUNTIF(G18:K18,"TRUE") -> 0 | M18: =L18*4 -> 0
D19: Gizem Fukul | E19: =VLOOKUP(D19,Data!H:I,2,0) -> Ankara | F19: Medya Özgür Deniz | G19: TRUE | H19: TRUE | I19: TRUE | J19: TRUE | K19: TRUE | L19: =COUNTIF(G19:K19,"TRUE") -> 5 | M19: =L19*4 -> 20
D20: Ahmet Kasap | E20: =VLOOKUP(D20,Data!H:I,2,0) -> Ankara | F20: Medya Özgür Deniz | G20: TRUE | H20: TRUE | I20: TRUE | J20: TRUE | K20: TRUE | L20: =COUNTIF(G20:K20,"TRUE") -> 5 | M20: =L20*4 -> 20
D21: Onur Ay | E21: =VLOOKUP(D21,Data!H:I,2,0) -> Ankara | F21: Medya Özgür Deniz | G21: TRUE | H21: TRUE | I21: TRUE | J21: TRUE | K21: TRUE | L21: =COUNTIF(G21:K21,"TRUE") -> 5 | M21: =L21*4 -> 20
D22: Ahmet Emeklioğlu | E22: =VLOOKUP(D22,Data!H:I,2,0) -> Antalya | F22: Nazım Öztel | G22: FALSE | H22: FALSE | I22: FALSE | J22: FALSE | K22: FALSE | L22: =COUNTIF(G22:K22,"TRUE") -> 0 | M22: =L22*4 -> 0
D23: Ergin Avcı | E23: =VLOOKUP(D23,Data!H:I,2,0) -> Antalya | F23: Nazım Öztel | G23: TRUE | H23: TRUE | I23: TRUE | J23: TRUE | K23: TRUE | L23: =COUNTIF(G23:K23,"TRUE") -> 5 | M23: =L23*4 -> 20
D24: Önder Örtel | E24: =VLOOKUP(D24,Data!H:I,2,0) -> Antalya | F24: Freelance | G24: FALSE | H24: FALSE | I24: FALSE | J24: FALSE | K24: FALSE | L24: =COUNTIF(G24:K24,"TRUE") -> 0 | M24: =L24*4 -> 0
D25: Hamdi Can Hikmet | E25: =VLOOKUP(D25,Data!H:I,2,0) -> Bursa | F25: Nazım Öztel | G25: TRUE | H25: TRUE | I25: TRUE | J25: TRUE | K25: TRUE | L25: =COUNTIF(G25:K25,"TRUE") -> 5 | M25: =L25*4 -> 20
D26: Tamay Alper Gökdemir | E26: =VLOOKUP(D26,Data!H:I,2,0) -> Bursa | F26: Freelance | G26: TRUE | H26: TRUE | I26: TRUE | J26: TRUE | K26: TRUE | L26: =COUNTIF(G26:K26,"TRUE") -> 5 | M26: =L26*4 -> 20
... D71: Ahmet Koç | E71: =VLOOKUP(D71,Data!H:I,2,0) -> Trabzon | F71: Nazım Öztel | G71: FALSE | H71: FALSE | I71: FALSE | J71: FALSE | K71: FALSE | L71: =COUNTIF(G71:K71,"TRUE") -> 0 | M71: =L71*4 -> 0
G72: =4*(COUNTIF(G14:G71,"true"))+9 -> 129 | H72: =4*(COUNTIF(H14:H71,"true"))+6 -> 126 | I72: =4*(COUNTIF(I14:I71,"true"))+9 -> 137 | J72: =4*(COUNTIF(J14:J71,"true"))+9 -> 129 | K72: =4*(COUNTIF(K14:K71,"true"))+9 -> 105 | M72: =SUM(G72:K72) -> 626

Sheet 16.08 
D6: 16-20 Ağustos
D7: Ağustos 3. Hafta
D9: Dikkat ➜
F10: Fotoğrafçılar sekmesindeki üçgen tuşa basarak kendi isminizi aratıp, daha hızlı bir şekilde işlem yapabilirsiniz.
D14: Fotoğrafçılar | E14: Şehir | F14: Ekip | G14: 44424 | H14: 44425 | I14: 44426 | J14: 44427 | K14: 44428 | L14: Top. Gün | M14: Top. Hedef Randevu
D15: Furkan Berat Altunkaya | E15: =VLOOKUP(D15,Data!H:I,2,0) -> Adana | F15: Freelance | G15: TRUE | H15: TRUE | I15: TRUE | J15: TRUE | K15: TRUE | L15: =COUNTIF(G15:K15,"TRUE") -> 5 | M15: =L15*4 -> 20
D16: Furkan Berat Altunkaya 2 | E16: =VLOOKUP(D16,Data!H:I,2,0) -> Adana | F16: Freelance | G16: FALSE | H16: FALSE | I16: TRUE | J16: TRUE | K16: TRUE | L16: =COUNTIF(G16:K16,"TRUE") -> 3 | M16: =L16*4 -> 12
D17: Bedirhan Ankara | E17: =VLOOKUP(D17,Data!H:I,2,0) -> Ankara | F17: Medya Özgür Deniz | G17: FALSE | H17: TRUE | I17: FALSE | J17: TRUE | K17: FALSE | L17: =COUNTIF(G17:K17,"TRUE") -> 2 | M17: =L17*4 -> 8
D18: Furkan Ankara | E18: =VLOOKUP(D18,Data!H:I,2,0) -> Ankara | F18: Medya Özgür Deniz | G18: FALSE | H18: TRUE | I18: FALSE | J18: FALSE | K18: FALSE | L18: =COUNTIF(G18:K18,"TRUE") -> 1 | M18: =L18*4 -> 4
D19: Gizem Fukul | E19: =VLOOKUP(D19,Data!H:I,2,0) -> Ankara | F19: Medya Özgür Deniz | G19: TRUE | H19: TRUE | I19: TRUE | J19: TRUE | K19: TRUE | L19: =COUNTIF(G19:K19,"TRUE") -> 5 | M19: =L19*4 -> 20
D20: Ahmet Kasap | E20: =VLOOKUP(D20,Data!H:I,2,0) -> Ankara | F20: Medya Özgür Deniz | G20: TRUE | H20: TRUE | I20: TRUE | J20: TRUE | K20: TRUE | L20: =COUNTIF(G20:K20,"TRUE") -> 5 | M20: =L20*4 -> 20
D21: Onur Ay | E21: =VLOOKUP(D21,Data!H:I,2,0) -> Ankara | F21: Medya Özgür Deniz | G21: TRUE | H21: TRUE | I21: TRUE | J21: TRUE | K21: TRUE | L21: =COUNTIF(G21:K21,"TRUE") -> 5 | M21: =L21*4 -> 20
D22: Ahmet Emeklioğlu | E22: =VLOOKUP(D22,Data!H:I,2,0) -> Antalya | F22: Nazım Öztel | G22: FALSE | H22: FALSE | I22: FALSE | J22: FALSE | K22: FALSE | L22: =COUNTIF(G22:K22,"TRUE") -> 0 | M22: =L22*4 -> 0
D23: Ergin Avcı | E23: =VLOOKUP(D23,Data!H:I,2,0) -> Antalya | F23: Nazım Öztel | G23: TRUE | H23: TRUE | I23: FALSE | J23: TRUE | K23: FALSE | L23: =COUNTIF(G23:K23,"TRUE") -> 3 | M23: =L23*4 -> 12
D24: Önder Örtel | E24: =VLOOKUP(D24,Data!H:I,2,0) -> Antalya | F24: Freelance | G24: TRUE | H24: TRUE | I24: TRUE | J24: TRUE | K24: FALSE | L24: =COUNTIF(G24:K24,"TRUE") -> 4 | M24: =L24*4 -> 16
D25: Hamdi Can Hikmet | E25: =VLOOKUP(D25,Data!H:I,2,0) -> Bursa | F25: Nazım Öztel | G25: TRUE | H25: TRUE | I25: TRUE | J25: TRUE | K25: TRUE | L25: =COUNTIF(G25:K25,"TRUE") -> 5 | M25: =L25*4 -> 20
D26: Tamay Alper Gökdemir | E26: =VLOOKUP(D26,Data!H:I,2,0) -> Bursa | F26: Freelance | G26: TRUE | H26: TRUE | I26: TRUE | J26: TRUE | K26: TRUE | L26: =COUNTIF(G26:K26,"TRUE") -> 5 | M26: =L26*4 -> 20
... D65: Mustafa Kemal İbiş | E65: =VLOOKUP(D65,Data!H:I,2,0) -> Tekirdağ | F65: Freelance | G65: FALSE | H65: FALSE | I65: FALSE | J65: FALSE | K65: FALSE | L65: =COUNTIF(G65:K65,"TRUE") -> 0 | M65: =L65*4 -> 0
G66: =4*(COUNTIF(G14:G65,"true"))+9 -> 133 | H66: =4*(COUNTIF(H14:H65,"true"))+9 -> 145 | I66: =4*(COUNTIF(I14:I65,"true"))+6 -> 134 | J66: =4*(COUNTIF(J14:J65,"true"))+9 -> 137 | K66: =4*(COUNTIF(K14:K65,"true"))+3 -> 115 | M66: =SUM(M15:M65) -> 628

Sheet 23.08
D6: 23-27 Ağustos
D7: Ağustos 4. Hafta
D9: Dikkat ➜
F10: Fotoğrafçılar sekmesindeki üçgen tuşa basarak kendi isminizi aratıp, daha hızlı bir şekilde işlem yapabilirsiniz.
D14: Fotoğrafçılar | E14: Şehir | F14: Ekip | G14: 44431 | H14: 44432 | I14: 44433 | J14: 44434 | K14: 44435 | L14: Top. Gün | M14: Top. Hedef Randevu
D15: Furkan Berat Altunkaya | E15: =VLOOKUP(D15,Data!H:I,2,0) -> Adana | F15: Freelance | G15: TRUE | H15: TRUE | I15: TRUE | J15: TRUE | K15: TRUE | L15: =COUNTIF(G15:K15,"TRUE") -> 5 | M15: =L15*4 -> 20
D16: Furkan Berat Altunkaya 2 | E16: =VLOOKUP(D16,Data!H:I,2,0) -> Adana | F16: Freelance | G16: TRUE | H16: TRUE | I16: TRUE | J16: TRUE | K16: TRUE | L16: =COUNTIF(G16:K16,"TRUE") -> 5 | M16: =L16*4 -> 20
D17: Bedirhan Ankara | E17: =VLOOKUP(D17,Data!H:I,2,0) -> Ankara | F17: Medya Özgür Deniz | G17: FALSE | H17: TRUE | I17: FALSE | J17: TRUE | K17: FALSE | L17: =COUNTIF(G17:K17,"TRUE") -> 2 | M17: =L17*4 -> 8
D18: Furkan Ankara | E18: =VLOOKUP(D18,Data!H:I,2,0) -> Ankara | F18: Medya Özgür Deniz | G18: FALSE | H18: FALSE | I18: FALSE | J18: FALSE | K18: FALSE | L18: =COUNTIF(G18:K18,"TRUE") -> 0 | M18: =L18*4 -> 0
D19: Gizem Fukul | E19: =VLOOKUP(D19,Data!H:I,2,0) -> Ankara | F19: Medya Özgür Deniz | G19: TRUE | H19: TRUE | I19: TRUE | J19: TRUE | K19: TRUE | L19: =COUNTIF(G19:K19,"TRUE") -> 5 | M19: =L19*4 -> 20
D20: Ahmet Kasap | E20: =VLOOKUP(D20,Data!H:I,2,0) -> Ankara | F20: Medya Özgür Deniz | G20: TRUE | H20: TRUE | I20: TRUE | J20: TRUE | K20: TRUE | L20: =COUNTIF(G20:K20,"TRUE") -> 5 | M20: =L20*4 -> 20
D21: Onur Ay | E21: =VLOOKUP(D21,Data!H:I,2,0) -> Ankara | F21: Medya Özgür Deniz | G21: TRUE | H21: TRUE | I21: TRUE | J21: TRUE | K21: TRUE | L21: =COUNTIF(G21:K21,"TRUE") -> 5 | M21: =L21*4 -> 20
D22: Ergin Avcı | E22: =VLOOKUP(D22,Data!H:I,2,0) -> Antalya | F22: Nazım Öztel | G22: TRUE | H22: TRUE | I22: TRUE | J22: TRUE | K22: TRUE | L22: =COUNTIF(G22:K22,"TRUE") -> 5 | M22: =L22*4 -> 20
D23: Önder Örtel | E23: =VLOOKUP(D23,Data!H:I,2,0) -> Antalya | F23: Freelance | G23: TRUE | H23: TRUE | I23: TRUE | J23: TRUE | K23: TRUE | L23: =COUNTIF(G23:K23,"TRUE") -> 5 | M23: =L23*4 -> 20
D24: Hamdi Can Hikmet | E24: =VLOOKUP(D24,Data!H:I,2,0) -> Bursa | F24: Nazım Öztel | G24: TRUE | H24: TRUE | I24: TRUE | J24: TRUE | K24: TRUE | L24: =COUNTIF(G24:K24,"TRUE") -> 5 | M24: =L24*4 -> 20
D25: Tamay Alper Gökdemir | E25: =VLOOKUP(D25,Data!H:I,2,0) -> Bursa | F25: Freelance | G25: TRUE | H25: TRUE | I25: TRUE | J25: TRUE | K25: TRUE | L25: =COUNTIF(G25:K25,"TRUE") -> 5 | M25: =L25*4 -> 20
D26: Serhat Tarancı | E26: =VLOOKUP(D26,Data!H:I,2,0) -> Diyarbakır | F26: Nazım Öztel | G26: TRUE | H26: TRUE | I26: FALSE | J26: FALSE | K26: FALSE | L26: =COUNTIF(G26:K26,"TRUE") -> 2 | M26: =L26*4 -> 8
... D55: Gündüz Akşamoldu | E55: =VLOOKUP(D55,Data!H:I,2,0) -> İzmir | F55: Nazım Öztel | G55: TRUE | H55: TRUE | I55: TRUE | J55: TRUE | K55: TRUE | L55: =COUNTIF(G55:K55,"TRUE") -> 5 | M55: =L55*4 -> 20
D56: Hasan Ceylan | E56: İzmir | F56: Nazım Öztel | G56: FALSE | H56: FALSE | I56: TRUE | J56: TRUE | K56: TRUE | L56: =COUNTIF(G56:K56,"TRUE") -> 3 | M56: =L56*4 -> 12
D57: Murat Megus | E57: =VLOOKUP(D57,Data!H:I,2,0) -> İzmir | F57: Freelance | G57: TRUE | H57: TRUE | I57: TRUE | J57: TRUE | K57: FALSE | L57: =COUNTIF(G57:K57,"TRUE") -> 4 | M57: =L57*4 -> 16
D58: Levent Akdeniz | E58: =VLOOKUP(D58,Data!H:I,2,0) -> Kocaeli | F58: Nazım Öztel | G58: FALSE | H58: FALSE | I58: FALSE | J58: TRUE | K58: TRUE | L58: =COUNTIF(G58:K58,"TRUE") -> 2 | M58: =L58*4 -> 8
D59: Kathade Elhalaf | E59: =VLOOKUP(D59,Data!H:I,2,0) -> Konya | F59: Nazım Öztel | G59: TRUE | H59: TRUE | I59: TRUE | J59: TRUE | K59: TRUE | L59: =COUNTIF(G59:K59,"TRUE") -> 5 | M59: =L59*4 -> 20
D60: Zeynep Zülal Örman | E60: =VLOOKUP(D60,Data!H:I,2,0) -> Manisa | F60: Nazım Öztel | G60: TRUE | H60: FALSE | I60: FALSE | J60: FALSE | K60: FALSE | L60: =COUNTIF(G60:K60,"TRUE") -> 1 | M60: =L60*4 -> 4 | N60: Covid
D61: Burçin Sezer | E61: =VLOOKUP(D61,Data!H:I,2,0) -> Mersin | F61: Nazım Öztel | G61: TRUE | H61: FALSE | I61: FALSE | J61: TRUE | K61: FALSE | L61: =COUNTIF(G61:K61,"TRUE") -> 2 | M61: =L61*4 -> 8
D62: Mustafa Kemal İbiş | E62: =VLOOKUP(D62,Data!H:I,2,0) -> Tekirdağ | F62: Freelance | G62: TRUE | H62: TRUE | I62: TRUE | J62: TRUE | K62: FALSE | L62: =COUNTIF(G62:K62,"TRUE") -> 4 | M62: =L62*4 -> 16
G63: =4*(COUNTIF(G14:G62,"true"))+9 -> 145 | H63: =4*(COUNTIF(H14:H62,"true"))+9 -> 145 | I63: =4*(COUNTIF(I14:I62,"true"))+9 -> 137 | J63: =4*(COUNTIF(J14:J62,"true"))+9 -> 149 | K63: =4*(COUNTIF(K14:K62,"true"))+6 -> 126 | M63: =SUM(G63:K63) -> 702

Sheet 30.08
D6: 30 Ağustos - 3 Eylül
D7: Ağustos 5. Hafta
D9: Dikkat ➜
F10: Fotoğrafçılar sekmesindeki üçgen tuşa basarak kendi isminizi aratıp, daha hızlı bir şekilde işlem yapabilirsiniz.
D14: Fotoğrafçılar | E14: Şehir | F14: Ekip | G14: 44438 | H14: 44439 | I14: 44440 | J14: 44441 | K14: 44442 | L14: Top. Gün | M14: Top. Hedef Randevu
D15: Furkan Berat Altunkaya | E15: =VLOOKUP(D15,Data!H:I,2,0) -> Adana | F15: Freelance | G15: TRUE | H15: TRUE | I15: TRUE | J15: TRUE | K15: TRUE | L15: =COUNTIF(G15:K15,"TRUE") -> 5 | M15: =L15*4 -> 20
D16: Furkan Berat Altunkaya 2 | E16: =VLOOKUP(D16,Data!H:I,2,0) -> Adana | F16: Freelance | G16: TRUE | H16: TRUE | I16: TRUE | J16: TRUE | K16: TRUE | L16: =COUNTIF(G16:K16,"TRUE") -> 5 | M16: =L16*4 -> 20
D17: Bedirhan Ankara | E17: =VLOOKUP(D17,Data!H:I,2,0) -> Ankara | F17: Medya Özgür Deniz | G17: FALSE | H17: TRUE | I17: FALSE | J17: TRUE | K17: FALSE | L17: =COUNTIF(G17:K17,"TRUE") -> 2 | M17: =L17*4 -> 8
D18: Furkan Ankara | E18: =VLOOKUP(D18,Data!H:I,2,0) -> Ankara | F18: Medya Özgür Deniz | G18: TRUE | H18: FALSE | I18: FALSE | J18: FALSE | K18: FALSE | L18: =COUNTIF(G18:K18,"TRUE") -> 1 | M18: =L18*4 -> 4
D19: Gizem Fukul | E19: =VLOOKUP(D19,Data!H:I,2,0) -> Ankara | F19: Medya Özgür Deniz | G19: TRUE | H19: TRUE | I19: TRUE | J19: TRUE | K19: TRUE | L19: =COUNTIF(G19:K19,"TRUE") -> 5 | M19: =L19*4 -> 20
D20: Ahmet Kasap | E20: =VLOOKUP(D20,Data!H:I,2,0) -> Ankara | F20: Medya Özgür Deniz | G20: TRUE | H20: TRUE | I20: TRUE | J20: TRUE | K20: TRUE | L20: =COUNTIF(G20:K20,"TRUE") -> 5 | M20: =L20*4 -> 20
D21: Onur Ay | E21: =VLOOKUP(D21,Data!H:I,2,0) -> Ankara | F21: Medya Özgür Deniz | G21: TRUE | H21: TRUE | I21: FALSE | J21: TRUE | K21: TRUE | L21: =COUNTIF(G21:K21,"TRUE") -> 4 | M21: =L21*4 -> 16
D22: Ergin Avcı | E22: =VLOOKUP(D22,Data!H:I,2,0) -> Antalya | F22: Nazım Öztel | G22: TRUE | H22: TRUE | I22: TRUE | J22: TRUE | K22: TRUE | L22: =COUNTIF(G22:K22,"TRUE") -> 5 | M22: =L22*4 -> 20
D23: Önder Örtel | E23: =VLOOKUP(D23,Data!H:I,2,0) -> Antalya | F23: Freelance | G23: TRUE | H23: TRUE | I23: TRUE | J23: TRUE | K23: TRUE | L23: =COUNTIF(G23:K23,"TRUE") -> 5 | M23: =L23*4 -> 20
D24: Hamdi Can Hikmet | E24: =VLOOKUP(D24,Data!H:I,2,0) -> Bursa | F24: Nazım Öztel | G24: TRUE | H24: TRUE | I24: TRUE | J24: TRUE | K24: FALSE | L24: =COUNTIF(G24:K24,"TRUE") -> 4 | M24: =L24*4 -> 16
D25: Tamay Alper Gökdemir | E25: =VLOOKUP(D25,Data!H:I,2,0) -> Bursa | F25: Freelance | G25: FALSE | H25: TRUE | I25: TRUE | J25: TRUE | K25: TRUE | L25: =COUNTIF(G25:K25,"TRUE") -> 4 | M25: =L25*4 -> 16
D26: Serhat Tarancı | E26: =VLOOKUP(D26,Data!H:I,2,0) -> Diyarbakır | F26: Nazım Öztel | G26: FALSE | H26: FALSE | I26: FALSE | J26: FALSE | K26: FALSE | L26: =COUNTIF(G26:K26,"TRUE") -> 0 | M26: =L26*4 -> 0
... D58: Gündüz Akşamoldu | E58: =VLOOKUP(D58,Data!H:I,2,0) -> İzmir | F58: Nazım Öztel | G58: TRUE | H58: TRUE | I58: TRUE | J58: TRUE | K58: TRUE | L58: =COUNTIF(G58:K58,"TRUE") -> 5 | M58: =L58*4 -> 20
D59: Buket Köken | E59: İzmir | F59: Nazım Öztel | G59: TRUE | H59: TRUE | I59: TRUE | J59: TRUE | K59: TRUE | L59: =COUNTIF(G59:K59,"TRUE") -> 5 | M59: =L59*4 -> 20
D60: Murat Megus | E60: =VLOOKUP(D60,Data!H:I,2,0) -> İzmir | F60: Freelance | G60: TRUE | H60: TRUE | I60: TRUE | J60: FALSE | K60: FALSE | L60: =COUNTIF(G60:K60,"TRUE") -> 3 | M60: =L60*4 -> 12
D61: Levent Akdeniz | E61: =VLOOKUP(D61,Data!H:I,2,0) -> Kocaeli | F61: Nazım Öztel | G61: FALSE | H61: FALSE | I61: FALSE | J61: FALSE | K61: FALSE | L61: =COUNTIF(G61:K61,"TRUE") -> 0 | M61: =L61*4 -> 0
D62: Kathade Elhalaf | E62: =VLOOKUP(D62,Data!H:I,2,0) -> Konya | F62: Nazım Öztel | G62: TRUE | H62: TRUE | I62: TRUE | J62: TRUE | K62: FALSE | L62: =COUNTIF(G62:K62,"TRUE") -> 4 | M62: =L62*4 -> 16
D63: Zeynep Zülal Örman | E63: =VLOOKUP(D63,Data!H:I,2,0) -> Manisa | F63: Nazım Öztel | G63: FALSE | H63: FALSE | I63: FALSE | J63: FALSE | K63: FALSE | L63: =COUNTIF(G63:K63,"TRUE") -> 0 | M63: =L63*4 -> 0
D64: Burçin Sezer | E64: =VLOOKUP(D64,Data!H:I,2,0) -> Mersin | F64: Nazım Öztel | G64: TRUE | H64: FALSE | I64: FALSE | J64: TRUE | K64: FALSE | L64: =COUNTIF(G64:K64,"TRUE") -> 2 | M64: =L64*4 -> 8
D65: Recep Çakır | E65: =VLOOKUP(D65,Data!H:I,2,0) -> Samsun | F65: Nazım Öztel | G65: FALSE | H65: FALSE | I65: FALSE | J65: FALSE | K65: FALSE | L65: =COUNTIF(G65:K65,"TRUE") -> 0 | M65: =L65*4 -> 0
D66: Mustafa Kemal İbiş | E66: =VLOOKUP(D66,Data!H:I,2,0) -> Tekirdağ | F66: Freelance | G66: FALSE | H66: FALSE | I66: FALSE | J66: FALSE | K66: FALSE | L66: =COUNTIF(G66:K66,"TRUE") -> 0 | M66: =L66*4 -> 0
G67: =4*(COUNTIF(G14:G66,"true")) -> 116 | H67: =4*(COUNTIF(H14:H66,"true"))+6 -> 138 | I67: =4*(COUNTIF(I14:I66,"true"))+6 -> 138 | J67: =4*(COUNTIF(J14:J66,"true"))+9 -> 145 | K67: =4*(COUNTIF(K14:K66,"true"))+9 -> 125 | M67: =SUM(M15:M66) -> 632

Sheet 06.09
D6: 6-10 Eylül
D7: Eylül 1. Hafta
D9: Dikkat ➜
F10: Fotoğrafçılar sekmesindeki üçgen tuşa basarak kendi isminizi aratıp, daha hızlı bir şekilde işlem yapabilirsiniz.
D14: Fotoğrafçılar | E14: Şehir | F14: Ekip | G14: 44445 | H14: 44446 | I14: 44447 | J14: 44448 | K14: 44449 | L14: Top. Gün | M14: Top. Hedef Randevu
D15: Furkan Berat Altunkaya | E15: =VLOOKUP(D15,Data!H:I,2,0) -> Adana | F15: =VLOOKUP(D15,Data!H:J,3,0) -> Freelance | G15: TRUE | H15: TRUE | I15: TRUE | J15: TRUE | K15: TRUE | L15: =COUNTIF(G15:K15,"TRUE") -> 5 | M15: =L15*4 -> 20
D16: Furkan Berat Altunkaya 2 | E16: =VLOOKUP(D16,Data!H:I,2,0) -> Adana | F16: =VLOOKUP(D16,Data!H:J,3,0) -> Freelance | G16: TRUE | H16: TRUE | I16: TRUE | J16: TRUE | K16: TRUE | L16: =COUNTIF(G16:K16,"TRUE") -> 5 | M16: =L16*4 -> 20
D17: Ahmet Kasap | E17: =VLOOKUP(D17,Data!H:I,2,0) -> Ankara | F17: =VLOOKUP(D17,Data!H:J,3,0) -> Medya Özgür Deniz | G17: TRUE | H17: TRUE | I17: TRUE | J17: TRUE | K17: TRUE | L17: =COUNTIF(G17:K17,"TRUE") -> 5 | M17: =L17*4 -> 20
D18: Bedirhan Ankara | E18: =VLOOKUP(D18,Data!H:I,2,0) -> Ankara | F18: =VLOOKUP(D18,Data!H:J,3,0) -> Medya Özgür Deniz | G18: FALSE | H18: TRUE | I18: FALSE | J18: TRUE | K18: FALSE | L18: =COUNTIF(G18:K18,"TRUE") -> 2 | M18: =L18*4 -> 8
D19: Furkan Ankara | E19: =VLOOKUP(D19,Data!H:I,2,0) -> Ankara | F19: =VLOOKUP(D19,Data!H:J,3,0) -> Medya Özgür Deniz | G19: FALSE | H19: FALSE | I19: FALSE | J19: FALSE | K19: TRUE | L19: =COUNTIF(G19:K19,"TRUE") -> 1 | M19: =L19*4 -> 4
D20: Gizem Fukul | E20: =VLOOKUP(D20,Data!H:I,2,0) -> Ankara | F20: =VLOOKUP(D20,Data!H:J,3,0) -> Medya Özgür Deniz | G20: TRUE | H20: TRUE | I20: TRUE | J20: TRUE | K20: FALSE | L20: =COUNTIF(G20:K20,"TRUE") -> 4 | M20: =L20*4 -> 16
D21: Onur Ay | E21: =VLOOKUP(D21,Data!H:I,2,0) -> Ankara | F21: =VLOOKUP(D21,Data!H:J,3,0) -> Medya Özgür Deniz | G21: TRUE | H21: TRUE | I21: TRUE | J21: TRUE | K21: TRUE | L21: =COUNTIF(G21:K21,"TRUE") -> 5 | M21: =L21*4 -> 20
D22: Ergin Avcı | E22: =VLOOKUP(D22,Data!H:I,2,0) -> Antalya | F22: =VLOOKUP(D22,Data!H:J,3,0) -> Nazım Öztel | G22: TRUE | H22: TRUE | I22: FALSE | J22: FALSE | K22: FALSE | L22: =COUNTIF(G22:K22,"TRUE") -> 2 | M22: =L22*4 -> 8
D23: Önder Örtel | E23: =VLOOKUP(D23,Data!H:I,2,0) -> Antalya | F23: =VLOOKUP(D23,Data!H:J,3,0) -> Freelance | G23: TRUE | H23: TRUE | I23: FALSE | J23: FALSE | K23: TRUE | L23: =COUNTIF(G23:K23,"TRUE") -> 3 | M23: =L23*4 -> 12
D24: Hamdi Can Hikmet | E24: =VLOOKUP(D24,Data!H:I,2,0) -> Bursa | F24: =VLOOKUP(D24,Data!H:J,3,0) -> Nazım Öztel | G24: TRUE | H24: TRUE | I24: FALSE | J24: TRUE | K24: FALSE | L24: =COUNTIF(G24:K24,"TRUE") -> 3 | M24: =L24*4 -> 12
D25: Tamay Alper Gökdemir | E25: =VLOOKUP(D25,Data!H:I,2,0) -> Bursa | F25: =VLOOKUP(D25,Data!H:J,3,0) -> Freelance | G25: TRUE | H25: TRUE | I25: TRUE | J25: TRUE | K25: TRUE | L25: =COUNTIF(G25:K25,"TRUE") -> 5 | M25: =L25*4 -> 20
D26: Serhat Tarancı | E26: =VLOOKUP(D26,Data!H:I,2,0) -> Diyarbakır | F26: =VLOOKUP(D26,Data!H:J,3,0) -> Nazım Öztel | G26: FALSE | H26: FALSE | I26: FALSE | J26: FALSE | K26: FALSE | L26: =COUNTIF(G26:K26,"TRUE") -> 0 | M26: =L26*4 -> 0
... D58: Gündüz Akşamoldu | E58: =VLOOKUP(D58,Data!H:I,2,0) -> İzmir | F58: =VLOOKUP(D58,Data!H:J,3,0) -> Nazım Öztel | G58: TRUE | H58: TRUE | I58: TRUE | J58: TRUE | K58: TRUE | L58: =COUNTIF(G58:K58,"TRUE") -> 5 | M58: =L58*4 -> 20
D59: Buket Köken | E59: İzmir | F59: =VLOOKUP(D59,Data!H:J,3,0) -> Nazım Öztel | G59: TRUE | H59: FALSE | I59: TRUE | J59: TRUE | K59: TRUE | L59: =COUNTIF(G59:K59,"TRUE") -> 4 | M59: =L59*4 -> 16
D60: Murat Megus | E60: =VLOOKUP(D60,Data!H:I,2,0) -> İzmir | F60: =VLOOKUP(D60,Data!H:J,3,0) -> Freelance | G60: TRUE | H60: TRUE | I60: TRUE | J60: TRUE | K60: FALSE | L60: =COUNTIF(G60:K60,"TRUE") -> 4 | M60: =L60*4 -> 16
D61: Levent Akdeniz | E61: =VLOOKUP(D61,Data!H:I,2,0) -> Kocaeli | F61: =VLOOKUP(D61,Data!H:J,3,0) -> Nazım Öztel | G61: FALSE | H61: FALSE | I61: TRUE | J61: FALSE | K61: TRUE | L61: =COUNTIF(G61:K61,"TRUE") -> 2 | M61: =L61*4 -> 8
D62: Kathade Elhalaf | E62: =VLOOKUP(D62,Data!H:I,2,0) -> Konya | F62: =VLOOKUP(D62,Data!H:J,3,0) -> Nazım Öztel | G62: FALSE | H62: FALSE | I62: FALSE | J62: TRUE | K62: FALSE | L62: =COUNTIF(G62:K62,"TRUE") -> 1 | M62: =L62*4 -> 4
D63: Zeynep Zülal Örman | E63: =VLOOKUP(D63,Data!H:I,2,0) -> Manisa | F63: =VLOOKUP(D63,Data!H:J,3,0) -> Nazım Öztel | G63: FALSE | H63: FALSE | I63: FALSE | J63: FALSE | K63: FALSE | L63: =COUNTIF(G63:K63,"TRUE") -> 0 | M63: =L63*4 -> 0
D64: Burçin Sezer | E64: =VLOOKUP(D64,Data!H:I,2,0) -> Mersin | F64: =VLOOKUP(D64,Data!H:J,3,0) -> Nazım Öztel | G64: TRUE | H64: FALSE | I64: FALSE | J64: TRUE | K64: FALSE | L64: =COUNTIF(G64:K64,"TRUE") -> 2 | M64: =L64*4 -> 8
D65: Recep Çakır | E65: =VLOOKUP(D65,Data!H:I,2,0) -> Samsun | F65: =VLOOKUP(D65,Data!H:J,3,0) -> Nazım Öztel | G65: FALSE | H65: FALSE | I65: FALSE | J65: FALSE | K65: FALSE | L65: =COUNTIF(G65:K65,"TRUE") -> 0 | M65: =L65*4 -> 0
D66: Mustafa Kemal İbiş | E66: =VLOOKUP(D66,Data!H:I,2,0) -> Tekirdağ | F66: =VLOOKUP(D66,Data!H:J,3,0) -> Freelance | G66: FALSE | H66: FALSE | I66: FALSE | J66: FALSE | K66: FALSE | L66: =COUNTIF(G66:K66,"TRUE") -> 0 | M66: =L66*4 -> 0
G67: =4*(COUNTIF(G14:G66,"true"))+9 -> 129 | H67: =4*(COUNTIF(H14:H66,"true"))+9 -> 133 | I67: =4*(COUNTIF(I14:I66,"true"))+6 -> 114 | J67: =4*(COUNTIF(J14:J66,"true"))+9 -> 133 | K67: =4*(COUNTIF(K14:K66,"true"))+6 -> 102 | M67: =SUM(G67:K67) -> 611

Sheet 13.09
D6: 13-17 Eylül
D7: Eylül 2. Hafta
D9: Dikkat ➜
F10: Fotoğrafçılar sekmesindeki üçgen tuşa basarak kendi isminizi aratıp, daha hızlı bir şekilde işlem yapabilirsiniz.
D14: Fotoğrafçılar | E14: Şehir | F14: Ekip | G14: 44452 | H14: 44453 | I14: 44454 | J14: 44455 | K14: 44456 | L14: Top. Gün | M14: Top. Hedef Randevu
D15: Furkan Berat Altunkaya | E15: =VLOOKUP(D15,Data!H:I,2,0) -> Adana | F15: =VLOOKUP(D15,Data!H:J,3,0) -> Freelance | G15: TRUE | H15: TRUE | I15: TRUE | J15: TRUE | K15: TRUE | L15: =COUNTIF(G15:K15,"TRUE") -> 5 | M15: =L15*4 -> 20
D16: Furkan Berat Altunkaya 2 | E16: =VLOOKUP(D16,Data!H:I,2,0) -> Adana | F16: =VLOOKUP(D16,Data!H:J,3,0) -> Freelance | G16: TRUE | H16: TRUE | I16: TRUE | J16: TRUE | K16: TRUE | L16: =COUNTIF(G16:K16,"TRUE") -> 5 | M16: =L16*4 -> 20
D17: Ahmet Kasap | E17: =VLOOKUP(D17,Data!H:I,2,0) -> Ankara | F17: =VLOOKUP(D17,Data!H:J,3,0) -> Medya Özgür Deniz | G17: TRUE | H17: TRUE | I17: TRUE | J17: TRUE | K17: FALSE | L17: =COUNTIF(G17:K17,"TRUE") -> 4 | M17: =L17*4 -> 16
D18: Bedirhan Ankara | E18: =VLOOKUP(D18,Data!H:I,2,0) -> Ankara | F18: =VLOOKUP(D18,Data!H:J,3,0) -> Medya Özgür Deniz | G18: FALSE | H18: TRUE | I18: FALSE | J18: TRUE | K18: FALSE | L18: =COUNTIF(G18:K18,"TRUE") -> 2 | M18: =L18*4 -> 8
D19: Furkan Ankara | E19: =VLOOKUP(D19,Data!H:I,2,0) -> Ankara | F19: =VLOOKUP(D19,Data!H:J,3,0) -> Medya Özgür Deniz | G19: FALSE | H19: FALSE | I19: FALSE | J19: FALSE | K19: TRUE | L19: =COUNTIF(G19:K19,"TRUE") -> 1 | M19: =L19*4 -> 4
D20: Gizem Fukul | E20: =VLOOKUP(D20,Data!H:I,2,0) -> Ankara | F20: =VLOOKUP(D20,Data!H:J,3,0) -> Medya Özgür Deniz | G20: TRUE | H20: TRUE | I20: TRUE | J20: TRUE | K20: TRUE | L20: =COUNTIF(G20:K20,"TRUE") -> 5 | M20: =L20*4 -> 20
D21: Onur Ay | E21: =VLOOKUP(D21,Data!H:I,2,0) -> Ankara | F21: =VLOOKUP(D21,Data!H:J,3,0) -> Medya Özgür Deniz | G21: TRUE | H21: TRUE | I21: TRUE | J21: TRUE | K21: TRUE | L21: =COUNTIF(G21:K21,"TRUE") -> 5 | M21: =L21*4 -> 20
D22: Önder Örtel | E22: =VLOOKUP(D22,Data!H:I,2,0) -> Antalya | F22: =VLOOKUP(D22,Data!H:J,3,0) -> Freelance | G22: TRUE | H22: TRUE | I22: TRUE | J22: TRUE | K22: TRUE | L22: =COUNTIF(G22:K22,"TRUE") -> 5 | M22: =L22*4 -> 20
D23: İlke Aktaş | E23: =VLOOKUP(D23,Data!H:I,2,0) -> Balıkesir | F23: =VLOOKUP(D23,Data!H:J,3,0) -> Nazım Öztel | G23: FALSE | H23: FALSE | I23: TRUE | J23: TRUE | K23: FALSE | L23: =COUNTIF(G23:K23,"TRUE") -> 2 | M23: =L23*4 -> 8
D24: Hamdi Can Hikmet | E24: =VLOOKUP(D24,Data!H:I,2,0) -> Bursa | F24: =VLOOKUP(D24,Data!H:J,3,0) -> Nazım Öztel | G24: TRUE | H24: TRUE | I24: TRUE | J24: TRUE | K24: TRUE | L24: =COUNTIF(G24:K24,"TRUE") -> 5 | M24: =L24*4 -> 20
D25: Tamay Alper Gökdemir | E25: =VLOOKUP(D25,Data!H:I,2,0) -> Bursa | F25: =VLOOKUP(D25,Data!H:J,3,0) -> Freelance | G25: TRUE | H25: TRUE | I25: TRUE | J25: TRUE | K25: TRUE | L25: =COUNTIF(G25:K25,"TRUE") -> 5 | M25: =L25*4 -> 20
D26: Serhat Tarancı | E26: =VLOOKUP(D26,Data!H:I,2,0) -> Diyarbakır | F26: =VLOOKUP(D26,Data!H:J,3,0) -> Nazım Öztel | G26: FALSE | H26: FALSE | I26: FALSE | J26: FALSE | K26: FALSE | L26: =COUNTIF(G26:K26,"TRUE") -> 0 | M26: =L26*4 -> 0
... D56: Gündüz Akşamoldu | E56: =VLOOKUP(D56,Data!H:I,2,0) -> İzmir | F56: =VLOOKUP(D56,Data!H:J,3,0) -> Nazım Öztel | G56: TRUE | H56: TRUE | I56: TRUE | J56: TRUE | K56: TRUE | L56: =COUNTIF(G56:K56,"TRUE") -> 5 | M56: =L56*4 -> 20
D57: Buket Köken | E57: İzmir | F57: =VLOOKUP(D57,Data!H:J,3,0) -> Nazım Öztel | G57: TRUE | H57: TRUE | I57: TRUE | J57: FALSE | K57: TRUE | L57: =COUNTIF(G57:K57,"TRUE") -> 4 | M57: =L57*4 -> 16
D58: Murat Megus | E58: =VLOOKUP(D58,Data!H:I,2,0) -> İzmir | F58: =VLOOKUP(D58,Data!H:J,3,0) -> Freelance | G58: FALSE | H58: FALSE | I58: FALSE | J58: FALSE | K58: FALSE | L58: =COUNTIF(G58:K58,"TRUE") -> 0 | M58: =L58*4 -> 0
D59: Levent Akdeniz | E59: =VLOOKUP(D59,Data!H:I,2,0) -> Kocaeli | F59: =VLOOKUP(D59,Data!H:J,3,0) -> Nazım Öztel | G59: TRUE | H59: FALSE | I59: FALSE | J59: FALSE | K59: FALSE | L59: =COUNTIF(G59:K59,"TRUE") -> 1 | M59: =L59*4 -> 4
D60: Rümeysa Kekeç | E60: =VLOOKUP(D60,Data!H:I,2,0) -> Kocaeli | F60: =VLOOKUP(D60,Data!H:J,3,0) -> Nazım Öztel | G60: TRUE | H60: TRUE | I60: FALSE | J60: FALSE | K60: FALSE | L60: =COUNTIF(G60:K60,"TRUE") -> 2 | M60: =L60*4 -> 8
D61: Kathade Elhalaf | E61: =VLOOKUP(D61,Data!H:I,2,0) -> Konya | F61: =VLOOKUP(D61,Data!H:J,3,0) -> Nazım Öztel | G61: FALSE | H61: FALSE | I61: FALSE | J61: FALSE | K61: FALSE | L61: =COUNTIF(G61:K61,"TRUE") -> 0 | M61: =L61*4 -> 0
D62: Zeynep Zülal Örman | E62: =VLOOKUP(D62,Data!H:I,2,0) -> Manisa | F62: =VLOOKUP(D62,Data!H:J,3,0) -> Nazım Öztel | G62: FALSE | H62: FALSE | I62: FALSE | J62: TRUE | K62: FALSE | L62: =COUNTIF(G62:K62,"TRUE") -> 1 | M62: =L62*4 -> 4
D63: Burçin Sezer | E63: =VLOOKUP(D63,Data!H:I,2,0) -> Mersin | F63: =VLOOKUP(D63,Data!H:J,3,0) -> Nazım Öztel | G63: TRUE | H63: FALSE | I63: FALSE | J63: TRUE | K63: FALSE | L63: =COUNTIF(G63:K63,"TRUE") -> 2 | M63: =L63*4 -> 8
D64: Serkan Özdalgıç | E64: =VLOOKUP(D64,Data!H:I,2,0) -> Muğla | F64: =VLOOKUP(D64,Data!H:J,3,0) -> Nazım Öztel | G64: FALSE | H64: FALSE | I64: TRUE | J64: FALSE | K64: FALSE | L64: =COUNTIF(G64:K64,"TRUE") -> 1 | M64: =L64*4 -> 4
D65: Mustafa Kemal İbiş | E65: =VLOOKUP(D65,Data!H:I,2,0) -> Tekirdağ | F65: =VLOOKUP(D65,Data!H:J,3,0) -> Freelance | G65: TRUE | H65: TRUE | I65: TRUE | J65: TRUE | K65: TRUE | L65: =COUNTIF(G65:K65,"TRUE") -> 5 | M65: =L65*4 -> 20
G66: =4*(COUNTIF(G14:G65,"true"))+6 -> 118 | H66: =4*(COUNTIF(H14:H65,"true"))+9 -> 129 | I66: =4*(COUNTIF(I14:I65,"true"))+3 -> 119 | J66: =4*(COUNTIF(J14:J65,"true"))+3 -> 123 | K66: =4*(COUNTIF(K14:K65,"true"))+9 -> 109 | M66: =SUM(G66:K66) -> 598

Sheet 20.09
D6: 20-24 Eylül
D7: Eylül 3. Hafta
D9: Dikkat ➜
F10: Fotoğrafçılar sekmesindeki üçgen tuşa basarak kendi isminizi aratıp, daha hızlı bir şekilde işlem yapabilirsiniz.
D14: Fotoğrafçılar | E14: Şehir | F14: Ekip | G14: 44459 | H14: 44460 | I14: 44461 | J14: 44462 | K14: 44463 | L14: Top. Gün | M14: Top. Hedef Randevu
D15: Furkan Berat Altunkaya | E15: =VLOOKUP(D15,Data!H:I,2,0) -> Adana | F15: =VLOOKUP(D15,Data!H:J,3,0) -> Freelance | G15: TRUE | H15: TRUE | I15: TRUE | J15: TRUE | K15: TRUE | L15: =COUNTIF(G15:K15,"TRUE") -> 5 | M15: =L15*4 -> 20
