Workbook

Sheet Hedef Liste
A1: Restaurant ID | B1: Restoran Adı | C1: Satışa Açık Mı? | D1: Mutfak | E1: TOPLAM SİPARİŞ | F1: SON 2 HAFTA | G1: RESİMLİ ÜRÜN | H1: RESİMSİZ ÜRÜN | I1: TOPLAM ÜRÜN | J1: Ratio | K1: Yetkili | L1: Telefon | M1: İLÇE | N1: MAHALLE | O1: ADRES | P1: Geleneksel Zincir | Q1: FOTOĞRAF SEGMENT | R1: Aradık Mı? | S1: Kendi Fotosu Var | T1: Randevu Durumu | U1: Randevu Alan | V1: Fotoğrafçı | W1: Not | X1: Randevu Alma Tarihi | Y1: Randevu Tarihi | Z1: Anket Durum | AA1: 1. Arama | AB1: 1. Arama Tarihi | AC1: 2. Arama | AD1: 2. Arama Tarihi | AE1: 3. Arama | AF1: 3. Arama Tarihi | AG1: 4. Arama | AH1: 4. Arama Tarihi | AI1: 5. Arama | AJ1: 5. Arama Tarihi | AK1: 1. Arayan | AL1: 2. Arayan | AM1: 3. Arayan | AN1: 4. Arayan | AO1: 5. Arayan | AP1: SY | AQ1: SY - Durum
A2: 5ff2f522e5886ade7f95c664 | B2: @'li Burger, Melikgazi (Fatih Mah.-İldem) | C2: =VLOOKUP(A2,import!A:C,3,0) -> DOĞRU | D2: Burger | E2: =VLOOKUP(A2,import!A:J,5,0) -> 1899 | F2: =VLOOKUP(A2,import!A:J,6,0) -> 25 | G2: =VLOOKUP(A2,import!A:J,7,0) -> 21 | H2: =VLOOKUP(A2,import!A:J,8,0) -> 22 | I2: =VLOOKUP(A2,import!A:J,9,0) -> 43 | J2: =VLOOKUP(A2,import!A:J,10,0) -> 0.49 | K2: Ahmet Tiryakioğlu | L2: 3522473838 | M2: Melikgazi | N2: Gesi Fatih | O2: İldem Fatih Mah. Günsazak Cad. No:65/109 Melikgazi/KAYSERİ | P2: =VLOOKUP(A2,import!A:P,16,0) -> Geleneksel | R2: TRUE | S2: FALSE | T2: Franchise | V2: 10 dk sonra// açmadı | W2: merkeze bağlı olduklarını belirtti | AA2: Ulaşılamadı | AB2: 44358 | AC2: Görüşüldü | AD2: 44365 | AK2: Hatice Özer | AL2: Hatice Özer | AP2: Mustafa Dursun
A3: 60476b283ca27400207fbf26 | B3: 1991 Tarihi Ortaköy Kumpircisi, Talas (Mevlana Mah.) | C3: =VLOOKUP(A3,import!A:C,3,0) -> YANLIŞ | D3: Sokak Lezzetleri | E3: =VLOOKUP(A3,import!A:J,5,0) -> 919 | F3: =VLOOKUP(A3,import!A:J,6,0) | G3: =VLOOKUP(A3,import!A:J,7,0) -> 0 | H3: =VLOOKUP(A3,import!A:J,8,0) -> 11 | I3: =VLOOKUP(A3,import!A:J,9,0) -> 11 | J3: =VLOOKUP(A3,import!A:J,10,0) -> 0 | K3: Muammer Efe Bayrakdar | L3: 3525045202 | M3: Talas | N3: Mevlana | O3: Mevlana Mah. Bilge Kağan Cad. No:40, 38280 Talas/Kayseri | P3: =VLOOKUP(A3,import!A:P,16,0) -> Geleneksel | R3: TRUE | S3: FALSE | T3: Dönüş Yapacak | W3: açmadılar//açmadılar/ulaşılamıyor// malzemeleri henüz tam değil 3 ürünü var elinde tamamlayınca geri dönüş yapacak / meşgul çalıyor | AA3: Dönüş Yapacak | AB3: 44369 | AC3: Ulaşılamadı | AD3: 44608 | AK3: Hatice Özer | AL3: Enes Günal | AP3: Mustafa Dursun
A4: 609523a9cdfc10ad229f0016 | B4: Abadan Cafe & Restaurant & Baklava, Kocasinan (Yeşil Mah.) | C4: =VLOOKUP(A4,import!A:C,3,0) -> DOĞRU | D4: Pasta & Tatlı | E4: =VLOOKUP(A4,import!A:J,5,0) -> 57 | F4: =VLOOKUP(A4,import!A:J,6,0) -> 3 | G4: =VLOOKUP(A4,import!A:J,7,0) -> 5 | H4: =VLOOKUP(A4,import!A:J,8,0) -> 3 | I4: =VLOOKUP(A4,import!A:J,9,0) -> 8 | J4: =VLOOKUP(A4,import!A:J,10,0) -> 0.63 | K4: Muhammed Mustafa Duman | L4: 3523395958 | M4: Kocasinan | N4: Yeşil | O4: Yeşil Mah. Erkilet Blv. No:182 Kocasinan/KAYSERİ | P4: =VLOOKUP(A4,import!A:P,16,0) -> Geleneksel | R4: TRUE | S4: FALSE | T4: Randevu Alındı | U4: Ferhat Köksal | V4: Muzaffer Köprü | W4: 12.30 gibi ararsanız eğer sizlere çok yardımcı olurum dedi//6-6,5 gibi ara dedi/1 saat sonra aranılcsk | X4: 44627 | Y4: 44627 | AA4: Görüşüldü | AB4: 44349 | AC4: Tekrar Aranacak | AD4: 44378 | AE4: Ulaşılamadı | AF4: 44590 | AG4: Görüşüldü | AH4: 44627 | AK4: Simge Tüçay | AL4: Simge Tüçay | AM4: Selcan Topçu | AN4: Ferhat Köksal | AP4: Mustafa Dursun
A5: 5fdc980a677179fbcebca723 | B5: Abamın Yeri, Talas (Mevlana Mah.) | C5: =VLOOKUP(A5,import!A:C,3,0) -> DOĞRU | D5: Tost & Sandviç | E5: =VLOOKUP(A5,import!A:J,5,0) -> 1296 | F5: =VLOOKUP(A5,import!A:J,6,0) -> 1 | G5: =VLOOKUP(A5,import!A:J,7,0) -> 0 | H5: =VLOOKUP(A5,import!A:J,8,0) -> 17 | I5: =VLOOKUP(A5,import!A:J,9,0) -> 17 | J5: =VLOOKUP(A5,import!A:J,10,0) -> 0 | K5: Hatice Dirik | L5: 5370444907 | M5: Talas | N5: Mevlana | O5: Mevlana Mah., Papatya Cad., No:44/C Talas/Kayseri | P5: =VLOOKUP(A5,import!A:P,16,0) -> Geleneksel | R5: TRUE | S5: FALSE | T5: Randevu Alındı | U5: Zeliha Özer | W5: meşgule attı//yüzüme kapattı/açmadılar//aömadılar\ramazandan sonra aranacak//11 haziranda randevu oluşacak | AA5: Görüşüldü | AB5: 44349 | AC5: Ulaşılamadı | AD5: 44361 | AE5: Görüşüldü | AF5: 44579 | AK5: Simge Tüçay | AL5: Eylem Ünal | AM5: Zeliha Özer | AP5: Mustafa Dursun
A6: 5fd2434c74b885204e058ea7 | B6: Aboww Pizza Talas (Mevlana Mah.) | C6: =VLOOKUP(A6,import!A:C,3,0) -> DOĞRU | D6: Pizza | E6: =VLOOKUP(A6,import!A:J,5,0) -> 3685 | F6: =VLOOKUP(A6,import!A:J,6,0) -> 85 | G6: =VLOOKUP(A6,import!A:J,7,0) -> 15 | H6: =VLOOKUP(A6,import!A:J,8,0) -> 41 | I6: =VLOOKUP(A6,import!A:J,9,0) -> 56 | J6: =VLOOKUP(A6,import!A:J,10,0) -> 0.27 | K6: Yaşar Üsten | L6: 3525037727 | M6: Talas | N6: Mevlana | O6: Mevlana, 6078. Sokak, 38250 Talas/Kayseri | P6: =VLOOKUP(A6,import!A:P,16,0) -> Geleneksel | R6: TRUE | S6: FALSE | T6: Randevu İptal | U6: Hatem Soyaslan | V6: Feyza Yıldırım | W6: açmadı/açmadılar/açmadılar\\açmıyor//ÜSTEKİYLE AYNI YETKİLİ | X6: 44349 | Y6: 44351 | AA6: Görüşüldü | AB6: 44349 | AK6: Simge Tüçay | AP6: Mustafa Dursun
A7: 61e903e12f86de2d69cd7435 | B7: Acıyaman Çiğ Köfte, Kocasinan (Sahabiye Mah.) | C7: =VLOOKUP(A7,import!A:C,3,0) -> DOĞRU | D7: Çiğ Köfte | E7: =VLOOKUP(A7,import!A:J,5,0) -> 85 | F7: =VLOOKUP(A7,import!A:J,6,0) -> 10 | G7: =VLOOKUP(A7,import!A:J,7,0) -> 11 | H7: =VLOOKUP(A7,import!A:J,8,0) -> 1 | I7: =VLOOKUP(A7,import!A:J,9,0) -> 12 | J7: =VLOOKUP(A7,import!A:J,10,0) -> 0.92 | K7: Abdulmenaf Mendi | L7: 3522311583 | M7: Kocasinan | N7: Serçeönü | O7: Sahabiye Mah. Çankaya Cad. No:9/E Kocasinan/KAYSERİ | P7: =VLOOKUP(A7,import!A:P,16,0) -> Geleneksel | R7: TRUE | S7: FALSE | T7: Randevu Alındı | U7: Selcan Topçu | W7: 5352764060 | X7: 44609 | Y7: 44610 | AA7: Görüşüldü | AB7: 44609 | AK7: Selcan Topçu
A8: 60e4210f3dc05857257bd751 | B8: Acıyaman Çiğ Köfte, Melikgazi (Bahçelievler Mah.) | C8: =VLOOKUP(A8,import!A:C,3,0) -> DOĞRU | D8: Çiğ Köfte | E8: =VLOOKUP(A8,import!A:J,5,0) -> 88 | F8: =VLOOKUP(A8,import!A:J,6,0) -> 1 | G8: =VLOOKUP(A8,import!A:J,7,0) -> 4 | H8: =VLOOKUP(A8,import!A:J,8,0) -> 10 | I8: =VLOOKUP(A8,import!A:J,9,0) -> 14 | J8: =VLOOKUP(A8,import!A:J,10,0) -> 0.29 | K8: Serdar Burak Karaca | L8: 5431064121 | M8: Melikgazi | N8: Bahçelievler | O8: Bahçelievler Mah. Kocasinan 2. Cad. No:13/D Melikgazi/KAYSERİ | P8: =VLOOKUP(A8,import!A:P,16,0) -> Geleneksel | R8: TRUE | S8: FALSE | T8: Randevu Alındı | U8: Ferhat Köksal | V8: Muzaffer Köprü | W8: fotoğrafçı işten çıktığı için iptal oldu | X8: 44603 | Y8: 44606 | AA8: Görüşüldü | AB8: 44480 | AC8: Görüşüldü | AD8: 44522 | AE8: Görüşüldü | AF8: 44588 | AG8: Görüşüldü | AH8: 44603 | AK8: Selcan Topçu | AL8: Hatem Soyaslan | AM8: Betül Demir | AN8: Ferhat Köksal | AP8: Mustafa Dursun
A9: 61b8d603e492d21fa9d22c12 | B9: Acıyaman Çiğ Köfte, Melikgazi (Fatih Mah.-İldem - 2354. Sok.) | C9: =VLOOKUP(A9,import!A:C,3,0) -> YANLIŞ | D9: Çiğ Köfte | E9: =VLOOKUP(A9,import!A:J,5,0) -> 2 | F9: =VLOOKUP(A9,import!A:J,6,0) | G9: =VLOOKUP(A9,import!A:J,7,0) -> 0 | H9: =VLOOKUP(A9,import!A:J,8,0) -> 9 | I9: =VLOOKUP(A9,import!A:J,9,0) -> 9 | J9: =VLOOKUP(A9,import!A:J,10,0) -> 0 | K9: Mehmet Eldaş | L9: 5399793981 | M9: Melikgazi | N9: Gesi Fatih | O9: Gesi Fatih Mah. 2354. Sok. No:10/C Melikgazi/KAYSERİ | P9: =VLOOKUP(A9,import!A:P,16,0) -> Geleneksel | R9: TRUE | S9: FALSE | T9: Restoran Silindi | W9: restorantı kapatmışlar | AA9: Görüşüldü | AB9: 44588 | AK9: Betül Demir
A10: 61bc76b2cfa49e2f7163db46 | B10: Acıyaman Çiğ Köfte, Melikgazi (Fatih Mah.-İldem) | C10: =VLOOKUP(A10,import!A:C,3,0) -> DOĞRU | D10: Çiğ Köfte | E10: =VLOOKUP(A10,import!A:J,5,0) -> 140 | F10: =VLOOKUP(A10,import!A:J,6,0) -> 32 | G10: =VLOOKUP(A10,import!A:J,7,0) -> 9 | H10: =VLOOKUP(A10,import!A:J,8,0) -> 2 | I10: =VLOOKUP(A10,import!A:J,9,0) -> 11 | J10: =VLOOKUP(A10,import!A:J,10,0) -> 0.82 | K10: Turgut Aras | L10: 5465063838 | M10: Melikgazi | N10: Gesi Fatih | O10: Gesi Fatih Mah. Uygar Sok. No:26/B Melikgazi/KAYSERİ | P10: =VLOOKUP(A10,import!A:P,16,0) -> Geleneksel | R10: TRUE | S10: FALSE | T10: Randevu Alındı | U10: Betül Demir | V10: Hacı Baba Lale | X10: 44571 | Y10: 44572 | AA10: Görüşüldü | AB10: 44571 | AK10: Betül Demir
A11: 620bd78cdf3d594c19d20b28 | B11: Acıyaman Çiğ Köfte, Melikgazi (Kılıçaslan Mah.) | C11: =VLOOKUP(A11,import!A:C,3,0) -> DOĞRU | D11: Çiğ Köfte | E11: =VLOOKUP(A11,import!A:J,5,0) -> 67 | F11: =VLOOKUP(A11,import!A:J,6,0) -> 5 | G11: =VLOOKUP(A11,import!A:J,7,0) -> 4 | H11: =VLOOKUP(A11,import!A:J,8,0) -> 11 | I11: =VLOOKUP(A11,import!A:J,9,0) -> 15 | J11: =VLOOKUP(A11,import!A:J,10,0) -> 0.27 | K11: Ertuğrulhan Öztürkoğlu | L11: 3522350515 | M11: Melikgazi | N11: Kılıçaslan | O11: Kılıçaslan Mah. Sivas Blv. No:62/F Melikgazi/KAYSERİ | P11: =VLOOKUP(A11,import!A:P,16,0) -> Geleneksel | R11: TRUE | S11: FALSE | T11: Randevu Alındı | U11: Betül Demir | V11: Muzaffer Köprü | X11: 44614 | Y11: 44615 | AA11: Görüşüldü | AB11: 44614 | AC11: Görüşüldü | AD11: 44631 | AK11: Betül Demir | AL11: Yurdagül Kulaksız
A12: 6130c94e1e3f4b837f22a193 | B12: Acıyaman Çiğ Köfte, Melikgazi (Köşk Mah.) | C12: =VLOOKUP(A12,import!A:C,3,0) -> DOĞRU | D12: Çiğ Köfte | E12: =VLOOKUP(A12,import!A:J,5,0) -> 5 | F12: =VLOOKUP(A12,import!A:J,6,0) | G12: =VLOOKUP(A12,import!A:J,7,0) -> 0 | H12: =VLOOKUP(A12,import!A:J,8,0) -> 7 | I12: =VLOOKUP(A12,import!A:J,9,0) -> 7 | J12: =VLOOKUP(A12,import!A:J,10,0) -> 0 | K12: Barış Arslan | L12: 5076881502 | M12: Melikgazi | N12: Köşk | O12: Köşk Mah. Çakır Sok. No:9/B Melikgazi/KAYSERİ | P12: =VLOOKUP(A12,import!A:P,16,0) -> Geleneksel | R12: TRUE | S12: FALSE | T12: İleride Randevu Alınacak | W12: daha sonra arancak / babası ameliyat olmuş daha sonra aranabilir / babası vefat etmiş daha sonra görüşelim dedi | AA12: Görüşüldü | AB12: 44587 | AC12: Görüşüldü | AD12: 44599 | AE12: Görüşüldü | AF12: 44614 | AK12: Zeliha Özer | AL12: Betül Demir | AM12: Betül Demir | AP12: Mustafa Dursun
A13: 6110430691aca476a6279eb4 | B13: Acıyaman Çiğ Köfte, Melikgazi (Yeşilyurt Mah.-İldem) | C13: =VLOOKUP(A13,import!A:C,3,0) -> YANLIŞ | D13: Çiğ Köfte | E13: =VLOOKUP(A13,import!A:J,5,0) -> 296 | F13: =VLOOKUP(A13,import!A:J,6,0) | G13: =VLOOKUP(A13,import!A:J,7,0) -> 6 | H13: =VLOOKUP(A13,import!A:J,8,0) -> 3 | I13: =VLOOKUP(A13,import!A:J,9,0) -> 9 | J13: =VLOOKUP(A13,import!A:J,10,0) -> 0.67 | K13: MELİKE ŞULE ÖZMEN | L13: 5526300238 | M13: Melikgazi | N13: Yeşilyurt | O13: Yeşilyurt Mah.2776. Sok. A-Blok D25 Apt. No:47/B Melikgazi/KAYSERİ | P13: =VLOOKUP(A13,import!A:P,16,0) -> Geleneksel | R13: TRUE | S13: FALSE | T13: Randevu Alındı | U13: Sude Alkan | V13: Muzaffer Köprü | W13: perihan | X13: 44588 | Y13: 44589 | AA13: Görüşüldü | AB13: 44588 | AK13: Sude Alkan | AP13: Mustafa Dursun
A14: 61a8d5d02c33a9fb4f2e0b8e | B14: Acıyaman Çiğ Köfte, Melikgazi (Yeşilyurt Mah.-İldem) | C14: =VLOOKUP(A14,import!A:C,3,0) -> DOĞRU | D14: Çiğ Köfte | E14: =VLOOKUP(A14,import!A:J,5,0) -> 426 | F14: =VLOOKUP(A14,import!A:J,6,0) -> 22 | G14: =VLOOKUP(A14,import!A:J,7,0) -> 0 | H14: =VLOOKUP(A14,import!A:J,8,0) -> 10 | I14: =VLOOKUP(A14,import!A:J,9,0) -> 10 | J14: =VLOOKUP(A14,import!A:J,10,0) -> 0 | K14: Rukiye Yılmaz | L14: 5526300238 | M14: Melikgazi | N14: Yeşilyurt | O14: Yeşilyurt Mah. 2776. Sok. No:47/B Melikgazi/KAYSERİ | P14: =VLOOKUP(A14,import!A:P,16,0) -> Geleneksel | R14: TRUE | S14: FALSE | T14: Başka Şubeden Çekilecek | AP14: Mustafa Dursun
A15: 61e14231e2b19c723200d4aa | B15: Acıyaman Çiğ Köfte, Talas (Mevlana Mah.) | C15: =VLOOKUP(A15,import!A:C,3,0) -> DOĞRU | D15: Çiğ Köfte | E15: =VLOOKUP(A15,import!A:J,5,0) -> 10 | F15: =VLOOKUP(A15,import!A:J,6,0) -> 6 | G15: =VLOOKUP(A15,import!A:J,7,0) -> 0 | H15: =VLOOKUP(A15,import!A:J,8,0) -> 13 | I15: =VLOOKUP(A15,import!A:J,9,0) -> 13 | J15: =VLOOKUP(A15,import!A:J,10,0) -> 0 | K15: Özgür Bektaş | L15: 5345604096 | M15: Talas | N15: Mevlana | O15: Mevlana Mah. Halef Hoca Cad. No:70/D Talas/KAYSERİ | P15: =VLOOKUP(A15,import!A:P,16,0) -> Geleneksel | R15: TRUE | S15: FALSE | T15: Sistemden Çıkmak İstiyor | W15: sistemden çıkmak istediğini belirtti | AA15: Görüşüldü | AB15: 44594 | AK15: Zeliha Özer
A16: 61f8203ce7f2725c65d56b31 | B16: Acıyaman Çiğköfte, Melikgazi (Yeniköy Mah.) | C16: =VLOOKUP(A16,import!A:C,3,0) -> DOĞRU | D16: Çiğ Köfte | E16: =VLOOKUP(A16,import!A:J,5,0) -> 11 | F16: =VLOOKUP(A16,import!A:J,6,0) -> 1 | G16: =VLOOKUP(A16,import!A:J,7,0) -> 11 | H16: =VLOOKUP(A16,import!A:J,8,0) -> 21 | I16: =VLOOKUP(A16,import!A:J,9,0) -> 32 | J16: =VLOOKUP(A16,import!A:J,10,0) -> 0.34 | K16: Hülya Bayram | L16: 5312730594 | M16: Melikgazi | N16: Yeniköy | O16: Yeniköy Mah. Bülbül Cad. No:8/A Melikgazi/KAYSERİ | P16: =VLOOKUP(A16,import!A:P,16,0) -> Geleneksel | R16: TRUE | S16: FALSE | T16: Randevu Alındı | U16: Ferhat Köksal | V16: Muzaffer Köprü | X16: 44606 | Y16: 44606 | AA16: Görüşüldü | AB16: 44606 | AK16: Ferhat Köksal
A17: 5fdb9cf9521daf8d68679514 | B17: Acil Pizza Pide Lahmacun, Talas (Tablakaya Mah.) | C17: =VLOOKUP(A17,import!A:C,3,0) -> YANLIŞ | D17: Pizza | E17: =VLOOKUP(A17,import!A:J,5,0) -> 252 | F17: =VLOOKUP(A17,import!A:J,6,0) | G17: =VLOOKUP(A17,import!A:J,7,0) -> 0 | H17: =VLOOKUP(A17,import!A:J,8,0) -> 19 | I17: =VLOOKUP(A17,import!A:J,9,0) -> 19 | J17: =VLOOKUP(A17,import!A:J,10,0) -> 0 | K17: Mustafa Okan Demirci | L17: 3524378971 | M17: Talas | N17: Tablakaya | O17: Tablakaya mh talas kayseri | P17: =VLOOKUP(A17,import!A:P,16,0) -> Geleneksel | R17: TRUE | S17: FALSE | W17: açmadı/düşünmüyolarmış | AP17: Mustafa Dursun
A18: 6166e31190a1b0c4cdd796d7 | B18: Aç Geldim Pide & Lahmacun, Talas (Mevlana Mah.) | C18: =VLOOKUP(A18,import!A:C,3,0) -> DOĞRU | D18: Pide | E18: =VLOOKUP(A18,import!A:J,5,0) -> 910 | F18: =VLOOKUP(A18,import!A:J,6,0) | G18: =VLOOKUP(A18,import!A:J,7,0) -> 0 | H18: =VLOOKUP(A18,import!A:J,8,0) -> 6 | I18: =VLOOKUP(A18,import!A:J,9,0) -> 6 | J18: =VLOOKUP(A18,import!A:J,10,0) -> 0 | K18: Yasin Kösem | L18: 3528883898 | M18: Talas | N18: Mevlana | O18: Mevlana Mah. Bademli Cad. No:2/A Talas/KAYSERİ | P18: =VLOOKUP(A18,import!A:P,16,0) -> Geleneksel | R18: TRUE | S18: FALSE | T18: Çekim İstemiyor | W18: istemedi gerek yok dedi | AA18: Görüşüldü | AB18: 44579 | AK18: Zeliha Özer | AP18: Mustafa Dursun
A19: 61cc7a6ed0f64b3ca7a85762 | B19: Ada Döner, Kocasinan (Hacı Saki Mah.) | C19: =VLOOKUP(A19,import!A:C,3,0) -> DOĞRU | D19: Döner | E19: =VLOOKUP(A19,import!A:J,5,0) -> 105 | F19: =VLOOKUP(A19,import!A:J,6,0) -> 14 | G19: =VLOOKUP(A19,import!A:J,7,0) -> 13 | H19: =VLOOKUP(A19,import!A:J,8,0) -> 4 | I19: =VLOOKUP(A19,import!A:J,9,0) -> 17 | J19: =VLOOKUP(A19,import!A:J,10,0) -> 0.76 | K19: Ali Aktay | L19: 3523201239 | M19: Kocasinan | N19: Hacı Saki | O19: Hacı Saki Mah. Atatürk Blv. No:29/B Kocasinan/KAYSERİ | P19: =VLOOKUP(A19,import!A:P,16,0) -> Geleneksel | R19: TRUE | S19: FALSE | T19: Randevu Alındı | U19: Ferhat Köksal | V19: Muzaffer Köprü | W19: 5531989800 | X19: 44627 | Y19: 44628 | AA19: Görüşüldü | AB19: 44627 | AK19: Ferhat Köksal
A20: 5fda06ff8e3739fd3a13204a | B20: Ada Tost, Kocasinan (Mevlana Mah.) | C20: =VLOOKUP(A20,import!A:C,3,0) -> YANLIŞ | D20: Tost & Sandviç | E20: =VLOOKUP(A20,import!A:J,5,0) -> 1064 | F20: =VLOOKUP(A20,import!A:J,6,0) | G20: =VLOOKUP(A20,import!A:J,7,0) -> 19 | H20: =VLOOKUP(A20,import!A:J,8,0) -> 5 | I20: =VLOOKUP(A20,import!A:J,9,0) -> 24 | J20: =VLOOKUP(A20,import!A:J,10,0) -> 0.79 | K20: Ahmet Lütfullah Dirican | L20: 5303839538 | M20: Kocasinan | N20: Plevne | O20: Mevlana Mah. Barış Manço Cad. No:8/B Kocasinan Kayseri | P20: =VLOOKUP(A20,import!A:P,16,0) -> Geleneksel | R20: TRUE | S20: FALSE | T20: Randevu Alındı | U20: Senanur Çınar | V20: Feyza Yıldırım | X20: 44287 | Y20: 44292 | AP20: Mustafa Dursun
A21: 60e5b7c557031a248f0d2c1c | B21: Ada Tost, Melikgazi (Kılıçaslan Mah.) | C21: =VLOOKUP(A21,import!A:C,3,0) -> DOĞRU | D21: Tost & Sandviç | E21: =VLOOKUP(A21,import!A:J,5,0) -> 835 | F21: =VLOOKUP(A21,import!A:J,6,0) | G21: =VLOOKUP(A21,import!A:J,7,0) -> 0 | H21: =VLOOKUP(A21,import!A:J,8,0) -> 18 | I21: =VLOOKUP(A21,import!A:J,9,0) -> 18 | J21: =VLOOKUP(A21,import!A:J,10,0) -> 0 | K21: Mehmet Ali Çetin | L21: 5331429538 | M21: Melikgazi | N21: Kılıçaslan | O21: Kılıçaslan Mah. Şht. Ütğm. Mustafa Şimşek Blv. No:41/B Melikgazi/KAYSERİ | P21: =VLOOKUP(A21,import!A:P,16,0) -> Geleneksel | R21: TRUE | S21: TRUE | W21: öğleden sonra 2 gibi arayın der / kendi fotoğrafları varmış mail atacak | AA21: Tekrar Aranacak | AB21: 44476 | AC21: Görüşüldü | AD21: 44586 | AE21: Görüşüldü | AF21: 44614 | AK21: Hatem Soyaslan | AL21: Betül Demir | AM21: Betül Demir | AP21: Mustafa Dursun
A22: 6227a4948eff0032b06d42b7 | B22: Ada Tost, Melikgazi (Kılıçaslan Mah.) | C22: =VLOOKUP(A22,import!A:C,3,0) -> DOĞRU | D22: Tost & Sandviç | E22: =VLOOKUP(A22,import!A:J,5,0) -> 53 | F22: =VLOOKUP(A22,import!A:J,6,0) -> 14 | G22: =VLOOKUP(A22,import!A:J,7,0) -> 0 | H22: =VLOOKUP(A22,import!A:J,8,0) -> 26 | I22: =VLOOKUP(A22,import!A:J,9,0) -> 26 | J22: =VLOOKUP(A22,import!A:J,10,0) -> 0 | K22: Gökhan Derin | L22: 5331429538 | M22: Melikgazi | N22: Kılıçaslan | O22: Kılıçaslan Mah. Şht. Ütğm. Mustafa Şimşek Blv. No:41/B Melikgazi/KAYSERİ | P22: =VLOOKUP(A22,import!A:P,16,0) -> Geleneksel | R22: TRUE | S22: FALSE | W22: dükkan devir aşamasında panelin açılmasını bekliyorum - ramazan sonra yapalım | AA22: Görüşüldü | AB22: 44634 | AK22: Ferhat Köksal
A23: 5fda0d214a5aa19b40da7467 | B23: Ada Tost, Talas (Mevlana Mah.) | C23: =VLOOKUP(A23,import!A:C,3,0) -> YANLIŞ | D23: Tost & Sandviç | E23: =VLOOKUP(A23,import!A:J,5,0) -> 537 | F23: =VLOOKUP(A23,import!A:J,6,0) | G23: =VLOOKUP(A23,import!A:J,7,0) -> 0 | H23: =VLOOKUP(A23,import!A:J,8,0) -> 24 | I23: =VLOOKUP(A23,import!A:J,9,0) -> 24 | J23: =VLOOKUP(A23,import!A:J,10,0) -> 0 | K23: Serdar Yargı | L23: 5435740503 | M23: Talas | N23: Mevlana | O23: Mevlana, Fildişi Sk. No: 30/ A, 38280 Talas/Kayseri | P23: =VLOOKUP(A23,import!A:P,16,0) -> Geleneksel | R23: TRUE | S23: FALSE | T23: Başka Şubeden Çekilecek | W23: diğer şube ile randevu ayarlnamış ordan | AP23: Mustafa Dursun
A24: 6192251d4e902f570f793b74 | B24: Adıger Çiğ Köfte, Melikgazi (Fatih Mah. - İldem) | C24: =VLOOKUP(A24,import!A:C,3,0) -> DOĞRU | D24: Çiğ Köfte | E24: =VLOOKUP(A24,import!A:J,5,0) -> 142 | F24: =VLOOKUP(A24,import!A:J,6,0) -> 2 | G24: =VLOOKUP(A24,import!A:J,7,0) -> 0 | H24: =VLOOKUP(A24,import!A:J,8,0) -> 6 | I24: =VLOOKUP(A24,import!A:J,9,0) -> 6 | J24: =VLOOKUP(A24,import!A:J,10,0) -> 0 | K24: Hikmet Karatepe | L24: 5523557126 | M24: Melikgazi | N24: Gesi Fatih | O24: Gesi Fatih Mah. 2351. Sok. No:5/A Melikgazi/KAYSERİ | P24: =VLOOKUP(A24,import!A:P,16,0) -> Geleneksel | R24: TRUE | S24: FALSE | T24: BlackList | U24: Betül Demir | V24: Muzaffer Köprü | W24: bir daha alınmasın | X24: 44596 | Y24: 44602 | AA24: Görüşüldü | AB24: 44588 | AC24: Görüşüldü | AD24: 44589 | AE24: Görüşüldü | AF24: 44596 | AK24: Betül Demir | AL24: Betül Demir | AP24: Mustafa Dursun
A25: 623e17df82283e1aa18ccb06 | B25: Adıyaman Ciğ Köftecisi Bayram Usta, (Hoca Ahmet Yesevi Mah.) | C25: =VLOOKUP(A25,import!A:C,3,0) -> DOĞRU | D25: Çiğ Köfte | E25: =VLOOKUP(A25,import!A:J,5,0) | F25: =VLOOKUP(A25,import!A:J,6,0) | G25: =VLOOKUP(A25,import!A:J,7,0) -> 0 | H25: =VLOOKUP(A25,import!A:J,8,0) -> 12 | I25: =VLOOKUP(A25,import!A:J,9,0) -> 12 | J25: =VLOOKUP(A25,import!A:J,10,0) -> 0 | K25: Abdullah Çakırbeyli | L25: 3525043339 | M25: Kocasinan | N25: Hoca Ahmet Yesevi | O25: Hoca Ahmet Yesevi Mah. Kaman 1. Sok. No:11/A Kocasinan/KAYSERİ | P25: =VLOOKUP(A25,import!A:P,16,0) -> Geleneksel | R25: FALSE | S25: FALSE | T25: Franchise
A26: 61f822875bb75953ca722175 | B26: Adıyaman Çiğ Köftecisi Bayram Usta, (Erkilet Ertuğrul Gazi Mah.) | C26: =VLOOKUP(A26,import!A:C,3,0) -> DOĞRU | D26: Çiğ Köfte | E26: =VLOOKUP(A26,import!A:J,5,0) -> 17 | F26: =VLOOKUP(A26,import!A:J,6,0) | G26: =VLOOKUP(A26,import!A:J,7,0) -> 0 | H26: =VLOOKUP(A26,import!A:J,8,0) -> 4 | I26: =VLOOKUP(A26,import!A:J,9,0) -> 4 | J26: =VLOOKUP(A26,import!A:J,10,0) -> 0 | K26: Orhan Tezcan | L26: 5300329892 | M26: Kocasinan | N26: Dere | O26: Ertuğrul Gazi Mah. Pusula Cad. No:8/C Kocasinan/KAYSERİ | P26: =VLOOKUP(A26,import!A:P,16,0) -> Geleneksel | R26: FALSE | S26: FALSE | T26: Franchise
A27: 614a1fd8ade6451dc4787606 | B27: Adıyaman Çiğ Köftecisi Bayram Usta, (Erkilet Osman Gazi Mah.) | C27: =VLOOKUP(A27,import!A:C,3,0) -> DOĞRU | D27: Çiğ Köfte | E27: =VLOOKUP(A27,import!A:J,5,0) -> 36 | F27: =VLOOKUP(A27,import!A:J,6,0) | G27: =VLOOKUP(A27,import!A:J,7,0) -> 7 | H27: =VLOOKUP(A27,import!A:J,8,0) -> 1 | I27: =VLOOKUP(A27,import!A:J,9,0) -> 8 | J27: =VLOOKUP(A27,import!A:J,10,0) -> 0.88 | K27: Mustafa Kaplan | L27: 5436649359 | M27: Kocasinan | N27: Osmangazi | O27: Osmangazi Mah. 54. Sok. No:29/B Kocasinan/KAYSERİ | P27: =VLOOKUP(A27,import!A:P,16,0) -> Geleneksel | R27: TRUE | S27: FALSE | T27: Randevu Alındı | U27: Betül Demir | V27: Muzaffer Köprü | W27: devam çekimi alındı | X27: 44621 | Y27: 44648 | AA27: Görüşüldü | AB27: 44621 | AK27: Betül Demir | AP27: Mustafa Dursun
A28: 6006a6da3c42003af6bef424 | B28: Adıyaman Çiğ Köftecisi Bayram Usta, (Yeşilyurt Mah.-İldem) | C28: =VLOOKUP(A28,import!A:C,3,0) -> DOĞRU | D28: Çiğ Köfte | E28: =VLOOKUP(A28,import!A:J,5,0) -> 810 | F28: =VLOOKUP(A28,import!A:J,6,0) -> 7 | G28: =VLOOKUP(A28,import!A:J,7,0) -> 0 | H28: =VLOOKUP(A28,import!A:J,8,0) -> 10 | I28: =VLOOKUP(A28,import!A:J,9,0) -> 10 | J28: =VLOOKUP(A28,import!A:J,10,0) -> 0 | K28: Özlem arı | L28: 5466945570 | M28: Melikgazi | N28: Yeşilyurt | O28: Yeşilyurt Mah. 2357. Cad. B Blok(D17) No:37/C Melikgazi/KAYSERİ | P28: =VLOOKUP(A28,import!A:P,16,0) -> Geleneksel | R28: TRUE | S28: FALSE | T28: Franchise | AP28: Mustafa Dursun
A29: 614a1ab51cc882677b63dd31 | B29: Adıyaman Çiğ Köftecisi Bayram Usta, Kocasinan (Beyazşehir Mah.) | C29: =VLOOKUP(A29,import!A:C,3,0) -> DOĞRU | D29: Çiğ Köfte | E29: =VLOOKUP(A29,import!A:J,5,0) -> 701 | F29: =VLOOKUP(A29,import!A:J,6,0) -> 17 | G29: =VLOOKUP(A29,import!A:J,7,0) -> 0 | H29: =VLOOKUP(A29,import!A:J,8,0) -> 31 | I29: =VLOOKUP(A29,import!A:J,9,0) -> 31 | J29: =VLOOKUP(A29,import!A:J,10,0) -> 0 | K29: Büşra Tekmanlı | L29: 5534434688 | M29: Kocasinan | N29: Beyazşehir | O29: Beyazşehir Mah. 825. Sok. No:22/E Kocasinan/KAYSERİ | P29: =VLOOKUP(A29,import!A:P,16,0) -> Geleneksel | R29: TRUE | S29: FALSE | T29: Ulaşılamadı | U29: Enes Günal | V29: Muzaffer Köprü | W29: Mesut Bey 5534434688 | X29: 44614 | Y29: 44617 | AA29: Görüşüldü | AB29: 44614 | AK29: Enes Günal | AP29: Mustafa Dursun
A30: 60422696b826f0d63b306be6 | B30: Adıyaman Çiğ Köftecisi Bayram Usta, Kocasinan (Sümer Mah.) | C30: =VLOOKUP(A30,import!A:C,3,0) -> DOĞRU | D30: Çiğ Köfte | E30: =VLOOKUP(A30,import!A:J,5,0) -> 283 | F30: =VLOOKUP(A30,import!A:J,6,0) -> 4 | G30: =VLOOKUP(A30,import!A:J,7,0) -> 0 | H30: =VLOOKUP(A30,import!A:J,8,0) -> 9 | I30: =VLOOKUP(A30,import!A:J,9,0) -> 9 | J30: =VLOOKUP(A30,import!A:J,10,0) -> 0 | K30: Ahmet Diri | L30: 3523380233 | M30: Kocasinan | N30: Sümer | O30: Sümer Mah. 11.Cad. No:4/B Kocasinan/KAYSERİ | P30: =VLOOKUP(A30,import!A:P,16,0) -> Geleneksel | R30: FALSE | S30: FALSE | T30: Franchise | AP30: Mustafa Dursun
A31: 61bc6fe34ae455c0386d1bf4 | B31: Adıyaman Çiğ Köftecisi Bayram Usta, Melikgazi (Fatih Mah.-İldem) | C31: =VLOOKUP(A31,import!A:C,3,0) -> YANLIŞ | D31: Çiğ Köfte | E31: =VLOOKUP(A31,import!A:J,5,0) -> 1 | F31: =VLOOKUP(A31,import!A:J,6,0) | G31: =VLOOKUP(A31,import!A:J,7,0) -> 0 | H31: =VLOOKUP(A31,import!A:J,8,0) -> 7 | I31: =VLOOKUP(A31,import!A:J,9,0) -> 7 | J31: =VLOOKUP(A31,import!A:J,10,0) -> 0 | K31: Doğuş Bak | L31: 5427253357 | M31: Melikgazi | N31: Gesi Fatih | O31: Gesi Fatih Mah. İhlas Sok. No:16/B Melikgazi/KAYSERİ | P31: =VLOOKUP(A31,import!A:P,16,0) -> Geleneksel | R31: TRUE | S31: FALSE | T31: Franchise
A32: 61fc2d91b572d22bc0a6acfe | B32: Adıyaman Çiğ Köftecisi Bayram Usta, Melikgazi (Fatih Mah.-İldem) | C32: =VLOOKUP(A32,import!A:C,3,0) -> DOĞRU | D32: Çiğ Köfte | E32: =VLOOKUP(A32,import!A:J,5,0) -> 215 | F32: =VLOOKUP(A32,import!A:J,6,0) -> 27 | G32: =VLOOKUP(A32,import!A:J,7,0) -> 0 | H32: =VLOOKUP(A32,import!A:J,8,0) -> 7 | I32: =VLOOKUP(A32,import!A:J,9,0) -> 7 | J32: =VLOOKUP(A32,import!A:J,10,0) -> 0 | K32: Ömer Faruk Demirkoparan | L32: 5392978018 | M32: Melikgazi | N32: Gesi Fatih | O32: Gesi Fatih Mah. İhlas Sok. No:16/B Melikgazi/KAYSERİ | P32: =VLOOKUP(A32,import!A:P,16,0) -> Geleneksel | R32: TRUE | S32: FALSE | T32: Franchise
A33: 61a8dcde392c8abc8fb07615 | B33: Adıyaman Çiğ Köftecisi Bayram Usta, Melikgazi(Bahçelievler Mah.) | C33: =VLOOKUP(A33,import!A:C,3,0) -> DOĞRU | D33: Çiğ Köfte | E33: =VLOOKUP(A33,import!A:J,5,0) -> 89 | F33: =VLOOKUP(A33,import!A:J,6,0) -> 1 | G33: =VLOOKUP(A33,import!A:J,7,0) -> 0 | H33: =VLOOKUP(A33,import!A:J,8,0) -> 7 | I33: =VLOOKUP(A33,import!A:J,9,0) -> 7 | J33: =VLOOKUP(A33,import!A:J,10,0) -> 0 | K33: Berkay Kenan Çelik | L33: 5382683726 | M33: Melikgazi | N33: Bahçelievler | O33: Bahçelievler Mah. Kocasinan 2. Cad. No:8/F Melikgazi/KAYSERİ | P33: =VLOOKUP(A33,import!A:P,16,0) -> Geleneksel | R33: TRUE | S33: TRUE | W33: panelde fotoğrafları var | AA33: Görüşüldü | AB33: 44588 | AK33: Betül Demir | AP33: Mustafa Dursun
A34: 6242271b4adec638e6f07a11 | B34: Adıyaman Çiğ Köftecisi Bayram Usta, Talas (Mevlana Mah.) | C34: =VLOOKUP(A34,import!A:C,3,0) -> DOĞRU | D34: Çiğ Köfte | E34: =VLOOKUP(A34,import!A:J,5,0) -> 405 | F34: =VLOOKUP(A34,import!A:J,6,0) -> 390 | G34: =VLOOKUP(A34,import!A:J,7,0) -> 0 | H34: =VLOOKUP(A34,import!A:J,8,0) -> 16 | I34: =VLOOKUP(A34,import!A:J,9,0) -> 16 | J34: =VLOOKUP(A34,import!A:J,10,0) -> 0 | K34: BERAT BURHAN KÖSE | L34: 5417382611 | M34: Talas | N34: Mevlana | O34: Mevlana Mah. Taslak Sok. No:2/B Talas/KAYSERİ | P34: =VLOOKUP(A34,import!A:P,16,0) -> Geleneksel | R34: FALSE | S34: FALSE | T34: Franchise
A35: 618a7701adfb063b750bb16a | B35: Adıyaman Çiğ Köftecisi Bayram Usta, Talas (Yenidoğan Mah.) | C35: =VLOOKUP(A35,import!A:C,3,0) -> DOĞRU | D35: Çiğ Köfte | E35: =VLOOKUP(A35,import!A:J,5,0) -> 953 | F35: =VLOOKUP(A35,import!A:J,6,0) -> 47 | G35: =VLOOKUP(A35,import!A:J,7,0) -> 0 | H35: =VLOOKUP(A35,import!A:J,8,0) -> 18 | I35: =VLOOKUP(A35,import!A:J,9,0) -> 18 | J35: =VLOOKUP(A35,import!A:J,10,0) -> 0 | K35: Yunus Emre Erdoğan | L35: 3525013388 | M35: Talas | N35: Yenidoğan | O35: Yenidoğan Mah. Çimenli Cad. No:35/C Talas/KAYSERİ | P35: =VLOOKUP(A35,import!A:P,16,0) -> Geleneksel | R35: TRUE | S35: FALSE | T35: Franchise | AP35: Mustafa Dursun
A36: 61d53a98874a59f37ed67c4c | B36: Adıyaman Çiğ Köftecisi Ömer Aybak, Melikgazi (Köşk Mah.) | C36: =VLOOKUP(A36,import!A:C,3,0) -> YANLIŞ | D36: Çiğ Köfte | E36: =VLOOKUP(A36,import!A:J,5,0) | F36: =VLOOKUP(A36,import!A:J,6,0) | G36: =VLOOKUP(A36,import!A:J,7,0) -> 9 | H36: =VLOOKUP(A36,import!A:J,8,0) -> 11 | I36: =VLOOKUP(A36,import!A:J,9,0) -> 20 | J36: =VLOOKUP(A36,import!A:J,10,0) -> 0.45 | K36: Bilal Sarıoğlu | L36: 5541120402 | M36: Melikgazi | N36: Köşk | O36: Köşk Mah. Kışla Cad. No:52 Sosyete Pazarı Melikgazi/KAYSERİ | P36: =VLOOKUP(A36,import!A:P,16,0) -> Geleneksel | R36: TRUE | S36: FALSE | T36: Franchise
A37: 610d27657ea705a07e2d4b6c | B37: Adıyaman Çiğköfte Yeri, Melikgazi (Esentepe Mah.) | C37: =VLOOKUP(A37,import!A:C,3,0) -> DOĞRU | D37: Çiğ Köfte | E37: =VLOOKUP(A37,import!A:J,5,0) -> 399 | F37: =VLOOKUP(A37,import!A:J,6,0) -> 14 | G37: =VLOOKUP(A37,import!A:J,7,0) -> 0 | H37: =VLOOKUP(A37,import!A:J,8,0) -> 24 | I37: =VLOOKUP(A37,import!A:J,9,0) -> 24 | J37: =VLOOKUP(A37,import!A:J,10,0) -> 0 | K37: Yasemin Karaca | L37: 5520655893 | M37: Melikgazi | N37: Esentepe | O37: Esentepe Mah. 981. Sok. No:3/B Melikgazi/KAYSERİ | P37: =VLOOKUP(A37,import!A:P,16,0) -> Geleneksel | R37: TRUE | S37: FALSE | T37: Randevu Alındı | U37: Sude Alkan | V37: Muzaffer Köprü | W37: keykubat mah kuyu caddesi no 14/a | X37: 44586 | Y37: 44587 | AA37: Görüşüldü | AB37: 44586 | AK37: Sude Alkan | AP37: Mustafa Dursun
A38: 5fdb2adb1e128f82cb8143c9 | B38: Adıyaman Çiğköftecisi Bayram Usta, Kocasinan(Fevziçakmak Mah.) | C38: =VLOOKUP(A38,import!A:C,3,0) -> DOĞRU | D38: Çiğ Köfte | E38: =VLOOKUP(A38,import!A:J,5,0) -> 2248 | F38: =VLOOKUP(A38,import!A:J,6,0) -> 51 | G38: =VLOOKUP(A38,import!A:J,7,0) -> 0 | H38: =VLOOKUP(A38,import!A:J,8,0) -> 22 | I38: =VLOOKUP(A38,import!A:J,9,0) -> 22 | J38: =VLOOKUP(A38,import!A:J,10,0) -> 0 | K38: Ersin Pugar | L38: 5345200917 | M38: Kocasinan | N38: Fevzi Çakmak | O38: Sivas bulvarı, defne apt., A Blok No:63 B | P38: =VLOOKUP(A38,import!A:P,16,0) -> Geleneksel | R38: TRUE | S38: FALSE | T38: Ulaşılamadı | W38: açmadı | AA38: Ulaşılamadı | AB38: 44378 | AK38: Simge Tüçay | AP38: Mustafa Dursun
A39: 5fda33ef2eff062b2f202ec3 | B39: Adıyaman Çiğköftecisi Bayram Usta, Kocasinan(Mimarsinan Mah.) | C39: =VLOOKUP(A39,import!A:C,3,0) -> DOĞRU | D39: Çiğ Köfte | E39: =VLOOKUP(A39,import!A:J,5,0) -> 86 | F39: =VLOOKUP(A39,import!A:J,6,0) -> 4 | G39: =VLOOKUP(A39,import!A:J,7,0) -> 0 | H39: =VLOOKUP(A39,import!A:J,8,0) -> 25 | I39: =VLOOKUP(A39,import!A:J,9,0) -> 25 | J39: =VLOOKUP(A39,import!A:J,10,0) -> 0 | K39: Hakan Yıldırım | L39: 5300651695 | M39: Melikgazi | N39: Alpaslan | O39: Mimar Sinan Mah., Sivas Bulvarı, No:165/A | P39: =VLOOKUP(A39,import!A:P,16,0) -> Geleneksel | R39: TRUE | S39: FALSE | T39: Franchise | W39: yt yok akşam gelir dedi. | AA39: Görüşüldü | AB39: 44327 | AK39: Hatice Özer | AP39: Mustafa Dursun
A40: 61a8d8e82c7e5b4d44e5e19f | B40: Adıyaman Tadımca Çiğ Köfte, Melikgazi (Keykubat Mah.) | C40: =VLOOKUP(A40,import!A:C,3,0) -> DOĞRU | D40: Çiğ Köfte | E40: =VLOOKUP(A40,import!A:J,5,0) -> 115 | F40: =VLOOKUP(A40,import!A:J,6,0) | G40: =VLOOKUP(A40,import!A:J,7,0) -> 6 | H40: =VLOOKUP(A40,import!A:J,8,0) -> 3 | I40: =VLOOKUP(A40,import!A:J,9,0) -> 9 | J40: =VLOOKUP(A40,import!A:J,10,0) -> 0.67 | K40: Nazif Burak Kiraz | L40: 5070934768 | M40: Melikgazi | N40: Keykubat | O40: Keykubat Mah. Anafartalar Cad. No:137/E Melikgazi/KAYSERİ | P40: =VLOOKUP(A40,import!A:P,16,0) -> Geleneksel | R40: TRUE | S40: FALSE | T40: Randevu Alındı | U40: Hatem Soyaslan | V40: Muzaffer Köprü | W40: 5075701420 | X40: 44586 | Y40: 44587 | AA40: Görüşüldü | AB40: 44586 | AK40: Hatem Soyaslan | AP40: Mustafa Dursun
...

Sheet Takvim
A1: x | B1: TARİH.$. | C1: Randevu Alan | D1: ID | E1: RESTORAN | F1: SAAT | G1: İLÇE / MAHALLE | H1: YETKİLİ KİŞİ / TELEFON | I1: ADRES | J1: Notlar | K1: Fotoğraf Adeti | L1: Toplam Ürün | M1: Şubeli | N1: İptal
B2: 44285
A3: Melikgazi | M3: FALSE | N3: FALSE
B4: Feyza Yıldırım | C4: Senanur Çınar | D4: 5fcfd488f6dd3a5bc82596bd | E4: Hisar, Melikgazi (Kılıçaslan Mah.) | F4: 0.45833333 | G4: Melikgazi/Köşk | H4: Ercan Göktepe/5321622262 | I4: Kılıçaslan Mah., Şht. Ütğm. Mustafa Şimşek Blv., No:51, Melikgazi, Kayseri, Türkiye | L4: =VLOOKUP(D4,'Hedef Liste'!A:I,8,false) -> 41 | M4: FALSE | N4: FALSE
B5: Feyza Yıldırım | C5: Senanur Çınar | D5: 5fda36f0a991c50ed136d1c3 | E5: Sır Cafe, Kocasinan (Mimarsinan Mah.) | F5: 0.54166667 | G5: Melikgazi/Alpaslan | H5: Hakan Yıldırım/5300651695 | I5: Sivas caddesi, Akın apt., No:165/A, Alparslan tramvay durağı | L5: =VLOOKUP(D5,'Hedef Liste'!A:I,8,false) -> 30 | M5: FALSE | N5: FALSE
B6: Feyza Yıldırım | C6: Senanur Çınar | D6: 5fd8ba9b01128239822dc5e4 | E6: Pimacun, Melikgazi (Alpaslan Mah.)/ diğer tabela ismi pidezza | F6: 15:00 | G6: Melikgazi/Alpaslan | H6: Emre Çetin/3522300011/05459379213 | I6: Alpaslan, Kızılırmak Cd. No:80, 38030 Melikgazi/Kayseri | L6: =VLOOKUP(D6,'Hedef Liste'!A:I,8,false) -> #N/A | M6: FALSE | N6: FALSE
B7: Feyza Yıldırım | C7: Senanur Çınar | D7: 5ff5e56df73b332e1acfc26e | E7: Hacıbey Baklavaları, Melikgazi (Kılıçaslan Mah.) | F7: 17:00 | G7: Melikgazi/Alpaslan | H7: Ali Kenger/5550019238 | I7: Kılıçaslan Mah. Sivas Blv. No:90/B Melikgazi/KAYSERİ | L7: =VLOOKUP(D7,'Hedef Liste'!A:I,8,false) -> #N/A | M7: FALSE | N7: FALSE
M8: FALSE | N8: FALSE
B9: 44286
A10: Melikgazi | M10: FALSE | N10: FALSE
B11: Feyza Yıldırım | C11: Senanur Çınar | D11: 602be89553e01d3aab4efdb8 | E11: Pide King, Melikgazi (Fatih Mah.-İldem) | F11: 0.45833333 | G11: Melikgazi/Fatih | H11: Gül İleli/5061401513 | I11: Gesi Fatih Mah. Gün Sazak Cad. No:65 Melikgazi/KAYSERİ /kaysermall avm içerisi | L11: =VLOOKUP(D11,'Hedef Liste'!A:I,8,false) -> 9 | M11: FALSE | N11: FALSE
B12: Feyza Yıldırım | C12: Senanur Çınar | D12: 601abb58587d0e89a1b6b777 | E12: Matmazel Patisserie, Melikgazi (Kılıçaslan Mah.) | F12: 0.54166667 | G12: Melikgazi/Kılıçaslan | H12: Rukiye Demirci/5343540220 | I12: Kılıçaslan Mah. Kızılırmak Cad. No:66/A Melikgazi/KAYSERİ | L12: =VLOOKUP(D12,'Hedef Liste'!A:I,8,false) -> #N/A | M12: FALSE | N12: FALSE
B13: Feyza Yıldırım | C13: Senanur Çınar | D13: 5fe0c7910a229935fa90f782 | E13: Hasan Usta Pizza & Lahmacun, Melikgazi (Kılıçaslan Mah.) | F13: 15:00 | G13: Melikgazi/Kılıçaslan | H13: Hasan Salırlıoğlu/05346678022 | I13: Kılıçaslan Mah. ŞHT.ÜTĞM. Mustafa Şimşek Blv. Candoğan Apt. No: 27 A MElikgazi/Kayseri | L13: =VLOOKUP(D13,'Hedef Liste'!A:I,8,false) -> 14 | M13: FALSE | N13: FALSE
B14: Feyza Yıldırım | C14: Senanur Çınar | D14: 602fcb29b868aa6fc7f784ce | E14: Köşem Kebap, Kocasinan (Fevzi Çakmak Mah.) | F14: 18:00 | G14: Kocasinan/Fevzi Çakmak | H14: Keziban Toprak/3523334344 | I14: Fevzi Çakmak Mah. Yeşilırmak Cad. No:23/A Kocasinan/KAYSERİ | L14: =VLOOKUP(D14,'Hedef Liste'!A:I,8,false) -> 7 | M14: FALSE | N14: FALSE
M15: FALSE | N15: FALSE
B16: 44287
A17: Melikgazi | M17: FALSE | N17: FALSE
B18: Feyza Yıldırım | E18: 10-12 arası randevu alınmayacak | L18: =VLOOKUP(D18,'Hedef Liste'!A:I,8,false) -> #N/A | M18: FALSE | N18: FALSE
B19: Feyza Yıldırım | C19: Senanur Çınar | D19: 60058169a2992703a59821fe | E19: Meydan Merkez Pide Salonu, Kocasinan (Serçeönü Mah.) | F19: 0.54166667 | G19: Kocasinan/Serçeönü | H19: Asım Yaşar/5367764858 | I19: sahabiye Mah. Ahmet Paşa cad. No:13/C Kocasinan/KAYSERİ | L19: =VLOOKUP(D19,'Hedef Liste'!A:I,8,false) -> 7 | M19: FALSE | N19: FALSE
B20: Feyza Yıldırım | C20: Senanur Çınar | D20: 5fe5c275ce622f0674cb33d9 | E20: Hizmet Çorba Kebap, Kocasinan (Sahabiye Mah.) | F20: 15:00 | G20: Kocasinan/Sahabiye | H20: Mehmet Özen/3522314019 | I20: Sahabiye Mah. İstasyon Cad. Ak İş Merkezi No:14/A Kocasinan/KAYSERİ | L20: =VLOOKUP(D20,'Hedef Liste'!A:I,8,false) -> 8 | M20: FALSE | N20: FALSE
B21: Feyza Yıldırım | C21: Senanur Çınar | D21: 5ff588d560a4ccc93d909c9d | E21: Mutlu Sarıyer Börek & Kahvaltı Evi, Kocasinan (Sahabiye Mah.) | F21: 17:00 | G21: Kocasinan/Serçeönü | H21: Fırat Kaplan/3522229545 | I21: Sahabiye Mah. Birkan Sok. No:18/B Kocasinan/KAYSERİ | J21: Çekim için bekledik gelmediği için elemanlarımı gönderdim dedi. Çarşamba gününe randevu alındı geç kalınmasını istemiyor | L21: =VLOOKUP(D21,'Hedef Liste'!A:I,8,false) -> #N/A | M21: FALSE | N21: FALSE
C22: Senanur Çınar | D22: 602d3736c20d04e6675030ca | E22: Bon Pizza, Kocasinan (Sahabiye Mah.) | F22: 18.30 | G22: Kocasinan/Sahabiye | H22: LÜTFİYE PINAR/3522200909 | I22: Sahabiye Mah. Türkay Sok. No:4 Kocasinan/KAYSERİ | J22: Sadece 5 6 adet ürün çekilecek | M22: FALSE | N22: FALSE
B23: 44288
A24: Melikgazi | M24: FALSE | N24: FALSE
B25: Feyza Yıldırım | C25: Sıla Göksunaz Esen | D25: 6008723e26a65adee8334a2b | E25: İkinci Bahar Ev Yemekleri, (Camikebir Mah.) | F25: 0.4375 | G25: Melikgazi/Cumhuriyet | H25: Hatice Hanım/05319718097 | I25: Cumhuriyet Mah. Cumhuriyet Cad. No:30 Melikgazi/KAYSERİ | L25: =VLOOKUP(D25,'Hedef Liste'!A:I,8,false) -> #N/A | M25: FALSE | N25: FALSE
B26: Feyza Yıldırım | C26: Sıla Göksunaz Esen | D26: 60211e74627f6e221db475d5 | E26: Acıyaman Çiğ Köfte, Melikgazi (Gülük Mah.) | F26: 0.54166667 | G26: Melikgazi/Gülük | H26: Ahmet Bey/05527112198 | I26: Gülük Mah. Bağlar Cad. No:31/B Melikgazi/KAYSERİ | L26: =VLOOKUP(D26,'Hedef Liste'!A:I,8,false) -> #N/A | M26: FALSE | N26: FALSE
B27: Feyza Yıldırım | D27: 5ff4465ea415e991cd3dbbbf | E27: Acıyaman Çiğ Köfte, Kocasinan (Sahabiye Mah.) | F27: 0.54166667 | J27: Diğer şubedekiler de buraya yüklenecek | M27: FALSE | N27: FALSE
B28: Feyza Yıldırım | C28: Sıla Göksunaz Esen | D28: 5fe9a36512a85077a0bb864a | E28: Kebapçı Numan Baba Torun, Melikgazi (Cumhuriyet Mah.) | F28: 15:00 | G28: Melikgazi/Cumhuriyet | H28: Murat Bey/03522229893 | I28: Cumhuriyet Mah. Karanlık Çarşı Sok. No:1 Melikgazi/KAYSERİ | L28: =VLOOKUP(D28,'Hedef Liste'!A:I,8,false) -> #N/A | M28: FALSE | N28: FALSE
B29: Feyza Yıldırım | C29: Sıla Göksunaz Esen | D29: 5fec36a3ac60e837ae6d9ae5 | E29: On Parmak Pizza & Cafe, Melikgazi (Hunat Mah.) | F29: 17:00 | G29: Melikgazi/Hunat | H29: Faruk Bey/05428028538 | I29: Hunat Mah. Rehber Sok. No:5/A Melikgazi/KAYSERİ | L29: =VLOOKUP(D29,'Hedef Liste'!A:I,8,false) -> #N/A | M29: FALSE | N29: FALSE
M30: FALSE | N30: FALSE
B31: 44292
A32: Melikgazi | E32: İlk Randevu 13:00 olacak | M32: FALSE | N32: FALSE
B33: Feyza Yıldırım | C33: Senanur Çınar | D33: 5fd9fd0a46ac1e85a05683f8 | E33: Neva-le Çiğ Köfte, Kocasinan (Mimarsinan Mah.) | F33: 13.30 | G33: Kocasinan/Mimarsinan | H33: Abbas Şahin/3522238080 | I33: Mimarsinan Mah. Fuzuli Cad. Gözenler Apt. No:44/A-B Kocasinan/KAYSERİ | L33: =VLOOKUP(D33,'Hedef Liste'!A:I,8,false) -> #N/A | M33: FALSE | N33: FALSE
B34: Feyza Yıldırım | C34: Senanur Çınar | D34: 5fda06ff8e3739fd3a13204a | E34: Ada Tost, Kocasinan (Mevlana Mah.) | F34: 15:00 | G34: Kocasinan/Plevne | H34: Ahmet Lütfullah Dirican/5303839538 | I34: Mevlana Mah. Barış Manço Cad. No:8/B Kocasinan Kayseri | L34: =VLOOKUP(D34,'Hedef Liste'!A:I,8,false) -> 5 | M34: FALSE | N34: FALSE
B35: Feyza Yıldırım | C35: Senanur Çınar | D35: 5fe35619d3f42bc6deaf3c3e | E35: Acıyaman Çiğ Köfte, Kocasinan (Gevhernesibe Mah.) | F35: 17:00 | G35: Kocasinan/Örnekevler | H35: Murat Can Kaya/5523838732 | I35: Gevher Nesibe Mah., Salih Avgun Paşa Cad., No:21, Kocasinan, Kayseri, Türkiye, | L35: =VLOOKUP(D35,'Hedef Liste'!A:I,8,false) -> #N/A | M35: FALSE | N35: FALSE
B36: Feyza Yıldırım | C36: Senanur Çınar | D36: 5fe369c30345d26c817fe449 | E36: Bereket Sofrası, Kocasinan (Sahabiye Mah.) | F36: 0.77083333 | G36: Kocasinan/Gevher Nesibe | H36: Hasan Albayrak/3522232601 | I36: Sahabiye Mah., Oğuz Cad., No:3, Kocasinan, Kayseri, Türkiye, | J36: tekrar alndı 14.04 | L36: =VLOOKUP(D36,'Hedef Liste'!A:I,8,false) -> 43 | M36: FALSE | N36: FALSE
M37: FALSE | N37: FALSE
B38: 44293
A39: Melikgazi | M39: FALSE | N39: FALSE
B40: Feyza Yıldırım | C40: Sıla Göksunaz Esen | D40: 5ff3112cdc26c73c2dd19cc1 | E40: Tes Pizza, Kocasinan (Şeker Mah.-K.Şehir Hastanesi) | F40: 0.47916667 | G40: Kocasinan/Şeker | H40: Talha Bey/05355114590 | I40: Şeker Mah. 3169. Sok. B Blok No:5/A Kocasinan/KAYSERİ | J40: Yoğunluktan dolayı erteleme istiyor. | L40: =VLOOKUP(D40,'Hedef Liste'!A:I,8,false) -> #N/A | M40: FALSE | N40: FALSE
...

Sheet import
A1: Restaurant ID | B1: Restoran Adı | C1: IsActive | D1: Mutfak | E1: TOPLAM SİPARİŞ | F1: SON 2 HAFTA | G1: RESİMLİ ÜRÜN | H1: RESİMSİZ ÜRÜN | I1: TOPLAM ÜRÜN | J1: Ratio | K1: Yetkili | L1: Telefon | M1: İLÇE | N1: MAHALLE | O1: ADRES | P1: Geleneksel Zincir | Q1: Eklendi mi
A2: 5fe4ae371a12f93b20f7a2d3 | B2: KFC, Melikgazi (Alpaslan Mah.) | C2: DOĞRU | D2: Tavuk | E2: 12460 | F2: 244 | G2: 92 | H2: 1 | I2: 93 | J2: 0.99 | K2: Tamer Yılmaz | L2: 1111111111 | M2: Melikgazi | N2: Melikgazi | O2: Alparslan Mah, Orgeneral Eşref Bitlis Blv. No:10, 38030 Melikgazi/Kayseri | P2: Key | Q2: =COUNTIF('Hedef Liste'!A:A,A2) -> 0
A3: 5fcfd488f6dd3a5bc82596bd | B3: Hisar, Melikgazi (Kılıçaslan Mah.) | C3: YANLIŞ | D3: Pasta & Tatlı | E3: 113 | G3: 15 | H3: 41 | I3: 56 | J3: 0.27 | K3: Ercan Göktepe | L3: 5321622262 | M3: Melikgazi | N3: Köşk | O3: Kılıçaslan Mah., Şht. Ütğm. Mustafa Şimşek Blv., No:51, Melikgazi, Kayseri, Türkiye | P3: Geleneksel | Q3: =COUNTIF('Hedef Liste'!A:A,A3) -> 1
A4: 5fd77baa12cbf32125e54708 | B4: Talas Köşk, Talas (Kiçiköy Mah.) | C4: DOĞRU | D4: Döner | E4: 10237 | F4: 95 | G4: 4 | H4: 7 | I4: 11 | J4: 0.36 | K4: Ümit Ulaş | L4: 3524377070 | M4: Talas | N4: Kiçiköy | O4: Kiçiköy, Hoca Ahmet Yesevi Cd. No:12, 38280 Talas/Kayseri | P4: Geleneksel | Q4: =COUNTIF('Hedef Liste'!A:A,A4) -> 1
A5: 5fe2fa620345d282cc7fd2d5 | B5: Ciğerci Mehmet, Kocasinan (Sahabiye Mah.) | C5: DOĞRU | D5: Kebap | E5: 2855 | F5: 89 | G5: 0 | H5: 67 | I5: 67 | J5: 0 | K5: Metin Aybar | L5: 3522233838 | M5: Kocasinan | N5: Serçeönü | O5: Sahabiye, Saray Cd. No:6/A, 38015 Kocasinan/Kayseri | P5: Geleneksel | Q5: =COUNTIF('Hedef Liste'!A:A,A5) -> 1
A6: 5fde1230cd4e0c0fe9169e3a | B6: Pane Döner, Talas (Yenidoğan Mah.) | C6: DOĞRU | D6: Döner | E6: 11008 | F6: 238 | G6: 0 | H6: 19 | I6: 19 | J6: 0 | K6: Nuh Mehmet Gökçek | L6: 3524378080 | M6: Talas | N6: Yenidoğan | O6: Yenidoğan, Oğulcuklu Cd. 3 A, 38280 Talas/Kayseri | P6: Geleneksel | Q6: =COUNTIF('Hedef Liste'!A:A,A6) -> 1
A7: 5fe1c0b56ce3dd9f37cfd74d | B7: Dönerci Baba, Melikgazi (Gültepe Mah.) | C7: DOĞRU | D7: Döner | E7: 5030 | F7: 63 | G7: 0 | H7: 35 | I7: 35 | J7: 0 | K7: Yusuf Sapayer | L7: 3522334400 | M7: Melikgazi | N7: Kılıçaslan | O7: Eski Hama İlerisi, Gültepe Mah. Mustafa Şimşek Bulv. Zafer Apt. Altı, 38030 Melikgazi/Kayseri | P7: Geleneksel | Q7: =COUNTIF('Hedef Liste'!A:A,A7) -> 1
A8: 5fd355b7d595925ebebc025c | B8: Kötü Gün Tostu, Talas (Tablakaya Mah.) | C8: DOĞRU | D8: Tost & Sandviç | E8: 3429 | F8: 240 | G8: 7 | H8: 23 | I8: 30 | J8: 0.23 | K8: Savaş Dağlı | L8: 5537061313 | M8: Talas | N8: Tablakaya | O8: Tablakaya Mh. Yahya Sk. No:8/B Talas/Kayseri | P8: Geleneksel | Q8: =COUNTIF('Hedef Liste'!A:A,A8) -> 1
A9: 5fe44599d108fc934e2c5492 | B9: Kaygısız Izgara, Kocasinan (Gevhernesibe Mah.) | C9: DOĞRU | D9: Kebap | E9: 6045 | G9: 0 | H9: 8 | I9: 8 | J9: 0 | K9: Serdar Koç | L9: 3522310106 | M9: Kocasinan | N9: Gevher Nesibe | O9: Gevhernesibe Mah. Kurşunlu Sok. 13/A Kocasinan, Kayseri | P9: Geleneksel | Q9: =COUNTIF('Hedef Liste'!A:A,A9) -> 1
A10: 5fd888eb4d587052641b84f8 | B10: Confurt Dondurma, Melikgazi (Köşk Mah.) | C10: DOĞRU | D10: Dondurma | E10: 90 | F10: 3 | G10: 0 | H10: 37 | I10: 37 | J10: 0 | K10: Bülent Şahin | L10: 3522370010 | M10: Melikgazi | N10: Melikgazi | O10: Köşk Mah. Mustafa Şimşek Cad. Hisar Apt. No:56/E Melikgazi/KAYSERİ | P10: Geleneksel | Q10: =COUNTIF('Hedef Liste'!A:A,A10) -> 1
A11: 5fde26cf3587c378d752ded5 | B11: Antep-lim Gaziantep Baklavaları, Talas (Mevlana Mah.) | C11: DOĞRU | D11: Pasta & Tatlı | E11: 359 | F11: 1 | G11: 11 | H11: 0 | I11: 11 | J11: 1 | K11: Rıdvan Kefkir | L11: 3529993872 | M11: Talas | N11: Mevlana | O11: Mevlana, Yavuz Sultan Selim Cd. No:18 D:E, 38280 Talas/Kayseri | P11: Geleneksel | Q11: =COUNTIF('Hedef Liste'!A:A,A11) -> 1
A12: 5fd88b8f4304e6a50bca03b8 | B12: Confurt Dondurma, Melikgazi (Alpaslan Mah.) | C12: YANLIŞ | D12: Dondurma | E12: 26 | G12: 0 | H12: 46 | I12: 46 | J12: 0 | K12: Bülent Şahin | L12: 3522345668 | M12: Melikgazi | N12: Alpaslan | O12: Alpaslan Mah. Kızılırmak Cad. Vakıf Yenipark Apt. No:118/B Melikgazi/KAYSERİ | P12: Geleneksel | Q12: =COUNTIF('Hedef Liste'!A:A,A12) -> 1
A13: 5fd21bb199fe01829eadd170 | B13: Kanatçı Bahadır, Talas (Yenidoğan Mah.) | C13: DOĞRU | D13: Kebap | E13: 1239 | F13: 13 | G13: 32 | H13: 21 | I13: 53 | J13: 0.6 | K13: Hüseyin Bahadır Per | L13: 3522204141 | M13: Talas | N13: Mevlana | O13: mevlana mah. elçibey cad no:38Atalas/ kayseri | P13: Geleneksel | Q13: =COUNTIF('Hedef Liste'!A:A,A13) -> 1
A14: 5fd5e388cba35d420dd1898e | B14: Elit 38 Lahmacun & Pide Talas (Mevlana Mah.) | C14: YANLIŞ | D14: Pide | E14: 2846 | G14: 0 | H14: 9 | I14: 9 | J14: 0 | K14: Onur Karakoç | L14: 3525046085 | M14: Talas | N14: Mevlana | O14: Mevlana Mh. Bilge Kağan Cd. B giriş No: 30/E | P14: Geleneksel | Q14: =COUNTIF('Hedef Liste'!A:A,A14) -> 1
A15: 5fcfd64e40fbdb8962745940 | B15: Efece Ev Yemekleri, Talas (Bahçelievler) | C15: DOĞRU | D15: Ev Yemekleri | E15: 190 | G15: 0 | H15: 38 | I15: 38 | J15: 0 | K15: Gülten Özmen | L15: 5051469496 | M15: Talas | N15: Bahçelievler | O15: Bahçelievler, Hacı Cemil 1. Sk. 25/A, 38280 Talas/Kayseri | P15: Geleneksel | Q15: =COUNTIF('Hedef Liste'!A:A,A15) -> 1
A16: 5fd340c0a926a55f2561973d | B16: Tatlıses Lahmacun, Talas (Mevlana Mah.) | C16: DOĞRU | D16: Lahmacun | E16: 3907 | F16: 111 | G16: 0 | H16: 45 | I16: 45 | J16: 0 | K16: Önder Yamaç | L16: 3523335626 | M16: Talas | N16: Mevlana | O16: Mevlana Mah. Melikşah Cad. 6 D TALAS / KAYSERİ | P16: Geleneksel | Q16: =COUNTIF('Hedef Liste'!A:A,A16) -> 1
A17: 5fe0c7910a229935fa90f782 | B17: Hasan Usta Pizza & Lahmacun, Melikgazi (Kılıçaslan Mah.) | C17: YANLIŞ | D17: Pizza | E17: 1942 | G17: 24 | H17: 14 | I17: 38 | J17: 0.63 | K17: Hasan Salırlıoğlu | L17: 3523331002 | M17: Melikgazi | N17: Kılıçaslan | O17: Kılıçaslan Mah. ŞHT.ÜTĞM. Mustafa Şimşek Blv. Candoğan Apt. No: 27 A MElikgazi/Kayseri | P17: Geleneksel | Q17: =COUNTIF('Hedef Liste'!A:A,A17) -> 1
A18: 5fe47960d4987a7f7dfbd969 | B18: Aygün 2 Pide & Döner & Lahmacun, Talas (Mevlana Mah.) | C18: DOĞRU | D18: Pide | E18: 4133 | F18: 85 | G18: 0 | H18: 16 | I18: 16 | J18: 0 | K18: Fevziye Güneş | L18: 3524310061 | M18: Talas | N18: Mevlana | O18: Mevlana, Mehmet Timuçin Cd. no:26\1, 38280 Talas/Kayseri | P18: Geleneksel | Q18: =COUNTIF('Hedef Liste'!A:A,A18) -> 1
A19: 5fd0f9fbe4047ebc90fd04fb | B19: As Pat Burger, Talas (Mevlana Mah.) | C19: DOĞRU | D19: Burger | E19: 1070 | F19: 24 | G19: 4 | H19: 11 | I19: 15 | J19: 0.27 | K19: Tugay Gündüz | L19: 3525046718 | M19: Talas | N19: Mevlana | O19: istanbul adalar | P19: Geleneksel | Q19: =COUNTIF('Hedef Liste'!A:A,A19) -> 1
A20: 5fd22d23da5e216be008e307 | B20: Ahbap'ss Köfte & Islak Hamburger, Talas (Yenidoğan Mah.) | C20: DOĞRU | D20: Sokak Lezzetleri | E20: 1236 | F20: 11 | G20: 0 | H20: 14 | I20: 14 | J20: 0 | K20: Selim dirik | L20: 3525043090 | M20: Talas | N20: Bahçelievler | O20: Yenidoğan Mah. Atatürk Blv. No:15/C Talas/KAYSERİ | P20: Geleneksel | Q20: =COUNTIF('Hedef Liste'!A:A,A20) -> 1
A21: 5feb2ebb0e63fedc83cb0eec | B21: Bereket Develi Cıvıklısı, Melikgazi (Gültepe Mah.) | C21: DOĞRU | D21: Pide | E21: 516 | G21: 5 | H21: 10 | I21: 15 | J21: 0.33 | K21: Cafer Nalbant | L21: 3522360121 | M21: Melikgazi | N21: Gültepe | O21: Gültepe Mah. Şehit Üstegmen Mustafa Şimşek Blv. No:6 Melikgazi/KAYSERİ | P21: Geleneksel | Q21: =COUNTIF('Hedef Liste'!A:A,A21) -> 1
A22: 5fe74891f0267ceee6127091 | B22: Şekerpare Pasta ve Börek Evi, Kocasinan (Erciyesevler Mah.) | C22: DOĞRU | D22: Pasta & Tatlı | E22: 876 | F22: 32 | G22: 44 | H22: 8 | I22: 52 | J22: 0.85 | K22: Ferhat Kara | L22: 3522335005 | M22: Kocasinan | N22: Erciyesevler | O22: Erciyesevler Mah. Güney Sok. No:22/B Kocasinan/KAYSERİ | P22: Geleneksel | Q22: =COUNTIF('Hedef Liste'!A:A,A22) -> 1
A23: 5feaf45adc26c732aad052c0 | B23: Dört Döner, Melikgazi (Hürriyet Mah.) | C23: DOĞRU | D23: Sokak Lezzetleri | E23: 1304 | G23: 5 | H23: 5 | I23: 10 | J23: 0.5 | K23: Burhan Vural | L23: 5077904989 | M23: Melikgazi | N23: Çorakçılar | O23: Çorakçılar Mah. Cengiz Topel Cad. No:33/B Melikgazi/KAYSERİ | P23: Geleneksel | Q23: =COUNTIF('Hedef Liste'!A:A,A23) -> 1
A24: 5fec905fe4a5e267417972d7 | B24: Komagene Etsiz Çiğ Köfte, Melikgazi (Altınoluk Mah.) | C24: DOĞRU | D24: Çiğ Köfte | E24: 1224 | F24: 14 | G24: 82 | H24: 11 | I24: 93 | J24: 0.88 | K24: Esra Gonca Parlar | L24: 5535808504 | M24: Melikgazi | N24: Altınoluk | O24: FATİH SULTAN MEHMET BLV. NO:60 | P24: Key | Q24: =COUNTIF('Hedef Liste'!A:A,A24) -> 0
A25: 5ff33c7fe5886a195295edc8 | B25: Aşk Lokmam, Talas (Yenidoğan Mah.) | C25: DOĞRU | D25: Pasta & Tatlı | E25: 3428 | F25: 137 | G25: 14 | H25: 1 | I25: 15 | J25: 0.93 | K25: Ahmet Konyalıoğlu | L25: 5316453973 | M25: Talas | N25: Erciyes Üniversitesi 5. Bölge | O25: Yenidoğan Mah. Bilge Kağan Cad. Çiğdem Apt. No:5/A Talas/KAYSERİ | P25: Geleneksel | Q25: =COUNTIF('Hedef Liste'!A:A,A25) -> 1
A26: 5ff41e7dee0f724013a910a3 | B26: Mimsin Bol Kepçe Döner, Melikgazi (Şirintepe Mah.) | C26: YANLIŞ | D26: Döner | E26: 580 | G26: 0 | H26: 11 | I26: 11 | J26: 0 | K26: Bilent Demiral | L26: 5054725759 | M26: Melikgazi | N26: Şirintepe | O26: Şirintepe Mah. Malazgirt Blv. No:26/E Melikgazi/KAYSERİ | P26: Geleneksel | Q26: =COUNTIF('Hedef Liste'!A:A,A26) -> 1
A27: 5ff6b0fcdef388dfe1dee198 | B27: Yapar Kebap, Melikgazi (Kılıçaslan Mah.) | C27: DOĞRU | D27: Döner | E27: 5033 | G27: 14 | H27: 12 | I27: 26 | J27: 0.54 | K27: Abdurrahim Kırtaş | L27: 3524080119 | M27: Melikgazi | N27: Kılıçaslan | O27: Kılıçaslan Mah. Yahya Kemal Cad. No:22/C Melikgazi/KAYSERİ | P27: Geleneksel | Q27: =COUNTIF('Hedef Liste'!A:A,A27) -> 1
A28: 5ff731f3bb116173ba759981 | B28: Cihan Exclusive, Melikgazi (Cumhuriyet Mah.) | C28: DOĞRU | D28: Dünya Mutfağı | E28: 1067 | F28: 57 | G28: 0 | H28: 153 | I28: 153 | J28: 0 | K28: Şaban Zenger | L28: 3522324426 | M28: Melikgazi | N28: Cumhuriyet | O28: Cumhuriyet Mah. Millet Cad. No:11 Melikgazi/KAYSERİ | P28: Geleneksel | Q28: =COUNTIF('Hedef Liste'!A:A,A28) -> 1
A29: 5ff2f124630a768747002543 | B29: Tavada Tavuk, Melikgazi (Fatih Mah.-İldem) | C29: DOĞRU | D29: Tavuk | E29: 889 | F29: 1 | G29: 0 | H29: 51 | I29: 51 | J29: 0 | K29: Ahmet Tiryakioğlu | L29: 3522473838 | M29: Melikgazi | N29: Gesi Fatih | O29: İldem Fatih Mah. Günsazak Cad. No:65/109 Melikgazi/KAYSERİ | P29: Geleneksel | Q29: =COUNTIF('Hedef Liste'!A:A,A29) -> 1
A30: 5fcfdc54b13fa6167404bcdb | B30: S. Kaygısız Kebapcımm, Talas (Bahçelievler) | C30: DOĞRU | D30: Kebap | E30: 8209 | F30: 285 | G30: 0 | H30: 22 | I30: 22 | J30: 0 | K30: Gül Betül Kaygısız | L30: 3524381515 | M30: Talas | N30: Bahçelievler | O30: Bahçelievler, Atatürk Blv. 56/b, 38280 Talas/Kayseri | P30: Geleneksel | Q30: =COUNTIF('Hedef Liste'!A:A,A30) -> 1
A31: 5fd9ce23a908bd05347a38a3 | B31: Anayurt1 Köşk, Melikgazi (Kılıçaslan Mah.) | C31: DOĞRU | D31: Döner | E31: 2113 | F31: 59 | G31: 0 | H31: 17 | I31: 17 | J31: 0 | K31: Serkan Adıyaman | L31: 3522335931 | M31: Melikgazi | N31: Alpaslan | O31: Kılıçaslan Mah. Sivas Blv. No.86D Çınar Apt. Altı, 38030 Melikgazi/Kayseri | P31: Geleneksel | Q31: =COUNTIF('Hedef Liste'!A:A,A31) -> 1
A32: 5fe1e2add3f42b18b3af05f9 | B32: Beylerin Beyi Bey Evi, Kocasinan (Sahabiye Mah.) | C32: DOĞRU | D32: Kebap | E32: 781 | G32: 0 | H32: 25 | I32: 25 | J32: 0 | K32: Canan İlhan | L32: 5412310534 | M32: Kocasinan | N32: Serçeönü | O32: Serçeönü, Çankaya Cd. no: 17/d, 38010 Kocasinan/Kayseri | P32: Geleneksel | Q32: =COUNTIF('Hedef Liste'!A:A,A32) -> 1
A33: 5fda0d214a5aa19b40da7467 | B33: Ada Tost, Talas (Mevlana Mah.) | C33: YANLIŞ | D33: Tost & Sandviç | E33: 537 | G33: 0 | H33: 24 | I33: 24 | J33: 0 | K33: Serdar Yargı | L33: 5435740503 | M33: Talas | N33: Mevlana | O33: Mevlana, Fildişi Sk. No: 30/ A, 38280 Talas/Kayseri | P33: Geleneksel | Q33: =COUNTIF('Hedef Liste'!A:A,A33) -> 1
A34: 5fda1cc01b92e7553b860e98 | B34: Zümrüt Köşk, Kocasinan (Mevlana Mah.) | C34: DOĞRU | D34: Döner | E34: 3930 | F34: 103 | G34: 0 | H34: 25 | I34: 25 | J34: 0 | K34: Ferdi Aydemir | L34: 3523374053 | M34: Kocasinan | N34: Mevlana | O34: mevlana mah., mustafa kemal paşa bulvarı., 38090, Kocasinan | P34: Geleneksel | Q34: =COUNTIF('Hedef Liste'!A:A,A34) -> 1
A35: 5fda33ef2eff062b2f202ec3 | B35: Adıyaman Çiğköftecisi Bayram Usta, Kocasinan(Mimarsinan Mah.) | C35: DOĞRU | D35: Çiğ Köfte | E35: 86 | F35: 4 | G35: 0 | H35: 25 | I35: 25 | J35: 0 | K35: Hakan Yıldırım | L35: 5300651695 | M35: Melikgazi | N35: Alpaslan | O35: Mimar Sinan Mah., Sivas Bulvarı, No:165/A | P35: Geleneksel | Q35: =COUNTIF('Hedef Liste'!A:A,A35) -> 1
A36: 5fddfc12fdea333ff4dec27b | B36: Gurme Dondurma & Cafe, Talas (Yenidoğan Mah.) | C36: DOĞRU | D36: Salata | E36: 939 | F36: 17 | G36: 0 | H36: 37 | I36: 37 | J36: 0 | K36: İsmail Tekgöz | L36: 5526621010 | M36: Talas | N36: Mevlana | O36: Yenidoğan, Bilge Kağan Cd, 38280 Talas/Kayseri | P36: Geleneksel | Q36: =COUNTIF('Hedef Liste'!A:A,A36) -> 1
A37: 5fe369c30345d26c817fe449 | B37: Bereket Sofrası, Kocasinan (Sahabiye Mah.) | C37: DOĞRU | D37: Pizza | E37: 787 | F37: 35 | G37: 31 | H37: 43 | I37: 74 | J37: 0.42 | K37: Hasan Albayrak | L37: 3522232601 | M37: Kocasinan | N37: Gevher Nesibe | O37: Sahabiye Mah., Oğuz Cad., No:3, Kocasinan, Kayseri, Türkiye, | P37: Geleneksel | Q37: =COUNTIF('Hedef Liste'!A:A,A37) -> 1
A38: 5fd0d8754a2e1e3f0a43d08e | B38: Ozşef Profiterol, Talas (Mevlana Mah.) | C38: DOĞRU | D38: Pasta & Tatlı | E38: 1146 | F38: 19 | G38: 0 | H38: 15 | I38: 15 | J38: 0 | K38: Ozan Yazıcı | L38: 5445446926 | M38: Talas | N38: Mevlana | O38: Mevlana mah, Kasrı Eylül Apart, Mehmet Timuçin Cd. 8/A, 38280 Talas/Kayseri | P38: Geleneksel | Q38: =COUNTIF('Hedef Liste'!A:A,A38) -> 1
A39: 5fdb2adb1e128f82cb8143c9 | B39: Adıyaman Çiğköftecisi Bayram Usta, Kocasinan(Fevziçakmak Mah.) | C39: DOĞRU | D39: Çiğ Köfte | E39: 2248 | F39: 51 | G39: 0 | H39: 22 | I39: 22 | J39: 0 | K39: Ersin Pugar | L39: 5345200917 | M39: Kocasinan | N39: Fevzi Çakmak | O39: Sivas bulvarı, defne apt., A Blok No:63 B | P39: Geleneksel | Q39: =COUNTIF('Hedef Liste'!A:A,A39) -> 1
A40: 5fd35e75d0cd4b74a1538d1a | B40: Albina Restoran Talas (Mevlana) | C40: DOĞRU | D40: Kahvaltı | E40: 498 | G40: 0 | H40: 14 | I40: 14 | J40: 0 | K40: Kaan Nart | L40: 5466966569 | M40: Talas | N40: Mevlana | O40: Mevlana Mah. Elçibey Cad. No: 18 B | P40: Geleneksel | Q40: =COUNTIF('Hedef Liste'!A:A,A40) -> 1
...

Sheet Durum Parametreler
C2: Başka Şubeden Çekilecek | H2: Mertcan
C3: BlackList | F3: Feyza Yıldırım | H3: Enes
A4: 44197 | C4: Çekim İstemiyor | H4: Ezgi Turan
A5: 44198 | C5: Devir | H5: Hatem Soyaslan
A6: 44199 | C6: Dönüş Yapacak | H6: Zeliha Özer
A7: 44200 | C7: Franchise | H7: Emre Dalgıç
A8: 44201 | C8: İleride Randevu Alınacak | F8: Ayşegül Kır | H8: Gül Değirmenci
A9: 44202 | C9: Lokasyon Uzak | F9: Betül Demir | H9: Yurdagül Kulaksız
A10: 44203 | C10: Haziran'da Aranacak | F10: Hatem Soyaslan | H10: Ayfer Altın
A11: 44204 | C11: Menü Güncellemesi Yapılacak | F11: Selcan Topçu | H11: Ayşegül Kır
A12: 44205 | C12: Personel Eksik | F12: Sude Alkan | H12: Damla Kılcı
A13: 44206 | C13: Randevu Alındı | F13: Yurdagül Kulaksız | H13: Özlem arslan
A14: 44207 | C14: Randevu İptal | F14: Zeliha Özer | H14: Beyza gülşah
A15: 44208 | C15: Restoran Silindi | F15: Ferhat Köksal | H15: Özlem gümüş
A16: 44209 | C16: Sistemden Çıkmak İstiyor | F16: Enes Günal | H16: Tuğba Buyur
A17: 44210 | C17: Tadilat Var | F17: Serap Apaydın | H17: Kadriye Polat
A18: 44211 | C18: Ulaşılamadı | H18: Şükriye Demir
A19: 44212 | C19: Yılbaşından Sonra Aranacak | H19: Ece Bayındır
A20: 44213 | H20: Senanur Çınar
A21: 44214 | H21: Şura Özcan
A22: 44215 | C22: Dönüş Yapacak | H22: Funda Ünlü
A23: 44216 | C23: Görüşüldü | H23: Sıla Göksunaz Esen
A24: 44217 | C24: Tekrar Aranacak | H24: Emel Yılmaz
A25: 44218 | C25: Ulaşılamadı | H25: Ecem Ersöz
A26: 44219 | C26: Yetkili Yok | H26: Livanur Elibol
A27: 44220 | H27: Eda Cıbır
A28: 44221 | C28: Hemen Randevu İstiyorum | H28: Meryem Yalabık
A29: 44222 | C29: Fotoğraflarım Var | H29: Serenay Yalabık
A30: 44223 | C30: İleride Randevu İstiyorum
A31: 44224
A32: 44225 | C32: Randevu Alınabilir
A33: 44226 | C33: Çekim İstemiyor
A34: 44227 | C34: Fotoğrafları Yok - Randevu Alınabilir
A35: 44228 | C35: Fotoğrafları Gönderecek
A36: 44229
A37: 44230
A38: 44231
A39: 44232
A40: 44233
A41: 44234
...

Sheet özet
G4: Tarih | H4: Başarılı Randevu | I4: İptal Randevu | J4: Top. Rest | K4: =COUNTIFS(import!$C:$C,"true",import!$P:$P,"Geleneksel") -> 0 | O4: İptal Randevu | P4: Fotoğraflandırılan Top. Ürün | Q4: Fotoğraflandırılan Ort. Ürün
B5: Başka Şubeden Çekilecek | C5: =COUNTIFS('Hedef Liste'!T:T,B5,'Hedef Liste'!C:C,"true",'Hedef Liste'!P:P,"Geleneksel",'Hedef Liste'!J:J,"=0%") -> 0 | D5: toplam rest | E5: =COUNTIFS(import!C:C,"true",import!P:P,"Geleneksel") -> 0 | J5: Fotoğraflı | K5: =COUNTIFS(import!$C:$C,"true",import!$P:$P,"Geleneksel",import!$J:$J,">0%") -> 0 | M5: =$K$5/$K$4 -> #DIV/0!
B6: BlackList | C6: =COUNTIF('Hedef Liste'!T:T,B6) -> 4 | D6: fotoğraflı | E6: =COUNTIFS(import!C:C,"true",import!P:P,"Geleneksel",import!J:J,">0%") -> 0
B7: Çekim İstemiyor | C7: =COUNTIFS('Hedef Liste'!T:T,B7,'Hedef Liste'!C:C,"true",'Hedef Liste'!P:P,"Geleneksel",'Hedef Liste'!J:J,"=0%") -> 0 | D7: % | E7: =E6/E5 -> #DIV/0! | J7: Ürün Adet | K7: 0-25 | M7: 25+ | S7: İptal Oranı
B8: Devir | C8: =COUNTIF('Hedef Liste'!T:T,B8) -> 2 | J8: Fotoğraflı | K8: =COUNTIFS(import!$C:$C,"true",import!$J:$J,">0%",import!$P:$P,"Geleneksel",import!$I:$I,"<=25") -> 0 | L8: =K8/K5 -> #DIV/0! | M8: =COUNTIFS(import!C:C,"true",import!J:J,">0%",import!P:P,"Geleneksel",import!I:I,">25") -> 0 | N8: =M8/K5 -> #DIV/0! | S8: =O13/N13 -> #DIV/0!
B9: Dönüş Yapacak | C9: =COUNTIFS('Hedef Liste'!T:T,B9,'Hedef Liste'!C:C,"true",'Hedef Liste'!P:P,"Geleneksel",'Hedef Liste'!J:J,"=0%") -> 0 | J9: 0-20% | K9: =COUNTIFS(import!C:C,"true",import!J:J,">0%",import!J:J,"<=20%",import!P:P,"Geleneksel",import!I:I,"<=25") -> 0 | L9: =K9/K8 -> #DIV/0! | M9: =COUNTIFS(import!C:C,"true",import!J:J,">0%",import!J:J,"<=20%",import!P:P,"Geleneksel",import!I:I,">25") -> 0 | N9: =M9/M8 -> #DIV/0!
B10: Franchise | C10: =COUNTIFS('Hedef Liste'!T:T,B10,'Hedef Liste'!C:C,"true",'Hedef Liste'!P:P,"Geleneksel",'Hedef Liste'!J:J,"=0%") -> 0 | J10: 21-50% | K10: =COUNTIFS(import!C:C,"true",import!J:J,">20%",import!J:J,"<=50%",import!P:P,"Geleneksel",import!I:I,"<=25") -> 0 | L10: =K10/K8 -> #DIV/0! | M10: =COUNTIFS(import!C:C,"true",import!J:J,">20%",import!J:J,"<=50%",import!P:P,"Geleneksel",import!I:I,">25") -> 0 | N10: =M10/M8 -> #DIV/0!
B11: İleride Randevu Alınacak | C11: =COUNTIFS('Hedef Liste'!T:T,B11,'Hedef Liste'!C:C,"true",'Hedef Liste'!P:P,"Geleneksel",'Hedef Liste'!J:J,"=0%") -> 0 | J11: 51-80% | K11: =COUNTIFS(import!C:C,"true",import!J:J,">50%",import!J:J,"<=80%",import!P:P,"Geleneksel",import!I:I,"<=25") -> 0 | L11: =K11/K8 -> #DIV/0! | M11: =COUNTIFS(import!C:C,"true",import!J:J,">50%",import!J:J,"<=80%",import!P:P,"Geleneksel",import!I:I,">25") -> 0 | N11: =M11/M8 -> #DIV/0!
B12: Lokasyon Uzak | C12: =COUNTIFS('Hedef Liste'!T:T,B12,'Hedef Liste'!C:C,"true",'Hedef Liste'!P:P,"Geleneksel",'Hedef Liste'!J:J,"=0%") -> 0 | J12: >80% | K12: =COUNTIFS(import!C:C,"true",import!J:J,">80%",import!P:P,"Geleneksel",import!I:I,"<=25") -> 0 | L12: =K12/K8 -> #DIV/0! | M12: =COUNTIFS(import!C:C,"true",import!J:J,">80%",import!P:P,"Geleneksel",import!I:I,">25") -> 0 | N12: =M12/M8 -> #DIV/0!
B13: Haziran'da Aranacak | C13: =COUNTIFS('Hedef Liste'!T:T,B13,'Hedef Liste'!C:C,"true",'Hedef Liste'!P:P,"Geleneksel",'Hedef Liste'!J:J,"=0%") -> 0
B14: Menü Güncellemesi Yapılacak | C14: =COUNTIFS('Hedef Liste'!T:T,B14,'Hedef Liste'!C:C,"true",'Hedef Liste'!P:P,"Geleneksel",'Hedef Liste'!J:J,"=0%") -> 0
B15: Personel Eksik | C15: =COUNTIFS('Hedef Liste'!T:T,B15,'Hedef Liste'!C:C,"true",'Hedef Liste'!P:P,"Geleneksel",'Hedef Liste'!J:J,"=0%") -> 0
B16: Randevu Alındı | C16: =COUNTIFS('Hedef Liste'!T:T,B16,'Hedef Liste'!C:C,"true",'Hedef Liste'!P:P,"Geleneksel",'Hedef Liste'!J:J,"=0%") -> 0
B17: Randevu İptal | C17: =COUNTIFS('Hedef Liste'!T:T,B17,'Hedef Liste'!C:C,"true",'Hedef Liste'!P:P,"Geleneksel",'Hedef Liste'!J:J,"=0%") -> 0
B18: Restoran Silindi | C18: =COUNTIFS('Hedef Liste'!T:T,B18,'Hedef Liste'!C:C,"true",'Hedef Liste'!P:P,"Geleneksel",'Hedef Liste'!J:J,"=0%") -> 0
B19: Sistemden Çıkmak İstiyor | C19: =COUNTIFS('Hedef Liste'!T:T,B19,'Hedef Liste'!C:C,"true",'Hedef Liste'!P:P,"Geleneksel",'Hedef Liste'!J:J,"=0%") -> 0
B20: Tadilat Var | C20: =COUNTIFS('Hedef Liste'!T:T,B20,'Hedef Liste'!C:C,"true",'Hedef Liste'!P:P,"Geleneksel",'Hedef Liste'!J:J,"=0%") -> 0
B21: Ulaşılamadı | C21: =COUNTIFS('Hedef Liste'!T:T,B21,'Hedef Liste'!C:C,"true",'Hedef Liste'!P:P,"Geleneksel",'Hedef Liste'!J:J,"=0%") -> 0
B22: Ramazandan Sonra Randevu Istiyor | C22: =COUNTIFS('Hedef Liste'!T:T,B22,'Hedef Liste'!C:C,"true",'Hedef Liste'!P:P,"Geleneksel",'Hedef Liste'!J:J,"=0%") -> 0
B23: Fotoğrafı Var | C23: =COUNTIFS('Hedef Liste'!S:S,"True",'Hedef Liste'!C:C,"true",'Hedef Liste'!P:P,"Geleneksel",'Hedef Liste'!J:J,"=0%",'Hedef Liste'!T:T,"") -> 0
B24: TOPLAM | C24: =SUM(C5:C23) -> 6 | D24: =COUNTIFS('Hedef Liste'!C:C,"true",'Hedef Liste'!P:P,"Geleneksel") -> 0
B27: Randevu Başarı %
B28: =C16/COUNTIFS('Hedef Liste'!R:R,"true",'Hedef Liste'!C:C,"true") -> #DIV/0!
