Workbook

Sheet Hedef Liste
A1: Restaurant ID | B1: Restoran Adı | C1: Satışa Açık Mı? | D1: Mutfak | E1: TOPLAM SİPARİŞ | F1: SON 2 HAFTA | G1: RESİMLİ ÜRÜN | H1: RESİMSİZ ÜRÜN | I1: TOPLAM ÜRÜN | J1: Ratio | K1: Yetkili | L1: Telefon | M1: İLÇE | N1: MAHALLE | O1: ADRES | P1: Geleneksel Zincir | Q1: FOTOĞRAF SEGMENT | R1: Aradık Mı? | S1: Kendi Fotosu Var | T1: Randevu Durumu | U1: Randevu Alan | V1: Fotoğrafçı | W1: Not | X1: Randevu Alma Tarihi | Y1: Randevu Tarihi | Z1: Anket Durum | AA1: 1. Arama | AB1: 1. Arama Tarihi | AC1: 2. Arama | AD1: 2. Arama Tarihi | AE1: 3. Arama | AF1: 3. Arama Tarihi | AG1: 4. Arama | AH1: 4. Arama Tarihi | AI1: 5. Arama | AJ1: 5. Arama Tarihi | AK1: 1. Arayan | AL1: 2. Arayan | AM1: 3. Arayan | AN1: 4. Arayan | AO1: 5. Arayan | AP1: SY | AQ1: SY - Durum
A2: 6011db81bb98bb6dff370268 | B2: @'li Burger, Erdemli (Merkez Mah.) | C2: =VLOOKUP(A2,import!A:C,3,0) -> DOĞRU | D2: Burger | E2: =VLOOKUP(A2,import!A:J,5,0) -> 853 | F2: =VLOOKUP(A2,import!A:J,6,0) -> 28 | G2: =VLOOKUP(A2,import!A:J,7,0) -> 2 | H2: =VLOOKUP(A2,import!A:J,8,0) -> 19 | I2: =VLOOKUP(A2,import!A:J,9,0) -> 21 | J2: =VLOOKUP(A2,import!A:J,10,0) -> 0.1 | K2: Seviye Durma | L2: 5333472405 | M2: Erdemli | N2: Merkez 1. Bölge | O2: Merkez Mah.Erdemoğlu Bulvarı, Erdemli Kültür Merlezi No/44 Erdemli, Mersin | P2: =VLOOKUP(A2,import!A:P,16,0) -> Geleneksel | Q2: 0-15 | R2: TRUE | S2: FALSE | T2: Randevu Alındı | U2: Hatem Soyaslan | V2: Burçin Sezer | W2: merkez mah nova city avm 3.kat | X2: 44503 | Y2: 44504 | AA2: Ulaşılamadı | AB2: 44418 | AC2: Görüşüldü | AD2: 44503 | AK2: Deneme | AL2: Hatem Soyaslan | AP2: Serkan Kutlutürk
A3: 6002f166e2740f0a9319bef3 | B3: 01 Mis Börek, Mezitli (Fatih Mah.) | C3: =VLOOKUP(A3,import!A:C,3,0) -> DOĞRU | D3: Börek | E3: =VLOOKUP(A3,import!A:J,5,0) -> 2570 | F3: =VLOOKUP(A3,import!A:J,6,0) -> 112 | G3: =VLOOKUP(A3,import!A:J,7,0) -> 3 | H3: =VLOOKUP(A3,import!A:J,8,0) -> 5 | I3: =VLOOKUP(A3,import!A:J,9,0) -> 8 | J3: =VLOOKUP(A3,import!A:J,10,0) -> 0.38 | K3: Serhat Kırçiçek | L3: 5532992238 | M3: Mezitli | N3: Fatih | O3: Fatih Mah. 30016 Sokak No/2-C Mezitli,Mersin | P3: =VLOOKUP(A3,import!A:P,16,0) -> Geleneksel | Q3: 0-15 | R3: TRUE | S3: FALSE | T3: Randevu Alındı | U3: Hatem Soyaslan | V3: Hikmet Avcı | W3: önemli fotoğraflar panelde ekli | X3: 44274 | Y3: 44277 | AP3: Serkan Kutlutürk
A4: 5ffcabd15757432cd8db3247 | B4: 12:15 Tantuni & Döner & Sakatat, Yenişehir (Güvenevler Mah.) | C4: =VLOOKUP(A4,import!A:C,3,0) -> DOĞRU | D4: Döner | E4: =VLOOKUP(A4,import!A:J,5,0) -> 14612 | F4: =VLOOKUP(A4,import!A:J,6,0) -> 168 | G4: =VLOOKUP(A4,import!A:J,7,0) -> 14 | H4: =VLOOKUP(A4,import!A:J,8,0) -> 36 | I4: =VLOOKUP(A4,import!A:J,9,0) -> 50 | J4: =VLOOKUP(A4,import!A:J,10,0) -> 0.28 | K4: Emirhan Ergül | L4: 5525823245 | M4: Yenişehir | N4: Güvenevler | O4: Güvenevler Mah.1904 Sokak No/6-A Yenişehir,Mersin | P4: =VLOOKUP(A4,import!A:P,16,0) -> Geleneksel | Q4: 26-35 | R4: TRUE | S4: FALSE | T4: Randevu Alındı | U4: Emre Dalgıç | V4: Burçin Sezer | W4: meşgul //meşgul | X4: 44271 | Y4: 44271 | AP4: Serkan Kutlutürk
A5: 601af201499bfc3d0aab2620 | B5: 1991 Tarihi Ortaköy Kumpircisi, Yenişehir (Çiftlikköy Mah.) | C5: =VLOOKUP(A5,import!A:C,3,0) -> DOĞRU | D5: Sokak Lezzetleri | E5: =VLOOKUP(A5,import!A:J,5,0) -> 6257 | F5: =VLOOKUP(A5,import!A:J,6,0) -> 297 | G5: =VLOOKUP(A5,import!A:J,7,0) -> 12 | H5: =VLOOKUP(A5,import!A:J,8,0) -> 108 | I5: =VLOOKUP(A5,import!A:J,9,0) -> 120 | J5: =VLOOKUP(A5,import!A:J,10,0) -> 0.1 | K5: Özkan Arıkan | L5: 5525153333 | M5: Yenişehir | N5: Çiftlikköy | O5: Çiftlikköy Mah.Üniversite Cad.No/42-D Yenişehir,Mersin | P5: =VLOOKUP(A5,import!A:P,16,0) -> Geleneksel | Q5: 35+ | R5: TRUE | S5: TRUE | W5: 05355691111 meşgul // kndılerı cekıp paylasılcak / kalan ürünlerini kendisi mail atacakmış | AA5: Tekrar Aranacak | AB5: 44393 | AC5: Görüşüldü | AD5: 44519 | AE5: Ulaşılamadı | AF5: 44350 | AG5: Görüşüldü | AH5: 44538 | AI5: Görüşüldü | AJ5: 44580 | AK5: Hatem Soyaslan | AL5: Selcan Topçu | AM5: Hatice Özer | AN5: Selcan Topçu | AO5: Betül Demir | AP5: Serkan Kutlutürk
A6: 60900b0d800b49719bcac447 | B6: 33 Orhan Usta Tantuni, Mezitli (Akdeniz Mah.) | C6: =VLOOKUP(A6,import!A:C,3,0) -> DOĞRU | D6: Sokak Lezzetleri | E6: =VLOOKUP(A6,import!A:J,5,0) -> 2608 | F6: =VLOOKUP(A6,import!A:J,6,0) -> 135 | G6: =VLOOKUP(A6,import!A:J,7,0) -> 10 | H6: =VLOOKUP(A6,import!A:J,8,0) -> 10 | I6: =VLOOKUP(A6,import!A:J,9,0) -> 20 | J6: =VLOOKUP(A6,import!A:J,10,0) -> 0.5 | K6: Orhan Pelin | L6: 5378913233 | M6: Mezitli | N6: Merkez | O6: Akdeniz Mah.Zeytinli Cad. No/5-A Mezitli,Mersin | P6: =VLOOKUP(A6,import!A:P,16,0) -> Geleneksel | R6: TRUE | S6: FALSE | T6: Randevu Alındı | U6: Ravza Eğilmez | V6: Burçin Sezer | W6: 5326210445 kendi numarası | X6: 44417 | Y6: 44424 | AA6: Görüşüldü | AB6: 44417 | AK6: Ravza Eğilmez | AP6: Serkan Kutlutürk
A7: 61e6cb8253b020c4c8ae77bb | B7: 33 Öz Mersin Döner, Mezitli (Viranşehir Mah.) | C7: =VLOOKUP(A7,import!A:C,3,0) -> DOĞRU | D7: Döner | E7: =VLOOKUP(A7,import!A:J,5,0) -> 1212 | F7: =VLOOKUP(A7,import!A:J,6,0) | G7: =VLOOKUP(A7,import!A:J,7,0) -> 5 | H7: =VLOOKUP(A7,import!A:J,8,0) -> 2 | I7: =VLOOKUP(A7,import!A:J,9,0) -> 7 | J7: =VLOOKUP(A7,import!A:J,10,0) -> 0.71 | K7: Ali Dinçel | L7: 3243585861 | M7: Mezitli | N7: Viranşehir | O7: Viranşehir Mah.Milli Egemenlik Cad.No:11-F Mezitli,Mersin | P7: =VLOOKUP(A7,import!A:P,16,0) -> Geleneksel | R7: TRUE | S7: FALSE | T7: Randevu Alındı | U7: Betül Demir | V7: Hikmet Avcı | W7: duygu / 5523901989 | X7: 44590 | Y7: 44594 | AA7: Görüşüldü | AB7: 44585 | AC7: Görüşüldü | AD7: 44590 | AK7: Sude Alkan | AL7: Betül Demir
A8: 601954628ecbe9f3ef5c861c | B8: 33 Öz Mersin Tantuni, Mezitli (Viranşehir Mah.) | C8: =VLOOKUP(A8,import!A:C,3,0) -> DOĞRU | D8: Tavuk | E8: =VLOOKUP(A8,import!A:J,5,0) -> 7107 | F8: =VLOOKUP(A8,import!A:J,6,0) -> 597 | G8: =VLOOKUP(A8,import!A:J,7,0) -> 9 | H8: =VLOOKUP(A8,import!A:J,8,0) -> 1 | I8: =VLOOKUP(A8,import!A:J,9,0) -> 10 | J8: =VLOOKUP(A8,import!A:J,10,0) -> 0.9 | K8: Ali Dinçel | L8: 3243585861 | M8: Mezitli | N8: Viranşehir | O8: Viranşehir mh.milli egemenlik caddesi no11/F - Eski Mezitli Belediye Binası Ve Teb Bankası Arasında 100 mtre aşagıda | P8: =VLOOKUP(A8,import!A:P,16,0) -> Geleneksel | Q8: 0-15 | R8: TRUE | S8: FALSE | T8: Randevu Alındı | U8: Tuğba Buyur | V8: Hikmet Avcı | W8: çekim yapılmış \\tamamı çekilmiş. | X8: 44266 | Y8: 44270 | AP8: Serkan Kutlutürk
A9: 6155b04f0f840cd101625ed8 | B9: 421 Burger, Yenişehir (İnönü Mah.) | C9: =VLOOKUP(A9,import!A:C,3,0) -> DOĞRU | D9: Burger | E9: =VLOOKUP(A9,import!A:J,5,0) -> 1396 | F9: =VLOOKUP(A9,import!A:J,6,0) -> 175 | G9: =VLOOKUP(A9,import!A:J,7,0) -> 0 | H9: =VLOOKUP(A9,import!A:J,8,0) -> 31 | I9: =VLOOKUP(A9,import!A:J,9,0) -> 31 | J9: =VLOOKUP(A9,import!A:J,10,0) -> 0 | K9: Fatma Dilara İnan | L9: 3243250421 | M9: Yenişehir | N9: İnönü | O9: İnönü Mah.1407 Sokak No/13-A Yenişehir,Mersin | P9: =VLOOKUP(A9,import!A:P,16,0) -> Geleneksel | R9: TRUE | S9: TRUE | W9: mail paylasıldı / öğle ara / 12 gibi ara / mail adresine atacak bugün | AA9: Görüşüldü | AB9: 44481 | AC9: Görüşüldü | AD9: 44540 | AK9: Selcan Topçu | AL9: Betül Demir | AP9: Serkan Kutlutürk
A10: 601fd7b7d7f75e71dfdbdc56 | B10: 63 Ciğer Kebap , Yenişehir (Barboros Mah.) | C10: =VLOOKUP(A10,import!A:C,3,0) -> DOĞRU | D10: Kebap | E10: =VLOOKUP(A10,import!A:J,5,0) -> 2176 | F10: =VLOOKUP(A10,import!A:J,6,0) -> 72 | G10: =VLOOKUP(A10,import!A:J,7,0) -> 9 | H10: =VLOOKUP(A10,import!A:J,8,0) -> 21 | I10: =VLOOKUP(A10,import!A:J,9,0) -> 30 | J10: =VLOOKUP(A10,import!A:J,10,0) -> 0.3 | K10: Hacı Ahmet Uyar | L10: 3243271463 | M10: Yenişehir | N10: Barbaros | O10: Barboros Mah.Gazi Mustafa Kemal Bulvarı No/482-B Yenişehir,Mersin | P10: =VLOOKUP(A10,import!A:P,16,0) -> Geleneksel | Q10: 26-35 | R10: TRUE | S10: FALSE | T10: Randevu Alındı | U10: Betül Demir | V10: Hikmet Avcı | W10: ÇEKİM YAPILDI DİYOR AMA NEREDE YAPILMIŞ ARKADAŞLAR BUNLARI SORALIM LÜTFEN, ÇEKİM YAPILAN BAŞKA ŞUBE YOK ÇÜNKÜ // Çekim bu şubede yapılmış tüm ürünleri çekilmiş | X10: 44560 | Y10: 44565 | AA10: Ulaşılamadı | AB10: 44350 | AC10: Ulaşılamadı | AD10: 44354 | AG10: Görüşüldü | AH10: 44358 | AI10: Görüşüldü | AJ10: 44580 | AL10: Derya Tatlı | AM10: Hatice Özer | AN10: Nazmiye Yuka | AO10: Betül Demir | AP10: Serkan Kutlutürk
A11: 604c813fcc98d71d93a662aa | B11: Abidin Tantuni, Yenişehir (Aydınlıkevler Mah.) | C11: =VLOOKUP(A11,import!A:C,3,0) -> DOĞRU | D11: Sokak Lezzetleri | E11: =VLOOKUP(A11,import!A:J,5,0) -> 1132 | F11: =VLOOKUP(A11,import!A:J,6,0) -> 75 | G11: =VLOOKUP(A11,import!A:J,7,0) -> 8 | H11: =VLOOKUP(A11,import!A:J,8,0) -> 8 | I11: =VLOOKUP(A11,import!A:J,9,0) -> 16 | J11: =VLOOKUP(A11,import!A:J,10,0) -> 0.5 | K11: Mehmet Sungu | L11: 3243283031 | M11: Yenişehir | N11: Aydınlıkevler | O11: Aydınlıkevler Mah.Gazi Mustafa Kemal Bulvarı No/416-A Yenişehir,Mersin | P11: =VLOOKUP(A11,import!A:P,16,0) -> Geleneksel | R11: TRUE | S11: FALSE | T11: İleride Randevu Alınacak | U11: Betül Demir | V11: Nilay Kaplan | W11: teyit için aranıldığında çekim olmadığını ve istediğini söyledi | X11: 44660 | Y11: 44662 | AA11: Görüşüldü | AB11: 44559 | AC11: Görüşüldü | AD11: 44580 | AE11: Görüşüldü | AF11: 44660 | AK11: Zeliha Özer | AL11: Betül Demir | AM11: Betül Demir | AP11: Serkan Kutlutürk
A12: 61d7f93fb1d37d9493fdf1ff | B12: Acı Tantuni, Akdeniz (Camişerif Mah.) | C12: =VLOOKUP(A12,import!A:C,3,0) -> DOĞRU | D12: Sokak Lezzetleri | E12: =VLOOKUP(A12,import!A:J,5,0) -> 345 | F12: =VLOOKUP(A12,import!A:J,6,0) -> 40 | G12: =VLOOKUP(A12,import!A:J,7,0) -> 0 | H12: =VLOOKUP(A12,import!A:J,8,0) -> 15 | I12: =VLOOKUP(A12,import!A:J,9,0) -> 15 | J12: =VLOOKUP(A12,import!A:J,10,0) -> 0 | K12: Süleyman Acı | L12: 3242382306 | M12: Akdeniz | N12: Cami Şerif | O12: Camiserif Mah. İstiklal Cad Çınar İşhanı Altı No :24 Akdeniz/Mersin | P12: =VLOOKUP(A12,import!A:P,16,0) -> Geleneksel | R12: TRUE | S12: FALSE | T12: Başka Şubeden Çekilecek | U12: Hatem Soyaslan | V12: Hikmet Avcı | W12: 3281999- / 5394242480 / 6026dd5755fa61c439fcfb44 Acı Tantuni, Akdeniz (Kiremithane Mah.) alınacak | X12: 44579 | Y12: 44588 | AA12: Görüşüldü | AB12: 44579 | AK12: Hatem Soyaslan
A13: 6026dd5755fa61c439fcfb44 | B13: Acı Tantuni, Akdeniz (Kiremithane Mah.) | C13: =VLOOKUP(A13,import!A:C,3,0) -> DOĞRU | D13: Sokak Lezzetleri | E13: =VLOOKUP(A13,import!A:J,5,0) -> 1837 | F13: =VLOOKUP(A13,import!A:J,6,0) -> 50 | G13: =VLOOKUP(A13,import!A:J,7,0) -> 18 | H13: =VLOOKUP(A13,import!A:J,8,0) -> 5 | I13: =VLOOKUP(A13,import!A:J,9,0) -> 23 | J13: =VLOOKUP(A13,import!A:J,10,0) -> 0.78 | K13: Süleyman Acı | L13: 5394242480 | M13: Akdeniz | N13: Kiremithane | O13: Kiremithane Mah.Dr.Cemalettin Tanrıöver Sokak No/9-C Akdeniz,Mersin | P13: =VLOOKUP(A13,import!A:P,16,0) -> Geleneksel | Q13: 16-25 | R13: TRUE | S13: FALSE | T13: Randevu Alındı | U13: Sude Alkan | V13: Hikmet Avcı | W13: telekom karşısı gazişehir mah no337 işletmesi için de çekim ister | X13: 44267 | Y13: 44270 | AA13: Görüşüldü | AB13: 44489 | AK13: Sude Alkan | AP13: Serkan Kutlutürk
A14: 617943787f837320f378cefb | B14: Acı Tantuni, Yenişehir (Gazi Mah.) | C14: =VLOOKUP(A14,import!A:C,3,0) -> DOĞRU | D14: Sokak Lezzetleri | E14: =VLOOKUP(A14,import!A:J,5,0) -> 1424 | F14: =VLOOKUP(A14,import!A:J,6,0) -> 189 | G14: =VLOOKUP(A14,import!A:J,7,0) -> 13 | H14: =VLOOKUP(A14,import!A:J,8,0) -> 2 | I14: =VLOOKUP(A14,import!A:J,9,0) -> 15 | J14: =VLOOKUP(A14,import!A:J,10,0) -> 0.87 | K14: Süleyman Acı | L14: 5394242480 | M14: Yenişehir | N14: Gazi | O14: Gazi Mah.G.M.K Bulvarı No/337 Yenişehir,Mersin | P14: =VLOOKUP(A14,import!A:P,16,0) -> Geleneksel | R14: TRUE | S14: FALSE | T14: Randevu Alındı | U14: Hatem Soyaslan | V14: Hikmet Avcı | W14: çekim yapılmış | X14: 44508 | Y14: 44510 | AA14: Ulaşılamadı | AB14: 44508 | AC14: Görüşüldü | AD14: 44508 | AK14: Zeliha Özer | AL14: Hatem Soyaslan | AP14: Serkan Kutlutürk
A15: 61d5f0ab342ac96ba015df68 | B15: Acılı İskenderun Döner, Tarsus (Caminur Mah.) | C15: =VLOOKUP(A15,import!A:C,3,0) -> DOĞRU | D15: Döner | E15: =VLOOKUP(A15,import!A:J,5,0) -> 281 | F15: =VLOOKUP(A15,import!A:J,6,0) -> 39 | G15: =VLOOKUP(A15,import!A:J,7,0) -> 0 | H15: =VLOOKUP(A15,import!A:J,8,0) -> 26 | I15: =VLOOKUP(A15,import!A:J,9,0) -> 26 | J15: =VLOOKUP(A15,import!A:J,10,0) -> 0 | K15: Osman Aydar | L15: 3246140909 | M15: Tarsus | N15: Caminur | O15: Caminur Mah.801 sokak No:1-A Tarsus,Mersin | P15: =VLOOKUP(A15,import!A:P,16,0) -> Geleneksel | R15: FALSE | S15: FALSE
A16: 603028708364b83200993c49 | B16: Acıpare Fast & Food, Yenişehir (Aydınlıkevler Mah.) | C16: =VLOOKUP(A16,import!A:C,3,0) -> DOĞRU | D16: Burger | E16: =VLOOKUP(A16,import!A:J,5,0) -> 582 | F16: =VLOOKUP(A16,import!A:J,6,0) | G16: =VLOOKUP(A16,import!A:J,7,0) -> 4 | H16: =VLOOKUP(A16,import!A:J,8,0) -> 4 | I16: =VLOOKUP(A16,import!A:J,9,0) -> 8 | J16: =VLOOKUP(A16,import!A:J,10,0) -> 0.5 | K16: Fatih Şentürk | L16: 5079527788 | M16: Yenişehir | N16: Aydınlıkevler | O16: Aydınlıkevler Mah.G.M.K Bulvarı No/402-B Yenişehir,Mersin | P16: =VLOOKUP(A16,import!A:P,16,0) -> Geleneksel | Q16: 0-15 | R16: TRUE | S16: FALSE | T16: Randevu Alındı | U16: İpek Aytaç | V16: Burçin Sezer | W16: eksikleri studyoda yaptırmış. onları mail atacakmış. | X16: 44355 | Y16: 44358 | AA16: Görüşüldü | AB16: 44355 | AK16: İpek Aytaç | AP16: Serkan Kutlutürk
A17: 614eab7b73bb3d6c3ed878ef | B17: Acıyörem Çiğ Köfte, Yenişehir (Çiftlikköy Mah.) | C17: =VLOOKUP(A17,import!A:C,3,0) -> YANLIŞ | D17: Çiğ Köfte | E17: =VLOOKUP(A17,import!A:J,5,0) -> 312 | F17: =VLOOKUP(A17,import!A:J,6,0) | G17: =VLOOKUP(A17,import!A:J,7,0) -> 8 | H17: =VLOOKUP(A17,import!A:J,8,0) -> 3 | I17: =VLOOKUP(A17,import!A:J,9,0) -> 11 | J17: =VLOOKUP(A17,import!A:J,10,0) -> 0.73 | K17: Selçuk Vakitbilir | L17: 5455313302 | M17: Yenişehir | N17: Çiftlikköy | O17: Çiftlikköy Mah.32133 sokak No/1-B Yenişehir,Mersin | P17: =VLOOKUP(A17,import!A:P,16,0) -> Geleneksel | R17: TRUE | S17: FALSE | T17: Randevu Alındı | U17: Betül Demir | V17: Hikmet Avcı | W17: açmadı | X17: 44565 | Y17: 44567 | AA17: Görüşüldü | AB17: 44476 | AC17: Görüşüldü | AD17: 44565 | AE17: Ulaşılamadı | AF17: 44572 | AK17: Gül Değirmenci | AL17: Betül Demir | AM17: Zeliha Özer | AP17: Serkan Kutlutürk
A18: 6198872fa140e20233da85e4 | B18: Ad-Mun Döner, Akdeniz (Mahmudiye Mah.) | C18: =VLOOKUP(A18,import!A:C,3,0) -> DOĞRU | D18: Döner | E18: =VLOOKUP(A18,import!A:J,5,0) -> 87 | F18: =VLOOKUP(A18,import!A:J,6,0) | G18: =VLOOKUP(A18,import!A:J,7,0) -> 7 | H18: =VLOOKUP(A18,import!A:J,8,0) -> 14 | I18: =VLOOKUP(A18,import!A:J,9,0) -> 21 | J18: =VLOOKUP(A18,import!A:J,10,0) -> 0.33 | K18: Hüseyin Güzel | L18: 5528689353 | M18: Akdeniz | N18: Mahmudiye | O18: Mahmudiye Mah.108.Cad No/14-A Akdeniz,Mersin | P18: =VLOOKUP(A18,import!A:P,16,0) -> Geleneksel | R18: TRUE | S18: FALSE | T18: Randevu Alındı | U18: Betül Demir | V18: Burçin Sezer | W18: mehmet bey // açmadı / çekime gidilmemeiş tekrardan randevu alındı | X18: 44558 | Y18: 44561 | AA18: Ulaşılamadı | AB18: 44536 | AC18: Ulaşılamadı | AD18: 44551 | AE18: Görüşüldü | AF18: 44558 | AK18: Hatem Soyaslan | AL18: Sude Alkan | AM18: Zeliha Özer | AN18: Betül Demir | AP18: Serkan Kutlutürk
A19: 5fe63c3571e89c393095c2fa | B19: Ada Et Döner, Yenişehir (Cumhuriyet Mah.) | C19: =VLOOKUP(A19,import!A:C,3,0) -> DOĞRU | D19: Döner | E19: =VLOOKUP(A19,import!A:J,5,0) -> 565 | F19: =VLOOKUP(A19,import!A:J,6,0) -> 34 | G19: =VLOOKUP(A19,import!A:J,7,0) -> 7 | H19: =VLOOKUP(A19,import!A:J,8,0) -> 6 | I19: =VLOOKUP(A19,import!A:J,9,0) -> 13 | J19: =VLOOKUP(A19,import!A:J,10,0) -> 0.54 | K19: Hikmet Hakan Başkan | L19: 3243250293 | M19: Yenişehir | N19: Cumhuriyet | O19: Cumhuriyet Mah.İsmet İnönü Bulvarı 254/B Yenişehir Mersin | P19: =VLOOKUP(A19,import!A:P,16,0) -> Geleneksel | Q19: 0-15 | R19: TRUE | S19: FALSE | T19: Randevu Alındı | U19: Hatem Soyaslan | V19: Burçin Sezer | W19: açmadı \\randevu oluşturuldu//5 ürünü kalmış sadece | X19: 44280 | Y19: 44281 | AP19: Serkan Kutlutürk
A20: 621cfa0f0cf860fb14ef3a1d | B20: Adana Ocakbaşı, Silifke (Göksu Mah.) | C20: =VLOOKUP(A20,import!A:C,3,0) -> DOĞRU | D20: Kebap | E20: =VLOOKUP(A20,import!A:J,5,0) -> 693 | F20: =VLOOKUP(A20,import!A:J,6,0) -> 65 | G20: =VLOOKUP(A20,import!A:J,7,0) -> 0 | H20: =VLOOKUP(A20,import!A:J,8,0) -> 11 | I20: =VLOOKUP(A20,import!A:J,9,0) -> 11 | J20: =VLOOKUP(A20,import!A:J,10,0) -> 0 | K20: Mahmut Arslan | L20: 3247144646 | M20: Silifke | N20: Göksu | O20: Göksu Mah.Fatih Sultan Mehmet Cad.No:15-A Silifke,Mersin | P20: =VLOOKUP(A20,import!A:P,16,0) -> Geleneksel | R20: FALSE | S20: FALSE
A21: 61e054500aa66b3de81593f0 | B21: Adanalı Bekir Usta, Mezitli (Viranşehir Mah.) | C21: =VLOOKUP(A21,import!A:C,3,0) -> DOĞRU | D21: Kebap | E21: =VLOOKUP(A21,import!A:J,5,0) -> 815 | F21: =VLOOKUP(A21,import!A:J,6,0) -> 76 | G21: =VLOOKUP(A21,import!A:J,7,0) -> 0 | H21: =VLOOKUP(A21,import!A:J,8,0) -> 13 | I21: =VLOOKUP(A21,import!A:J,9,0) -> 13 | J21: =VLOOKUP(A21,import!A:J,10,0) -> 0 | K21: Bekir Ekici | L21: 3243588844 | M21: Mezitli | N21: Viranşehir | O21: Viranşehir Mah.3451 Sokak No/8-A Mezitli,Mersin | P21: =VLOOKUP(A21,import!A:P,16,0) -> Geleneksel | R21: TRUE | S21: FALSE | T21: Başka Şubeden Çekilecek | W21: ibrahim bey sadece isim değişikliği oldu eski panelden alın der | AA21: Görüşüldü | AB21: 44585 | AK21: Sude Alkan
A22: 5ff358d8ce622f2f40cd2e9b | B22: Adım 46 Kebap, Mezitli (Merkez Mah.) | C22: =VLOOKUP(A22,import!A:C,3,0) -> DOĞRU | D22: Kebap | E22: =VLOOKUP(A22,import!A:J,5,0) -> 3419 | F22: =VLOOKUP(A22,import!A:J,6,0) -> 90 | G22: =VLOOKUP(A22,import!A:J,7,0) -> 0 | H22: =VLOOKUP(A22,import!A:J,8,0) -> 25 | I22: =VLOOKUP(A22,import!A:J,9,0) -> 25 | J22: =VLOOKUP(A22,import!A:J,10,0) -> 0 | K22: Yıldız Uzcüce | L22: 5304052009 | M22: Mezitli | N22: Merkez | O22: Merkez Mah.52060 Sokak Özkan Yılmaz Apt.NO/ 18 A Mezitli, Mersin | P22: =VLOOKUP(A22,import!A:P,16,0) -> Geleneksel | Q22: 16-25 | R22: TRUE | S22: FALSE | T22: Çekim İstemiyor | W22: şuan istemiyorum belki daha sonra \\ çekim istemiyor.\\şu an ihtiyacım yok dedi./ürünlerin hepsini hazırlamak gerekiyo bize maliyetli geliyo dediler / cenazem var şuan uygun değilim dedi | AC22: Ulaşılamadı | AD22: 44418 | AE22: Ulaşılamadı | AF22: 44495 | AG22: Görüşüldü | AH22: 44560 | AL22: Ravza Eğilmez | AM22: Betül Demir | AN22: Betül Demir | AP22: Serkan Kutlutürk
A23: 60562dab6bf3018ad33586e4 | B23: Adıyaman Çiğ Köfte Hayri Usta, Tarsus (Ergenekon Mah.) | C23: =VLOOKUP(A23,import!A:C,3,0) -> DOĞRU | D23: Çiğ Köfte | E23: =VLOOKUP(A23,import!A:J,5,0) -> 1773 | F23: =VLOOKUP(A23,import!A:J,6,0) -> 67 | G23: =VLOOKUP(A23,import!A:J,7,0) -> 8 | H23: =VLOOKUP(A23,import!A:J,8,0) -> 10 | I23: =VLOOKUP(A23,import!A:J,9,0) -> 18 | J23: =VLOOKUP(A23,import!A:J,10,0) -> 0.44 | K23: Hayri Karakoç | L23: 3246259393 | M23: Tarsus | N23: Ergenekon | O23: Ergenekon Mah.Fatih Sultan Mehmet Bulvarı No/37-C Tarsus, Erdemli | P23: =VLOOKUP(A23,import!A:P,16,0) -> Geleneksel | R23: TRUE | S23: FALSE | T23: Randevu Alındı | U23: Zeliha Özer | V23: Hikmet Avcı | X23: 44300 | Y23: 44301 | AP23: Serkan Kutlutürk
A24: 618d58f6cdedebd544e666a4 | B24: Adıyaman Çiğ Köfte, Akdeniz (Çankaya Mah.-Çarşı) | C24: =VLOOKUP(A24,import!A:C,3,0) -> DOĞRU | D24: Çiğ Köfte | E24: =VLOOKUP(A24,import!A:J,5,0) -> 762 | F24: =VLOOKUP(A24,import!A:J,6,0) -> 61 | G24: =VLOOKUP(A24,import!A:J,7,0) -> 8 | H24: =VLOOKUP(A24,import!A:J,8,0) -> 4 | I24: =VLOOKUP(A24,import!A:J,9,0) -> 12 | J24: =VLOOKUP(A24,import!A:J,10,0) -> 0.67 | K24: Yunus Emre Pamukçu | L24: 5527521733 | M24: Akdeniz | N24: Çankaya | O24: Çankaya Mah.Atatürk 1 Cad.No/26 Akdeniz,Mersin | P24: =VLOOKUP(A24,import!A:P,16,0) -> Geleneksel | R24: TRUE | S24: FALSE | T24: Randevu Alındı | U24: Betül Demir | V24: Hikmet Avcı | W24: çekim sağlanmış | X24: 44526 | Y24: 44529 | AA24: Görüşüldü | AB24: 44526 | AK24: Betül Demir | AP24: Serkan Kutlutürk
A25: 6036aa1b05dd29c17cfede64 | B25: Adıyaman Çiğ Köftecisi Servet Usta, Toroslar (Kurdali Mah.) | C25: =VLOOKUP(A25,import!A:C,3,0) -> DOĞRU | D25: Çiğ Köfte | E25: =VLOOKUP(A25,import!A:J,5,0) -> 564 | F25: =VLOOKUP(A25,import!A:J,6,0) -> 14 | G25: =VLOOKUP(A25,import!A:J,7,0) -> 12 | H25: =VLOOKUP(A25,import!A:J,8,0) -> 2 | I25: =VLOOKUP(A25,import!A:J,9,0) -> 14 | J25: =VLOOKUP(A25,import!A:J,10,0) -> 0.86 | K25: Tarık Han Düşünüklü | L25: 5339134933 | M25: Toroslar | N25: Kurdali | O25: Kurdali Mah.100125 Sokak No/21 Toroslar,Mersin | P25: =VLOOKUP(A25,import!A:P,16,0) -> Geleneksel | Q25: 0-15 | R25: TRUE | S25: FALSE | T25: Randevu Alındı | U25: Zeliha Özer | V25: Burçin Sezer | W25: eksik yok | X25: 44281 | Y25: 44285 | AP25: Serkan Kutlutürk
A26: 61f5274f704da279242021af | B26: Adıyaman Çiğ Köftesi, Tarsus (Şehitler Tepesi Mah.) | C26: =VLOOKUP(A26,import!A:C,3,0) -> DOĞRU | D26: Çiğ Köfte | E26: =VLOOKUP(A26,import!A:J,5,0) -> 174 | F26: =VLOOKUP(A26,import!A:J,6,0) -> 38 | G26: =VLOOKUP(A26,import!A:J,7,0) -> 0 | H26: =VLOOKUP(A26,import!A:J,8,0) -> 16 | I26: =VLOOKUP(A26,import!A:J,9,0) -> 16 | J26: =VLOOKUP(A26,import!A:J,10,0) -> 0 | K26: Ömer Faruk Koyuncu | L26: 5302309957 | M26: Tarsus | N26: Şehitler Tepesi | O26: Şehitler Tepesi Mah.Kasım Ekenler Bulvarı No:207-B Tarsus,Mersin | P26: =VLOOKUP(A26,import!A:P,16,0) -> Geleneksel | R26: FALSE | S26: FALSE
A27: 616daadb1b2b12101fbc719c | B27: Adıyaman Çiğköfte Evi, Toroslar (Zeki Ayan Mah.) | C27: =VLOOKUP(A27,import!A:C,3,0) -> YANLIŞ | D27: Çiğ Köfte | E27: =VLOOKUP(A27,import!A:J,5,0) -> 73 | F27: =VLOOKUP(A27,import!A:J,6,0) | G27: =VLOOKUP(A27,import!A:J,7,0) -> 7 | H27: =VLOOKUP(A27,import!A:J,8,0) -> 0 | I27: =VLOOKUP(A27,import!A:J,9,0) -> 7 | J27: =VLOOKUP(A27,import!A:J,10,0) -> 1 | K27: Muhammet Gazali Arslan | L27: 5526039802 | M27: Toroslar | N27: Zeki Ayan | O27: Zeki Ayan Mah.Kuvayi Milliye Bulvarı No/261-C Toroslar,Mersin | P27: =VLOOKUP(A27,import!A:P,16,0) -> Geleneksel | R27: TRUE | S27: FALSE | T27: Randevu Alındı | U27: Selcan Topçu | V27: Burçin Sezer | W27: 5378779213 mesgul | X27: 44495 | Y27: 44496 | AA27: Yetkili Yok | AB27: 44495 | AC27: Görüşüldü | AD27: 44495 | AK27: Selcan Topçu | AL27: Selcan Topçu | AP27: Serkan Kutlutürk
A28: 609a744d9dabfad14f81496a | B28: Adıyaman Çiğköfte Salih Usta, Tarsus (Gazipaşa Mah.) | C28: =VLOOKUP(A28,import!A:C,3,0) -> DOĞRU | D28: Çiğ Köfte | E28: =VLOOKUP(A28,import!A:J,5,0) -> 81 | F28: =VLOOKUP(A28,import!A:J,6,0) | G28: =VLOOKUP(A28,import!A:J,7,0) -> 0 | H28: =VLOOKUP(A28,import!A:J,8,0) -> 23 | I28: =VLOOKUP(A28,import!A:J,9,0) -> 23 | J28: =VLOOKUP(A28,import!A:J,10,0) -> 0 | K28: Halime Altay | L28: 5316163321 | M28: Tarsus | N28: Gazipaşa | O28: Gazipaşa Mah.M.Akif Ersoy Cad.No/107-F Tarsus,Mersin | P28: =VLOOKUP(A28,import!A:P,16,0) -> Geleneksel | R28: TRUE | S28: FALSE | T28: İleride Randevu Alınacak | U28: Hatem Soyaslan | V28: Hikmet Avcı | X28: 44540 | Y28: 44543 | AA28: Görüşüldü | AB28: 44540 | AK28: Hatem Soyaslan | AP28: Serkan Kutlutürk
A29: 61c4b19704cd9dcf2ac81453 | B29: Adıyamanlı Çiğ Köfte, Toroslar (Osmaniye Mah.) | C29: =VLOOKUP(A29,import!A:C,3,0) -> DOĞRU | D29: Çiğ Köfte | E29: =VLOOKUP(A29,import!A:J,5,0) -> 44 | F29: =VLOOKUP(A29,import!A:J,6,0) -> 12 | G29: =VLOOKUP(A29,import!A:J,7,0) -> 0 | H29: =VLOOKUP(A29,import!A:J,8,0) -> 12 | I29: =VLOOKUP(A29,import!A:J,9,0) -> 12 | J29: =VLOOKUP(A29,import!A:J,10,0) -> 0 | K29: Nuran Kamer | L29: 5372770233 | M29: Toroslar | N29: Osmaniye | O29: OSMANİYE MAH. AV. AHMET BOZ CAD. NO:8 K:1 D:4 TOROSLAR / MERSİN | P29: =VLOOKUP(A29,import!A:P,16,0) -> Geleneksel | R29: TRUE | S29: FALSE | T29: Ulaşılamadı | AA29: Ulaşılamadı | AB29: 44559 | AC29: Ulaşılamadı | AD29: 44656 | AK29: Zeliha Özer | AL29: Sude Alkan
A30: 602ad0999710c010c1d1dfc5 | B30: Adıyamanlı Çiğ Köfteci Hasan Aybak, Akdeniz (Çankaya Mah.) | C30: =VLOOKUP(A30,import!A:C,3,0) -> DOĞRU | D30: Çiğ Köfte | E30: =VLOOKUP(A30,import!A:J,5,0) -> 348 | F30: =VLOOKUP(A30,import!A:J,6,0) -> 36 | G30: =VLOOKUP(A30,import!A:J,7,0) -> 6 | H30: =VLOOKUP(A30,import!A:J,8,0) -> 1 | I30: =VLOOKUP(A30,import!A:J,9,0) -> 7 | J30: =VLOOKUP(A30,import!A:J,10,0) -> 0.86 | K30: Şükrü Erdoğan | L30: 3242338202 | M30: Akdeniz | N30: Çankaya | O30: Çankaya Mah.İstiklal Cad.No/63-C Akdeniz,Mersin | P30: =VLOOKUP(A30,import!A:P,16,0) -> Geleneksel | Q30: 0-15 | R30: TRUE | S30: FALSE | T30: Randevu Alındı | U30: Hatem Soyaslan | V30: Burçin Sezer | X30: 44343 | Y30: 44344 | AA30: Görüşüldü | AB30: 44580 | AK30: Betül Demir | AP30: Serkan Kutlutürk
A31: 602acb366a39b523b96ae197 | B31: Adıyamanlı Çiğ Köfteci Hasan Aybak, Mezitli (Merkez Mah.) | C31: =VLOOKUP(A31,import!A:C,3,0) -> DOĞRU | D31: Çiğ Köfte | E31: =VLOOKUP(A31,import!A:J,5,0) -> 1350 | F31: =VLOOKUP(A31,import!A:J,6,0) -> 62 | G31: =VLOOKUP(A31,import!A:J,7,0) -> 8 | H31: =VLOOKUP(A31,import!A:J,8,0) -> 9 | I31: =VLOOKUP(A31,import!A:J,9,0) -> 17 | J31: =VLOOKUP(A31,import!A:J,10,0) -> 0.47 | K31: Şükrü Erdoğan | L31: 3243590233 | M31: Mezitli | N31: Merkez | O31: Merkez Mah.G.M.K Bulvarı No/800-G Mezitli,Mersin | P31: =VLOOKUP(A31,import!A:P,16,0) -> Geleneksel | Q31: 0-15 | R31: FALSE | S31: FALSE | T31: Franchise | AP31: Serkan Kutlutürk
A32: 60466fa40a4ea4073fb2b2b0 | B32: Adıyamanlı Çiğ Köfteci Hasan Aybak, Tarsus (Öğretmenler Mah.) | C32: =VLOOKUP(A32,import!A:C,3,0) -> DOĞRU | D32: Çiğ Köfte | E32: =VLOOKUP(A32,import!A:J,5,0) -> 858 | F32: =VLOOKUP(A32,import!A:J,6,0) -> 58 | G32: =VLOOKUP(A32,import!A:J,7,0) -> 9 | H32: =VLOOKUP(A32,import!A:J,8,0) -> 4 | I32: =VLOOKUP(A32,import!A:J,9,0) -> 13 | J32: =VLOOKUP(A32,import!A:J,10,0) -> 0.69 | K32: Rukiye Bağcı | L32: 5317615261 | M32: Tarsus | N32: Öğretmenler | O32: Öğretmenler Mah.Dumlupınar Bulvarı No/5-D Tarsus,Mersin | P32: =VLOOKUP(A32,import!A:P,16,0) -> Geleneksel | Q32: 0-15 | R32: FALSE | S32: FALSE | AP32: Serkan Kutlutürk
A33: 60089558f9bae48434535aa8 | B33: Adıyamanlı Çiğ Köftecim, Akdeniz (Mahmudiye Mah.-Çarşı Şube) | C33: =VLOOKUP(A33,import!A:C,3,0) -> DOĞRU | D33: Çiğ Köfte | E33: =VLOOKUP(A33,import!A:J,5,0) -> 671 | F33: =VLOOKUP(A33,import!A:J,6,0) -> 40 | G33: =VLOOKUP(A33,import!A:J,7,0) -> 10 | H33: =VLOOKUP(A33,import!A:J,8,0) -> 2 | I33: =VLOOKUP(A33,import!A:J,9,0) -> 12 | J33: =VLOOKUP(A33,import!A:J,10,0) -> 0.83 | K33: Emre Kaya | L33: 3243370037 | M33: Akdeniz | N33: Mahmudiye | O33: Mahmudiye Mah.Zeytinli Bahçe Cad.No/103-B Akdeniz,Mersin | P33: =VLOOKUP(A33,import!A:P,16,0) -> Geleneksel | Q33: 0-15 | R33: TRUE | S33: FALSE | T33: Randevu Alındı | U33: Funda Ünlü | V33: Burçin Sezer | W33: kendi fotoğrafları var yollayacaklarmış | X33: 44285 | Y33: 44287 | AP33: Serkan Kutlutürk
A34: 6183c05d8b3c8cc7d7acff21 | B34: Adıyamanlı Çiğ Köftecim, Toroslar (Sağlık Mah.) | C34: =VLOOKUP(A34,import!A:C,3,0) -> YANLIŞ | D34: Çiğ Köfte | E34: =VLOOKUP(A34,import!A:J,5,0) | F34: =VLOOKUP(A34,import!A:J,6,0) | G34: =VLOOKUP(A34,import!A:J,7,0) -> 0 | H34: =VLOOKUP(A34,import!A:J,8,0) -> 8 | I34: =VLOOKUP(A34,import!A:J,9,0) -> 8 | J34: =VLOOKUP(A34,import!A:J,10,0) -> 0 | K34: Hacer Demir | L34: 3243207037 | M34: Toroslar | N34: Sağlık | O34: Sağlık Mah.Kuvayi Milliye Bulvarı No/178-A Toroslar,Mersin | P34: =VLOOKUP(A34,import!A:P,16,0) -> Geleneksel | R34: TRUE | S34: FALSE | T34: Dönüş Yapacak | W34: kendileri dönüş yapacaklar henüz paneli açmamışlar | AA34: Ulaşılamadı | AB34: 44508 | AC34: Görüşüldü | AD34: 44511 | AK34: Zeliha Özer | AL34: Ayşegül Kır | AP34: Serkan Kutlutürk
A35: 616e8ff56c1a4d2de2c771db | B35: Adıyamanlı Çiğ Köftecim, Yenişehir (Aydınlıkevler Mah.) | C35: =VLOOKUP(A35,import!A:C,3,0) -> DOĞRU | D35: Çiğ Köfte | E35: =VLOOKUP(A35,import!A:J,5,0) -> 391 | F35: =VLOOKUP(A35,import!A:J,6,0) -> 51 | G35: =VLOOKUP(A35,import!A:J,7,0) -> 8 | H35: =VLOOKUP(A35,import!A:J,8,0) -> 14 | I35: =VLOOKUP(A35,import!A:J,9,0) -> 22 | J35: =VLOOKUP(A35,import!A:J,10,0) -> 0.36 | K35: Elburuz Çözel | L35: 5366813996 | M35: Yenişehir | N35: Aydınlıkevler | O35: Aydınlıkevler Mah.2009 sokak No/11-B Yenişehir,Mersin | P35: =VLOOKUP(A35,import!A:P,16,0) -> Geleneksel | R35: TRUE | S35: FALSE | T35: Randevu İptal | U35: Zeliha Özer | V35: Hikmet Avcı | W35: devam çekimi | X35: 44572 | Y35: 44574 | AA35: Görüşüldü | AB35: 44494 | AC35: Görüşüldü | AD35: 44572 | AK35: Hatem Soyaslan | AL35: Zeliha Özer | AP35: Serkan Kutlutürk
A36: 60139c0fbb98bb5216377bb6 | B36: Adıyamanlı Çiğ Köftecim, Yenişehir (Güvenevler Mah.-Pozcu.) | C36: =VLOOKUP(A36,import!A:C,3,0) -> DOĞRU | D36: Çiğ Köfte | E36: =VLOOKUP(A36,import!A:J,5,0) -> 609 | F36: =VLOOKUP(A36,import!A:J,6,0) -> 14 | G36: =VLOOKUP(A36,import!A:J,7,0) -> 7 | H36: =VLOOKUP(A36,import!A:J,8,0) -> 4 | I36: =VLOOKUP(A36,import!A:J,9,0) -> 11 | J36: =VLOOKUP(A36,import!A:J,10,0) -> 0.64 | K36: Şevket Çetin | L36: 5337266702 | M36: Yenişehir | N36: Güvenevler | O36: İnönü Mah.Gazi Mustafa Kemal Bulvarı No/369-B Yenişehir,Mersin | P36: =VLOOKUP(A36,import!A:P,16,0) -> Geleneksel | Q36: 0-15 | R36: TRUE | S36: FALSE | T36: Randevu Alındı | U36: Hatem Soyaslan | V36: Aykut Gülaslan | W36: panelde tüm fotoğrafları var | X36: 44280 | Y36: 44280 | AP36: Serkan Kutlutürk
A37: 6034127beeb805b0274dfb4e | B37: Adıyamanlı Çiğköfteci Ahmet Usta, (Altaylılar Mah.-Ülküköy) | C37: =VLOOKUP(A37,import!A:C,3,0) -> DOĞRU | D37: Çiğ Köfte | E37: =VLOOKUP(A37,import!A:J,5,0) -> 335 | F37: =VLOOKUP(A37,import!A:J,6,0) | G37: =VLOOKUP(A37,import!A:J,7,0) -> 5 | H37: =VLOOKUP(A37,import!A:J,8,0) -> 6 | I37: =VLOOKUP(A37,import!A:J,9,0) -> 11 | J37: =VLOOKUP(A37,import!A:J,10,0) -> 0.45 | K37: Pakize Aslan | L37: 3246266626 | M37: Tarsus | N37: Altaylılar | O37: Gaziler Mah.Gazi Paşa Bulvarı No/68-B Tarsus, Mersin | P37: =VLOOKUP(A37,import!A:P,16,0) -> Geleneksel | Q37: 0-15 | R37: FALSE | S37: FALSE | AP37: Serkan Kutlutürk
A38: 6155b7955833eea31f13d649 | B38: Adıyamanlı Çiğköfteci Ali Baba, Toroslar (Halkkent Mah.) | C38: =VLOOKUP(A38,import!A:C,3,0) -> DOĞRU | D38: Çiğ Köfte | E38: =VLOOKUP(A38,import!A:J,5,0) -> 1367 | F38: =VLOOKUP(A38,import!A:J,6,0) -> 135 | G38: =VLOOKUP(A38,import!A:J,7,0) -> 9 | H38: =VLOOKUP(A38,import!A:J,8,0) -> 19 | I38: =VLOOKUP(A38,import!A:J,9,0) -> 28 | J38: =VLOOKUP(A38,import!A:J,10,0) -> 0.32 | K38: Ömer Utku Armut | L38: 5510561079 | M38: Toroslar | N38: Halkkent | O38: Halkkent Mah.Köroğlu Cad.No/7 HE Toroslar,Mersin | P38: =VLOOKUP(A38,import!A:P,16,0) -> Geleneksel | R38: TRUE | S38: FALSE | T38: Randevu Alındı | U38: Sude Alkan | V38: Burçin Sezer | W38: açmadı | X38: 44483 | Y38: 44484 | AA38: Görüşüldü | AB38: 44483 | AC38: Ulaşılamadı | AD38: 44559 | AK38: Sude Alkan | AL38: Zeliha Özer | AP38: Serkan Kutlutürk
A39: 6046680319345fcddd41a395 | B39: Adıyamanlı Çiğköfteci Hasan Aybak, (Altaylılar Mah.-Ülküköy) | C39: =VLOOKUP(A39,import!A:C,3,0) -> DOĞRU | D39: Çiğ Köfte | E39: =VLOOKUP(A39,import!A:J,5,0) -> 985 | F39: =VLOOKUP(A39,import!A:J,6,0) -> 63 | G39: =VLOOKUP(A39,import!A:J,7,0) -> 6 | H39: =VLOOKUP(A39,import!A:J,8,0) -> 9 | I39: =VLOOKUP(A39,import!A:J,9,0) -> 15 | J39: =VLOOKUP(A39,import!A:J,10,0) -> 0.4 | K39: Ahmet Bağcı | L39: 5530647233 | M39: Tarsus | N39: Altaylılar | O39: Ergenekon Mah.Fatih Sultan Mehmet Bulvarı No/7B Tarsus,Mersin | P39: =VLOOKUP(A39,import!A:P,16,0) -> Geleneksel | Q39: 0-15 | R39: FALSE | S39: FALSE | AP39: Serkan Kutlutürk
A40: 62433ecb55b5dbf7d4e0443e | B40: Adıyamanlı Çiğköfteci Hasan Aybak, Tarsus (İsmetpaşa Mah.) | C40: =VLOOKUP(A40,import!A:C,3,0) -> DOĞRU | D40: Çiğ Köfte | E40: =VLOOKUP(A40,import!A:J,5,0) -> 79 | F40: =VLOOKUP(A40,import!A:J,6,0) -> 76 | G40: =VLOOKUP(A40,import!A:J,7,0) -> 0 | H40: =VLOOKUP(A40,import!A:J,8,0) -> 10 | I40: =VLOOKUP(A40,import!A:J,9,0) -> 10 | J40: =VLOOKUP(A40,import!A:J,10,0) -> 0 | K40: HATİCE DAL | L40: 3246134373 | M40: Tarsus | N40: Öğretmenler | O40: İsmetpaşa Mah. Rasim Dokur Blv. No:39D Tarsus/Mersin | P40: =VLOOKUP(A40,import!A:P,16,0) -> Geleneksel | R40: FALSE | S40: FALSE
...

Sheet takvim
A1: x | B1: Hedef İlçeler | C1: TARİH | D1: Randevu Alan | E1: ID | F1: RESTORAN | G1: SAAT | H1: İLÇE / MAHALLE | I1: YETKİLİ KİŞİ / TELEFON | J1: ADRES | K1: Notlar | L1: Fotoğraf Adeti | M1: Toplam Ürün | N1: Şubeli | O1: İptal | P1: @
C2: 44270
A3: =E3 -> 5ffc92665f0ab4b544e7da57 | B3: Mezitli Yenişehir Toroslar | C3: Hikmet Avcı | D3: Tuğba Buyur | E3: 5ffc92665f0ab4b544e7da57 | F3: Biber Tantuni, Mezitli (Menderes Mah.) | G3: 0.45833333 | H3: Mezitli / Menderes | I3: İbrahim Bey / 3243575714 | J3: Menderes Mah.Milli Egemenlik Cad.No/34-A Mezitli,Mersin | K3: Fotoğraf Çekimi Yapıldı. | L3: 13 | M3: =VLOOKUP(E3,'Hedef Liste'!A:I,9,false) -> 18 | N3: FALSE | O3: FALSE
A4: =E4 -> 6026d563ff60ad8f5fc077b9 | C4: Hikmet Avcı | D4: Tuğba Buyur | E4: 6026d563ff60ad8f5fc077b9 | F4: Gül 'ün Ev Lezzetleri, Mezitli (Menderes Mah.) | G4: 0.52083333 | H4: Mezitli / Menderes | I4: Hacer Hanım / 5326714792 | J4: Menderes Mah.35404 Sokak No/20-A Mezitli,Mersin | K4: Fotoğraf Çekimi Yapıldı. | L4: 27 | M4: =VLOOKUP(E4,'Hedef Liste'!A:I,9,false) -> 47 | N4: FALSE | O4: FALSE
A5: =E5 -> 601954628ecbe9f3ef5c861c | C5: Hikmet Avcı | D5: Tuğba Buyur | E5: 601954628ecbe9f3ef5c861c | F5: 33 Öz Mersin Tantuni, Mezitli (Viranşehir Mah.) | G5: 0.58333333 | H5: Mezitli / Viranşehir | I5: Mustafa Bey / 5323407091 | J5: Viranşehir mh.milli egemenlik caddesi no11/F - Eski Mezitli Belediye Binası Ve Teb Bankası Arasında 100 mtre aşagıda | K5: Fotoğraf Çekimi Yapıldı. | L5: 13 | M5: =VLOOKUP(E5,'Hedef Liste'!A:I,9,false) -> 10 | N5: FALSE | O5: FALSE
A6: =E6 -> 600d90d6104d8be4f7f2c1b6 | C6: Hikmet Avcı | D6: Tuğba Buyur | E6: 600d90d6104d8be4f7f2c1b6 | F6: Banvit Antakya Döner & Tantuni, Mezitli (Viranşehir Mah.) | G6: 0.66666667 | H6: Mezitli / Viranşehir | I6: Aydın Bey / 5306404320 | J6: Viranşehir Mah.Cengiz Topel Cad.34224 Sokak No/22 Viranşehir,Mezitli | K6: Fotoğraf Çekimi Yapıldı. IPTAL OLDU ÇÜNKÜ FOTO YOK | M6: =VLOOKUP(E6,'Hedef Liste'!A:I,9,false) -> 33 | N6: FALSE | O6: FALSE
A7: =E7 | C7: Hikmet Avcı | N7: FALSE | O7: FALSE
A8: =E8 | N8: FALSE | O8: FALSE
A9: =E9 -> 5ff6332965ba5259742b37c3 | B9: Yenişehir Toroslar Akdeniz | C9: Burçin Sezer | D9: Zeliha Özer | E9: 5ff6332965ba5259742b37c3 | F9: Atakule Kumpir, Yenişehir (Akkent Mah.) | G9: 0.52083333 | H9: Yenişehir /Akkent | I9: Teoman Çetindağ /5377830910 | J9: Akkent Mah.H.Okan Merzeci Bulvarı No/206-207 (Sayapark Avm) Yenişehir,Mersin | L9: 6 | M9: =VLOOKUP(E9,'Hedef Liste'!A:I,9,false) -> 21 | N9: FALSE | O9: FALSE
A10: =E10 -> 5fde3e352a802b2b35fc967c | C10: Burçin Sezer | D10: Zeliha Özer | E10: 5fde3e352a802b2b35fc967c | F10: Göksel Tantuni , Yenişehir (Akkent Mah.) | G10: 0.60416667 | H10: Yenişehir/ Akkent | I10: Begüm Özbey 3243410202 | J10: Akkent mah hüseyin okan merzeci bulvarı Akdeniz avm No: 759 iç kapı no: 220/A Yenişehir/ Mersin serapark avm | L10: 13 | M10: =VLOOKUP(E10,'Hedef Liste'!A:I,9,false) -> 20 | N10: FALSE | O10: FALSE
A11: =E11 -> 602577df9364ae38cbf178d1 | C11: Burçin Sezer | D11: Zeliha Özer | E11: 602577df9364ae38cbf178d1 | F11: Çiko Çiğ Köfte & Kokoreç, Yenişehir (Batıkent Mah.) | G11: 0.66666667 | H11: Yenişehir/ Batıkent | I11: Ercan Onur 5551015533 | J11: Batıkent Mah.Nevit Kodallı Cad.No/69-A Yenişehir,Mersin | L11: 7 | M11: =VLOOKUP(E11,'Hedef Liste'!A:I,9,false) -> #N/A | N11: FALSE | O11: FALSE
A12: =E12 -> 601aa4e6ef295e7d15faa710 | C12: Burçin Sezer | D12: Zeliha Özer | E12: 601aa4e6ef295e7d15faa710 | F12: Petek Pastanesi & Cafe, Yenişehir (Batıkent Mah.) | G12: 17:30 | H12: Yenişehir/ Batıkent | I12: Mehmet Veysel kaçan/3249331399 | J12: Batıkent Mah. İstemihan Talay Caddesi No:163/A Yenişehir/ MERSİN (mersin nefrolojı dıyaliz merkezi karşısı petek patiseri) | K12: Petek patiseri urunleri tamamlanmadi sabah kalanlar cekilecek urunleri sabah cikiyormus | L12: 12 | M12: =VLOOKUP(E12,'Hedef Liste'!A:I,9,false) -> 36 | N12: FALSE | O12: FALSE
A13: =E13 | N13: FALSE | O13: FALSE
A14: =E14 | N14: FALSE | O14: FALSE
A15: =E15 | B15: Yenişehir Mezitli Akdeniz | N15: FALSE | O15: FALSE
A16: =E16 -> 6026dd5755fa61c439fcfb44 | C16: Aykut Gülaslan | D16: Hatem Soyaslan | E16: 6026dd5755fa61c439fcfb44 | F16: Acı Tantuni, Akdeniz (Kiremithane Mah.) | G16: 11:00 | H16: Akdeniz / Kiremithane | I16: Süleyman Bey / 5394242480 | J16: Kiremithane Mah.Dr.Cemalettin Tanrıöver Sokak No/9-C Akdeniz,Mersin | K16: Fotoğraf Çekimi Yapıldı. | L16: 21 | M16: =VLOOKUP(E16,'Hedef Liste'!A:I,9,false) -> 23 | N16: FALSE | O16: FALSE
A17: =E17 -> 600b1ca4e94019dd5eeb32bc | C17: Aykut Gülaslan | D17: Hatem Soyaslan | E17: 600b1ca4e94019dd5eeb32bc | F17: Künefeci Emin Usta, Akdeniz (Kiremithane Mah.) | G17: 12:30 | H17: Akdeniz / Kiremithane | I17: Emin Bey / 5314260033 | J17: Kiremithane Mah.Silifke Cad.No/101 Akdeniz,Mersin | K17: Fotoğraf Çekimi Yapıldı. | L17: 16 | M17: =VLOOKUP(E17,'Hedef Liste'!A:I,9,false) -> 47 | N17: FALSE | O17: FALSE
A18: =E18 -> 602bf01417a37670303595b6 | C18: Aykut Gülaslan | D18: Hatem Soyaslan | E18: 602bf01417a37670303595b6 | F18: Ünlüoğlu Cici Baklava & Künefe, Akdeniz (Kiremithane Mah.) | G18: 14:00 | H18: Akdeniz / Kiremithane | I18: İhsan Bey / 3242371188 | J18: Kiremithane Mah.İstiklal Cad.No/99-A Akdeniz,Mersin | K18: Fotoğraf Çekimi Yapıldı. | L18: 10 | M18: =VLOOKUP(E18,'Hedef Liste'!A:I,9,false) -> 55 | N18: FALSE | O18: FALSE
A19: =E19 -> 5ff77f4a5f2349557873245c | C19: Aykut Gülaslan | D19: Hatem Soyaslan | E19: 5ff77f4a5f2349557873245c | F19: Murat Tantuni , Akdeniz (Hamidiye Mah.) | G19: 16:00 | H19: Akdeniz / Turgutreis | I19: Murat Bey / 5366765210 | J19: Hamidiye Mah.Silifke Cad.Atay Apt No/159 C Akdeniz,Mersin | K19: Fotoğraf Çekimi Yapıldı. | L19: 8 | M19: =VLOOKUP(E19,'Hedef Liste'!A:I,9,false) -> 25 | N19: FALSE | O19: FALSE
A20: =E20 | N20: FALSE | O20: FALSE
A21: =E21 | C21: 44271
A22: =E22 -> 6022ce49c8b9111f8d92a988 | B22: Mezitli Yenişehir Toroslar | C22: Hikmet Avcı | D22: Zeliha Özer | E22: 6022ce49c8b9111f8d92a988 | F22: Nevin Ablanın Mutfağı, Mezitli (Yeni Mah.) | G22: 0.5 | H22: Mezitli /Yeni | I22: Merve Akay /5527790133 | J22: Yeni Mah.Kelveli Cad.No/9-A Mezitli,Mersin | K22: Fotoğraf Çekimi Yapıldı. | L22: 24 | M22: =VLOOKUP(E22,'Hedef Liste'!A:I,9,false) -> #N/A | N22: FALSE | O22: FALSE
A23: =E23 -> 602568c90aeff91b79b89846 | C23: Hikmet Avcı | D23: Tuğba Buyur | E23: 602568c90aeff91b79b89846 | F23: Recep Usta Tantuni & Biftek, Mezitli (Merkez Mah.) | G23: 14:00 | H23: Mezitli / Menderes | I23: Mehmet Ali Bey / 5067513614 | J23: Menderes Mah.G.M.K B ulvarı No/723-B Mezitli,Mersin | K23: Fotoğraf Çekimi Yapıldı. | L23: 13 | M23: =VLOOKUP(E23,'Hedef Liste'!A:I,9,false) -> 17 | N23: FALSE | O23: FALSE
A24: =E24 -> 5ff761d3757a6c3dfa603768 | C24: Hikmet Avcı | D24: Zeliha Özer | E24: 5ff761d3757a6c3dfa603768 | F24: Zeliş Ev Yemekleri, Mezitli (Yeni Mah.) | G24: 0.66666667 | H24: Mezitli /Yeni | I24: Gizem Leman Ülkü /5413876343 | J24: Yeni Mah.33195 Sokak Alp Plaza No/2 A/B Altı Mezitli,Mersin | K24: şuan paket elemanım yok şimdilik iptal edelim vaktim yok | M24: =VLOOKUP(E24,'Hedef Liste'!A:I,9,false) -> 39 | N24: FALSE | O24: FALSE
A25: =E25 -> 6000b3213cc99f3452cdc395 | C25: Hikmet Avcı | D25: Zeliha Özer | E25: 6000b3213cc99f3452cdc395 | F25: Ares Ütü Tost, Mezitli (Yenimahalle Mah.) | G25: 17:30 | H25: mezitli/ yeni | I25: İbrahim Duman /5301203362 | J25: Yeni Mah.Kelveli Cad.Ziya Ünsal Sitesi A-B Blok Altı No/3-A Mezitli,Mersin | L25: 12 | M25: =VLOOKUP(E25,'Hedef Liste'!A:I,9,false) -> #N/A | N25: FALSE | O25: FALSE
A26: =E26 -> 5fdf8c76daff1648a66db3ab | C26: Hikmet Avcı | D26: Zeliha Özer | E26: 5fdf8c76daff1648a66db3ab | F26: Özhan Tantuni & Döner , Mezitli (Atatürk Mah.) | G26: 16:00 | H26: Mezitli /Atatürk | I26: Hasan Pamuk /3243581424 | J26: Atatürk, 31060. Sk., 33340 Mezitli/Mersin | K26: Fotoğraf Çekimi Yapıldı. | L26: 18 | N26: FALSE | O26: FALSE
A27: =E27 | N27: FALSE | O27: FALSE
A28: =E28 -> 5fdf41970654ee6da6e8a3b5 | B28: Yenişehir Toroslar Akdeniz | C28: Burçin Sezer | D28: Zeliha Özer | E28: 5fdf41970654ee6da6e8a3b5 | F28: Çapa Waffle , Yenişehir (Çiftlikköy Mah.) | G28: 0.54166667 | H28: Yenişehir /Çiftlikköy | I28: Mehmet Gazen/5539128499 | J28: Özlem Üniversite konutları 2 B Blok no:63, Üniversite Cd., 33110 Yenişehir | L28: 11 | M28: =VLOOKUP(E28,'Hedef Liste'!A:I,9,false) -> 38 | N28: FALSE | O28: FALSE
A29: =E29 | C29: Burçin Sezer | M29: =VLOOKUP(E29,'Hedef Liste'!A:I,9,false) -> #N/A | N29: FALSE | O29: FALSE
A30: =E30 -> 5fdfa7d0bc2d63483612b950 | C30: Burçin Sezer | D30: Zeliha Özer | E30: 5fdfa7d0bc2d63483612b950 | F30: Baraka Kokoreç & Tantuni , Yenişehir (Akkent Mah.) | G30: 0.66666667 | H30: Yenişehir/Çiftlikköy | I30: Ali Kaya /5384175465 | J30: Akkent Mah.34.Cadde Şimşekler Recidance No/68 BA Yenişehir Mersin | K30: devam çekimi alındı | L30: 13 | M30: =VLOOKUP(E30,'Hedef Liste'!A:I,9,false) -> #N/A | N30: FALSE | O30: FALSE
A31: =E31 -> 5ffcabd15757432cd8db3247 | C31: Burçin Sezer | D31: Emre Dalgıç | E31: 5ffcabd15757432cd8db3247 | F31: 12:15 Tantuni & Döner & Sakatat, Yenişehir (Güvenevler Mah.) | G31: 19.00 | H31: Yenişehir/Güvenevler | I31: Emirhan Ergül / 5525823245 | J31: Güvenevler Mah.1904 Sokak No/6-A Yenişehir,Mersin İşbankası yanı | L31: 18 | M31: =VLOOKUP(E31,'Hedef Liste'!A:I,9,false) -> 50 | N31: FALSE | O31: FALSE
A32: =E32 | N32: FALSE | O32: FALSE
A33: =E33 | N33: FALSE | O33: FALSE
A34: =E34 | B34: Yenişehir Mezitli Akdeniz | N34: FALSE | O34: FALSE
A35: =E35 | C35: Aykut Gülaslan | M35: =VLOOKUP(E35,'Hedef Liste'!A:I,9,false) -> #N/A | N35: FALSE | O35: FALSE
A36: =E36 -> 602589d85bb03e5adf4e33d1 | C36: Aykut Gülaslan | D36: Hatem Soyaslan | E36: 602589d85bb03e5adf4e33d1 | F36: Ciğerci Yakup, Yenişehir (Pirireis Mah.) | G36: 13:00 | H36: Yenişehir / Pirireis | I36: İsmet Bey / 3243289033 | J36: Pirireis Mah.İsmet İnönü Bulvarı No/222-A Yenişehir,Mersin | K36: ramazandan sonra düşünelim dedi | M36: =VLOOKUP(E36,'Hedef Liste'!A:I,9,false) -> 12 | N36: FALSE | O36: FALSE
A37: =E37 -> 60259059fc9e27288db6c1cc | C37: Aykut Gülaslan | D37: Hatem Soyaslan | E37: 60259059fc9e27288db6c1cc | F37: Kokoreçci Ahmet, Yenişehir (Pirireis Mah.) | G37: 15:00 | H37: Yenişehir / Pirireis | I37: Ahmet Bey / 5366473839 | J37: Pirireis Mah. 1115.Sok. No: 3 | K37: eşi rahatsızlanmış | M37: =VLOOKUP(E37,'Hedef Liste'!A:I,9,false) -> 4 | N37: FALSE | O37: FALSE
A38: =E38 -> 60422036133a2988eb41312b | C38: Aykut Gülaslan | D38: Hatem Soyaslan | E38: 60422036133a2988eb41312b | F38: Tutku Tantuni, Yenişehir (Pirireis Mah.) | G38: 15:30 | H38: Yenişehir / Pirireis | I38: Fırat Bey / 5392391864 | J38: Pirireis mahallesi 1116 sokak Hamit Özcan apartmanı altı 21/C Yenişehir Mersin | K38: Fotoğraf Çekimi Yapıldı. | L38: 9 | M38: =VLOOKUP(E38,'Hedef Liste'!A:I,9,false) -> 32 | N38: FALSE | O38: FALSE
A39: =E39 -> 60087a9637de625c30b3eb13 | C39: Aykut Gülaslan | D39: Enes | E39: 60087a9637de625c30b3eb13 | F39: Mersinli Hasan Usta Tantuni, Yenişehir (Hürriyet Mah.) | G39: 17:00 | H39: Yenişehir / Hürriyet | I39: Mustafa Bey / 5323103433 | J39: Hürriyet Mah.İsmet İnönü Bulvarı No/292-A Yenişehir,Mersin | K39: Fotoğraf Çekimi Yapıldı. | L39: 6 | N39: FALSE | O39: FALSE
A40: =E40 | C40: 44272
...

Sheet import
A1: Restaurant ID | B1: Restoran Adı | C1: IsActive | D1: Mutfak | E1: TOPLAM SİPARİŞ | F1: SON 2 HAFTA | G1: RESİMLİ ÜRÜN | H1: RESİMSİZ ÜRÜN | I1: TOPLAM ÜRÜN | J1: Ratio | K1: Yetkili | L1: Telefon | M1: İLÇE | N1: MAHALLE | O1: ADRES | P1: Geleneksel Zincir | Q1: Eklendi mi
A2: 5fe251f6a8ae93f4cfbaa9a3 | B2: Marka Közde Piliç, Mezitli (Menderes Mah.) | C2: DOĞRU | D2: Sokak Lezzetleri | E2: 1958 | F2: 79 | G2: 0 | H2: 15 | I2: 15 | J2: 0 | K2: Cumali Arslan | L2: 3243580767 | M2: Mezitli | N2: Menderes | O2: Menderes, 35415. Sk., 33340 Mezitli/Mersin | P2: Geleneksel | Q2: =COUNTIF('Hedef Liste'!A:A,A2) -> 1
A3: 5fe241e222f5bd501ed7512e | B3: Fiori, Yenişehir (Eğriçam Mah.) | C3: DOĞRU | D3: Pasta & Tatlı | E3: 319 | G3: 6 | H3: 65 | I3: 71 | J3: 0.08 | K3: Ezgi Özyıldırım | L3: 5389540213 | M3: Yenişehir | N3: Eğriçam | O3: Eğriçam mah adnan menderes bulvarı Kıratlı apt no: 170/B Yenişehir/ Mersin | P3: Geleneksel | Q3: =COUNTIF('Hedef Liste'!A:A,A3) -> 1
A4: 5fe21886bbf1bd4c15fae921 | B4: Enjoy Burger House, Mezitli (Menderes Mah.) | C4: DOĞRU | D4: Burger | E4: 8638 | F4: 252 | G4: 29 | H4: 57 | I4: 86 | J4: 0.34 | K4: Halil Yıldızer | L4: 3249992787 | M4: Mezitli | N4: Menderes | O4: A, Menderes Mahallesi, Limon Caddesi No:3, 33340 Mezitli/Mersin | P4: Geleneksel | Q4: =COUNTIF('Hedef Liste'!A:A,A4) -> 1
A5: 5fe38ce222f5bd539ad77ad7 | B5: Hacıbaba ,Yenişehir (İnönü Mah.) | C5: DOĞRU | D5: Ev Yemekleri | E5: 12753 | F5: 224 | G5: 38 | H5: 21 | I5: 59 | J5: 0.64 | K5: Şehmus Ceylan | L5: 4446908 | M5: Yenişehir | N5: İnönü | O5: İnönü Mah. Gazi Mustafa Kemal Blv. M.Akarsu Apt. No:391 A Yenişehir /Mersin | P5: Geleneksel | Q5: =COUNTIF('Hedef Liste'!A:A,A5) -> 1
A6: 5fe39b7035987abb215f3a21 | B6: Köseoğlu Fırın & Mutfak & Patiseri , Yenişehir (Çiftlikköy Mah.) | C6: DOĞRU | D6: Pasta & Tatlı | E6: 630 | F6: 7 | G6: 9 | H6: 17 | I6: 26 | J6: 0.35 | K6: Muhammet Ali Kaya | L6: 5444218611 | M6: Yenişehir | N6: Çiftlikköy | O6: Çiftlikköy Mah. Üniversite Cad. Akademi Plaza 37 nolu bağımsız NO:41 Ak Yenişehir/Mersin | P6: Geleneksel | Q6: =COUNTIF('Hedef Liste'!A:A,A6) -> 1
A7: 5fe40e62879562f5a9cd02a2 | B7: S Katık Döner, Yenişehir (Çiftlikköy Mah.) | C7: DOĞRU | D7: Döner | E7: 12547 | F7: 233 | G7: 5 | H7: 22 | I7: 27 | J7: 0.19 | K7: Ferudun Taçyıldız | L7: 3243610166 | M7: Yenişehir | N7: Çiftlikköy | O7: Çiftlikköy, Üniversite Cd. No:31, 33110 Yenişehir/Mersin | P7: Geleneksel | Q7: =COUNTIF('Hedef Liste'!A:A,A7) -> 1
A8: 5fe79918ad8a3856f9251ffb | B8: Merkez Biftek Tantuni & Döner , Mezitli (Fatih Mah.) | C8: DOĞRU | D8: Döner | E8: 1949 | F8: 83 | G8: 13 | H8: 11 | I8: 24 | J8: 0.54 | K8: Ali Deniz | L8: 3243585088 | M8: Mezitli | N8: Fatih | O8: Fatih Mah.Gazi Mustafa Kemal Bulvarı Dikoğlu Apt.No/575 A Mezitli Mersin | P8: Geleneksel | Q8: =COUNTIF('Hedef Liste'!A:A,A8) -> 1
A9: 5fe885ffac60e870386ccc1c | B9: Lido Pizza, Mezitli (Merkez Mah.) | C9: DOĞRU | D9: Pizza | E9: 1190 | F9: 58 | G9: 73 | H9: 18 | I9: 91 | J9: 0.8 | K9: Deniz Çürük | L9: 3243278587 | M9: Mezitli | N9: Merkez | O9: Merkez Mah.G.M.K Bulvarı Üç Bal Sitesi Altı 882/F Mezitli Mersin | P9: Geleneksel | Q9: =COUNTIF('Hedef Liste'!A:A,A9) -> 1
A10: 5fdf715da8b06d2229a4860f | B10: Eyfel Pastanesi , Yenişehir (Bahçelievler Mah.) | C10: DOĞRU | D10: Dondurma | E10: 1905 | F10: 38 | G10: 67 | H10: 8 | I10: 75 | J10: 0.89 | K10: Burak Abakay | L10: 3243293683 | M10: Yenişehir | N10: Bahçelievler | O10: Bahçelievler mh., no:72, yenişehir | P10: Geleneksel | Q10: =COUNTIF('Hedef Liste'!A:A,A10) -> 1
A11: 5fec4f6737c1db852055a013 | B11: Komagene Etsiz Çiğ Köfte, Yenişehir (Çiftlikköy Mah.) | C11: DOĞRU | D11: Çiğ Köfte | E11: 6228 | F11: 217 | G11: 63 | H11: 3 | I11: 66 | J11: 0.95 | K11: Esra Gonca Parlar | L11: 5308235138 | M11: Yenişehir | N11: Çiftlikköy | O11: ÇİFTLİKKÖY MH. ÜNİVERSİTE CD. NO:31/C | P11: Key | Q11: =COUNTIF('Hedef Liste'!A:A,A11) -> 0
A12: 5fedc3ccf351dc771967517e | B12: McDonald's, İçel (Fevzi Çakmak Mah. Tarsu Avm) | C12: DOĞRU | D12: Burger | E12: 4552 | F12: 146 | G12: 94 | H12: 0 | I12: 94 | J12: 1 | K12: Ömer Tarık Güney | L12: 2123363575 | M12: Tarsus | N12: Fevzi Çakmak | O12: Fevzi Çakmak Mah. Tarsu Alışveriş Merkezi 1.Kat Mağaza No:1090 Tarsus/Mersin | P12: Key | Q12: =COUNTIF('Hedef Liste'!A:A,A12) -> 0
A13: 5feccaf2345867fe5946437a | B13: Ayyıldız Kebap, Tarsus (Altaylılar Mah.- Ülküköy) | C13: DOĞRU | D13: Kebap | E13: 3711 | F13: 118 | G13: 10 | H13: 21 | I13: 31 | J13: 0.32 | K13: Asım Turgut | L13: 5387494964 | M13: Tarsus | N13: Altaylılar | O13: Altaylılar Mah.Orhun Cad.No/67/1-A Tarsus,Mersin | P13: Geleneksel | Q13: =COUNTIF('Hedef Liste'!A:A,A13) -> 1
A14: 5ff4afc458f3ac23d7e7464d | B14: Ketchap Burger, Tarsus (Şehitler Tepesi Mah.) | C14: DOĞRU | D14: Burger | E14: 4383 | F14: 249 | G14: 0 | H14: 25 | I14: 25 | J14: 0 | K14: Alper Beray Günaştı | L14: 5331271200 | M14: Tarsus | N14: Şehitler Tepesi | O14: Kasım Ekenler Bulvarı No/180 A Mahmut Şentut Apt Altı Tarsus,Mersin | P14: Geleneksel | Q14: =COUNTIF('Hedef Liste'!A:A,A14) -> 1
A15: 5ff4ca3a333ef5625db0982c | B15: Cafe Meritalia, Akdeniz (Çankaya Mah.-Çarşı) | C15: DOĞRU | D15: Döner | E15: 1050 | F15: 27 | G15: 17 | H15: 38 | I15: 55 | J15: 0.31 | K15: Faruk Sarica | L15: 5354380909 | M15: Akdeniz | N15: Cami Şerif | O15: Çankaya Mah.4702 Sokak No/13 A Akdeniz, Mersin | P15: Geleneksel | Q15: =COUNTIF('Hedef Liste'!A:A,A15) -> 1
... A26: 5fe6b71c3458672d21458cea | B26: Antakya Döner Alaaddin Gurme, Yenişehir (Çiftlikköy Mah.) | C26: DOĞRU | D26: Döner | E26: 1773 | F26: 96 | G26: 0 | H26: 30 | I26: 30 | J26: 0 | K26: Mehmet Yücel | L26: 3249994248 | M26: Yenişehir | N26: Çiftlikköy | O26: Çiftlikköy Mah.Üniversite Cad.Akademi Plaza 41 AC Yenişehir Mersin | P26: Geleneksel | Q26: =COUNTIF('Hedef Liste'!A:A,A26) -> 1
A27: 5fde3e352a802b2b35fc967c | B27: Göksel Tantuni , Yenişehir (Akkent Mah.) | C27: DOĞRU | D27: Sokak Lezzetleri | E27: 1783 | G27: 12 | H27: 8 | I27: 20 | J27: 0.6 | K27: Beğüm Özbey | L27: 3243410202 | M27: Yenişehir | N27: Akkent | O27: Akkent mah hüseyin okan merzeci bulvarı Akdeniz avm No: 759 iç kapı no: 220/A Yenişehir/ Mersin | P27: Geleneksel | Q27: =COUNTIF('Hedef Liste'!A:A,A27) -> 1
A28: 5fe030d3798e59498934701f | B28: Çorbacım , Yenişehir (Çitflikköy Mah.) | C28: DOĞRU | D28: Sokak Lezzetleri | E28: 2843 | F28: 90 | G28: 0 | H28: 34 | I28: 34 | J28: 0 | K28: Zehra Belge | L28: 5315541881 | M28: Yenişehir | N28: Çiftlikköy | O28: Çiftlikköy, İsmet İnönü Blv. 688 B, 33110 Yenişehir/Mersin | P28: Geleneksel | Q28: =COUNTIF('Hedef Liste'!A:A,A28) -> 1
A29: 5fe65f4ccf33764b3fb351c7 | B29: Karataş Balıkçılık, Yenişehir (Çiftlikköy Mah.) | C29: DOĞRU | D29: Deniz Ürünleri | E29: 465 | F29: 22 | G29: 34 | H29: 34 | I29: 68 | J29: 0.5 | K29: Emel Kan | L29: 5511727320 | M29: Yenişehir | N29: Çiftlikköy | O29: Çiftlikköy Mah.Üniversite Cad.Akademi Plaza 41 AG Yenişehir Mersin | P29: Geleneksel | Q29: =COUNTIF('Hedef Liste'!A:A,A29) -> 1
A30: 5feb41ddf351dc41ab66faaf | B30: McDonald's, Mezitli (Merkez Mah.) | C30: DOĞRU | D30: Burger | E30: 25459 | F30: 731 | G30: 90 | H30: 0 | I30: 90 | J30: 1 | K30: Ömer Tarık Güney | L30: 2123363575 | M30: Mezitli | N30: 75.yıl | O30: Yeni Mahalle, Gazi Mustafa Kemal Bulvarı, Opet Yanı No:728/A Mezitli - Mersin | P30: Key | Q30: =COUNTIF('Hedef Liste'!A:A,A30) -> 0
A31: 5fec5484ad8a389b7825aa08 | B31: Komagene Etsiz Çiğ Köfte, Erdemli (Merkez Mah.) | C31: DOĞRU | D31: Çiğ Köfte | E31: 2676 | F31: 71 | G31: 60 | H31: 3 | I31: 63 | J31: 0.95 | K31: Esra Gonca Parlar | L31: 5305432536 | M31: Erdemli | N31: Merkez 2. Bölge | O31: MERKEZ MH. S. ÇAKMAKOĞLU CD. (1. PLAJ YOLU) NO:19/A | P31: Key | Q31: =COUNTIF('Hedef Liste'!A:A,A31) -> 0
A32: 5ff16664f351dc4322681a97 | B32: Red Buffalo Burger, Yenişehir (Çiftlikköy Mah.) | C32: DOĞRU | D32: Burger | E32: 16137 | F32: 338 | G32: 31 | H32: 15 | I32: 46 | J32: 0.67 | K32: Aytunç Güneş | L32: 5495295522 | M32: Yenişehir | N32: Çiftlikköy | O32: Üniversite Cad.Çiftlikköy Mah.Smart Point Sitesi B blok 48/B Yenişehir, Mersin | P32: Geleneksel | Q32: =COUNTIF('Hedef Liste'!A:A,A32) -> 1
A33: 5fe63c3571e89c393095c2fa | B33: Ada Et Döner, Yenişehir (Cumhuriyet Mah.) | C33: DOĞRU | D33: Döner | E33: 565 | F33: 34 | G33: 7 | H33: 6 | I33: 13 | J33: 0.54 | K33: Hikmet Hakan Başkan | L33: 3243250293 | M33: Yenişehir | N33: Cumhuriyet | O33: Cumhuriyet Mah.İsmet İnönü Bulvarı 254/B Yenişehir Mersin | P33: Geleneksel | Q33: =COUNTIF('Hedef Liste'!A:A,A33) -> 1
A34: 5fe23beed3f42b1acbaf1b12 | B34: Çifte Kumru, Yenişehir (Güvenevler Mah.) | C34: DOĞRU | D34: Burger | E34: 1866 | F34: 95 | G34: 2 | H34: 18 | I34: 20 | J34: 0.1 | K34: Bencemin Uzun | L34: 3243285808 | M34: Yenişehir | N34: Güvenevler | O34: Güvenevler Mahallesi 1910 sokak no:7/B Yenişehir / Mersin | P34: Geleneksel | Q34: =COUNTIF('Hedef Liste'!A:A,A34) -> 1
A35: 5fdf917fa8ae93e23eba0104 | B35: Salaş Ciğer & Kebap, Yenişehir(Akkent Mah.) | C35: YANLIŞ | D35: Kebap | E35: 22 | G35: 0 | H35: 12 | I35: 12 | J35: 0 | K35: Sadettin Arif Satar | L35: 3243414545 | M35: Yenişehir | N35: Akkent | O35: Akkent Mah., Hüseyin Okan Merzeci Blv., No:755E, Yenişehir, Mersin, Türkiye, | P35: Geleneksel | Q35: =COUNTIF('Hedef Liste'!A:A,A35) -> 1
A36: 5fdf3e8e24561e176695d04e | B36: Gül Kafe Plus , Mezitli (Fatih Mah.) | C36: DOĞRU | D36: Pasta & Tatlı | E36: 634 | F36: 23 | G36: 11 | H36: 65 | I36: 76 | J36: 0.14 | K36: Ercan Güzel | L36: 3243255339 | M36: Mezitli | N36: Fatih | O36: Fatih Mah., Adnan Menderes Blv., No:210/B, | P36: Geleneksel | Q36: =COUNTIF('Hedef Liste'!A:A,A36) -> 1
A37: 5fe6590c4f55ab4bbd9c73b5 | B37: Cadde Katık Döner , Yenişehir (İnönü Mah.) | C37: DOĞRU | D37: Döner | E37: 28180 | F37: 1846 | G37: 11 | H37: 40 | I37: 51 | J37: 0.22 | K37: Selman Kaya (Vekaletname Mehmet Karaca) | L37: 3243253131 | M37: Yenişehir | N37: İnönü | O37: İnönü Mah.1405 Sokak Yenişehir ,Mersin | P37: Geleneksel | Q37: =COUNTIF('Hedef Liste'!A:A,A37) -> 1
A38: 5fe112d8a8ae93b4a1ba616b | B38: Enjoy Burger House, Yenişehir (Güvenevler Mah.) | C38: DOĞRU | D38: Burger | E38: 6777 | F38: 127 | G38: 26 | H38: 57 | I38: 83 | J38: 0.31 | K38: Halil Yıldızer | L38: 3243252444 | M38: Yenişehir | N38: Güvenevler | O38: Güvenevler mahallesi 1914 sokak Boss Point İş Merkezi B blok no:5, 33110 Yenişehir/Mersin | P38: Geleneksel | Q38: =COUNTIF('Hedef Liste'!A:A,A38) -> 1
A39: 5fe4f6804743e1ced351b244 | B39: Bizim Kebap, Yenişehir (Güvenevler Mah.) | C39: DOĞRU | D39: Döner | E39: 48490 | F39: 2556 | G39: 19 | H39: 7 | I39: 26 | J39: 0.73 | K39: Hasan Kilisli | L39: 3243268589 | M39: Yenişehir | N39: Güvenevler | O39: Güvenevler mah. , Dumlupınar Cd. No:9, 33140 Yenişehir/Mersin | P39: Geleneksel | Q39: =COUNTIF('Hedef Liste'!A:A,A39) -> 1
A40: 5fe9691871e89c6c8b95fb8d | B40: Çiftlik Cızzgara Közde Piliç & Et Köfte (Çiftlikköy Mah.) | C40: DOĞRU | D40: Tavuk | E40: 6993 | F40: 485 | G40: 15 | H40: 23 | I40: 38 | J40: 0.39 | K40: Emre Akçiçek | L40: 5362426008 | M40: Yenişehir | N40: Çiftlikköy | O40: Çiftlikköy Mah.Üniversite Cad.Ziraat Bankası Karşısı 44 A Yenişehir Mersin | P40: Geleneksel | Q40: =COUNTIF('Hedef Liste'!A:A,A40) -> 1
A41: 5fe0f0fedaff16445f6e1cbc | B41: La Vita Akdeniz Patiseri, Mezitli (Merkez Mah.) | C41: DOĞRU | D41: Pasta & Tatlı | E41: 3089 | F41: 129 | G41: 0 | H41: 84 | I41: 84 | J41: 0 | K41: Benevşe Kayabaşı | L41: 3249337314 | M41: Mezitli | N41: Merkez | O41: Merkez, Vatan Cd. 23 I, 33330 Mezitli/Mersin | P41: Geleneksel | Q41: =COUNTIF('Hedef Liste'!A:A,A41) -> 1
A42: 5fe3af060654ee79e4e913a1 | B42: Göksel Tantuni, Yenişehir (Dumlupınar Mah.) | C42: DOĞRU | D42: Sokak Lezzetleri | E42: 185 | G42: 4 | H42: 7 | I42: 11 | J42: 0.36 | K42: Melike Oğuz | L42: 3243275651 | M42: Yenişehir | N42: Dumlupınar | O42: Dumlupınar, Adnan Menderes Blv. 122/A, 33130 Yenişehir/Mersin | P42: Geleneksel | Q42: =COUNTIF('Hedef Liste'!A:A,A42) -> 1
A43: 5fdf6cb40345d20df07f472d | B43: Eymen Et & Mangal , Yenişehir (Menteş Mah.) | C43: DOĞRU | D43: Kebap | E43: 703 | G43: 6 | H43: 8 | I43: 14 | J43: 0.43 | K43: Tufan Topaktaş | L43: 3243360408 | M43: Yenişehir | N43: Menteş | O43: Menteş mahallesi Nevit kodallı caddesi, 2541. Sk., 33150 Yenişehir | P43: Geleneksel | Q43: =COUNTIF('Hedef Liste'!A:A,A43) -> 1
A44: 5fec62b7f351dc4340671c59 | B44: Komagene Etsiz Çiğ Köfte, Mezitli (Fatih Mah.) | C44: DOĞRU | D44: Çiğ Köfte | E44: 2228 | F44: 108 | G44: 64 | H44: 3 | I44: 67 | J44: 0.96 | K44: Esra Gonca Parlar | L44: 5416362974 | M44: Mezitli | N44: Fatih | O44: FATİH MH. G. MUSTAFA KEMAL BLV. BATMAZ APT. NO:567/A | P44: Key | Q44: =COUNTIF('Hedef Liste'!A:A,A44) -> 0
A45: 5fdf9ee624561e482d95d566 | B45: Kastınmoni Kır Pidesi & Börek Evi, Yenişehir (Çiftlikköy Mah.) | C45: DOĞRU | D45: Pide | E45: 6021 | F45: 370 | G45: 15 | H45: 15 | I45: 30 | J45: 0.5 | K45: Hüseyin Oduncu | L45: 3245020666 | M45: Yenişehir | N45: Çiftlikköy | O45: Çiftlikköy Mh. Üni. Cad. No:41 Akademi Plaza A, 33090 Yenişehir/Mersin | P45: Geleneksel | Q45: =COUNTIF('Hedef Liste'!A:A,A45) -> 1
A46: 5ff358d8ce622f2f40cd2e9b | B46: Adım 46 Kebap, Mezitli (Merkez Mah.) | C46: DOĞRU | D46: Kebap | E46: 3419 | F46: 90 | G46: 0 | H46: 25 | I46: 25 | J46: 0 | K46: Yıldız Uzcüce | L46: 5442081300 | M46: Mezitli | N46: Merkez | O46: Merkez Mah.52060 Sokak Özkan Yılmaz Apt.NO/ 18 A Mezitli, Mersin | P46: Geleneksel | Q46: =COUNTIF('Hedef Liste'!A:A,A46) -> 1
A47: 5ff35dbfee0f720340a8eec4 | B47: Eylül Dondurma & Baklava & Börek, Mezitli (Yeni Mah.) | C47: YANLIŞ | D47: Pasta & Tatlı | E47: 1079 | G47: 5 | H47: 12 | I47: 17 | J47: 0.29 | K47: Burak Güldoğan | L47: 5462064633 | M47: Mezitli | N47: Yeni | O47: Yeni mahalle, 33166. sok, no:14/B, Mezitli, Mersin | P47: Geleneksel | Q47: =COUNTIF('Hedef Liste'!A:A,A47) -> 1
A48: 5ff4bf1ce5886ac1319637ec | B48: Caps Burger, Yenişehir (Çiftlikköy Mah.) | C48: DOĞRU | D48: Burger | E48: 3012 | F48: 159 | G48: 0 | H48: 44 | I48: 44 | J48: 0 | K48: Ali Dağlıoğlu | L48: 5330211305 | M48: Yenişehir | N48: Çiftlikköy | O48: Çiftlikköy Mah.İstemihan Talay Cad.Özlem 1 Üniversite Konutları B blok No/229 Yenişehir,Mersin | P48: Geleneksel | Q48: =COUNTIF('Hedef Liste'!A:A,A48) -> 1
A49: 5ff4c5e6f351dcb550689d91 | B49: Melek Tantuni, Mezitli (Menderes Mah.) | C49: DOĞRU | D49: Sokak Lezzetleri | E49: 2452 | F49: 76 | G49: 12 | H49: 4 | I49: 16 | J49: 0.75 | K49: Osman Özdemir | L49: 5367804567 | M49: Mezitli | N49: Menderes | O49: Menderes Mah.Doğaner Apt.Altı No/709 A blok Mezitli, Mersin | P49: Geleneksel | Q49: =COUNTIF('Hedef Liste'!A:A,A49) -> 1
A50: 5ff8ad273b0c6d0d6a0de500 | B50: Cafe Betül, Yenişehir (Fuat Morel Mah.) | C50: DOĞRU | D50: Burger | E50: 476 | F50: 5 | G50: 29 | H50: 35 | I50: 64 | J50: 0.45 | K50: Barış Baykul | L50: 5323047605 | M50: Yenişehir | N50: Fuatmorel | O50: Fuat Morel Mah.Kanal Yolu 2819 Sokak No/23 Yenişehir,Mersin | P50: Geleneksel | Q50: =COUNTIF('Hedef Liste'!A:A,A50) -> 1
...

Sheet Durum Parametreler
C2: Başka Şubeden Çekilecek | F2: Hikmet Avcı | H2: Mertcan
C3: BlackList | F3: Burçin Sezer | H3: Enes
A4: 44197 | C4: Çekim İstemiyor | F4: Aykut Gülaslan | H4: Ezgi Turan
A5: 44198 | C5: Devir | H5: Hatem Soyaslan
A6: 44199 | C6: Dönüş Yapacak | H6: Zeliha Özer
A7: 44200 | C7: Franchise | H7: Emre Dalgıç
A8: 44201 | C8: İleride Randevu Alınacak | H8: Gül Değirmenci
A9: 44202 | C9: Lokasyon Uzak | H9: Yurdagül Kulaksız
A10: 44203 | C10: Haziran'da Aranacak | F10: Ayşegül Kır | H10: Ayfer Altın
A11: 44204 | C11: Menü Güncellemesi Yapılacak | F11: Betül Demir | H11: Ayşegül Kır
A12: 44205 | C12: Personel Eksik | F12: Hatem Soyaslan | H12: Damla Kılcı
A13: 44206 | C13: Randevu Alındı | F13: Selcan Topçu | H13: Özlem arslan
A14: 44207 | C14: Randevu İptal | F14: Sude Alkan | H14: Beyza gülşah
A15: 44208 | C15: Restoran Silindi | F15: Yurdagül Kulaksız | H15: Özlem gümüş
A16: 44209 | C16: Sistemden Çıkmak İstiyor | F16: Zeliha Özer | H16: Tuğba Buyur
A17: 44210 | C17: Tadilat Var | F17: Ferhat Köksal | H17: Kadriye Polat
A18: 44211 | C18: Ulaşılamadı | F18: Enes Günal | H18: Şükriye Demir
A19: 44212 | C19: Yılbaşından Sonra Aranacak | F19: Serap Apaydın | H19: Ece Bayındır
A20: 44213 | H20: Senanur Çınar
A21: 44214 | H21: Şura Özcan
A22: 44215 | H22: Funda Ünlü
A23: 44216 | H23: Sıla Göksunaz Esen
A24: 44217 | C24: Dönüş Yapacak | H24: Emel Yılmaz
A25: 44218 | C25: Görüşüldü | H25: Ecem Ersöz
A26: 44219 | C26: Tekrar Aranacak | H26: Livanur Elibol
A27: 44220 | C27: Ulaşılamadı | H27: Eda Cıbır
A28: 44221 | C28: Yetkili Yok | H28: Meryem Yalabık
A29: 44222 | H29: Serenay Yalabık
A30: 44223 | C30: Hemen Randevu İstiyorum | H30: Livanur Elibol
A31: 44224 | C31: Fotoğraflarım Var | H31: Meryem Yalabık
A32: 44225 | C32: İleride Randevu İstiyorum | H32: Eda Cıbır
A33: 44226
A34: 44227
A35: 44228 | C35: Randevu Alınabilir
A36: 44229 | C36: Çekim İstemiyor
A37: 44230 | C37: Fotoğrafları Yok - Randevu Alınabilir
A38: 44231 | C38: Fotoğrafları Gönderecek
A39: 44232
A40: 44233
A41: 44234
...

Sheet özet
