Workbook

Sheet Takvim
B1: TARİH | C1: Randevu Alan | D1: ID | E1: RESTORAN | F1: SAAT | G1: İLÇE / MAHALLE | H1: YETKİLİ KİŞİ / TELEFON | I1: ADRES | J1: NOTLAR | K1: Fotoğraf Adeti | L1: Toplam ürün | M1: Şubeli | N1: İptal
B2: 44286
A3: Serdivan Erenler Arifiye | M3: FALSE | N3: FALSE
B4: Burak Kavakçı | C4: Tuğba Buyur | D4: 6007de51e4ab4e0f0b9219a5 | E4: Hey Tost'um (Kemalpaşa Mah) | F4: 0.45833333 | G4: Serdivan/Kemalpaşa | H4: yusuf bey / 5383161453 | I4: Kemalpaşa Mah., Medeniyet Cad., No:9, Serdivan, Sakarya, Türkiye, | L4: =VLOOKUP(D4,'Hedef Liste'!A:I,8,false) -> 25 | M4: FALSE | N4: FALSE
B5: Burak Kavakçı | C5: Beyza gülşah | D5: 601326186c164262e2908d1c | E5: Ada Zurna Mavi Durak (Kemalpaşa Mah.) | F5: 0.54166667 | G5: Serdivan/Kemalpaşa | H5: Behice Hanım/5312105658 | I5: Kemalpaşa Mah., Usta Sok., No:4, Serdivan, Sakarya, Türkiye, Kemalpaşa mah. | L5: =VLOOKUP(D5,'Hedef Liste'!A:I,8,false) -> #N/A | M5: FALSE | N5: FALSE
B6: Burak Kavakçı | C6: Senanur Çınar | D6: 600c2cc2bce91f4701a58c7c | E6: Nap Cafe Restaurant (Kemalpaşa Mah.) | F6: 15:00 | G6: Serdivan/Kemalpaşa | H6: Ali Gülle/5423614452 | I6: Kemalpaşa Mah., Döner Sok., No:24, Serdivan, Sakarya, Türkiye, | J6: RANDEVUSU ALINDI | L6: =VLOOKUP(D6,'Hedef Liste'!A:I,8,false) -> 33 | M6: FALSE | N6: FALSE
B7: Burak Kavakçı | C7: Beyza gülşah | D7: 601e3e8b98337b6e604cf966 | E7: Gece Pilavcısı, Serdivan (İstiklal Mah.) | F7: 17:00 | G7: Serdivan/Kemalpaşa | H7: Tahsin bey/5466116241 | I7: Kemalpaşa Mah., Karabaş Sok., No:12/a, Serdivan, Sakarya, Türkiye, | L7: =VLOOKUP(D7,'Hedef Liste'!A:I,8,false) -> 3 | M7: FALSE | N7: FALSE
M8: FALSE | N8: FALSE
B9: 44287
A10: Serdivan Erenler Arifiye | M10: FALSE | N10: FALSE
B11: Burak Kavakçı | C11: Tuğba Buyur | D11: 60238bc0e36a14486f688337 | E11: Kaşık, Serdivan (Kemalpaşa Mah.) | F11: 0.45833333 | G11: Serdivan/Kemalpaşa | H11: fecri / bey / 5428152528 | I11: Kemalpaşa Mah., Üniversite Cad., No:90, Serdivan, Sakarya, Türkiye, | L11: =VLOOKUP(D11,'Hedef Liste'!A:I,8,false) -> 38 | M11: FALSE | N11: FALSE
B12: Burak Kavakçı | C12: Tuğba Buyur | D12: 6018feb915c6598a5aa42283 | E12: Grill Burger, Serdivan (Kemalpaşa Mah.) | F12: 0.54166667 | G12: Serdivan/Kemalpaşa | H12: yakup bey / 5392575755 | I12: Kemalpaşa Mah., Üniversite Cad., No:31 A Blok Serdivan, Sakarya, Türkiye, | L12: =VLOOKUP(D12,'Hedef Liste'!A:I,8,false) -> #N/A | M12: FALSE | N12: FALSE
B13: Burak Kavakçı | C13: Beyza gülşah | D13: 6008a4ecf69aa44a794721da | E13: Tok Burger (Kemalpaşa Mah) | F13: 15:00 | G13: Serdivan/Kemalpaşa | H13: ertuğrul bey/2642110855 | I13: Kemalpaşa Mah., Dağköy Sok., No:31A, Serdivan, Sakarya, Türkiye, | L13: =VLOOKUP(D13,'Hedef Liste'!A:I,8,false) -> #N/A | M13: FALSE | N13: FALSE
B14: Burak Kavakçı | C14: Beyza gülşah | D14: 600c9d22276d0f3cf87a6431 | E14: Adı Civan Izgara (Kemalpaşa Mah.) | F14: 17:30 | G14: Serdivan/Kemalpaşa | H14: Harun Bey/5443291390 | I14: Kemalpaşa Mah., Atak Sok., No:1, Serdivan, Sakarya, Türkiye, | L14: =VLOOKUP(D14,'Hedef Liste'!A:I,8,false) -> #N/A | M14: FALSE | N14: FALSE
M15: FALSE | N15: FALSE
B16: 44288
A17: Serdivan Erenler Arifiye | M17: FALSE | N17: FALSE
B18: Burak Kavakçı | C18: Tuğba Buyur | D18: 601dcb046d12e94755486a92 | E18: Pizza & Kebap House (Bahçelievler Mah.) | F18: 0.45833333 | G18: serdivan / bahçelievler | H18: ömer bey / 5418157310 | I18: Kirişhane Cad., No:93/B, Serdivan, Sakarya, Türkiye, | L18: =VLOOKUP(D18,'Hedef Liste'!A:I,8,false) -> 135 | M18: FALSE | N18: FALSE
B19: Burak Kavakçı | C19: Tuğba Buyur | D19: 6043383fb8edc7e4780fdeb9 | E19: Yagoda, Serdivan (Kemalpaşa Mah.) | F19: 0.54166667 | G19: Serdivan/Kemalpaşa | H19: onur bey / 5535491624 | I19: Kemalpaşa Mah., 105 Sok., No:3, serdivan | L19: =VLOOKUP(D19,'Hedef Liste'!A:I,8,false) -> 26 | M19: FALSE | N19: FALSE
B20: Burak Kavakçı | C20: Tuğba Buyur | D20: 603dfbbcb3d2c3527538f8a3 | E20: Ada Yakamoz Tantuni, Serdivan (Kemalpaşa Mah.) | F20: 15:00 | G20: Serdivan/Kemalpaşa | H20: ömer faruk / 5395537433 | I20: Kemalpaşa Mah., Üniversite Cad., No:39, Serdivan, Sakarya, Türkiye, | L20: =VLOOKUP(D20,'Hedef Liste'!A:I,8,false) -> 25 | M20: FALSE | N20: FALSE
B21: Burak Kavakçı | C21: Tuğba Buyur | D21: 60080b4535cc59210bfdceb4 | E21: Sakarya Kahve Akademisi (Bahçelievler Mah.) | F21: 17:00 | G21: serdivan / bahçelievler | H21: enes bey / 5511608118 | I21: Bahçelievler Mah. Muhsin Yazıcıoğlu Blv. No:12/B Serdivan/Sakarya | L21: =VLOOKUP(D21,'Hedef Liste'!A:I,8,false) -> #N/A | M21: FALSE | N21: FALSE
M22: FALSE | N22: FALSE
B23: 44293
A24: Serdivan Erenler Arifiye | M24: FALSE | N24: FALSE
B25: Burak Kavakçı | L25: =VLOOKUP(D25,'Hedef Liste'!A:I,8,false) -> #N/A | M25: FALSE | N25: FALSE
B26: Burak Kavakçı | C26: Özlem arslan | D26: 604bdaf14df8547dc705cc8f | E26: Colombia Coffee, Serdivan (İstiklal Mah.) | F26: 0.47916667 | G26: Serdivan Kemalpaşa | H26: Gürkan Bukan 2642101351 | I26: Kemalpaşa Mah. Bağlar Cad., No:108, Serdivan, Sakarya, Türkiye, | L26: =VLOOKUP(D26,'Hedef Liste'!A:I,8,false) -> #N/A | M26: FALSE | N26: FALSE
B27: Burak Kavakçı | C27: Özlem arslan | D27: 604bdc1f6b5424e15d1b196d | E27: Coffee And Study, Serdivan (Kemalpaşa Mah.) | F27: 13:00 | G27: Serdivan İstiklal | H27: Gürkan Bukan 2642111910 | I27: İstiklal Bağlar Cad., No:81, , Sakarya, Türkiye, | L27: =VLOOKUP(D27,'Hedef Liste'!A:I,8,false) -> #N/A | M27: FALSE | N27: FALSE
B28: Burak Kavakçı | C28: Özlem arslan | D28: 600c2cc2bce91f4701a58c7c | E28: Nap Cafe Restaurant (Kemalpaşa Mah.) | F28: 14:00 | G28: Serdivan Kemalpaşa | H28: Ali Gülle 5423614452 | I28: Kemalpaşa Mah., Döner Sok., No:24, Serdivan, Sakarya, Türkiye, | L28: =VLOOKUP(D28,'Hedef Liste'!A:I,8,false) -> 33 | M28: FALSE | N28: FALSE
B29: Burak Kavakçı | C29: Özlem arslan | D29: 600fb7f98ee57e780c400d55 | E29: Serdivan Osmanoğulları Pide ve Börek (Kemalpaşa Mah.) | F29: 0.64583333 | G29: Serdivan Kemalpaşa | H29: Ramazan Arslan 2642114911 | I29: Kemalpaşa mah. Bağlar Cad., No:96, Serdivan, Sakarya, Türkiye, | M29: FALSE | N29: FALSE
B30: 44294
A31: Serdivan Erenler Arifiye | M31: FALSE | N31: FALSE
B32: Zeynep Yazıcı | C32: Nazlıcan Dinçer | D32: 6023a20a966d0a269bdba8d0 | E32: Pir Kebap Lahmacun & Pide, Erenler (Hacıoğlu Mah.) | F32: 11.00 | G32: Erenler/Dilmen | H32: Ali PİR 2642414190 | I32: Sakarbaba Cad., No:39, Erenler, Sakarya, Türkiye, | L32: =VLOOKUP(D32,'Hedef Liste'!A:I,8,false) -> 9 | M32: FALSE | N32: FALSE
B33: Zeynep Yazıcı | C33: Nazlıcan Dinçer | D33: 6047489cb997c40ee71bd0b4 | E33: Tezgeller Kebap & Pide, Erenler (Hacıoğlu Mah.) | F33: 13.00 | G33: Erenler Hacıoğlu | H33: RAMAZAN TEZGEL 5362504936 | I33: Mehmet Akif Ersoy Cad., No:5, Erenler, Sakarya, Türkiye, | L33: =VLOOKUP(D33,'Hedef Liste'!A:I,8,false) -> 6 | M33: FALSE | N33: FALSE
B34: Zeynep Yazıcı | C34: Mertcan | D34: 60409e4bdc8b325656c3c30d | E34: Ay Dons Döner, Erenler (Erenler Mah.) | F34: 15.00 | G34: erenler erenler | H34: yunus kara 5537510354 | I34: Erenler Mah., Erenler Cad., No:8, Erenler, Sakarya, Türkiye, | L34: =VLOOKUP(D34,'Hedef Liste'!A:I,8,false) -> 5 | M34: FALSE | N34: FALSE
B35: Zeynep Yazıcı | C35: Mertcan | D35: 6040a753703aca4cacfed352 | E35: Tarihi Roma Dondurması, Erenler (Hacıoğlu Mah.) | F35: 18:00 | G35: erenler hacıoğlu | H35: ali erdemir 5399342723 | I35: Erenler Mah., Evliya Çelebi Cad no :9 ., Erenler, Sakarya, Türkiye, | J35: randevu gununu yanlıs anlamıs 28.04 e randevu alındı | L35: =VLOOKUP(D35,'Hedef Liste'!A:I,8,false) -> 1 | M35: FALSE | N35: FALSE
M36: FALSE | N36: FALSE
B37: 44295
A38: Serdivan Erenler Arifiye | B38: Zeynep Yazıcı | C38: Nazlıcan Dinçer | D38: 60432d259cc87d5877132ab8 | E38: Şulenin Mutfağı, Serdivan (Arabacı Alanı Mah.) | F38: 11.00 | G38: Serdivan Arabacıalanı | H38: Şule Tufan 5373801343 | I38: Arabacıalanı Mah., Mert Sok., No:34, Serdivan, Sakarya, Türkiye, | M38: FALSE | N38: FALSE
B39: Zeynep Yazıcı | C39: Nazlıcan Dinçer | D39: 6018f7dbf8fb0bd076faac18 | E39: Urfaca Kebap, Serdivan (Arabacı Alanı Mah.) | F39: 12.00 | G39: Serdivan Arabacıalanı | H39: Kemal Keskinkılıç 5439206234 | I39: Çark Cad., No:306, Sakarya, Türkiye, | L39: =VLOOKUP(D39,'Hedef Liste'!A:I,8,false) -> 36 | M39: FALSE | N39: FALSE
B40: Zeynep Yazıcı | C40: Nazlıcan Dinçer | D40: 601004900354af7f0e855490 | E40: Hira Lezzet Dünyası (Arabacıalanı Mah.) | F40: 14.00 | G40: Serdivan Arabacıalanı | H40: Raziye Özcan 5376679654 | I40: Arabacıalanı Mah., Mert Sok., No:22, Serdivan, Sakarya, Türkiye, | L40: =VLOOKUP(D40,'Hedef Liste'!A:I,8,false) -> #N/A | M40: FALSE | N40: FALSE
...

Sheet Hedef Liste
A1: Restaurant ID | B1: Restoran Adı | C1: Satışa Açık Mı? | D1: Mutfak | E1: TOPLAM SİPARİŞ | F1: SON 2 HAFTA | G1: RESİMLİ ÜRÜN | H1: RESİMSİZ ÜRÜN | I1: TOPLAM ÜRÜN | J1: Ratio | K1: Yetkili | L1: Telefon | M1: İLÇE | N1: MAHALLE | O1: ADRES | P1: Geleneksel Zincir | Q1: FOTOĞRAF SEGMENT | R1: Aradık Mı? | S1: Kendi Fotosu Var | T1: Randevu Durumu | U1: Randevu Alan | V1: Fotoğrafçı | W1: Not | X1: Randevu Alma Tarihi | Y1: Randevu Tarihi | Z1: Anket Durum | AA1: 1. Arama | AB1: 1. Arama Tarihi | AC1: 2. Arama | AD1: 2. Arama Tarihi | AE1: 3. Arama | AF1: 3. Arama Tarihi | AG1: 4. Arama | AH1: 4. Arama Tarihi | AI1: 5. Arama | AJ1: 5. Arama Tarihi | AK1: 1. Arayan | AL1: 2. Arayan | AM1: 3. Arayan | AN1: 4. Arayan | AO1: 5. Arayan | AP1: SY | AQ1: SY - Durum
A2: 6092b55667cf30580ff7cc00 | B2: @'li Burger (Arabacıalanı Mah.) | C2: =VLOOKUP(A2,import!A:C,3,0) -> YANLIŞ | D2: Burger | E2: =VLOOKUP(A2,import!A:AA,5,0) | F2: =VLOOKUP(A2,import!A:AA,6,0) | G2: =VLOOKUP(A2,import!A:AA,7,0) -> 15 | H2: =VLOOKUP(A2,import!A:AA,8,0) -> 4 | I2: =VLOOKUP(A2,import!A:AA,9,0) -> 19 | J2: =VLOOKUP(A2,import!A:AA,10,0) -> 0.79 | K2: Tolga İkiz | L2: 5394067198 | M2: Serdivan | N2: Arabacıalanı | O2: Arabacıalanı Mah., Mert Sok., Serdivan, Sakarya, Türkiye, | P2: =VLOOKUP(A2,import!A:P,16,0) -> Geleneksel | R2: TRUE | S2: TRUE | W2: bu şube daha inşaatta dedi. / hala inşaattaymış daha sonra tekrara aransın. | AA2: Görüşüldü | AB2: 44379 | AK2: Gül Değirmenci | AP2: Simge Demiray
A3: 61de9e5080ca03e293095ca7 | B3: 54 Han Kebap | C3: =VLOOKUP(A3,import!A:C,3,0) -> DOĞRU | D3: Kebap | E3: =VLOOKUP(A3,import!A:AA,5,0) -> 120 | F3: =VLOOKUP(A3,import!A:AA,6,0) | G3: =VLOOKUP(A3,import!A:AA,7,0) -> 0 | H3: =VLOOKUP(A3,import!A:AA,8,0) -> 41 | I3: =VLOOKUP(A3,import!A:AA,9,0) -> 41 | J3: =VLOOKUP(A3,import!A:AA,10,0) -> 0 | K3: MEHMET EMİN KARAGÖZ | L3: 5380593677 | M3: Serdivan | N3: Esentepe | O3: Kemalpaşa Mah., Medeniyet Cad., No:21, Serdivan, Sakarya, Türkiye, | P3: =VLOOKUP(A3,import!A:P,16,0) -> Geleneksel | R3: TRUE | S3: FALSE | T3: Tadilat Var | W3: Tadilat varmış önümüzdeki hafta bitecekmiş tadilatı | AA3: Görüşüldü | AB3: 44606 | AK3: Enes Günal
A4: 600bdf5fd6c5917679df8e5e | B4: 6Nova Aperatif (İstiklal Mah.) | C4: =VLOOKUP(A4,import!A:C,3,0) -> DOĞRU | D4: Tost & Sandviç | E4: =VLOOKUP(A4,import!A:AA,5,0) -> 563 | F4: =VLOOKUP(A4,import!A:AA,6,0) | G4: =VLOOKUP(A4,import!A:AA,7,0) -> 12 | H4: =VLOOKUP(A4,import!A:AA,8,0) -> 15 | I4: =VLOOKUP(A4,import!A:AA,9,0) -> 27 | J4: =VLOOKUP(A4,import!A:AA,10,0) -> 0.44 | K4: SERAP AKAGÜNDÜZ | L4: 5436606666 | M4: Serdivan | N4: İstiklal | O4: Muhsin Yazıcıoğlu Blv., No:69, Serdivan, Sakarya, Türkiye, | P4: =VLOOKUP(A4,import!A:P,16,0) -> Geleneksel | R4: TRUE | S4: FALSE | T4: Randevu Alındı | U4: Ezgi Turan | V4: Zeynep Yazıcı | W4: no67 çekimler yapılmış tüm ürünlerin sadece gönderilen fotoğrafların düzenlenmesi gerekiyormuş | X4: 44299 | Y4: 44300 | AA4: Görüşüldü | AB4: 44363 | AK4: Tutku Erdoğan | AP4: Simge Demiray
A5: 621e1757fc019f60a9fc1be2 | B5: 7/24 Çorbacı (Şirinevler Mah.) | C5: =VLOOKUP(A5,import!A:C,3,0) -> DOĞRU | D5: Sokak Lezzetleri | E5: =VLOOKUP(A5,import!A:AA,5,0) -> 46 | F5: =VLOOKUP(A5,import!A:AA,6,0) -> 20 | G5: =VLOOKUP(A5,import!A:AA,7,0) -> 0 | H5: =VLOOKUP(A5,import!A:AA,8,0) -> 20 | I5: =VLOOKUP(A5,import!A:AA,9,0) -> 20 | J5: =VLOOKUP(A5,import!A:AA,10,0) -> 0 | K5: REŞAT ULUSİNAN | L5: 5493773444 | M5: Adapazarı | N5: Şirinevler | O5: Adnan Menderes Cad., No:194, Adapazarı, Sakarya, Türkiye, | P5: =VLOOKUP(A5,import!A:P,16,0) -> Geleneksel | R5: FALSE | S5: FALSE
A6: 606da86221d646e339348c59 | B6: Ada Börek & Çiğ Köfte, Erenler (Dilmen Mah. | C6: =VLOOKUP(A6,import!A:C,3,0) -> YANLIŞ | D6: Börek | E6: =VLOOKUP(A6,import!A:AA,5,0) -> 44 | F6: =VLOOKUP(A6,import!A:AA,6,0) | G6: =VLOOKUP(A6,import!A:AA,7,0) -> 7 | H6: =VLOOKUP(A6,import!A:AA,8,0) -> 11 | I6: =VLOOKUP(A6,import!A:AA,9,0) -> 18 | J6: =VLOOKUP(A6,import!A:AA,10,0) -> 0.39 | K6: Recep Rençber | L6: 5428330750 | M6: Erenler | N6: Dilmen | O6: Dilmen Mah Sakarbaba Cad., No:93, Erenler, Sakarya, Türkiye, | P6: =VLOOKUP(A6,import!A:P,16,0) -> Geleneksel | R6: TRUE | S6: FALSE | T6: Randevu Alındı | U6: Eda Cıbır | V6: Zeynep Yazıcı | W6: teyit için ulaşılamadı | X6: 44314 | Y6: 44315 | AP6: Simge Demiray
A7: 6258563e70d10b86e62acdff | B7: Ada Çiğ Köfte (Bağlar Mah.) | C7: =VLOOKUP(A7,import!A:C,3,0) -> DOĞRU | D7: Çiğ Köfte | E7: =VLOOKUP(A7,import!A:AA,5,0) | F7: =VLOOKUP(A7,import!A:AA,6,0) | G7: =VLOOKUP(A7,import!A:AA,7,0) -> 0 | H7: =VLOOKUP(A7,import!A:AA,8,0) -> 4 | I7: =VLOOKUP(A7,import!A:AA,9,0) -> 4 | J7: =VLOOKUP(A7,import!A:AA,10,0) -> 0 | K7: SEMA KAHRAMAN | L7: 5417338374 | M7: Erenler | N7: Bağlar | O7: Bağlar Mah., Yıldız Tepe Cad., Erenler, Sakarya, Türkiye, | P7: =VLOOKUP(A7,import!A:P,16,0) -> Geleneksel | R7: FALSE | S7: FALSE
A8: 6256bda8f82cc64423844ed8 | B8: Ada Döner (Cumhuriyet Mah.) | C8: =VLOOKUP(A8,import!A:C,3,0) -> DOĞRU | D8: Döner | E8: =VLOOKUP(A8,import!A:AA,5,0) | F8: =VLOOKUP(A8,import!A:AA,6,0) | G8: =VLOOKUP(A8,import!A:AA,7,0) -> 0 | H8: =VLOOKUP(A8,import!A:AA,8,0) -> 20 | I8: =VLOOKUP(A8,import!A:AA,9,0) -> 20 | J8: =VLOOKUP(A8,import!A:AA,10,0) -> 0 | K8: BAHADDİN YILDIZ | L8: 5354313106 | M8: Adapazarı | N8: Semerciler | O8: Semerciler Mah., Saraçlar Sok., No:52, Adapazarı, Sakarya, Türkiye, | P8: =VLOOKUP(A8,import!A:P,16,0) -> Geleneksel | R8: FALSE | S8: FALSE
A9: 6012d02582ce14688957e9aa | B9: Ada Dönercim | C9: =VLOOKUP(A9,import!A:C,3,0) -> DOĞRU | D9: Döner | E9: =VLOOKUP(A9,import!A:AA,5,0) -> 3106 | F9: =VLOOKUP(A9,import!A:AA,6,0) -> 104 | G9: =VLOOKUP(A9,import!A:AA,7,0) -> 12 | H9: =VLOOKUP(A9,import!A:AA,8,0) -> 9 | I9: =VLOOKUP(A9,import!A:AA,9,0) -> 21 | J9: =VLOOKUP(A9,import!A:AA,10,0) -> 0.57 | K9: Çetin Ayaz | L9: 5338174818 | M9: Adapazarı | N9: Yenidoğan | O9: Yenidoğan Mah. Saray Bosna Cad. No:50/B Adapazarı, Sakarya | P9: =VLOOKUP(A9,import!A:P,16,0) -> Geleneksel | R9: TRUE | S9: FALSE | T9: Randevu Alındı | U9: Ezgi Turan | V9: Zeynep Yazıcı | W9: Çekim gerçeklemiş eksik ürün yok. | X9: 44363 | Y9: 44368 | AP9: Simge Demiray
A10: 60103af58ee57e1999402aa0 | B10: Ada Kabak(Orta Mah.) | C10: =VLOOKUP(A10,import!A:C,3,0) -> DOĞRU | D10: Kebap | E10: =VLOOKUP(A10,import!A:AA,5,0) -> 30 | F10: =VLOOKUP(A10,import!A:AA,6,0) | G10: =VLOOKUP(A10,import!A:AA,7,0) -> 10 | H10: =VLOOKUP(A10,import!A:AA,8,0) -> 10 | I10: =VLOOKUP(A10,import!A:AA,9,0) -> 20 | J10: =VLOOKUP(A10,import!A:AA,10,0) -> 0.5 | K10: Süleyman Çubukçuoğlu | L10: 5425839950 | M10: Adapazarı | N10: Orta | O10: Orta Mah., Çeşme Meydanı Cad., No:66, Adapazarı, Sakarya, Türkiye, | P10: =VLOOKUP(A10,import!A:P,16,0) -> Geleneksel | R10: TRUE | S10: FALSE | T10: Randevu Alındı | U10: Ezgi Turan | V10: Zeynep Yazıcı | W10: DEVAM ÇEKİMİ | X10: 44340 | Y10: 44340 | AP10: Simge Demiray
A11: 601fabc09f03555ba9b64ec1 | B11: Ada Lezzet Kampüs Dürüm, Serdivan (Kemalpaşa Mah.) | C11: =VLOOKUP(A11,import!A:C,3,0) -> YANLIŞ | D11: Döner | E11: =VLOOKUP(A11,import!A:AA,5,0) -> 366 | F11: =VLOOKUP(A11,import!A:AA,6,0) | G11: =VLOOKUP(A11,import!A:AA,7,0) -> 0 | H11: =VLOOKUP(A11,import!A:AA,8,0) -> 24 | I11: =VLOOKUP(A11,import!A:AA,9,0) -> 24 | J11: =VLOOKUP(A11,import!A:AA,10,0) -> 0 | K11: Samir Allahverdiyev | L11: 5525305454 | M11: Serdivan | N11: Kemalpaşa | O11: Kemalpaşa Mah., Üniversite Cad., No:50, Serdivan, Sakarya, Türkiye, | P11: =VLOOKUP(A11,import!A:P,16,0) -> Geleneksel | R11: TRUE | S11: FALSE | T11: Ulaşılamadı | W11: Telefonu Kapalı. | AA11: Ulaşılamadı | AB11: 44350 | AC11: Ulaşılamadı | AD11: 44351 | AE11: Ulaşılamadı | AF11: 44358 | AG11: Ulaşılamadı | AH11: 44368 | AI11: Ulaşılamadı | AJ11: 44405 | AK11: Ecem Ünal | AL11: Gül Değirmenci | AM11: Tutku Erdoğan | AN11: Nazlıcan Dinçer | AO11: Nazlıcan Dinçer | AP11: Simge Demiray
A12: 607e8d16191de0cbdba20784 | B12: Ada Midye Gurme Lezzetleri & Çiğ Köfte (Arabacıalanı Mah.) | C12: =VLOOKUP(A12,import!A:C,3,0) -> YANLIŞ | D12: Sokak Lezzetleri | E12: =VLOOKUP(A12,import!A:AA,5,0) -> 21 | F12: =VLOOKUP(A12,import!A:AA,6,0) | G12: =VLOOKUP(A12,import!A:AA,7,0) -> 0 | H12: =VLOOKUP(A12,import!A:AA,8,0) -> 6 | I12: =VLOOKUP(A12,import!A:AA,9,0) -> 6 | J12: =VLOOKUP(A12,import!A:AA,10,0) -> 0 | K12: Emir Ali Çakıcı | L12: 5528283210 | M12: Serdivan | N12: Arabacıalanı | O12: Arabacıalanı Mah., Şehit Kemal Durak Sok., No:33, Serdivan, Sakarya, Türkiye, | P12: =VLOOKUP(A12,import!A:P,16,0) -> Geleneksel | R12: TRUE | S12: FALSE | T12: Sistemden Çıkmak İstiyor | AP12: Simge Demiray
A13: 607e8d23d415f0b185ad3f9e | B13: Ada Midye Gurme Lezzetleri & Çiğ Köfte (Yeni Mah.) | C13: =VLOOKUP(A13,import!A:C,3,0) -> DOĞRU | D13: Sokak Lezzetleri | E13: =VLOOKUP(A13,import!A:AA,5,0) -> 14 | F13: =VLOOKUP(A13,import!A:AA,6,0) | G13: =VLOOKUP(A13,import!A:AA,7,0) -> 0 | H13: =VLOOKUP(A13,import!A:AA,8,0) -> 5 | I13: =VLOOKUP(A13,import!A:AA,9,0) -> 5 | J13: =VLOOKUP(A13,import!A:AA,10,0) -> 0 | K13: Emir Ali Çakıcı | L13: 5528283210 | M13: Serdivan | N13: Arabacıalanı | O13: Arabacıalanı Mah., Eski Kazımpaşa Cad., No:203A , Serdivan, Sakarya, Türkiye, | P13: =VLOOKUP(A13,import!A:P,16,0) -> Geleneksel | R13: TRUE | S13: FALSE | T13: Sistemden Çıkmak İstiyor | W13: TEYİD İÇİN ARANDI AÇMADI | AP13: Simge Demiray
A14: 6242db2d195cc73670471f53 | B14: Ada Pizza Pide & Lahmacun (32 Evler Mah.) | C14: =VLOOKUP(A14,import!A:C,3,0) -> DOĞRU | D14: Pizza | E14: =VLOOKUP(A14,import!A:AA,5,0) | F14: =VLOOKUP(A14,import!A:AA,6,0) | G14: =VLOOKUP(A14,import!A:AA,7,0) -> 0 | H14: =VLOOKUP(A14,import!A:AA,8,0) -> 14 | I14: =VLOOKUP(A14,import!A:AA,9,0) -> 14 | J14: =VLOOKUP(A14,import!A:AA,10,0) -> 0 | K14: CELAL UÇAR | L14: 2642756060 | M14: Serdivan | N14: Otuziki Evler | O14: Otuziki Evler Mah., Genç Sok., No:1, Serdivan, Sakarya, Türkiye, | P14: =VLOOKUP(A14,import!A:P,16,0) -> Geleneksel | R14: FALSE | S14: FALSE
A15: 60be00983632e31216528579 | B15: Ada Roma Dondurmaları 2 (Sakarya Cad.) | C15: =VLOOKUP(A15,import!A:C,3,0) -> YANLIŞ | D15: Dondurma | E15: =VLOOKUP(A15,import!A:AA,5,0) -> 1 | F15: =VLOOKUP(A15,import!A:AA,6,0) | G15: =VLOOKUP(A15,import!A:AA,7,0) -> 8 | H15: =VLOOKUP(A15,import!A:AA,8,0) -> 10 | I15: =VLOOKUP(A15,import!A:AA,9,0) -> 18 | J15: =VLOOKUP(A15,import!A:AA,10,0) -> 0.44 | K15: Eşref YÜZKOLLAR | L15: 5543149053 | M15: Adapazarı | N15: Sakarya | O15: Sakarya Cad., No:15, Erenler, Sakarya, Türkiye, | P15: =VLOOKUP(A15,import!A:P,16,0) -> Geleneksel | R15: TRUE | S15: FALSE | T15: Randevu Alındı | U15: Ecem Ünal | V15: Zeynep Yazıcı | X15: 44362 | Y15: 44364 | AA15: Görüşüldü | AB15: 44362 | AK15: Ecem Ünal | AP15: Simge Demiray
A16: 604ba358f1352d123849b7ea | B16: Ada Şark Pide & Lahmacun, Adapazarı (Yenigün Mah.) | C16: =VLOOKUP(A16,import!A:C,3,0) -> YANLIŞ | D16: Pide | E16: =VLOOKUP(A16,import!A:AA,5,0) -> 6 | F16: =VLOOKUP(A16,import!A:AA,6,0) | G16: =VLOOKUP(A16,import!A:AA,7,0) -> 0 | H16: =VLOOKUP(A16,import!A:AA,8,0) -> 8 | I16: =VLOOKUP(A16,import!A:AA,9,0) -> 8 | J16: =VLOOKUP(A16,import!A:AA,10,0) -> 0 | K16: Abdurrahman Alptekin | L16: 5342256045 | M16: Adapazarı | N16: Yenigün | O16: Yenigün Mah. Yeğenler Cad., No:128, Adapazarı, Sakarya, Türkiye, | P16: =VLOOKUP(A16,import!A:P,16,0) -> Geleneksel | R16: TRUE | S16: FALSE | T16: Personel Eksik | W16: paket elemanı yokmuş o yuzden istememişler. ileride düşünürsem dönerim dedi ikna edilebilir faydalardan bahsedildi.-Aradık fakat telefonu kapalıydı. | AA16: Görüşüldü | AB16: 44356 | AC16: Görüşüldü | AD16: 44363 | AE16: Ulaşılamadı | AG16: Ulaşılamadı | AH16: 44405 | AK16: Nazlıcan Dinçer | AL16: Selcan Topçu | AM16: Ezgi Turan | AN16: Nazlıcan Dinçer | AP16: Simge Demiray
A17: 6120f882a03cfb2f8e335a64 | B17: Ada Şelale, Serdivan (Kemalpaşa Mah.) | C17: =VLOOKUP(A17,import!A:C,3,0) -> DOĞRU | D17: Tavuk | E17: =VLOOKUP(A17,import!A:AA,5,0) -> 10650 | F17: =VLOOKUP(A17,import!A:AA,6,0) -> 419 | G17: =VLOOKUP(A17,import!A:AA,7,0) -> 3 | H17: =VLOOKUP(A17,import!A:AA,8,0) -> 22 | I17: =VLOOKUP(A17,import!A:AA,9,0) -> 25 | J17: =VLOOKUP(A17,import!A:AA,10,0) -> 0.12 | K17: Adaer Ticaret Nakl. İnş. Hayv. Ltd. Şti | L17: 5388201124 | M17: Serdivan | N17: Kemalpaşa | O17: kemalpaşa mah üniversite cad no 82 | P17: =VLOOKUP(A17,import!A:P,16,0) -> Geleneksel | R17: TRUE | S17: FALSE | T17: Ulaşılamadı | W17: açmadı | AA17: Ulaşılamadı | AB17: 44606 | AK17: Enes Günal | AP17: Simge Demiray
A18: 6009e79e9873d870b68c9b84 | B18: Ada Tantuni (Yalı Mah.) | C18: =VLOOKUP(A18,import!A:C,3,0) -> DOĞRU | D18: Sokak Lezzetleri | E18: =VLOOKUP(A18,import!A:AA,5,0) -> 565 | F18: =VLOOKUP(A18,import!A:AA,6,0) | G18: =VLOOKUP(A18,import!A:AA,7,0) -> 1 | H18: =VLOOKUP(A18,import!A:AA,8,0) -> 18 | I18: =VLOOKUP(A18,import!A:AA,9,0) -> 19 | J18: =VLOOKUP(A18,import!A:AA,10,0) -> 0.05 | K18: Fatih Recep Parmaksız | L18: 5434705404 | M18: Karasu | N18: Yalı | O18: Yalı Mah Plaj Cad. No :119/B | P18: =VLOOKUP(A18,import!A:P,16,0) -> Geleneksel | R18: FALSE | S18: FALSE | AK18: Ezgi Turan | AP18: Simge Demiray
A19: 603dfbbcb3d2c3527538f8a3 | B19: Ada Yakamoz Tantuni, Serdivan (Kemalpaşa Mah.) | C19: =VLOOKUP(A19,import!A:C,3,0) -> DOĞRU | D19: Sokak Lezzetleri | E19: =VLOOKUP(A19,import!A:AA,5,0) -> 2916 | F19: =VLOOKUP(A19,import!A:AA,6,0) -> 315 | G19: =VLOOKUP(A19,import!A:AA,7,0) -> 14 | H19: =VLOOKUP(A19,import!A:AA,8,0) -> 25 | I19: =VLOOKUP(A19,import!A:AA,9,0) -> 39 | J19: =VLOOKUP(A19,import!A:AA,10,0) -> 0.36 | K19: Ömer Faruk Tağma | L19: 2645024549 | M19: Serdivan | N19: Kemalpaşa | O19: Kemalpaşa Mah., Üniversite Cad., No:39, Serdivan, Sakarya, Türkiye, | P19: =VLOOKUP(A19,import!A:P,16,0) -> Geleneksel | R19: TRUE | S19: FALSE | T19: Randevu Alındı | U19: Tuğba Buyur | V19: Burak Kavakçı | W19: 5395537433 devam çekimine gerek yok sadece içeçekler kaldı dedi | X19: 44285 | Y19: 44288 | AA19: Görüşüldü | AB19: 44351 | AK19: Gül Değirmenci | AP19: Simge Demiray
A20: 606c41fcab152dcb37346d42 | B20: Ada Zurna Hatay Usulü Dürüm, Serdivan (Kemalpaşa Mah.) | C20: =VLOOKUP(A20,import!A:C,3,0) -> DOĞRU | D20: Döner | E20: =VLOOKUP(A20,import!A:AA,5,0) -> 637 | F20: =VLOOKUP(A20,import!A:AA,6,0) -> 237 | G20: =VLOOKUP(A20,import!A:AA,7,0) -> 0 | H20: =VLOOKUP(A20,import!A:AA,8,0) -> 40 | I20: =VLOOKUP(A20,import!A:AA,9,0) -> 40 | J20: =VLOOKUP(A20,import!A:AA,10,0) -> 0 | K20: Behice DEMİRKOL | L20: 5312105658 | M20: Serdivan | N20: Kemalpaşa | O20: Kemalpaşa mah.universite cad.kartepe şok no 29 daire 1 | P20: =VLOOKUP(A20,import!A:P,16,0) -> Geleneksel | R20: TRUE | S20: FALSE | T20: Başka Şubeden Çekilecek | W20: sistem de sorun var fotoğraf çekimi istiyor.-10 Dakika sonra ulaşım sağlanabilirmiş./başka bi şubesi daha varmış oraya çekim yapılmış | AA20: Dönüş Yapacak | AB20: 44384 | AC20: Ulaşılamadı | AD20: 44389 | AE20: Ulaşılamadı | AF20: 44404 | AG20: Tekrar Aranacak | AH20: 44405 | AK20: Ezgi Turan | AL20: Ezgi Turan | AM20: Ayşegül Dulkadir | AN20: Nazlıcan Dinçer | AP20: Simge Demiray
A21: 6200ecd836d5485e3ab0fd69 | B21: Adabahçem Dondurma & Kahvaltı (Arabacıalanı Mah.) | C21: =VLOOKUP(A21,import!A:C,3,0) -> DOĞRU | D21: Kahvaltı | E21: =VLOOKUP(A21,import!A:AA,5,0) -> 383 | F21: =VLOOKUP(A21,import!A:AA,6,0) -> 132 | G21: =VLOOKUP(A21,import!A:AA,7,0) -> 52 | H21: =VLOOKUP(A21,import!A:AA,8,0) -> 18 | I21: =VLOOKUP(A21,import!A:AA,9,0) -> 70 | J21: =VLOOKUP(A21,import!A:AA,10,0) -> 0.74 | K21: FAHRİYE DURĞAN | L21: 5323403401 | M21: Serdivan | N21: Arabacıalanı | O21: Şehit Mehmet Karabaşoğlu Cad., No:76, Serdivan, Sakarya, Türkiye, | P21: =VLOOKUP(A21,import!A:P,16,0) -> Geleneksel | R21: TRUE | S21: FALSE | T21: Randevu Alındı | U21: Zeliha Özer | V21: Aleyna Küççük | X21: 44608 | Y21: 44609 | AA21: Görüşüldü | AB21: 44608 | AK21: Zeliha Özer
A22: 6018f365aa213ab3f0e42016 | B22: Adakule Restaurant, Adapazarı (Maltepe Mah.) | C22: =VLOOKUP(A22,import!A:C,3,0) -> DOĞRU | D22: Burger | E22: =VLOOKUP(A22,import!A:AA,5,0) -> 2504 | F22: =VLOOKUP(A22,import!A:AA,6,0) -> 29 | G22: =VLOOKUP(A22,import!A:AA,7,0) -> 4 | H22: =VLOOKUP(A22,import!A:AA,8,0) -> 25 | I22: =VLOOKUP(A22,import!A:AA,9,0) -> 29 | J22: =VLOOKUP(A22,import!A:AA,10,0) -> 0.14 | K22: Mesut Timar | L22: 5324095676 | M22: Adapazarı | N22: Maltepe | O22: Maltepe Mah., Maltepe Cad., No:67, Adapazarı, Sakarya, Türkiye, | P22: =VLOOKUP(A22,import!A:P,16,0) -> Geleneksel | R22: TRUE | S22: FALSE | T22: Dönüş Yapacak | W22: aramayın düşünmüyor/şuan düşünmüyormuş/bizim aramamızı istemedi düşünürse kendisi dönecek | AA22: Görüşüldü | AB22: 44356 | AC22: Görüşüldü | AD22: 44363 | AE22: Görüşüldü | AF22: 44371 | AG22: Görüşüldü | AH22: 44371 | AI22: Görüşüldü | AJ22: 44390 | AK22: Nazlıcan Dinçer | AL22: Tutku Erdoğan | AM22: Ecem Ünal | AN22: Ezgi Turan | AO22: Derya Tatlı | AP22: Simge Demiray
A23: 60966a31822d878c7c5a0630 | B23: Adana Kebapçısı Suphi Usta, Adapazarı (Korucuk Mah.) | C23: =VLOOKUP(A23,import!A:C,3,0) -> DOĞRU | D23: Kebap | E23: =VLOOKUP(A23,import!A:AA,5,0) -> 799 | F23: =VLOOKUP(A23,import!A:AA,6,0) | G23: =VLOOKUP(A23,import!A:AA,7,0) -> 0 | H23: =VLOOKUP(A23,import!A:AA,8,0) -> 35 | I23: =VLOOKUP(A23,import!A:AA,9,0) -> 35 | J23: =VLOOKUP(A23,import!A:AA,10,0) -> 0 | K23: Suphi Şahin | L23: 5464985001 | M23: Adapazarı | N23: Korucuk | O23: Korucuk Mah. Keremçoskun Cad. Tunahan Sitesi 2 No : 1 Korucuk / Sakarya | P23: =VLOOKUP(A23,import!A:P,16,0) -> Geleneksel | R23: TRUE | S23: TRUE | W23: Bayramdan sonra maile gönderecekler | AA23: Ulaşılamadı | AB23: 44379 | AC23: Ulaşılamadı | AD23: 44384 | AE23: Görüşüldü | AF23: 44390 | AK23: Gül Değirmenci | AL23: Ezgi Turan | AM23: Ayşegül Dulkadir | AP23: Simge Demiray
A24: 606b2e7b2b4d0ee5dd1bac90 | B24: Adanalı Halil Usta, Adapazarı (Korucuk Mah.) | C24: =VLOOKUP(A24,import!A:C,3,0) -> DOĞRU | D24: Pide | E24: =VLOOKUP(A24,import!A:AA,5,0) -> 2182 | F24: =VLOOKUP(A24,import!A:AA,6,0) -> 47 | G24: =VLOOKUP(A24,import!A:AA,7,0) -> 0 | H24: =VLOOKUP(A24,import!A:AA,8,0) -> 31 | I24: =VLOOKUP(A24,import!A:AA,9,0) -> 31 | J24: =VLOOKUP(A24,import!A:AA,10,0) -> 0 | K24: Ayten Kalay | L24: 5325100864 | M24: Adapazarı | N24: Korucuk | O24: Korucuk Mah., Vakıf Cad., No:14/1A, Adapazarı, Sakarya, Türkiye, | P24: =VLOOKUP(A24,import!A:P,16,0) -> Geleneksel | R24: TRUE | S24: FALSE | T24: Çekim İstemiyor | W24: halil bey ile görüşüldü problemleri çöcülünce aranacak . kızgındı ama biraz yumuşak konuşunca onay verıyor.-Problemle ilgilenildi saha temsilcisi dönüş sağlayacakmış çok sonra aranabilir./fotoğraftan önce başka sıkıntılarımız var çekim istmeiyorum dedi | AA24: Görüşüldü | AB24: 44365 | AC24: Yetkili Yok | AD24: 44371 | AE24: Tekrar Aranacak | AF24: 44389 | AG24: Görüşüldü | AH24: 44609 | AK24: Nurhayat Kabataş | AL24: Ezgi Turan | AM24: Ezgi Turan | AN24: Ayşegül Kır | AP24: Simge Demiray
A25: 60cdeaaf8d492c7994e5f54a | B25: Adanalı Mustafa’nın Yeri, Karasu (Yalı Mah.) | C25: =VLOOKUP(A25,import!A:C,3,0) -> DOĞRU | D25: Lahmacun | E25: =VLOOKUP(A25,import!A:AA,5,0) -> 308 | F25: =VLOOKUP(A25,import!A:AA,6,0) | G25: =VLOOKUP(A25,import!A:AA,7,0) -> 0 | H25: =VLOOKUP(A25,import!A:AA,8,0) -> 45 | I25: =VLOOKUP(A25,import!A:AA,9,0) -> 45 | J25: =VLOOKUP(A25,import!A:AA,10,0) -> 0 | K25: MUSTAFA KUYBULU | L25: 5344117719 | M25: Karasu | N25: İncilli | O25: YALI MAH. PLAJ CAD. NO: 132 İÇ KAPI NO: 3 KARASU/SAKARYA | P25: =VLOOKUP(A25,import!A:P,16,0) -> Geleneksel | R25: FALSE | S25: FALSE | AP25: Simge Demiray
A26: 609664778bff0b36506686aa | B26: Addmore, Serdivan (Arabacı Alanı Mah.) | C26: =VLOOKUP(A26,import!A:C,3,0) -> DOĞRU | D26: Pizza | E26: =VLOOKUP(A26,import!A:AA,5,0) -> 577 | F26: =VLOOKUP(A26,import!A:AA,6,0) -> 44 | G26: =VLOOKUP(A26,import!A:AA,7,0) -> 0 | H26: =VLOOKUP(A26,import!A:AA,8,0) -> 61 | I26: =VLOOKUP(A26,import!A:AA,9,0) -> 61 | J26: =VLOOKUP(A26,import!A:AA,10,0) -> 0 | K26: ÖZERLER SÜT ÜRÜNLERİVE MARKETÇİLİK A.Ş. | L26: 5428270692 | M26: Serdivan | N26: Arabacıalanı | O26: Arabacıalanı, Mehmet Akif Ersoy Cd. No:8/2, 54050 Serdivan/Sakarya | P26: =VLOOKUP(A26,import!A:P,16,0) -> Geleneksel | R26: TRUE | S26: FALSE | T26: İleride Randevu Alınacak | U26: Ezgi Turan | V26: Zeynep Yazıcı | W26: YETKİLİ İZİNLİ YARIN GÖRÜŞME SAĞLANABİLİR YETKİLİ KİŞİ EMRE BEY 09.00 DAN SONRA ARANABİLİR. | X26: 44348 | Y26: 44349 | AA26: Görüşüldü | AB26: 44349 | AC26: Görüşüldü | AD26: 44384 | AK26: Selcan Topçu | AL26: Ezgi Turan | AP26: Simge Demiray
A27: 6092a0af42ff6acb5dc7089f | B27: Addmore, Serdivan (Semerciler Mah.) | C27: =VLOOKUP(A27,import!A:C,3,0) -> DOĞRU | D27: Pizza | E27: =VLOOKUP(A27,import!A:AA,5,0) -> 168 | F27: =VLOOKUP(A27,import!A:AA,6,0) -> 10 | G27: =VLOOKUP(A27,import!A:AA,7,0) -> 18 | H27: =VLOOKUP(A27,import!A:AA,8,0) -> 44 | I27: =VLOOKUP(A27,import!A:AA,9,0) -> 62 | J27: =VLOOKUP(A27,import!A:AA,10,0) -> 0.29 | K27: ÖZERLER SÜT ÜRÜNLERİVE MARKETÇİLİK A.Ş. | L27: 5428270692 | M27: Adapazarı | N27: Semerciler | O27: semerciler mah çark cad. | P27: =VLOOKUP(A27,import!A:P,16,0) -> Geleneksel | R27: TRUE | S27: FALSE | T27: Randevu Alındı | U27: Ezgi Turan | V27: Zeynep Yazıcı | W27: getir yemekten çıkıtğını randevu alınıp gelinmediğini söyledi/ teyit için arandı ulaşılamadı | X27: 44344 | Y27: 44349 | AA27: Görüşüldü | AB27: 44384 | AC27: Görüşüldü | AD27: 44404 | AK27: Ezgi Turan | AL27: Ezgi Turan | AP27: Simge Demiray
A28: 62584721a7b30e48310d27aa | B28: Adıyaman Çiğ Köftecisi (Erenler Mah.) | C28: =VLOOKUP(A28,import!A:C,3,0) -> DOĞRU | D28: Çiğ Köfte | E28: =VLOOKUP(A28,import!A:AA,5,0) | F28: =VLOOKUP(A28,import!A:AA,6,0) | G28: =VLOOKUP(A28,import!A:AA,7,0) -> 0 | H28: =VLOOKUP(A28,import!A:AA,8,0) -> 31 | I28: =VLOOKUP(A28,import!A:AA,9,0) -> 31 | J28: =VLOOKUP(A28,import!A:AA,10,0) -> 0 | K28: ÇAĞLA KISA | L28: 5424601841 | M28: Erenler | N28: Erenler | O28: Erenler Mah., Erenler Cad., No:13, Erenler, Sakarya, Türkiye, | P28: =VLOOKUP(A28,import!A:P,16,0) -> Geleneksel | R28: FALSE | S28: FALSE
A29: 60caf19b2b6d293799cb3bdd | B29: Adıyamanlı Çiğ Köfteci Ali Baba (Tığçılar Mah.) | C29: =VLOOKUP(A29,import!A:C,3,0) -> DOĞRU | D29: Çiğ Köfte | E29: =VLOOKUP(A29,import!A:AA,5,0) | F29: =VLOOKUP(A29,import!A:AA,6,0) | G29: =VLOOKUP(A29,import!A:AA,7,0) -> 0 | H29: =VLOOKUP(A29,import!A:AA,8,0) -> 13 | I29: =VLOOKUP(A29,import!A:AA,9,0) -> 13 | J29: =VLOOKUP(A29,import!A:AA,10,0) -> 0 | K29: MEHMET DEMİREL | L29: 5322824382 | M29: Adapazarı | N29: Tığcılar | O29: Tığcılar Mah Kesci sok 93/a | P29: =VLOOKUP(A29,import!A:P,16,0) -> Geleneksel | R29: TRUE | S29: FALSE | T29: Ulaşılamadı | AA29: Ulaşılamadı | AB29: 44389 | AC29: Ulaşılamadı | AD29: 44404 | AK29: Nazlıcan Dinçer | AL29: Ezgi Turan | AP29: Simge Demiray
A30: 606ef87f20d6a1581ae6fec0 | B30: Ahsen Pastaneleri (Semerciler Mah.) | C30: =VLOOKUP(A30,import!A:C,3,0) -> DOĞRU | D30: Pasta & Tatlı | E30: =VLOOKUP(A30,import!A:AA,5,0) -> 565 | F30: =VLOOKUP(A30,import!A:AA,6,0) -> 12 | G30: =VLOOKUP(A30,import!A:AA,7,0) -> 27 | H30: =VLOOKUP(A30,import!A:AA,8,0) -> 11 | I30: =VLOOKUP(A30,import!A:AA,9,0) -> 38 | J30: =VLOOKUP(A30,import!A:AA,10,0) -> 0.71 | K30: Huriye Çakır | L30: 5315130658 | M30: Adapazarı | N30: Semerciler | O30: Semerciler mah Atatürk blv. Pasaj 2000 NO :2 M ADAPAZARI /SAKARYA | P30: =VLOOKUP(A30,import!A:P,16,0) -> Geleneksel | R30: TRUE | S30: FALSE | T30: Randevu Alındı | U30: Gül Değirmenci | V30: Zeynep Yazıcı | W30: devam çekimi randevusu alındı. | X30: 44368 | Y30: 44371 | AA30: Görüşüldü | AB30: 44368 | AK30: Gül Değirmenci | AP30: Simge Demiray
A31: 622afb1ded7bafd0212078c9 | B31: Akdeniz Tantuni (İstiklal Mah.) | C31: =VLOOKUP(A31,import!A:C,3,0) -> DOĞRU | D31: Sokak Lezzetleri | E31: =VLOOKUP(A31,import!A:AA,5,0) -> 49 | F31: =VLOOKUP(A31,import!A:AA,6,0) -> 32 | G31: =VLOOKUP(A31,import!A:AA,7,0) -> 0 | H31: =VLOOKUP(A31,import!A:AA,8,0) -> 11 | I31: =VLOOKUP(A31,import!A:AA,9,0) -> 11 | J31: =VLOOKUP(A31,import!A:AA,10,0) -> 0 | K31: ELİF OKAY | L31: 5302006954 | M31: Serdivan | N31: İstiklal | O31: Bağlar Cad., No:43, Serdivan, Sakarya, Türkiye, | P31: =VLOOKUP(A31,import!A:P,16,0) -> Geleneksel | R31: FALSE | S31: FALSE
A32: 60ce01f675a6b8c0c6b423bd | B32: Al Götür Express, Adapazarı (Semerciler Mah. - Çark Cad.) | C32: =VLOOKUP(A32,import!A:C,3,0) -> YANLIŞ | D32: Kahve | E32: =VLOOKUP(A32,import!A:AA,5,0) | F32: =VLOOKUP(A32,import!A:AA,6,0) | G32: =VLOOKUP(A32,import!A:AA,7,0) -> 0 | H32: =VLOOKUP(A32,import!A:AA,8,0) -> 27 | I32: =VLOOKUP(A32,import!A:AA,9,0) -> 27 | J32: =VLOOKUP(A32,import!A:AA,10,0) -> 0 | K32: OĞUZHAN KARAHAN | L32: 5061060077 | M32: Adapazarı | N32: Semerciler | O32: Semerciler Mah., Gökçe Sok., No:8, Adapazarı, Sakarya, Türkiye, | P32: =VLOOKUP(A32,import!A:P,16,0) -> Geleneksel | R32: TRUE | S32: TRUE | AA32: Görüşüldü | AB32: 44379 | AC32: Görüşüldü | AD32: 44392 | AE32: Tekrar Aranacak | AF32: 44405 | AK32: Derya Tatlı | AL32: Tutku Erdoğan | AM32: Ayşegül Dulkadir | AP32: Simge Demiray
A33: 620534d7fa2e86bbb73f1f8e | B33: Alâ Balık & Meze (Rüstempaşa Mah.) | C33: =VLOOKUP(A33,import!A:C,3,0) -> DOĞRU | D33: Deniz Ürünleri | E33: =VLOOKUP(A33,import!A:AA,5,0) -> 8 | F33: =VLOOKUP(A33,import!A:AA,6,0) | G33: =VLOOKUP(A33,import!A:AA,7,0) -> 0 | H33: =VLOOKUP(A33,import!A:AA,8,0) -> 11 | I33: =VLOOKUP(A33,import!A:AA,9,0) -> 11 | J33: =VLOOKUP(A33,import!A:AA,10,0) -> 0 | K33: ADNAN ALEM | L33: 5382918185 | M33: Sapanca | N33: Rüstempaşa | O33: Rüstempaşa Mah., Kuvayi Milliye Cad., Sapanca, Sakarya, Türkiye, | P33: =VLOOKUP(A33,import!A:P,16,0) -> Geleneksel | R33: FALSE | S33: FALSE
A34: 6204fe776c82f695a93d97c8 | B34: Alaçatı Kumru & Burger (Kırkpınar Hasanpaşa Mah.) | C34: =VLOOKUP(A34,import!A:C,3,0) -> DOĞRU | D34: Burger | E34: =VLOOKUP(A34,import!A:AA,5,0) | F34: =VLOOKUP(A34,import!A:AA,6,0) | G34: =VLOOKUP(A34,import!A:AA,7,0) -> 0 | H34: =VLOOKUP(A34,import!A:AA,8,0) -> 62 | I34: =VLOOKUP(A34,import!A:AA,9,0) -> 62 | J34: =VLOOKUP(A34,import!A:AA,10,0) -> 0 | K34: ZERRİN KIZILDEMİR | L34: 5491323535 | M34: Sapanca | N34: Kırkpınar Hasanpaşa | O34: Şehit Cevdet Koç Cad., Sapanca, Sakarya, Türkiye, | P34: =VLOOKUP(A34,import!A:P,16,0) -> Geleneksel | R34: FALSE | S34: FALSE
A35: 61211a91542a0d2769c0c5ef | B35: Alo Acıktııık, Adapazarı (Şeker Mah.) | C35: =VLOOKUP(A35,import!A:C,3,0) -> DOĞRU | D35: Sokak Lezzetleri | E35: =VLOOKUP(A35,import!A:AA,5,0) -> 7 | F35: =VLOOKUP(A35,import!A:AA,6,0) | G35: =VLOOKUP(A35,import!A:AA,7,0) -> 0 | H35: =VLOOKUP(A35,import!A:AA,8,0) -> 40 | I35: =VLOOKUP(A35,import!A:AA,9,0) -> 40 | J35: =VLOOKUP(A35,import!A:AA,10,0) -> 0 | K35: Yakup Kırca | L35: 5050346475 | M35: Adapazarı | N35: Kurtuluş | O35: Kurtuluş Mah., Bahçıvan Sok., No:46, Adapazarı, Sakarya, Türkiye, | P35: =VLOOKUP(A35,import!A:P,16,0) -> Geleneksel | R35: TRUE | S35: FALSE | T35: Ulaşılamadı | W35: Numara kullanılmıyor ve internette hep aynı numara var | AA35: Ulaşılamadı | AB35: 44607 | AK35: Enes Günal | AP35: Simge Demiray
A36: 6041eb9617e4246bab0c1602 | B36: Alo Balık (15 Temmuz Camili Mah.) | C36: =VLOOKUP(A36,import!A:C,3,0) -> DOĞRU | D36: Balık & Deniz Ürünleri | E36: =VLOOKUP(A36,import!A:AA,5,0) -> 201 | F36: =VLOOKUP(A36,import!A:AA,6,0) | G36: =VLOOKUP(A36,import!A:AA,7,0) -> 0 | H36: =VLOOKUP(A36,import!A:AA,8,0) -> 4 | I36: =VLOOKUP(A36,import!A:AA,9,0) -> 4 | J36: =VLOOKUP(A36,import!A:AA,10,0) -> 0 | K36: Erdinç Tekinoğlu | L36: 5326009910 | M36: Adapazarı | N36: 15 Temmuz Camili | O36: 15 temmuz camili mah 1634 küme evleri 338 nolu sarı iş merkezi No .z22 | P36: =VLOOKUP(A36,import!A:P,16,0) -> Geleneksel | R36: TRUE | S36: FALSE | T36: İleride Randevu Alınacak | W36: dükkan kapalı daha sonra arayın /şuan sezon bitmiş eylülde başlaaycak eğer devam edilirse aranacak eğer devam edilmezse kendi çekip göndericek | AA36: Görüşüldü | AC36: Görüşüldü | AD36: 44404 | AP36: Simge Demiray
A37: 6040aa583f01ac8eb783a324 | B37: Alo Sokak Başı, Serdivan (İstiklal Mah.) | C37: =VLOOKUP(A37,import!A:C,3,0) -> DOĞRU | D37: Ev Yemekleri | E37: =VLOOKUP(A37,import!A:AA,5,0) -> 34 | F37: =VLOOKUP(A37,import!A:AA,6,0) | G37: =VLOOKUP(A37,import!A:AA,7,0) -> 0 | H37: =VLOOKUP(A37,import!A:AA,8,0) -> 23 | I37: =VLOOKUP(A37,import!A:AA,9,0) -> 23 | J37: =VLOOKUP(A37,import!A:AA,10,0) -> 0 | K37: Havva KOTAN | L37: 5161669161 | M37: Serdivan | N37: İstiklal | O37: İstiklal Mah., Çelebi Sok., No:1, Serdivan, Sakarya, Türkiye, | P37: =VLOOKUP(A37,import!A:P,16,0) -> Geleneksel | R37: TRUE | S37: FALSE | T37: İleride Randevu Alınacak | W37: Eşim ve ben şeker hastasıyız herkesi alamıyoruz bu yüzden daha ileri tarihlerde ded/tadılatimız olucak baya ılerde olabılır ama sımdı olmaz dedı /şeker hastasıymış kendisini çokiyi koruyormuş yani riske gşrmek istemiyor pandemi süresincede istemez | AA37: Görüşüldü | AB37: 44358 | AC37: Görüşüldü | AD37: 44376 | AE37: Görüşüldü | AF37: 44405 | AK37: Tutku Erdoğan | AL37: Ezgi Turan | AM37: Derya Tatlı | AP37: Simge Demiray
A38: 60cde8b8acb711e901cc8436 | B38: Altınova Çiğ Köfte (İstiklal Mah.) | C38: =VLOOKUP(A38,import!A:C,3,0) -> DOĞRU | D38: Çiğ Köfte | E38: =VLOOKUP(A38,import!A:AA,5,0) -> 121 | F38: =VLOOKUP(A38,import!A:AA,6,0) | G38: =VLOOKUP(A38,import!A:AA,7,0) -> 5 | H38: =VLOOKUP(A38,import!A:AA,8,0) -> 2 | I38: =VLOOKUP(A38,import!A:AA,9,0) -> 7 | J38: =VLOOKUP(A38,import!A:AA,10,0) -> 0.71 | K38: Hasan BağcıatalHasan Bağcıatal | L38: 5424542934 | M38: Serdivan | N38: İstiklal | O38: istiklal mah muhsin yazıcıoğlu bulv no 55 | P38: =VLOOKUP(A38,import!A:P,16,0) -> Geleneksel | R38: TRUE | S38: FALSE | T38: Randevu Alındı | U38: Zeliha Özer | X38: 44608 | Y38: 44609 | AA38: Görüşüldü | AB38: 44608 | AK38: Zeliha Özer | AP38: Simge Demiray
A39: 62557e2ea7b76af6d41683af | B39: Alzide Kebap (Kemaliye Mah.) | C39: =VLOOKUP(A39,import!A:C,3,0) -> DOĞRU | D39: Kebap | E39: =VLOOKUP(A39,import!A:AA,5,0) | F39: =VLOOKUP(A39,import!A:AA,6,0) | G39: =VLOOKUP(A39,import!A:AA,7,0) -> 0 | H39: =VLOOKUP(A39,import!A:AA,8,0) -> 39 | I39: =VLOOKUP(A39,import!A:AA,9,0) -> 39 | J39: =VLOOKUP(A39,import!A:AA,10,0) -> 0 | K39: GÜLPERİ DEMİR | L39: 5317865383 | M39: Hendek | N39: Başpınar | O39: Başpınar Mah., Profesör Doktor Ayhan Kızıl Cad., No:36, Hendek, Sakarya, Türkiye, | P39: =VLOOKUP(A39,import!A:P,16,0) -> Geleneksel | R39: FALSE | S39: FALSE
A40: 617fb5fc4b1a05116240999d | B40: Antep Hacıoğlu Baklava | C40: =VLOOKUP(A40,import!A:C,3,0) -> DOĞRU | D40: Pasta & Tatlı | E40: =VLOOKUP(A40,import!A:AA,5,0) -> 932 | F40: =VLOOKUP(A40,import!A:AA,6,0) -> 68 | G40: =VLOOKUP(A40,import!A:AA,7,0) -> 4 | H40: =VLOOKUP(A40,import!A:AA,8,0) -> 6 | I40: =VLOOKUP(A40,import!A:AA,9,0) -> 10 | J40: =VLOOKUP(A40,import!A:AA,10,0) -> 0.4 | K40: ŞABAN ALIÇ | L40: 5075015557 | M40: Serdivan | N40: Köprübaşı | O40: Süleyman Binek Cad., No:49, Serdivan, Sakarya, Türkiye, | P40: =VLOOKUP(A40,import!A:P,16,0) -> Geleneksel | R40: TRUE | S40: FALSE | T40: Randevu Alındı | U40: Ferhat Köksal | V40: Aleyna Küççük | X40: 44610 | Y40: 44613 | AA40: Görüşüldü | AB40: 44610 | AK40: Ferhat Köksal | AP40: Simge Demiray
...

Sheet import
A1: Restaurant ID | B1: Restoran Adı | C1: IsActive | D1: Mutfak | E1: TOPLAM SİPARİŞ | F1: SON 2 HAFTA | G1: RESİMLİ ÜRÜN | H1: RESİMSİZ ÜRÜN | I1: TOPLAM ÜRÜN | J1: Ratio | K1: Yetkili | L1: Telefon | M1: İLÇE | N1: MAHALLE | O1: ADRES | P1: Geleneksel Zincir | Q1: Eklendi mi
A2: 5f5b81ac69bc226d55bfe6ce | B2: Hakkı Usta’nın Adana Sofrası, Adapazarı (Merkez) | C2: YANLIŞ | D2: Kebap | E2: 205 | G2: 0 | H2: 44 | I2: 44 | J2: 0 | K2: Mehmet Hakkı Uçar | L2: 2642798872 | M2: Adapazarı | N2: Yenidoğan | O2: Yenidoğan, Yeni Bosna Cd. No:66, 54100 Adapazarı/Sakarya | P2: Geleneksel | Q2: =COUNTIF('Hedef Liste'!A:A,A2) -> 1
A3: 5f60b0aa37521c1f416c3f25 | B3: Sushikado, Serdivan (Merkez) | C3: DOĞRU | D3: Uzak Doğu | E3: 1206 | G3: 42 | H3: 49 | I3: 91 | J3: 0.46 | K3: Zeynep Rençber | L3: 5388121136 | M3: Serdivan | N3: İstiklal | O3: İstiklal, Bağlar Cd. No:43/A, 54050 Serdivan/Sakarya | P3: Geleneksel | Q3: =COUNTIF('Hedef Liste'!A:A,A3) -> 1
A4: 5f87fd0a1cfa9804022d7c80 | B4: Ekşi Fırın (İstiklal Mah.) | C4: YANLIŞ | D4: Pasta & Tatlı | E4: 73 | G4: 48 | H4: 10 | I4: 58 | J4: 0.83 | K4: Tufan Bahar | L4: 2642110800 | M4: Serdivan | N4: İstiklal | O4: İstiklal, 2. Cd. No:45, 54050 Serdivan/Sakarya | P4: Geleneksel | Q4: =COUNTIF('Hedef Liste'!A:A,A4) -> 1
A5: 6007de51e4ab4e0f0b9219a5 | B5: Hey Tost'um (Kemalpaşa Mah) | C5: DOĞRU | D5: Tost & Sandviç | E5: 2123 | F5: 124 | G5: 32 | H5: 25 | I5: 57 | J5: 0.56 | K5: NESLİHAN KABA | L5: 5462777754 | M5: Serdivan | N5: Kemalpaşa | O5: Kemalpaşa Mah., Medeniyet Cad., No:9, Serdivan, Sakarya, Türkiye, | P5: Geleneksel | Q5: =COUNTIF('Hedef Liste'!A:A,A5) -> 1
A6: 600bd5ac9dceb635b8081c40 | B6: Edman Kanat (İstiklal Mah.) | C6: DOĞRU | D6: Tavuk | E6: 266 | G6: 24 | H6: 17 | I6: 41 | J6: 0.59 | K6: Vedat Furkan Edman | L6: 5324709754 | M6: Serdivan | N6: İstiklal | O6: Muhsin Yazıcıoğlu Blv., No:69, Serdivan, Sakarya, Türkiye, | P6: Geleneksel | Q6: =COUNTIF('Hedef Liste'!A:A,A6) -> 1
A7: 600d32517e16da055beaa003 | B7: Roll Döner (15 Temmuz Camili Mah.) | C7: DOĞRU | D7: Döner | E7: 869 | F7: 35 | G7: 8 | H7: 3 | I7: 11 | J7: 0.73 | K7: Şevval Küçükoğlu | L7: 5425741454 | M7: Adapazarı | N7: 15 Temmuz Camili | O7: 15 Temmuz Camili mah. Şehit Kaymakam Muhammet Fatih Safitürk Cad. 339 nolu iş merkezi z02 | P7: Geleneksel | Q7: =COUNTIF('Hedef Liste'!A:A,A7) -> 1
A8: 600c2cc2bce91f4701a58c7c | B8: Nap Cafe Restaurant (Kemalpaşa Mah.) | C8: DOĞRU | D8: Tost & Sandviç | E8: 5615 | F8: 125 | G8: 7 | H8: 33 | I8: 40 | J8: 0.18 | K8: Ali Gülle | L8: 5423614452 | M8: Serdivan | N8: Esentepe | O8: Kemalpaşa Mah., Döner Sok., No:24, Serdivan, Sakarya, Türkiye, | P8: Geleneksel | Q8: =COUNTIF('Hedef Liste'!A:A,A8) -> 1
A9: 600de4070475c8011eabbf68 | B9: Ciğerci Bahattin (Kemalpaşa Mah.) | C9: DOĞRU | D9: Kebap | E9: 906 | G9: 14 | H9: 10 | I9: 24 | J9: 0.58 | K9: Emrullah Sakin | L9: 5340794102 | M9: Serdivan | N9: Kemalpaşa | O9: Kemalpaşa Mah. Kenan Sofuoğlu Cad. no2 serdivan/Sakarya | P9: Geleneksel | Q9: =COUNTIF('Hedef Liste'!A:A,A9) -> 1
A10: 600820c20a79b124d9e367fe | B10: Pilove House (Kemalpaşa Mah) | C10: DOĞRU | D10: Sokak Lezzetleri | E10: 2025 | F10: 199 | G10: 0 | H10: 23 | I10: 23 | J10: 0 | K10: Birtekin Omurca | L10: 5399224034 | M10: Serdivan | N10: İstiklal | O10: Kemalpaşa Mah., Belediye Cad. (Yeni Cad.), No:4B | P10: Geleneksel | Q10: =COUNTIF('Hedef Liste'!A:A,A10) -> 1
A11: 600fe50ad6c591990de050e9 | B11: Öz Urfa Sofrası (Hacıoğlu Mah.) | C11: DOĞRU | D11: Lahmacun | E11: 875 | F11: 56 | G11: 7 | H11: 29 | I11: 36 | J11: 0.19 | K11: Mehmet Keskinkılıç | L11: 5413238570 | M11: Erenler | N11: Tabakhane | O11: Mehmet Akif Ersoy Cad., No:41, Erenler, Sakarya, Türkiye, | P11: Geleneksel | Q11: =COUNTIF('Hedef Liste'!A:A,A11) -> 1
A12: 6007f9e899244e076f05f2c9 | B12: Pizza Lazza, Adapazarı (Orta Mah.) | C12: DOĞRU | D12: Pizza | E12: 8464 | F12: 290 | G12: 121 | H12: 3 | I12: 124 | J12: 0.98 | K12: Mustafa Gündoğdu | L12: 2642786810 | M12: Adapazarı | N12: Orta | O12: Karaağaç Cad. Orta Mah.No:14/1 | P12: Key | Q12: =COUNTIF('Hedef Liste'!A:A,A12) -> 0
A13: 60081099c795bdd8a142624d | B13: Pizza Lazza, Akyazı (Küçücek Cumhuriyet Mah.) | C13: DOĞRU | D13: Pizza | E13: 121 | F13: 17 | G13: 121 | H13: 3 | I13: 124 | J13: 0.98 | K13: Mustafa Gündoğdu | L13: 2644621592 | M13: Akyazı | N13: Küçücek İstiklal | O13: Alaağaç İÖO Cad. Küçücek Cumhuriyet Mah. Adapazarı/Sakarya | P13: Key | Q13: =COUNTIF('Hedef Liste'!A:A,A13) -> 0
A14: 60081be6c11c767fa8b9ee85 | B14: Pizza Lazza, Serdivan (İstiklal Mah.) | C14: DOĞRU | D14: Pizza | E14: 9990 | F14: 439 | G14: 121 | H14: 3 | I14: 124 | J14: 0.98 | K14: Mustafa Gündoğdu | L14: 2642282203 | M14: Serdivan | N14: İstiklal | O14: Bağlar Cad. İstiklal Mah. Nur Sitesi No:38 A/ | P14: Key | Q14: =COUNTIF('Hedef Liste'!A:A,A14) -> 0
A15: 60074c36c11c76b50bb9c4f4 | B15: Nana Cafe & Restaurant (Cumhuriyet Mah.) | C15: YANLIŞ | D15: Tost & Sandviç | E15: 98 | G15: 5 | H15: 34 | I15: 39 | J15: 0.13 | K15: Taner Demirel | L15: 5434311111 | M15: Adapazarı | N15: Cumhuriyet | O15: Cumhuriyet Mah., Hüseyin Rahmi Sok., No:5, Adapazarı, Sakarya, Türkiye | P15: Geleneksel | Q15: =COUNTIF('Hedef Liste'!A:A,A15) -> 1
A16: 6007e68de13dbd621a5c3b07 | B16: Panino Pizza (Dilmen Mah.) | C16: DOĞRU | D16: Pizza | E16: 1653 | F16: 33 | G16: 124 | H16: 3 | I16: 127 | J16: 0.98 | K16: Yunus Atay | L16: 2642412626 | M16: Erenler | N16: Dilmen | O16: Dilmen Mah. Sakarbaba Cad. No:107/8 Erenler/Sakarya | P16: Geleneksel | Q16: =COUNTIF('Hedef Liste'!A:A,A16) -> 1
A17: 6009df0ac795bd5b1b42c508 | B17: Lezizan (Kemalpaşa Mah.) | C17: DOĞRU | D17: Kebap | E17: 2585 | F17: 199 | G17: 31 | H17: 25 | I17: 56 | J17: 0.55 | K17: Ali Deribaş | L17: 2642722222 | M17: Serdivan | N17: İstiklal | O17: Kemalpaşa Mah. Mehtap Sok. No:1A/B | P17: Geleneksel | Q17: =COUNTIF('Hedef Liste'!A:A,A17) -> 1
A18: 6009fd9b35cc59b6dbfe29f2 | B18: La Pide (Arabacı Alanı Mah.) | C18: DOĞRU | D18: Pide | E18: 114 | G18: 0 | H18: 9 | I18: 9 | J18: 0 | K18: Uğur Demir | L18: 2642796136 | M18: Serdivan | N18: Arabacıalanı | O18: Arabacıalanı Mah., Mert Sok., No:54, Serdivan, Sakarya, Türkiye, | P18: Geleneksel | Q18: =COUNTIF('Hedef Liste'!A:A,A18) -> 1
A19: 600d3e0eb19c482330c2d1aa | B19: Bisiklet Kahvesi (15 Temmuz Camili Mah.) | C19: DOĞRU | D19: Kahve | E19: 525 | F19: 9 | G19: 0 | H19: 54 | I19: 54 | J19: 0 | K19: Fatih Ertuğrul Çolak | L19: 5441406154 | M19: Adapazarı | N19: 15 Temmuz Camili | O19: 15 Temmuz Camili Mah., 221 Nolu Cad., No:3C, Adapazarı, Sakarya, Türkiye, | P19: Geleneksel | Q19: =COUNTIF('Hedef Liste'!A:A,A19) -> 1
A20: 600e6434b19c483b93c2e6ea | B20: Saklı Köşk (Gazipaşa Mah.) | C20: DOĞRU | D20: Tavuk | E20: 784 | F20: 31 | G20: 13 | H20: 21 | I20: 34 | J20: 0.38 | K20: Selvinaz Savaş | L20: 5322140537 | M20: Sapanca | N20: Çayiçi | O20: Gazipaşa Mahallesi İzmit Caddesi No. 39 Sapanca/Sakarya | P20: Geleneksel | Q20: =COUNTIF('Hedef Liste'!A:A,A20) -> 1
A21: 600fbd32cf43c1885dbce17f | B21: Buhara İskender (Semerciler Mah.- Çark cad.) | C21: DOĞRU | D21: Döner | E21: 3785 | F21: 81 | G21: 19 | H21: 14 | I21: 33 | J21: 0.58 | K21: Has Döner Gıda Otomotiv İnş. San. ve Tic. Ltd. Şti. | L21: 2642733141 | M21: Adapazarı | N21: Semerciler | O21: Çark Cad., No:9, Sakarya, Türkiye, | P21: Geleneksel | Q21: =COUNTIF('Hedef Liste'!A:A,A21) -> 1
A22: 601502054337de4f542c59de | B22: Burger Brothers Köfteci İsmail Serdivan (İstiklal Mah.) | C22: YANLIŞ | D22: Burger | E22: 707 | G22: 0 | H22: 29 | I22: 29 | J22: 0 | K22: Recep Özbek | L22: 2642755275 | M22: Adapazarı | N22: Mithatpaşa | O22: Çark Cad., No:169, Sakarya, Türkiye, | P22: Geleneksel | Q22: =COUNTIF('Hedef Liste'!A:A,A22) -> 1
A23: 6018fc9ce3c69cd8cc83fed6 | B23: Sakız Dondurma & Waffle, Serdivan (Arabacı Alanı Mah.) | C23: DOĞRU | D23: Pasta & Tatlı | E23: 1025 | F23: 33 | G23: 21 | H23: 10 | I23: 31 | J23: 0.68 | K23: Çağrı Görür | L23: 5323942354 | M23: Serdivan | N23: Arabacıalanı | O23: Çark Cad., No:343, Sakarya, Türkiye, | P23: Geleneksel | Q23: =COUNTIF('Hedef Liste'!A:A,A23) -> 1
A24: 601a6b19587d0eb400b696ad | B24: Tel Dolap Pasta & Cafe, Sapanca (Merkez) | C24: DOĞRU | D24: Pasta & Tatlı | E24: 208 | F24: 5 | G24: 0 | H24: 63 | I24: 63 | J24: 0 | K24: Ahmet Efiloğlu | L24: 2645825452 | M24: Sapanca | N24: Rüstempaşa | O24: Ersin Cad., No:36, Sapanca, Sakarya, Türkiye, | P24: Geleneksel | Q24: =COUNTIF('Hedef Liste'!A:A,A24) -> 1
A25: 601dc1f409400e2d06ce3cbd | B25: Mengen Döner, Adapazarı (Cumhuriyet Mah.) | C25: DOĞRU | D25: Döner | E25: 6 | F25: 2 | G25: 0 | H25: 20 | I25: 20 | J25: 0 | K25: Vedat Korkmaz | L25: 5300271965 | M25: Adapazarı | N25: Semerciler | O25: Semerciler Mah., İtfaiye Cad., No:41, Adapazarı, Sakarya, Türkiye, | P25: Geleneksel | Q25: =COUNTIF('Hedef Liste'!A:A,A25) -> 1
A26: 601e335e8adaa12715e3d2dc | B26: Erzurum Cağ Kebabı, Erenler (Hacıoğlu Mah.) | C26: YANLIŞ | D26: Kebap | E26: 93 | G26: 22 | H26: 16 | I26: 38 | J26: 0.58 | K26: Ayşe Kılıç | L26: 2642411919 | M26: Erenler | N26: Erenler | O26: Sakarbaba Cad., No:6, Erenler, Sakarya, Türkiye, | P26: Geleneksel | Q26: =COUNTIF('Hedef Liste'!A:A,A26) -> 1
A27: 601d11d17167d41f9c67c865 | B27: Çiğ Köfteci Sait, Sapanca (Kırkpınar Hasanpaşa Mah.) | C27: DOĞRU | D27: Çiğ Köfte | E27: 621 | F27: 19 | G27: 8 | H27: 1 | I27: 9 | J27: 0.89 | K27: Sevgi Ceylan | L27: 5528375854 | M27: Sapanca | N27: Kırkpınar Hasanpaşa | O27: Kırkpınar Hasanpaşa Mah., İstasyon Cad., No:11, Sapanca, Sakarya, Türkiye, | P27: Geleneksel | Q27: =COUNTIF('Hedef Liste'!A:A,A27) -> 1
A28: 60210a96bd45894c82a12c0f | B28: Aydın Pide & Kebap, Karasu (Yalı Mah.) | C28: DOĞRU | D28: Kebap | E28: 999 | F28: 22 | G28: 3 | H28: 16 | I28: 19 | J28: 0.16 | K28: Mehmet Aydın | L28: 5418954334 | M28: Karasu | N28: Aziziye | O28: Doğu Karadeniz Cad., No:1 A, Karasu, Sakarya, Türkiye, | P28: Geleneksel | Q28: =COUNTIF('Hedef Liste'!A:A,A28) -> 1
A29: 602248ea6d12e9617149c634 | B29: Mabella, Serdivan (Arabacı Alanı Mah.) | C29: YANLIŞ | D29: Pasta & Tatlı | G29: 0 | H29: 36 | I29: 36 | J29: 0 | K29: Müyesser Kabadayı | L29: 5433299137 | M29: Serdivan | N29: Arabacıalanı | O29: Arabacıalanı mah 551. Sok. No:1 B | P29: Geleneksel | Q29: =COUNTIF('Hedef Liste'!A:A,A29) -> 1
A30: 601e35dd98337bc5cd4cf94f | B30: Kahveci Vahdettin (Cumhuriyet Mah.) | C30: YANLIŞ | D30: Kahve | E30: 1 | G30: 0 | H30: 37 | I30: 37 | J30: 0 | K30: EMRAH CELAL AYDIN | L30: 5062044065 | M30: Adapazarı | N30: Semerciler | O30: CUMHURİYET M. UZUNÇARŞI NO: 88 ADAPAZARI/ SAKARYA | P30: Geleneksel | Q30: =COUNTIF('Hedef Liste'!A:A,A30) -> 1
A31: 601fbcee252c44120f134bfa | B31: Pala Kebap Sarayı, Adapazarı (Mithatpaşa Mah.) | C31: YANLIŞ | D31: Kebap | E31: 2960 | G31: 34 | H31: 21 | I31: 55 | J31: 0.62 | K31: Ramazan Pala | L31: 5312105641 | M31: Adapazarı | N31: Güllük | O31: Adnan Menderes Cad., No:132, Adapazarı, Sakarya, Türkiye, | P31: Geleneksel | Q31: =COUNTIF('Hedef Liste'!A:A,A31) -> 1
A32: 60089ca5b4fcb4c6a375fcc1 | B32: Çağlar Dondurma Izgara (Arabacı Alanı Mah.) | C32: DOĞRU | D32: Dondurma | E32: 469 | F32: 9 | G32: 0 | H32: 37 | I32: 37 | J32: 0 | K32: Emre Akbaba | L32: 2642735240 | M32: Serdivan | N32: Arabacıalanı | O32: Arabacıalanı Mah., Eski Kazımpaşa Cad., No:203A , Serdivan, Sakarya, Türkiye, | P32: Geleneksel | Q32: =COUNTIF('Hedef Liste'!A:A,A32) -> 1
A33: 600a654d0a79b11ba3e3d9a2 | B33: Pizza Piece (İstiklal Mh.) | C33: YANLIŞ | D33: Pizza | E33: 1396 | G33: 0 | H33: 34 | I33: 34 | J33: 0 | K33: Hediye Apaydın | L33: 2642761001 | M33: Serdivan | N33: Bahçelievler | O33: BAHÇELİEVLER MAH. 9. CAD. NO: 5 A SERDİVAN/ SAKARYA | P33: Geleneksel | Q33: =COUNTIF('Hedef Liste'!A:A,A33) -> 1
A34: 600b6ae49dceb6349c080fd9 | B34: Tiki Taka Cafe (Kemalpaşa Mah.) | C34: DOĞRU | D34: Tost & Sandviç | E34: 410 | F34: 22 | G34: 15 | H34: 35 | I34: 50 | J34: 0.3 | K34: Mustafa Gürbüz | L34: 5396772462 | M34: Serdivan | N34: Kemalpaşa | O34: Kemalpaşa Mah. 128. Sok. No.1C Kapı No. 4 Serdivan/Sakarya | P34: Geleneksel | Q34: =COUNTIF('Hedef Liste'!A:A,A34) -> 1
A35: 600bdf5fd6c5917679df8e5e | B35: 6Nova Aperatif (İstiklal Mah.) | C35: DOĞRU | D35: Tost & Sandviç | E35: 563 | G35: 12 | H35: 15 | I35: 27 | J35: 0.44 | K35: SERAP AKAGÜNDÜZ | L35: 5436606666 | M35: Serdivan | N35: İstiklal | O35: Muhsin Yazıcıoğlu Blv., No:69, Serdivan, Sakarya, Türkiye, | P35: Geleneksel | Q35: =COUNTIF('Hedef Liste'!A:A,A35) -> 1
A36: 600eb200262a1803e866f06f | B36: Pera Cafe (Orta Mah.) | C36: DOĞRU | D36: Tost & Sandviç | E36: 561 | F36: 34 | G36: 0 | H36: 57 | I36: 57 | J36: 0 | K36: Emine YAMAN | L36: 2642793939 | M36: Adapazarı | N36: Orta | O36: Orta Mah., Kuzu Sok., No:24, Adapazarı, Sakarya, Türkiye, | P36: Geleneksel | Q36: =COUNTIF('Hedef Liste'!A:A,A36) -> 1
A37: 60101989bce91f700fa632c4 | B37: Ekrem Coşkun Döner, Serdivan (Kemalpaşa Mah) | C37: DOĞRU | D37: Döner | E37: 1588 | F37: 32 | G37: 3 | H37: 16 | I37: 19 | J37: 0.16 | K37: Aykut Aşan | L37: 5398644354 | M37: Serdivan | N37: Esentepe | O37: Bağlar Cad., No:94, Serdivan, Sakarya, Türkiye, | P37: Geleneksel | Q37: =COUNTIF('Hedef Liste'!A:A,A37) -> 1
A38: 6011a7f24337def3c02b94ec | B38: Muammer Usta Pizza (Kemalpaşa Mah.) | C38: DOĞRU | D38: Pizza | E38: 4928 | F38: 194 | G38: 0 | H38: 16 | I38: 16 | J38: 0 | K38: Muammer Akbulut | L38: 5538319554 | M38: Serdivan | N38: Kemalpaşa | O38: Kemalpaşa Mah., 103. Sok., No:9, Serdivan, Sakarya, Türkiye, | P38: Geleneksel | Q38: =COUNTIF('Hedef Liste'!A:A,A38) -> 1
A39: 6015079067e562c4c8859236 | B39: Beytuş, Adapazarı (Cumhuriyet Mah.) | C39: DOĞRU | D39: Burger | E39: 32 | G39: 6 | H39: 23 | I39: 29 | J39: 0.21 | K39: Orçun İbrişim | L39: 5375141441 | M39: Adapazarı | N39: Cumhuriyet | O39: Cumhuriyet Mah., Tül Sok., No:9, Adapazarı, Sakarya, Türkiye, | P39: Geleneksel | Q39: =COUNTIF('Hedef Liste'!A:A,A39) -> 1
A40: 6009f00a9611de6e18cd1ca8 | B40: E-Yemekhane (İstiklal Mah.) | C40: YANLIŞ | D40: Ev Yemekleri | E40: 115 | G40: 0 | H40: 20 | I40: 20 | J40: 0 | K40: Akif Akyıldız | L40: 5075312331 | M40: Adapazarı | N40: Çukurahmediye | O40: Çukurahmediye mah. 226 sok. No:1 Adapazarı / Sakarya | P40: Geleneksel | Q40: =COUNTIF('Hedef Liste'!A:A,A40) -> 1
...

Sheet Durum Parametreler
C2: Başka Şubeden Çekilecek | H2: Mertcan
C3: BlackList | F3: Burak Kavakçı | H3: Enes
A4: 44197 | C4: Çekim İstemiyor | F4: Zeynep Yazıcı | H4: Ezgi Turan
A5: 44198 | C5: Devir | H5: Hatem Soyaslan
A6: 44199 | C6: Dönüş Yapacak | H6: Zeliha Özer
A7: 44200 | C7: Franchise | H7: Emre Dalgıç
A8: 44201 | C8: İleride Randevu Alınacak | H8: Gül Değirmenci
A9: 44202 | C9: Lokasyon Uzak | H9: Yurdagül Kulaksız
A10: 44203 | C10: Haziran'da Aranacak | H10: Ayfer Altın
A11: 44204 | C11: Menü Güncellemesi Yapılacak | F11: Ayşegül Kır | H11: Ayşegül Kır
A12: 44205 | C12: Personel Eksik | F12: Betül Demir | H12: Damla Kılcı
A13: 44206 | C13: Randevu Alındı | F13: Hatem Soyaslan | H13: Özlem arslan
A14: 44207 | C14: Randevu İptal | F14: Selcan Topçu | H14: Beyza gülşah
A15: 44208 | C15: Restoran Silindi | F15: Sude Alkan | H15: Özlem gümüş
A16: 44209 | C16: Sistemden Çıkmak İstiyor | F16: Yurdagül Kulaksız | H16: Tuğba Buyur
A17: 44210 | C17: Tadilat Var | F17: Zeliha Özer | H17: Kadriye Polat
A18: 44211 | C18: Ulaşılamadı | F18: Ferhat Köksal | H18: Şükriye Demir
A19: 44212 | C19: Yılbaşından Sonra Aranacak | F19: Enes Günal | H19: Ece Bayındır
A20: 44213 | F20: Serap Apaydın | H20: Senanur Çınar
A21: 44214 | C21: Dönüş Yapacak | H21: Şura Özcan
A22: 44215 | C22: Görüşüldü | H22: Funda Ünlü
A23: 44216 | C23: Tekrar Aranacak | H23: Sıla Göksunaz Esen
A24: 44217 | C24: Ulaşılamadı | H24: Emel Yılmaz
A25: 44218 | C25: Yetkili Yok | H25: Ecem Ersöz
A26: 44219 | H26: Livanur Elibol
A27: 44220 | C27: Hemen Randevu İstiyorum | H27: Eda Cıbır
A28: 44221 | C28: Fotoğraflarım Var | H28: Meryem Yalabık
A29: 44222 | C29: İleride Randevu İstiyorum | H29: Serenay Yalabık
A30: 44223
A31: 44224
A32: 44225 | C32: Randevu Alınabilir
A33: 44226 | C33: Çekim İstemiyor
A34: 44227 | C34: Fotoğrafları Yok - Randevu Alınabilir
A35: 44228 | C35: Fotoğrafları Gönderecek
A36: 44229
A37: 44230
A38: 44231
A39: 44232
A40: 44233
A41: 44234
...

Sheet Sayfa12
A1: 6071ce22e66040e3b5ba79c7 | B1: =VLOOKUP(A1,'Hedef Liste'!A:T,20) -> İleride Randevu Alınacak | C1: =VLOOKUP(A1,'Hedef Liste'!A:Y,25)
A2: 607e94bf78e84cd044d98fbb | B2: =VLOOKUP(A2,'Hedef Liste'!A:T,20) -> Franchise | C2: =VLOOKUP(A2,'Hedef Liste'!A:Y,25)
A3: 606c43c7fbec05d65a17c1ef | B3: =VLOOKUP(A3,'Hedef Liste'!A:T,20) -> İleride Randevu Alınacak | C3: =VLOOKUP(A3,'Hedef Liste'!A:Y,25)
A4: 6007e68de13dbd621a5c3b07 | B4: =VLOOKUP(A4,'Hedef Liste'!A:T,20) -> #N/A | C4: =VLOOKUP(A4,'Hedef Liste'!A:Y,25) -> #N/A
A5: 60a64fa277346a34507a60a2 | B5: =VLOOKUP(A5,'Hedef Liste'!A:T,20) | C5: =VLOOKUP(A5,'Hedef Liste'!A:Y,25)
A6: 601b19519b217f6c71b3b86f | B6: =VLOOKUP(A6,'Hedef Liste'!A:T,20) -> Randevu Alındı | C6: =VLOOKUP(A6,'Hedef Liste'!A:Y,25) -> 44300
A7: 607a98ead384d4985ad2c708 | B7: =VLOOKUP(A7,'Hedef Liste'!A:T,20) -> Franchise | C7: =VLOOKUP(A7,'Hedef Liste'!A:Y,25)
A8: 608818cce7384949ae5fcc1c | B8: =VLOOKUP(A8,'Hedef Liste'!A:T,20) -> Franchise | C8: =VLOOKUP(A8,'Hedef Liste'!A:Y,25)

Sheet özet
G4: Tarih | H4: Başarılı Randevu | I4: İptal Randevu | J4: Top. Rest | K4: =COUNTIFS(import!$C:$C,"true",import!$P:$P,"Geleneksel") -> 0 | O4: İptal Randevu | P4: Fotoğraflandırılan Top. Ürün | Q4: Fotoğraflandırılan Ort. Ürün
B5: Başka Şubeden Çekilecek | C5: =COUNTIFS('Hedef Liste'!T:T,B5,'Hedef Liste'!C:C,"doğru",'Hedef Liste'!P:P,"Geleneksel",'Hedef Liste'!J:J,"=0%") -> 4 | D5: toplam rest | E5: =COUNTIFS(import!C:C,"doğru",import!P:P,"Geleneksel") -> 307 | J5: Fotoğraflı | K5: =COUNTIFS(import!$C:$C,"true",import!$P:$P,"Geleneksel",import!$J:$J,">0%") -> 0 | M5: =$K$5/$K$4 -> #DIV/0!
B6: BlackList | C6: =COUNTIFS('Hedef Liste'!T:T,B6,'Hedef Liste'!C:C,"doğru",'Hedef Liste'!P:P,"Geleneksel",'Hedef Liste'!J:J,"=0%") -> 1 | D6: fotoğraflı | E6: =COUNTIFS(import!C:C,"doğru",import!P:P,"Geleneksel",import!J:J,">0%") -> 143
B7: Çekim İstemiyor | C7: =COUNTIFS('Hedef Liste'!T:T,B7,'Hedef Liste'!C:C,"doğru",'Hedef Liste'!P:P,"Geleneksel",'Hedef Liste'!J:J,"=0%") -> 16 | D7: % | E7: =E6/E5 -> 0.46579805 | J7: Ürün Adet | K7: 0-25 | M7: 25+ | S7: İptal Oranı
B8: Devir | C8: =COUNTIFS('Hedef Liste'!T:T,B8,'Hedef Liste'!C:C,"doğru",'Hedef Liste'!P:P,"Geleneksel",'Hedef Liste'!J:J,"=0%") -> 0 | J8: Fotoğraflı | K8: =COUNTIFS(import!$C:$C,"true",import!$J:$J,">0%",import!$P:$P,"Geleneksel",import!$I:$I,"<=25") -> 0 | L8: =K8/K5 -> #DIV/0! | M8: =COUNTIFS(import!C:C,"true",import!J:J,">0%",import!P:P,"Geleneksel",import!I:I,">25") -> 0 | N8: =M8/K5 -> #DIV/0! | S8: =O13/N13 -> #DIV/0!
B9: Dönüş Yapacak | C9: =COUNTIFS('Hedef Liste'!T:T,B9,'Hedef Liste'!C:C,"doğru",'Hedef Liste'!P:P,"Geleneksel",'Hedef Liste'!J:J,"=0%") -> 1 | J9: 0-20% | K9: =COUNTIFS(import!C:C,"true",import!J:J,">0%",import!J:J,"<=20%",import!P:P,"Geleneksel",import!I:I,"<=25") -> 0 | L9: =K9/K8 -> #DIV/0! | M9: =COUNTIFS(import!C:C,"true",import!J:J,">0%",import!J:J,"<=20%",import!P:P,"Geleneksel",import!I:I,">25") -> 0 | N9: =M9/M8 -> #DIV/0!
B10: Franchise | C10: =COUNTIFS('Hedef Liste'!T:T,B10,'Hedef Liste'!C:C,"doğru",'Hedef Liste'!P:P,"Geleneksel",'Hedef Liste'!J:J,"=0%") -> 6 | J10: 21-50% | K10: =COUNTIFS(import!C:C,"true",import!J:J,">20%",import!J:J,"<=50%",import!P:P,"Geleneksel",import!I:I,"<=25") -> 0 | L10: =K10/K8 -> #DIV/0! | M10: =COUNTIFS(import!C:C,"true",import!J:J,">20%",import!J:J,"<=50%",import!P:P,"Geleneksel",import!I:I,">25") -> 0 | N10: =M10/M8 -> #DIV/0!
B11: İleride Randevu Alınacak | C11: =COUNTIFS('Hedef Liste'!T:T,B11,'Hedef Liste'!C:C,"doğru",'Hedef Liste'!P:P,"Geleneksel",'Hedef Liste'!J:J,"=0%") -> 16 | J11: 51-80% | K11: =COUNTIFS(import!C:C,"true",import!J:J,">50%",import!J:J,"<=80%",import!P:P,"Geleneksel",import!I:I,"<=25") -> 0 | L11: =K11/K8 -> #DIV/0! | M11: =COUNTIFS(import!C:C,"true",import!J:J,">50%",import!J:J,"<=80%",import!P:P,"Geleneksel",import!I:I,">25") -> 0 | N11: =M11/M8 -> #DIV/0!
B12: Lokasyon Uzak | C12: =COUNTIFS('Hedef Liste'!T:T,B12,'Hedef Liste'!C:C,"doğru",'Hedef Liste'!P:P,"Geleneksel",'Hedef Liste'!J:J,"=0%") -> 0 | J12: >80% | K12: =COUNTIFS(import!C:C,"true",import!J:J,">80%",import!P:P,"Geleneksel",import!I:I,"<=25") -> 0 | L12: =K12/K8 -> #DIV/0! | M12: =COUNTIFS(import!C:C,"true",import!J:J,">80%",import!P:P,"Geleneksel",import!I:I,">25") -> 0 | N12: =M12/M8 -> #DIV/0!
B13: Haziran'da Aranacak | C13: =COUNTIFS('Hedef Liste'!T:T,B13,'Hedef Liste'!C:C,"doğru",'Hedef Liste'!P:P,"Geleneksel",'Hedef Liste'!J:J,"=0%") -> 0
