Workbook

Sheet Özet
C2: Adıyaman | D2: Afyon | E2: Amasya | F2: Bartın | G2: Bilecik | H2: Bolu | I2: Çankırı | J2: Diyarbakır | K2: Düzce | L2: Elazığ | M2: Erzurum | N2: Giresun | O2: Iğdır | P2: Karabük | Q2: Kastamonu | R2: Kırklareli | S2: Konya | T2: Malatya | U2: Ordu | V2: Osmaniye | W2: Sinop | X2: Tokat | Y2: Uşak | Z2: Yalova | AA2: Zonguldak | AB2: Karaman
B3: Başka Şubeden Çekilecek | C3: =COUNTIFS('Hedef Liste Adıyaman'!R:R,B3,'Hedef Liste Adıyaman'!C:C,"doğru",'Hedef Liste Adıyaman'!J:J,"=0%",'Hedef Liste Adıyaman'!P:P,"Geleneksel") -> 5 | D3: =COUNTIFS('Hedef Liste Afyon'!R:R,B3,'Hedef Liste Afyon'!C:C,"true",'Hedef Liste Afyon'!J:J,"=0%",'Hedef Liste Afyon'!P:P,"Geleneksel") -> 2 | E3: =COUNTIFS('Hedef Liste Amasya'!R:R,B3,'Hedef Liste Amasya'!C:C,"doğru",'Hedef Liste Amasya'!J:J,"=0%",'Hedef Liste Amasya'!P:P,"Geleneksel") -> 0 | F3: =COUNTIFS('Hedef Liste Bartın'!R:R,B3,'Hedef Liste Bartın'!C:C,"doğru",'Hedef Liste Bartın'!J:J,"=0%",'Hedef Liste Bartın'!P:P,"Geleneksel") -> 0 | G3: =COUNTIFS('Hedef Liste Bilecik'!R:R,B3,'Hedef Liste Bilecik'!C:C,"doğru",'Hedef Liste Bilecik'!J:J,"=0%",'Hedef Liste Bilecik'!P:P,"Geleneksel") -> 0 | H3: =COUNTIFS('Hedef Liste Bolu'!R:R,B3,'Hedef Liste Bolu'!C:C,"doğru",'Hedef Liste Bolu'!J:J,"=0%",'Hedef Liste Bolu'!P:P,"Geleneksel") -> 0 | I3: =COUNTIFS('Hedef Liste Çankırı'!R:R,B3,'Hedef Liste Çankırı'!C:C,"doğru",'Hedef Liste Çankırı'!J:J,"=0%",'Hedef Liste Çankırı'!P:P,"Geleneksel") -> 0 | J3: =COUNTIFS('Hedef Liste Diyarbakır'!R:R,B3,'Hedef Liste Diyarbakır'!C:C,"doğru",'Hedef Liste Diyarbakır'!J:J,"=0%",'Hedef Liste Diyarbakır'!P:P,"Geleneksel") -> 0 | K3: =COUNTIFS('Hedef Liste Düzce'!R:R,B3,'Hedef Liste Düzce'!C:C,"true",'Hedef Liste Düzce'!J:J,"=0%",'Hedef Liste Düzce'!P:P,"Geleneksel") -> 0 | L3: =COUNTIFS('Hedef Liste Elazığ'!R:R,B3,'Hedef Liste Elazığ'!C:C,"doğru",'Hedef Liste Elazığ'!J:J,"=0%",'Hedef Liste Elazığ'!P:P,"Geleneksel") -> 0 | M3: =COUNTIFS('Hedef Liste Erzurum'!R:R,B3,'Hedef Liste Erzurum'!C:C,"true",'Hedef Liste Erzurum'!J:J,"=0%",'Hedef Liste Erzurum'!P:P,"Geleneksel") -> 4 | N3: =COUNTIFS('Hedef Liste Giresun'!R:R,B3,'Hedef Liste Giresun'!C:C,"doğru",'Hedef Liste Giresun'!J:J,"=0%",'Hedef Liste Giresun'!P:P,"Geleneksel") -> 0 | O3: =COUNTIFS('Hedef Liste Iğdır'!R:R,B3,'Hedef Liste Iğdır'!C:C,"doğru",'Hedef Liste Iğdır'!J:J,"=0%",'Hedef Liste Iğdır'!P:P,"Geleneksel") -> 0 | P3: =COUNTIFS('Hedef Liste Karabük'!R:R,B3,'Hedef Liste Karabük'!C:C,"true",'Hedef Liste Karabük'!J:J,"=0%",'Hedef Liste Karabük'!P:P,"Geleneksel") -> 0 | Q3: =COUNTIFS('Hedef Liste Kastamonu'!R:R,B3,'Hedef Liste Kastamonu'!C:C,"true",'Hedef Liste Kastamonu'!J:J,"=0%",'Hedef Liste Kastamonu'!P:P,"Geleneksel") -> 0 | R3: =COUNTIFS('Hedef Liste Kırklareli'!R:R,B3,'Hedef Liste Kırklareli'!C:C,"doğru",'Hedef Liste Kırklareli'!J:J,"=0%",'Hedef Liste Kırklareli'!P:P,"Geleneksel") -> 0 | S3: =COUNTIFS('Hedef Liste Konya'!R:R,B3,'Hedef Liste Konya'!C:C,"doğru",'Hedef Liste Konya'!J:J,"=0%",'Hedef Liste Konya'!P:P,"Geleneksel") -> 11 | T3: =COUNTIFS('Hedef Liste Malatya'!R:R,B3,'Hedef Liste Malatya'!C:C,"doğru",'Hedef Liste Malatya'!J:J,"=0%",'Hedef Liste Malatya'!P:P,"Geleneksel") -> 6 | U3: =COUNTIFS('Hedef Liste Ordu'!R:R,B3,'Hedef Liste Ordu'!C:C,"true",'Hedef Liste Ordu'!J:J,"=0%",'Hedef Liste Ordu'!P:P,"Geleneksel") -> 6 | V3: =COUNTIFS('Hedef Liste Osmaniye'!R:R,B3,'Hedef Liste Osmaniye'!C:C,"doğru",'Hedef Liste Osmaniye'!J:J,"=0%",'Hedef Liste Osmaniye'!P:P,"Geleneksel") -> 0 | W3: =COUNTIFS('Hedef Liste Sinop'!T:T,B3,'Hedef Liste Sinop'!C:C,"doğru",'Hedef Liste Sinop'!J:J,"=0%",'Hedef Liste Sinop'!P:P,"Geleneksel") -> 0 | X3: =COUNTIFS('Hedef Liste Tokat'!R:R,B3,'Hedef Liste Tokat'!C:C,"doğru",'Hedef Liste Tokat'!J:J,"=0%",'Hedef Liste Tokat'!P:P,"Geleneksel") -> 3 | Y3: =COUNTIFS('Hedef Liste Uşak'!R:R,B3,'Hedef Liste Uşak'!C:C,"true",'Hedef Liste Uşak'!J:J,"=0%",'Hedef Liste Uşak'!P:P,"Geleneksel") -> 0 | Z3: =COUNTIFS('Hedef Liste Yalova'!R:R,B3,'Hedef Liste Yalova'!C:C,"true",'Hedef Liste Yalova'!J:J,"=0%",'Hedef Liste Yalova'!P:P,"Geleneksel") -> 0 | AA3: =COUNTIFS('Hedef Liste Zonguldak'!R:R,B3,'Hedef Liste Zonguldak'!C:C,"true",'Hedef Liste Zonguldak'!J:J,"=0%",'Hedef Liste Zonguldak'!P:P,"Geleneksel") -> 0 | AB3: =COUNTIFS('Hedef Liste Karaman'!R:R,B3,'Hedef Liste Karaman'!C:C,"doğru",'Hedef Liste Karaman'!J:J,"=0%",'Hedef Liste Karaman'!P:P,"Geleneksel") -> 0
B4: BlackList | C4: =COUNTIFS('Hedef Liste Adıyaman'!R:R,B4,'Hedef Liste Adıyaman'!C:C,"doğru",'Hedef Liste Adıyaman'!J:J,"=0%",'Hedef Liste Adıyaman'!P:P,"Geleneksel") -> 0 | D4: =COUNTIFS('Hedef Liste Afyon'!R:R,B4,'Hedef Liste Afyon'!C:C,"true",'Hedef Liste Afyon'!J:J,"=0%",'Hedef Liste Afyon'!P:P,"Geleneksel") -> 2 | E4: =COUNTIFS('Hedef Liste Amasya'!R:R,B4,'Hedef Liste Amasya'!C:C,"doğru",'Hedef Liste Amasya'!J:J,"=0%",'Hedef Liste Amasya'!P:P,"Geleneksel") -> 0 | F4: =COUNTIFS('Hedef Liste Bartın'!R:R,B4,'Hedef Liste Bartın'!C:C,"doğru",'Hedef Liste Bartın'!J:J,"=0%",'Hedef Liste Bartın'!P:P,"Geleneksel") -> 0 | G4: =COUNTIFS('Hedef Liste Bilecik'!R:R,B4,'Hedef Liste Bilecik'!C:C,"doğru",'Hedef Liste Bilecik'!J:J,"=0%",'Hedef Liste Bilecik'!P:P,"Geleneksel") -> 0 | H4: =COUNTIFS('Hedef Liste Bolu'!R:R,B4,'Hedef Liste Bolu'!C:C,"doğru",'Hedef Liste Bolu'!J:J,"=0%",'Hedef Liste Bolu'!P:P,"Geleneksel") -> 0 | I4: =COUNTIFS('Hedef Liste Çankırı'!R:R,B4,'Hedef Liste Çankırı'!C:C,"doğru",'Hedef Liste Çankırı'!J:J,"=0%",'Hedef Liste Çankırı'!P:P,"Geleneksel") -> 0 | J4: =COUNTIFS('Hedef Liste Diyarbakır'!R:R,B4,'Hedef Liste Diyarbakır'!C:C,"doğru",'Hedef Liste Diyarbakır'!J:J,"=0%",'Hedef Liste Diyarbakır'!P:P,"Geleneksel") -> 0 | K4: =COUNTIFS('Hedef Liste Düzce'!R:R,B4,'Hedef Liste Düzce'!C:C,"true",'Hedef Liste Düzce'!J:J,"=0%",'Hedef Liste Düzce'!P:P,"Geleneksel") -> 0 | L4: =COUNTIFS('Hedef Liste Elazığ'!R:R,B4,'Hedef Liste Elazığ'!C:C,"doğru",'Hedef Liste Elazığ'!J:J,"=0%",'Hedef Liste Elazığ'!P:P,"Geleneksel") -> 0 | M4: =COUNTIFS('Hedef Liste Erzurum'!R:R,B4,'Hedef Liste Erzurum'!C:C,"true",'Hedef Liste Erzurum'!J:J,"=0%",'Hedef Liste Erzurum'!P:P,"Geleneksel") -> 1 | N4: =COUNTIFS('Hedef Liste Giresun'!R:R,B4,'Hedef Liste Giresun'!C:C,"doğru",'Hedef Liste Giresun'!J:J,"=0%",'Hedef Liste Giresun'!P:P,"Geleneksel") -> 0 | O4: =COUNTIFS('Hedef Liste Iğdır'!R:R,B4,'Hedef Liste Iğdır'!C:C,"doğru",'Hedef Liste Iğdır'!J:J,"=0%",'Hedef Liste Iğdır'!P:P,"Geleneksel") -> 0 | P4: =COUNTIFS('Hedef Liste Karabük'!R:R,B4,'Hedef Liste Karabük'!C:C,"true",'Hedef Liste Karabük'!J:J,"=0%",'Hedef Liste Karabük'!P:P,"Geleneksel") -> 0 | Q4: =COUNTIFS('Hedef Liste Kastamonu'!R:R,B4,'Hedef Liste Kastamonu'!C:C,"true",'Hedef Liste Kastamonu'!J:J,"=0%",'Hedef Liste Kastamonu'!P:P,"Geleneksel") -> 0 | R4: =COUNTIFS('Hedef Liste Kırklareli'!R:R,B4,'Hedef Liste Kırklareli'!C:C,"doğru",'Hedef Liste Kırklareli'!J:J,"=0%",'Hedef Liste Kırklareli'!P:P,"Geleneksel") -> 0 | S4: =COUNTIFS('Hedef Liste Konya'!R:R,B4,'Hedef Liste Konya'!C:C,"doğru",'Hedef Liste Konya'!J:J,"=0%",'Hedef Liste Konya'!P:P,"Geleneksel") -> 6 | T4: =COUNTIFS('Hedef Liste Malatya'!R:R,B4,'Hedef Liste Malatya'!C:C,"doğru",'Hedef Liste Malatya'!J:J,"=0%",'Hedef Liste Malatya'!P:P,"Geleneksel") -> 0 | U4: =COUNTIFS('Hedef Liste Ordu'!R:R,B4,'Hedef Liste Ordu'!C:C,"true",'Hedef Liste Ordu'!J:J,"=0%",'Hedef Liste Ordu'!P:P,"Geleneksel") -> 0 | V4: =COUNTIFS('Hedef Liste Osmaniye'!R:R,B4,'Hedef Liste Osmaniye'!C:C,"doğru",'Hedef Liste Osmaniye'!J:J,"=0%",'Hedef Liste Osmaniye'!P:P,"Geleneksel") -> 0 | W4: =COUNTIFS('Hedef Liste Sinop'!T:T,B4,'Hedef Liste Sinop'!C:C,"doğru",'Hedef Liste Sinop'!J:J,"=0%",'Hedef Liste Sinop'!P:P,"Geleneksel") -> 0 | X4: =COUNTIFS('Hedef Liste Tokat'!R:R,B4,'Hedef Liste Tokat'!C:C,"doğru",'Hedef Liste Tokat'!J:J,"=0%",'Hedef Liste Tokat'!P:P,"Geleneksel") -> 1 | Y4: =COUNTIFS('Hedef Liste Uşak'!R:R,B4,'Hedef Liste Uşak'!C:C,"true",'Hedef Liste Uşak'!J:J,"=0%",'Hedef Liste Uşak'!P:P,"Geleneksel") -> 0 | Z4: =COUNTIFS('Hedef Liste Yalova'!R:R,B4,'Hedef Liste Yalova'!C:C,"true",'Hedef Liste Yalova'!J:J,"=0%",'Hedef Liste Yalova'!P:P,"Geleneksel") -> 0 | AA4: =COUNTIFS('Hedef Liste Zonguldak'!R:R,B4,'Hedef Liste Zonguldak'!C:C,"true",'Hedef Liste Zonguldak'!J:J,"=0%",'Hedef Liste Zonguldak'!P:P,"Geleneksel") -> 0 | AB4: =COUNTIFS('Hedef Liste Karaman'!R:R,B4,'Hedef Liste Karaman'!C:C,"doğru",'Hedef Liste Karaman'!J:J,"=0%",'Hedef Liste Karaman'!P:P,"Geleneksel") -> 0
B5: Çekim İstemiyor | C5: =COUNTIFS('Hedef Liste Adıyaman'!R:R,B5,'Hedef Liste Adıyaman'!C:C,"doğru",'Hedef Liste Adıyaman'!J:J,"=0%",'Hedef Liste Adıyaman'!P:P,"Geleneksel") -> 10 | D5: =COUNTIFS('Hedef Liste Afyon'!R:R,B5,'Hedef Liste Afyon'!C:C,"true",'Hedef Liste Afyon'!J:J,"=0%",'Hedef Liste Afyon'!P:P,"Geleneksel") -> 15 | E5: =COUNTIFS('Hedef Liste Amasya'!R:R,B5,'Hedef Liste Amasya'!C:C,"doğru",'Hedef Liste Amasya'!J:J,"=0%",'Hedef Liste Amasya'!P:P,"Geleneksel") -> 10 | F5: =COUNTIFS('Hedef Liste Bartın'!R:R,B5,'Hedef Liste Bartın'!C:C,"doğru",'Hedef Liste Bartın'!J:J,"=0%",'Hedef Liste Bartın'!P:P,"Geleneksel") -> 14 | G5: =COUNTIFS('Hedef Liste Bilecik'!R:R,B5,'Hedef Liste Bilecik'!C:C,"doğru",'Hedef Liste Bilecik'!J:J,"=0%",'Hedef Liste Bilecik'!P:P,"Geleneksel") -> 4 | H5: =COUNTIFS('Hedef Liste Bolu'!R:R,B5,'Hedef Liste Bolu'!C:C,"doğru",'Hedef Liste Bolu'!J:J,"=0%",'Hedef Liste Bolu'!P:P,"Geleneksel") -> 4 | I5: =COUNTIFS('Hedef Liste Çankırı'!R:R,B5,'Hedef Liste Çankırı'!C:C,"doğru",'Hedef Liste Çankırı'!J:J,"=0%",'Hedef Liste Çankırı'!P:P,"Geleneksel") -> 0 | J5: =COUNTIFS('Hedef Liste Diyarbakır'!R:R,B5,'Hedef Liste Diyarbakır'!C:C,"doğru",'Hedef Liste Diyarbakır'!J:J,"=0%",'Hedef Liste Diyarbakır'!P:P,"Geleneksel") -> 0 | K5: =COUNTIFS('Hedef Liste Düzce'!R:R,B5,'Hedef Liste Düzce'!C:C,"true",'Hedef Liste Düzce'!J:J,"=0%",'Hedef Liste Düzce'!P:P,"Geleneksel") -> 12 | L5: =COUNTIFS('Hedef Liste Elazığ'!R:R,B5,'Hedef Liste Elazığ'!C:C,"doğru",'Hedef Liste Elazığ'!J:J,"=0%",'Hedef Liste Elazığ'!P:P,"Geleneksel") -> 2 | M5: =COUNTIFS('Hedef Liste Erzurum'!R:R,B5,'Hedef Liste Erzurum'!C:C,"true",'Hedef Liste Erzurum'!J:J,"=0%",'Hedef Liste Erzurum'!P:P,"Geleneksel") -> 3 | N5: =COUNTIFS('Hedef Liste Giresun'!R:R,B5,'Hedef Liste Giresun'!C:C,"doğru",'Hedef Liste Giresun'!J:J,"=0%",'Hedef Liste Giresun'!P:P,"Geleneksel") -> 2 | O5: =COUNTIFS('Hedef Liste Iğdır'!R:R,B5,'Hedef Liste Iğdır'!C:C,"doğru",'Hedef Liste Iğdır'!J:J,"=0%",'Hedef Liste Iğdır'!P:P,"Geleneksel") -> 0 | P5: =COUNTIFS('Hedef Liste Karabük'!R:R,B5,'Hedef Liste Karabük'!C:C,"true",'Hedef Liste Karabük'!J:J,"=0%",'Hedef Liste Karabük'!P:P,"Geleneksel") -> 15 | Q5: =COUNTIFS('Hedef Liste Kastamonu'!R:R,B5,'Hedef Liste Kastamonu'!C:C,"true",'Hedef Liste Kastamonu'!J:J,"=0%",'Hedef Liste Kastamonu'!P:P,"Geleneksel") -> 0 | R5: =COUNTIFS('Hedef Liste Kırklareli'!R:R,B5,'Hedef Liste Kırklareli'!C:C,"doğru",'Hedef Liste Kırklareli'!J:J,"=0%",'Hedef Liste Kırklareli'!P:P,"Geleneksel") -> 13 | S5: =COUNTIFS('Hedef Liste Konya'!R:R,B5,'Hedef Liste Konya'!C:C,"doğru",'Hedef Liste Konya'!J:J,"=0%",'Hedef Liste Konya'!P:P,"Geleneksel") -> 57 | T5: =COUNTIFS('Hedef Liste Malatya'!R:R,B5,'Hedef Liste Malatya'!C:C,"doğru",'Hedef Liste Malatya'!J:J,"=0%",'Hedef Liste Malatya'!P:P,"Geleneksel") -> 14 | U5: =COUNTIFS('Hedef Liste Ordu'!R:R,B5,'Hedef Liste Ordu'!C:C,"true",'Hedef Liste Ordu'!J:J,"=0%",'Hedef Liste Ordu'!P:P,"Geleneksel") -> 7 | V5: =COUNTIFS('Hedef Liste Osmaniye'!R:R,B5,'Hedef Liste Osmaniye'!C:C,"doğru",'Hedef Liste Osmaniye'!J:J,"=0%",'Hedef Liste Osmaniye'!P:P,"Geleneksel") -> 6 | W5: =COUNTIFS('Hedef Liste Sinop'!T:T,B5,'Hedef Liste Sinop'!C:C,"doğru",'Hedef Liste Sinop'!J:J,"=0%",'Hedef Liste Sinop'!P:P,"Geleneksel") -> 3 | X5: =COUNTIFS('Hedef Liste Tokat'!R:R,B5,'Hedef Liste Tokat'!C:C,"doğru",'Hedef Liste Tokat'!J:J,"=0%",'Hedef Liste Tokat'!P:P,"Geleneksel") -> 6 | Y5: =COUNTIFS('Hedef Liste Uşak'!R:R,B5,'Hedef Liste Uşak'!C:C,"true",'Hedef Liste Uşak'!J:J,"=0%",'Hedef Liste Uşak'!P:P,"Geleneksel") -> 0 | Z5: =COUNTIFS('Hedef Liste Yalova'!R:R,B5,'Hedef Liste Yalova'!C:C,"true",'Hedef Liste Yalova'!J:J,"=0%",'Hedef Liste Yalova'!P:P,"Geleneksel") -> 8 | AA5: =COUNTIFS('Hedef Liste Zonguldak'!R:R,B5,'Hedef Liste Zonguldak'!C:C,"true",'Hedef Liste Zonguldak'!J:J,"=0%",'Hedef Liste Zonguldak'!P:P,"Geleneksel") -> 0 | AB5: =COUNTIFS('Hedef Liste Karaman'!R:R,B5,'Hedef Liste Karaman'!C:C,"doğru",'Hedef Liste Karaman'!J:J,"=0%",'Hedef Liste Karaman'!P:P,"Geleneksel") -> 8
B6: Devir | C6: =COUNTIFS('Hedef Liste Adıyaman'!R:R,B6,'Hedef Liste Adıyaman'!C:C,"doğru",'Hedef Liste Adıyaman'!J:J,"=0%",'Hedef Liste Adıyaman'!P:P,"Geleneksel") -> 0 | D6: =COUNTIFS('Hedef Liste Afyon'!R:R,B6,'Hedef Liste Afyon'!C:C,"true",'Hedef Liste Afyon'!J:J,"=0%",'Hedef Liste Afyon'!P:P,"Geleneksel") -> 0 | E6: =COUNTIFS('Hedef Liste Amasya'!R:R,B6,'Hedef Liste Amasya'!C:C,"doğru",'Hedef Liste Amasya'!J:J,"=0%",'Hedef Liste Amasya'!P:P,"Geleneksel") -> 0 | F6: =COUNTIFS('Hedef Liste Bartın'!R:R,B6,'Hedef Liste Bartın'!C:C,"doğru",'Hedef Liste Bartın'!J:J,"=0%",'Hedef Liste Bartın'!P:P,"Geleneksel") -> 0 | G6: =COUNTIFS('Hedef Liste Bilecik'!R:R,B6,'Hedef Liste Bilecik'!C:C,"doğru",'Hedef Liste Bilecik'!J:J,"=0%",'Hedef Liste Bilecik'!P:P,"Geleneksel") -> 2 | H6: =COUNTIFS('Hedef Liste Bolu'!R:R,B6,'Hedef Liste Bolu'!C:C,"doğru",'Hedef Liste Bolu'!J:J,"=0%",'Hedef Liste Bolu'!P:P,"Geleneksel") -> 1 | I6: =COUNTIFS('Hedef Liste Çankırı'!R:R,B6,'Hedef Liste Çankırı'!C:C,"doğru",'Hedef Liste Çankırı'!J:J,"=0%",'Hedef Liste Çankırı'!P:P,"Geleneksel") -> 0 | J6: =COUNTIFS('Hedef Liste Diyarbakır'!R:R,B6,'Hedef Liste Diyarbakır'!C:C,"doğru",'Hedef Liste Diyarbakır'!J:J,"=0%",'Hedef Liste Diyarbakır'!P:P,"Geleneksel") -> 0 | K6: =COUNTIFS('Hedef Liste Düzce'!R:R,B6,'Hedef Liste Düzce'!C:C,"true",'Hedef Liste Düzce'!J:J,"=0%",'Hedef Liste Düzce'!P:P,"Geleneksel") -> 1 | L6: =COUNTIFS('Hedef Liste Elazığ'!R:R,B6,'Hedef Liste Elazığ'!C:C,"doğru",'Hedef Liste Elazığ'!J:J,"=0%",'Hedef Liste Elazığ'!P:P,"Geleneksel") -> 0 | M6: =COUNTIFS('Hedef Liste Erzurum'!R:R,B6,'Hedef Liste Erzurum'!C:C,"true",'Hedef Liste Erzurum'!J:J,"=0%",'Hedef Liste Erzurum'!P:P,"Geleneksel") -> 0 | N6: =COUNTIFS('Hedef Liste Giresun'!R:R,B6,'Hedef Liste Giresun'!C:C,"doğru",'Hedef Liste Giresun'!J:J,"=0%",'Hedef Liste Giresun'!P:P,"Geleneksel") -> 2 | O6: =COUNTIFS('Hedef Liste Iğdır'!R:R,B6,'Hedef Liste Iğdır'!C:C,"doğru",'Hedef Liste Iğdır'!J:J,"=0%",'Hedef Liste Iğdır'!P:P,"Geleneksel") -> 0 | P6: =COUNTIFS('Hedef Liste Karabük'!R:R,B6,'Hedef Liste Karabük'!C:C,"true",'Hedef Liste Karabük'!J:J,"=0%",'Hedef Liste Karabük'!P:P,"Geleneksel") -> 1 | Q6: =COUNTIFS('Hedef Liste Kastamonu'!R:R,B6,'Hedef Liste Kastamonu'!C:C,"true",'Hedef Liste Kastamonu'!J:J,"=0%",'Hedef Liste Kastamonu'!P:P,"Geleneksel") -> 0 | R6: =COUNTIFS('Hedef Liste Kırklareli'!R:R,B6,'Hedef Liste Kırklareli'!C:C,"doğru",'Hedef Liste Kırklareli'!J:J,"=0%",'Hedef Liste Kırklareli'!P:P,"Geleneksel") -> 1 | S6: =COUNTIFS('Hedef Liste Konya'!R:R,B6,'Hedef Liste Konya'!C:C,"doğru",'Hedef Liste Konya'!J:J,"=0%",'Hedef Liste Konya'!P:P,"Geleneksel") -> 1 | T6: =COUNTIFS('Hedef Liste Malatya'!R:R,B6,'Hedef Liste Malatya'!C:C,"doğru",'Hedef Liste Malatya'!J:J,"=0%",'Hedef Liste Malatya'!P:P,"Geleneksel") -> 1 | U6: =COUNTIFS('Hedef Liste Ordu'!R:R,B6,'Hedef Liste Ordu'!C:C,"true",'Hedef Liste Ordu'!J:J,"=0%",'Hedef Liste Ordu'!P:P,"Geleneksel") -> 0 | V6: =COUNTIFS('Hedef Liste Osmaniye'!R:R,B6,'Hedef Liste Osmaniye'!C:C,"doğru",'Hedef Liste Osmaniye'!J:J,"=0%",'Hedef Liste Osmaniye'!P:P,"Geleneksel") -> 0 | W6: =COUNTIFS('Hedef Liste Sinop'!T:T,B6,'Hedef Liste Sinop'!C:C,"doğru",'Hedef Liste Sinop'!J:J,"=0%",'Hedef Liste Sinop'!P:P,"Geleneksel") -> 0 | X6: =COUNTIFS('Hedef Liste Tokat'!R:R,B6,'Hedef Liste Tokat'!C:C,"doğru",'Hedef Liste Tokat'!J:J,"=0%",'Hedef Liste Tokat'!P:P,"Geleneksel") -> 0 | Y6: =COUNTIFS('Hedef Liste Uşak'!R:R,B6,'Hedef Liste Uşak'!C:C,"true",'Hedef Liste Uşak'!J:J,"=0%",'Hedef Liste Uşak'!P:P,"Geleneksel") -> 0 | Z6: =COUNTIFS('Hedef Liste Yalova'!R:R,B6,'Hedef Liste Yalova'!C:C,"true",'Hedef Liste Yalova'!J:J,"=0%",'Hedef Liste Yalova'!P:P,"Geleneksel") -> 0 | AA6: =COUNTIFS('Hedef Liste Zonguldak'!R:R,B6,'Hedef Liste Zonguldak'!C:C,"true",'Hedef Liste Zonguldak'!J:J,"=0%",'Hedef Liste Zonguldak'!P:P,"Geleneksel") -> 0 | AB6: =COUNTIFS('Hedef Liste Karaman'!R:R,B6,'Hedef Liste Karaman'!C:C,"doğru",'Hedef Liste Karaman'!J:J,"=0%",'Hedef Liste Karaman'!P:P,"Geleneksel") -> 0
B7: Dönüş Yapacak | C7: =COUNTIFS('Hedef Liste Adıyaman'!R:R,B7,'Hedef Liste Adıyaman'!C:C,"doğru",'Hedef Liste Adıyaman'!J:J,"=0%",'Hedef Liste Adıyaman'!P:P,"Geleneksel") -> 2 | D7: =COUNTIFS('Hedef Liste Afyon'!R:R,B7,'Hedef Liste Afyon'!C:C,"true",'Hedef Liste Afyon'!J:J,"=0%",'Hedef Liste Afyon'!P:P,"Geleneksel") -> 2 | E7: =COUNTIFS('Hedef Liste Amasya'!R:R,B7,'Hedef Liste Amasya'!C:C,"doğru",'Hedef Liste Amasya'!J:J,"=0%",'Hedef Liste Amasya'!P:P,"Geleneksel") -> 2 | F7: =COUNTIFS('Hedef Liste Bartın'!R:R,B7,'Hedef Liste Bartın'!C:C,"doğru",'Hedef Liste Bartın'!J:J,"=0%",'Hedef Liste Bartın'!P:P,"Geleneksel") -> 4 | G7: =COUNTIFS('Hedef Liste Bilecik'!R:R,B7,'Hedef Liste Bilecik'!C:C,"doğru",'Hedef Liste Bilecik'!J:J,"=0%",'Hedef Liste Bilecik'!P:P,"Geleneksel") -> 2 | H7: =COUNTIFS('Hedef Liste Bolu'!R:R,B7,'Hedef Liste Bolu'!C:C,"doğru",'Hedef Liste Bolu'!J:J,"=0%",'Hedef Liste Bolu'!P:P,"Geleneksel") -> 2 | I7: =COUNTIFS('Hedef Liste Çankırı'!R:R,B7,'Hedef Liste Çankırı'!C:C,"doğru",'Hedef Liste Çankırı'!J:J,"=0%",'Hedef Liste Çankırı'!P:P,"Geleneksel") -> 0 | J7: =COUNTIFS('Hedef Liste Diyarbakır'!R:R,B7,'Hedef Liste Diyarbakır'!C:C,"doğru",'Hedef Liste Diyarbakır'!J:J,"=0%",'Hedef Liste Diyarbakır'!P:P,"Geleneksel") -> 0 | K7: =COUNTIFS('Hedef Liste Düzce'!R:R,B7,'Hedef Liste Düzce'!C:C,"true",'Hedef Liste Düzce'!J:J,"=0%",'Hedef Liste Düzce'!P:P,"Geleneksel") -> 8 | L7: =COUNTIFS('Hedef Liste Elazığ'!R:R,B7,'Hedef Liste Elazığ'!C:C,"doğru",'Hedef Liste Elazığ'!J:J,"=0%",'Hedef Liste Elazığ'!P:P,"Geleneksel") -> 3 | M7: =COUNTIFS('Hedef Liste Erzurum'!R:R,B7,'Hedef Liste Erzurum'!C:C,"true",'Hedef Liste Erzurum'!J:J,"=0%",'Hedef Liste Erzurum'!P:P,"Geleneksel") -> 3 | N7: =COUNTIFS('Hedef Liste Giresun'!R:R,B7,'Hedef Liste Giresun'!C:C,"doğru",'Hedef Liste Giresun'!J:J,"=0%",'Hedef Liste Giresun'!P:P,"Geleneksel") -> 2 | O7: =COUNTIFS('Hedef Liste Iğdır'!R:R,B7,'Hedef Liste Iğdır'!C:C,"doğru",'Hedef Liste Iğdır'!J:J,"=0%",'Hedef Liste Iğdır'!P:P,"Geleneksel") -> 3 | P7: =COUNTIFS('Hedef Liste Karabük'!R:R,B7,'Hedef Liste Karabük'!C:C,"true",'Hedef Liste Karabük'!J:J,"=0%",'Hedef Liste Karabük'!P:P,"Geleneksel") -> 3 | Q7: =COUNTIFS('Hedef Liste Kastamonu'!R:R,B7,'Hedef Liste Kastamonu'!C:C,"true",'Hedef Liste Kastamonu'!J:J,"=0%",'Hedef Liste Kastamonu'!P:P,"Geleneksel") -> 0 | R7: =COUNTIFS('Hedef Liste Kırklareli'!R:R,B7,'Hedef Liste Kırklareli'!C:C,"doğru",'Hedef Liste Kırklareli'!J:J,"=0%",'Hedef Liste Kırklareli'!P:P,"Geleneksel") -> 7 | S7: =COUNTIFS('Hedef Liste Konya'!R:R,B7,'Hedef Liste Konya'!C:C,"doğru",'Hedef Liste Konya'!J:J,"=0%",'Hedef Liste Konya'!P:P,"Geleneksel") -> 11 | T7: =COUNTIFS('Hedef Liste Malatya'!R:R,B7,'Hedef Liste Malatya'!C:C,"doğru",'Hedef Liste Malatya'!J:J,"=0%",'Hedef Liste Malatya'!P:P,"Geleneksel") -> 3 | U7: =COUNTIFS('Hedef Liste Ordu'!R:R,B7,'Hedef Liste Ordu'!C:C,"true",'Hedef Liste Ordu'!J:J,"=0%",'Hedef Liste Ordu'!P:P,"Geleneksel") -> 1 | V7: =COUNTIFS('Hedef Liste Osmaniye'!R:R,B7,'Hedef Liste Osmaniye'!C:C,"doğru",'Hedef Liste Osmaniye'!J:J,"=0%",'Hedef Liste Osmaniye'!P:P,"Geleneksel") -> 0 | W7: =COUNTIFS('Hedef Liste Sinop'!T:T,B7,'Hedef Liste Sinop'!C:C,"doğru",'Hedef Liste Sinop'!J:J,"=0%",'Hedef Liste Sinop'!P:P,"Geleneksel") -> 1 | X7: =COUNTIFS('Hedef Liste Tokat'!R:R,B7,'Hedef Liste Tokat'!C:C,"doğru",'Hedef Liste Tokat'!J:J,"=0%",'Hedef Liste Tokat'!P:P,"Geleneksel") -> 1 | Y7: =COUNTIFS('Hedef Liste Uşak'!R:R,B7,'Hedef Liste Uşak'!C:C,"true",'Hedef Liste Uşak'!J:J,"=0%",'Hedef Liste Uşak'!P:P,"Geleneksel") -> 0 | Z7: =COUNTIFS('Hedef Liste Yalova'!R:R,B7,'Hedef Liste Yalova'!C:C,"true",'Hedef Liste Yalova'!J:J,"=0%",'Hedef Liste Yalova'!P:P,"Geleneksel") -> 5 | AA7: =COUNTIFS('Hedef Liste Zonguldak'!R:R,B7,'Hedef Liste Zonguldak'!C:C,"true",'Hedef Liste Zonguldak'!J:J,"=0%",'Hedef Liste Zonguldak'!P:P,"Geleneksel") -> 0 | AB7: =COUNTIFS('Hedef Liste Karaman'!R:R,B7,'Hedef Liste Karaman'!C:C,"doğru",'Hedef Liste Karaman'!J:J,"=0%",'Hedef Liste Karaman'!P:P,"Geleneksel") -> 1
B8: Franchise | C8: =COUNTIFS('Hedef Liste Adıyaman'!R:R,B8,'Hedef Liste Adıyaman'!C:C,"doğru",'Hedef Liste Adıyaman'!J:J,"=0%",'Hedef Liste Adıyaman'!P:P,"Geleneksel") -> 0 | D8: =COUNTIFS('Hedef Liste Afyon'!R:R,B8,'Hedef Liste Afyon'!C:C,"true",'Hedef Liste Afyon'!J:J,"=0%",'Hedef Liste Afyon'!P:P,"Geleneksel") -> 2 | E8: =COUNTIFS('Hedef Liste Amasya'!R:R,B8,'Hedef Liste Amasya'!C:C,"doğru",'Hedef Liste Amasya'!J:J,"=0%",'Hedef Liste Amasya'!P:P,"Geleneksel") -> 1 | F8: =COUNTIFS('Hedef Liste Bartın'!R:R,B8,'Hedef Liste Bartın'!C:C,"doğru",'Hedef Liste Bartın'!J:J,"=0%",'Hedef Liste Bartın'!P:P,"Geleneksel") -> 1 | G8: =COUNTIFS('Hedef Liste Bilecik'!R:R,B8,'Hedef Liste Bilecik'!C:C,"doğru",'Hedef Liste Bilecik'!J:J,"=0%",'Hedef Liste Bilecik'!P:P,"Geleneksel") -> 1 | H8: =COUNTIFS('Hedef Liste Bolu'!R:R,B8,'Hedef Liste Bolu'!C:C,"doğru",'Hedef Liste Bolu'!J:J,"=0%",'Hedef Liste Bolu'!P:P,"Geleneksel") -> 0 | I8: =COUNTIFS('Hedef Liste Çankırı'!R:R,B8,'Hedef Liste Çankırı'!C:C,"doğru",'Hedef Liste Çankırı'!J:J,"=0%",'Hedef Liste Çankırı'!P:P,"Geleneksel") -> 0 | J8: =COUNTIFS('Hedef Liste Diyarbakır'!R:R,B8,'Hedef Liste Diyarbakır'!C:C,"doğru",'Hedef Liste Diyarbakır'!J:J,"=0%",'Hedef Liste Diyarbakır'!P:P,"Geleneksel") -> 0 | K8: =COUNTIFS('Hedef Liste Düzce'!R:R,B8,'Hedef Liste Düzce'!C:C,"true",'Hedef Liste Düzce'!J:J,"=0%",'Hedef Liste Düzce'!P:P,"Geleneksel") -> 0 | L8: =COUNTIFS('Hedef Liste Elazığ'!R:R,B8,'Hedef Liste Elazığ'!C:C,"doğru",'Hedef Liste Elazığ'!J:J,"=0%",'Hedef Liste Elazığ'!P:P,"Geleneksel") -> 0 | M8: =COUNTIFS('Hedef Liste Erzurum'!R:R,B8,'Hedef Liste Erzurum'!C:C,"true",'Hedef Liste Erzurum'!J:J,"=0%",'Hedef Liste Erzurum'!P:P,"Geleneksel") -> 0 | N8: =COUNTIFS('Hedef Liste Giresun'!R:R,B8,'Hedef Liste Giresun'!C:C,"doğru",'Hedef Liste Giresun'!J:J,"=0%",'Hedef Liste Giresun'!P:P,"Geleneksel") -> 0 | O8: =COUNTIFS('Hedef Liste Iğdır'!R:R,B8,'Hedef Liste Iğdır'!C:C,"doğru",'Hedef Liste Iğdır'!J:J,"=0%",'Hedef Liste Iğdır'!P:P,"Geleneksel") -> 1 | P8: =COUNTIFS('Hedef Liste Karabük'!R:R,B8,'Hedef Liste Karabük'!C:C,"true",'Hedef Liste Karabük'!J:J,"=0%",'Hedef Liste Karabük'!P:P,"Geleneksel") -> 0 | Q8: =COUNTIFS('Hedef Liste Kastamonu'!R:R,B8,'Hedef Liste Kastamonu'!C:C,"true",'Hedef Liste Kastamonu'!J:J,"=0%",'Hedef Liste Kastamonu'!P:P,"Geleneksel") -> 0 | R8: =COUNTIFS('Hedef Liste Kırklareli'!R:R,B8,'Hedef Liste Kırklareli'!C:C,"doğru",'Hedef Liste Kırklareli'!J:J,"=0%",'Hedef Liste Kırklareli'!P:P,"Geleneksel") -> 2 | S8: =COUNTIFS('Hedef Liste Konya'!R:R,B8,'Hedef Liste Konya'!C:C,"doğru",'Hedef Liste Konya'!J:J,"=0%",'Hedef Liste Konya'!P:P,"Geleneksel") -> 10 | T8: =COUNTIFS('Hedef Liste Malatya'!R:R,B8,'Hedef Liste Malatya'!C:C,"doğru",'Hedef Liste Malatya'!J:J,"=0%",'Hedef Liste Malatya'!P:P,"Geleneksel") -> 4 | U8: =COUNTIFS('Hedef Liste Ordu'!R:R,B8,'Hedef Liste Ordu'!C:C,"true",'Hedef Liste Ordu'!J:J,"=0%",'Hedef Liste Ordu'!P:P,"Geleneksel") -> 2 | V8: =COUNTIFS('Hedef Liste Osmaniye'!R:R,B8,'Hedef Liste Osmaniye'!C:C,"doğru",'Hedef Liste Osmaniye'!J:J,"=0%",'Hedef Liste Osmaniye'!P:P,"Geleneksel") -> 1 | W8: =COUNTIFS('Hedef Liste Sinop'!T:T,B8,'Hedef Liste Sinop'!C:C,"doğru",'Hedef Liste Sinop'!J:J,"=0%",'Hedef Liste Sinop'!P:P,"Geleneksel") -> 0 | X8: =COUNTIFS('Hedef Liste Tokat'!R:R,B8,'Hedef Liste Tokat'!C:C,"doğru",'Hedef Liste Tokat'!J:J,"=0%",'Hedef Liste Tokat'!P:P,"Geleneksel") -> 4 | Y8: =COUNTIFS('Hedef Liste Uşak'!R:R,B8,'Hedef Liste Uşak'!C:C,"true",'Hedef Liste Uşak'!J:J,"=0%",'Hedef Liste Uşak'!P:P,"Geleneksel") -> 0 | Z8: =COUNTIFS('Hedef Liste Yalova'!R:R,B8,'Hedef Liste Yalova'!C:C,"true",'Hedef Liste Yalova'!J:J,"=0%",'Hedef Liste Yalova'!P:P,"Geleneksel") -> 0 | AA8: =COUNTIFS('Hedef Liste Zonguldak'!R:R,B8,'Hedef Liste Zonguldak'!C:C,"true",'Hedef Liste Zonguldak'!J:J,"=0%",'Hedef Liste Zonguldak'!P:P,"Geleneksel") -> 0 | AB8: =COUNTIFS('Hedef Liste Karaman'!R:R,B8,'Hedef Liste Karaman'!C:C,"doğru",'Hedef Liste Karaman'!J:J,"=0%",'Hedef Liste Karaman'!P:P,"Geleneksel") -> 1
B9: İleride Randevu Alınacak | C9: =COUNTIFS('Hedef Liste Adıyaman'!R:R,B9,'Hedef Liste Adıyaman'!C:C,"doğru",'Hedef Liste Adıyaman'!J:J,"=0%",'Hedef Liste Adıyaman'!P:P,"Geleneksel") -> 5 | D9: =COUNTIFS('Hedef Liste Afyon'!R:R,B9,'Hedef Liste Afyon'!C:C,"true",'Hedef Liste Afyon'!J:J,"=0%",'Hedef Liste Afyon'!P:P,"Geleneksel") -> 5 | E9: =COUNTIFS('Hedef Liste Amasya'!R:R,B9,'Hedef Liste Amasya'!C:C,"doğru",'Hedef Liste Amasya'!J:J,"=0%",'Hedef Liste Amasya'!P:P,"Geleneksel") -> 2 | F9: =COUNTIFS('Hedef Liste Bartın'!R:R,B9,'Hedef Liste Bartın'!C:C,"doğru",'Hedef Liste Bartın'!J:J,"=0%",'Hedef Liste Bartın'!P:P,"Geleneksel") -> 0 | G9: =COUNTIFS('Hedef Liste Bilecik'!R:R,B9,'Hedef Liste Bilecik'!C:C,"doğru",'Hedef Liste Bilecik'!J:J,"=0%",'Hedef Liste Bilecik'!P:P,"Geleneksel") -> 3 | H9: =COUNTIFS('Hedef Liste Bolu'!R:R,B9,'Hedef Liste Bolu'!C:C,"doğru",'Hedef Liste Bolu'!J:J,"=0%",'Hedef Liste Bolu'!P:P,"Geleneksel") -> 1 | I9: =COUNTIFS('Hedef Liste Çankırı'!R:R,B9,'Hedef Liste Çankırı'!C:C,"doğru",'Hedef Liste Çankırı'!J:J,"=0%",'Hedef Liste Çankırı'!P:P,"Geleneksel") -> 0 | J9: =COUNTIFS('Hedef Liste Diyarbakır'!R:R,B9,'Hedef Liste Diyarbakır'!C:C,"doğru",'Hedef Liste Diyarbakır'!J:J,"=0%",'Hedef Liste Diyarbakır'!P:P,"Geleneksel") -> 0 | K9: =COUNTIFS('Hedef Liste Düzce'!R:R,B9,'Hedef Liste Düzce'!C:C,"true",'Hedef Liste Düzce'!J:J,"=0%",'Hedef Liste Düzce'!P:P,"Geleneksel") -> 4 | L9: =COUNTIFS('Hedef Liste Elazığ'!R:R,B9,'Hedef Liste Elazığ'!C:C,"doğru",'Hedef Liste Elazığ'!J:J,"=0%",'Hedef Liste Elazığ'!P:P,"Geleneksel") -> 2 | M9: =COUNTIFS('Hedef Liste Erzurum'!R:R,B9,'Hedef Liste Erzurum'!C:C,"true",'Hedef Liste Erzurum'!J:J,"=0%",'Hedef Liste Erzurum'!P:P,"Geleneksel") -> 2 | N9: =COUNTIFS('Hedef Liste Giresun'!R:R,B9,'Hedef Liste Giresun'!C:C,"doğru",'Hedef Liste Giresun'!J:J,"=0%",'Hedef Liste Giresun'!P:P,"Geleneksel") -> 10 | O9: =COUNTIFS('Hedef Liste Iğdır'!R:R,B9,'Hedef Liste Iğdır'!C:C,"doğru",'Hedef Liste Iğdır'!J:J,"=0%",'Hedef Liste Iğdır'!P:P,"Geleneksel") -> 6 | P9: =COUNTIFS('Hedef Liste Karabük'!R:R,B9,'Hedef Liste Karabük'!C:C,"true",'Hedef Liste Karabük'!J:J,"=0%",'Hedef Liste Karabük'!P:P,"Geleneksel") -> 5 | Q9: =COUNTIFS('Hedef Liste Kastamonu'!R:R,B9,'Hedef Liste Kastamonu'!C:C,"true",'Hedef Liste Kastamonu'!J:J,"=0%",'Hedef Liste Kastamonu'!P:P,"Geleneksel") -> 0 | R9: =COUNTIFS('Hedef Liste Kırklareli'!R:R,B9,'Hedef Liste Kırklareli'!C:C,"doğru",'Hedef Liste Kırklareli'!J:J,"=0%",'Hedef Liste Kırklareli'!P:P,"Geleneksel") -> 11 | S9: =COUNTIFS('Hedef Liste Konya'!R:R,B9,'Hedef Liste Konya'!C:C,"doğru",'Hedef Liste Konya'!J:J,"=0%",'Hedef Liste Konya'!P:P,"Geleneksel") -> 34 | T9: =COUNTIFS('Hedef Liste Malatya'!R:R,B9,'Hedef Liste Malatya'!C:C,"doğru",'Hedef Liste Malatya'!J:J,"=0%",'Hedef Liste Malatya'!P:P,"Geleneksel") -> 5 | U9: =COUNTIFS('Hedef Liste Ordu'!R:R,B9,'Hedef Liste Ordu'!C:C,"true",'Hedef Liste Ordu'!J:J,"=0%",'Hedef Liste Ordu'!P:P,"Geleneksel") -> 1 | V9: =COUNTIFS('Hedef Liste Osmaniye'!R:R,B9,'Hedef Liste Osmaniye'!C:C,"doğru",'Hedef Liste Osmaniye'!J:J,"=0%",'Hedef Liste Osmaniye'!P:P,"Geleneksel") -> 3 | W9: =COUNTIFS('Hedef Liste Sinop'!T:T,B9,'Hedef Liste Sinop'!C:C,"doğru",'Hedef Liste Sinop'!J:J,"=0%",'Hedef Liste Sinop'!P:P,"Geleneksel") -> 0 | X9: =COUNTIFS('Hedef Liste Tokat'!R:R,B9,'Hedef Liste Tokat'!C:C,"doğru",'Hedef Liste Tokat'!J:J,"=0%",'Hedef Liste Tokat'!P:P,"Geleneksel") -> 3 | Y9: =COUNTIFS('Hedef Liste Uşak'!R:R,B9,'Hedef Liste Uşak'!C:C,"true",'Hedef Liste Uşak'!J:J,"=0%",'Hedef Liste Uşak'!P:P,"Geleneksel") -> 0 | Z9: =COUNTIFS('Hedef Liste Yalova'!R:R,B9,'Hedef Liste Yalova'!C:C,"true",'Hedef Liste Yalova'!J:J,"=0%",'Hedef Liste Yalova'!P:P,"Geleneksel") -> 3 | AA9: =COUNTIFS('Hedef Liste Zonguldak'!R:R,B9,'Hedef Liste Zonguldak'!C:C,"true",'Hedef Liste Zonguldak'!J:J,"=0%",'Hedef Liste Zonguldak'!P:P,"Geleneksel") -> 0 | AB9: =COUNTIFS('Hedef Liste Karaman'!R:R,B9,'Hedef Liste Karaman'!C:C,"doğru",'Hedef Liste Karaman'!J:J,"=0%",'Hedef Liste Karaman'!P:P,"Geleneksel") -> 2
B10: Lokasyon Uzak | C10: =COUNTIFS('Hedef Liste Adıyaman'!R:R,B10,'Hedef Liste Adıyaman'!C:C,"doğru",'Hedef Liste Adıyaman'!J:J,"=0%",'Hedef Liste Adıyaman'!P:P,"Geleneksel") -> 0 | D10: =COUNTIFS('Hedef Liste Afyon'!R:R,B10,'Hedef Liste Afyon'!C:C,"true",'Hedef Liste Afyon'!J:J,"=0%",'Hedef Liste Afyon'!P:P,"Geleneksel") -> 9 | E10: =COUNTIFS('Hedef Liste Amasya'!R:R,B10,'Hedef Liste Amasya'!C:C,"doğru",'Hedef Liste Amasya'!J:J,"=0%",'Hedef Liste Amasya'!P:P,"Geleneksel") -> 0 | F10: =COUNTIFS('Hedef Liste Bartın'!R:R,B10,'Hedef Liste Bartın'!C:C,"doğru",'Hedef Liste Bartın'!J:J,"=0%",'Hedef Liste Bartın'!P:P,"Geleneksel") -> 0 | G10: =COUNTIFS('Hedef Liste Bilecik'!R:R,B10,'Hedef Liste Bilecik'!C:C,"doğru",'Hedef Liste Bilecik'!J:J,"=0%",'Hedef Liste Bilecik'!P:P,"Geleneksel") -> 0 | H10: =COUNTIFS('Hedef Liste Bolu'!R:R,B10,'Hedef Liste Bolu'!C:C,"doğru",'Hedef Liste Bolu'!J:J,"=0%",'Hedef Liste Bolu'!P:P,"Geleneksel") -> 0 | I10: =COUNTIFS('Hedef Liste Çankırı'!R:R,B10,'Hedef Liste Çankırı'!C:C,"doğru",'Hedef Liste Çankırı'!J:J,"=0%",'Hedef Liste Çankırı'!P:P,"Geleneksel") -> 0 | J10: =COUNTIFS('Hedef Liste Diyarbakır'!R:R,B10,'Hedef Liste Diyarbakır'!C:C,"doğru",'Hedef Liste Diyarbakır'!J:J,"=0%",'Hedef Liste Diyarbakır'!P:P,"Geleneksel") -> 0 | K10: =COUNTIFS('Hedef Liste Düzce'!R:R,B10,'Hedef Liste Düzce'!C:C,"true",'Hedef Liste Düzce'!J:J,"=0%",'Hedef Liste Düzce'!P:P,"Geleneksel") -> 2 | L10: =COUNTIFS('Hedef Liste Elazığ'!R:R,B10,'Hedef Liste Elazığ'!C:C,"doğru",'Hedef Liste Elazığ'!J:J,"=0%",'Hedef Liste Elazığ'!P:P,"Geleneksel") -> 0 | M10: =COUNTIFS('Hedef Liste Erzurum'!R:R,B10,'Hedef Liste Erzurum'!C:C,"true",'Hedef Liste Erzurum'!J:J,"=0%",'Hedef Liste Erzurum'!P:P,"Geleneksel") -> 0 | N10: =COUNTIFS('Hedef Liste Giresun'!R:R,B10,'Hedef Liste Giresun'!C:C,"doğru",'Hedef Liste Giresun'!J:J,"=0%",'Hedef Liste Giresun'!P:P,"Geleneksel") -> 0 | O10: =COUNTIFS('Hedef Liste Iğdır'!R:R,B10,'Hedef Liste Iğdır'!C:C,"doğru",'Hedef Liste Iğdır'!J:J,"=0%",'Hedef Liste Iğdır'!P:P,"Geleneksel") -> 0 | P10: =COUNTIFS('Hedef Liste Karabük'!R:R,B10,'Hedef Liste Karabük'!C:C,"true",'Hedef Liste Karabük'!J:J,"=0%",'Hedef Liste Karabük'!P:P,"Geleneksel") -> 0 | Q10: =COUNTIFS('Hedef Liste Kastamonu'!R:R,B10,'Hedef Liste Kastamonu'!C:C,"true",'Hedef Liste Kastamonu'!J:J,"=0%",'Hedef Liste Kastamonu'!P:P,"Geleneksel") -> 0 | R10: =COUNTIFS('Hedef Liste Kırklareli'!R:R,B10,'Hedef Liste Kırklareli'!C:C,"doğru",'Hedef Liste Kırklareli'!J:J,"=0%",'Hedef Liste Kırklareli'!P:P,"Geleneksel") -> 0 | S10: =COUNTIFS('Hedef Liste Konya'!R:R,B10,'Hedef Liste Konya'!C:C,"doğru",'Hedef Liste Konya'!J:J,"=0%",'Hedef Liste Konya'!P:P,"Geleneksel") -> 0 | T10: =COUNTIFS('Hedef Liste Malatya'!R:R,B10,'Hedef Liste Malatya'!C:C,"doğru",'Hedef Liste Malatya'!J:J,"=0%",'Hedef Liste Malatya'!P:P,"Geleneksel") -> 1 | U10: =COUNTIFS('Hedef Liste Ordu'!R:R,B10,'Hedef Liste Ordu'!C:C,"true",'Hedef Liste Ordu'!J:J,"=0%",'Hedef Liste Ordu'!P:P,"Geleneksel") -> 4 | V10: =COUNTIFS('Hedef Liste Osmaniye'!R:R,B10,'Hedef Liste Osmaniye'!C:C,"doğru",'Hedef Liste Osmaniye'!J:J,"=0%",'Hedef Liste Osmaniye'!P:P,"Geleneksel") -> 0 | W10: =COUNTIFS('Hedef Liste Sinop'!T:T,B10,'Hedef Liste Sinop'!C:C,"doğru",'Hedef Liste Sinop'!J:J,"=0%",'Hedef Liste Sinop'!P:P,"Geleneksel") -> 0 | X10: =COUNTIFS('Hedef Liste Tokat'!R:R,B10,'Hedef Liste Tokat'!C:C,"doğru",'Hedef Liste Tokat'!J:J,"=0%",'Hedef Liste Tokat'!P:P,"Geleneksel") -> 0 | Y10: =COUNTIFS('Hedef Liste Uşak'!R:R,B10,'Hedef Liste Uşak'!C:C,"true",'Hedef Liste Uşak'!J:J,"=0%",'Hedef Liste Uşak'!P:P,"Geleneksel") -> 0 | Z10: =COUNTIFS('Hedef Liste Yalova'!R:R,B10,'Hedef Liste Yalova'!C:C,"true",'Hedef Liste Yalova'!J:J,"=0%",'Hedef Liste Yalova'!P:P,"Geleneksel") -> 0 | AA10: =COUNTIFS('Hedef Liste Zonguldak'!R:R,B10,'Hedef Liste Zonguldak'!C:C,"true",'Hedef Liste Zonguldak'!J:J,"=0%",'Hedef Liste Zonguldak'!P:P,"Geleneksel") -> 0 | AB10: =COUNTIFS('Hedef Liste Karaman'!R:R,B10,'Hedef Liste Karaman'!C:C,"doğru",'Hedef Liste Karaman'!J:J,"=0%",'Hedef Liste Karaman'!P:P,"Geleneksel") -> 1
B11: Haziran'da Aranacak | C11: =COUNTIFS('Hedef Liste Adıyaman'!R:R,B11,'Hedef Liste Adıyaman'!C:C,"doğru",'Hedef Liste Adıyaman'!J:J,"=0%",'Hedef Liste Adıyaman'!P:P,"Geleneksel") -> 0 | D11: =COUNTIFS('Hedef Liste Afyon'!R:R,B11,'Hedef Liste Afyon'!C:C,"true",'Hedef Liste Afyon'!J:J,"=0%",'Hedef Liste Afyon'!P:P,"Geleneksel") -> 0 | E11: =COUNTIFS('Hedef Liste Amasya'!R:R,B11,'Hedef Liste Amasya'!C:C,"doğru",'Hedef Liste Amasya'!J:J,"=0%",'Hedef Liste Amasya'!P:P,"Geleneksel") -> 0 | F11: =COUNTIFS('Hedef Liste Bartın'!R:R,B11,'Hedef Liste Bartın'!C:C,"doğru",'Hedef Liste Bartın'!J:J,"=0%",'Hedef Liste Bartın'!P:P,"Geleneksel") -> 0 | G11: =COUNTIFS('Hedef Liste Bilecik'!R:R,B11,'Hedef Liste Bilecik'!C:C,"doğru",'Hedef Liste Bilecik'!J:J,"=0%",'Hedef Liste Bilecik'!P:P,"Geleneksel") -> 0 | H11: =COUNTIFS('Hedef Liste Bolu'!R:R,B11,'Hedef Liste Bolu'!C:C,"doğru",'Hedef Liste Bolu'!J:J,"=0%",'Hedef Liste Bolu'!P:P,"Geleneksel") -> 0 | I11: =COUNTIFS('Hedef Liste Çankırı'!R:R,B11,'Hedef Liste Çankırı'!C:C,"doğru",'Hedef Liste Çankırı'!J:J,"=0%",'Hedef Liste Çankırı'!P:P,"Geleneksel") -> 0 | J11: =COUNTIFS('Hedef Liste Diyarbakır'!R:R,B11,'Hedef Liste Diyarbakır'!C:C,"doğru",'Hedef Liste Diyarbakır'!J:J,"=0%",'Hedef Liste Diyarbakır'!P:P,"Geleneksel") -> 0 | K11: =COUNTIFS('Hedef Liste Düzce'!R:R,B11,'Hedef Liste Düzce'!C:C,"true",'Hedef Liste Düzce'!J:J,"=0%",'Hedef Liste Düzce'!P:P,"Geleneksel") -> 0 | L11: =COUNTIFS('Hedef Liste Elazığ'!R:R,B11,'Hedef Liste Elazığ'!C:C,"doğru",'Hedef Liste Elazığ'!J:J,"=0%",'Hedef Liste Elazığ'!P:P,"Geleneksel") -> 0 | M11: =COUNTIFS('Hedef Liste Erzurum'!R:R,B11,'Hedef Liste Erzurum'!C:C,"true",'Hedef Liste Erzurum'!J:J,"=0%",'Hedef Liste Erzurum'!P:P,"Geleneksel") -> 0 | N11: =COUNTIFS('Hedef Liste Giresun'!R:R,B11,'Hedef Liste Giresun'!C:C,"doğru",'Hedef Liste Giresun'!J:J,"=0%",'Hedef Liste Giresun'!P:P,"Geleneksel") -> 0 | O11: =COUNTIFS('Hedef Liste Iğdır'!R:R,B11,'Hedef Liste Iğdır'!C:C,"doğru",'Hedef Liste Iğdır'!J:J,"=0%",'Hedef Liste Iğdır'!P:P,"Geleneksel") -> 0 | P11: =COUNTIFS('Hedef Liste Karabük'!R:R,B11,'Hedef Liste Karabük'!C:C,"true",'Hedef Liste Karabük'!J:J,"=0%",'Hedef Liste Karabük'!P:P,"Geleneksel") -> 0 | Q11: =COUNTIFS('Hedef Liste Kastamonu'!R:R,B11,'Hedef Liste Kastamonu'!C:C,"true",'Hedef Liste Kastamonu'!J:J,"=0%",'Hedef Liste Kastamonu'!P:P,"Geleneksel") -> 0 | R11: =COUNTIFS('Hedef Liste Kırklareli'!R:R,B11,'Hedef Liste Kırklareli'!C:C,"doğru",'Hedef Liste Kırklareli'!J:J,"=0%",'Hedef Liste Kırklareli'!P:P,"Geleneksel") -> 0 | S11: =COUNTIFS('Hedef Liste Konya'!R:R,B11,'Hedef Liste Konya'!C:C,"doğru",'Hedef Liste Konya'!J:J,"=0%",'Hedef Liste Konya'!P:P,"Geleneksel") -> 0 | T11: =COUNTIFS('Hedef Liste Malatya'!R:R,B11,'Hedef Liste Malatya'!C:C,"doğru",'Hedef Liste Malatya'!J:J,"=0%",'Hedef Liste Malatya'!P:P,"Geleneksel") -> 0 | U11: =COUNTIFS('Hedef Liste Ordu'!R:R,B11,'Hedef Liste Ordu'!C:C,"true",'Hedef Liste Ordu'!J:J,"=0%",'Hedef Liste Ordu'!P:P,"Geleneksel") -> 0 | V11: =COUNTIFS('Hedef Liste Osmaniye'!R:R,B11,'Hedef Liste Osmaniye'!C:C,"doğru",'Hedef Liste Osmaniye'!J:J,"=0%",'Hedef Liste Osmaniye'!P:P,"Geleneksel") -> 0 | W11: =COUNTIFS('Hedef Liste Sinop'!T:T,B11,'Hedef Liste Sinop'!C:C,"doğru",'Hedef Liste Sinop'!J:J,"=0%",'Hedef Liste Sinop'!P:P,"Geleneksel") -> 0 | X11: =COUNTIFS('Hedef Liste Tokat'!R:R,B11,'Hedef Liste Tokat'!C:C,"doğru",'Hedef Liste Tokat'!J:J,"=0%",'Hedef Liste Tokat'!P:P,"Geleneksel") -> 0 | Y11: =COUNTIFS('Hedef Liste Uşak'!R:R,B11,'Hedef Liste Uşak'!C:C,"true",'Hedef Liste Uşak'!J:J,"=0%",'Hedef Liste Uşak'!P:P,"Geleneksel") -> 0 | Z11: =COUNTIFS('Hedef Liste Yalova'!R:R,B11,'Hedef Liste Yalova'!C:C,"true",'Hedef Liste Yalova'!J:J,"=0%",'Hedef Liste Yalova'!P:P,"Geleneksel") -> 0 | AA11: =COUNTIFS('Hedef Liste Zonguldak'!R:R,B11,'Hedef Liste Zonguldak'!C:C,"true",'Hedef Liste Zonguldak'!J:J,"=0%",'Hedef Liste Zonguldak'!P:P,"Geleneksel") -> 0 | AB11: =COUNTIFS('Hedef Liste Karaman'!R:R,B11,'Hedef Liste Karaman'!C:C,"doğru",'Hedef Liste Karaman'!J:J,"=0%",'Hedef Liste Karaman'!P:P,"Geleneksel") -> 0
B12: Menü Güncellemesi Yapılacak | C12: =COUNTIFS('Hedef Liste Adıyaman'!R:R,B12,'Hedef Liste Adıyaman'!C:C,"doğru",'Hedef Liste Adıyaman'!J:J,"=0%",'Hedef Liste Adıyaman'!P:P,"Geleneksel") -> 0 | D12: =COUNTIFS('Hedef Liste Afyon'!R:R,B12,'Hedef Liste Afyon'!C:C,"true",'Hedef Liste Afyon'!J:J,"=0%",'Hedef Liste Afyon'!P:P,"Geleneksel") -> 1 | E12: =COUNTIFS('Hedef Liste Amasya'!R:R,B12,'Hedef Liste Amasya'!C:C,"doğru",'Hedef Liste Amasya'!J:J,"=0%",'Hedef Liste Amasya'!P:P,"Geleneksel") -> 0 | F12: =COUNTIFS('Hedef Liste Bartın'!R:R,B12,'Hedef Liste Bartın'!C:C,"doğru",'Hedef Liste Bartın'!J:J,"=0%",'Hedef Liste Bartın'!P:P,"Geleneksel") -> 0 | G12: =COUNTIFS('Hedef Liste Bilecik'!R:R,B12,'Hedef Liste Bilecik'!C:C,"doğru",'Hedef Liste Bilecik'!J:J,"=0%",'Hedef Liste Bilecik'!P:P,"Geleneksel") -> 0 | H12: =COUNTIFS('Hedef Liste Bolu'!R:R,B12,'Hedef Liste Bolu'!C:C,"doğru",'Hedef Liste Bolu'!J:J,"=0%",'Hedef Liste Bolu'!P:P,"Geleneksel") -> 0 | I12: =COUNTIFS('Hedef Liste Çankırı'!R:R,B12,'Hedef Liste Çankırı'!C:C,"doğru",'Hedef Liste Çankırı'!J:J,"=0%",'Hedef Liste Çankırı'!P:P,"Geleneksel") -> 0 | J12: =COUNTIFS('Hedef Liste Diyarbakır'!R:R,B12,'Hedef Liste Diyarbakır'!C:C,"doğru",'Hedef Liste Diyarbakır'!J:J,"=0%",'Hedef Liste Diyarbakır'!P:P,"Geleneksel") -> 0 | K12: =COUNTIFS('Hedef Liste Düzce'!R:R,B12,'Hedef Liste Düzce'!C:C,"true",'Hedef Liste Düzce'!J:J,"=0%",'Hedef Liste Düzce'!P:P,"Geleneksel") -> 0 | L12: =COUNTIFS('Hedef Liste Elazığ'!R:R,B12,'Hedef Liste Elazığ'!C:C,"doğru",'Hedef Liste Elazığ'!J:J,"=0%",'Hedef Liste Elazığ'!P:P,"Geleneksel") -> 0 | M12: =COUNTIFS('Hedef Liste Erzurum'!R:R,B12,'Hedef Liste Erzurum'!C:C,"true",'Hedef Liste Erzurum'!J:J,"=0%",'Hedef Liste Erzurum'!P:P,"Geleneksel") -> 1 | N12: =COUNTIFS('Hedef Liste Giresun'!R:R,B12,'Hedef Liste Giresun'!C:C,"doğru",'Hedef Liste Giresun'!J:J,"=0%",'Hedef Liste Giresun'!P:P,"Geleneksel") -> 0 | O12: =COUNTIFS('Hedef Liste Iğdır'!R:R,B12,'Hedef Liste Iğdır'!C:C,"doğru",'Hedef Liste Iğdır'!J:J,"=0%",'Hedef Liste Iğdır'!P:P,"Geleneksel") -> 0 | P12: =COUNTIFS('Hedef Liste Karabük'!R:R,B12,'Hedef Liste Karabük'!C:C,"true",'Hedef Liste Karabük'!J:J,"=0%",'Hedef Liste Karabük'!P:P,"Geleneksel") -> 1 | Q12: =COUNTIFS('Hedef Liste Kastamonu'!R:R,B12,'Hedef Liste Kastamonu'!C:C,"true",'Hedef Liste Kastamonu'!J:J,"=0%",'Hedef Liste Kastamonu'!P:P,"Geleneksel") -> 0 | R12: =COUNTIFS('Hedef Liste Kırklareli'!R:R,B12,'Hedef Liste Kırklareli'!C:C,"doğru",'Hedef Liste Kırklareli'!J:J,"=0%",'Hedef Liste Kırklareli'!P:P,"Geleneksel") -> 1 | S12: =COUNTIFS('Hedef Liste Konya'!R:R,B12,'Hedef Liste Konya'!C:C,"doğru",'Hedef Liste Konya'!J:J,"=0%",'Hedef Liste Konya'!P:P,"Geleneksel") -> 1 | T12: =COUNTIFS('Hedef Liste Malatya'!R:R,B12,'Hedef Liste Malatya'!C:C,"doğru",'Hedef Liste Malatya'!J:J,"=0%",'Hedef Liste Malatya'!P:P,"Geleneksel") -> 0 | U12: =COUNTIFS('Hedef Liste Ordu'!R:R,B12,'Hedef Liste Ordu'!C:C,"true",'Hedef Liste Ordu'!J:J,"=0%",'Hedef Liste Ordu'!P:P,"Geleneksel") -> 0 | V12: =COUNTIFS('Hedef Liste Osmaniye'!R:R,B12,'Hedef Liste Osmaniye'!C:C,"doğru",'Hedef Liste Osmaniye'!J:J,"=0%",'Hedef Liste Osmaniye'!P:P,"Geleneksel") -> 0 | W12: =COUNTIFS('Hedef Liste Sinop'!T:T,B12,'Hedef Liste Sinop'!C:C,"doğru",'Hedef Liste Sinop'!J:J,"=0%",'Hedef Liste Sinop'!P:P,"Geleneksel") -> 0 | X12: =COUNTIFS('Hedef Liste Tokat'!R:R,B12,'Hedef Liste Tokat'!C:C,"doğru",'Hedef Liste Tokat'!J:J,"=0%",'Hedef Liste Tokat'!P:P,"Geleneksel") -> 0 | Y12: =COUNTIFS('Hedef Liste Uşak'!R:R,B12,'Hedef Liste Uşak'!C:C,"true",'Hedef Liste Uşak'!J:J,"=0%",'Hedef Liste Uşak'!P:P,"Geleneksel") -> 0 | Z12: =COUNTIFS('Hedef Liste Yalova'!R:R,B12,'Hedef Liste Yalova'!C:C,"true",'Hedef Liste Yalova'!J:J,"=0%",'Hedef Liste Yalova'!P:P,"Geleneksel") -> 0 | AA12: =COUNTIFS('Hedef Liste Zonguldak'!R:R,B12,'Hedef Liste Zonguldak'!C:C,"true",'Hedef Liste Zonguldak'!J:J,"=0%",'Hedef Liste Zonguldak'!P:P,"Geleneksel") -> 0 | AB12: =COUNTIFS('Hedef Liste Karaman'!R:R,B12,'Hedef Liste Karaman'!C:C,"doğru",'Hedef Liste Karaman'!J:J,"=0%",'Hedef Liste Karaman'!P:P,"Geleneksel") -> 0
B13: Personel Eksik | C13: =COUNTIFS('Hedef Liste Adıyaman'!R:R,B13,'Hedef Liste Adıyaman'!C:C,"doğru",'Hedef Liste Adıyaman'!J:J,"=0%",'Hedef Liste Adıyaman'!P:P,"Geleneksel") -> 0 | D13: =COUNTIFS('Hedef Liste Afyon'!R:R,B13,'Hedef Liste Afyon'!C:C,"true",'Hedef Liste Afyon'!J:J,"=0%",'Hedef Liste Afyon'!P:P,"Geleneksel") -> 0 | E13: =COUNTIFS('Hedef Liste Amasya'!R:R,B13,'Hedef Liste Amasya'!C:C,"doğru",'Hedef Liste Amasya'!J:J,"=0%",'Hedef Liste Amasya'!P:P,"Geleneksel") -> 0 | F13: =COUNTIFS('Hedef Liste Bartın'!R:R,B13,'Hedef Liste Bartın'!C:C,"doğru",'Hedef Liste Bartın'!J:J,"=0%",'Hedef Liste Bartın'!P:P,"Geleneksel") -> 0 | G13: =COUNTIFS('Hedef Liste Bilecik'!R:R,B13,'Hedef Liste Bilecik'!C:C,"doğru",'Hedef Liste Bilecik'!J:J,"=0%",'Hedef Liste Bilecik'!P:P,"Geleneksel") -> 0 | H13: =COUNTIFS('Hedef Liste Bolu'!R:R,B13,'Hedef Liste Bolu'!C:C,"doğru",'Hedef Liste Bolu'!J:J,"=0%",'Hedef Liste Bolu'!P:P,"Geleneksel") -> 0 | I13: =COUNTIFS('Hedef Liste Çankırı'!R:R,B13,'Hedef Liste Çankırı'!C:C,"doğru",'Hedef Liste Çankırı'!J:J,"=0%",'Hedef Liste Çankırı'!P:P,"Geleneksel") -> 0 | J13: =COUNTIFS('Hedef Liste Diyarbakır'!R:R,B13,'Hedef Liste Diyarbakır'!C:C,"doğru",'Hedef Liste Diyarbakır'!J:J,"=0%",'Hedef Liste Diyarbakır'!P:P,"Geleneksel") -> 0 | K13: =COUNTIFS('Hedef Liste Düzce'!R:R,B13,'Hedef Liste Düzce'!C:C,"true",'Hedef Liste Düzce'!J:J,"=0%",'Hedef Liste Düzce'!P:P,"Geleneksel") -> 0 | L13: =COUNTIFS('Hedef Liste Elazığ'!R:R,B13,'Hedef Liste Elazığ'!C:C,"doğru",'Hedef Liste Elazığ'!J:J,"=0%",'Hedef Liste Elazığ'!P:P,"Geleneksel") -> 0 | M13: =COUNTIFS('Hedef Liste Erzurum'!R:R,B13,'Hedef Liste Erzurum'!C:C,"true",'Hedef Liste Erzurum'!J:J,"=0%",'Hedef Liste Erzurum'!P:P,"Geleneksel") -> 0 | N13: =COUNTIFS('Hedef Liste Giresun'!R:R,B13,'Hedef Liste Giresun'!C:C,"doğru",'Hedef Liste Giresun'!J:J,"=0%",'Hedef Liste Giresun'!P:P,"Geleneksel") -> 0 | O13: =COUNTIFS('Hedef Liste Iğdır'!R:R,B13,'Hedef Liste Iğdır'!C:C,"doğru",'Hedef Liste Iğdır'!J:J,"=0%",'Hedef Liste Iğdır'!P:P,"Geleneksel") -> 0 | P13: =COUNTIFS('Hedef Liste Karabük'!R:R,B13,'Hedef Liste Karabük'!C:C,"true",'Hedef Liste Karabük'!J:J,"=0%",'Hedef Liste Karabük'!P:P,"Geleneksel") -> 1 | Q13: =COUNTIFS('Hedef Liste Kastamonu'!R:R,B13,'Hedef Liste Kastamonu'!C:C,"true",'Hedef Liste Kastamonu'!J:J,"=0%",'Hedef Liste Kastamonu'!P:P,"Geleneksel") -> 0 | R13: =COUNTIFS('Hedef Liste Kırklareli'!R:R,B13,'Hedef Liste Kırklareli'!C:C,"doğru",'Hedef Liste Kırklareli'!J:J,"=0%",'Hedef Liste Kırklareli'!P:P,"Geleneksel") -> 0 | S13: =COUNTIFS('Hedef Liste Konya'!R:R,B13,'Hedef Liste Konya'!C:C,"doğru",'Hedef Liste Konya'!J:J,"=0%",'Hedef Liste Konya'!P:P,"Geleneksel") -> 1 | T13: =COUNTIFS('Hedef Liste Malatya'!R:R,B13,'Hedef Liste Malatya'!C:C,"doğru",'Hedef Liste Malatya'!J:J,"=0%",'Hedef Liste Malatya'!P:P,"Geleneksel") -> 0 | U13: =COUNTIFS('Hedef Liste Ordu'!R:R,B13,'Hedef Liste Ordu'!C:C,"true",'Hedef Liste Ordu'!J:J,"=0%",'Hedef Liste Ordu'!P:P,"Geleneksel") -> 0 | V13: =COUNTIFS('Hedef Liste Osmaniye'!R:R,B13,'Hedef Liste Osmaniye'!C:C,"doğru",'Hedef Liste Osmaniye'!J:J,"=0%",'Hedef Liste Osmaniye'!P:P,"Geleneksel") -> 1 | W13: =COUNTIFS('Hedef Liste Sinop'!T:T,B13,'Hedef Liste Sinop'!C:C,"doğru",'Hedef Liste Sinop'!J:J,"=0%",'Hedef Liste Sinop'!P:P,"Geleneksel") -> 0 | X13: =COUNTIFS('Hedef Liste Tokat'!R:R,B13,'Hedef Liste Tokat'!C:C,"doğru",'Hedef Liste Tokat'!J:J,"=0%",'Hedef Liste Tokat'!P:P,"Geleneksel") -> 0 | Y13: =COUNTIFS('Hedef Liste Uşak'!R:R,B13,'Hedef Liste Uşak'!C:C,"true",'Hedef Liste Uşak'!J:J,"=0%",'Hedef Liste Uşak'!P:P,"Geleneksel") -> 0 | Z13: =COUNTIFS('Hedef Liste Yalova'!R:R,B13,'Hedef Liste Yalova'!C:C,"true",'Hedef Liste Yalova'!J:J,"=0%",'Hedef Liste Yalova'!P:P,"Geleneksel") -> 0 | AA13: =COUNTIFS('Hedef Liste Zonguldak'!R:R,B13,'Hedef Liste Zonguldak'!C:C,"true",'Hedef Liste Zonguldak'!J:J,"=0%",'Hedef Liste Zonguldak'!P:P,"Geleneksel") -> 0 | AB13: =COUNTIFS('Hedef Liste Karaman'!R:R,B13,'Hedef Liste Karaman'!C:C,"doğru",'Hedef Liste Karaman'!J:J,"=0%",'Hedef Liste Karaman'!P:P,"Geleneksel") -> 1
B14: Randevu Alındı | C14: =COUNTIFS('Hedef Liste Adıyaman'!R:R,B14,'Hedef Liste Adıyaman'!C:C,"doğru",'Hedef Liste Adıyaman'!J:J,"=0%",'Hedef Liste Adıyaman'!P:P,"Geleneksel") -> 3 | D14: =COUNTIFS('Hedef Liste Afyon'!R:R,B14,'Hedef Liste Afyon'!C:C,"true",'Hedef Liste Afyon'!J:J,"=0%",'Hedef Liste Afyon'!P:P,"Geleneksel") -> 1 | E14: =COUNTIFS('Hedef Liste Amasya'!R:R,B14,'Hedef Liste Amasya'!C:C,"doğru",'Hedef Liste Amasya'!J:J,"=0%",'Hedef Liste Amasya'!P:P,"Geleneksel") -> 10 | F14: =COUNTIFS('Hedef Liste Bartın'!R:R,B14,'Hedef Liste Bartın'!C:C,"doğru",'Hedef Liste Bartın'!J:J,"=0%",'Hedef Liste Bartın'!P:P,"Geleneksel") -> 4 | G14: =COUNTIFS('Hedef Liste Bilecik'!R:R,B14,'Hedef Liste Bilecik'!C:C,"doğru",'Hedef Liste Bilecik'!J:J,"=0%",'Hedef Liste Bilecik'!P:P,"Geleneksel") -> 4 | H14: =COUNTIFS('Hedef Liste Bolu'!R:R,B14,'Hedef Liste Bolu'!C:C,"doğru",'Hedef Liste Bolu'!J:J,"=0%",'Hedef Liste Bolu'!P:P,"Geleneksel") -> 12 | I14: =COUNTIFS('Hedef Liste Çankırı'!R:R,B14,'Hedef Liste Çankırı'!C:C,"doğru",'Hedef Liste Çankırı'!J:J,"=0%",'Hedef Liste Çankırı'!P:P,"Geleneksel") -> 0 | J14: =COUNTIFS('Hedef Liste Diyarbakır'!R:R,B14,'Hedef Liste Diyarbakır'!C:C,"doğru",'Hedef Liste Diyarbakır'!J:J,"=0%",'Hedef Liste Diyarbakır'!P:P,"Geleneksel") -> 0 | K14: =COUNTIFS('Hedef Liste Düzce'!R:R,B14,'Hedef Liste Düzce'!C:C,"true",'Hedef Liste Düzce'!J:J,"=0%",'Hedef Liste Düzce'!P:P,"Geleneksel") -> 0 | L14: =COUNTIFS('Hedef Liste Elazığ'!R:R,B14,'Hedef Liste Elazığ'!C:C,"doğru",'Hedef Liste Elazığ'!J:J,"=0%",'Hedef Liste Elazığ'!P:P,"Geleneksel") -> 16 | M14: =COUNTIFS('Hedef Liste Erzurum'!R:R,B14,'Hedef Liste Erzurum'!C:C,"true",'Hedef Liste Erzurum'!J:J,"=0%",'Hedef Liste Erzurum'!P:P,"Geleneksel") -> 3 | N14: =COUNTIFS('Hedef Liste Giresun'!R:R,B14,'Hedef Liste Giresun'!C:C,"doğru",'Hedef Liste Giresun'!J:J,"=0%",'Hedef Liste Giresun'!P:P,"Geleneksel") -> 6 | O14: =COUNTIFS('Hedef Liste Iğdır'!R:R,B14,'Hedef Liste Iğdır'!C:C,"doğru",'Hedef Liste Iğdır'!J:J,"=0%",'Hedef Liste Iğdır'!P:P,"Geleneksel") -> 7 | P14: =COUNTIFS('Hedef Liste Karabük'!R:R,B14,'Hedef Liste Karabük'!C:C,"true",'Hedef Liste Karabük'!J:J,"=0%",'Hedef Liste Karabük'!P:P,"Geleneksel") -> 4 | Q14: =COUNTIFS('Hedef Liste Kastamonu'!R:R,B14,'Hedef Liste Kastamonu'!C:C,"true",'Hedef Liste Kastamonu'!J:J,"=0%",'Hedef Liste Kastamonu'!P:P,"Geleneksel") -> 0 | R14: =COUNTIFS('Hedef Liste Kırklareli'!R:R,B14,'Hedef Liste Kırklareli'!C:C,"doğru",'Hedef Liste Kırklareli'!J:J,"=0%",'Hedef Liste Kırklareli'!P:P,"Geleneksel") -> 10 | S14: =COUNTIFS('Hedef Liste Konya'!R:R,B14,'Hedef Liste Konya'!C:C,"doğru",'Hedef Liste Konya'!J:J,"=0%",'Hedef Liste Konya'!P:P,"Geleneksel") -> 17 | T14: =COUNTIFS('Hedef Liste Malatya'!R:R,B14,'Hedef Liste Malatya'!C:C,"doğru",'Hedef Liste Malatya'!J:J,"=0%",'Hedef Liste Malatya'!P:P,"Geleneksel") -> 8 | U14: =COUNTIFS('Hedef Liste Ordu'!R:R,B14,'Hedef Liste Ordu'!C:C,"true",'Hedef Liste Ordu'!J:J,"=0%",'Hedef Liste Ordu'!P:P,"Geleneksel") -> 3 | V14: =COUNTIFS('Hedef Liste Osmaniye'!R:R,B14,'Hedef Liste Osmaniye'!C:C,"doğru",'Hedef Liste Osmaniye'!J:J,"=0%",'Hedef Liste Osmaniye'!P:P,"Geleneksel") -> 1 | W14: =COUNTIFS('Hedef Liste Sinop'!T:T,B14,'Hedef Liste Sinop'!C:C,"doğru",'Hedef Liste Sinop'!J:J,"=0%",'Hedef Liste Sinop'!P:P,"Geleneksel") -> 1 | X14: =COUNTIFS('Hedef Liste Tokat'!R:R,B14,'Hedef Liste Tokat'!C:C,"doğru",'Hedef Liste Tokat'!J:J,"=0%",'Hedef Liste Tokat'!P:P,"Geleneksel") -> 4 | Y14: =COUNTIFS('Hedef Liste Uşak'!R:R,B14,'Hedef Liste Uşak'!C:C,"true",'Hedef Liste Uşak'!J:J,"=0%",'Hedef Liste Uşak'!P:P,"Geleneksel") -> 0 | Z14: =COUNTIFS('Hedef Liste Yalova'!R:R,B14,'Hedef Liste Yalova'!C:C,"true",'Hedef Liste Yalova'!J:J,"=0%",'Hedef Liste Yalova'!P:P,"Geleneksel") -> 1 | AA14: =COUNTIFS('Hedef Liste Zonguldak'!R:R,B14,'Hedef Liste Zonguldak'!C:C,"true",'Hedef Liste Zonguldak'!J:J,"=0%",'Hedef Liste Zonguldak'!P:P,"Geleneksel") -> 0 | AB14: =COUNTIFS('Hedef Liste Karaman'!R:R,B14,'Hedef Liste Karaman'!C:C,"doğru",'Hedef Liste Karaman'!J:J,"=0%",'Hedef Liste Karaman'!P:P,"Geleneksel") -> 5
... B20: Yılbaşından Sonra Aranacak | C20: =COUNTIFS('Hedef Liste Adıyaman'!R:R,B20,'Hedef Liste Adıyaman'!C:C,"doğru",'Hedef Liste Adıyaman'!J:J,"=0%",'Hedef Liste Adıyaman'!P:P,"Geleneksel") -> 0 | D20: =COUNTIFS('Hedef Liste Afyon'!R:R,B20,'Hedef Liste Afyon'!C:C,"true",'Hedef Liste Afyon'!J:J,"=0%",'Hedef Liste Afyon'!P:P,"Geleneksel") -> 0 | E20: =COUNTIFS('Hedef Liste Amasya'!R:R,B20,'Hedef Liste Amasya'!C:C,"doğru",'Hedef Liste Amasya'!J:J,"=0%",'Hedef Liste Amasya'!P:P,"Geleneksel") -> 0 | F20: =COUNTIFS('Hedef Liste Bartın'!R:R,B20,'Hedef Liste Bartın'!C:C,"doğru",'Hedef Liste Bartın'!J:J,"=0%",'Hedef Liste Bartın'!P:P,"Geleneksel") -> 0 | G20: =COUNTIFS('Hedef Liste Bilecik'!R:R,B20,'Hedef Liste Bilecik'!C:C,"doğru",'Hedef Liste Bilecik'!J:J,"=0%",'Hedef Liste Bilecik'!P:P,"Geleneksel") -> 0 | H20: =COUNTIFS('Hedef Liste Bolu'!R:R,B20,'Hedef Liste Bolu'!C:C,"doğru",'Hedef Liste Bolu'!J:J,"=0%",'Hedef Liste Bolu'!P:P,"Geleneksel") -> 0 | I20: =COUNTIFS('Hedef Liste Çankırı'!R:R,B20,'Hedef Liste Çankırı'!C:C,"doğru",'Hedef Liste Çankırı'!J:J,"=0%",'Hedef Liste Çankırı'!P:P,"Geleneksel") -> 0 | J20: =COUNTIFS('Hedef Liste Diyarbakır'!R:R,B20,'Hedef Liste Diyarbakır'!C:C,"doğru",'Hedef Liste Diyarbakır'!J:J,"=0%",'Hedef Liste Diyarbakır'!P:P,"Geleneksel") -> 0 | K20: =COUNTIFS('Hedef Liste Düzce'!R:R,B20,'Hedef Liste Düzce'!C:C,"true",'Hedef Liste Düzce'!J:J,"=0%",'Hedef Liste Düzce'!P:P,"Geleneksel") -> 0 | L20: =COUNTIFS('Hedef Liste Elazığ'!R:R,B20,'Hedef Liste Elazığ'!C:C,"doğru",'Hedef Liste Elazığ'!J:J,"=0%",'Hedef Liste Elazığ'!P:P,"Geleneksel") -> 0 | M20: =COUNTIFS('Hedef Liste Erzurum'!R:R,B20,'Hedef Liste Erzurum'!C:C,"true",'Hedef Liste Erzurum'!J:J,"=0%",'Hedef Liste Erzurum'!P:P,"Geleneksel") -> 0 | N20: =COUNTIFS('Hedef Liste Giresun'!R:R,B20,'Hedef Liste Giresun'!C:C,"doğru",'Hedef Liste Giresun'!J:J,"=0%",'Hedef Liste Giresun'!P:P,"Geleneksel") -> 0 | O20: =COUNTIFS('Hedef Liste Iğdır'!R:R,B20,'Hedef Liste Iğdır'!C:C,"doğru",'Hedef Liste Iğdır'!J:J,"=0%",'Hedef Liste Iğdır'!P:P,"Geleneksel") -> 0 | P20: =COUNTIFS('Hedef Liste Karabük'!R:R,B20,'Hedef Liste Karabük'!C:C,"true",'Hedef Liste Karabük'!J:J,"=0%",'Hedef Liste Karabük'!P:P,"Geleneksel") -> 0 | Q20: =COUNTIFS('Hedef Liste Kastamonu'!R:R,B20,'Hedef Liste Kastamonu'!C:C,"true",'Hedef Liste Kastamonu'!J:J,"=0%",'Hedef Liste Kastamonu'!P:P,"Geleneksel") -> 0 | R20: =COUNTIFS('Hedef Liste Kırklareli'!R:R,B20,'Hedef Liste Kırklareli'!C:C,"doğru",'Hedef Liste Kırklareli'!J:J,"=0%",'Hedef Liste Kırklareli'!P:P,"Geleneksel") -> 0 | S20: =COUNTIFS('Hedef Liste Konya'!R:R,B20,'Hedef Liste Konya'!C:C,"doğru",'Hedef Liste Konya'!J:J,"=0%",'Hedef Liste Konya'!P:P,"Geleneksel") -> 0 | T20: =COUNTIFS('Hedef Liste Malatya'!R:R,B20,'Hedef Liste Malatya'!C:C,"doğru",'Hedef Liste Malatya'!J:J,"=0%",'Hedef Liste Malatya'!P:P,"Geleneksel") -> 0 | U20: =COUNTIFS('Hedef Liste Ordu'!R:R,B20,'Hedef Liste Ordu'!C:C,"true",'Hedef Liste Ordu'!J:J,"=0%",'Hedef Liste Ordu'!P:P,"Geleneksel") -> 0 | V20: =COUNTIFS('Hedef Liste Osmaniye'!R:R,B20,'Hedef Liste Osmaniye'!C:C,"doğru",'Hedef Liste Osmaniye'!J:J,"=0%",'Hedef Liste Osmaniye'!P:P,"Geleneksel") -> 0 | W20: =COUNTIFS('Hedef Liste Sinop'!T:T,B20,'Hedef Liste Sinop'!C:C,"doğru",'Hedef Liste Sinop'!J:J,"=0%",'Hedef Liste Sinop'!P:P,"Geleneksel") -> 0 | X20: =COUNTIFS('Hedef Liste Tokat'!R:R,B20,'Hedef Liste Tokat'!C:C,"doğru",'Hedef Liste Tokat'!J:J,"=0%",'Hedef Liste Tokat'!P:P,"Geleneksel") -> 0 | Y20: =COUNTIFS('Hedef Liste Uşak'!R:R,B20,'Hedef Liste Uşak'!C:C,"true",'Hedef Liste Uşak'!J:J,"=0%",'Hedef Liste Uşak'!P:P,"Geleneksel") -> 0 | Z20: =COUNTIFS('Hedef Liste Yalova'!R:R,B20,'Hedef Liste Yalova'!C:C,"true",'Hedef Liste Yalova'!J:J,"=0%",'Hedef Liste Yalova'!P:P,"Geleneksel") -> 0 | AA20: =COUNTIFS('Hedef Liste Zonguldak'!R:R,B20,'Hedef Liste Zonguldak'!C:C,"true",'Hedef Liste Zonguldak'!J:J,"=0%",'Hedef Liste Zonguldak'!P:P,"Geleneksel") -> 0 | AB20: =COUNTIFS('Hedef Liste Karaman'!R:R,B20,'Hedef Liste Karaman'!C:C,"doğru",'Hedef Liste Karaman'!J:J,"=0%",'Hedef Liste Karaman'!P:P,"Geleneksel") -> 0
B21: Fotoğrafı Var | C21: =COUNTIFS('Hedef Liste Adıyaman'!Q:Q,"true",'Hedef Liste Adıyaman'!C:C,"doğru",'Hedef Liste Adıyaman'!J:J,"=0%",'Hedef Liste Adıyaman'!P:P,"Geleneksel") -> 5 | D21: =COUNTIFS('Hedef Liste Afyon'!Q:Q,"true",'Hedef Liste Afyon'!C:C,"true",'Hedef Liste Afyon'!J:J,"=0%",'Hedef Liste Afyon'!P:P,"Geleneksel",'Hedef Liste Afyon'!R:R,"") -> 18 | E21: =COUNTIFS('Hedef Liste Amasya'!Q:Q,TRUE,'Hedef Liste Amasya'!C:C,"doğru",'Hedef Liste Amasya'!J:J,"=0%",'Hedef Liste Amasya'!P:P,"Geleneksel") -> 3 | F21: =COUNTIFS('Hedef Liste Bartın'!Q:Q,"true",'Hedef Liste Bartın'!C:C,"doğru",'Hedef Liste Bartın'!J:J,"=0%",'Hedef Liste Bartın'!P:P,"Geleneksel") -> 3 | G21: =COUNTIFS('Hedef Liste Bilecik'!Q:Q,"true",'Hedef Liste Bilecik'!C:C,"doğru",'Hedef Liste Bilecik'!J:J,"=0%",'Hedef Liste Bilecik'!P:P,"Geleneksel") -> 5 | H21: =COUNTIFS('Hedef Liste Bolu'!Q:Q,"true",'Hedef Liste Bolu'!C:C,"doğru",'Hedef Liste Bolu'!J:J,"=0%",'Hedef Liste Bolu'!P:P,"Geleneksel") -> 2 | I21: =COUNTIFS('Hedef Liste Çankırı'!Q:Q,"true",'Hedef Liste Çankırı'!C:C,"doğru",'Hedef Liste Çankırı'!J:J,"=0%",'Hedef Liste Çankırı'!P:P,"Geleneksel") -> 0 | J21: =COUNTIFS('Hedef Liste Diyarbakır'!Q:Q,"true",'Hedef Liste Diyarbakır'!C:C,"doğru",'Hedef Liste Diyarbakır'!J:J,"=0%",'Hedef Liste Diyarbakır'!P:P,"Geleneksel",'Hedef Liste Diyarbakır'!R:R,"") -> 0 | K21: =COUNTIFS('Hedef Liste Düzce'!Q:Q,B12,'Hedef Liste Düzce'!C:C,"true",'Hedef Liste Düzce'!J:J,"=0%",'Hedef Liste Düzce'!P:P,"Geleneksel",'Hedef Liste Düzce'!R:R,"") -> 0 | L21: =COUNTIFS('Hedef Liste Elazığ'!Q:Q,"true",'Hedef Liste Elazığ'!C:C,"doğru",'Hedef Liste Elazığ'!J:J,"=0%",'Hedef Liste Elazığ'!P:P,"Geleneksel") -> 2 | M21: =COUNTIFS('Hedef Liste Erzurum'!Q:Q,"true",'Hedef Liste Erzurum'!C:C,"true",'Hedef Liste Erzurum'!J:J,"=0%",'Hedef Liste Erzurum'!P:P,"Geleneksel",'Hedef Liste Erzurum'!R:R,"") -> 13 | N21: =COUNTIFS('Hedef Liste Giresun'!Q:Q,"true",'Hedef Liste Giresun'!C:C,"doğru",'Hedef Liste Giresun'!J:J,"=0%",'Hedef Liste Giresun'!P:P,"Geleneksel") -> 3 | O21: =COUNTIFS('Hedef Liste Iğdır'!Q:Q,"true",'Hedef Liste Iğdır'!C:C,"doğru",'Hedef Liste Iğdır'!J:J,"=0%",'Hedef Liste Iğdır'!P:P,"Geleneksel") -> 2 | P21: =COUNTIFS('Hedef Liste Karabük'!Q:Q,B12,'Hedef Liste Karabük'!C:C,"true",'Hedef Liste Karabük'!J:J,"=0%",'Hedef Liste Karabük'!P:P,"Geleneksel",'Hedef Liste Karabük'!R:R,"") -> 0 | Q21: =COUNTIFS('Hedef Liste Kastamonu'!Q:Q,"true",'Hedef Liste Kastamonu'!C:C,"true",'Hedef Liste Kastamonu'!J:J,"=0%",'Hedef Liste Kastamonu'!P:P,"Geleneksel") -> 0 | R21: =COUNTIFS('Hedef Liste Kırklareli'!Q:Q,"true",'Hedef Liste Kırklareli'!C:C,"doğru",'Hedef Liste Kırklareli'!J:J,"=0%",'Hedef Liste Kırklareli'!P:P,"Geleneksel") -> 8 | S21: =COUNTIFS('Hedef Liste Konya'!Q:Q,"True",'Hedef Liste Konya'!C:C,"doğru",'Hedef Liste Konya'!J:J,"=0%",'Hedef Liste Konya'!P:P,"Geleneksel",'Hedef Liste Konya'!R:R,"") -> 63 | T21: =COUNTIFS('Hedef Liste Malatya'!Q:Q,"True",'Hedef Liste Malatya'!C:C,"doğru",'Hedef Liste Malatya'!J:J,"=0%",'Hedef Liste Malatya'!P:P,"Geleneksel",'Hedef Liste Malatya'!R:R,"") -> 16 | U21: =COUNTIFS('Hedef Liste Ordu'!Q:Q,"true",'Hedef Liste Ordu'!C:C,"true",'Hedef Liste Ordu'!J:J,"=0%",'Hedef Liste Ordu'!P:P,"Geleneksel",'Hedef Liste Ordu'!R:R,"") -> 12 | V21: =COUNTIFS('Hedef Liste Osmaniye'!R:R,B21,'Hedef Liste Osmaniye'!C:C,"doğru",'Hedef Liste Osmaniye'!J:J,"=0%",'Hedef Liste Osmaniye'!P:P,"Geleneksel") -> 0 | W21: =COUNTIFS('Hedef Liste Sinop'!S:S,"true",'Hedef Liste Sinop'!C:C,"doğru",'Hedef Liste Sinop'!J:J,"=0%",'Hedef Liste Sinop'!P:P,"Geleneksel") -> 1 | X21: =COUNTIFS('Hedef Liste Tokat'!Q:Q,"true",'Hedef Liste Tokat'!C:C,"doğru",'Hedef Liste Tokat'!J:J,"=0%",'Hedef Liste Tokat'!P:P,"Geleneksel") -> 4 | Y21: =COUNTIFS('Hedef Liste Uşak'!Q:Q,"true",'Hedef Liste Uşak'!C:C,"true",'Hedef Liste Uşak'!J:J,"=0%",'Hedef Liste Uşak'!P:P,"Geleneksel",'Hedef Liste Uşak'!R:R,"") -> 0 | Z21: =COUNTIFS('Hedef Liste Yalova'!Q:Q,"true",'Hedef Liste Yalova'!C:C,"true",'Hedef Liste Yalova'!J:J,"=0%",'Hedef Liste Yalova'!P:P,"Geleneksel",'Hedef Liste Yalova'!R:R,"") -> 11 | AA21: =COUNTIFS('Hedef Liste Zonguldak'!Q:Q,"true",'Hedef Liste Zonguldak'!C:C,"true",'Hedef Liste Zonguldak'!J:J,"=0%",'Hedef Liste Zonguldak'!P:P,"Geleneksel",'Hedef Liste Zonguldak'!R:R,"") -> 0 | AB21: =COUNTIFS('Hedef Liste Karaman'!Q:Q,"true",'Hedef Liste Karaman'!C:C,"doğru",'Hedef Liste Karaman'!J:J,"=0%",'Hedef Liste Karaman'!P:P,"Geleneksel") -> 3
B22: TOPLAM | C22: =SUM(C3:C21) -> 34 | D22: =SUM(D3:D21) -> 70 | E22: =SUM(E3:E21) -> 30 | F22: =SUM(F3:F21) -> 27 | G22: =SUM(G3:G21) -> 26 | H22: =SUM(H3:H21) -> 25 | I22: =SUM(I3:I21) -> 0 | J22: =SUM(J3:J21) -> 0 | ... AB22: =SUM(AB3:AB21) -> 28
